{"entries":[{"blockCount":16,"bytes":640,"file":"chunks/y000-z000-x320.json","offset":{"x":320,"y":0,"z":0},"requirements":{"minecraft:sandstone":16},"sha256":"6644b69e6c81c6d3841e4528a96aa8cc6c8a0c657949220325d74aece8d597f8","size":{"x":32,"y":1,"z":32}},{"blockCount":32,"bytes":640,"file":"chunks/y000-z000-x352.json","offset":{"x":352,"y":0,"z":0},"requirements":{"minecraft:sandstone":32},"sha256":"5a1c3bad4f38fc5b2eb8055b5504e556911de31e9d0c4adad9a2f0f2a269a4b7","size":{"x":32,"y":1,"z":32}},{"blockCount":14,"bytes":989,"file":"chunks/y000-z000-x384.json","offset":{"x":384,"y":0,"z":0},"requirements":{"minecraft:sandstone":14},"sha256":"310cfaa8e7b29c2dad35fde2d3cdffb0378b18228ace4771d4399554db6110d7","size":{"x":32,"y":1,"z":32}},{"blockCount":91,"bytes":1880,"file":"chunks/y000-z032-x320.json","offset":{"x":320,"y":0,"z":32},"requirements":{"minecraft:spruce_planks":29,"minecraft:stone_bricks":62},"sha256":"519fcd4f0599a50e74fa9d98678cc807e6646cb853de007edfad0dadd7ed731e","size":{"x":32,"y":1,"z":32}},{"blockCount":32,"bytes":891,"file":"chunks/y000-z032-x352.json","offset":{"x":352,"y":0,"z":32},"requirements":{"minecraft:sandstone":13,"minecraft:spruce_planks":18,"minecraft:stone_bricks":1},"sha256":"c9d24b9172b474ebe9148e109c47c101ae1a56507f7dab0a95cf5ef2df834dc8","size":{"x":32,"y":1,"z":32}},{"blockCount":7,"bytes":871,"file":"chunks/y000-z032-x384.json","offset":{"x":384,"y":0,"z":32},"requirements":{"minecraft:sandstone":7},"sha256":"aa04b400b624077e3604b399ec4d60009e90688f47a38b685f234a9ea98d2f81","size":{"x":32,"y":1,"z":32}},{"blockCount":91,"bytes":1972,"file":"chunks/y000-z064-x320.json","offset":{"x":320,"y":0,"z":64},"requirements":{"minecraft:spruce_planks":21,"minecraft:stone_bricks":70},"sha256":"cc16147487669a3bf33f93be52af7851ad34c8a92c00706f6b2c3ca529664f1b","size":{"x":32,"y":1,"z":32}},{"blockCount":65,"bytes":982,"file":"chunks/y000-z064-x352.json","offset":{"x":352,"y":0,"z":64},"requirements":{"minecraft:spruce_planks":1,"minecraft:stone_bricks":64},"sha256":"a19b27f364118dc6f40700987b2fb81ac8a7020a4be47f8f3a4782827623a2e4","size":{"x":32,"y":1,"z":32}},{"blockCount":241,"bytes":1847,"file":"chunks/y000-z096-x320.json","offset":{"x":320,"y":0,"z":96},"requirements":{"minecraft:sandstone":2,"minecraft:spruce_planks":11,"minecraft:stone_bricks":228},"sha256":"c87318b887b46dab38c481d90a727ce8f36d311d6c22407803a2bd287334037d","size":{"x":32,"y":1,"z":32}},{"blockCount":150,"bytes":1247,"file":"chunks/y000-z096-x352.json","offset":{"x":352,"y":0,"z":96},"requirements":{"minecraft:stone_bricks":150},"sha256":"410c5306377e2aad0e8c8a0a72672837391f4e577ed19ae2dae149064db877d3","size":{"x":32,"y":1,"z":32}},{"blockCount":147,"bytes":1380,"file":"chunks/y000-z128-x160.json","offset":{"x":160,"y":0,"z":128},"requirements":{"minecraft:cobbled_deepslate":21,"minecraft:stone_bricks":126},"sha256":"44d5a02a28941a00bdee9461e987eae37c33fdfb71a38d184d50e47701e653ab","size":{"x":32,"y":1,"z":32}},{"blockCount":208,"bytes":1398,"file":"chunks/y000-z128-x192.json","offset":{"x":192,"y":0,"z":128},"requirements":{"minecraft:cobbled_deepslate":10,"minecraft:stone_bricks":198},"sha256":"ff903d3851378e083aebfdfe65a6142a0e9926062ee9efa5279c91b4a4a1172b","size":{"x":32,"y":1,"z":32}},{"blockCount":92,"bytes":1377,"file":"chunks/y000-z128-x224.json","offset":{"x":224,"y":0,"z":128},"requirements":{"minecraft:cobbled_deepslate":6,"minecraft:stone_bricks":86},"sha256":"fab93f4d2e1ee23130134e01c5389fee6105eff09e060903eb6e702529cf1c73","size":{"x":32,"y":1,"z":32}},{"blockCount":285,"bytes":1483,"file":"chunks/y000-z128-x256.json","offset":{"x":256,"y":0,"z":128},"requirements":{"minecraft:stone_bricks":285},"sha256":"9f7d27644e7af15bdd15a5634faba9a9b71f65c01b17f31316570363147a2e17","size":{"x":32,"y":1,"z":32}},{"blockCount":30,"bytes":1662,"file":"chunks/y000-z160-x160.json","offset":{"x":160,"y":0,"z":160},"requirements":{"minecraft:cobbled_deepslate":30},"sha256":"77836cf2277485f7574a50ca5fa186b9e017388d3ede78e0c0def8ad263e29a7","size":{"x":32,"y":1,"z":32}},{"blockCount":43,"bytes":1311,"file":"chunks/y000-z192-x160.json","offset":{"x":160,"y":0,"z":192},"requirements":{"minecraft:cobbled_deepslate":43},"sha256":"99b9aec1abdc0c757925215ae5c0ab790dad2bc472775ab27bd685227c8c43c6","size":{"x":32,"y":1,"z":32}},{"blockCount":32,"bytes":650,"file":"chunks/y000-z192-x192.json","offset":{"x":192,"y":0,"z":192},"requirements":{"minecraft:cobbled_deepslate":32},"sha256":"51308912b9ee5dd2a71a0fa68c43241a072b90b24f381ed44ee12db308a067f7","size":{"x":32,"y":1,"z":32}},{"blockCount":19,"bytes":650,"file":"chunks/y000-z192-x224.json","offset":{"x":224,"y":0,"z":192},"requirements":{"minecraft:cobbled_deepslate":19},"sha256":"99e7f5b2a2d979e7f4e64fe8d6e7039a9be40b040456e59f66dbd83dc285120d","size":{"x":32,"y":1,"z":32}},{"blockCount":3,"bytes":704,"file":"chunks/y000-z224-x384.json","offset":{"x":384,"y":0,"z":224},"requirements":{"minecraft:sandstone":2,"minecraft:stone_bricks":1},"sha256":"357ed6a49534d7170d4d8cd6dcdb9f5577f425466a7a89b9620dd5e5dc0863a7","size":{"x":32,"y":1,"z":15}},{"blockCount":26,"bytes":1029,"file":"chunks/y001-z000-x320.json","offset":{"x":320,"y":1,"z":0},"requirements":{"minecraft:sandstone":26},"sha256":"9b568cdc69ae29c7186248886267296a48e3d296ef50eb2b029efd26bcbd6fe2","size":{"x":32,"y":1,"z":32}},{"blockCount":32,"bytes":640,"file":"chunks/y001-z000-x352.json","offset":{"x":352,"y":1,"z":0},"requirements":{"minecraft:sandstone":32},"sha256":"3ae810ca449aba29c521770d0876328a3e98c77672d1799e99aa7e1c5c7c611a","size":{"x":32,"y":1,"z":32}},{"blockCount":14,"bytes":989,"file":"chunks/y001-z000-x384.json","offset":{"x":384,"y":1,"z":0},"requirements":{"minecraft:sandstone":14},"sha256":"e03bc863bcbd2e27c59ab0d430d7a709bb1452adcd89b0e79214da684715daea","size":{"x":32,"y":1,"z":32}},{"blockCount":600,"bytes":3778,"file":"chunks/y001-z032-x320.json","offset":{"x":320,"y":1,"z":32},"requirements":{"minecraft:bricks":1,"minecraft:sandstone":7,"minecraft:spruce_planks":415,"minecraft:stone_bricks":177},"sha256":"8b84bb353ac1a794a380d970dac195f690529d008c8a2779c5b22d18e4339e0b","size":{"x":32,"y":1,"z":32}},{"blockCount":819,"bytes":1232,"file":"chunks/y001-z032-x352.json","offset":{"x":352,"y":1,"z":32},"requirements":{"minecraft:glass":1,"minecraft:spruce_planks":786,"minecraft:stone_bricks":32},"sha256":"e99a49007c8a6618bb8aca5fc0abaa6f116d6eed2015319266ef2f320ab10b62","size":{"x":32,"y":1,"z":32}},{"blockCount":15,"bytes":1024,"file":"chunks/y001-z032-x384.json","offset":{"x":384,"y":1,"z":32},"requirements":{"minecraft:sandstone":7,"minecraft:spruce_planks":4,"minecraft:stone_bricks":4},"sha256":"4b7c48ffbab2c3452f4626f6f074b673c33bfb97e4c9a6c94695a5630d6ff9df","size":{"x":32,"y":1,"z":32}},{"blockCount":599,"bytes":4455,"file":"chunks/y001-z064-x320.json","offset":{"x":320,"y":1,"z":64},"requirements":{"minecraft:bricks":1,"minecraft:cobbled_deepslate":1,"minecraft:glass":2,"minecraft:sandstone":33,"minecraft:spruce_planks":174,"minecraft:stone_bricks":388},"sha256":"ad5cf79ff96c06e952659154ff5f221da7d6dc5536e5847f9e9f98a89ae912e0","size":{"x":32,"y":1,"z":32}},{"blockCount":335,"bytes":1411,"file":"chunks/y001-z064-x352.json","offset":{"x":352,"y":1,"z":64},"requirements":{"minecraft:glass":1,"minecraft:sandstone":38,"minecraft:spruce_planks":247,"minecraft:stone_bricks":49},"sha256":"8815e33dff1f128ba991d16953975beaea8a4a4ed1931a15869ff15fe37ae685","size":{"x":32,"y":1,"z":32}},{"blockCount":28,"bytes":1377,"file":"chunks/y001-z064-x384.json","offset":{"x":384,"y":1,"z":64},"requirements":{"minecraft:sandstone":21,"minecraft:spruce_planks":3,"minecraft:stone_bricks":4},"sha256":"a77de0259f285f8eb2a27435ee4e3e63bbaf404cb89a922cccaf69fc5b090f6f","size":{"x":32,"y":1,"z":32}},{"blockCount":16,"bytes":1216,"file":"chunks/y001-z096-x192.json","offset":{"x":192,"y":1,"z":96},"requirements":{"minecraft:bricks":16},"sha256":"838816017898567bed48877eaf7b992080492d5968f19950e8cabc616167fe79","size":{"x":32,"y":1,"z":32}},{"blockCount":19,"bytes":1216,"file":"chunks/y001-z096-x224.json","offset":{"x":224,"y":1,"z":96},"requirements":{"minecraft:bricks":19},"sha256":"dc8e3ff84330a5740d1d0a006c8c43b80549b50ee5523cce59af587e21911c41","size":{"x":32,"y":1,"z":32}},{"blockCount":296,"bytes":3269,"file":"chunks/y001-z096-x320.json","offset":{"x":320,"y":1,"z":96},"requirements":{"minecraft:cobbled_deepslate":3,"minecraft:sandstone":1,"minecraft:spruce_planks":38,"minecraft:stone_bricks":254},"sha256":"958380d3ff92fec6224c2bdf829a7fccaedcd383bbda6e909969c859ca91e622","size":{"x":32,"y":1,"z":32}},{"blockCount":252,"bytes":1473,"file":"chunks/y001-z096-x352.json","offset":{"x":352,"y":1,"z":96},"requirements":{"minecraft:cobbled_deepslate":1,"minecraft:oak_planks":1,"minecraft:sandstone":4,"minecraft:stone_bricks":246},"sha256":"ad7b9fc66a412c9949139650aace311290a73a9ecbc561a4ba67d86fe88e9f75","size":{"x":32,"y":1,"z":32}},{"blockCount":123,"bytes":1341,"file":"chunks/y001-z128-x160.json","offset":{"x":160,"y":1,"z":128},"requirements":{"minecraft:cobbled_deepslate":21,"minecraft:stone_bricks":102},"sha256":"d304208b91d99d04b213a80323df00c162556c57a6b38ec1cafd0fbc415308c4","size":{"x":32,"y":1,"z":32}},{"blockCount":224,"bytes":2305,"file":"chunks/y001-z128-x192.json","offset":{"x":192,"y":1,"z":128},"requirements":{"minecraft:bricks":24,"minecraft:cobbled_deepslate":10,"minecraft:stone_bricks":190},"sha256":"d10f369dea6de0407a3f9385d8fdf21959e290b39c271e531a2ac033c06a5f1c","size":{"x":32,"y":1,"z":32}},{"blockCount":144,"bytes":3849,"file":"chunks/y001-z128-x224.json","offset":{"x":224,"y":1,"z":128},"requirements":{"minecraft:bricks":38,"minecraft:cobbled_deepslate":36,"minecraft:polished_diorite":6,"minecraft:stone_bricks":64},"sha256":"066db1afce0b56be36ecfa495c6338e8f3d6dc7754f6b4dad9ad8e657a8303c0","size":{"x":32,"y":1,"z":32}},{"blockCount":201,"bytes":2650,"file":"chunks/y001-z128-x256.json","offset":{"x":256,"y":1,"z":128},"requirements":{"minecraft:cobbled_deepslate":52,"minecraft:polished_diorite":18,"minecraft:spruce_planks":1,"minecraft:stone_bricks":130},"sha256":"ec0b756e4b45fe12046718dfaab06482364b36b2c56c12bd12f55e272befb97a","size":{"x":32,"y":1,"z":32}},{"blockCount":5,"bytes":828,"file":"chunks/y001-z128-x288.json","offset":{"x":288,"y":1,"z":128},"requirements":{"minecraft:oak_planks":2,"minecraft:spruce_planks":3},"sha256":"302ed298199ee779a97aced1083d258b10233cb233a5f135571dc7156530e3ff","size":{"x":32,"y":1,"z":32}},{"blockCount":4,"bytes":714,"file":"chunks/y001-z128-x320.json","offset":{"x":320,"y":1,"z":128},"requirements":{"minecraft:bricks":4},"sha256":"f46c8311534d6dd8c7acb6396aca6d570f7d73988be02e3f868d86f0e2be48b8","size":{"x":32,"y":1,"z":32}},{"blockCount":1,"bytes":643,"file":"chunks/y001-z160-x128.json","offset":{"x":128,"y":1,"z":160},"requirements":{"minecraft:stone_bricks":1},"sha256":"4aafb2d0b5a9d92e187f3ca14c361e29f4dfe986eafdb0765de2cf4b3b366586","size":{"x":32,"y":1,"z":32}},{"blockCount":30,"bytes":1662,"file":"chunks/y001-z160-x160.json","offset":{"x":160,"y":1,"z":160},"requirements":{"minecraft:cobbled_deepslate":30},"sha256":"1b98db0c40b1c6863c424cf36884c3b826b3a31e16b2c50ff8abc7cea057e398","size":{"x":32,"y":1,"z":32}},{"blockCount":7,"bytes":867,"file":"chunks/y001-z160-x192.json","offset":{"x":192,"y":1,"z":160},"requirements":{"minecraft:bricks":7},"sha256":"8384c20a6a5a1632f1e5625b5c57ed816bad4ff24acc34e51ad38cff849ff9d0","size":{"x":32,"y":1,"z":32}},{"blockCount":10,"bytes":923,"file":"chunks/y001-z160-x224.json","offset":{"x":224,"y":1,"z":160},"requirements":{"minecraft:bricks":10},"sha256":"e41b761b6e5876f22a7048bc2e43f2b94566f3ef47693b26c8d579bcd2d5febf","size":{"x":32,"y":1,"z":32}},{"blockCount":3,"bytes":723,"file":"chunks/y001-z160-x256.json","offset":{"x":256,"y":1,"z":160},"requirements":{"minecraft:spruce_planks":3},"sha256":"34c747bd16bd848cb490302618fb6db3e8b650155a6b937a80e0cad8be364585","size":{"x":32,"y":1,"z":32}},{"blockCount":2,"bytes":681,"file":"chunks/y001-z160-x320.json","offset":{"x":320,"y":1,"z":160},"requirements":{"minecraft:spruce_planks":2},"sha256":"66b780faf8e62d517b749a2842882aca6f54c15f2320cfb2751842e0dc488af9","size":{"x":32,"y":1,"z":32}},{"blockCount":43,"bytes":1311,"file":"chunks/y001-z192-x160.json","offset":{"x":160,"y":1,"z":192},"requirements":{"minecraft:cobbled_deepslate":43},"sha256":"de28232199a8f5de5e4cd4b9a089767e89bf91d6e346cbb518413104ab404bf4","size":{"x":32,"y":1,"z":32}},{"blockCount":32,"bytes":650,"file":"chunks/y001-z192-x192.json","offset":{"x":192,"y":1,"z":192},"requirements":{"minecraft:cobbled_deepslate":32},"sha256":"c33567f498d9c0c9a60b59f5962a9a322908b1d0eb94a6aa9a0abea421ee5c82","size":{"x":32,"y":1,"z":32}},{"blockCount":19,"bytes":650,"file":"chunks/y001-z192-x224.json","offset":{"x":224,"y":1,"z":192},"requirements":{"minecraft:cobbled_deepslate":19},"sha256":"26b3002bd49ca60b43c1aa7962b618ed040174be70320f86f571f44ee9f922cb","size":{"x":32,"y":1,"z":32}},{"blockCount":3,"bytes":731,"file":"chunks/y001-z224-x384.json","offset":{"x":384,"y":1,"z":224},"requirements":{"minecraft:cobbled_deepslate":2,"minecraft:stone_bricks":1},"sha256":"71cd8e328b644e8f60fb854895848d0b6e43d0e190ffb3ddb3d14154a9aaf8f5","size":{"x":32,"y":1,"z":15}},{"blockCount":26,"bytes":1029,"file":"chunks/y002-z000-x320.json","offset":{"x":320,"y":2,"z":0},"requirements":{"minecraft:sandstone":26},"sha256":"974c1127a638aa8f0fbe655f688a0866e4327e3e9ad8ae60ee328b3239e663a4","size":{"x":32,"y":1,"z":32}},{"blockCount":32,"bytes":640,"file":"chunks/y002-z000-x352.json","offset":{"x":352,"y":2,"z":0},"requirements":{"minecraft:sandstone":32},"sha256":"5b934ec0ae086c7fa41ee4ce808d0453b0aa996837678f8e026d9dcd501c6017","size":{"x":32,"y":1,"z":32}},{"blockCount":14,"bytes":989,"file":"chunks/y002-z000-x384.json","offset":{"x":384,"y":2,"z":0},"requirements":{"minecraft:sandstone":14},"sha256":"87252dd35cbf8919568b166894ac9e54f54c033eb963da76b29b028567a7803d","size":{"x":32,"y":1,"z":32}},{"blockCount":162,"bytes":4270,"file":"chunks/y002-z032-x320.json","offset":{"x":320,"y":2,"z":32},"requirements":{"minecraft:bricks":6,"minecraft:sandstone":7,"minecraft:spruce_planks":139,"minecraft:stone_bricks":10},"sha256":"e929aaad0accb1072c7ea01d4a5a37cc6e4d6f9478306adc394844dff6e53fc3","size":{"x":32,"y":1,"z":32}},{"blockCount":167,"bytes":2647,"file":"chunks/y002-z032-x352.json","offset":{"x":352,"y":2,"z":32},"requirements":{"minecraft:polished_diorite":11,"minecraft:spruce_planks":152,"minecraft:stone_bricks":4},"sha256":"0140d4da4cb6e00830486fd61c6cd1fccfcf01d124fcfebd78c4cd8ab50ab996","size":{"x":32,"y":1,"z":32}},{"blockCount":30,"bytes":1661,"file":"chunks/y002-z032-x384.json","offset":{"x":384,"y":2,"z":32},"requirements":{"minecraft:bricks":4,"minecraft:sandstone":7,"minecraft:spruce_planks":19},"sha256":"7bf458f69c55744b8656b612c055ef6a394ff5684ec195d7ad0c83b615a97274","size":{"x":32,"y":1,"z":32}},{"blockCount":187,"bytes":4955,"file":"chunks/y002-z064-x320.json","offset":{"x":320,"y":2,"z":64},"requirements":{"minecraft:bricks":2,"minecraft:glass":9,"minecraft:sandstone":33,"minecraft:spruce_planks":87,"minecraft:stone_bricks":56},"sha256":"88534b87cff87941237ff06c3cc214c7977576290b027d280ca1ece88ffb93c6","size":{"x":32,"y":1,"z":32}},{"blockCount":90,"bytes":1621,"file":"chunks/y002-z064-x352.json","offset":{"x":352,"y":2,"z":64},"requirements":{"minecraft:sandstone":36,"minecraft:spruce_planks":36,"minecraft:stone_bricks":18},"sha256":"0a4e9e466e9d6638a71aab14922a2010366d94e9073b36f56986b149102ad87c","size":{"x":32,"y":1,"z":32}},{"blockCount":31,"bytes":1642,"file":"chunks/y002-z064-x384.json","offset":{"x":384,"y":2,"z":64},"requirements":{"minecraft:bricks":1,"minecraft:sandstone":21,"minecraft:spruce_planks":9},"sha256":"2eb8f8f7ff94dcf08381b567e6cc81e82d74aad886daf43dc5bec1c7d8fff368","size":{"x":32,"y":1,"z":32}},{"blockCount":22,"bytes":1406,"file":"chunks/y002-z096-x192.json","offset":{"x":192,"y":2,"z":96},"requirements":{"minecraft:bricks":22},"sha256":"d060097f6ccc9a35baa2fd70805578a534ae61a31b3627f43f7afafbd5904e57","size":{"x":32,"y":1,"z":32}},{"blockCount":110,"bytes":1474,"file":"chunks/y002-z096-x224.json","offset":{"x":224,"y":2,"z":96},"requirements":{"minecraft:bricks":14,"minecraft:cobbled_deepslate":20,"minecraft:stone_bricks":76},"sha256":"7c7048abf7cfa68f981c3010bf3a89ef6c8dbf58de7faa1d4673242fa0769244","size":{"x":32,"y":1,"z":32}},{"blockCount":570,"bytes":3295,"file":"chunks/y002-z096-x256.json","offset":{"x":256,"y":2,"z":96},"requirements":{"minecraft:cobbled_deepslate":92,"minecraft:oak_planks":5,"minecraft:polished_diorite":3,"minecraft:spruce_planks":26,"minecraft:stone_bricks":444},"sha256":"d22a93da897714bc504724c094c3eda6800e4e8a557380319fd5eb7d4152943d","size":{"x":32,"y":1,"z":32}},{"blockCount":416,"bytes":2634,"file":"chunks/y002-z096-x288.json","offset":{"x":288,"y":2,"z":96},"requirements":{"minecraft:cobbled_deepslate":160,"minecraft:oak_planks":11,"minecraft:polished_diorite":3,"minecraft:spruce_planks":103,"minecraft:stone_bricks":139},"sha256":"76894a3088a519f56350aa66289ea86db34a9e0ccb2ffa558ce4d5cd1075cffe","size":{"x":32,"y":1,"z":32}},{"blockCount":382,"bytes":4267,"file":"chunks/y002-z096-x320.json","offset":{"x":320,"y":2,"z":96},"requirements":{"minecraft:bricks":7,"minecraft:cobbled_deepslate":1,"minecraft:polished_diorite":7,"minecraft:spruce_planks":241,"minecraft:stone_bricks":126},"sha256":"d1ed8b5b19524b4373aacaf907f1cf19d57c2be5373ff348b791773160a199e0","size":{"x":32,"y":1,"z":32}},{"blockCount":193,"bytes":1202,"file":"chunks/y002-z096-x352.json","offset":{"x":352,"y":2,"z":96},"requirements":{"minecraft:sandstone":1,"minecraft:stone_bricks":192},"sha256":"449bb1aa62e7ea9283341029d4ec02db7f8792b0c20f8dad8b40c4618346d596","size":{"x":32,"y":1,"z":32}},{"blockCount":122,"bytes":2349,"file":"chunks/y002-z128-x160.json","offset":{"x":160,"y":2,"z":128},"requirements":{"minecraft:cobbled_deepslate":21,"minecraft:glass":29,"minecraft:stone_bricks":72},"sha256":"2c385123e496aeda76841786989903133e0b9ee77bc3b7cf2b0a90eba761f2c2","size":{"x":32,"y":1,"z":32}},{"blockCount":233,"bytes":5106,"file":"chunks/y002-z128-x192.json","offset":{"x":192,"y":2,"z":128},"requirements":{"minecraft:bricks":33,"minecraft:cobbled_deepslate":10,"minecraft:glass":67,"minecraft:stone_bricks":123},"sha256":"cf5e6b3712da8776ac96171e7f26e32e1d1d5b0eb53bbccd48d40c6bc5e02f5b","size":{"x":32,"y":1,"z":32}},{"blockCount":412,"bytes":4731,"file":"chunks/y002-z128-x224.json","offset":{"x":224,"y":2,"z":128},"requirements":{"minecraft:bricks":48,"minecraft:cobbled_deepslate":230,"minecraft:polished_diorite":2,"minecraft:spruce_planks":26,"minecraft:stone_bricks":106},"sha256":"d2e74afab02f53d16dc491afb4526d6538f0fde065ae50f91201d5bb189ef792","size":{"x":32,"y":1,"z":32}},{"blockCount":784,"bytes":6019,"file":"chunks/y002-z128-x256.json","offset":{"x":256,"y":2,"z":128},"requirements":{"minecraft:cobbled_deepslate":292,"minecraft:oak_planks":57,"minecraft:polished_diorite":6,"minecraft:spruce_planks":261,"minecraft:stone_bricks":168},"sha256":"447fffc6875defc901fd6897204889ad55158e886c205fba115fde10f9434c4a","size":{"x":32,"y":1,"z":32}},{"blockCount":875,"bytes":7549,"file":"chunks/y002-z128-x288.json","offset":{"x":288,"y":2,"z":128},"requirements":{"minecraft:oak_planks":143,"minecraft:polished_diorite":5,"minecraft:spruce_planks":716,"minecraft:stone_bricks":11},"sha256":"a89522265874fefd561084bbdec2da5ce7eb58acee8ea1bdcf2d563da08753e7","size":{"x":32,"y":1,"z":32}},{"blockCount":861,"bytes":3987,"file":"chunks/y002-z128-x320.json","offset":{"x":320,"y":2,"z":128},"requirements":{"minecraft:bricks":324,"minecraft:glass":1,"minecraft:polished_diorite":16,"minecraft:spruce_planks":472,"minecraft:stone_bricks":48},"sha256":"0b964c6f71c72f8cfba3f2873fad88e99199fbfc38939dcc82793fbdaefc9538","size":{"x":32,"y":1,"z":32}},{"blockCount":30,"bytes":1662,"file":"chunks/y002-z160-x160.json","offset":{"x":160,"y":2,"z":160},"requirements":{"minecraft:cobbled_deepslate":30},"sha256":"42bde6e0b0538b1125b90dfc23c0d86a77f55e1269b332f3bbb4fefa5b1880b5","size":{"x":32,"y":1,"z":32}},{"blockCount":14,"bytes":1046,"file":"chunks/y002-z160-x192.json","offset":{"x":192,"y":2,"z":160},"requirements":{"minecraft:bricks":8,"minecraft:stone_bricks":6},"sha256":"02238039b7e86df8f20dd3ded8a5a16a5778faeeb04ed2d4f3f5645783bb8b9b","size":{"x":32,"y":1,"z":32}},{"blockCount":229,"bytes":1656,"file":"chunks/y002-z160-x224.json","offset":{"x":224,"y":2,"z":160},"requirements":{"minecraft:bricks":3,"minecraft:spruce_planks":220,"minecraft:stone_bricks":6},"sha256":"8974208de09bdbb3b9248681590f0635c3825417526ade13e27b1e9c5de37e3c","size":{"x":32,"y":1,"z":32}},{"blockCount":816,"bytes":2578,"file":"chunks/y002-z160-x256.json","offset":{"x":256,"y":2,"z":160},"requirements":{"minecraft:cobbled_deepslate":152,"minecraft:spruce_planks":664},"sha256":"060be4dab29d9ad6c1093d83f295aa4939fc36af3be965f37b208c632ce62727","size":{"x":32,"y":1,"z":32}},{"blockCount":269,"bytes":2063,"file":"chunks/y002-z160-x288.json","offset":{"x":288,"y":2,"z":160},"requirements":{"minecraft:polished_diorite":5,"minecraft:spruce_planks":257,"minecraft:stone_bricks":7},"sha256":"6539d5ef9dfeb7a485c2d6c3e4edce685baef79fa4609239d3fb1f7bc56cbc91","size":{"x":32,"y":1,"z":32}},{"blockCount":284,"bytes":2132,"file":"chunks/y002-z160-x320.json","offset":{"x":320,"y":2,"z":160},"requirements":{"minecraft:polished_diorite":12,"minecraft:spruce_planks":252,"minecraft:stone_bricks":20},"sha256":"4f7c6f88d77b85173e64dae5db1258fe82803d45b79da34256f8e66390687162","size":{"x":32,"y":1,"z":32}},{"blockCount":43,"bytes":1311,"file":"chunks/y002-z192-x160.json","offset":{"x":160,"y":2,"z":192},"requirements":{"minecraft:cobbled_deepslate":43},"sha256":"0b5e204d48d3b8959a9a431a14d336167bf21cfcaf024d4c5569e470fa763f7c","size":{"x":32,"y":1,"z":32}},{"blockCount":32,"bytes":650,"file":"chunks/y002-z192-x192.json","offset":{"x":192,"y":2,"z":192},"requirements":{"minecraft:cobbled_deepslate":32},"sha256":"7e3d5597f2bf5ee2a45cafd2c31e1463ac202e3e0d5ea3769dbcb6be09c9882c","size":{"x":32,"y":1,"z":32}},{"blockCount":19,"bytes":650,"file":"chunks/y002-z192-x224.json","offset":{"x":224,"y":2,"z":192},"requirements":{"minecraft:cobbled_deepslate":19},"sha256":"82e86538dd3a58d5bd447562db1d81fa50f43b9669c3237a2cb2d8cc59507281","size":{"x":32,"y":1,"z":32}},{"blockCount":475,"bytes":2050,"file":"chunks/y002-z192-x256.json","offset":{"x":256,"y":2,"z":192},"requirements":{"minecraft:spruce_planks":475},"sha256":"624b3d32072db201870dd82a86544d01f4df152963edf68a371c9b0348b16f25","size":{"x":32,"y":1,"z":32}},{"blockCount":109,"bytes":1993,"file":"chunks/y002-z192-x288.json","offset":{"x":288,"y":2,"z":192},"requirements":{"minecraft:spruce_planks":104,"minecraft:stone_bricks":5},"sha256":"02884aef5ede4c534d499ce69fc5e1e3907f6ec1bcd6183a4ced7a96967d42be","size":{"x":32,"y":1,"z":32}},{"blockCount":75,"bytes":805,"file":"chunks/y002-z224-x256.json","offset":{"x":256,"y":2,"z":224},"requirements":{"minecraft:spruce_planks":75},"sha256":"920b530ff4a5b91830219ab2443de3a0775ecc6ac7f84f780a877c03a049bae1","size":{"x":32,"y":1,"z":15}},{"blockCount":15,"bytes":780,"file":"chunks/y002-z224-x288.json","offset":{"x":288,"y":2,"z":224},"requirements":{"minecraft:spruce_planks":15},"sha256":"2f89023a3c71f7a7330ac9019b7ee549da1ce33511d72563a3d642dda13f50d5","size":{"x":32,"y":1,"z":15}},{"blockCount":3,"bytes":723,"file":"chunks/y002-z224-x384.json","offset":{"x":384,"y":2,"z":224},"requirements":{"minecraft:sandstone":2,"minecraft:stone_bricks":1},"sha256":"817e357074d8eaa20756b2e0cd4a08d9f67893c16d1e7dcf623a188ab58c56b0","size":{"x":32,"y":1,"z":15}},{"blockCount":25,"bytes":990,"file":"chunks/y003-z000-x320.json","offset":{"x":320,"y":3,"z":0},"requirements":{"minecraft:sandstone":25},"sha256":"a8f8bb3b1a918daecbc4d9fe123df5e1b7b94de082622f0e8f90d5cb0cf5b512","size":{"x":32,"y":1,"z":32}},{"blockCount":32,"bytes":640,"file":"chunks/y003-z000-x352.json","offset":{"x":352,"y":3,"z":0},"requirements":{"minecraft:sandstone":32},"sha256":"a857f3e61b5002d07c6b4c9b61beef2282968e684b4fabd8f6ba57d0d2803764","size":{"x":32,"y":1,"z":32}},{"blockCount":14,"bytes":989,"file":"chunks/y003-z000-x384.json","offset":{"x":384,"y":3,"z":0},"requirements":{"minecraft:sandstone":14},"sha256":"1f137dfdc6374e239bc29af6853eebe5a77eae0f1146ecb017fbf7df3c3a6794","size":{"x":32,"y":1,"z":32}},{"blockCount":181,"bytes":4519,"file":"chunks/y003-z032-x320.json","offset":{"x":320,"y":3,"z":32},"requirements":{"minecraft:bricks":30,"minecraft:glass":4,"minecraft:sandstone":7,"minecraft:spruce_planks":138,"minecraft:stone_bricks":2},"sha256":"1625de3d1b6cbc9a0692cc8a5832b35e8aa2cce9c582a27c9b19e96e971d1678","size":{"x":32,"y":1,"z":32}},{"blockCount":141,"bytes":2455,"file":"chunks/y003-z032-x352.json","offset":{"x":352,"y":3,"z":32},"requirements":{"minecraft:glass":6,"minecraft:polished_diorite":3,"minecraft:spruce_planks":129,"minecraft:stone_bricks":3},"sha256":"0ac4b82932df916e433a40485a4730921b10144b31d92e7fca6d02f0f5cc8900","size":{"x":32,"y":1,"z":32}},{"blockCount":31,"bytes":1701,"file":"chunks/y003-z032-x384.json","offset":{"x":384,"y":3,"z":32},"requirements":{"minecraft:bricks":4,"minecraft:sandstone":7,"minecraft:spruce_planks":20},"sha256":"5c494042e7967fb8956fa2c41da3f2b49d7112ba50fd3078314d654ad9f50179","size":{"x":32,"y":1,"z":32}},{"blockCount":186,"bytes":4964,"file":"chunks/y003-z064-x320.json","offset":{"x":320,"y":3,"z":64},"requirements":{"minecraft:bricks":27,"minecraft:glass":8,"minecraft:sandstone":32,"minecraft:spruce_planks":86,"minecraft:stone_bricks":33},"sha256":"79290ca6b2a8023cb869ba1c080eda78cabf31b03374ed7f28d7cc7e06c7e193","size":{"x":32,"y":1,"z":32}},{"blockCount":188,"bytes":3606,"file":"chunks/y003-z064-x352.json","offset":{"x":352,"y":3,"z":64},"requirements":{"minecraft:glass":15,"minecraft:polished_diorite":54,"minecraft:sandstone":34,"minecraft:spruce_planks":20,"minecraft:stone_bricks":65},"sha256":"416bba2d9d8d1c08032227ceed9caba0aa7e628d46d04c9d98ef33c9ab8e0706","size":{"x":32,"y":1,"z":32}},{"blockCount":35,"bytes":1751,"file":"chunks/y003-z064-x384.json","offset":{"x":384,"y":3,"z":64},"requirements":{"minecraft:bricks":1,"minecraft:polished_diorite":4,"minecraft:sandstone":21,"minecraft:spruce_planks":9},"sha256":"cf390f91b724b4ece5a2ac900e31b86d85ffc344d0d4efdc929da4c8ca929a5a","size":{"x":32,"y":1,"z":32}},{"blockCount":17,"bytes":1213,"file":"chunks/y003-z096-x192.json","offset":{"x":192,"y":3,"z":96},"requirements":{"minecraft:bricks":17},"sha256":"e1f2989644ee867679afc61b326981e7aaf6fe79e7b9a47119f03749842cae75","size":{"x":32,"y":1,"z":32}},{"blockCount":40,"bytes":1664,"file":"chunks/y003-z096-x224.json","offset":{"x":224,"y":3,"z":96},"requirements":{"minecraft:bricks":24,"minecraft:spruce_planks":16},"sha256":"0a394ee84abf7b8071671eadd66d30083919cc5ecf2cc3bca111a930d6441780","size":{"x":32,"y":1,"z":32}},{"blockCount":162,"bytes":3416,"file":"chunks/y003-z096-x256.json","offset":{"x":256,"y":3,"z":96},"requirements":{"minecraft:cobbled_deepslate":16,"minecraft:polished_diorite":39,"minecraft:spruce_planks":85,"minecraft:stone_bricks":22},"sha256":"dce88f4fdb479af438a1236df2bee7a71a7d942bc57d1b103f4cf18372298376","size":{"x":32,"y":1,"z":32}},{"blockCount":151,"bytes":3183,"file":"chunks/y003-z096-x288.json","offset":{"x":288,"y":3,"z":96},"requirements":{"minecraft:cobbled_deepslate":52,"minecraft:glass":2,"minecraft:oak_planks":4,"minecraft:polished_diorite":22,"minecraft:spruce_planks":66,"minecraft:stone_bricks":5},"sha256":"364cfa2213a78e9819f851980595fcffbf1200ff4573a6a4b582077965888354","size":{"x":32,"y":1,"z":32}},{"blockCount":143,"bytes":4184,"file":"chunks/y003-z096-x320.json","offset":{"x":320,"y":3,"z":96},"requirements":{"minecraft:bricks":11,"minecraft:cobbled_deepslate":1,"minecraft:glass":4,"minecraft:polished_diorite":2,"minecraft:spruce_planks":75,"minecraft:stone_bricks":50},"sha256":"f645b2e0000a6ad1798696245c2afd0892c7b5ad87bffc4b7e9e5914b5e72e7f","size":{"x":32,"y":1,"z":32}},{"blockCount":268,"bytes":2651,"file":"chunks/y003-z096-x352.json","offset":{"x":352,"y":3,"z":96},"requirements":{"minecraft:polished_diorite":41,"minecraft:stone_bricks":227},"sha256":"ebb0b30ef1f72b0f849cf6eb0c813478e4dbe6c5ff3aaaec93a9ed29bcf1af46","size":{"x":32,"y":1,"z":32}},{"blockCount":1,"bytes":626,"file":"chunks/y003-z096-x384.json","offset":{"x":384,"y":3,"z":96},"requirements":{"minecraft:polished_diorite":1},"sha256":"228dfd527c46c3fbb57c46ff4f635ac1e3ece87aeaff23b18ff6e1008fcce3cb","size":{"x":32,"y":1,"z":32}},{"blockCount":85,"bytes":2254,"file":"chunks/y003-z128-x160.json","offset":{"x":160,"y":3,"z":128},"requirements":{"minecraft:cobbled_deepslate":21,"minecraft:glass":25,"minecraft:stone_bricks":39},"sha256":"e194631a2636842986171db702cd040b118c213b8540d3a16479d9f9df5c628b","size":{"x":32,"y":1,"z":32}},{"blockCount":143,"bytes":4511,"file":"chunks/y003-z128-x192.json","offset":{"x":192,"y":3,"z":128},"requirements":{"minecraft:bricks":19,"minecraft:cobbled_deepslate":10,"minecraft:glass":63,"minecraft:stone_bricks":51},"sha256":"d02d7eb09516eb8e4fc951f01f1e61f126a03fe1958edc284472bd6fd5dded35","size":{"x":32,"y":1,"z":32}},{"blockCount":180,"bytes":4166,"file":"chunks/y003-z128-x224.json","offset":{"x":224,"y":3,"z":128},"requirements":{"minecraft:bricks":14,"minecraft:cobbled_deepslate":16,"minecraft:polished_diorite":4,"minecraft:spruce_planks":63,"minecraft:stone_bricks":83},"sha256":"243bf0c86b2f4c45f244039952693f646bbc04402ddcc79511732fc4f1cf9724","size":{"x":32,"y":1,"z":32}},{"blockCount":274,"bytes":5343,"file":"chunks/y003-z128-x256.json","offset":{"x":256,"y":3,"z":128},"requirements":{"minecraft:bricks":9,"minecraft:cobbled_deepslate":60,"minecraft:glass":6,"minecraft:polished_diorite":9,"minecraft:spruce_planks":119,"minecraft:stone_bricks":71},"sha256":"c93c6ade37683d9e872dd7cec2f880e7e1c587cd68315b10ae49cda38df8c7d2","size":{"x":32,"y":1,"z":32}},{"blockCount":188,"bytes":4971,"file":"chunks/y003-z128-x288.json","offset":{"x":288,"y":3,"z":128},"requirements":{"minecraft:cobbled_deepslate":36,"minecraft:glass":12,"minecraft:oak_planks":4,"minecraft:polished_diorite":2,"minecraft:spruce_planks":130,"minecraft:stone_bricks":4},"sha256":"b48cf3358cb0bf5a6776e339f9798a02692bb53f0711521237d7bb9adec684d4","size":{"x":32,"y":1,"z":32}},{"blockCount":246,"bytes":4669,"file":"chunks/y003-z128-x320.json","offset":{"x":320,"y":3,"z":128},"requirements":{"minecraft:oak_planks":47,"minecraft:polished_diorite":18,"minecraft:spruce_planks":171,"minecraft:stone_bricks":10},"sha256":"11a7aa1d722915d245e8472638ef6a7940c57fb97137dbab3042b13756077456","size":{"x":32,"y":1,"z":32}},{"blockCount":30,"bytes":1662,"file":"chunks/y003-z160-x160.json","offset":{"x":160,"y":3,"z":160},"requirements":{"minecraft:cobbled_deepslate":30},"sha256":"eaec228a6ec93b482128110cc5b9234a30aeb82497cf819dbf7f8ef1704872ce","size":{"x":32,"y":1,"z":32}},{"blockCount":2,"bytes":675,"file":"chunks/y003-z160-x192.json","offset":{"x":192,"y":3,"z":160},"requirements":{"minecraft:bricks":2},"sha256":"d61ff1031d0b346e58815db31dc5215d94780b2b0babaa45a912f7705c02eb76","size":{"x":32,"y":1,"z":32}},{"blockCount":54,"bytes":1841,"file":"chunks/y003-z160-x224.json","offset":{"x":224,"y":3,"z":160},"requirements":{"minecraft:bricks":3,"minecraft:spruce_planks":51},"sha256":"f89499821711e97cc2a62457439539b6a6e58b2dcae7811ffc726be9def552c7","size":{"x":32,"y":1,"z":32}},{"blockCount":205,"bytes":3897,"file":"chunks/y003-z160-x256.json","offset":{"x":256,"y":3,"z":160},"requirements":{"minecraft:spruce_planks":205},"sha256":"d9e63755c118a204df063b9a03c6a388516097a65d8d5bfea1b162949d309d02","size":{"x":32,"y":1,"z":32}},{"blockCount":63,"bytes":2089,"file":"chunks/y003-z160-x288.json","offset":{"x":288,"y":3,"z":160},"requirements":{"minecraft:bricks":2,"minecraft:spruce_planks":59,"minecraft:stone_bricks":2},"sha256":"95c48de25ef253e9f53bcf1b31d9660ce17cfb5bf219fd12c742a516bfae6af3","size":{"x":32,"y":1,"z":32}},{"blockCount":156,"bytes":3167,"file":"chunks/y003-z160-x320.json","offset":{"x":320,"y":3,"z":160},"requirements":{"minecraft:polished_diorite":51,"minecraft:spruce_planks":48,"minecraft:stone_bricks":57},"sha256":"185a1e6c0678d21075df081452353591c9100c8bdf3cc71f1fa602569b61e833","size":{"x":32,"y":1,"z":32}},{"blockCount":43,"bytes":1311,"file":"chunks/y003-z192-x160.json","offset":{"x":160,"y":3,"z":192},"requirements":{"minecraft:cobbled_deepslate":43},"sha256":"6e6893d0925089ad3499b591ce6b95d00463e2f2ebae2cf0b80d852599b1fb52","size":{"x":32,"y":1,"z":32}},{"blockCount":32,"bytes":650,"file":"chunks/y003-z192-x192.json","offset":{"x":192,"y":3,"z":192},"requirements":{"minecraft:cobbled_deepslate":32},"sha256":"ad92d129d6241a46a4d7a78a3fab81227fb7bc7306887d42adbf45adf1ea2d68","size":{"x":32,"y":1,"z":32}},{"blockCount":19,"bytes":650,"file":"chunks/y003-z192-x224.json","offset":{"x":224,"y":3,"z":192},"requirements":{"minecraft:cobbled_deepslate":19},"sha256":"accc3f36e1dab05f74df2c32eb734adaba70b0bb650e84e6d9be2da2d42b370b","size":{"x":32,"y":1,"z":32}},{"blockCount":294,"bytes":2752,"file":"chunks/y003-z192-x256.json","offset":{"x":256,"y":3,"z":192},"requirements":{"minecraft:oak_planks":245,"minecraft:polished_diorite":5,"minecraft:spruce_planks":29,"minecraft:stone_bricks":15},"sha256":"ac19b6b140113638999528afcc68d5b789187a77caa21dcc5eb38141628257d3","size":{"x":32,"y":1,"z":32}},{"blockCount":68,"bytes":2034,"file":"chunks/y003-z192-x288.json","offset":{"x":288,"y":3,"z":192},"requirements":{"minecraft:glass":4,"minecraft:oak_planks":41,"minecraft:polished_diorite":1,"minecraft:sandstone":4,"minecraft:spruce_planks":15,"minecraft:stone_bricks":3},"sha256":"b99fb30b13cf46f232de833bc5873aaef005cd5e228389bd2acae44a443c4b86","size":{"x":32,"y":1,"z":32}},{"blockCount":3,"bytes":728,"file":"chunks/y003-z224-x384.json","offset":{"x":384,"y":3,"z":224},"requirements":{"minecraft:cobbled_deepslate":2,"minecraft:sandstone":1},"sha256":"e81b568a004fdd66dbfb1f705e79c25d5b041009237786cc69251c93408f002a","size":{"x":32,"y":1,"z":15}},{"blockCount":25,"bytes":990,"file":"chunks/y004-z000-x320.json","offset":{"x":320,"y":4,"z":0},"requirements":{"minecraft:sandstone":25},"sha256":"a8c6005a898dfe297f7ab27629a151af651f9401764df72f6505e8a6b56cc150","size":{"x":32,"y":1,"z":32}},{"blockCount":32,"bytes":640,"file":"chunks/y004-z000-x352.json","offset":{"x":352,"y":4,"z":0},"requirements":{"minecraft:sandstone":32},"sha256":"3efbf15fdd2e0eb655668dfe42bfdf496a21a72e8a26e734cbb2b62add02e5f1","size":{"x":32,"y":1,"z":32}},{"blockCount":14,"bytes":989,"file":"chunks/y004-z000-x384.json","offset":{"x":384,"y":4,"z":0},"requirements":{"minecraft:sandstone":14},"sha256":"8828a3c7e71772b2b26def0c9ac060453ab359940fdac66cae7ce799496d7a95","size":{"x":32,"y":1,"z":32}},{"blockCount":120,"bytes":3887,"file":"chunks/y004-z032-x320.json","offset":{"x":320,"y":4,"z":32},"requirements":{"minecraft:glass":8,"minecraft:sandstone":7,"minecraft:spruce_planks":105},"sha256":"899bee5617e3bc7c41a4eca524c6b868c8d6ffe085c951d62522a7807b44f6a9","size":{"x":32,"y":1,"z":32}},{"blockCount":83,"bytes":2550,"file":"chunks/y004-z032-x352.json","offset":{"x":352,"y":4,"z":32},"requirements":{"minecraft:glass":18,"minecraft:oak_planks":1,"minecraft:polished_diorite":7,"minecraft:spruce_planks":57},"sha256":"f9ef57f280409e37fe6a19a887f2ac87a295c7ef732dba0541892157e6dad005","size":{"x":32,"y":1,"z":32}},{"blockCount":620,"bytes":2874,"file":"chunks/y004-z032-x384.json","offset":{"x":384,"y":4,"z":32},"requirements":{"minecraft:bricks":4,"minecraft:sandstone":7,"minecraft:spruce_planks":36,"minecraft:stone_bricks":573},"sha256":"b2aacd1f6a83c1081489896534194bda848364571a32964e1127b60087d88ed3","size":{"x":32,"y":1,"z":32}},{"blockCount":133,"bytes":4079,"file":"chunks/y004-z064-x320.json","offset":{"x":320,"y":4,"z":64},"requirements":{"minecraft:sandstone":32,"minecraft:spruce_planks":85,"minecraft:stone_bricks":16},"sha256":"53f244ccbd9c4e225d77c81beafda15fd99bda655a6b9243a1adb69a77028817","size":{"x":32,"y":1,"z":32}},{"blockCount":113,"bytes":2029,"file":"chunks/y004-z064-x352.json","offset":{"x":352,"y":4,"z":64},"requirements":{"minecraft:cobbled_deepslate":26,"minecraft:oak_planks":1,"minecraft:polished_diorite":1,"minecraft:sandstone":36,"minecraft:spruce_planks":28,"minecraft:stone_bricks":21},"sha256":"570b97bcab2af740f5c1b81e851e4049c0e19d2cb0e87a05cf337d8d2a16071e","size":{"x":32,"y":1,"z":32}},{"blockCount":183,"bytes":2098,"file":"chunks/y004-z064-x384.json","offset":{"x":384,"y":4,"z":64},"requirements":{"minecraft:cobbled_deepslate":2,"minecraft:polished_diorite":6,"minecraft:sandstone":21,"minecraft:spruce_planks":11,"minecraft:stone_bricks":143},"sha256":"291a033fbf4c023839b74ab4227fe9068ac8ff5e608d6d58bc5730fb35e4e0d8","size":{"x":32,"y":1,"z":32}},{"blockCount":15,"bytes":1177,"file":"chunks/y004-z096-x192.json","offset":{"x":192,"y":4,"z":96},"requirements":{"minecraft:bricks":15},"sha256":"937bf6d7ba457ffbbc071d2834280dbf4cf4b24ab5ab6555aad6ccfc8a1007ec","size":{"x":32,"y":1,"z":32}},{"blockCount":36,"bytes":1625,"file":"chunks/y004-z096-x224.json","offset":{"x":224,"y":4,"z":96},"requirements":{"minecraft:bricks":18,"minecraft:spruce_planks":18},"sha256":"b5e487493f068399538b05589f3c2a5ec2c1fdc69b503abea5d67dc9bd0e39d8","size":{"x":32,"y":1,"z":32}}],"schema":1}
