{"entries":[{"blockCount":123,"bytes":3151,"file":"chunks/y004-z096-x256.json","offset":{"x":256,"y":4,"z":96},"requirements":{"minecraft:cobbled_deepslate":23,"minecraft:polished_diorite":4,"minecraft:spruce_planks":68,"minecraft:stone_bricks":28},"sha256":"098c1577f29a1257fa0bb4ad71643bf567531dea6354120656421f672fdca253","size":{"x":32,"y":1,"z":32}},{"blockCount":135,"bytes":3086,"file":"chunks/y004-z096-x288.json","offset":{"x":288,"y":4,"z":96},"requirements":{"minecraft:cobbled_deepslate":50,"minecraft:oak_planks":5,"minecraft:polished_diorite":2,"minecraft:spruce_planks":68,"minecraft:stone_bricks":10},"sha256":"9cc31cc60d6b24dcac66d4b35547692746b89e57d65155d57e2f8c92b5563ee6","size":{"x":32,"y":1,"z":32}},{"blockCount":184,"bytes":4301,"file":"chunks/y004-z096-x320.json","offset":{"x":320,"y":4,"z":96},"requirements":{"minecraft:bricks":3,"minecraft:cobbled_deepslate":40,"minecraft:glass":2,"minecraft:polished_diorite":3,"minecraft:spruce_planks":80,"minecraft:stone_bricks":56},"sha256":"875559df0cd28a863be0ace0327da5c320521f2a830f4cf91ec570ff6def698f","size":{"x":32,"y":1,"z":32}},{"blockCount":668,"bytes":3665,"file":"chunks/y004-z096-x352.json","offset":{"x":352,"y":4,"z":96},"requirements":{"minecraft:cobbled_deepslate":308,"minecraft:polished_diorite":3,"minecraft:sandstone":2,"minecraft:spruce_planks":1,"minecraft:stone_bricks":354},"sha256":"82ca3abe7d2347be815f025caf6cc7e8df2e6158e4262c448f53091f1df4463d","size":{"x":32,"y":1,"z":32}},{"blockCount":6,"bytes":735,"file":"chunks/y004-z096-x384.json","offset":{"x":384,"y":4,"z":96},"requirements":{"minecraft:cobbled_deepslate":2,"minecraft:polished_diorite":4},"sha256":"79105af60e5fc1126931cb199d2bf7b5165d2e996abb48f51bf21a63ba7039a5","size":{"x":32,"y":1,"z":32}},{"blockCount":60,"bytes":1340,"file":"chunks/y004-z128-x160.json","offset":{"x":160,"y":4,"z":128},"requirements":{"minecraft:cobbled_deepslate":21,"minecraft:stone_bricks":39},"sha256":"f089445d1d610caa6053e7691795f683d1c27ad824c8ee8d1b4b59550cae0a48","size":{"x":32,"y":1,"z":32}},{"blockCount":81,"bytes":2173,"file":"chunks/y004-z128-x192.json","offset":{"x":192,"y":4,"z":128},"requirements":{"minecraft:bricks":18,"minecraft:cobbled_deepslate":10,"minecraft:stone_bricks":53},"sha256":"42e01ae6e3e970c561fd895070e4b4e8217ed57f065d6288911a2236146670de","size":{"x":32,"y":1,"z":32}},{"blockCount":141,"bytes":4232,"file":"chunks/y004-z128-x224.json","offset":{"x":224,"y":4,"z":128},"requirements":{"minecraft:bricks":20,"minecraft:polished_diorite":2,"minecraft:spruce_planks":65,"minecraft:stone_bricks":54},"sha256":"f5b9b3ad97060ea1705af2ce97fab7b93d15e7e0bc0829d6e75067bfb1591f1f","size":{"x":32,"y":1,"z":32}},{"blockCount":201,"bytes":4510,"file":"chunks/y004-z128-x256.json","offset":{"x":256,"y":4,"z":128},"requirements":{"minecraft:bricks":12,"minecraft:cobbled_deepslate":6,"minecraft:glass":3,"minecraft:polished_diorite":6,"minecraft:spruce_planks":114,"minecraft:stone_bricks":60},"sha256":"06b149a7d6001bc8fcaa35acfa84377953e42b5c9f5fa8900104bb819ab44083","size":{"x":32,"y":1,"z":32}},{"blockCount":129,"bytes":4203,"file":"chunks/y004-z128-x288.json","offset":{"x":288,"y":4,"z":128},"requirements":{"minecraft:cobbled_deepslate":6,"minecraft:glass":9,"minecraft:oak_planks":6,"minecraft:polished_diorite":2,"minecraft:spruce_planks":106},"sha256":"5309324da8329249ff67649926bc2501634db9144d325084b828906f06ba43fb","size":{"x":32,"y":1,"z":32}},{"blockCount":186,"bytes":4471,"file":"chunks/y004-z128-x320.json","offset":{"x":320,"y":4,"z":128},"requirements":{"minecraft:cobbled_deepslate":74,"minecraft:polished_diorite":18,"minecraft:spruce_planks":63,"minecraft:stone_bricks":31},"sha256":"e26403d0e358d29cb51964bc883b0e8121d04ffdc06bcd1bafc30a5694fbdfe5","size":{"x":32,"y":1,"z":32}},{"blockCount":923,"bytes":8213,"file":"chunks/y004-z128-x352.json","offset":{"x":352,"y":4,"z":128},"requirements":{"minecraft:bricks":38,"minecraft:cobbled_deepslate":568,"minecraft:stone_bricks":317},"sha256":"45db232cb84c206672723940ccac2aface1742e8c2b208f90db57cb74068ca32","size":{"x":32,"y":1,"z":32}},{"blockCount":30,"bytes":1662,"file":"chunks/y004-z160-x160.json","offset":{"x":160,"y":4,"z":160},"requirements":{"minecraft:cobbled_deepslate":30},"sha256":"4859a9d88b383b51234db0c3d4144a7874e088d0e65f45ce28d40fa1a709c29b","size":{"x":32,"y":1,"z":32}},{"blockCount":4,"bytes":713,"file":"chunks/y004-z160-x192.json","offset":{"x":192,"y":4,"z":160},"requirements":{"minecraft:bricks":4},"sha256":"6c02d249f2cfe26745d10515081bbfc723f4a2bd28c4b48a48ae6d264b085dc2","size":{"x":32,"y":1,"z":32}},{"blockCount":60,"bytes":2031,"file":"chunks/y004-z160-x224.json","offset":{"x":224,"y":4,"z":160},"requirements":{"minecraft:bricks":6,"minecraft:spruce_planks":54},"sha256":"54d821d225837d66f6681dc3e2536588202d0f75288eefdace3f55c0b5ac922d","size":{"x":32,"y":1,"z":32}},{"blockCount":220,"bytes":4220,"file":"chunks/y004-z160-x256.json","offset":{"x":256,"y":4,"z":160},"requirements":{"minecraft:glass":4,"minecraft:spruce_planks":216},"sha256":"5734ed20365b53bbcc56d8d5e7f61c2c7ccf5b645ac06714c1b461d99cb9c373","size":{"x":32,"y":1,"z":32}},{"blockCount":62,"bytes":2054,"file":"chunks/y004-z160-x288.json","offset":{"x":288,"y":4,"z":160},"requirements":{"minecraft:oak_planks":2,"minecraft:spruce_planks":58,"minecraft:stone_bricks":2},"sha256":"eb5b288f9f96e4547f2c29c9874db2883b96ffa942bdbc27fe5c987c5f3179a8","size":{"x":32,"y":1,"z":32}},{"blockCount":356,"bytes":3793,"file":"chunks/y004-z160-x320.json","offset":{"x":320,"y":4,"z":160},"requirements":{"minecraft:cobbled_deepslate":39,"minecraft:glass":14,"minecraft:sandstone":16,"minecraft:spruce_planks":72,"minecraft:stone_bricks":215},"sha256":"3ccf7b80e0401697e3702da1712928f5cebbe72779590de7d77b00140925046c","size":{"x":32,"y":1,"z":32}},{"blockCount":910,"bytes":2722,"file":"chunks/y004-z160-x352.json","offset":{"x":352,"y":4,"z":160},"requirements":{"minecraft:cobbled_deepslate":378,"minecraft:glass":22,"minecraft:stone_bricks":510},"sha256":"6671a73a05b5f1a452fec47ed24598213b03688beb2b1ddb4eb31897c1cc7b50","size":{"x":32,"y":1,"z":32}},{"blockCount":43,"bytes":1311,"file":"chunks/y004-z192-x160.json","offset":{"x":160,"y":4,"z":192},"requirements":{"minecraft:cobbled_deepslate":43},"sha256":"9eaebdd5cdb3936de71c65fd472e69556bd34f97e4a46ed0878b54af1c2de7dc","size":{"x":32,"y":1,"z":32}},{"blockCount":32,"bytes":650,"file":"chunks/y004-z192-x192.json","offset":{"x":192,"y":4,"z":192},"requirements":{"minecraft:cobbled_deepslate":32},"sha256":"810e810c636d6a428dab1a958fe13e4d7d543de8c41547d62cae3c7211f002c6","size":{"x":32,"y":1,"z":32}},{"blockCount":19,"bytes":650,"file":"chunks/y004-z192-x224.json","offset":{"x":224,"y":4,"z":192},"requirements":{"minecraft:cobbled_deepslate":19},"sha256":"39f5e422eb3b7421911eed1103bb56558540d0c72c8384ac4ac13e76423b8741","size":{"x":32,"y":1,"z":32}},{"blockCount":91,"bytes":2804,"file":"chunks/y004-z192-x256.json","offset":{"x":256,"y":4,"z":192},"requirements":{"minecraft:cobbled_deepslate":12,"minecraft:oak_planks":4,"minecraft:polished_diorite":12,"minecraft:spruce_planks":57,"minecraft:stone_bricks":6},"sha256":"3ff258de6f6641511da488fc3f9ec7d0ef4499e7d3b1b2e38d05c15087a0a572","size":{"x":32,"y":1,"z":32}},{"blockCount":43,"bytes":1808,"file":"chunks/y004-z192-x288.json","offset":{"x":288,"y":4,"z":192},"requirements":{"minecraft:glass":1,"minecraft:polished_diorite":4,"minecraft:sandstone":6,"minecraft:spruce_planks":32},"sha256":"98b1cc95187bad4f6499ed5f7672b0298624d8ed8c361e0ae775ce91b7e2c969","size":{"x":32,"y":1,"z":32}},{"blockCount":384,"bytes":2477,"file":"chunks/y004-z192-x320.json","offset":{"x":320,"y":4,"z":192},"requirements":{"minecraft:glass":16,"minecraft:stone_bricks":368},"sha256":"a0eafa4c27a5c0d73570484a1d9259aa00786226b3ba4aae40c7836091477c8f","size":{"x":32,"y":1,"z":32}},{"blockCount":896,"bytes":2461,"file":"chunks/y004-z192-x352.json","offset":{"x":352,"y":4,"z":192},"requirements":{"minecraft:glass":16,"minecraft:stone_bricks":880},"sha256":"efd0d7f6cca6127043aa897236b84d1a082dcce48bf84cba257c15f9bc2f929f","size":{"x":32,"y":1,"z":32}},{"blockCount":32,"bytes":914,"file":"chunks/y004-z224-x320.json","offset":{"x":320,"y":4,"z":224},"requirements":{"minecraft:glass":5,"minecraft:stone_bricks":27},"sha256":"72fb282491f6cd76992a22f757b772aac384b6bdb9c4787457ab0a4e4187297b","size":{"x":32,"y":1,"z":15}},{"blockCount":81,"bytes":1217,"file":"chunks/y004-z224-x352.json","offset":{"x":352,"y":4,"z":224},"requirements":{"minecraft:glass":13,"minecraft:stone_bricks":68},"sha256":"cd62c42777a5ce4eeba41911f8f5d84020800540607b9b13073b633852e339bb","size":{"x":32,"y":1,"z":15}},{"blockCount":2,"bytes":677,"file":"chunks/y004-z224-x384.json","offset":{"x":384,"y":4,"z":224},"requirements":{"minecraft:sandstone":2},"sha256":"c6fcd736ae6222839e62ba0b1e4fdcb95fb71d1e720c5728c714cee97e5384b2","size":{"x":32,"y":1,"z":15}},{"blockCount":25,"bytes":990,"file":"chunks/y005-z000-x320.json","offset":{"x":320,"y":5,"z":0},"requirements":{"minecraft:sandstone":25},"sha256":"fcccc2c0b97a55a2d3d6e7759cdd07aefad2e1e4407f0836d390286bf5b81725","size":{"x":32,"y":1,"z":32}},{"blockCount":32,"bytes":640,"file":"chunks/y005-z000-x352.json","offset":{"x":352,"y":5,"z":0},"requirements":{"minecraft:sandstone":32},"sha256":"db123e869dbc75bafa16a7da47c6f5c9cd01e4ae73adf2d74f7aef21cae1bb42","size":{"x":32,"y":1,"z":32}},{"blockCount":14,"bytes":989,"file":"chunks/y005-z000-x384.json","offset":{"x":384,"y":5,"z":0},"requirements":{"minecraft:sandstone":14},"sha256":"76d3d9934c23b5f2ed0ff7382979ebf7841bef1d2f43e1b619f43ee8f3e7de2b","size":{"x":32,"y":1,"z":32}},{"blockCount":117,"bytes":4229,"file":"chunks/y005-z032-x320.json","offset":{"x":320,"y":5,"z":32},"requirements":{"minecraft:bricks":65,"minecraft:glass":10,"minecraft:sandstone":7,"minecraft:spruce_planks":35},"sha256":"ec0dc10c4c92bbc782d09d2e43393cdbc04ed9891c2faf25f8ff44319cb99e04","size":{"x":32,"y":1,"z":32}},{"blockCount":77,"bytes":2611,"file":"chunks/y005-z032-x352.json","offset":{"x":352,"y":5,"z":32},"requirements":{"minecraft:bricks":6,"minecraft:glass":27,"minecraft:oak_planks":1,"minecraft:polished_diorite":9,"minecraft:spruce_planks":34},"sha256":"85f088f5eedf28faf0a8b50b3c65eb536a9defdf4cf4b0300b0fde635acba6cf","size":{"x":32,"y":1,"z":32}},{"blockCount":250,"bytes":4434,"file":"chunks/y005-z032-x384.json","offset":{"x":384,"y":5,"z":32},"requirements":{"minecraft:bricks":17,"minecraft:sandstone":7,"minecraft:spruce_planks":33,"minecraft:stone_bricks":193},"sha256":"b9ce42fffd39b912bf56276823a9a7c49575ceb3243ee73dc2a3334c1066bdd7","size":{"x":32,"y":1,"z":32}},{"blockCount":288,"bytes":1052,"file":"chunks/y005-z064-x096.json","offset":{"x":96,"y":5,"z":64},"requirements":{"minecraft:stone_bricks":288},"sha256":"85082e3101b2b88917a70ef0c205dd66c518b3730b3e82844830ec3b3b154592","size":{"x":32,"y":1,"z":32}},{"blockCount":108,"bytes":1072,"file":"chunks/y005-z064-x128.json","offset":{"x":128,"y":5,"z":64},"requirements":{"minecraft:stone_bricks":108},"sha256":"16c49aacfaf6d2253532e51ab1e9bc7cfb7c0877b83b3b38a78cbbcc224d2bbd","size":{"x":32,"y":1,"z":32}},{"blockCount":128,"bytes":4196,"file":"chunks/y005-z064-x320.json","offset":{"x":320,"y":5,"z":64},"requirements":{"minecraft:bricks":58,"minecraft:sandstone":32,"minecraft:spruce_planks":22,"minecraft:stone_bricks":16},"sha256":"51905f7bcb26ba954dd25d0f82090e5436e010efbf38b9beaad4f4bdf1104d49","size":{"x":32,"y":1,"z":32}},{"blockCount":100,"bytes":1651,"file":"chunks/y005-z064-x352.json","offset":{"x":352,"y":5,"z":64},"requirements":{"minecraft:bricks":6,"minecraft:cobbled_deepslate":26,"minecraft:oak_planks":2,"minecraft:polished_diorite":1,"minecraft:sandstone":34,"minecraft:spruce_planks":20,"minecraft:stone_bricks":11},"sha256":"3eca3c3a18ec9cf5eb7ac74b31c5442982ed888646a975694dc10d608d715fa8","size":{"x":32,"y":1,"z":32}},{"blockCount":91,"bytes":2250,"file":"chunks/y005-z064-x384.json","offset":{"x":384,"y":5,"z":64},"requirements":{"minecraft:bricks":9,"minecraft:cobbled_deepslate":2,"minecraft:polished_diorite":7,"minecraft:sandstone":21,"minecraft:spruce_planks":3,"minecraft:stone_bricks":49},"sha256":"03ba5309833a9d02018a310a13e5e45a14105d4347697e669a5cd52f330f4504","size":{"x":32,"y":1,"z":32}},{"blockCount":221,"bytes":1070,"file":"chunks/y005-z096-x096.json","offset":{"x":96,"y":5,"z":96},"requirements":{"minecraft:stone_bricks":221},"sha256":"2682e36f1594e25d7b450b82dc57cc79a63c4f5f639b099d1111376d638bbb88","size":{"x":32,"y":1,"z":32}},{"blockCount":82,"bytes":973,"file":"chunks/y005-z096-x128.json","offset":{"x":128,"y":5,"z":96},"requirements":{"minecraft:stone_bricks":82},"sha256":"7b98f1a30bad4ecc2f9544947b410f36c3ad9d794b234f01733fe600aee3702f","size":{"x":32,"y":1,"z":32}},{"blockCount":20,"bytes":1289,"file":"chunks/y005-z096-x192.json","offset":{"x":192,"y":5,"z":96},"requirements":{"minecraft:bricks":20},"sha256":"4eeb3382f501491f6fe3a52d2cf2d00acd231c2fc0594a946115164581e15150","size":{"x":32,"y":1,"z":32}},{"blockCount":14,"bytes":1099,"file":"chunks/y005-z096-x224.json","offset":{"x":224,"y":5,"z":96},"requirements":{"minecraft:bricks":14},"sha256":"d765ff3be462e2f988be4be343f2c4052b1210917a75826884abe099fbdaf783","size":{"x":32,"y":1,"z":32}},{"blockCount":57,"bytes":2089,"file":"chunks/y005-z096-x256.json","offset":{"x":256,"y":5,"z":96},"requirements":{"minecraft:cobbled_deepslate":11,"minecraft:glass":6,"minecraft:spruce_planks":16,"minecraft:stone_bricks":24},"sha256":"9f0c8414efa5c8097a96415c721e40d2fa99970dc42dd41871175f34d21fce1a","size":{"x":32,"y":1,"z":32}},{"blockCount":81,"bytes":2388,"file":"chunks/y005-z096-x288.json","offset":{"x":288,"y":5,"z":96},"requirements":{"minecraft:bricks":2,"minecraft:cobbled_deepslate":10,"minecraft:glass":6,"minecraft:oak_planks":5,"minecraft:spruce_planks":49,"minecraft:stone_bricks":9},"sha256":"f38ae7e4806c3e4bcaf617a64857d55868677b26ae1aac128d416e2c38781b2a","size":{"x":32,"y":1,"z":32}},{"blockCount":187,"bytes":4685,"file":"chunks/y005-z096-x320.json","offset":{"x":320,"y":5,"z":96},"requirements":{"minecraft:bricks":76,"minecraft:cobbled_deepslate":17,"minecraft:glass":3,"minecraft:polished_diorite":4,"minecraft:sandstone":1,"minecraft:spruce_planks":45,"minecraft:stone_bricks":41},"sha256":"097c5c10725c3e681ebf3c648c111fcd6d6f3df5fb45030e4184218fba059dd9","size":{"x":32,"y":1,"z":32}},{"blockCount":723,"bytes":2424,"file":"chunks/y005-z096-x352.json","offset":{"x":352,"y":5,"z":96},"requirements":{"minecraft:bricks":406,"minecraft:cobbled_deepslate":69,"minecraft:oak_planks":1,"minecraft:polished_diorite":3,"minecraft:sandstone":4,"minecraft:spruce_planks":1,"minecraft:stone_bricks":239},"sha256":"1b4de8b29c1dfe3fc1e7d7a99a3df443168ab58f95688c7a4fa6e9a470fe6b26","size":{"x":32,"y":1,"z":32}},{"blockCount":9,"bytes":800,"file":"chunks/y005-z096-x384.json","offset":{"x":384,"y":5,"z":96},"requirements":{"minecraft:cobbled_deepslate":2,"minecraft:polished_diorite":6,"minecraft:stone_bricks":1},"sha256":"7b04c2b5bb837b82067de9ac0bf350009afee6a3415a74443e6d482513d0f589","size":{"x":32,"y":1,"z":32}},{"blockCount":60,"bytes":1340,"file":"chunks/y005-z128-x160.json","offset":{"x":160,"y":5,"z":128},"requirements":{"minecraft:cobbled_deepslate":21,"minecraft:stone_bricks":39},"sha256":"ac479459a60a6362a1007a2cdb101ed36ca42a487eb681320bbad01b23b3c4ce","size":{"x":32,"y":1,"z":32}},{"blockCount":78,"bytes":2043,"file":"chunks/y005-z128-x192.json","offset":{"x":192,"y":5,"z":128},"requirements":{"minecraft:bricks":13,"minecraft:cobbled_deepslate":10,"minecraft:stone_bricks":55},"sha256":"184cff178683483e57294be1b1a96d0787b95e908b694ee3a53c251684b35a7d","size":{"x":32,"y":1,"z":32}},{"blockCount":104,"bytes":3098,"file":"chunks/y005-z128-x224.json","offset":{"x":224,"y":5,"z":128},"requirements":{"minecraft:bricks":30,"minecraft:polished_diorite":2,"minecraft:spruce_planks":20,"minecraft:stone_bricks":52},"sha256":"e85ba256861327bd8c5af457bbbbc588c4b001231b0cf9ac5fb0a95999eb14ca","size":{"x":32,"y":1,"z":32}},{"blockCount":137,"bytes":3678,"file":"chunks/y005-z128-x256.json","offset":{"x":256,"y":5,"z":128},"requirements":{"minecraft:bricks":8,"minecraft:glass":2,"minecraft:polished_diorite":6,"minecraft:spruce_planks":75,"minecraft:stone_bricks":46},"sha256":"60f0e216838e8045a48644e26b7ff5d885252c2a4b048dc993f613abb615de19","size":{"x":32,"y":1,"z":32}},{"blockCount":111,"bytes":3528,"file":"chunks/y005-z128-x288.json","offset":{"x":288,"y":5,"z":128},"requirements":{"minecraft:glass":5,"minecraft:oak_planks":6,"minecraft:spruce_planks":100},"sha256":"36dd01052e7f4dec9b82d60d09d22df8f19cffca4554a0a06cf0ae23309d0b00","size":{"x":32,"y":1,"z":32}},{"blockCount":192,"bytes":3890,"file":"chunks/y005-z128-x320.json","offset":{"x":320,"y":5,"z":128},"requirements":{"minecraft:bricks":96,"minecraft:cobbled_deepslate":32,"minecraft:spruce_planks":60,"minecraft:stone_bricks":4},"sha256":"347d8c6bf0005531cf0d51e0ae277dc47db598d605876d6ddf746ea69cddd538","size":{"x":32,"y":1,"z":32}},{"blockCount":960,"bytes":2545,"file":"chunks/y005-z128-x352.json","offset":{"x":352,"y":5,"z":128},"requirements":{"minecraft:bricks":926,"minecraft:cobbled_deepslate":34},"sha256":"a72861480503f5696cb9bdc0395abca09da657b77f7da932e59158b570a79b62","size":{"x":32,"y":1,"z":32}},{"blockCount":389,"bytes":1326,"file":"chunks/y005-z160-x096.json","offset":{"x":96,"y":5,"z":160},"requirements":{"minecraft:stone_bricks":389},"sha256":"5c1d6e0acc9c50e543fff6051a5f8da2ca21088484c13b381827a1dd314ab29a","size":{"x":32,"y":1,"z":32}},{"blockCount":145,"bytes":1268,"file":"chunks/y005-z160-x128.json","offset":{"x":128,"y":5,"z":160},"requirements":{"minecraft:stone_bricks":145},"sha256":"e88dc1cc5a1b062d66b30520ed2624dd1f6af10f6d03c6af6fadf2f76e8a5b2c","size":{"x":32,"y":1,"z":32}},{"blockCount":30,"bytes":1662,"file":"chunks/y005-z160-x160.json","offset":{"x":160,"y":5,"z":160},"requirements":{"minecraft:cobbled_deepslate":30},"sha256":"cc708d7f4046de27daf88285b265dfe90d9b2d205e29778ea12180547c3615e0","size":{"x":32,"y":1,"z":32}},{"blockCount":16,"bytes":1009,"file":"chunks/y005-z160-x192.json","offset":{"x":192,"y":5,"z":160},"requirements":{"minecraft:bricks":8,"minecraft:stone_bricks":8},"sha256":"2ced4553871e4c78f302b8d399ac63c4b34d41f82b3cc863c056c35ea73a5031","size":{"x":32,"y":1,"z":32}},{"blockCount":58,"bytes":1956,"file":"chunks/y005-z160-x224.json","offset":{"x":224,"y":5,"z":160},"requirements":{"minecraft:bricks":4,"minecraft:spruce_planks":54},"sha256":"661c8f4c2cbae50b2e58892925667d25a7212af3cb2b116c9d0008cd68f24855","size":{"x":32,"y":1,"z":32}},{"blockCount":220,"bytes":4220,"file":"chunks/y005-z160-x256.json","offset":{"x":256,"y":5,"z":160},"requirements":{"minecraft:glass":4,"minecraft:spruce_planks":216},"sha256":"8d4e859b3011051af5a75917ca49c4274bcab1e4c24c36cc6e759822c983de06","size":{"x":32,"y":1,"z":32}},{"blockCount":61,"bytes":2016,"file":"chunks/y005-z160-x288.json","offset":{"x":288,"y":5,"z":160},"requirements":{"minecraft:oak_planks":2,"minecraft:spruce_planks":58,"minecraft:stone_bricks":1},"sha256":"f5cfc619329ad6f5b47e171bf8966c2af210c911d882c81b06b164b41257aeb6","size":{"x":32,"y":1,"z":32}},{"blockCount":280,"bytes":6509,"file":"chunks/y005-z160-x320.json","offset":{"x":320,"y":5,"z":160},"requirements":{"minecraft:bricks":36,"minecraft:cobbled_deepslate":16,"minecraft:glass":14,"minecraft:sandstone":4,"minecraft:spruce_planks":72,"minecraft:stone_bricks":138},"sha256":"2d974eccf7616f013dd354626ec2cc474ab0ddb3aa2ca3c7d75150de38ed5fc2","size":{"x":32,"y":1,"z":32}},{"blockCount":701,"bytes":11049,"file":"chunks/y005-z160-x352.json","offset":{"x":352,"y":5,"z":160},"requirements":{"minecraft:bricks":349,"minecraft:cobbled_deepslate":41,"minecraft:glass":22,"minecraft:stone_bricks":289},"sha256":"188e2eeb6c949800e408b7de22cccc63f0878d0e5aa94024b8dacadde7836f13","size":{"x":32,"y":1,"z":32}},{"blockCount":120,"bytes":799,"file":"chunks/y005-z192-x096.json","offset":{"x":96,"y":5,"z":192},"requirements":{"minecraft:stone_bricks":120},"sha256":"98ac99426785b315ca956b4397264907d0a4df9d836593183ac6d790c2ee5955","size":{"x":32,"y":1,"z":32}},{"blockCount":45,"bytes":779,"file":"chunks/y005-z192-x128.json","offset":{"x":128,"y":5,"z":192},"requirements":{"minecraft:stone_bricks":45},"sha256":"ae8831f5106558e52595f2576d0bf648a38e9f2c6bfdf5b700463135a4df4450","size":{"x":32,"y":1,"z":32}},{"blockCount":43,"bytes":1311,"file":"chunks/y005-z192-x160.json","offset":{"x":160,"y":5,"z":192},"requirements":{"minecraft:cobbled_deepslate":43},"sha256":"518d099cf9f5fead33c0a8e25abf1c0f69db7a796423e65814cdbd006a6c1dec","size":{"x":32,"y":1,"z":32}},{"blockCount":34,"bytes":716,"file":"chunks/y005-z192-x192.json","offset":{"x":192,"y":5,"z":192},"requirements":{"minecraft:cobbled_deepslate":32,"minecraft:stone_bricks":2},"sha256":"d300d00886686131f3fa69501343ce5bf62d3b4f1d654a4a5f3b1d583d223a13","size":{"x":32,"y":1,"z":32}},{"blockCount":19,"bytes":650,"file":"chunks/y005-z192-x224.json","offset":{"x":224,"y":5,"z":192},"requirements":{"minecraft:cobbled_deepslate":19},"sha256":"65d95958ce500950b344e0caf06ea4efed0e5b2c56c69357121ce0b0e89c95f1","size":{"x":32,"y":1,"z":32}},{"blockCount":62,"bytes":2089,"file":"chunks/y005-z192-x256.json","offset":{"x":256,"y":5,"z":192},"requirements":{"minecraft:oak_planks":4,"minecraft:spruce_planks":46,"minecraft:stone_bricks":12},"sha256":"fc85abfe37f18558a1835cabecd0d936625569cef8be6955279dceb81b83e522","size":{"x":32,"y":1,"z":32}},{"blockCount":32,"bytes":1531,"file":"chunks/y005-z192-x288.json","offset":{"x":288,"y":5,"z":192},"requirements":{"minecraft:sandstone":7,"minecraft:spruce_planks":21,"minecraft:stone_bricks":4},"sha256":"91a293f5b7a8bfca0bc9da9ad479c17a1bbf4ae70ddd7ef023376e06ffd5e417","size":{"x":32,"y":1,"z":32}},{"blockCount":240,"bytes":7325,"file":"chunks/y005-z192-x320.json","offset":{"x":320,"y":5,"z":192},"requirements":{"minecraft:glass":16,"minecraft:stone_bricks":224},"sha256":"2563aead371dce87b3a8ceee6589172920ef64d8dcd1675e1dcee0f98b67667c","size":{"x":32,"y":1,"z":32}},{"blockCount":480,"bytes":17629,"file":"chunks/y005-z192-x352.json","offset":{"x":352,"y":5,"z":192},"requirements":{"minecraft:glass":16,"minecraft:stone_bricks":464},"sha256":"d5ce5f80467b8ac9b398777e3e9b030d6de3c93c118f879b689fbe0788677dbb","size":{"x":32,"y":1,"z":32}},{"blockCount":32,"bytes":914,"file":"chunks/y005-z224-x320.json","offset":{"x":320,"y":5,"z":224},"requirements":{"minecraft:glass":5,"minecraft:stone_bricks":27},"sha256":"c2b3017fa81ab1537b279f10af1224712524e61aa57feca7dcf2ba8bb1ba6cb3","size":{"x":32,"y":1,"z":15}},{"blockCount":81,"bytes":1217,"file":"chunks/y005-z224-x352.json","offset":{"x":352,"y":5,"z":224},"requirements":{"minecraft:glass":13,"minecraft:stone_bricks":68},"sha256":"88f22dd8874a7f2c7c2c36364347592b39bbb2414aa086a74172cc4329966ba4","size":{"x":32,"y":1,"z":15}},{"blockCount":3,"bytes":666,"file":"chunks/y005-z224-x384.json","offset":{"x":384,"y":5,"z":224},"requirements":{"minecraft:cobbled_deepslate":3},"sha256":"5ae174981dc353d7dc8115b3fb1867fbfe186438d1f92a6e9e2ec70ad5f85787","size":{"x":32,"y":1,"z":15}},{"blockCount":25,"bytes":990,"file":"chunks/y006-z000-x320.json","offset":{"x":320,"y":6,"z":0},"requirements":{"minecraft:sandstone":25},"sha256":"74162c5b104aef8089ac7538626ebb4ed21e3ae075aadbce8ecea64a52456b69","size":{"x":32,"y":1,"z":32}},{"blockCount":32,"bytes":640,"file":"chunks/y006-z000-x352.json","offset":{"x":352,"y":6,"z":0},"requirements":{"minecraft:sandstone":32},"sha256":"1c9cac7f87e3e409a6668a4a4589e2b03323793e8b31f293c1018842f2bc868f","size":{"x":32,"y":1,"z":32}},{"blockCount":14,"bytes":989,"file":"chunks/y006-z000-x384.json","offset":{"x":384,"y":6,"z":0},"requirements":{"minecraft:sandstone":14},"sha256":"4e227b43145360e19df8509308d1fec891a41b7b9d1b4ba3b902a22815d01469","size":{"x":32,"y":1,"z":32}},{"blockCount":115,"bytes":4154,"file":"chunks/y006-z032-x320.json","offset":{"x":320,"y":6,"z":32},"requirements":{"minecraft:bricks":65,"minecraft:glass":8,"minecraft:sandstone":7,"minecraft:spruce_planks":35},"sha256":"8ef654fe20a643290e4f02c0cf695ef4a8abab8368be934194c9c5d8ccf4c192","size":{"x":32,"y":1,"z":32}},{"blockCount":72,"bytes":2540,"file":"chunks/y006-z032-x352.json","offset":{"x":352,"y":6,"z":32},"requirements":{"minecraft:bricks":6,"minecraft:glass":18,"minecraft:oak_planks":6,"minecraft:polished_diorite":2,"minecraft:spruce_planks":39,"minecraft:stone_bricks":1},"sha256":"183e2274a3590932643f379b79987485a2ac0efdcfe07d3e02b49de2ec04de5b","size":{"x":32,"y":1,"z":32}},{"blockCount":183,"bytes":3539,"file":"chunks/y006-z032-x384.json","offset":{"x":384,"y":6,"z":32},"requirements":{"minecraft:bricks":15,"minecraft:sandstone":7,"minecraft:spruce_planks":15,"minecraft:stone_bricks":146},"sha256":"e13214dad319c75779f9991ad835aecc6a3438bed5fb6ac78504695deecd2092","size":{"x":32,"y":1,"z":32}},{"blockCount":42,"bytes":1261,"file":"chunks/y006-z064-x096.json","offset":{"x":96,"y":6,"z":64},"requirements":{"minecraft:stone_bricks":42},"sha256":"461f46d05a6075234711a77f02e08b9399cfefe21a144ce2ed510a3571b8665e","size":{"x":32,"y":1,"z":32}},{"blockCount":24,"bytes":1148,"file":"chunks/y006-z064-x128.json","offset":{"x":128,"y":6,"z":64},"requirements":{"minecraft:stone_bricks":24},"sha256":"4e4ea61bf23c68f1e71b35b9d8eb44fa23f7dc1861c79dfc0a90ed776f58c97b","size":{"x":32,"y":1,"z":32}},{"blockCount":128,"bytes":4221,"file":"chunks/y006-z064-x320.json","offset":{"x":320,"y":6,"z":64},"requirements":{"minecraft:bricks":58,"minecraft:oak_planks":2,"minecraft:sandstone":32,"minecraft:spruce_planks":22,"minecraft:stone_bricks":14},"sha256":"6228bae69c4673f5d468568c9422b4cf46207c77475367de7d783adeda77824b","size":{"x":32,"y":1,"z":32}},{"blockCount":87,"bytes":1313,"file":"chunks/y006-z064-x352.json","offset":{"x":352,"y":6,"z":64},"requirements":{"minecraft:bricks":6,"minecraft:oak_planks":1,"minecraft:polished_diorite":27,"minecraft:sandstone":33,"minecraft:spruce_planks":9,"minecraft:stone_bricks":11},"sha256":"4139121fb167acc6f3d880e62d5f752356e8255d615fc497f99cc2822f9c1abf","size":{"x":32,"y":1,"z":32}},{"blockCount":81,"bytes":2104,"file":"chunks/y006-z064-x384.json","offset":{"x":384,"y":6,"z":64},"requirements":{"minecraft:bricks":9,"minecraft:polished_diorite":10,"minecraft:sandstone":21,"minecraft:spruce_planks":2,"minecraft:stone_bricks":39},"sha256":"d0ee93bc5dac0421142debef9457b4e417093aca8747190e693084f74aa55598","size":{"x":32,"y":1,"z":32}},{"blockCount":12,"bytes":777,"file":"chunks/y006-z096-x032.json","offset":{"x":32,"y":6,"z":96},"requirements":{"minecraft:stone_bricks":12},"sha256":"fb8675d6f06460f8c6f49eb317c79c385fb6c9abaef5a3c95b99404f1ce26ebd","size":{"x":32,"y":1,"z":32}},{"blockCount":109,"bytes":1880,"file":"chunks/y006-z096-x064.json","offset":{"x":64,"y":6,"z":96},"requirements":{"minecraft:stone_bricks":109},"sha256":"0633a51a3169d59f7386814a1b7acb901133817f0079917b0263ce50aa70d37d","size":{"x":32,"y":1,"z":32}},{"blockCount":460,"bytes":6607,"file":"chunks/y006-z096-x096.json","offset":{"x":96,"y":6,"z":96},"requirements":{"minecraft:stone_bricks":460},"sha256":"37e11a1a2e13a65d357e78cd37fbab1f24ce35317ce7954da4f0b1f763c80582","size":{"x":32,"y":1,"z":32}},{"blockCount":247,"bytes":4511,"file":"chunks/y006-z096-x128.json","offset":{"x":128,"y":6,"z":96},"requirements":{"minecraft:stone_bricks":247},"sha256":"d9581f81f67531905b2c7940d741b0c3117795759a5e5627afa7d87bb9555a1e","size":{"x":32,"y":1,"z":32}},{"blockCount":15,"bytes":1060,"file":"chunks/y006-z096-x192.json","offset":{"x":192,"y":6,"z":96},"requirements":{"minecraft:bricks":15},"sha256":"6a69385b4c11ca54c60b57f62e283cc53415384011aab59208ab39976b8156c7","size":{"x":32,"y":1,"z":32}},{"blockCount":13,"bytes":1061,"file":"chunks/y006-z096-x224.json","offset":{"x":224,"y":6,"z":96},"requirements":{"minecraft:bricks":13},"sha256":"a9c50d17fd6181b9b8103900ae633a185dd4994f50398a6c5356df51dc10649f","size":{"x":32,"y":1,"z":32}},{"blockCount":86,"bytes":2222,"file":"chunks/y006-z096-x256.json","offset":{"x":256,"y":6,"z":96},"requirements":{"minecraft:cobbled_deepslate":11,"minecraft:spruce_planks":37,"minecraft:stone_bricks":38},"sha256":"c784c3125e1dc0c393cbe80a95bb08cd60883c007d27b9b2f11e1553dac89b15","size":{"x":32,"y":1,"z":32}},{"blockCount":99,"bytes":2290,"file":"chunks/y006-z096-x288.json","offset":{"x":288,"y":6,"z":96},"requirements":{"minecraft:bricks":2,"minecraft:cobbled_deepslate":9,"minecraft:oak_planks":5,"minecraft:spruce_planks":68,"minecraft:stone_bricks":15},"sha256":"267e48399287a65a43edbda68173dc0d07fe71f3d99c6165a828c1f5c3ec7d5f","size":{"x":32,"y":1,"z":32}},{"blockCount":179,"bytes":4372,"file":"chunks/y006-z096-x320.json","offset":{"x":320,"y":6,"z":96},"requirements":{"minecraft:bricks":93,"minecraft:oak_planks":1,"minecraft:polished_diorite":6,"minecraft:sandstone":2,"minecraft:spruce_planks":40,"minecraft:stone_bricks":37},"sha256":"0c62b82157daabc384551737b150e7183f3d0935f197e5717b0b99c245760218","size":{"x":32,"y":1,"z":32}},{"blockCount":725,"bytes":2164,"file":"chunks/y006-z096-x352.json","offset":{"x":352,"y":6,"z":96},"requirements":{"minecraft:bricks":437,"minecraft:oak_planks":2,"minecraft:polished_diorite":30,"minecraft:sandstone":4,"minecraft:spruce_planks":1,"minecraft:stone_bricks":251},"sha256":"4b2254683334eb20d7282d4ebca1cf32aecd94751bcae44377105acb7cb71f4d","size":{"x":32,"y":1,"z":32}},{"blockCount":9,"bytes":768,"file":"chunks/y006-z096-x384.json","offset":{"x":384,"y":6,"z":96},"requirements":{"minecraft:polished_diorite":8,"minecraft:stone_bricks":1},"sha256":"fccc16c91b2b9a8286851f125d86adb4bb437987853bde2a221ca5c041ceb05a","size":{"x":32,"y":1,"z":32}},{"blockCount":84,"bytes":2227,"file":"chunks/y006-z128-x032.json","offset":{"x":32,"y":6,"z":128},"requirements":{"minecraft:stone_bricks":84},"sha256":"48729378f5b4b7756fbdc39b12ab7395035c7e38f196c53c512047202a40a0a2","size":{"x":32,"y":1,"z":32}},{"blockCount":696,"bytes":9736,"file":"chunks/y006-z128-x064.json","offset":{"x":64,"y":6,"z":128},"requirements":{"minecraft:stone_bricks":696},"sha256":"87b8e3f64d98e1c67b69d826e538cf5a870bc773e5f31a1e21183a2a7201d3f6","size":{"x":32,"y":1,"z":32}},{"blockCount":742,"bytes":10099,"file":"chunks/y006-z128-x096.json","offset":{"x":96,"y":6,"z":128},"requirements":{"minecraft:stone_bricks":742},"sha256":"6c3860ae7cefc959e79b95457e198acca33f8fa55255e38cd7ea433e9248cab1","size":{"x":32,"y":1,"z":32}},{"blockCount":595,"bytes":8639,"file":"chunks/y006-z128-x128.json","offset":{"x":128,"y":6,"z":128},"requirements":{"minecraft:stone_bricks":595},"sha256":"e2e5b5699f00bbc37415b66fddd6aad58d9dd353bc68fa922755061485666cd9","size":{"x":32,"y":1,"z":32}},{"blockCount":60,"bytes":1340,"file":"chunks/y006-z128-x160.json","offset":{"x":160,"y":6,"z":128},"requirements":{"minecraft:cobbled_deepslate":21,"minecraft:stone_bricks":39},"sha256":"d4667ed6796dfdcfbcb45d797433cae9fa5fed97081a0dabd585c8490833e2ba","size":{"x":32,"y":1,"z":32}},{"blockCount":79,"bytes":2113,"file":"chunks/y006-z128-x192.json","offset":{"x":192,"y":6,"z":128},"requirements":{"minecraft:bricks":14,"minecraft:cobbled_deepslate":10,"minecraft:stone_bricks":55},"sha256":"26ed06d9648a1db1f8f97eebf4fc5a12faafdfd684f0bd9cff00d54013bc347a","size":{"x":32,"y":1,"z":32}},{"blockCount":101,"bytes":3050,"file":"chunks/y006-z128-x224.json","offset":{"x":224,"y":6,"z":128},"requirements":{"minecraft:bricks":30,"minecraft:polished_diorite":2,"minecraft:spruce_planks":20,"minecraft:stone_bricks":49},"sha256":"1d616bacafb334c411c33f055ad3f2174932cfa3ad9679f5db5e400f1d8f1615","size":{"x":32,"y":1,"z":32}},{"blockCount":144,"bytes":3717,"file":"chunks/y006-z128-x256.json","offset":{"x":256,"y":6,"z":128},"requirements":{"minecraft:glass":2,"minecraft:polished_diorite":6,"minecraft:spruce_planks":90,"minecraft:stone_bricks":46},"sha256":"4c11420c8ed734aafb9930d47680dba3a07704e3a810cfcc5c9f3d8b41874ac9","size":{"x":32,"y":1,"z":32}},{"blockCount":178,"bytes":4574,"file":"chunks/y006-z128-x288.json","offset":{"x":288,"y":6,"z":128},"requirements":{"minecraft:oak_planks":6,"minecraft:polished_diorite":1,"minecraft:spruce_planks":168,"minecraft:stone_bricks":3},"sha256":"950f48351ea46c6bb22ca5b2c12234191415f9dd5ddce848ccd47e4788c22389","size":{"x":32,"y":1,"z":32}},{"blockCount":165,"bytes":3909,"file":"chunks/y006-z128-x320.json","offset":{"x":320,"y":6,"z":128},"requirements":{"minecraft:bricks":104,"minecraft:polished_diorite":1,"minecraft:spruce_planks":32,"minecraft:stone_bricks":28},"sha256":"8809b57a4328d553aec45b898c71a29282ec63c78e481da2c3bc33c69a603fa9","size":{"x":32,"y":1,"z":32}},{"blockCount":959,"bytes":7405,"file":"chunks/y006-z128-x352.json","offset":{"x":352,"y":6,"z":128},"requirements":{"minecraft:bricks":622,"minecraft:cobbled_deepslate":1,"minecraft:stone_bricks":336},"sha256":"c33d2037eaacd02dfe1b4de68f3e8c501f9f3968a2eb20a2f93bedcf3d672d3d","size":{"x":32,"y":1,"z":32}},{"blockCount":5,"bytes":642,"file":"chunks/y006-z160-x064.json","offset":{"x":64,"y":6,"z":160},"requirements":{"minecraft:stone_bricks":5},"sha256":"7e9efdb9d356af42b22e65798d6ba495d8b226cc2521e05336d6b85fe26e7f2d","size":{"x":32,"y":1,"z":32}},{"blockCount":319,"bytes":5300,"file":"chunks/y006-z160-x096.json","offset":{"x":96,"y":6,"z":160},"requirements":{"minecraft:stone_bricks":319},"sha256":"7ab5dab921d947c75efe1fdb4a13205d3375992462c7165770fba81babc9edc3","size":{"x":32,"y":1,"z":32}},{"blockCount":159,"bytes":3603,"file":"chunks/y006-z160-x128.json","offset":{"x":128,"y":6,"z":160},"requirements":{"minecraft:stone_bricks":159},"sha256":"57286829bc497fe5dfe841a4914bf363bc59c98f4e7d07500a9fb5a62ac3908d","size":{"x":32,"y":1,"z":32}},{"blockCount":44,"bytes":1861,"file":"chunks/y006-z160-x160.json","offset":{"x":160,"y":6,"z":160},"requirements":{"minecraft:cobbled_deepslate":30,"minecraft:stone_bricks":14},"sha256":"76f27b87a5f4905ef2921ae02cc176bbd8dc471d362ea2b4ac19e87c7f34e3a7","size":{"x":32,"y":1,"z":32}},{"blockCount":82,"bytes":1845,"file":"chunks/y006-z160-x192.json","offset":{"x":192,"y":6,"z":160},"requirements":{"minecraft:bricks":5,"minecraft:stone_bricks":77},"sha256":"6dd212ded1397d03d4518a2c0d2438eb4fed813a6d8f113354797071a87991cd","size":{"x":32,"y":1,"z":32}},{"blockCount":61,"bytes":2014,"file":"chunks/y006-z160-x224.json","offset":{"x":224,"y":6,"z":160},"requirements":{"minecraft:bricks":5,"minecraft:spruce_planks":56},"sha256":"71c49a8b19560c7f9b4ee2b45f2bdb7557c887e0aeae40224fb319ea7333663a","size":{"x":32,"y":1,"z":32}},{"blockCount":211,"bytes":5027,"file":"chunks/y006-z160-x256.json","offset":{"x":256,"y":6,"z":160},"requirements":{"minecraft:bricks":27,"minecraft:spruce_planks":169,"minecraft:stone_bricks":15},"sha256":"bd03ecfce81308b715f0cb065905510ac0c08ffa191f3ddfedb2fa66e3671739","size":{"x":32,"y":1,"z":32}},{"blockCount":64,"bytes":2132,"file":"chunks/y006-z160-x288.json","offset":{"x":288,"y":6,"z":160},"requirements":{"minecraft:oak_planks":2,"minecraft:spruce_planks":52,"minecraft:stone_bricks":10},"sha256":"13edc4cfa1da4b262179366f879c52a4217d4bfaf7e0dbfd542076aef4f1bddf","size":{"x":32,"y":1,"z":32}},{"blockCount":247,"bytes":5324,"file":"chunks/y006-z160-x320.json","offset":{"x":320,"y":6,"z":160},"requirements":{"minecraft:bricks":52,"minecraft:glass":14,"minecraft:spruce_planks":41,"minecraft:stone_bricks":140},"sha256":"f936b38ecc885c583efeb3102fea6f00ea2eed3b69a6acdf86c000607876dee0","size":{"x":32,"y":1,"z":32}},{"blockCount":696,"bytes":12868,"file":"chunks/y006-z160-x352.json","offset":{"x":352,"y":6,"z":160},"requirements":{"minecraft:bricks":293,"minecraft:glass":22,"minecraft:stone_bricks":381},"sha256":"4180fbfb355586153474bd3aea8ca3358a3ee5ce7b772f728ea4eaa4a1cb1b85","size":{"x":32,"y":1,"z":32}},{"blockCount":33,"bytes":989,"file":"chunks/y006-z192-x096.json","offset":{"x":96,"y":6,"z":192},"requirements":{"minecraft:stone_bricks":33},"sha256":"e029bfe98e094d63b02a7d994d872e613e17fb6d5c190b66582ecdd825e03d80","size":{"x":32,"y":1,"z":32}},{"blockCount":15,"bytes":875,"file":"chunks/y006-z192-x128.json","offset":{"x":128,"y":6,"z":192},"requirements":{"minecraft:stone_bricks":15},"sha256":"b6551b177cb0f0e1aa309d17253ff56e73ad0cd507b748d02a1c32bb00c7dfc3","size":{"x":32,"y":1,"z":32}},{"blockCount":49,"bytes":1452,"file":"chunks/y006-z192-x160.json","offset":{"x":160,"y":6,"z":192},"requirements":{"minecraft:cobbled_deepslate":43,"minecraft:stone_bricks":6},"sha256":"52901fa87b5d5f229f1d7745c5d0e4a6a6974e3fe2898f769fbeb20b6a8a8bf2","size":{"x":32,"y":1,"z":32}},{"blockCount":74,"bytes":1191,"file":"chunks/y006-z192-x192.json","offset":{"x":192,"y":6,"z":192},"requirements":{"minecraft:cobbled_deepslate":32,"minecraft:stone_bricks":42},"sha256":"599cf1354c4c954dbea381e6ad211fe2a5992bb7eef4ffb3b08f2101cd7370fa","size":{"x":32,"y":1,"z":32}},{"blockCount":19,"bytes":650,"file":"chunks/y006-z192-x224.json","offset":{"x":224,"y":6,"z":192},"requirements":{"minecraft:cobbled_deepslate":19},"sha256":"a8b779bb5bd1cf97ffcfcb1f199471d7a6aa7fe3128d93ee5b98b8d38c1329ea","size":{"x":32,"y":1,"z":32}},{"blockCount":107,"bytes":1899,"file":"chunks/y006-z192-x256.json","offset":{"x":256,"y":6,"z":192},"requirements":{"minecraft:spruce_planks":48,"minecraft:stone_bricks":59},"sha256":"c203abab3d9d4aacc615e4e51c6b35ec8a46c757f66eaea57f19dd54d2265f21","size":{"x":32,"y":1,"z":32}},{"blockCount":26,"bytes":1465,"file":"chunks/y006-z192-x288.json","offset":{"x":288,"y":6,"z":192},"requirements":{"minecraft:sandstone":3,"minecraft:stone_bricks":23},"sha256":"e61d0d25704795972aaa61f9c80297df50080dc5c1a3d032d879a9f8df7f0220","size":{"x":32,"y":1,"z":32}},{"blockCount":240,"bytes":7325,"file":"chunks/y006-z192-x320.json","offset":{"x":320,"y":6,"z":192},"requirements":{"minecraft:glass":16,"minecraft:stone_bricks":224},"sha256":"294791c5bc7ba3af7bc83be6735843c55cf9da825e1290137f64291e7986d2dd","size":{"x":32,"y":1,"z":32}}],"schema":1}
