{"entries":[{"blockCount":480,"bytes":17629,"file":"chunks/y006-z192-x352.json","offset":{"x":352,"y":6,"z":192},"requirements":{"minecraft:glass":16,"minecraft:stone_bricks":464},"sha256":"1990f50e259277ee8ab5ec28452d8b57e4cc740096eb277a7524253863570d2b","size":{"x":32,"y":1,"z":32}},{"blockCount":126,"bytes":1079,"file":"chunks/y006-z224-x256.json","offset":{"x":256,"y":6,"z":224},"requirements":{"minecraft:stone_bricks":126},"sha256":"d5f08b74c65fdf6401d453c31e767aa6c8f4d1c1ddb858b2ce2e0dfce3fe7681","size":{"x":32,"y":1,"z":15}},{"blockCount":10,"bytes":974,"file":"chunks/y006-z224-x288.json","offset":{"x":288,"y":6,"z":224},"requirements":{"minecraft:stone_bricks":10},"sha256":"009b673a79cae05a377350c99ede45bb364c145e66530b95449be3455e644ca1","size":{"x":32,"y":1,"z":15}},{"blockCount":32,"bytes":914,"file":"chunks/y006-z224-x320.json","offset":{"x":320,"y":6,"z":224},"requirements":{"minecraft:glass":5,"minecraft:stone_bricks":27},"sha256":"2aad4e18002dfcdcc41e6d5862c6d505f68c1047bc351bb834e5eaf1426f0196","size":{"x":32,"y":1,"z":15}},{"blockCount":81,"bytes":1217,"file":"chunks/y006-z224-x352.json","offset":{"x":352,"y":6,"z":224},"requirements":{"minecraft:glass":13,"minecraft:stone_bricks":68},"sha256":"28d3fee0d07a1ccd3fb102005f9734321476d8119ac537d94ce1c63f866f2ed9","size":{"x":32,"y":1,"z":15}},{"blockCount":1,"bytes":619,"file":"chunks/y006-z224-x384.json","offset":{"x":384,"y":6,"z":224},"requirements":{"minecraft:sandstone":1},"sha256":"0fe44c57ced686cac826baeda80081770feb4cce3c4ab81f7fa588d2920b5e21","size":{"x":32,"y":1,"z":15}},{"blockCount":25,"bytes":990,"file":"chunks/y007-z000-x320.json","offset":{"x":320,"y":7,"z":0},"requirements":{"minecraft:sandstone":25},"sha256":"a8a46b64a4f88c9c9b410794afc5444e42b1f7b322dd5bff2cc68aae7b1e7db0","size":{"x":32,"y":1,"z":32}},{"blockCount":32,"bytes":640,"file":"chunks/y007-z000-x352.json","offset":{"x":352,"y":7,"z":0},"requirements":{"minecraft:sandstone":32},"sha256":"eaa6fe2f43f047710d3c406f016fbb747da4b1d41f5a4cda434251b1a1e0a0a8","size":{"x":32,"y":1,"z":32}},{"blockCount":14,"bytes":989,"file":"chunks/y007-z000-x384.json","offset":{"x":384,"y":7,"z":0},"requirements":{"minecraft:sandstone":14},"sha256":"05356d0790d0f0d5243d0fbb5770a498302df54ee679c4629635647be3f5782e","size":{"x":32,"y":1,"z":32}},{"blockCount":115,"bytes":4154,"file":"chunks/y007-z032-x320.json","offset":{"x":320,"y":7,"z":32},"requirements":{"minecraft:bricks":65,"minecraft:glass":8,"minecraft:sandstone":7,"minecraft:spruce_planks":35},"sha256":"54499bc1dbd408dd7110166808aea45fe3b4eabd56b69efceaa802a835faf091","size":{"x":32,"y":1,"z":32}},{"blockCount":63,"bytes":2377,"file":"chunks/y007-z032-x352.json","offset":{"x":352,"y":7,"z":32},"requirements":{"minecraft:bricks":6,"minecraft:glass":18,"minecraft:oak_planks":5,"minecraft:sandstone":1,"minecraft:spruce_planks":31,"minecraft:stone_bricks":2},"sha256":"14136bc4a2da6cc3b7a567a35f9c527e27cdbe8ebea8623027005560ef67b44b","size":{"x":32,"y":1,"z":32}},{"blockCount":143,"bytes":3634,"file":"chunks/y007-z032-x384.json","offset":{"x":384,"y":7,"z":32},"requirements":{"minecraft:bricks":17,"minecraft:cobbled_deepslate":5,"minecraft:glass":2,"minecraft:sandstone":7,"minecraft:spruce_planks":10,"minecraft:stone_bricks":102},"sha256":"db4b6d4111949d236d9c827450b89ab5317018b526cea32dcfbc1ac6a59bbc25","size":{"x":32,"y":1,"z":32}},{"blockCount":42,"bytes":1261,"file":"chunks/y007-z064-x096.json","offset":{"x":96,"y":7,"z":64},"requirements":{"minecraft:stone_bricks":42},"sha256":"d52fda8ee5183e16c9e4ab78762bd21dc74809494363868e88e049c941bce1fe","size":{"x":32,"y":1,"z":32}},{"blockCount":24,"bytes":1148,"file":"chunks/y007-z064-x128.json","offset":{"x":128,"y":7,"z":64},"requirements":{"minecraft:stone_bricks":24},"sha256":"3f38347c78168e98024d2960facf59721d26b96dba8f36e3a832d2a585eb7b3a","size":{"x":32,"y":1,"z":32}},{"blockCount":128,"bytes":4259,"file":"chunks/y007-z064-x320.json","offset":{"x":320,"y":7,"z":64},"requirements":{"minecraft:bricks":58,"minecraft:oak_planks":4,"minecraft:sandstone":32,"minecraft:spruce_planks":22,"minecraft:stone_bricks":12},"sha256":"8f236277e578467c221f1e89c68695f6afaf42a50a728c5e0836d6162e53ea96","size":{"x":32,"y":1,"z":32}},{"blockCount":86,"bytes":1267,"file":"chunks/y007-z064-x352.json","offset":{"x":352,"y":7,"z":64},"requirements":{"minecraft:bricks":6,"minecraft:polished_diorite":1,"minecraft:sandstone":33,"minecraft:spruce_planks":8,"minecraft:stone_bricks":38},"sha256":"b904ae4d70d9c1b7a77d9a342e9646b78e0f292f2732eb5f6249b4590f2cf321","size":{"x":32,"y":1,"z":32}},{"blockCount":81,"bytes":2160,"file":"chunks/y007-z064-x384.json","offset":{"x":384,"y":7,"z":64},"requirements":{"minecraft:bricks":9,"minecraft:polished_diorite":6,"minecraft:sandstone":21,"minecraft:spruce_planks":2,"minecraft:stone_bricks":43},"sha256":"f890aa1e569b6d64f12af5c2a43ee5f99e3dc2f06f26c94c3c2d8309b690fb01","size":{"x":32,"y":1,"z":32}},{"blockCount":9,"bytes":796,"file":"chunks/y007-z096-x032.json","offset":{"x":32,"y":7,"z":96},"requirements":{"minecraft:stone_bricks":9},"sha256":"cbf40b7b3c169a3c47fd2955a442112468726995c71f9f767114059c918e9162","size":{"x":32,"y":1,"z":32}},{"blockCount":91,"bytes":1937,"file":"chunks/y007-z096-x064.json","offset":{"x":64,"y":7,"z":96},"requirements":{"minecraft:stone_bricks":91},"sha256":"01ec5263a7c5f8eeba4f43c920626f94a716a1811788780793b1fcda3bc5776b","size":{"x":32,"y":1,"z":32}},{"blockCount":154,"bytes":2685,"file":"chunks/y007-z096-x096.json","offset":{"x":96,"y":7,"z":96},"requirements":{"minecraft:stone_bricks":154},"sha256":"99b8a988bcd3ea8177888a5463607496a7c58968bc80f421533745235b4b2628","size":{"x":32,"y":1,"z":32}},{"blockCount":169,"bytes":3156,"file":"chunks/y007-z096-x128.json","offset":{"x":128,"y":7,"z":96},"requirements":{"minecraft:stone_bricks":169},"sha256":"35e20eb809cede2de0810a1709fe504bb0ba5005083f9497f87730b90269bc3a","size":{"x":32,"y":1,"z":32}},{"blockCount":11,"bytes":985,"file":"chunks/y007-z096-x192.json","offset":{"x":192,"y":7,"z":96},"requirements":{"minecraft:bricks":11},"sha256":"66e0442c4ae9692259bcbcfe6f21ef7f59eaeaddaee004b41b64a4fe5dff342f","size":{"x":32,"y":1,"z":32}},{"blockCount":16,"bytes":1136,"file":"chunks/y007-z096-x224.json","offset":{"x":224,"y":7,"z":96},"requirements":{"minecraft:bricks":16},"sha256":"ebb7e32a3ece442a5aa41d46d03eb8c076fa69d074d4d29bc7ed61b3e5e50b85","size":{"x":32,"y":1,"z":32}},{"blockCount":94,"bytes":2154,"file":"chunks/y007-z096-x256.json","offset":{"x":256,"y":7,"z":96},"requirements":{"minecraft:cobbled_deepslate":15,"minecraft:oak_planks":19,"minecraft:spruce_planks":33,"minecraft:stone_bricks":27},"sha256":"4044962e3e7668ba0a2b4dbd6258a0d561cd31e91e806758d0d6b0ff76e78acf","size":{"x":32,"y":1,"z":32}},{"blockCount":135,"bytes":2201,"file":"chunks/y007-z096-x288.json","offset":{"x":288,"y":7,"z":96},"requirements":{"minecraft:bricks":17,"minecraft:oak_planks":42,"minecraft:spruce_planks":58,"minecraft:stone_bricks":18},"sha256":"46c54033c32ec68f6c1eafa9d0451884bd782fed5cbe9c464ec3525312ea2287","size":{"x":32,"y":1,"z":32}},{"blockCount":188,"bytes":4564,"file":"chunks/y007-z096-x320.json","offset":{"x":320,"y":7,"z":96},"requirements":{"minecraft:bricks":110,"minecraft:oak_planks":1,"minecraft:polished_diorite":3,"minecraft:sandstone":2,"minecraft:spruce_planks":41,"minecraft:stone_bricks":31},"sha256":"3ee2ecc0ef3d220e8d73fa0e7468a3ab61fb82bb9b7fe4eea8eaa7345ebcd9d4","size":{"x":32,"y":1,"z":32}},{"blockCount":646,"bytes":2277,"file":"chunks/y007-z096-x352.json","offset":{"x":352,"y":7,"z":96},"requirements":{"minecraft:bricks":366,"minecraft:glass":1,"minecraft:oak_planks":2,"minecraft:polished_diorite":5,"minecraft:sandstone":4,"minecraft:spruce_planks":2,"minecraft:stone_bricks":266},"sha256":"edbcd4482ac6ce0094a65c7064c5cff031d2269b4d9798a191fdb3a59e092afd","size":{"x":32,"y":1,"z":32}},{"blockCount":5,"bytes":787,"file":"chunks/y007-z096-x384.json","offset":{"x":384,"y":7,"z":96},"requirements":{"minecraft:polished_diorite":2,"minecraft:stone_bricks":3},"sha256":"c904c355ca00f75aa29eb879621888d372aa0baf1e0620b1b31b425f09e7f936","size":{"x":32,"y":1,"z":32}},{"blockCount":33,"bytes":1613,"file":"chunks/y007-z128-x032.json","offset":{"x":32,"y":7,"z":128},"requirements":{"minecraft:stone_bricks":33},"sha256":"f9c599d5fb583f488dabd93206e44067190c074e9a7dabab9eaeb3f6bb77643d","size":{"x":32,"y":1,"z":32}},{"blockCount":134,"bytes":2826,"file":"chunks/y007-z128-x064.json","offset":{"x":64,"y":7,"z":128},"requirements":{"minecraft:glass":2,"minecraft:stone_bricks":132},"sha256":"c630bcff902c2b6b017940c67e7b12a0d80d5bf6257e0bd643fe5056d6261e04","size":{"x":32,"y":1,"z":32}},{"blockCount":173,"bytes":2869,"file":"chunks/y007-z128-x096.json","offset":{"x":96,"y":7,"z":128},"requirements":{"minecraft:glass":40,"minecraft:stone_bricks":133},"sha256":"9298d9b308132d7a28812090d22e37abd2ad89b2a5802beb5bb49745f9cdb332","size":{"x":32,"y":1,"z":32}},{"blockCount":101,"bytes":2468,"file":"chunks/y007-z128-x128.json","offset":{"x":128,"y":7,"z":128},"requirements":{"minecraft:stone_bricks":101},"sha256":"7ddeec7d9dc2509f0176b0b75fbfb2c2edeb3e4d518303542c7244dc016636ce","size":{"x":32,"y":1,"z":32}},{"blockCount":60,"bytes":1340,"file":"chunks/y007-z128-x160.json","offset":{"x":160,"y":7,"z":128},"requirements":{"minecraft:cobbled_deepslate":21,"minecraft:stone_bricks":39},"sha256":"e007b10dd9495304ad9a4dd3c2152eaa42094f7f06c2e648675d091749d7ee6e","size":{"x":32,"y":1,"z":32}},{"blockCount":86,"bytes":2383,"file":"chunks/y007-z128-x192.json","offset":{"x":192,"y":7,"z":128},"requirements":{"minecraft:bricks":22,"minecraft:cobbled_deepslate":10,"minecraft:stone_bricks":54},"sha256":"a4b22abc8ba69208cf30e74d3a0c2b77ae95870d44966a31f7f74c5b96c2e6dc","size":{"x":32,"y":1,"z":32}},{"blockCount":95,"bytes":2794,"file":"chunks/y007-z128-x224.json","offset":{"x":224,"y":7,"z":128},"requirements":{"minecraft:bricks":17,"minecraft:polished_diorite":2,"minecraft:spruce_planks":20,"minecraft:stone_bricks":56},"sha256":"1694df06b01df7c5d6acc3f6e079f248309318356691be74453a14537b97eea0","size":{"x":32,"y":1,"z":32}},{"blockCount":295,"bytes":3995,"file":"chunks/y007-z128-x256.json","offset":{"x":256,"y":7,"z":128},"requirements":{"minecraft:oak_planks":99,"minecraft:polished_diorite":6,"minecraft:spruce_planks":106,"minecraft:stone_bricks":84},"sha256":"088031642a14a06a6e216e5d4c8eed624c7baad6ebe9b145c4925931f015af93","size":{"x":32,"y":1,"z":32}},{"blockCount":468,"bytes":4200,"file":"chunks/y007-z128-x288.json","offset":{"x":288,"y":7,"z":128},"requirements":{"minecraft:bricks":35,"minecraft:glass":1,"minecraft:oak_planks":260,"minecraft:spruce_planks":172},"sha256":"b410ca0e7a7244a2e02a7fa74cf2271ba40aa2e7636f19e40100d50e8e01e72a","size":{"x":32,"y":1,"z":32}},{"blockCount":117,"bytes":4460,"file":"chunks/y007-z128-x320.json","offset":{"x":320,"y":7,"z":128},"requirements":{"minecraft:bricks":64,"minecraft:polished_diorite":17,"minecraft:spruce_planks":32,"minecraft:stone_bricks":4},"sha256":"08846baa40cf4632031dfa350b0b10b3253125ea5e215c2ec4a1b09069e57809","size":{"x":32,"y":1,"z":32}},{"blockCount":525,"bytes":8891,"file":"chunks/y007-z128-x352.json","offset":{"x":352,"y":7,"z":128},"requirements":{"minecraft:bricks":223,"minecraft:polished_diorite":212,"minecraft:spruce_planks":29,"minecraft:stone_bricks":61},"sha256":"ad250a43cc1fd8f6ed310ef9a24f4aeb1446a848fb5ffd0ebb51ca6bac963081","size":{"x":32,"y":1,"z":32}},{"blockCount":17,"bytes":776,"file":"chunks/y007-z160-x064.json","offset":{"x":64,"y":7,"z":160},"requirements":{"minecraft:stone_bricks":17},"sha256":"432d3862659c7c20f5af7783c0e3a9bcd4a21f485b739edf0d59277986626416","size":{"x":32,"y":1,"z":32}},{"blockCount":133,"bytes":2611,"file":"chunks/y007-z160-x096.json","offset":{"x":96,"y":7,"z":160},"requirements":{"minecraft:stone_bricks":133},"sha256":"81ebc1c42438964ee5917d6ed6497e1e00b1f8b874e2d9783f1f9eb2d3dc3d3b","size":{"x":32,"y":1,"z":32}},{"blockCount":128,"bytes":2816,"file":"chunks/y007-z160-x128.json","offset":{"x":128,"y":7,"z":160},"requirements":{"minecraft:stone_bricks":128},"sha256":"815d11cef6eaa5842ab935bdee1a6c2fde5817895c730eed6a67dccb7a0ec22c","size":{"x":32,"y":1,"z":32}},{"blockCount":37,"bytes":1843,"file":"chunks/y007-z160-x160.json","offset":{"x":160,"y":7,"z":160},"requirements":{"minecraft:cobbled_deepslate":30,"minecraft:stone_bricks":7},"sha256":"abfc56663065a5191950cc5aa762c7770514258e7b1e3e396014907ecf572654","size":{"x":32,"y":1,"z":32}},{"blockCount":34,"bytes":1505,"file":"chunks/y007-z160-x192.json","offset":{"x":192,"y":7,"z":160},"requirements":{"minecraft:bricks":9,"minecraft:stone_bricks":25},"sha256":"3b299e000615aecc80476736cef251ae81d749418e24f6050e4de445f901fa9c","size":{"x":32,"y":1,"z":32}},{"blockCount":59,"bytes":1956,"file":"chunks/y007-z160-x224.json","offset":{"x":224,"y":7,"z":160},"requirements":{"minecraft:bricks":4,"minecraft:spruce_planks":55},"sha256":"e7b6723066813aaffa0956faf2439be06e7406632a4b3a414d80ebdefe851bd7","size":{"x":32,"y":1,"z":32}},{"blockCount":195,"bytes":4989,"file":"chunks/y007-z160-x256.json","offset":{"x":256,"y":7,"z":160},"requirements":{"minecraft:bricks":29,"minecraft:spruce_planks":151,"minecraft:stone_bricks":15},"sha256":"6d4733d706d330f6f4c329e0cace98c214da4c541e3f047183d31b170dac1adf","size":{"x":32,"y":1,"z":32}},{"blockCount":68,"bytes":2033,"file":"chunks/y007-z160-x288.json","offset":{"x":288,"y":7,"z":160},"requirements":{"minecraft:bricks":6,"minecraft:spruce_planks":52,"minecraft:stone_bricks":10},"sha256":"bccb4d49ef733921bd994c61e8c2b954b3aab1a0eb976749bd088595c6ef855b","size":{"x":32,"y":1,"z":32}},{"blockCount":230,"bytes":5078,"file":"chunks/y007-z160-x320.json","offset":{"x":320,"y":7,"z":160},"requirements":{"minecraft:bricks":45,"minecraft:glass":91,"minecraft:spruce_planks":31,"minecraft:stone_bricks":63},"sha256":"fc0936df9d36a793fd45a1b34c2af31c6819346aa7096140608ecf078e3111f9","size":{"x":32,"y":1,"z":32}},{"blockCount":510,"bytes":12853,"file":"chunks/y007-z160-x352.json","offset":{"x":352,"y":7,"z":160},"requirements":{"minecraft:bricks":131,"minecraft:glass":243,"minecraft:polished_diorite":64,"minecraft:spruce_planks":2,"minecraft:stone_bricks":70},"sha256":"f628615c4f7e4a0b9e17a8d3b628d3bf305d19e251e8774519be845f1a2edbf0","size":{"x":32,"y":1,"z":32}},{"blockCount":33,"bytes":989,"file":"chunks/y007-z192-x096.json","offset":{"x":96,"y":7,"z":192},"requirements":{"minecraft:stone_bricks":33},"sha256":"4120e0d3842eac63b27acb47a57555b4484adb917f948b83c2c958d8c67ca139","size":{"x":32,"y":1,"z":32}},{"blockCount":15,"bytes":875,"file":"chunks/y007-z192-x128.json","offset":{"x":128,"y":7,"z":192},"requirements":{"minecraft:stone_bricks":15},"sha256":"abb6734c3843ddec4c163d5cf2956f999d089f2925938976ce1e9914130c4ca8","size":{"x":32,"y":1,"z":32}},{"blockCount":47,"bytes":1376,"file":"chunks/y007-z192-x160.json","offset":{"x":160,"y":7,"z":192},"requirements":{"minecraft:cobbled_deepslate":43,"minecraft:stone_bricks":4},"sha256":"e75d5c5d78c469ba11385996d78369c16e9a2f5b3fe9d2e8f5698a9ca6da33d4","size":{"x":32,"y":1,"z":32}},{"blockCount":63,"bytes":983,"file":"chunks/y007-z192-x192.json","offset":{"x":192,"y":7,"z":192},"requirements":{"minecraft:cobbled_deepslate":32,"minecraft:stone_bricks":31},"sha256":"0996259366900010ae2189727532d931b3250b63c23ca987c4b55a0140ba4715","size":{"x":32,"y":1,"z":32}},{"blockCount":19,"bytes":650,"file":"chunks/y007-z192-x224.json","offset":{"x":224,"y":7,"z":192},"requirements":{"minecraft:cobbled_deepslate":19},"sha256":"39839b4a038d439188891945be682f2ce110d290cdbe22daaff1c24dc80a9335","size":{"x":32,"y":1,"z":32}},{"blockCount":37,"bytes":1720,"file":"chunks/y007-z192-x256.json","offset":{"x":256,"y":7,"z":192},"requirements":{"minecraft:spruce_planks":8,"minecraft:stone_bricks":29},"sha256":"ff07b66037e2734ab01c7ae60e06c0c4d369249db0dde4f1b6da7690ab258dca","size":{"x":32,"y":1,"z":32}},{"blockCount":25,"bytes":1466,"file":"chunks/y007-z192-x288.json","offset":{"x":288,"y":7,"z":192},"requirements":{"minecraft:oak_planks":4,"minecraft:stone_bricks":21},"sha256":"7de7c02ec7f1a8c05050fdadba943de68cdd1c53f71c4b35d40ad4cc9721fab9","size":{"x":32,"y":1,"z":32}},{"blockCount":240,"bytes":7021,"file":"chunks/y007-z192-x320.json","offset":{"x":320,"y":7,"z":192},"requirements":{"minecraft:glass":160,"minecraft:stone_bricks":80},"sha256":"f7d4c0062306a262443b2352b38ffe8bfe79158656f2ec2261b4b500f04f4048","size":{"x":32,"y":1,"z":32}},{"blockCount":480,"bytes":17325,"file":"chunks/y007-z192-x352.json","offset":{"x":352,"y":7,"z":192},"requirements":{"minecraft:glass":432,"minecraft:stone_bricks":48},"sha256":"f0d6d58b86246142019bc2fb1cdba54b8573d181b3a122371a1ca87a24d38834","size":{"x":32,"y":1,"z":32}},{"blockCount":44,"bytes":1538,"file":"chunks/y007-z224-x256.json","offset":{"x":256,"y":7,"z":224},"requirements":{"minecraft:glass":8,"minecraft:polished_diorite":32,"minecraft:spruce_planks":4},"sha256":"5d7c55080cb13df6f349e81585e8b35256521c3a4c9617b1f5dde56d4c1ab87d","size":{"x":32,"y":1,"z":15}},{"blockCount":8,"bytes":899,"file":"chunks/y007-z224-x288.json","offset":{"x":288,"y":7,"z":224},"requirements":{"minecraft:polished_diorite":8},"sha256":"a708e610d7991a37fe8f7bf0a24011a50999c4ad58227ee0194454c5d1d998b9","size":{"x":32,"y":1,"z":15}},{"blockCount":32,"bytes":914,"file":"chunks/y007-z224-x320.json","offset":{"x":320,"y":7,"z":224},"requirements":{"minecraft:glass":5,"minecraft:stone_bricks":27},"sha256":"163b5230e6074c4847a6b9c570436648a931100ae2b720961e7b08a8d3545f63","size":{"x":32,"y":1,"z":15}},{"blockCount":81,"bytes":1217,"file":"chunks/y007-z224-x352.json","offset":{"x":352,"y":7,"z":224},"requirements":{"minecraft:glass":13,"minecraft:stone_bricks":68},"sha256":"168016e3f6750e591504ef157948efb682797ec18bbd71f82c6fcdc74bb2c7bb","size":{"x":32,"y":1,"z":15}},{"blockCount":1,"bytes":627,"file":"chunks/y007-z224-x384.json","offset":{"x":384,"y":7,"z":224},"requirements":{"minecraft:cobbled_deepslate":1},"sha256":"c49eff748dc9e0b19720dbac5f944121bd2e34e2faa5ac0dc112f1e6e27d93cc","size":{"x":32,"y":1,"z":15}},{"blockCount":25,"bytes":990,"file":"chunks/y008-z000-x320.json","offset":{"x":320,"y":8,"z":0},"requirements":{"minecraft:sandstone":25},"sha256":"eb1a373b9d232a3c0c8ed78fd9623b1647eccb5382d67f2eadbb7140b5eee08a","size":{"x":32,"y":1,"z":32}},{"blockCount":32,"bytes":640,"file":"chunks/y008-z000-x352.json","offset":{"x":352,"y":8,"z":0},"requirements":{"minecraft:sandstone":32},"sha256":"3f24e6262b489cafcf7e2b145fca6e1c4cdb0bfa71ddc32ed391fc05cc3abc88","size":{"x":32,"y":1,"z":32}},{"blockCount":14,"bytes":989,"file":"chunks/y008-z000-x384.json","offset":{"x":384,"y":8,"z":0},"requirements":{"minecraft:sandstone":14},"sha256":"1d5a680df00069f820f860374f27d41679c9fece1e1e9155266d736c97022744","size":{"x":32,"y":1,"z":32}},{"blockCount":118,"bytes":4268,"file":"chunks/y008-z032-x320.json","offset":{"x":320,"y":8,"z":32},"requirements":{"minecraft:bricks":65,"minecraft:glass":8,"minecraft:sandstone":7,"minecraft:spruce_planks":38},"sha256":"87f0b3d60fa54526a640eab151f15d3cafa81498783b4b30c93a9483113540e2","size":{"x":32,"y":1,"z":32}},{"blockCount":65,"bytes":2426,"file":"chunks/y008-z032-x352.json","offset":{"x":352,"y":8,"z":32},"requirements":{"minecraft:bricks":6,"minecraft:glass":18,"minecraft:oak_planks":7,"minecraft:sandstone":3,"minecraft:spruce_planks":31},"sha256":"23b199f49b4e7f1e83cb20294ed308b0fe78658b9897e61acc40e41f98d2024a","size":{"x":32,"y":1,"z":32}},{"blockCount":158,"bytes":3501,"file":"chunks/y008-z032-x384.json","offset":{"x":384,"y":8,"z":32},"requirements":{"minecraft:bricks":17,"minecraft:cobbled_deepslate":5,"minecraft:sandstone":7,"minecraft:spruce_planks":10,"minecraft:stone_bricks":119},"sha256":"7fce451aa2321ed83f7ab7745340abf9269b42bee9bad889af63a2830bae9c59","size":{"x":32,"y":1,"z":32}},{"blockCount":4,"bytes":679,"file":"chunks/y008-z064-x032.json","offset":{"x":32,"y":8,"z":64},"requirements":{"minecraft:stone_bricks":4},"sha256":"4aa8ffca3be3ba60d746a2b179f254869e4015225419db11e658fc798ca3937b","size":{"x":32,"y":1,"z":32}},{"blockCount":156,"bytes":1470,"file":"chunks/y008-z064-x064.json","offset":{"x":64,"y":8,"z":64},"requirements":{"minecraft:stone_bricks":156},"sha256":"cde917e90445a63c4c2d5ff65a1b034549a0205195db6eb53d09394fa7287815","size":{"x":32,"y":1,"z":32}},{"blockCount":98,"bytes":1755,"file":"chunks/y008-z064-x096.json","offset":{"x":96,"y":8,"z":64},"requirements":{"minecraft:stone_bricks":98},"sha256":"dc163769960ab641cdb5fc98a920b02ed7f2504041d294199fffedd9b5c9dd7a","size":{"x":32,"y":1,"z":32}},{"blockCount":24,"bytes":1148,"file":"chunks/y008-z064-x128.json","offset":{"x":128,"y":8,"z":64},"requirements":{"minecraft:stone_bricks":24},"sha256":"f9643f6dc3f67400ff5ce642e8b57ae1f373b05c577c2992990ea4af23dccce5","size":{"x":32,"y":1,"z":32}},{"blockCount":128,"bytes":4196,"file":"chunks/y008-z064-x320.json","offset":{"x":320,"y":8,"z":64},"requirements":{"minecraft:bricks":58,"minecraft:sandstone":32,"minecraft:spruce_planks":22,"minecraft:stone_bricks":16},"sha256":"305c2163be191ec0bfffcef2ba2f1856a097e9c851aa23023e1057690ab3f7d1","size":{"x":32,"y":1,"z":32}},{"blockCount":84,"bytes":1192,"file":"chunks/y008-z064-x352.json","offset":{"x":352,"y":8,"z":64},"requirements":{"minecraft:bricks":6,"minecraft:polished_diorite":27,"minecraft:sandstone":33,"minecraft:spruce_planks":8,"minecraft:stone_bricks":10},"sha256":"f823b4a1d25aa12f83fccc59044f582f2077788a8489d75a32d5378653aa4ca3","size":{"x":32,"y":1,"z":32}},{"blockCount":78,"bytes":1914,"file":"chunks/y008-z064-x384.json","offset":{"x":384,"y":8,"z":64},"requirements":{"minecraft:bricks":9,"minecraft:polished_diorite":4,"minecraft:sandstone":21,"minecraft:spruce_planks":2,"minecraft:stone_bricks":42},"sha256":"f1544344da5a8d255108227a51857326b3c1352a501e50f3b3fb7b561987e7db","size":{"x":32,"y":1,"z":32}},{"blockCount":7,"bytes":756,"file":"chunks/y008-z096-x032.json","offset":{"x":32,"y":8,"z":96},"requirements":{"minecraft:stone_bricks":7},"sha256":"550ee291ce27f42d2e7160fcad05d0fdcf314304db65e8d7010bd3c1456074fb","size":{"x":32,"y":1,"z":32}},{"blockCount":574,"bytes":7432,"file":"chunks/y008-z096-x064.json","offset":{"x":64,"y":8,"z":96},"requirements":{"minecraft:stone_bricks":574},"sha256":"aaa8638486a173f846af5b5b2e79377e92f9e7adef78c66c9a86deb9160314bd","size":{"x":32,"y":1,"z":32}},{"blockCount":238,"bytes":3274,"file":"chunks/y008-z096-x096.json","offset":{"x":96,"y":8,"z":96},"requirements":{"minecraft:stone_bricks":238},"sha256":"35022870ca034d865c342e79dbe78364c9f58e45d4d878abe97dd90a9d7be640","size":{"x":32,"y":1,"z":32}},{"blockCount":299,"bytes":2965,"file":"chunks/y008-z096-x128.json","offset":{"x":128,"y":8,"z":96},"requirements":{"minecraft:stone_bricks":299},"sha256":"e6656d561fda0900299ae3258ff34534dd15c81f8b79fa42aad40855e50d2c62","size":{"x":32,"y":1,"z":32}},{"blockCount":13,"bytes":948,"file":"chunks/y008-z096-x192.json","offset":{"x":192,"y":8,"z":96},"requirements":{"minecraft:bricks":13},"sha256":"600d6942a177fc9d683c06dca40ab0e917e58ae74c8aad1f76b6f5dc6b787278","size":{"x":32,"y":1,"z":32}},{"blockCount":7,"bytes":829,"file":"chunks/y008-z096-x224.json","offset":{"x":224,"y":8,"z":96},"requirements":{"minecraft:bricks":7},"sha256":"3d0ab3956cf3a29fed524dd6fabfe2dc012eb86968af3783b4fe942b13090cd9","size":{"x":32,"y":1,"z":32}},{"blockCount":117,"bytes":2448,"file":"chunks/y008-z096-x256.json","offset":{"x":256,"y":8,"z":96},"requirements":{"minecraft:cobbled_deepslate":44,"minecraft:glass":3,"minecraft:spruce_planks":5,"minecraft:stone_bricks":65},"sha256":"7e51844c38f4a4f9945cf49136c22b5990a6a2253d6b4f690f584030b5a31c6b","size":{"x":32,"y":1,"z":32}},{"blockCount":124,"bytes":2778,"file":"chunks/y008-z096-x288.json","offset":{"x":288,"y":8,"z":96},"requirements":{"minecraft:bricks":18,"minecraft:cobbled_deepslate":39,"minecraft:glass":7,"minecraft:spruce_planks":19,"minecraft:stone_bricks":41},"sha256":"e322ae2a41771b518d66acd669d6151a7b72efa9152dacfd5c9e18a76b4c8486","size":{"x":32,"y":1,"z":32}},{"blockCount":174,"bytes":4329,"file":"chunks/y008-z096-x320.json","offset":{"x":320,"y":8,"z":96},"requirements":{"minecraft:bricks":88,"minecraft:cobbled_deepslate":24,"minecraft:oak_planks":1,"minecraft:polished_diorite":8,"minecraft:sandstone":2,"minecraft:spruce_planks":14,"minecraft:stone_bricks":37},"sha256":"33da20931b4da234e74ab68feef8baa0baf482effb4ae55f42e22b0d3fba705c","size":{"x":32,"y":1,"z":32}},{"blockCount":638,"bytes":1983,"file":"chunks/y008-z096-x352.json","offset":{"x":352,"y":8,"z":96},"requirements":{"minecraft:bricks":364,"minecraft:oak_planks":2,"minecraft:polished_diorite":30,"minecraft:sandstone":4,"minecraft:stone_bricks":238},"sha256":"47d528272cbdd38cb59b9a5e773dc68037dd9b834a28c12daf40a2cbf806d77a","size":{"x":32,"y":1,"z":32}},{"blockCount":3,"bytes":703,"file":"chunks/y008-z096-x384.json","offset":{"x":384,"y":8,"z":96},"requirements":{"minecraft:polished_diorite":3},"sha256":"476c2b74161725154ee26ce9aa254776af91b7430f830358f549b8e80faefb10","size":{"x":32,"y":1,"z":32}},{"blockCount":33,"bytes":1613,"file":"chunks/y008-z128-x032.json","offset":{"x":32,"y":8,"z":128},"requirements":{"minecraft:stone_bricks":33},"sha256":"92c1df4140df233de6f299b213114a3b89672114d553423911326846c3abdae3","size":{"x":32,"y":1,"z":32}},{"blockCount":103,"bytes":2296,"file":"chunks/y008-z128-x064.json","offset":{"x":64,"y":8,"z":128},"requirements":{"minecraft:glass":4,"minecraft:stone_bricks":99},"sha256":"66e33765e5444a1964e76135d8b2c1fe4f0196554e9c6c90f4fccfe57d421894","size":{"x":32,"y":1,"z":32}},{"blockCount":131,"bytes":3048,"file":"chunks/y008-z128-x096.json","offset":{"x":96,"y":8,"z":128},"requirements":{"minecraft:glass":48,"minecraft:sandstone":4,"minecraft:stone_bricks":79},"sha256":"2de0eb33aff49c2167f77a96c612aa9525362f71b0745a1645c0d93769e4dc94","size":{"x":32,"y":1,"z":32}},{"blockCount":91,"bytes":2618,"file":"chunks/y008-z128-x128.json","offset":{"x":128,"y":8,"z":128},"requirements":{"minecraft:stone_bricks":91},"sha256":"96fe6591e4971768f9b184a266e297d2279126c85e1dd186dea4a9195d9b1fdc","size":{"x":32,"y":1,"z":32}},{"blockCount":65,"bytes":1456,"file":"chunks/y008-z128-x160.json","offset":{"x":160,"y":8,"z":128},"requirements":{"minecraft:cobbled_deepslate":21,"minecraft:stone_bricks":44},"sha256":"491df651139985a180a3de8926096b25c937c671f562b49ec5d5ed3e15da2e93","size":{"x":32,"y":1,"z":32}},{"blockCount":113,"bytes":2674,"file":"chunks/y008-z128-x192.json","offset":{"x":192,"y":8,"z":128},"requirements":{"minecraft:bricks":14,"minecraft:cobbled_deepslate":10,"minecraft:stone_bricks":89},"sha256":"e9328c197718e7d0b328ba68fc7ce7596d9bacff45b10d8cade5c9140712eeee","size":{"x":32,"y":1,"z":32}},{"blockCount":104,"bytes":2903,"file":"chunks/y008-z128-x224.json","offset":{"x":224,"y":8,"z":128},"requirements":{"minecraft:bricks":25,"minecraft:polished_diorite":2,"minecraft:spruce_planks":20,"minecraft:stone_bricks":57},"sha256":"4fc7dcf2c8a69afc0a5d1555f37b46831525a31522dc4ed23bd53ab81d939cc1","size":{"x":32,"y":1,"z":32}},{"blockCount":204,"bytes":3789,"file":"chunks/y008-z128-x256.json","offset":{"x":256,"y":8,"z":128},"requirements":{"minecraft:cobbled_deepslate":23,"minecraft:polished_diorite":6,"minecraft:spruce_planks":76,"minecraft:stone_bricks":99},"sha256":"11d4029749ccec3d931bb1a0934781642378b09428f029d4a0c636eecd1b74cd","size":{"x":32,"y":1,"z":32}},{"blockCount":224,"bytes":4593,"file":"chunks/y008-z128-x288.json","offset":{"x":288,"y":8,"z":128},"requirements":{"minecraft:bricks":35,"minecraft:cobbled_deepslate":104,"minecraft:glass":4,"minecraft:spruce_planks":80,"minecraft:stone_bricks":1},"sha256":"da3c78a06b1a5cd8254f7f004507b3918ff0993ce6cd07db70ddb1ba893e35b3","size":{"x":32,"y":1,"z":32}},{"blockCount":73,"bytes":3400,"file":"chunks/y008-z128-x320.json","offset":{"x":320,"y":8,"z":128},"requirements":{"minecraft:bricks":32,"minecraft:cobbled_deepslate":32,"minecraft:glass":1,"minecraft:polished_diorite":4,"minecraft:stone_bricks":4},"sha256":"6070198a39bd565f9f5eee6f90ce191d5d792d1a515ea3801bfe882a9fd7c48c","size":{"x":32,"y":1,"z":32}},{"blockCount":64,"bytes":1844,"file":"chunks/y008-z128-x352.json","offset":{"x":352,"y":8,"z":128},"requirements":{"minecraft:bricks":64},"sha256":"6b2de9388623f7c124525211d7d4ded15df197d1c1bc8106f7abcca2a19c776a","size":{"x":32,"y":1,"z":32}},{"blockCount":4,"bytes":680,"file":"chunks/y008-z160-x032.json","offset":{"x":32,"y":8,"z":160},"requirements":{"minecraft:stone_bricks":4},"sha256":"dda5350a86e5abd324a30e90c81757a0d660459f4841492586d62a1e263cd8ae","size":{"x":32,"y":1,"z":32}},{"blockCount":642,"bytes":7208,"file":"chunks/y008-z160-x064.json","offset":{"x":64,"y":8,"z":160},"requirements":{"minecraft:stone_bricks":642},"sha256":"49a884d3d8e3f3caa24c7244700e10167fe78f457a85cd0bac8f3aeecd25378c","size":{"x":32,"y":1,"z":32}},{"blockCount":242,"bytes":3371,"file":"chunks/y008-z160-x096.json","offset":{"x":96,"y":8,"z":160},"requirements":{"minecraft:stone_bricks":242},"sha256":"a5c11731e0b616825a4ab72a979c4039f2d5dd546ff6c79e41dc03c349491fc7","size":{"x":32,"y":1,"z":32}},{"blockCount":270,"bytes":2474,"file":"chunks/y008-z160-x128.json","offset":{"x":128,"y":8,"z":160},"requirements":{"minecraft:stone_bricks":270},"sha256":"ee131a0a22980f650d1292d0b820372e21be09a58dfd1c7727752c4da34398ad","size":{"x":32,"y":1,"z":32}},{"blockCount":45,"bytes":2153,"file":"chunks/y008-z160-x160.json","offset":{"x":160,"y":8,"z":160},"requirements":{"minecraft:cobbled_deepslate":30,"minecraft:stone_bricks":15},"sha256":"7a1f45da5bdaa47205fe789bfa3e74fd597b8fb406f6970cc6fcacc80e976f3b","size":{"x":32,"y":1,"z":32}},{"blockCount":40,"bytes":1392,"file":"chunks/y008-z160-x192.json","offset":{"x":192,"y":8,"z":160},"requirements":{"minecraft:bricks":8,"minecraft:stone_bricks":32},"sha256":"627b69a8dcb698b04152c17926efc2ab757148994e6cbe87d0fcebfc69633ae2","size":{"x":32,"y":1,"z":32}},{"blockCount":62,"bytes":1994,"file":"chunks/y008-z160-x224.json","offset":{"x":224,"y":8,"z":160},"requirements":{"minecraft:bricks":7,"minecraft:spruce_planks":55},"sha256":"e79ee7b10093eafb48efdee778bd6e7e563c9d94e9261cd6ccb02604cd8ac912","size":{"x":32,"y":1,"z":32}},{"blockCount":195,"bytes":4989,"file":"chunks/y008-z160-x256.json","offset":{"x":256,"y":8,"z":160},"requirements":{"minecraft:bricks":29,"minecraft:spruce_planks":151,"minecraft:stone_bricks":15},"sha256":"9e0eba5b837565ea02ef65d1c247486c1473cb094f6169b2e4cb46c85d03a440","size":{"x":32,"y":1,"z":32}},{"blockCount":67,"bytes":2065,"file":"chunks/y008-z160-x288.json","offset":{"x":288,"y":8,"z":160},"requirements":{"minecraft:bricks":7,"minecraft:cobbled_deepslate":7,"minecraft:spruce_planks":43,"minecraft:stone_bricks":10},"sha256":"4612dae19a7930e96510d6785d5f11109701d7e60d43b702c26aeae5f17eb311","size":{"x":32,"y":1,"z":32}},{"blockCount":149,"bytes":2626,"file":"chunks/y008-z160-x320.json","offset":{"x":320,"y":8,"z":160},"requirements":{"minecraft:bricks":43,"minecraft:cobbled_deepslate":25,"minecraft:glass":14,"minecraft:sandstone":1,"minecraft:spruce_planks":4,"minecraft:stone_bricks":62},"sha256":"35863715a051681103806853283c7c9d51e1b9e58edc6574e3cecdb757f35319","size":{"x":32,"y":1,"z":32}},{"blockCount":173,"bytes":2557,"file":"chunks/y008-z160-x352.json","offset":{"x":352,"y":8,"z":160},"requirements":{"minecraft:bricks":83,"minecraft:glass":22,"minecraft:stone_bricks":68},"sha256":"aba2698d63c09773226155c29bfdb51ffe1185212a848f72b77a847a03e922f1","size":{"x":32,"y":1,"z":32}},{"blockCount":35,"bytes":876,"file":"chunks/y008-z192-x064.json","offset":{"x":64,"y":8,"z":192},"requirements":{"minecraft:stone_bricks":35},"sha256":"7efdf3cf12eddd4f920a193371f262e80b2aafedc14b769d2940cd974710676a","size":{"x":32,"y":1,"z":32}},{"blockCount":61,"bytes":1197,"file":"chunks/y008-z192-x096.json","offset":{"x":96,"y":8,"z":192},"requirements":{"minecraft:stone_bricks":61},"sha256":"95971faa7f615962ae2be653df2b9cc95526d6e6ddbf1c23e3b085cb079f73f3","size":{"x":32,"y":1,"z":32}},{"blockCount":15,"bytes":875,"file":"chunks/y008-z192-x128.json","offset":{"x":128,"y":8,"z":192},"requirements":{"minecraft:stone_bricks":15},"sha256":"ce6a5eaf1f533ff637e9aed1e3d656c535bbeee34fadcfa997fc6966f3c590ad","size":{"x":32,"y":1,"z":32}},{"blockCount":54,"bytes":1531,"file":"chunks/y008-z192-x160.json","offset":{"x":160,"y":8,"z":192},"requirements":{"minecraft:cobbled_deepslate":43,"minecraft:stone_bricks":11},"sha256":"f176b9e35a32650a38abf322bcffe924433cd5e5ee5543600ea994fae80368b0","size":{"x":32,"y":1,"z":32}},{"blockCount":61,"bytes":1021,"file":"chunks/y008-z192-x192.json","offset":{"x":192,"y":8,"z":192},"requirements":{"minecraft:cobbled_deepslate":32,"minecraft:stone_bricks":29},"sha256":"c43a1d3c5004e35a649bf40b53d5fad11b2346cd5fb9392c854e934540acc56c","size":{"x":32,"y":1,"z":32}},{"blockCount":19,"bytes":650,"file":"chunks/y008-z192-x224.json","offset":{"x":224,"y":8,"z":192},"requirements":{"minecraft:cobbled_deepslate":19},"sha256":"e7f3a31e725bc8b8d5793d1026543e0cfaccc4944e9f28a3bbb961ad3bf79a68","size":{"x":32,"y":1,"z":32}},{"blockCount":30,"bytes":1643,"file":"chunks/y008-z192-x256.json","offset":{"x":256,"y":8,"z":192},"requirements":{"minecraft:spruce_planks":1,"minecraft:stone_bricks":29},"sha256":"f9f186da919d57347c5d28eabb46489f3aae0056447bdcacae2c0bb6e6f14637","size":{"x":32,"y":1,"z":32}},{"blockCount":24,"bytes":1475,"file":"chunks/y008-z192-x288.json","offset":{"x":288,"y":8,"z":192},"requirements":{"minecraft:oak_planks":2,"minecraft:spruce_planks":1,"minecraft:stone_bricks":21},"sha256":"3686bd15f93fb69f88d6de8c2420cbcaf90fecb7d43215ceeb6575afcb63590a","size":{"x":32,"y":1,"z":32}},{"blockCount":96,"bytes":2175,"file":"chunks/y008-z192-x320.json","offset":{"x":320,"y":8,"z":192},"requirements":{"minecraft:glass":16,"minecraft:stone_bricks":80},"sha256":"a1b7b39f2f016388d5b755e3139042daa4b390c6fcd0176a26bb40d700c72642","size":{"x":32,"y":1,"z":32}},{"blockCount":64,"bytes":2175,"file":"chunks/y008-z192-x352.json","offset":{"x":352,"y":8,"z":192},"requirements":{"minecraft:glass":16,"minecraft:stone_bricks":48},"sha256":"d001ea5db702e92c57bb635e382bd91a9e86bab5e6fa12b6df20ff1f4bba68c4","size":{"x":32,"y":1,"z":32}},{"blockCount":14,"bytes":1059,"file":"chunks/y008-z224-x256.json","offset":{"x":256,"y":8,"z":224},"requirements":{"minecraft:spruce_planks":10,"minecraft:stone_bricks":4},"sha256":"43ac4bbf342173acdf00431347187b9200e3d9adad783c6d22a5feaaa9665fe0","size":{"x":32,"y":1,"z":15}},{"blockCount":9,"bytes":954,"file":"chunks/y008-z224-x288.json","offset":{"x":288,"y":8,"z":224},"requirements":{"minecraft:spruce_planks":9},"sha256":"ed01e0c2bdf81733abd6b98d65c9ac6f7ccebf7a29b6c44f95435fdbdb6eb051","size":{"x":32,"y":1,"z":15}},{"blockCount":32,"bytes":914,"file":"chunks/y008-z224-x320.json","offset":{"x":320,"y":8,"z":224},"requirements":{"minecraft:glass":5,"minecraft:stone_bricks":27},"sha256":"146120eaca903f64612af0a18f22b5ef7f9afb8f266b237ee01fad76f4f37fb5","size":{"x":32,"y":1,"z":15}},{"blockCount":81,"bytes":1217,"file":"chunks/y008-z224-x352.json","offset":{"x":352,"y":8,"z":224},"requirements":{"minecraft:glass":13,"minecraft:stone_bricks":68},"sha256":"7159809c50582ab0ff5fda505b618ad1f4e28075ebb6c69c5f3175dbabc4bce1","size":{"x":32,"y":1,"z":15}},{"blockCount":1,"bytes":619,"file":"chunks/y008-z224-x384.json","offset":{"x":384,"y":8,"z":224},"requirements":{"minecraft:sandstone":1},"sha256":"b34068e5d210220821fe701e8611ae4274055d2ceb83007e712c3f73bb8bbc19","size":{"x":32,"y":1,"z":15}},{"blockCount":25,"bytes":990,"file":"chunks/y009-z000-x320.json","offset":{"x":320,"y":9,"z":0},"requirements":{"minecraft:sandstone":25},"sha256":"0d16d3a7de3e443ec948c2d18613275ebf7b80802b80ea018f3c49443758f3fb","size":{"x":32,"y":1,"z":32}},{"blockCount":32,"bytes":640,"file":"chunks/y009-z000-x352.json","offset":{"x":352,"y":9,"z":0},"requirements":{"minecraft:sandstone":32},"sha256":"a2fbbc5046eaa2f55042d6626266d35bf49a05b7d6d759232eb9498bfbc1970c","size":{"x":32,"y":1,"z":32}},{"blockCount":14,"bytes":989,"file":"chunks/y009-z000-x384.json","offset":{"x":384,"y":9,"z":0},"requirements":{"minecraft:sandstone":14},"sha256":"1d3e93ef6def0f6bed3c78f118f583f4f7bb5af7b15c5a36b5bf14faef58231a","size":{"x":32,"y":1,"z":32}},{"blockCount":121,"bytes":4230,"file":"chunks/y009-z032-x320.json","offset":{"x":320,"y":9,"z":32},"requirements":{"minecraft:bricks":65,"minecraft:glass":8,"minecraft:sandstone":7,"minecraft:spruce_planks":41},"sha256":"d7dba12052ea3336d71ca34ebec03e264b69a72aaa43dc9f7c777688272242c2","size":{"x":32,"y":1,"z":32}}],"schema":1}
