{"entries":[{"blockCount":63,"bytes":2388,"file":"chunks/y009-z032-x352.json","offset":{"x":352,"y":9,"z":32},"requirements":{"minecraft:bricks":6,"minecraft:glass":18,"minecraft:oak_planks":5,"minecraft:sandstone":3,"minecraft:spruce_planks":31},"sha256":"002a9e0ac30da6f4a53275264ce8db9c59459aebb1333ee0585d8ac80f6365bf","size":{"x":32,"y":1,"z":32}},{"blockCount":162,"bytes":3577,"file":"chunks/y009-z032-x384.json","offset":{"x":384,"y":9,"z":32},"requirements":{"minecraft:bricks":17,"minecraft:cobbled_deepslate":5,"minecraft:sandstone":7,"minecraft:spruce_planks":10,"minecraft:stone_bricks":123},"sha256":"ba6cdbe6d21833d34fe7b299a025376cf21a783d972794c81225373876200e8a","size":{"x":32,"y":1,"z":32}},{"blockCount":8,"bytes":737,"file":"chunks/y009-z064-x032.json","offset":{"x":32,"y":9,"z":64},"requirements":{"minecraft:stone_bricks":8},"sha256":"1ab63fd0409343c6c2d4435af2d68e5ed5e19a494ec6e2cfd52f604f911ccb3e","size":{"x":32,"y":1,"z":32}},{"blockCount":58,"bytes":1201,"file":"chunks/y009-z064-x064.json","offset":{"x":64,"y":9,"z":64},"requirements":{"minecraft:bricks":1,"minecraft:stone_bricks":57},"sha256":"c1e717da019e5d62e4a1a4ba066327eab80b943212a8bbc95fa50ef50902d992","size":{"x":32,"y":1,"z":32}},{"blockCount":53,"bytes":1565,"file":"chunks/y009-z064-x096.json","offset":{"x":96,"y":9,"z":64},"requirements":{"minecraft:stone_bricks":53},"sha256":"ed8c6e9a84d61ca446e9104e630a01a16624e59b340003733df4433942581c33","size":{"x":32,"y":1,"z":32}},{"blockCount":24,"bytes":1148,"file":"chunks/y009-z064-x128.json","offset":{"x":128,"y":9,"z":64},"requirements":{"minecraft:stone_bricks":24},"sha256":"4d88f7b0eddd4c23b6febb1bacff897862d4378a25b746f526641f58d54e97a3","size":{"x":32,"y":1,"z":32}},{"blockCount":136,"bytes":4192,"file":"chunks/y009-z064-x320.json","offset":{"x":320,"y":9,"z":64},"requirements":{"minecraft:bricks":58,"minecraft:sandstone":32,"minecraft:spruce_planks":30,"minecraft:stone_bricks":16},"sha256":"aab2e732d6729b7ac2d8fce922f23d0d53a40596ff117d094be7045534d146c6","size":{"x":32,"y":1,"z":32}},{"blockCount":85,"bytes":1230,"file":"chunks/y009-z064-x352.json","offset":{"x":352,"y":9,"z":64},"requirements":{"minecraft:bricks":6,"minecraft:polished_diorite":27,"minecraft:sandstone":34,"minecraft:spruce_planks":8,"minecraft:stone_bricks":10},"sha256":"0cc5f48ef4725c96cb6d6f10e63c79c9df831299494b4cbd2ebb9a4e82559e96","size":{"x":32,"y":1,"z":32}},{"blockCount":78,"bytes":1914,"file":"chunks/y009-z064-x384.json","offset":{"x":384,"y":9,"z":64},"requirements":{"minecraft:bricks":9,"minecraft:polished_diorite":4,"minecraft:sandstone":21,"minecraft:spruce_planks":2,"minecraft:stone_bricks":42},"sha256":"8d9329e98fc77bce24e5bf5fa41cf5a517ad4f6b25d9e6dfa2db4ff1bcf22020","size":{"x":32,"y":1,"z":32}},{"blockCount":72,"bytes":1848,"file":"chunks/y009-z096-x032.json","offset":{"x":32,"y":9,"z":96},"requirements":{"minecraft:stone_bricks":72},"sha256":"3a7da3f3575575811df7297f83ba12427665782e7ffa13c50f2e7690bbabeaee","size":{"x":32,"y":1,"z":32}},{"blockCount":269,"bytes":4143,"file":"chunks/y009-z096-x064.json","offset":{"x":64,"y":9,"z":96},"requirements":{"minecraft:bricks":3,"minecraft:glass":3,"minecraft:stone_bricks":263},"sha256":"c2e22c39a82546fd61abe06a93a3a7983880a54b02032a52e549dd796b4f790e","size":{"x":32,"y":1,"z":32}},{"blockCount":184,"bytes":3236,"file":"chunks/y009-z096-x096.json","offset":{"x":96,"y":9,"z":96},"requirements":{"minecraft:glass":3,"minecraft:stone_bricks":181},"sha256":"2dff3a534af070f2ccd3c52ffabd5622a3d0c0004657146a09dd431533c31828","size":{"x":32,"y":1,"z":32}},{"blockCount":179,"bytes":2962,"file":"chunks/y009-z096-x128.json","offset":{"x":128,"y":9,"z":96},"requirements":{"minecraft:stone_bricks":179},"sha256":"0a1cbd8bbebc0563d3f8457925a068e7c0dd56be049c05431f3df4985f6f943e","size":{"x":32,"y":1,"z":32}},{"blockCount":10,"bytes":946,"file":"chunks/y009-z096-x192.json","offset":{"x":192,"y":9,"z":96},"requirements":{"minecraft:bricks":10},"sha256":"499e44d7061785a8a3d7d5e56177346cb309a12210e905094a3b875057a092c8","size":{"x":32,"y":1,"z":32}},{"blockCount":24,"bytes":1131,"file":"chunks/y009-z096-x224.json","offset":{"x":224,"y":9,"z":96},"requirements":{"minecraft:bricks":11,"minecraft:polished_diorite":13},"sha256":"ab64189a2923f6d7db62d9eb501956d5d6c5639a7e74b97e1e05f5220ca4a9e1","size":{"x":32,"y":1,"z":32}},{"blockCount":156,"bytes":2625,"file":"chunks/y009-z096-x256.json","offset":{"x":256,"y":9,"z":96},"requirements":{"minecraft:cobbled_deepslate":12,"minecraft:glass":3,"minecraft:polished_diorite":70,"minecraft:spruce_planks":5,"minecraft:stone_bricks":66},"sha256":"8f904b3600ead4371436cab5aa006b5fb32cba9871cb633916fbfd8baef28878","size":{"x":32,"y":1,"z":32}},{"blockCount":139,"bytes":2922,"file":"chunks/y009-z096-x288.json","offset":{"x":288,"y":9,"z":96},"requirements":{"minecraft:bricks":2,"minecraft:cobbled_deepslate":42,"minecraft:glass":3,"minecraft:polished_diorite":35,"minecraft:spruce_planks":16,"minecraft:stone_bricks":41},"sha256":"640683bf21dc9c63314daea8aabe47b777a59718f6cf0ac96a3e31a893b7fc9c","size":{"x":32,"y":1,"z":32}},{"blockCount":183,"bytes":4337,"file":"chunks/y009-z096-x320.json","offset":{"x":320,"y":9,"z":96},"requirements":{"minecraft:bricks":85,"minecraft:cobbled_deepslate":36,"minecraft:polished_diorite":2,"minecraft:sandstone":1,"minecraft:spruce_planks":25,"minecraft:stone_bricks":34},"sha256":"5bf88278807a0706acdf3fe706f9ac8c8361f60943c60f1a73a56b2882e98c0c","size":{"x":32,"y":1,"z":32}},{"blockCount":636,"bytes":2025,"file":"chunks/y009-z096-x352.json","offset":{"x":352,"y":9,"z":96},"requirements":{"minecraft:bricks":363,"minecraft:polished_diorite":29,"minecraft:sandstone":4,"minecraft:spruce_planks":2,"minecraft:stone_bricks":238},"sha256":"55db8c93e5791a2633a348f68fd16653014641bab55dccda5a23f61c544cd2de","size":{"x":32,"y":1,"z":32}},{"blockCount":3,"bytes":703,"file":"chunks/y009-z096-x384.json","offset":{"x":384,"y":9,"z":96},"requirements":{"minecraft:polished_diorite":3},"sha256":"0d180114e08c345ff0c39f3707be2af5933f7e05a845f7eb388a7202c0747e0a","size":{"x":32,"y":1,"z":32}},{"blockCount":48,"bytes":1786,"file":"chunks/y009-z128-x032.json","offset":{"x":32,"y":9,"z":128},"requirements":{"minecraft:stone_bricks":48},"sha256":"4e33adb47888c73013da3d5296b6a265c4015752ce3a3efdd654a1b3996f805f","size":{"x":32,"y":1,"z":32}},{"blockCount":105,"bytes":2336,"file":"chunks/y009-z128-x064.json","offset":{"x":64,"y":9,"z":128},"requirements":{"minecraft:glass":5,"minecraft:stone_bricks":100},"sha256":"d2f3059c7a8e5e53ef369b6b5bc705abdfb29357c96ec1b0b0799ec701e4a6bc","size":{"x":32,"y":1,"z":32}},{"blockCount":136,"bytes":2971,"file":"chunks/y009-z128-x096.json","offset":{"x":96,"y":9,"z":128},"requirements":{"minecraft:glass":32,"minecraft:stone_bricks":104},"sha256":"28eb534006e1c5d06e17e752d3eb1f47ad738278a76da57a1c0279ba5a776b41","size":{"x":32,"y":1,"z":32}},{"blockCount":102,"bytes":2543,"file":"chunks/y009-z128-x128.json","offset":{"x":128,"y":9,"z":128},"requirements":{"minecraft:stone_bricks":102},"sha256":"962af48c1540132ced57d48bbe75324656515299f8c103bd1af311de3802f2bd","size":{"x":32,"y":1,"z":32}},{"blockCount":69,"bytes":1495,"file":"chunks/y009-z128-x160.json","offset":{"x":160,"y":9,"z":128},"requirements":{"minecraft:cobbled_deepslate":21,"minecraft:stone_bricks":48},"sha256":"975444ec6fd0c97d12d15e35d2d10612d72493694aa4f0118b27d41ab8721747","size":{"x":32,"y":1,"z":32}},{"blockCount":108,"bytes":2553,"file":"chunks/y009-z128-x192.json","offset":{"x":192,"y":9,"z":128},"requirements":{"minecraft:bricks":11,"minecraft:cobbled_deepslate":10,"minecraft:stone_bricks":87},"sha256":"b6b17db819e8aa55cfa169bd06b4c8140b2a797c7489b78a1801fce1b64e1431","size":{"x":32,"y":1,"z":32}},{"blockCount":143,"bytes":4047,"file":"chunks/y009-z128-x224.json","offset":{"x":224,"y":9,"z":128},"requirements":{"minecraft:bricks":20,"minecraft:polished_diorite":45,"minecraft:spruce_planks":20,"minecraft:stone_bricks":58},"sha256":"8543cd8d6b961c2a43e7820d3d0d33609c25be3cb1d1364731d42bc4d418792c","size":{"x":32,"y":1,"z":32}},{"blockCount":222,"bytes":4757,"file":"chunks/y009-z128-x256.json","offset":{"x":256,"y":9,"z":128},"requirements":{"minecraft:cobbled_deepslate":30,"minecraft:polished_diorite":45,"minecraft:spruce_planks":53,"minecraft:stone_bricks":94},"sha256":"292f2ed716ee00aa2a228d47395b8ccfd408e204f1054949cdca73aff3d413be","size":{"x":32,"y":1,"z":32}},{"blockCount":121,"bytes":4014,"file":"chunks/y009-z128-x288.json","offset":{"x":288,"y":9,"z":128},"requirements":{"minecraft:cobbled_deepslate":90,"minecraft:glass":9,"minecraft:spruce_planks":22},"sha256":"757969a9fa3e130312c2f99ec1038b1e5083a4c7cf97c867c421b44651204984","size":{"x":32,"y":1,"z":32}},{"blockCount":75,"bytes":3399,"file":"chunks/y009-z128-x320.json","offset":{"x":320,"y":9,"z":128},"requirements":{"minecraft:bricks":32,"minecraft:cobbled_deepslate":32,"minecraft:glass":3,"minecraft:polished_diorite":4,"minecraft:stone_bricks":4},"sha256":"8ff67c4bedc88fe1926979fd00edc5f6fbbab3f7b216e39bdcd481a7f7e147d7","size":{"x":32,"y":1,"z":32}},{"blockCount":64,"bytes":1844,"file":"chunks/y009-z128-x352.json","offset":{"x":352,"y":9,"z":128},"requirements":{"minecraft:bricks":64},"sha256":"f76f4dcccaacc2f7dd0cc014b4a843bbb0ed554633d4bb96f09adbc9138d7d57","size":{"x":32,"y":1,"z":32}},{"blockCount":60,"bytes":1733,"file":"chunks/y009-z160-x032.json","offset":{"x":32,"y":9,"z":160},"requirements":{"minecraft:stone_bricks":60},"sha256":"a1806caaf9f5af7e684406d1b58d28443482c62cf475afcd9490beea454b3d59","size":{"x":32,"y":1,"z":32}},{"blockCount":262,"bytes":3651,"file":"chunks/y009-z160-x064.json","offset":{"x":64,"y":9,"z":160},"requirements":{"minecraft:glass":3,"minecraft:stone_bricks":259},"sha256":"57f0b2fe544b6de2072fcd05f0b5b2c2eb6e7df6a72e4744d267ac0eb0af3932","size":{"x":32,"y":1,"z":32}},{"blockCount":149,"bytes":3139,"file":"chunks/y009-z160-x096.json","offset":{"x":96,"y":9,"z":160},"requirements":{"minecraft:stone_bricks":149},"sha256":"6a555d9f730458124c9c8e685cd20b62269280b9f9cda7cd939b14485a6c819d","size":{"x":32,"y":1,"z":32}},{"blockCount":135,"bytes":2623,"file":"chunks/y009-z160-x128.json","offset":{"x":128,"y":9,"z":160},"requirements":{"minecraft:stone_bricks":135},"sha256":"e0c39f2b753625cf9391941a6d36dd2c1c1ed350e4275062160c10dcec304b9f","size":{"x":32,"y":1,"z":32}},{"blockCount":51,"bytes":2379,"file":"chunks/y009-z160-x160.json","offset":{"x":160,"y":9,"z":160},"requirements":{"minecraft:cobbled_deepslate":30,"minecraft:stone_bricks":21},"sha256":"61b43c004d44fd59516afabc0f05bc225319d04591b8b8895322d16d41cb7ae8","size":{"x":32,"y":1,"z":32}},{"blockCount":53,"bytes":1655,"file":"chunks/y009-z160-x192.json","offset":{"x":192,"y":9,"z":160},"requirements":{"minecraft:bricks":9,"minecraft:stone_bricks":44},"sha256":"3a70b88dfdd1e5b7994f1fe34e5b7b716b4fc82e4206264555d1ea2b4e4035c9","size":{"x":32,"y":1,"z":32}},{"blockCount":60,"bytes":1974,"file":"chunks/y009-z160-x224.json","offset":{"x":224,"y":9,"z":160},"requirements":{"minecraft:bricks":5,"minecraft:spruce_planks":55},"sha256":"786d56735f707a4a8f5460076553ff6a902c9aeafd4ad2c4e9c6029580cc21bf","size":{"x":32,"y":1,"z":32}},{"blockCount":195,"bytes":4989,"file":"chunks/y009-z160-x256.json","offset":{"x":256,"y":9,"z":160},"requirements":{"minecraft:bricks":29,"minecraft:spruce_planks":151,"minecraft:stone_bricks":15},"sha256":"db4de14bf8091a6b28f5ef74809826b42f732a9023b97c68870fe158ee659474","size":{"x":32,"y":1,"z":32}},{"blockCount":61,"bytes":2069,"file":"chunks/y009-z160-x288.json","offset":{"x":288,"y":9,"z":160},"requirements":{"minecraft:cobbled_deepslate":7,"minecraft:oak_planks":1,"minecraft:spruce_planks":43,"minecraft:stone_bricks":10},"sha256":"9ad66ec4e3ea74ce9bb328c62b322da66a4c445f4c12c96ce8de610dab7c2d9d","size":{"x":32,"y":1,"z":32}},{"blockCount":160,"bytes":3078,"file":"chunks/y009-z160-x320.json","offset":{"x":320,"y":9,"z":160},"requirements":{"minecraft:bricks":20,"minecraft:cobbled_deepslate":25,"minecraft:glass":14,"minecraft:polished_diorite":34,"minecraft:sandstone":3,"minecraft:spruce_planks":4,"minecraft:stone_bricks":60},"sha256":"00f5e1c32b12e2040d024e96288471b3a7e54fe73d9e69538bc6537c84f52d87","size":{"x":32,"y":1,"z":32}},{"blockCount":169,"bytes":2671,"file":"chunks/y009-z160-x352.json","offset":{"x":352,"y":9,"z":160},"requirements":{"minecraft:bricks":81,"minecraft:glass":22,"minecraft:stone_bricks":66},"sha256":"0b83246787d6f0297513977b4b55869f110c2816feddfb925eabde35d01d84c5","size":{"x":32,"y":1,"z":32}},{"blockCount":5,"bytes":641,"file":"chunks/y009-z192-x064.json","offset":{"x":64,"y":9,"z":192},"requirements":{"minecraft:stone_bricks":5},"sha256":"fc16aadfefe2e283f1dc0dc50f926cc8405de5fc05370ca182bca22a2f50e008","size":{"x":32,"y":1,"z":32}},{"blockCount":37,"bytes":1008,"file":"chunks/y009-z192-x096.json","offset":{"x":96,"y":9,"z":192},"requirements":{"minecraft:stone_bricks":37},"sha256":"140509605b367a8cd02a12db744b0ed85fdad887774298e9d149da6c8f53f9b8","size":{"x":32,"y":1,"z":32}},{"blockCount":15,"bytes":875,"file":"chunks/y009-z192-x128.json","offset":{"x":128,"y":9,"z":192},"requirements":{"minecraft:stone_bricks":15},"sha256":"7438a0b6518c7ab742eff6e1424a45458c805e25e3fc93448d3c5e7dd6f351f0","size":{"x":32,"y":1,"z":32}},{"blockCount":53,"bytes":1609,"file":"chunks/y009-z192-x160.json","offset":{"x":160,"y":9,"z":192},"requirements":{"minecraft:cobbled_deepslate":43,"minecraft:stone_bricks":10},"sha256":"675a0ea6ccaaace0f8d87e9ddef955535d1cc96bab744cdde62cbb2c61e5f665","size":{"x":32,"y":1,"z":32}},{"blockCount":61,"bytes":1058,"file":"chunks/y009-z192-x192.json","offset":{"x":192,"y":9,"z":192},"requirements":{"minecraft:cobbled_deepslate":32,"minecraft:stone_bricks":29},"sha256":"2d48a06890e45f01c241ada8f3e248357fd93b9d0fc3d9c33c78fa101ff6a3dd","size":{"x":32,"y":1,"z":32}},{"blockCount":19,"bytes":650,"file":"chunks/y009-z192-x224.json","offset":{"x":224,"y":9,"z":192},"requirements":{"minecraft:cobbled_deepslate":19},"sha256":"30a6253e2ac403209eb314280dad100c01e6f3ff938d557d2e092a81cadb9e19","size":{"x":32,"y":1,"z":32}},{"blockCount":29,"bytes":1576,"file":"chunks/y009-z192-x256.json","offset":{"x":256,"y":9,"z":192},"requirements":{"minecraft:stone_bricks":29},"sha256":"fba4bcb29cd04dd9fd719b3eabffbfbe8787cae117a8ac62b3c942bd09c5760f","size":{"x":32,"y":1,"z":32}},{"blockCount":21,"bytes":1306,"file":"chunks/y009-z192-x288.json","offset":{"x":288,"y":9,"z":192},"requirements":{"minecraft:stone_bricks":21},"sha256":"ac0f74d21f3d3f6b47ae69cc82d4acb0a7ecfcd2a4f9b7a5f4d3286addbe1089","size":{"x":32,"y":1,"z":32}},{"blockCount":96,"bytes":2175,"file":"chunks/y009-z192-x320.json","offset":{"x":320,"y":9,"z":192},"requirements":{"minecraft:glass":16,"minecraft:stone_bricks":80},"sha256":"ce1089f664a2ec50b894f0e2f3f22445425596a6083e675e617bdf900c5af9a1","size":{"x":32,"y":1,"z":32}},{"blockCount":65,"bytes":2214,"file":"chunks/y009-z192-x352.json","offset":{"x":352,"y":9,"z":192},"requirements":{"minecraft:glass":16,"minecraft:stone_bricks":49},"sha256":"ca339fb8dbe9938d65f0bea77d4083bcf9a2371e985b11c01dbea42208322d0d","size":{"x":32,"y":1,"z":32}},{"blockCount":16,"bytes":1175,"file":"chunks/y009-z224-x256.json","offset":{"x":256,"y":9,"z":224},"requirements":{"minecraft:cobbled_deepslate":8,"minecraft:stone_bricks":8},"sha256":"c65fd9af251be5aeedd6ee1df6ddd9fcd593970f3405f5d41acb2bee83b52220","size":{"x":32,"y":1,"z":15}},{"blockCount":8,"bytes":919,"file":"chunks/y009-z224-x288.json","offset":{"x":288,"y":9,"z":224},"requirements":{"minecraft:cobbled_deepslate":8},"sha256":"e8ccc6e1a92d18c6c78837c60392aea2a398cec28aa664892f5bd4a47eaa4368","size":{"x":32,"y":1,"z":15}},{"blockCount":32,"bytes":914,"file":"chunks/y009-z224-x320.json","offset":{"x":320,"y":9,"z":224},"requirements":{"minecraft:glass":5,"minecraft:stone_bricks":27},"sha256":"aacc87f64a503974ea204825a09ec089a77f436fab4537d9ccdd967c76e70617","size":{"x":32,"y":1,"z":15}},{"blockCount":81,"bytes":1217,"file":"chunks/y009-z224-x352.json","offset":{"x":352,"y":9,"z":224},"requirements":{"minecraft:glass":13,"minecraft:stone_bricks":68},"sha256":"6e8b12f89fe4df947f7fda65e9ad04aef89e1b570ddb32aa3db4a3691e687572","size":{"x":32,"y":1,"z":15}},{"blockCount":1,"bytes":627,"file":"chunks/y009-z224-x384.json","offset":{"x":384,"y":9,"z":224},"requirements":{"minecraft:cobbled_deepslate":1},"sha256":"27217fe6ad216ff5373ce7023a697aa0d1c96716f94d3365101cf314856df974","size":{"x":32,"y":1,"z":15}},{"blockCount":25,"bytes":991,"file":"chunks/y010-z000-x320.json","offset":{"x":320,"y":10,"z":0},"requirements":{"minecraft:sandstone":25},"sha256":"1db0e1f7de3404e5fbd75843cf13c893cd7dacddd3f627a6900aad3fc04941fa","size":{"x":32,"y":1,"z":32}},{"blockCount":32,"bytes":641,"file":"chunks/y010-z000-x352.json","offset":{"x":352,"y":10,"z":0},"requirements":{"minecraft:sandstone":32},"sha256":"f88cc2da5121b5cb70143dfd010e87a890fac85bce2f9213892fb706f8d1923b","size":{"x":32,"y":1,"z":32}},{"blockCount":14,"bytes":990,"file":"chunks/y010-z000-x384.json","offset":{"x":384,"y":10,"z":0},"requirements":{"minecraft:sandstone":14},"sha256":"87df6e98506ecd65f0d3a7fe82fa0faab86ca41c8ff7cd51ca63da33e29c15e8","size":{"x":32,"y":1,"z":32}},{"blockCount":121,"bytes":4231,"file":"chunks/y010-z032-x320.json","offset":{"x":320,"y":10,"z":32},"requirements":{"minecraft:bricks":65,"minecraft:glass":8,"minecraft:sandstone":7,"minecraft:spruce_planks":41},"sha256":"28158bf2d400141cf6ee8f3093b66f5f9ad162a45a0a578bd0a3e59299c95e0b","size":{"x":32,"y":1,"z":32}},{"blockCount":61,"bytes":2313,"file":"chunks/y010-z032-x352.json","offset":{"x":352,"y":10,"z":32},"requirements":{"minecraft:bricks":6,"minecraft:glass":18,"minecraft:oak_planks":3,"minecraft:sandstone":3,"minecraft:spruce_planks":31},"sha256":"a3f4246f53e74ec05f6d2c34b088284778a0d8a877affee829643cb7d70bb6cc","size":{"x":32,"y":1,"z":32}},{"blockCount":142,"bytes":3843,"file":"chunks/y010-z032-x384.json","offset":{"x":384,"y":10,"z":32},"requirements":{"minecraft:bricks":17,"minecraft:cobbled_deepslate":5,"minecraft:sandstone":7,"minecraft:spruce_planks":10,"minecraft:stone_bricks":103},"sha256":"b9d9a930b4fc09580be18debfa883f8cd6a24eed4e070ffe6d3e9a6e03fe06ee","size":{"x":32,"y":1,"z":32}},{"blockCount":8,"bytes":738,"file":"chunks/y010-z064-x032.json","offset":{"x":32,"y":10,"z":64},"requirements":{"minecraft:stone_bricks":8},"sha256":"b478b9f00e202315b2f845429d9c5102382363a93637dcc65fee9192ab9aed35","size":{"x":32,"y":1,"z":32}},{"blockCount":58,"bytes":1181,"file":"chunks/y010-z064-x064.json","offset":{"x":64,"y":10,"z":64},"requirements":{"minecraft:stone_bricks":58},"sha256":"4a6fed622b71e5cab12eaa3b7389b2b334829ded75063ad54972223e58f64218","size":{"x":32,"y":1,"z":32}},{"blockCount":53,"bytes":1566,"file":"chunks/y010-z064-x096.json","offset":{"x":96,"y":10,"z":64},"requirements":{"minecraft:stone_bricks":53},"sha256":"d087281893e29174d46142ae962d5d0eac0d4545856ec42c656c6b29278b9df2","size":{"x":32,"y":1,"z":32}},{"blockCount":24,"bytes":1149,"file":"chunks/y010-z064-x128.json","offset":{"x":128,"y":10,"z":64},"requirements":{"minecraft:stone_bricks":24},"sha256":"08c99701cfe96a753d41fb6d154693fd6d6b3cb2f5d0391c57a79917c9a8c986","size":{"x":32,"y":1,"z":32}},{"blockCount":136,"bytes":4193,"file":"chunks/y010-z064-x320.json","offset":{"x":320,"y":10,"z":64},"requirements":{"minecraft:bricks":58,"minecraft:sandstone":32,"minecraft:spruce_planks":30,"minecraft:stone_bricks":16},"sha256":"027dd5708fb6b6881bf98d3fe1dfd09f2565d155461395542fb89460ae45b79e","size":{"x":32,"y":1,"z":32}},{"blockCount":139,"bytes":3281,"file":"chunks/y010-z064-x352.json","offset":{"x":352,"y":10,"z":64},"requirements":{"minecraft:bricks":6,"minecraft:polished_diorite":79,"minecraft:sandstone":35,"minecraft:spruce_planks":8,"minecraft:stone_bricks":11},"sha256":"2ea3f7184fd81afb858c6674019d41dec17933ee8699552d2175ec7042719594","size":{"x":32,"y":1,"z":32}},{"blockCount":66,"bytes":2142,"file":"chunks/y010-z064-x384.json","offset":{"x":384,"y":10,"z":64},"requirements":{"minecraft:bricks":9,"minecraft:polished_diorite":4,"minecraft:sandstone":21,"minecraft:spruce_planks":2,"minecraft:stone_bricks":30},"sha256":"5150327505f1de8d95fa29aa923e963bdcaf65126e95441590b6ff674d7a6c7c","size":{"x":32,"y":1,"z":32}},{"blockCount":70,"bytes":1849,"file":"chunks/y010-z096-x032.json","offset":{"x":32,"y":10,"z":96},"requirements":{"minecraft:stone_bricks":70},"sha256":"eb4c149db39ecf7d4729c9df5963ac1546cf7c3f33870d292d9a7b9a2b0cd96c","size":{"x":32,"y":1,"z":32}},{"blockCount":258,"bytes":3975,"file":"chunks/y010-z096-x064.json","offset":{"x":64,"y":10,"z":96},"requirements":{"minecraft:glass":2,"minecraft:stone_bricks":256},"sha256":"3f27e4d6b64c8147ecd7c6755ff496f2e88fafc1a3d621d5dd70166be5552229","size":{"x":32,"y":1,"z":32}},{"blockCount":178,"bytes":3161,"file":"chunks/y010-z096-x096.json","offset":{"x":96,"y":10,"z":96},"requirements":{"minecraft:glass":2,"minecraft:stone_bricks":176},"sha256":"3e81113d01ceccfd127091a0c85ad48b74116f63f19f07f9a627576d4224fdc0","size":{"x":32,"y":1,"z":32}},{"blockCount":167,"bytes":3115,"file":"chunks/y010-z096-x128.json","offset":{"x":128,"y":10,"z":96},"requirements":{"minecraft:stone_bricks":167},"sha256":"b3944e7d6c092bb74982628f1ae81dd2fa1b54816c629dbca0428611e29a8974","size":{"x":32,"y":1,"z":32}},{"blockCount":12,"bytes":1061,"file":"chunks/y010-z096-x192.json","offset":{"x":192,"y":10,"z":96},"requirements":{"minecraft:bricks":12},"sha256":"9ccc8bf45fae20d5a08393ba9feaab05098a95ed813410be6a0fd1f9831deb20","size":{"x":32,"y":1,"z":32}},{"blockCount":34,"bytes":1111,"file":"chunks/y010-z096-x224.json","offset":{"x":224,"y":10,"z":96},"requirements":{"minecraft:bricks":11,"minecraft:stone_bricks":23},"sha256":"ac37d6893e6c5d6c2b042c89dd0d9569886e5c348eb93f4f5177ec198895c72a","size":{"x":32,"y":1,"z":32}},{"blockCount":306,"bytes":3591,"file":"chunks/y010-z096-x256.json","offset":{"x":256,"y":10,"z":96},"requirements":{"minecraft:cobbled_deepslate":12,"minecraft:polished_diorite":73,"minecraft:spruce_planks":5,"minecraft:stone_bricks":216},"sha256":"71ce65840553d53683bcd42bfc5ecccd95044fa4ac89936e0f5bb9792f647565","size":{"x":32,"y":1,"z":32}},{"blockCount":202,"bytes":3090,"file":"chunks/y010-z096-x288.json","offset":{"x":288,"y":10,"z":96},"requirements":{"minecraft:bricks":2,"minecraft:cobbled_deepslate":42,"minecraft:polished_diorite":39,"minecraft:spruce_planks":16,"minecraft:stone_bricks":103},"sha256":"de17bf4e6a216ae57da22d33960141fec1ae62071b29dd4d69799d5f288852f3","size":{"x":32,"y":1,"z":32}},{"blockCount":178,"bytes":4241,"file":"chunks/y010-z096-x320.json","offset":{"x":320,"y":10,"z":96},"requirements":{"minecraft:bricks":90,"minecraft:cobbled_deepslate":36,"minecraft:glass":3,"minecraft:polished_diorite":1,"minecraft:spruce_planks":19,"minecraft:stone_bricks":29},"sha256":"decc7cad565d4c837c23ec37a70caeb60e78de17a93f05d2c945c769bd598521","size":{"x":32,"y":1,"z":32}},{"blockCount":675,"bytes":3477,"file":"chunks/y010-z096-x352.json","offset":{"x":352,"y":10,"z":96},"requirements":{"minecraft:bricks":364,"minecraft:polished_diorite":68,"minecraft:sandstone":2,"minecraft:stone_bricks":241},"sha256":"b8e4fcc8f398977a0dba1794b918b98e8718f473834fa7a9eb9f43a0e1baa1fe","size":{"x":32,"y":1,"z":32}},{"blockCount":3,"bytes":704,"file":"chunks/y010-z096-x384.json","offset":{"x":384,"y":10,"z":96},"requirements":{"minecraft:polished_diorite":3},"sha256":"5c57d00fcde91272176f8311ec463a7921de4a554d9a7095b895a01837c47b41","size":{"x":32,"y":1,"z":32}},{"blockCount":53,"bytes":1559,"file":"chunks/y010-z128-x032.json","offset":{"x":32,"y":10,"z":128},"requirements":{"minecraft:stone_bricks":53},"sha256":"3d013a2ab01ab13672a5ee6a0cd422d30ddf92fb71692e56405fbdb2a7ba0251","size":{"x":32,"y":1,"z":32}},{"blockCount":91,"bytes":2146,"file":"chunks/y010-z128-x064.json","offset":{"x":64,"y":10,"z":128},"requirements":{"minecraft:stone_bricks":91},"sha256":"19dcf0dab5b7a8f7d34dca4c70355185aceabce9cf260afe4070e88be18d3018","size":{"x":32,"y":1,"z":32}},{"blockCount":108,"bytes":2398,"file":"chunks/y010-z128-x096.json","offset":{"x":96,"y":10,"z":128},"requirements":{"minecraft:glass":24,"minecraft:stone_bricks":84},"sha256":"d34248d9db7dc5e7a40e24395efa6cc476205d4dd4e52fab16b6d6d162b2dea9","size":{"x":32,"y":1,"z":32}},{"blockCount":96,"bytes":2505,"file":"chunks/y010-z128-x128.json","offset":{"x":128,"y":10,"z":128},"requirements":{"minecraft:stone_bricks":96},"sha256":"a414b7801c113ca110ec6fef2b7aae3f7ca283ac2525e63f9ded99373356f98d","size":{"x":32,"y":1,"z":32}},{"blockCount":77,"bytes":1837,"file":"chunks/y010-z128-x160.json","offset":{"x":160,"y":10,"z":128},"requirements":{"minecraft:cobbled_deepslate":21,"minecraft:stone_bricks":56},"sha256":"0ebc9acf08d57b6a027120eff16b237b2bc5360852d4982ed3f6e9ba94cb2663","size":{"x":32,"y":1,"z":32}},{"blockCount":112,"bytes":2689,"file":"chunks/y010-z128-x192.json","offset":{"x":192,"y":10,"z":128},"requirements":{"minecraft:bricks":13,"minecraft:cobbled_deepslate":10,"minecraft:stone_bricks":89},"sha256":"f59d7b5ddb31704cff39d0e1404d6a3d4deb2e3836bd6dadb03abdc99c75fb55","size":{"x":32,"y":1,"z":32}},{"blockCount":339,"bytes":3127,"file":"chunks/y010-z128-x224.json","offset":{"x":224,"y":10,"z":128},"requirements":{"minecraft:bricks":16,"minecraft:polished_diorite":10,"minecraft:spruce_planks":13,"minecraft:stone_bricks":300},"sha256":"7ffbf58df9ec347eef87274366285d3633a6032af72c7612f17b73115e5a3122","size":{"x":32,"y":1,"z":32}},{"blockCount":407,"bytes":3378,"file":"chunks/y010-z128-x256.json","offset":{"x":256,"y":10,"z":128},"requirements":{"minecraft:cobbled_deepslate":23,"minecraft:polished_diorite":22,"minecraft:spruce_planks":40,"minecraft:stone_bricks":322},"sha256":"72b6e4c2c32c990e1e19b7b69236201852fd6d811f18bab4645672f877c30b81","size":{"x":32,"y":1,"z":32}},{"blockCount":117,"bytes":4072,"file":"chunks/y010-z128-x288.json","offset":{"x":288,"y":10,"z":128},"requirements":{"minecraft:cobbled_deepslate":85,"minecraft:glass":9,"minecraft:spruce_planks":23},"sha256":"14b5929575d13455383a0e36e95e599e8e8aac50191bdcf2fc0d0a43158dd0b4","size":{"x":32,"y":1,"z":32}},{"blockCount":73,"bytes":3438,"file":"chunks/y010-z128-x320.json","offset":{"x":320,"y":10,"z":128},"requirements":{"minecraft:bricks":32,"minecraft:cobbled_deepslate":32,"minecraft:glass":3,"minecraft:polished_diorite":2,"minecraft:stone_bricks":4},"sha256":"fcbf146298003572f92a4eccb844b6b19ca883f4ceb2f219dafbbfa48cc43c8b","size":{"x":32,"y":1,"z":32}},{"blockCount":64,"bytes":1845,"file":"chunks/y010-z128-x352.json","offset":{"x":352,"y":10,"z":128},"requirements":{"minecraft:bricks":64},"sha256":"d1e0c322c2340e4a3cbd380658d0b660f38da4b0ee504cd5e8de08986075deb8","size":{"x":32,"y":1,"z":32}},{"blockCount":59,"bytes":1734,"file":"chunks/y010-z160-x032.json","offset":{"x":32,"y":10,"z":160},"requirements":{"minecraft:stone_bricks":59},"sha256":"c298dc0fa0efa943417cb183abaa3ab0db47b9722e0fd98b343f174a6e4ada2a","size":{"x":32,"y":1,"z":32}},{"blockCount":203,"bytes":3319,"file":"chunks/y010-z160-x064.json","offset":{"x":64,"y":10,"z":160},"requirements":{"minecraft:glass":2,"minecraft:stone_bricks":201},"sha256":"5cc5a19bb5b6d969dcd10ee7d066ab2e2b8d366783d7ceb375aa9991d084fd05","size":{"x":32,"y":1,"z":32}},{"blockCount":145,"bytes":3102,"file":"chunks/y010-z160-x096.json","offset":{"x":96,"y":10,"z":160},"requirements":{"minecraft:stone_bricks":145},"sha256":"2473d20582282614ec0ad50bb5e9ee7007c18cbc92ffcace6a0f6ecd7f37e92f","size":{"x":32,"y":1,"z":32}},{"blockCount":127,"bytes":2738,"file":"chunks/y010-z160-x128.json","offset":{"x":128,"y":10,"z":160},"requirements":{"minecraft:stone_bricks":127},"sha256":"63ed946e8f188edbf086ad41e3f54aaf4d4c9e4036ffeb73a8248eba8f9f0059","size":{"x":32,"y":1,"z":32}},{"blockCount":62,"bytes":2571,"file":"chunks/y010-z160-x160.json","offset":{"x":160,"y":10,"z":160},"requirements":{"minecraft:cobbled_deepslate":30,"minecraft:stone_bricks":32},"sha256":"c00ebf94c8b4ce33b6c9e2e22794dbe9303d116fbf4599aa1779dbe360afa4ad","size":{"x":32,"y":1,"z":32}},{"blockCount":103,"bytes":2611,"file":"chunks/y010-z160-x192.json","offset":{"x":192,"y":10,"z":160},"requirements":{"minecraft:bricks":11,"minecraft:stone_bricks":92},"sha256":"96671e4f276aa1b56a5b57c8e8d652fa4f2d9941682ea0e6dde52066bb749b82","size":{"x":32,"y":1,"z":32}},{"blockCount":105,"bytes":1788,"file":"chunks/y010-z160-x224.json","offset":{"x":224,"y":10,"z":160},"requirements":{"minecraft:bricks":5,"minecraft:spruce_planks":100},"sha256":"ca2ee1e2c282a7e7ea0cda0ed35ec61cea9ef6b0305ba7a292a8eb34a4782ed7","size":{"x":32,"y":1,"z":32}},{"blockCount":250,"bytes":4651,"file":"chunks/y010-z160-x256.json","offset":{"x":256,"y":10,"z":160},"requirements":{"minecraft:bricks":29,"minecraft:spruce_planks":206,"minecraft:stone_bricks":15},"sha256":"c49fcda4614a508fe2664375d3d54a5b0358b449b5d564c24e39befcb83e25b5","size":{"x":32,"y":1,"z":32}},{"blockCount":100,"bytes":2204,"file":"chunks/y010-z160-x288.json","offset":{"x":288,"y":10,"z":160},"requirements":{"minecraft:cobbled_deepslate":7,"minecraft:glass":4,"minecraft:oak_planks":1,"minecraft:spruce_planks":78,"minecraft:stone_bricks":10},"sha256":"fbabeb44bc71eca5d26eb26fcb47fe93f85a8b4d814fac3b0336422befc7e1d5","size":{"x":32,"y":1,"z":32}},{"blockCount":181,"bytes":2836,"file":"chunks/y010-z160-x320.json","offset":{"x":320,"y":10,"z":160},"requirements":{"minecraft:bricks":20,"minecraft:cobbled_deepslate":25,"minecraft:glass":14,"minecraft:oak_planks":54,"minecraft:polished_diorite":1,"minecraft:sandstone":3,"minecraft:spruce_planks":4,"minecraft:stone_bricks":60},"sha256":"e1d4ce0257b0abc54ab43f71e6b2cb30cb84dfec46b7ac0ca126b7ab38a3f0d2","size":{"x":32,"y":1,"z":32}},{"blockCount":169,"bytes":2672,"file":"chunks/y010-z160-x352.json","offset":{"x":352,"y":10,"z":160},"requirements":{"minecraft:bricks":81,"minecraft:glass":22,"minecraft:stone_bricks":66},"sha256":"932af57947479aa278b6250e3164fd453b191885e2e39b17b3c481afb6f83eeb","size":{"x":32,"y":1,"z":32}},{"blockCount":5,"bytes":642,"file":"chunks/y010-z192-x064.json","offset":{"x":64,"y":10,"z":192},"requirements":{"minecraft:stone_bricks":5},"sha256":"353093634bf322720711c4881dacc55bd0939d12b8d495313dfe80456a7e5a99","size":{"x":32,"y":1,"z":32}},{"blockCount":37,"bytes":1009,"file":"chunks/y010-z192-x096.json","offset":{"x":96,"y":10,"z":192},"requirements":{"minecraft:stone_bricks":37},"sha256":"8b43f5bb1b0722dc5a9c8ba8b1ddd496dc587a508177e66d36b4dbe7bedbe346","size":{"x":32,"y":1,"z":32}},{"blockCount":15,"bytes":876,"file":"chunks/y010-z192-x128.json","offset":{"x":128,"y":10,"z":192},"requirements":{"minecraft:stone_bricks":15},"sha256":"0c41b6149c2435b424f00dfcf67a4175df1606b583646bd5c90e5d3cde49e00c","size":{"x":32,"y":1,"z":32}},{"blockCount":66,"bytes":1873,"file":"chunks/y010-z192-x160.json","offset":{"x":160,"y":10,"z":192},"requirements":{"minecraft:cobbled_deepslate":43,"minecraft:stone_bricks":23},"sha256":"fa454212db5df5e2f498d8d6319ba7b413965a53342cd45d678b01bc610b7bdb","size":{"x":32,"y":1,"z":32}},{"blockCount":124,"bytes":2125,"file":"chunks/y010-z192-x192.json","offset":{"x":192,"y":10,"z":192},"requirements":{"minecraft:cobbled_deepslate":32,"minecraft:stone_bricks":92},"sha256":"44ff25495cb0c6cd6f05162e13e471d0570611a66602d833cd7466ff813c22db","size":{"x":32,"y":1,"z":32}},{"blockCount":19,"bytes":651,"file":"chunks/y010-z192-x224.json","offset":{"x":224,"y":10,"z":192},"requirements":{"minecraft:cobbled_deepslate":19},"sha256":"48693672b0097ae24d44c1f05c646b914a4fa73a9b4fcb44e85ddbb62e15b246","size":{"x":32,"y":1,"z":32}},{"blockCount":70,"bytes":2143,"file":"chunks/y010-z192-x256.json","offset":{"x":256,"y":10,"z":192},"requirements":{"minecraft:oak_planks":4,"minecraft:stone_bricks":66},"sha256":"c5ab36b1c74ef25f1e404a4a292575220401203726ae6d327c1e9c8ab93ec157","size":{"x":32,"y":1,"z":32}},{"blockCount":34,"bytes":1657,"file":"chunks/y010-z192-x288.json","offset":{"x":288,"y":10,"z":192},"requirements":{"minecraft:stone_bricks":34},"sha256":"918bb5d45f376ab3a46b0374338f3af3ebfb300e740eca85783e02eb2b5a2758","size":{"x":32,"y":1,"z":32}},{"blockCount":96,"bytes":2176,"file":"chunks/y010-z192-x320.json","offset":{"x":320,"y":10,"z":192},"requirements":{"minecraft:glass":16,"minecraft:stone_bricks":80},"sha256":"e63d14cd265c58ac8de95a3da58d65acad1a064a53349bcee5c34686cd1e5894","size":{"x":32,"y":1,"z":32}},{"blockCount":64,"bytes":2176,"file":"chunks/y010-z192-x352.json","offset":{"x":352,"y":10,"z":192},"requirements":{"minecraft:glass":16,"minecraft:stone_bricks":48},"sha256":"508ee5b6a7325b668709d141293341a189c54c475e057ce2e15ba1602b4a79d5","size":{"x":32,"y":1,"z":32}},{"blockCount":16,"bytes":1176,"file":"chunks/y010-z224-x256.json","offset":{"x":256,"y":10,"z":224},"requirements":{"minecraft:cobbled_deepslate":8,"minecraft:stone_bricks":8},"sha256":"58b8654ae04a9eac73179fa20b8d4f7df4524a28b7f522e6160fb0055ca730d9","size":{"x":32,"y":1,"z":15}},{"blockCount":8,"bytes":920,"file":"chunks/y010-z224-x288.json","offset":{"x":288,"y":10,"z":224},"requirements":{"minecraft:cobbled_deepslate":8},"sha256":"1a207d957af7472bb2a68f316180c234df02977038002cf5fd5ca05ecb177eb6","size":{"x":32,"y":1,"z":15}},{"blockCount":32,"bytes":915,"file":"chunks/y010-z224-x320.json","offset":{"x":320,"y":10,"z":224},"requirements":{"minecraft:glass":5,"minecraft:stone_bricks":27},"sha256":"9584f2df6cd47a1582427ace3028fd82ffd08d5087f41ee0cc95c764d2d1b0ec","size":{"x":32,"y":1,"z":15}},{"blockCount":81,"bytes":1218,"file":"chunks/y010-z224-x352.json","offset":{"x":352,"y":10,"z":224},"requirements":{"minecraft:glass":13,"minecraft:stone_bricks":68},"sha256":"40457cd10a6952a1d422b76863c1139ec26d128b1c822ae6008fa2985e92871d","size":{"x":32,"y":1,"z":15}},{"blockCount":1,"bytes":620,"file":"chunks/y010-z224-x384.json","offset":{"x":384,"y":10,"z":224},"requirements":{"minecraft:sandstone":1},"sha256":"5477dd94e95ae8e2fa0a011e362cac75d752075d89729719a1782fc9e0c06e61","size":{"x":32,"y":1,"z":15}},{"blockCount":25,"bytes":991,"file":"chunks/y011-z000-x320.json","offset":{"x":320,"y":11,"z":0},"requirements":{"minecraft:sandstone":25},"sha256":"85572afdd4b6cb1a9528ea762c7765dc790a792f6849f0a790ceb26c34b788ab","size":{"x":32,"y":1,"z":32}},{"blockCount":32,"bytes":641,"file":"chunks/y011-z000-x352.json","offset":{"x":352,"y":11,"z":0},"requirements":{"minecraft:sandstone":32},"sha256":"a2321acfab35d066ba13fe382b1eb89e91d3366744a5951256b7e84a05e8d047","size":{"x":32,"y":1,"z":32}},{"blockCount":14,"bytes":990,"file":"chunks/y011-z000-x384.json","offset":{"x":384,"y":11,"z":0},"requirements":{"minecraft:sandstone":14},"sha256":"b09e8dfd209dce968cddaa7e5ff1a9a47395c263b63eb57cc9f3d81ed6fd9eea","size":{"x":32,"y":1,"z":32}},{"blockCount":150,"bytes":4599,"file":"chunks/y011-z032-x320.json","offset":{"x":320,"y":11,"z":32},"requirements":{"minecraft:bricks":65,"minecraft:glass":8,"minecraft:sandstone":7,"minecraft:spruce_planks":41,"minecraft:stone_bricks":29},"sha256":"0cb893d1fcb28908d969094f13feeb0c45f160e944cfe2a954a4e36cb06e6754","size":{"x":32,"y":1,"z":32}},{"blockCount":61,"bytes":2313,"file":"chunks/y011-z032-x352.json","offset":{"x":352,"y":11,"z":32},"requirements":{"minecraft:bricks":6,"minecraft:glass":18,"minecraft:oak_planks":3,"minecraft:sandstone":3,"minecraft:spruce_planks":31},"sha256":"f146713b9c43cb766fc4e782cbfbfb2bf3956e5d4aeaed94a15fa003469df93b","size":{"x":32,"y":1,"z":32}},{"blockCount":152,"bytes":3919,"file":"chunks/y011-z032-x384.json","offset":{"x":384,"y":11,"z":32},"requirements":{"minecraft:bricks":17,"minecraft:cobbled_deepslate":5,"minecraft:sandstone":7,"minecraft:spruce_planks":10,"minecraft:stone_bricks":113},"sha256":"5add63a9dacd5648d8cc3a5096fe5922636639be4b7e434132222f2ecd98eb69","size":{"x":32,"y":1,"z":32}},{"blockCount":8,"bytes":738,"file":"chunks/y011-z064-x032.json","offset":{"x":32,"y":11,"z":64},"requirements":{"minecraft:stone_bricks":8},"sha256":"d04049042ac3bc9a9babe960f47707db44da4a24c67c3b6948aedb3501b03278","size":{"x":32,"y":1,"z":32}},{"blockCount":57,"bytes":1143,"file":"chunks/y011-z064-x064.json","offset":{"x":64,"y":11,"z":64},"requirements":{"minecraft:stone_bricks":57},"sha256":"02b632e445bbab40be7276b05c6508b43f9ff7e26c45772d431f5d7fead341e4","size":{"x":32,"y":1,"z":32}},{"blockCount":53,"bytes":1566,"file":"chunks/y011-z064-x096.json","offset":{"x":96,"y":11,"z":64},"requirements":{"minecraft:stone_bricks":53},"sha256":"f5696b685aa162294961b6ccd6e23a3d646bb32bb7e19af1d8cfa504c79b9dbb","size":{"x":32,"y":1,"z":32}},{"blockCount":24,"bytes":1149,"file":"chunks/y011-z064-x128.json","offset":{"x":128,"y":11,"z":64},"requirements":{"minecraft:stone_bricks":24},"sha256":"48730080f6dd8102af7ba194635602c78b0d932da4a863a09f072cacf79e1744","size":{"x":32,"y":1,"z":32}}],"schema":1}
