{"entries":[{"blockCount":204,"bytes":4941,"file":"chunks/y011-z064-x320.json","offset":{"x":320,"y":11,"z":64},"requirements":{"minecraft:bricks":58,"minecraft:sandstone":32,"minecraft:spruce_planks":30,"minecraft:stone_bricks":84},"sha256":"6931ce77cd0eea179f66a9accc2608fb87a4038f56f99808a39cde35b6a15945","size":{"x":32,"y":1,"z":32}},{"blockCount":153,"bytes":1764,"file":"chunks/y011-z064-x352.json","offset":{"x":352,"y":11,"z":64},"requirements":{"minecraft:bricks":6,"minecraft:polished_diorite":95,"minecraft:sandstone":32,"minecraft:spruce_planks":8,"minecraft:stone_bricks":12},"sha256":"31653b648c247d25e658721d8b7665ebe103424da09824ebfc3f5672832764ec","size":{"x":32,"y":1,"z":32}},{"blockCount":62,"bytes":1955,"file":"chunks/y011-z064-x384.json","offset":{"x":384,"y":11,"z":64},"requirements":{"minecraft:bricks":9,"minecraft:sandstone":21,"minecraft:spruce_planks":2,"minecraft:stone_bricks":30},"sha256":"b5fc0d2f57c04d25936efb9c25d64ce613aed35ca98b634cdb89645ac89b96b7","size":{"x":32,"y":1,"z":32}},{"blockCount":71,"bytes":1830,"file":"chunks/y011-z096-x032.json","offset":{"x":32,"y":11,"z":96},"requirements":{"minecraft:stone_bricks":71},"sha256":"aa16305d3f0a77bc8dc64ad1d72df2ecb971e2dbf2efb4b3249471ba760f1e5a","size":{"x":32,"y":1,"z":32}},{"blockCount":210,"bytes":3261,"file":"chunks/y011-z096-x064.json","offset":{"x":64,"y":11,"z":96},"requirements":{"minecraft:glass":3,"minecraft:stone_bricks":207},"sha256":"d0792847a0d363d11116da53b5e830b217c3a931c5d0cf0eb50779802d63044d","size":{"x":32,"y":1,"z":32}},{"blockCount":182,"bytes":3084,"file":"chunks/y011-z096-x096.json","offset":{"x":96,"y":11,"z":96},"requirements":{"minecraft:glass":3,"minecraft:stone_bricks":179},"sha256":"da845a95d7089b30d18e100a468bec631ef3b53c94a137ccfe2e925469ef0827","size":{"x":32,"y":1,"z":32}},{"blockCount":167,"bytes":3115,"file":"chunks/y011-z096-x128.json","offset":{"x":128,"y":11,"z":96},"requirements":{"minecraft:stone_bricks":167},"sha256":"5fb3d5d142fcaa79879fdcc3087766a8258da8626b968f720455cbc98656de9e","size":{"x":32,"y":1,"z":32}},{"blockCount":13,"bytes":1100,"file":"chunks/y011-z096-x192.json","offset":{"x":192,"y":11,"z":96},"requirements":{"minecraft:bricks":13},"sha256":"61e1292d4f5efb507a754a42df5e44535746c6d4875d03b1abad12d3eaff9d05","size":{"x":32,"y":1,"z":32}},{"blockCount":27,"bytes":1400,"file":"chunks/y011-z096-x224.json","offset":{"x":224,"y":11,"z":96},"requirements":{"minecraft:bricks":19,"minecraft:cobbled_deepslate":8},"sha256":"01c0d5e95908ab332284d964279178a538968b1ebf42fa4ce417fc8525408a0c","size":{"x":32,"y":1,"z":32}},{"blockCount":271,"bytes":2124,"file":"chunks/y011-z096-x256.json","offset":{"x":256,"y":11,"z":96},"requirements":{"minecraft:cobbled_deepslate":12,"minecraft:polished_diorite":4,"minecraft:spruce_planks":7,"minecraft:stone_bricks":248},"sha256":"e81c000396f56444f97c034cd7a00d9868c1920d01a170680ecef5f138702df8","size":{"x":32,"y":1,"z":32}},{"blockCount":230,"bytes":2502,"file":"chunks/y011-z096-x288.json","offset":{"x":288,"y":11,"z":96},"requirements":{"minecraft:bricks":2,"minecraft:cobbled_deepslate":42,"minecraft:glass":5,"minecraft:spruce_planks":25,"minecraft:stone_bricks":156},"sha256":"da803b00c3a65694678d06866a6ec830b2a03a9e0f80b8e9f239ee7ac89b6150","size":{"x":32,"y":1,"z":32}},{"blockCount":219,"bytes":4774,"file":"chunks/y011-z096-x320.json","offset":{"x":320,"y":11,"z":96},"requirements":{"minecraft:bricks":90,"minecraft:cobbled_deepslate":39,"minecraft:glass":5,"minecraft:spruce_planks":19,"minecraft:stone_bricks":66},"sha256":"081908ca7556b32a93a3b6bdb9b5f09fb955157110a35562a91dd6489ba63e23","size":{"x":32,"y":1,"z":32}},{"blockCount":687,"bytes":1936,"file":"chunks/y011-z096-x352.json","offset":{"x":352,"y":11,"z":96},"requirements":{"minecraft:bricks":365,"minecraft:polished_diorite":80,"minecraft:stone_bricks":242},"sha256":"e407463bc73fceb2f874e9a43c1f487e82addc423e1ad53356c82cac43b97f50","size":{"x":32,"y":1,"z":32}},{"blockCount":56,"bytes":1559,"file":"chunks/y011-z128-x032.json","offset":{"x":32,"y":11,"z":128},"requirements":{"minecraft:stone_bricks":56},"sha256":"aa4b48c427fe9a04eb793ae82102d56fe95fe308bc291765a00672da3980a85d","size":{"x":32,"y":1,"z":32}},{"blockCount":72,"bytes":1893,"file":"chunks/y011-z128-x064.json","offset":{"x":64,"y":11,"z":128},"requirements":{"minecraft:stone_bricks":72},"sha256":"16c1a82756bd7faae0c8e2744e638966d3732f548a9a8984e2d5690cfca1aeb5","size":{"x":32,"y":1,"z":32}},{"blockCount":94,"bytes":2357,"file":"chunks/y011-z128-x096.json","offset":{"x":96,"y":11,"z":128},"requirements":{"minecraft:glass":16,"minecraft:stone_bricks":78},"sha256":"69d42b8bcb684c407bb2113a32d00f26d36c4f97245761af1d1a1c541e21a4bb","size":{"x":32,"y":1,"z":32}},{"blockCount":94,"bytes":2425,"file":"chunks/y011-z128-x128.json","offset":{"x":128,"y":11,"z":128},"requirements":{"minecraft:stone_bricks":94},"sha256":"154fa456ea2786963ca72023190b39c75d4e51aa62dde7dea61b01d5c9ce9b65","size":{"x":32,"y":1,"z":32}},{"blockCount":115,"bytes":2180,"file":"chunks/y011-z128-x160.json","offset":{"x":160,"y":11,"z":128},"requirements":{"minecraft:cobbled_deepslate":21,"minecraft:stone_bricks":94},"sha256":"ffe42446182399da9bf669a1b1c991ccd1424de75682de319191841ff6f1efd1","size":{"x":32,"y":1,"z":32}},{"blockCount":136,"bytes":2557,"file":"chunks/y011-z128-x192.json","offset":{"x":192,"y":11,"z":128},"requirements":{"minecraft:bricks":12,"minecraft:cobbled_deepslate":10,"minecraft:stone_bricks":114},"sha256":"61d50db3ffbc8d4ae9de3e63e43d349dbd0dd4cf7dcae81bd8056f5483c729f0","size":{"x":32,"y":1,"z":32}},{"blockCount":153,"bytes":3886,"file":"chunks/y011-z128-x224.json","offset":{"x":224,"y":11,"z":128},"requirements":{"minecraft:bricks":19,"minecraft:cobbled_deepslate":20,"minecraft:glass":20,"minecraft:oak_planks":9,"minecraft:polished_diorite":2,"minecraft:sandstone":10,"minecraft:spruce_planks":2,"minecraft:stone_bricks":71},"sha256":"ee45cbcf3a11fb36e83759423404dc1a7693b22624172a122d5edf0692e2d35b","size":{"x":32,"y":1,"z":32}},{"blockCount":193,"bytes":4120,"file":"chunks/y011-z128-x256.json","offset":{"x":256,"y":11,"z":128},"requirements":{"minecraft:cobbled_deepslate":23,"minecraft:glass":32,"minecraft:oak_planks":22,"minecraft:polished_diorite":6,"minecraft:spruce_planks":15,"minecraft:stone_bricks":95},"sha256":"0327998e98bb29b84471a82aff37e14ca51c5675156e0fa328820efc25260ea6","size":{"x":32,"y":1,"z":32}},{"blockCount":146,"bytes":4723,"file":"chunks/y011-z128-x288.json","offset":{"x":288,"y":11,"z":128},"requirements":{"minecraft:cobbled_deepslate":84,"minecraft:glass":24,"minecraft:spruce_planks":32,"minecraft:stone_bricks":6},"sha256":"755c249a1ac806bf3bd873d1fb105807dc3d8eebfcc9fb6f365727304d4cc12b","size":{"x":32,"y":1,"z":32}},{"blockCount":100,"bytes":4208,"file":"chunks/y011-z128-x320.json","offset":{"x":320,"y":11,"z":128},"requirements":{"minecraft:bricks":32,"minecraft:cobbled_deepslate":32,"minecraft:glass":26,"minecraft:stone_bricks":10},"sha256":"8da1fc20ebc6485de14b1dff18b49c6be73c85475a6ade7b9c51f650a7516409","size":{"x":32,"y":1,"z":32}},{"blockCount":64,"bytes":1845,"file":"chunks/y011-z128-x352.json","offset":{"x":352,"y":11,"z":128},"requirements":{"minecraft:bricks":64},"sha256":"fa3c60847f5eafad1585cb6dfdcf6280fff218e95c90d776b41adf392e5554f7","size":{"x":32,"y":1,"z":32}},{"blockCount":59,"bytes":1734,"file":"chunks/y011-z160-x032.json","offset":{"x":32,"y":11,"z":160},"requirements":{"minecraft:stone_bricks":59},"sha256":"21bac65ad46547bf2277458bfa937c508829d8da54de620df9787c44b193a2c4","size":{"x":32,"y":1,"z":32}},{"blockCount":217,"bytes":3657,"file":"chunks/y011-z160-x064.json","offset":{"x":64,"y":11,"z":160},"requirements":{"minecraft:glass":5,"minecraft:stone_bricks":212},"sha256":"d036d86a998202171fde7c8328b1b02da4916392d3f1889095e350ffbc9f2414","size":{"x":32,"y":1,"z":32}},{"blockCount":153,"bytes":3045,"file":"chunks/y011-z160-x096.json","offset":{"x":96,"y":11,"z":160},"requirements":{"minecraft:stone_bricks":153},"sha256":"a48c89e3212d2d26c648a4237eda1de8fee6cf5906f959e068307148cbd5848f","size":{"x":32,"y":1,"z":32}},{"blockCount":127,"bytes":2738,"file":"chunks/y011-z160-x128.json","offset":{"x":128,"y":11,"z":160},"requirements":{"minecraft:stone_bricks":127},"sha256":"18b8550a5916ebea5cc748f3ee6012eeeb873e207ae2c265ee298379c112dc41","size":{"x":32,"y":1,"z":32}},{"blockCount":59,"bytes":2575,"file":"chunks/y011-z160-x160.json","offset":{"x":160,"y":11,"z":160},"requirements":{"minecraft:cobbled_deepslate":30,"minecraft:glass":1,"minecraft:stone_bricks":28},"sha256":"68ba6fa4f816f6a2714e7c1eecb8bbee74f9d8114e763ee65029b8eb969ed6e4","size":{"x":32,"y":1,"z":32}},{"blockCount":64,"bytes":1777,"file":"chunks/y011-z160-x192.json","offset":{"x":192,"y":11,"z":160},"requirements":{"minecraft:bricks":5,"minecraft:glass":22,"minecraft:stone_bricks":37},"sha256":"c28926e7731879c4bf1648cc46f8df4b2ffc8ae8d34b8cc21d5f193b7569e9e0","size":{"x":32,"y":1,"z":32}},{"blockCount":125,"bytes":2055,"file":"chunks/y011-z160-x224.json","offset":{"x":224,"y":11,"z":160},"requirements":{"minecraft:bricks":3,"minecraft:oak_planks":102,"minecraft:stone_bricks":20},"sha256":"e8eb5eeb11dc565c6b4f16a1916b332b43ab4dcbcfefee5c998c9f9831a12631","size":{"x":32,"y":1,"z":32}},{"blockCount":353,"bytes":6540,"file":"chunks/y011-z160-x256.json","offset":{"x":256,"y":11,"z":160},"requirements":{"minecraft:bricks":29,"minecraft:oak_planks":216,"minecraft:spruce_planks":4,"minecraft:stone_bricks":104},"sha256":"c10c4c0554962924975873c609dcd425e5bc341498d6df20ce973ccf651f32f9","size":{"x":32,"y":1,"z":32}},{"blockCount":152,"bytes":1840,"file":"chunks/y011-z160-x288.json","offset":{"x":288,"y":11,"z":160},"requirements":{"minecraft:cobbled_deepslate":7,"minecraft:glass":1,"minecraft:oak_planks":133,"minecraft:spruce_planks":1,"minecraft:stone_bricks":10},"sha256":"6900255b23046ab856b85508513da1971696d3d1cb717f537eced857d280b97c","size":{"x":32,"y":1,"z":32}},{"blockCount":126,"bytes":2513,"file":"chunks/y011-z160-x320.json","offset":{"x":320,"y":11,"z":160},"requirements":{"minecraft:bricks":20,"minecraft:cobbled_deepslate":25,"minecraft:glass":14,"minecraft:sandstone":3,"minecraft:spruce_planks":4,"minecraft:stone_bricks":60},"sha256":"8652ffcca7b566b00227720d1c031bc80f55aafec2fe2f010243d59856cd19d0","size":{"x":32,"y":1,"z":32}},{"blockCount":172,"bytes":2558,"file":"chunks/y011-z160-x352.json","offset":{"x":352,"y":11,"z":160},"requirements":{"minecraft:bricks":83,"minecraft:glass":22,"minecraft:stone_bricks":67},"sha256":"057db74fde5f35f5784d2aed687a8061d7cca42499b5689801fa54ed1981c261","size":{"x":32,"y":1,"z":32}},{"blockCount":5,"bytes":642,"file":"chunks/y011-z192-x064.json","offset":{"x":64,"y":11,"z":192},"requirements":{"minecraft:stone_bricks":5},"sha256":"fe5251d3749ae4907b1165bb4beccb959f6205d568b70d96e6e497f4c352695c","size":{"x":32,"y":1,"z":32}},{"blockCount":37,"bytes":1009,"file":"chunks/y011-z192-x096.json","offset":{"x":96,"y":11,"z":192},"requirements":{"minecraft:stone_bricks":37},"sha256":"818267af2a79593121846f3ca70fc4dab44f9360bd769e43f37a1b0244c511d9","size":{"x":32,"y":1,"z":32}},{"blockCount":15,"bytes":876,"file":"chunks/y011-z192-x128.json","offset":{"x":128,"y":11,"z":192},"requirements":{"minecraft:stone_bricks":15},"sha256":"da7b25bf2032892035071a198da39365581a9bd8664776ba4f26132264702e55","size":{"x":32,"y":1,"z":32}},{"blockCount":60,"bytes":1859,"file":"chunks/y011-z192-x160.json","offset":{"x":160,"y":11,"z":192},"requirements":{"minecraft:cobbled_deepslate":43,"minecraft:glass":1,"minecraft:stone_bricks":16},"sha256":"a02898a3fbd0a99273ec4c2b1fe69b2bc468a87186f0f315816f2aba115a6ba3","size":{"x":32,"y":1,"z":32}},{"blockCount":86,"bytes":1748,"file":"chunks/y011-z192-x192.json","offset":{"x":192,"y":11,"z":192},"requirements":{"minecraft:cobbled_deepslate":32,"minecraft:glass":22,"minecraft:stone_bricks":32},"sha256":"f9fbcf77765cee01344242ea12ee840433ef3b9bb3f8e52c835ccc70b8d83bee","size":{"x":32,"y":1,"z":32}},{"blockCount":19,"bytes":651,"file":"chunks/y011-z192-x224.json","offset":{"x":224,"y":11,"z":192},"requirements":{"minecraft:cobbled_deepslate":19},"sha256":"b5b672ce5e885581faf7e1940245ac57660114be7fc4895325a3cca7872de09b","size":{"x":32,"y":1,"z":32}},{"blockCount":76,"bytes":2139,"file":"chunks/y011-z192-x256.json","offset":{"x":256,"y":11,"z":192},"requirements":{"minecraft:cobbled_deepslate":6,"minecraft:oak_planks":4,"minecraft:stone_bricks":66},"sha256":"b6e1bfe3cc766facf9538e391e6e17582e686e1cf70bc00df5df32d62efd242e","size":{"x":32,"y":1,"z":32}},{"blockCount":36,"bytes":1767,"file":"chunks/y011-z192-x288.json","offset":{"x":288,"y":11,"z":192},"requirements":{"minecraft:cobbled_deepslate":2,"minecraft:stone_bricks":34},"sha256":"c428b0f1b01b1ca9b63bf7fb537a033c0e89fb28bc15e3beee09bcd3cba3581f","size":{"x":32,"y":1,"z":32}},{"blockCount":96,"bytes":2176,"file":"chunks/y011-z192-x320.json","offset":{"x":320,"y":11,"z":192},"requirements":{"minecraft:glass":16,"minecraft:stone_bricks":80},"sha256":"74d43939756956380909d8a9359cd2d053afa40bf441771f0018769d3039b2be","size":{"x":32,"y":1,"z":32}},{"blockCount":64,"bytes":2176,"file":"chunks/y011-z192-x352.json","offset":{"x":352,"y":11,"z":192},"requirements":{"minecraft:glass":16,"minecraft:stone_bricks":48},"sha256":"ba7984a0da760d2e783f451cf239ca5f962edfc1fd79cc9394f2e4a4fd1f313e","size":{"x":32,"y":1,"z":32}},{"blockCount":12,"bytes":1024,"file":"chunks/y011-z224-x256.json","offset":{"x":256,"y":11,"z":224},"requirements":{"minecraft:cobbled_deepslate":8,"minecraft:stone_bricks":4},"sha256":"3ae0b7690156595172a5834158cc2ce2a15d8986b4ecae395a84585133832c55","size":{"x":32,"y":1,"z":15}},{"blockCount":8,"bytes":920,"file":"chunks/y011-z224-x288.json","offset":{"x":288,"y":11,"z":224},"requirements":{"minecraft:cobbled_deepslate":8},"sha256":"b86aa9d1e3dc803c06353f5b4c4061425beaa3c59d95695fc2fb0ea216062788","size":{"x":32,"y":1,"z":15}},{"blockCount":32,"bytes":915,"file":"chunks/y011-z224-x320.json","offset":{"x":320,"y":11,"z":224},"requirements":{"minecraft:glass":5,"minecraft:stone_bricks":27},"sha256":"5c468b3cba9d628627f0bed17696463ba9a5a714373023e8bdefb077e98ad2b4","size":{"x":32,"y":1,"z":15}},{"blockCount":81,"bytes":1218,"file":"chunks/y011-z224-x352.json","offset":{"x":352,"y":11,"z":224},"requirements":{"minecraft:glass":13,"minecraft:stone_bricks":68},"sha256":"116778eaf24fc841e3750298fc6f9394b24350c782e8eb1e7ac2690655abaa62","size":{"x":32,"y":1,"z":15}},{"blockCount":1,"bytes":628,"file":"chunks/y011-z224-x384.json","offset":{"x":384,"y":11,"z":224},"requirements":{"minecraft:cobbled_deepslate":1},"sha256":"9fd1db3dbc2efa4d6f5d6d4bd48d77f34b1d861007359fa7a90977fab1be31f2","size":{"x":32,"y":1,"z":15}},{"blockCount":25,"bytes":991,"file":"chunks/y012-z000-x320.json","offset":{"x":320,"y":12,"z":0},"requirements":{"minecraft:sandstone":25},"sha256":"596cae565ec7b3b6b54414265abb09787d56fe5a596aa9a9ef9f3b751dfdf9e5","size":{"x":32,"y":1,"z":32}},{"blockCount":32,"bytes":641,"file":"chunks/y012-z000-x352.json","offset":{"x":352,"y":12,"z":0},"requirements":{"minecraft:sandstone":32},"sha256":"093b73cb39e80353ee30efc2151f556fa969fd3a917dc24e89e7a394dd875887","size":{"x":32,"y":1,"z":32}},{"blockCount":14,"bytes":990,"file":"chunks/y012-z000-x384.json","offset":{"x":384,"y":12,"z":0},"requirements":{"minecraft:sandstone":14},"sha256":"e7f4e9063570efc42816f915f6a3c13cc9f1e81fb7fd42683057c7588b011a3c","size":{"x":32,"y":1,"z":32}},{"blockCount":181,"bytes":5032,"file":"chunks/y012-z032-x320.json","offset":{"x":320,"y":12,"z":32},"requirements":{"minecraft:bricks":65,"minecraft:glass":8,"minecraft:sandstone":7,"minecraft:spruce_planks":51,"minecraft:stone_bricks":50},"sha256":"60290dc5cd6e59efff439d88c0f4fa3ce20ae951eeca2e600696e29f6ab27cf0","size":{"x":32,"y":1,"z":32}},{"blockCount":61,"bytes":2278,"file":"chunks/y012-z032-x352.json","offset":{"x":352,"y":12,"z":32},"requirements":{"minecraft:bricks":6,"minecraft:glass":18,"minecraft:oak_planks":3,"minecraft:spruce_planks":33,"minecraft:stone_bricks":1},"sha256":"0170a5732b1d612ee6714f563d4f5f675021629bc1014f31cab871703948ace8","size":{"x":32,"y":1,"z":32}},{"blockCount":156,"bytes":3958,"file":"chunks/y012-z032-x384.json","offset":{"x":384,"y":12,"z":32},"requirements":{"minecraft:bricks":17,"minecraft:cobbled_deepslate":5,"minecraft:sandstone":7,"minecraft:spruce_planks":10,"minecraft:stone_bricks":117},"sha256":"155b350af435bcc982891e85d9fbd4a23615ebe627499a037126e4c4004b867b","size":{"x":32,"y":1,"z":32}},{"blockCount":8,"bytes":738,"file":"chunks/y012-z064-x032.json","offset":{"x":32,"y":12,"z":64},"requirements":{"minecraft:stone_bricks":8},"sha256":"735828cf82a1d2a6b2374437372def715ae74adbfe42836bbc06fc16a2796ea7","size":{"x":32,"y":1,"z":32}},{"blockCount":51,"bytes":1069,"file":"chunks/y012-z064-x064.json","offset":{"x":64,"y":12,"z":64},"requirements":{"minecraft:stone_bricks":51},"sha256":"4878807bca7f3e00b302cf7c48ca33ace33bc970381d0c907dbd6cf10c7649e7","size":{"x":32,"y":1,"z":32}},{"blockCount":53,"bytes":1566,"file":"chunks/y012-z064-x096.json","offset":{"x":96,"y":12,"z":64},"requirements":{"minecraft:stone_bricks":53},"sha256":"579f0ea07d5515f67ff6e8f9fc7daaa599e34bc2ddb6960cea60862bc88ee110","size":{"x":32,"y":1,"z":32}},{"blockCount":24,"bytes":1149,"file":"chunks/y012-z064-x128.json","offset":{"x":128,"y":12,"z":64},"requirements":{"minecraft:stone_bricks":24},"sha256":"0a670e941fe5990f1e8c4deca8b9d29f1ea3928427dcfff38b52c3f3d1fcb133","size":{"x":32,"y":1,"z":32}},{"blockCount":270,"bytes":5555,"file":"chunks/y012-z064-x320.json","offset":{"x":320,"y":12,"z":64},"requirements":{"minecraft:bricks":46,"minecraft:sandstone":32,"minecraft:spruce_planks":46,"minecraft:stone_bricks":146},"sha256":"52d87e9638d4f1c925913eb7cd0f401413ae292b86f32b917b943e05f50901da","size":{"x":32,"y":1,"z":32}},{"blockCount":243,"bytes":1259,"file":"chunks/y012-z064-x352.json","offset":{"x":352,"y":12,"z":64},"requirements":{"minecraft:bricks":6,"minecraft:sandstone":32,"minecraft:spruce_planks":8,"minecraft:stone_bricks":197},"sha256":"28693570dbf766ca1193d315cc5236bdb7d3330ec519f911a422c097640b8661","size":{"x":32,"y":1,"z":32}},{"blockCount":75,"bytes":2227,"file":"chunks/y012-z064-x384.json","offset":{"x":384,"y":12,"z":64},"requirements":{"minecraft:bricks":8,"minecraft:sandstone":21,"minecraft:spruce_planks":2,"minecraft:stone_bricks":44},"sha256":"5ee88bcd049621f5751cdfec3441cb5d607d51359d283c78dd8cf07c95da01fb","size":{"x":32,"y":1,"z":32}},{"blockCount":71,"bytes":1830,"file":"chunks/y012-z096-x032.json","offset":{"x":32,"y":12,"z":96},"requirements":{"minecraft:stone_bricks":71},"sha256":"a3c61169bfe36a423306161290fc9496db4c084a891fcae2a39af340648bedf5","size":{"x":32,"y":1,"z":32}},{"blockCount":206,"bytes":3164,"file":"chunks/y012-z096-x064.json","offset":{"x":64,"y":12,"z":96},"requirements":{"minecraft:stone_bricks":206},"sha256":"e8545a336b003b3ebe7c93ff06c13f3e7f5ab4461f02f83256c7557af46aec2e","size":{"x":32,"y":1,"z":32}},{"blockCount":180,"bytes":3106,"file":"chunks/y012-z096-x096.json","offset":{"x":96,"y":12,"z":96},"requirements":{"minecraft:stone_bricks":180},"sha256":"e45d0ed74adefa9ccf1d488061e7540670d5e386371cdd74c354bdf20f06c39d","size":{"x":32,"y":1,"z":32}},{"blockCount":167,"bytes":3115,"file":"chunks/y012-z096-x128.json","offset":{"x":128,"y":12,"z":96},"requirements":{"minecraft:stone_bricks":167},"sha256":"7e306fba976f1b44cbf7ac0f2a72397771b5676070f8d333fcf7305298ab08f2","size":{"x":32,"y":1,"z":32}},{"blockCount":15,"bytes":1139,"file":"chunks/y012-z096-x192.json","offset":{"x":192,"y":12,"z":96},"requirements":{"minecraft:bricks":15},"sha256":"0bc9e8a51a39f5e99164cd2382d1837ad761122d124155241f2156a921b218e7","size":{"x":32,"y":1,"z":32}},{"blockCount":10,"bytes":978,"file":"chunks/y012-z096-x224.json","offset":{"x":224,"y":12,"z":96},"requirements":{"minecraft:bricks":8,"minecraft:cobbled_deepslate":2},"sha256":"c4e0e60c38041acfc4d4a23b112768c7387ca2e641f67cbd974adad865fb996f","size":{"x":32,"y":1,"z":32}},{"blockCount":21,"bytes":1030,"file":"chunks/y012-z096-x256.json","offset":{"x":256,"y":12,"z":96},"requirements":{"minecraft:cobbled_deepslate":13,"minecraft:glass":2,"minecraft:spruce_planks":4,"minecraft:stone_bricks":2},"sha256":"a81026066591e74f96415ea760addfdbef62d693301225efa9ed3883e5693af7","size":{"x":32,"y":1,"z":32}},{"blockCount":67,"bytes":1579,"file":"chunks/y012-z096-x288.json","offset":{"x":288,"y":12,"z":96},"requirements":{"minecraft:bricks":2,"minecraft:cobbled_deepslate":39,"minecraft:spruce_planks":26},"sha256":"41af60ceeb49f81fe2a00b6514021455cd5337e29f4625cc0cf64dcf5202f955","size":{"x":32,"y":1,"z":32}},{"blockCount":267,"bytes":5069,"file":"chunks/y012-z096-x320.json","offset":{"x":320,"y":12,"z":96},"requirements":{"minecraft:bricks":91,"minecraft:cobbled_deepslate":39,"minecraft:spruce_planks":31,"minecraft:stone_bricks":106},"sha256":"a5502cea9733ec4420181d5b51d9e2e5e1de21cc156c543bee2320faf46edfcd","size":{"x":32,"y":1,"z":32}},{"blockCount":763,"bytes":1883,"file":"chunks/y012-z096-x352.json","offset":{"x":352,"y":12,"z":96},"requirements":{"minecraft:bricks":395,"minecraft:stone_bricks":368},"sha256":"6a15354d1a40ae59f33d20bbd713c5c02d3ac2fe8e740428782e16f3e909a251","size":{"x":32,"y":1,"z":32}},{"blockCount":12,"bytes":818,"file":"chunks/y012-z096-x384.json","offset":{"x":384,"y":12,"z":96},"requirements":{"minecraft:stone_bricks":12},"sha256":"d7aa632578e61dda0acb7dd014d88e3b2bb27278398b0cab7330c0380401bb29","size":{"x":32,"y":1,"z":32}},{"blockCount":56,"bytes":1559,"file":"chunks/y012-z128-x032.json","offset":{"x":32,"y":12,"z":128},"requirements":{"minecraft:stone_bricks":56},"sha256":"c4d7e7c37faaae3a38910f8065b0ae7bc6d5d759b3004335b784332bdc3c4c05","size":{"x":32,"y":1,"z":32}},{"blockCount":68,"bytes":1698,"file":"chunks/y012-z128-x064.json","offset":{"x":64,"y":12,"z":128},"requirements":{"minecraft:stone_bricks":68},"sha256":"9967c03376ee1e014cd9dd511380aa437bc5c5b04f6200f6e7c3fd2afec1f1f7","size":{"x":32,"y":1,"z":32}},{"blockCount":83,"bytes":1805,"file":"chunks/y012-z128-x096.json","offset":{"x":96,"y":12,"z":128},"requirements":{"minecraft:stone_bricks":83},"sha256":"f799193799f7f1fe01cb257a850bd31ebbe5c9e2bd79bf839f62988acd7c89e4","size":{"x":32,"y":1,"z":32}},{"blockCount":98,"bytes":2423,"file":"chunks/y012-z128-x128.json","offset":{"x":128,"y":12,"z":128},"requirements":{"minecraft:stone_bricks":98},"sha256":"c8c40c0e610316c3e66e8a83c476b17de0002c892c28d7c4f217bc1932389f2a","size":{"x":32,"y":1,"z":32}},{"blockCount":179,"bytes":3111,"file":"chunks/y012-z128-x160.json","offset":{"x":160,"y":12,"z":128},"requirements":{"minecraft:bricks":3,"minecraft:cobbled_deepslate":21,"minecraft:spruce_planks":2,"minecraft:stone_bricks":153},"sha256":"ce106d9d272e65fe727a1ba49f0a1f74ef9cabbee5ca4b0883a2ed24587444a5","size":{"x":32,"y":1,"z":32}},{"blockCount":244,"bytes":2618,"file":"chunks/y012-z128-x192.json","offset":{"x":192,"y":12,"z":128},"requirements":{"minecraft:bricks":8,"minecraft:cobbled_deepslate":10,"minecraft:stone_bricks":226},"sha256":"1f8f134f3a5693b0a1c014dca525ff642ce767fe893ac43f4be2b94ff5872ecb","size":{"x":32,"y":1,"z":32}},{"blockCount":87,"bytes":3203,"file":"chunks/y012-z128-x224.json","offset":{"x":224,"y":12,"z":128},"requirements":{"minecraft:bricks":20,"minecraft:cobbled_deepslate":4,"minecraft:glass":1,"minecraft:polished_diorite":2,"minecraft:sandstone":3,"minecraft:stone_bricks":57},"sha256":"f27c1c29360938294bca336c6ea29f5e8ec518bd71e647d33281ce8a209731af","size":{"x":32,"y":1,"z":32}},{"blockCount":93,"bytes":3505,"file":"chunks/y012-z128-x256.json","offset":{"x":256,"y":12,"z":128},"requirements":{"minecraft:cobbled_deepslate":26,"minecraft:glass":2,"minecraft:polished_diorite":6,"minecraft:spruce_planks":11,"minecraft:stone_bricks":48},"sha256":"26ff56515f072560f14352e8b068ef491132b75fe84e8ef91ad5a3f14583484a","size":{"x":32,"y":1,"z":32}},{"blockCount":154,"bytes":4385,"file":"chunks/y012-z128-x288.json","offset":{"x":288,"y":12,"z":128},"requirements":{"minecraft:cobbled_deepslate":81,"minecraft:glass":28,"minecraft:spruce_planks":36,"minecraft:stone_bricks":9},"sha256":"b0ddbe74be42a7d47bb52798ee98737bba7d794808f60fb5f489beed9ea27965","size":{"x":32,"y":1,"z":32}},{"blockCount":103,"bytes":3332,"file":"chunks/y012-z128-x320.json","offset":{"x":320,"y":12,"z":128},"requirements":{"minecraft:bricks":64,"minecraft:cobbled_deepslate":32,"minecraft:glass":3,"minecraft:stone_bricks":4},"sha256":"c230d79c55e6cf71963ab3167f01a2d19f1c04642afd8865e201385230c3cb68","size":{"x":32,"y":1,"z":32}},{"blockCount":96,"bytes":1845,"file":"chunks/y012-z128-x352.json","offset":{"x":352,"y":12,"z":128},"requirements":{"minecraft:bricks":96},"sha256":"ac4aa29fb231c531609156de3a5e8f6e385c37eede1806f4b31114669c0b5c26","size":{"x":32,"y":1,"z":32}},{"blockCount":59,"bytes":1734,"file":"chunks/y012-z160-x032.json","offset":{"x":32,"y":12,"z":160},"requirements":{"minecraft:stone_bricks":59},"sha256":"da3d16bf2cce2a3b76c6ae5acbc2722bf34a1fe4f2b4484aefb1e2b720b294e1","size":{"x":32,"y":1,"z":32}},{"blockCount":199,"bytes":2924,"file":"chunks/y012-z160-x064.json","offset":{"x":64,"y":12,"z":160},"requirements":{"minecraft:stone_bricks":199},"sha256":"2ac507f15deb1a002a7a13e2f5cc1c5a6c970103e04c7aef19998613c754e8b6","size":{"x":32,"y":1,"z":32}},{"blockCount":156,"bytes":3084,"file":"chunks/y012-z160-x096.json","offset":{"x":96,"y":12,"z":160},"requirements":{"minecraft:stone_bricks":156},"sha256":"abdb6acd126f7341181b9c17ea87efa48063a0d1bb8088956138ed035238526e","size":{"x":32,"y":1,"z":32}},{"blockCount":127,"bytes":2738,"file":"chunks/y012-z160-x128.json","offset":{"x":128,"y":12,"z":160},"requirements":{"minecraft:stone_bricks":127},"sha256":"6f3eae226d025373ba9154ed54eef8213bb60b39ee934f4873bba65f8d185206","size":{"x":32,"y":1,"z":32}},{"blockCount":157,"bytes":4676,"file":"chunks/y012-z160-x160.json","offset":{"x":160,"y":12,"z":160},"requirements":{"minecraft:bricks":7,"minecraft:cobbled_deepslate":30,"minecraft:glass":1,"minecraft:stone_bricks":119},"sha256":"36f5bc8fea73b47724a6df1c6c397d4282e3a6c9997545a5624a9bff742af7e4","size":{"x":32,"y":1,"z":32}},{"blockCount":97,"bytes":1815,"file":"chunks/y012-z160-x192.json","offset":{"x":192,"y":12,"z":160},"requirements":{"minecraft:bricks":5,"minecraft:glass":22,"minecraft:stone_bricks":70},"sha256":"95e572877445811654ccc0e009348281d1380aa1257674ea74a842a8cd247ca5","size":{"x":32,"y":1,"z":32}},{"blockCount":39,"bytes":839,"file":"chunks/y012-z160-x224.json","offset":{"x":224,"y":12,"z":160},"requirements":{"minecraft:bricks":3,"minecraft:oak_planks":36},"sha256":"2ad2423f817a8bde835b2df9165dbb551b69137c0b9de8f4a8abc1e922da48fc","size":{"x":32,"y":1,"z":32}},{"blockCount":267,"bytes":2916,"file":"chunks/y012-z160-x256.json","offset":{"x":256,"y":12,"z":160},"requirements":{"minecraft:bricks":29,"minecraft:oak_planks":217,"minecraft:stone_bricks":21},"sha256":"2947dfbd8139f8d3b603467afbb44b9423533ab5eb41025de3d1ee3344465058","size":{"x":32,"y":1,"z":32}},{"blockCount":22,"bytes":1195,"file":"chunks/y012-z160-x288.json","offset":{"x":288,"y":12,"z":160},"requirements":{"minecraft:cobbled_deepslate":7,"minecraft:glass":1,"minecraft:oak_planks":3,"minecraft:spruce_planks":1,"minecraft:stone_bricks":10},"sha256":"42151421c6faf4c39420b495bb95d75357d1cba0158c99832f129ac4dcef24ff","size":{"x":32,"y":1,"z":32}},{"blockCount":215,"bytes":5078,"file":"chunks/y012-z160-x320.json","offset":{"x":320,"y":12,"z":160},"requirements":{"minecraft:bricks":32,"minecraft:cobbled_deepslate":25,"minecraft:glass":91,"minecraft:sandstone":3,"minecraft:spruce_planks":4,"minecraft:stone_bricks":60},"sha256":"0dcd49fa4bc2cee8e03908c440dff08ca7611733bde8172cf3186f8dc9296352","size":{"x":32,"y":1,"z":32}},{"blockCount":429,"bytes":10561,"file":"chunks/y012-z160-x352.json","offset":{"x":352,"y":12,"z":160},"requirements":{"minecraft:bricks":120,"minecraft:glass":241,"minecraft:stone_bricks":68},"sha256":"c1094697db769ee64faca0593ce51bf844957c5c1637a94d4543f7677af66c47","size":{"x":32,"y":1,"z":32}},{"blockCount":5,"bytes":642,"file":"chunks/y012-z192-x064.json","offset":{"x":64,"y":12,"z":192},"requirements":{"minecraft:stone_bricks":5},"sha256":"d4958f1dd181793ee0865aa8556073c827afb3dbf510ffef3528ffc0aa57aba2","size":{"x":32,"y":1,"z":32}},{"blockCount":37,"bytes":1009,"file":"chunks/y012-z192-x096.json","offset":{"x":96,"y":12,"z":192},"requirements":{"minecraft:stone_bricks":37},"sha256":"05e9d1031fd1e5e714944ff7cd579767d22716503c98aee6957075f70cb891c9","size":{"x":32,"y":1,"z":32}},{"blockCount":15,"bytes":876,"file":"chunks/y012-z192-x128.json","offset":{"x":128,"y":12,"z":192},"requirements":{"minecraft:stone_bricks":15},"sha256":"6691019fbd2cb8eb2e6f7a6db2ac3e24a7c37c985c5d57f3955f10024a064808","size":{"x":32,"y":1,"z":32}},{"blockCount":71,"bytes":2067,"file":"chunks/y012-z192-x160.json","offset":{"x":160,"y":12,"z":192},"requirements":{"minecraft:cobbled_deepslate":43,"minecraft:glass":1,"minecraft:stone_bricks":27},"sha256":"948a11d0cee333c1978718cdc930517023d69eb6692c2a34fb8f99efc56f8224","size":{"x":32,"y":1,"z":32}},{"blockCount":116,"bytes":1806,"file":"chunks/y012-z192-x192.json","offset":{"x":192,"y":12,"z":192},"requirements":{"minecraft:cobbled_deepslate":32,"minecraft:glass":22,"minecraft:stone_bricks":62},"sha256":"194f45d14f4b569940c95751b877710784cc38b9070b606ff86078fe11997833","size":{"x":32,"y":1,"z":32}},{"blockCount":19,"bytes":651,"file":"chunks/y012-z192-x224.json","offset":{"x":224,"y":12,"z":192},"requirements":{"minecraft:cobbled_deepslate":19},"sha256":"21bfa3221dc57887e128d8d9365638fad9077ef0ae550a889b129e00e008ca7d","size":{"x":32,"y":1,"z":32}},{"blockCount":60,"bytes":1972,"file":"chunks/y012-z192-x256.json","offset":{"x":256,"y":12,"z":192},"requirements":{"minecraft:cobbled_deepslate":6,"minecraft:glass":1,"minecraft:spruce_planks":1,"minecraft:stone_bricks":52},"sha256":"118fd888afe3ac4b695f8784b634474e8076143de998d744ce4e2b873d5b2d7b","size":{"x":32,"y":1,"z":32}},{"blockCount":32,"bytes":1813,"file":"chunks/y012-z192-x288.json","offset":{"x":288,"y":12,"z":192},"requirements":{"minecraft:cobbled_deepslate":2,"minecraft:glass":1,"minecraft:spruce_planks":1,"minecraft:stone_bricks":28},"sha256":"38be2f9f91f077a22903e0c6e3380bc00059cd62c6ba6a9441bbdcbd705431c0","size":{"x":32,"y":1,"z":32}},{"blockCount":240,"bytes":7022,"file":"chunks/y012-z192-x320.json","offset":{"x":320,"y":12,"z":192},"requirements":{"minecraft:glass":160,"minecraft:stone_bricks":80},"sha256":"d0c106842066d7239db035ecc9a29bfa45e40da68ed933e0abb782fb985b4bd1","size":{"x":32,"y":1,"z":32}},{"blockCount":480,"bytes":17326,"file":"chunks/y012-z192-x352.json","offset":{"x":352,"y":12,"z":192},"requirements":{"minecraft:glass":432,"minecraft:stone_bricks":48},"sha256":"7956087bc5a86353c07a2d3a839a0ef2723f7ba23c7a2f78cac9604facf49b98","size":{"x":32,"y":1,"z":32}},{"blockCount":9,"bytes":956,"file":"chunks/y012-z224-x256.json","offset":{"x":256,"y":12,"z":224},"requirements":{"minecraft:spruce_planks":9},"sha256":"4c9c01017ac86b4f7f1d2819314b2911c244a0e3c4f5de2ef21968e836376150","size":{"x":32,"y":1,"z":15}},{"blockCount":9,"bytes":955,"file":"chunks/y012-z224-x288.json","offset":{"x":288,"y":12,"z":224},"requirements":{"minecraft:spruce_planks":9},"sha256":"66bd5067fbc9f03a2141e7d1a2df40a5d66e51910ecdd536cf6e381e3567636c","size":{"x":32,"y":1,"z":15}},{"blockCount":32,"bytes":915,"file":"chunks/y012-z224-x320.json","offset":{"x":320,"y":12,"z":224},"requirements":{"minecraft:glass":5,"minecraft:stone_bricks":27},"sha256":"fe4a3eb22176f939d7801ceef50160e2a9e688fd6cba488a55488ce0a2b19b1c","size":{"x":32,"y":1,"z":15}},{"blockCount":81,"bytes":1218,"file":"chunks/y012-z224-x352.json","offset":{"x":352,"y":12,"z":224},"requirements":{"minecraft:glass":13,"minecraft:stone_bricks":68},"sha256":"50f0de00d3f7b3c36773127c4e4ab9aa5645b201727d1abbbd03743b829dd277","size":{"x":32,"y":1,"z":15}},{"blockCount":25,"bytes":991,"file":"chunks/y013-z000-x320.json","offset":{"x":320,"y":13,"z":0},"requirements":{"minecraft:sandstone":25},"sha256":"c76cf71e044acc8a7118f9243b85531c36020e56d0fe7666035156169a868334","size":{"x":32,"y":1,"z":32}},{"blockCount":32,"bytes":641,"file":"chunks/y013-z000-x352.json","offset":{"x":352,"y":13,"z":0},"requirements":{"minecraft:sandstone":32},"sha256":"587f75d1d5f554940b84f52dd50424909de730941bfea8d223134cdd1a8cdd52","size":{"x":32,"y":1,"z":32}},{"blockCount":14,"bytes":990,"file":"chunks/y013-z000-x384.json","offset":{"x":384,"y":13,"z":0},"requirements":{"minecraft:sandstone":14},"sha256":"3386aa0d9a2966f1a698e37c4481d3014d96240790612d72dcbee55ba0acca68","size":{"x":32,"y":1,"z":32}},{"blockCount":189,"bytes":4862,"file":"chunks/y013-z032-x320.json","offset":{"x":320,"y":13,"z":32},"requirements":{"minecraft:bricks":60,"minecraft:glass":8,"minecraft:sandstone":7,"minecraft:spruce_planks":68,"minecraft:stone_bricks":46},"sha256":"f67475b9590e0c83f4627b34b60017d43a82d5767ceabf33becd9d36469e645f","size":{"x":32,"y":1,"z":32}},{"blockCount":77,"bytes":2724,"file":"chunks/y013-z032-x352.json","offset":{"x":352,"y":13,"z":32},"requirements":{"minecraft:bricks":6,"minecraft:cobbled_deepslate":10,"minecraft:glass":18,"minecraft:oak_planks":1,"minecraft:spruce_planks":42},"sha256":"82be68ac47215cbe8ac4ff461ce63b6e5187b4b88aa5593c07c34997d6d90c75","size":{"x":32,"y":1,"z":32}},{"blockCount":161,"bytes":4185,"file":"chunks/y013-z032-x384.json","offset":{"x":384,"y":13,"z":32},"requirements":{"minecraft:bricks":17,"minecraft:cobbled_deepslate":5,"minecraft:sandstone":9,"minecraft:spruce_planks":11,"minecraft:stone_bricks":119},"sha256":"cd90bdfe853c6c5cf75033ed3ed2df7e5ca53252dcc744ed02170072d34f04b7","size":{"x":32,"y":1,"z":32}},{"blockCount":8,"bytes":738,"file":"chunks/y013-z064-x032.json","offset":{"x":32,"y":13,"z":64},"requirements":{"minecraft:stone_bricks":8},"sha256":"b8f03c807b7e86d767081de94af1a95e60bb2a71bf22ad4d88bed7de3a7a4a47","size":{"x":32,"y":1,"z":32}},{"blockCount":51,"bytes":1069,"file":"chunks/y013-z064-x064.json","offset":{"x":64,"y":13,"z":64},"requirements":{"minecraft:stone_bricks":51},"sha256":"889033dd02a50d6c2fd76a41a8e6d8ffbc6aa83da6e21ad7296cce798b5dc3c9","size":{"x":32,"y":1,"z":32}},{"blockCount":53,"bytes":1566,"file":"chunks/y013-z064-x096.json","offset":{"x":96,"y":13,"z":64},"requirements":{"minecraft:stone_bricks":53},"sha256":"4defb5d9af9d735872f73a6e786ebf9893e7b7fe4fd431cb3296f7748d1f83b8","size":{"x":32,"y":1,"z":32}},{"blockCount":24,"bytes":1149,"file":"chunks/y013-z064-x128.json","offset":{"x":128,"y":13,"z":64},"requirements":{"minecraft:stone_bricks":24},"sha256":"29d432de67fc71eccbaaf8476e1ecb8122a8d2f609013b1aab8b612c391280a8","size":{"x":32,"y":1,"z":32}},{"blockCount":266,"bytes":4777,"file":"chunks/y013-z064-x320.json","offset":{"x":320,"y":13,"z":64},"requirements":{"minecraft:bricks":26,"minecraft:sandstone":32,"minecraft:spruce_planks":70,"minecraft:stone_bricks":138},"sha256":"b590737516acfddf80179e9b9912e284721a007e1e8e2d355b50ecef3f751c2c","size":{"x":32,"y":1,"z":32}},{"blockCount":261,"bytes":1792,"file":"chunks/y013-z064-x352.json","offset":{"x":352,"y":13,"z":64},"requirements":{"minecraft:bricks":6,"minecraft:cobbled_deepslate":10,"minecraft:sandstone":32,"minecraft:spruce_planks":16,"minecraft:stone_bricks":197},"sha256":"bd4ab54e65bdf5e653859e8ccae36c4430b5943bf47e0e461958bf7922cae37a","size":{"x":32,"y":1,"z":32}},{"blockCount":73,"bytes":2207,"file":"chunks/y013-z064-x384.json","offset":{"x":384,"y":13,"z":64},"requirements":{"minecraft:bricks":6,"minecraft:sandstone":21,"minecraft:spruce_planks":2,"minecraft:stone_bricks":44},"sha256":"5b7771192606bbdfcd151e1968fde8a1dc2e18436c3a249fd2356c9ab6110b21","size":{"x":32,"y":1,"z":32}},{"blockCount":70,"bytes":1849,"file":"chunks/y013-z096-x032.json","offset":{"x":32,"y":13,"z":96},"requirements":{"minecraft:stone_bricks":70},"sha256":"126ab8f1b2350c9ae79348a1cc03b9f6185c289c904a73e437c9c844a5bfc534","size":{"x":32,"y":1,"z":32}},{"blockCount":199,"bytes":3278,"file":"chunks/y013-z096-x064.json","offset":{"x":64,"y":13,"z":96},"requirements":{"minecraft:stone_bricks":199},"sha256":"84b011d855f48e894e944c4d1de180dc42dff8aa03e3fae803cb13fd3c33cd70","size":{"x":32,"y":1,"z":32}},{"blockCount":171,"bytes":2992,"file":"chunks/y013-z096-x096.json","offset":{"x":96,"y":13,"z":96},"requirements":{"minecraft:stone_bricks":171},"sha256":"45024e8ed0c75dce65fbac192fae3b243548171460de7be359c2357b3234b22c","size":{"x":32,"y":1,"z":32}},{"blockCount":167,"bytes":3115,"file":"chunks/y013-z096-x128.json","offset":{"x":128,"y":13,"z":96},"requirements":{"minecraft:stone_bricks":167},"sha256":"323a294719e651070164697ffd7efb3d93f111fd8a34d55417109d63154564cd","size":{"x":32,"y":1,"z":32}},{"blockCount":10,"bytes":947,"file":"chunks/y013-z096-x192.json","offset":{"x":192,"y":13,"z":96},"requirements":{"minecraft:bricks":10},"sha256":"f3f6354b014b16198555735ac4241f383f855097640a7732d74bc524b69d9db7","size":{"x":32,"y":1,"z":32}}],"schema":1}
