{"entries":[{"blockCount":12,"bytes":1006,"file":"chunks/y013-z096-x224.json","offset":{"x":224,"y":13,"z":96},"requirements":{"minecraft:bricks":11,"minecraft:glass":1},"sha256":"3935c0393007a26da41485a45b3bfe69cf5939d329633605be87f464c018bcaf","size":{"x":32,"y":1,"z":32}},{"blockCount":21,"bytes":994,"file":"chunks/y013-z096-x256.json","offset":{"x":256,"y":13,"z":96},"requirements":{"minecraft:cobbled_deepslate":13,"minecraft:glass":1,"minecraft:spruce_planks":6,"minecraft:stone_bricks":1},"sha256":"28fa6195e44deab03a83ab34b4e68914128480e890767a7d1957afcca105c24e","size":{"x":32,"y":1,"z":32}},{"blockCount":51,"bytes":1366,"file":"chunks/y013-z096-x288.json","offset":{"x":288,"y":13,"z":96},"requirements":{"minecraft:cobbled_deepslate":44,"minecraft:spruce_planks":7},"sha256":"b4026acf49bcdb20e54ed13c58f8f863f13ac0a51c06995d3bd80f3896039c96","size":{"x":32,"y":1,"z":32}},{"blockCount":239,"bytes":4122,"file":"chunks/y013-z096-x320.json","offset":{"x":320,"y":13,"z":96},"requirements":{"minecraft:bricks":52,"minecraft:cobbled_deepslate":39,"minecraft:spruce_planks":46,"minecraft:stone_bricks":102},"sha256":"12895c8235ed4a2821b7165adbcb8b97a9f67e902575bde2a070e0b8b60d8935","size":{"x":32,"y":1,"z":32}},{"blockCount":771,"bytes":1845,"file":"chunks/y013-z096-x352.json","offset":{"x":352,"y":13,"z":96},"requirements":{"minecraft:bricks":403,"minecraft:stone_bricks":368},"sha256":"8a44c35bdff39a8b39643dbc9c3eac6df5662103aac2a0ee7d7395aadadbc477","size":{"x":32,"y":1,"z":32}},{"blockCount":12,"bytes":818,"file":"chunks/y013-z096-x384.json","offset":{"x":384,"y":13,"z":96},"requirements":{"minecraft:stone_bricks":12},"sha256":"cd300c82b137e364097ce30f7947c82ba6aea28b61b7bb7f973a6bc16d361022","size":{"x":32,"y":1,"z":32}},{"blockCount":53,"bytes":1559,"file":"chunks/y013-z128-x032.json","offset":{"x":32,"y":13,"z":128},"requirements":{"minecraft:stone_bricks":53},"sha256":"d9a7ae2797b2ce41e51d1a441a49e6232b6ca8d21df21105dbe6c1e0a6d61a24","size":{"x":32,"y":1,"z":32}},{"blockCount":68,"bytes":1793,"file":"chunks/y013-z128-x064.json","offset":{"x":64,"y":13,"z":128},"requirements":{"minecraft:stone_bricks":68},"sha256":"22c3b2ca80e7b0408521ebf21ba19464a8d52118e6320aa93cb6e40001289132","size":{"x":32,"y":1,"z":32}},{"blockCount":84,"bytes":1962,"file":"chunks/y013-z128-x096.json","offset":{"x":96,"y":13,"z":128},"requirements":{"minecraft:stone_bricks":84},"sha256":"25f75b603bd87d873d563b600bf09459e085c87c9aab3312fc4af7a735d0553c","size":{"x":32,"y":1,"z":32}},{"blockCount":100,"bytes":2499,"file":"chunks/y013-z128-x128.json","offset":{"x":128,"y":13,"z":128},"requirements":{"minecraft:stone_bricks":100},"sha256":"b99467620c51bf69c3ed6d76adbb12ace96ba993d8a197288f84eed60bcc3126","size":{"x":32,"y":1,"z":32}},{"blockCount":135,"bytes":3432,"file":"chunks/y013-z128-x160.json","offset":{"x":160,"y":13,"z":128},"requirements":{"minecraft:cobbled_deepslate":21,"minecraft:glass":15,"minecraft:spruce_planks":6,"minecraft:stone_bricks":93},"sha256":"2b3508743c2384ce6b662a5d73a892b8b021a3506c7a194a2778bd8823521e58","size":{"x":32,"y":1,"z":32}},{"blockCount":141,"bytes":3527,"file":"chunks/y013-z128-x192.json","offset":{"x":192,"y":13,"z":128},"requirements":{"minecraft:bricks":13,"minecraft:cobbled_deepslate":10,"minecraft:glass":22,"minecraft:stone_bricks":96},"sha256":"6ec370323535ee997d1a13e4793ef4b8c50366ddfcbdaf7b89720a876ca107e3","size":{"x":32,"y":1,"z":32}},{"blockCount":96,"bytes":2963,"file":"chunks/y013-z128-x224.json","offset":{"x":224,"y":13,"z":128},"requirements":{"minecraft:bricks":17,"minecraft:glass":1,"minecraft:polished_diorite":4,"minecraft:spruce_planks":1,"minecraft:stone_bricks":73},"sha256":"0064cf0e4d44a11545fc8ab3cb9fc15abb4d9c84d3fd043c51d021799e74f0b6","size":{"x":32,"y":1,"z":32}},{"blockCount":125,"bytes":4335,"file":"chunks/y013-z128-x256.json","offset":{"x":256,"y":13,"z":128},"requirements":{"minecraft:cobbled_deepslate":32,"minecraft:glass":17,"minecraft:polished_diorite":12,"minecraft:spruce_planks":7,"minecraft:stone_bricks":57},"sha256":"8cd12be75524c0d1fd2b72f050e6009c8500c4ae0f4c6d64ddacfb9013e189d2","size":{"x":32,"y":1,"z":32}},{"blockCount":128,"bytes":4379,"file":"chunks/y013-z128-x288.json","offset":{"x":288,"y":13,"z":128},"requirements":{"minecraft:cobbled_deepslate":86,"minecraft:glass":27,"minecraft:spruce_planks":9,"minecraft:stone_bricks":6},"sha256":"3b6835c78e7cf64714110bb36a248cf45685994fd02a98a4d28956473d087449","size":{"x":32,"y":1,"z":32}},{"blockCount":136,"bytes":3368,"file":"chunks/y013-z128-x320.json","offset":{"x":320,"y":13,"z":128},"requirements":{"minecraft:bricks":96,"minecraft:cobbled_deepslate":32,"minecraft:stone_bricks":8},"sha256":"5588c9b69e01dcda9c40cc264bbbd4ec7a0887ca89d4fdff156c18f5d51fedfa","size":{"x":32,"y":1,"z":32}},{"blockCount":896,"bytes":1827,"file":"chunks/y013-z128-x352.json","offset":{"x":352,"y":13,"z":128},"requirements":{"minecraft:bricks":896},"sha256":"128050859d4dc9b75ab61157468909575f58723cb4170263bfd7482877798b78","size":{"x":32,"y":1,"z":32}},{"blockCount":59,"bytes":1734,"file":"chunks/y013-z160-x032.json","offset":{"x":32,"y":13,"z":160},"requirements":{"minecraft:stone_bricks":59},"sha256":"0263b261b18cc8667c036b7f3cbc1e2e5e475a5ead132842b9fdd119b6f8e423","size":{"x":32,"y":1,"z":32}},{"blockCount":195,"bytes":2999,"file":"chunks/y013-z160-x064.json","offset":{"x":64,"y":13,"z":160},"requirements":{"minecraft:stone_bricks":195},"sha256":"1f0cca9476db0aea42511ecc6d57e518a93f84594c1442d64986432eda921951","size":{"x":32,"y":1,"z":32}},{"blockCount":156,"bytes":3085,"file":"chunks/y013-z160-x096.json","offset":{"x":96,"y":13,"z":160},"requirements":{"minecraft:stone_bricks":156},"sha256":"c58d1e791b4f85e57e75f89068fa1fa6e2589198c2086c39b621f66695285f2e","size":{"x":32,"y":1,"z":32}},{"blockCount":127,"bytes":2738,"file":"chunks/y013-z160-x128.json","offset":{"x":128,"y":13,"z":160},"requirements":{"minecraft:stone_bricks":127},"sha256":"12a7276fc32b3985a1b7fdd172567a6c7de2345e4db32ef5df1d88cbba6e735c","size":{"x":32,"y":1,"z":32}},{"blockCount":143,"bytes":4903,"file":"chunks/y013-z160-x160.json","offset":{"x":160,"y":13,"z":160},"requirements":{"minecraft:cobbled_deepslate":30,"minecraft:glass":6,"minecraft:stone_bricks":107},"sha256":"044917547dc65cedc418ec6d7b11f28dbc522dffeda8f63e4430193d14d6189a","size":{"x":32,"y":1,"z":32}},{"blockCount":94,"bytes":2727,"file":"chunks/y013-z160-x192.json","offset":{"x":192,"y":13,"z":160},"requirements":{"minecraft:bricks":10,"minecraft:glass":19,"minecraft:stone_bricks":65},"sha256":"30af0efffa0f874d7f3739c17620d2bf57690c8f5dffd04b8cdbb6f05e57f12b","size":{"x":32,"y":1,"z":32}},{"blockCount":11,"bytes":943,"file":"chunks/y013-z160-x224.json","offset":{"x":224,"y":13,"z":160},"requirements":{"minecraft:bricks":11},"sha256":"161d483eb7bf280a51ab1a4f2a4db92f20e8b4f9ea39a357542426d85a142986","size":{"x":32,"y":1,"z":32}},{"blockCount":346,"bytes":3814,"file":"chunks/y013-z160-x256.json","offset":{"x":256,"y":13,"z":160},"requirements":{"minecraft:bricks":29,"minecraft:oak_planks":220,"minecraft:spruce_planks":69,"minecraft:stone_bricks":28},"sha256":"49938721837979beab6be9514c1cc6a5e9d59b9dbc321212e97827108f40c559","size":{"x":32,"y":1,"z":32}},{"blockCount":70,"bytes":2030,"file":"chunks/y013-z160-x288.json","offset":{"x":288,"y":13,"z":160},"requirements":{"minecraft:cobbled_deepslate":7,"minecraft:glass":1,"minecraft:oak_planks":43,"minecraft:spruce_planks":8,"minecraft:stone_bricks":11},"sha256":"c615fe4ffa603b999cd9e8aaaa491f2d6ec38cbb25d7cf1462ae0aa0ccfc00f7","size":{"x":32,"y":1,"z":32}},{"blockCount":218,"bytes":5205,"file":"chunks/y013-z160-x320.json","offset":{"x":320,"y":13,"z":160},"requirements":{"minecraft:bricks":36,"minecraft:cobbled_deepslate":25,"minecraft:glass":14,"minecraft:spruce_planks":3,"minecraft:stone_bricks":140},"sha256":"7d13f54f4410a8cf05797222d49e4fee6b16662629f6b19b255c9fb290429caf","size":{"x":32,"y":1,"z":32}},{"blockCount":646,"bytes":10675,"file":"chunks/y013-z160-x352.json","offset":{"x":352,"y":13,"z":160},"requirements":{"minecraft:bricks":336,"minecraft:glass":22,"minecraft:stone_bricks":288},"sha256":"16bd4ca11e9e962adc234df5a03febe82efe39ce73d3bb88a3e17f37c8ecd4b4","size":{"x":32,"y":1,"z":32}},{"blockCount":5,"bytes":642,"file":"chunks/y013-z192-x064.json","offset":{"x":64,"y":13,"z":192},"requirements":{"minecraft:stone_bricks":5},"sha256":"2dbbbf67b70f8cab9b12146d3613f8b433e944b435af4df128c9c31f992d3684","size":{"x":32,"y":1,"z":32}},{"blockCount":37,"bytes":1009,"file":"chunks/y013-z192-x096.json","offset":{"x":96,"y":13,"z":192},"requirements":{"minecraft:stone_bricks":37},"sha256":"05defa5d73baa0e04be4e0cebec125ef4d33ea2e455970d490a0b73d5f8eda9e","size":{"x":32,"y":1,"z":32}},{"blockCount":15,"bytes":876,"file":"chunks/y013-z192-x128.json","offset":{"x":128,"y":13,"z":192},"requirements":{"minecraft:stone_bricks":15},"sha256":"80be257f510551b54eeca0eaecb6de19e6c5537a0b4dcae73570d49f230a0495","size":{"x":32,"y":1,"z":32}},{"blockCount":87,"bytes":2256,"file":"chunks/y013-z192-x160.json","offset":{"x":160,"y":13,"z":192},"requirements":{"minecraft:cobbled_deepslate":43,"minecraft:glass":2,"minecraft:stone_bricks":42},"sha256":"9bcd5b2afd18854a87e6955f7262d518527cf28bb8c2702a352a8fcb1ce93d38","size":{"x":32,"y":1,"z":32}},{"blockCount":101,"bytes":1957,"file":"chunks/y013-z192-x192.json","offset":{"x":192,"y":13,"z":192},"requirements":{"minecraft:cobbled_deepslate":32,"minecraft:glass":19,"minecraft:stone_bricks":50},"sha256":"2f5daef5e4216367f35dcaf98bc2820e0b7e819f8aa4f5bd2b8a3bd8ecf2f5b0","size":{"x":32,"y":1,"z":32}},{"blockCount":19,"bytes":651,"file":"chunks/y013-z192-x224.json","offset":{"x":224,"y":13,"z":192},"requirements":{"minecraft:cobbled_deepslate":19},"sha256":"7d42501773f1cabde2a31be1bcb05426b8280795896b87c13143da1df697af34","size":{"x":32,"y":1,"z":32}},{"blockCount":101,"bytes":2261,"file":"chunks/y013-z192-x256.json","offset":{"x":256,"y":13,"z":192},"requirements":{"minecraft:cobbled_deepslate":6,"minecraft:glass":1,"minecraft:spruce_planks":42,"minecraft:stone_bricks":52},"sha256":"ad7e96ac9e6b69213c982d32bc861ea2345509ad1573a6290e6797a225b023c0","size":{"x":32,"y":1,"z":32}},{"blockCount":49,"bytes":2100,"file":"chunks/y013-z192-x288.json","offset":{"x":288,"y":13,"z":192},"requirements":{"minecraft:cobbled_deepslate":2,"minecraft:glass":1,"minecraft:spruce_planks":18,"minecraft:stone_bricks":28},"sha256":"7ded6840686f285a97c939d70f37f8824bde6f04257f7d8c111f891cceb0f6fe","size":{"x":32,"y":1,"z":32}},{"blockCount":240,"bytes":7326,"file":"chunks/y013-z192-x320.json","offset":{"x":320,"y":13,"z":192},"requirements":{"minecraft:glass":16,"minecraft:stone_bricks":224},"sha256":"0416c5b352e243ce48b71b5795d0df1a5bdb6bb1b508f165c683ba48c5d16adc","size":{"x":32,"y":1,"z":32}},{"blockCount":480,"bytes":17630,"file":"chunks/y013-z192-x352.json","offset":{"x":352,"y":13,"z":192},"requirements":{"minecraft:glass":16,"minecraft:stone_bricks":464},"sha256":"3cd6f3805220b145a014c2f27e4bb3325b169e2f53c7d9b4ed5acbde9628686e","size":{"x":32,"y":1,"z":32}},{"blockCount":22,"bytes":997,"file":"chunks/y013-z224-x256.json","offset":{"x":256,"y":13,"z":224},"requirements":{"minecraft:spruce_planks":22},"sha256":"a891d5253a0f07b85f9da968fdecb9e1071feb469615bd46c746d5038f52f15c","size":{"x":32,"y":1,"z":15}},{"blockCount":10,"bytes":976,"file":"chunks/y013-z224-x288.json","offset":{"x":288,"y":13,"z":224},"requirements":{"minecraft:spruce_planks":10},"sha256":"22c11e334f2ccfdd570a8d1e1dbb3830d5e8bfdc9ce02e9f6960034989753215","size":{"x":32,"y":1,"z":15}},{"blockCount":32,"bytes":915,"file":"chunks/y013-z224-x320.json","offset":{"x":320,"y":13,"z":224},"requirements":{"minecraft:glass":5,"minecraft:stone_bricks":27},"sha256":"c980b83b796618593ca72d7bb1a6312c33d65301a753d95ce69a11d663a3578c","size":{"x":32,"y":1,"z":15}},{"blockCount":81,"bytes":1218,"file":"chunks/y013-z224-x352.json","offset":{"x":352,"y":13,"z":224},"requirements":{"minecraft:glass":13,"minecraft:stone_bricks":68},"sha256":"aacf3c45a800c25605bdd2e888169ed50aae3750ed74ba9c60177a8107b46324","size":{"x":32,"y":1,"z":15}},{"blockCount":25,"bytes":991,"file":"chunks/y014-z000-x320.json","offset":{"x":320,"y":14,"z":0},"requirements":{"minecraft:sandstone":25},"sha256":"85fd6b16e9281afa4d265689548b9559428c34968df789db2323d9ba7a12ebad","size":{"x":32,"y":1,"z":32}},{"blockCount":32,"bytes":641,"file":"chunks/y014-z000-x352.json","offset":{"x":352,"y":14,"z":0},"requirements":{"minecraft:sandstone":32},"sha256":"6656824f6dc97773246b7f614075610e6eec6f1c19eed0b2cf3ae029410f31b8","size":{"x":32,"y":1,"z":32}},{"blockCount":14,"bytes":990,"file":"chunks/y014-z000-x384.json","offset":{"x":384,"y":14,"z":0},"requirements":{"minecraft:sandstone":14},"sha256":"6851c55b2fc96a7417be0a57d1236d88c95fc001b9623a581c032b6673d6ad1c","size":{"x":32,"y":1,"z":32}},{"blockCount":93,"bytes":2525,"file":"chunks/y014-z032-x320.json","offset":{"x":320,"y":14,"z":32},"requirements":{"minecraft:bricks":1,"minecraft:glass":8,"minecraft:sandstone":9,"minecraft:spruce_planks":75},"sha256":"a3bd3cf0feaf894e6415b361397094303465bd565caec909aa01bfc8b5be4c68","size":{"x":32,"y":1,"z":32}},{"blockCount":89,"bytes":2396,"file":"chunks/y014-z032-x352.json","offset":{"x":352,"y":14,"z":32},"requirements":{"minecraft:cobbled_deepslate":4,"minecraft:glass":18,"minecraft:sandstone":1,"minecraft:spruce_planks":66},"sha256":"ed07b9984e2019e80b4fe4a018e61cba9eb182c89f7fc506655f72806c0349a9","size":{"x":32,"y":1,"z":32}},{"blockCount":173,"bytes":4185,"file":"chunks/y014-z032-x384.json","offset":{"x":384,"y":14,"z":32},"requirements":{"minecraft:bricks":8,"minecraft:cobbled_deepslate":5,"minecraft:sandstone":11,"minecraft:spruce_planks":29,"minecraft:stone_bricks":120},"sha256":"02d090349be194c0bd6a921d79f70fb51a40e9e3772695ec18dbf551cd06ca57","size":{"x":32,"y":1,"z":32}},{"blockCount":6,"bytes":757,"file":"chunks/y014-z064-x032.json","offset":{"x":32,"y":14,"z":64},"requirements":{"minecraft:stone_bricks":6},"sha256":"f364db7b09d6d041d78497c9c2762ba1bc87d71b9e442c7b0367d107f4682cac","size":{"x":32,"y":1,"z":32}},{"blockCount":45,"bytes":1069,"file":"chunks/y014-z064-x064.json","offset":{"x":64,"y":14,"z":64},"requirements":{"minecraft:stone_bricks":45},"sha256":"234319dca36ccc2622d08e603b4cedb3f993590c22130e2ede7d962c6181a255","size":{"x":32,"y":1,"z":32}},{"blockCount":53,"bytes":1566,"file":"chunks/y014-z064-x096.json","offset":{"x":96,"y":14,"z":64},"requirements":{"minecraft:stone_bricks":53},"sha256":"ee3b4ec78762459a2b234e2fffe4fe633025ac07b41e94728d0f256b88f92032","size":{"x":32,"y":1,"z":32}},{"blockCount":24,"bytes":1149,"file":"chunks/y014-z064-x128.json","offset":{"x":128,"y":14,"z":64},"requirements":{"minecraft:stone_bricks":24},"sha256":"3eb79b68ad70d3ef3df29c25404ef5fdd1c0641f972b0b3d1d6a67afdeffe080","size":{"x":32,"y":1,"z":32}},{"blockCount":121,"bytes":2060,"file":"chunks/y014-z064-x320.json","offset":{"x":320,"y":14,"z":64},"requirements":{"minecraft:bricks":1,"minecraft:sandstone":34,"minecraft:spruce_planks":23,"minecraft:stone_bricks":63},"sha256":"081b4be05f05455cd7361836e16838bc53cd33691b9a9802401a362113442891","size":{"x":32,"y":1,"z":32}},{"blockCount":301,"bytes":1233,"file":"chunks/y014-z064-x352.json","offset":{"x":352,"y":14,"z":64},"requirements":{"minecraft:cobbled_deepslate":4,"minecraft:sandstone":33,"minecraft:spruce_planks":40,"minecraft:stone_bricks":224},"sha256":"b57767cedcfab6107b440cec09a0ad5535bfe5fae8742aad0357fe0cea7adf17","size":{"x":32,"y":1,"z":32}},{"blockCount":77,"bytes":2207,"file":"chunks/y014-z064-x384.json","offset":{"x":384,"y":14,"z":64},"requirements":{"minecraft:bricks":1,"minecraft:sandstone":25,"minecraft:spruce_planks":7,"minecraft:stone_bricks":44},"sha256":"f68073e8756b174d34e61684761d21d047560649a8b012437d250c2c9f34e2a6","size":{"x":32,"y":1,"z":32}},{"blockCount":59,"bytes":1849,"file":"chunks/y014-z096-x032.json","offset":{"x":32,"y":14,"z":96},"requirements":{"minecraft:stone_bricks":59},"sha256":"2430a7cb0a1f1fc52d2f944d365284caf6a0a7cec7098aa9725df7b2385226a8","size":{"x":32,"y":1,"z":32}},{"blockCount":164,"bytes":3353,"file":"chunks/y014-z096-x064.json","offset":{"x":64,"y":14,"z":96},"requirements":{"minecraft:stone_bricks":164},"sha256":"874727eb9a5db53c476a7e5282dcbe0668ac80350cc93ff04f8627fa2e2207f8","size":{"x":32,"y":1,"z":32}},{"blockCount":168,"bytes":3029,"file":"chunks/y014-z096-x096.json","offset":{"x":96,"y":14,"z":96},"requirements":{"minecraft:stone_bricks":168},"sha256":"9ff71badc5ff6ef586954afbad95b3ed167115f2c9a7b3fa9b0e3655d34c905f","size":{"x":32,"y":1,"z":32}},{"blockCount":167,"bytes":3115,"file":"chunks/y014-z096-x128.json","offset":{"x":128,"y":14,"z":96},"requirements":{"minecraft:stone_bricks":167},"sha256":"67ccbf11cdf8d5e569b0f754fcc15beae1b9f8f5e238e8376008bf3e7e17c245","size":{"x":32,"y":1,"z":32}},{"blockCount":14,"bytes":1139,"file":"chunks/y014-z096-x192.json","offset":{"x":192,"y":14,"z":96},"requirements":{"minecraft:bricks":14},"sha256":"eb4925a1963263b85e5963154972dd736ff4b6eae1d86f0fc61db8794af4f913","size":{"x":32,"y":1,"z":32}},{"blockCount":13,"bytes":1053,"file":"chunks/y014-z096-x224.json","offset":{"x":224,"y":14,"z":96},"requirements":{"minecraft:bricks":12,"minecraft:stone_bricks":1},"sha256":"c1fa58a70cd7d55ec719edb88346ac83eae942d31b5b2b953bebebfdc8b9e487","size":{"x":32,"y":1,"z":32}},{"blockCount":23,"bytes":878,"file":"chunks/y014-z096-x256.json","offset":{"x":256,"y":14,"z":96},"requirements":{"minecraft:cobbled_deepslate":13,"minecraft:spruce_planks":9,"minecraft:stone_bricks":1},"sha256":"cdea222b1e10a0379b55448fbc9b966794d50667ce70222b3bc54537b6078fbd","size":{"x":32,"y":1,"z":32}},{"blockCount":58,"bytes":1291,"file":"chunks/y014-z096-x288.json","offset":{"x":288,"y":14,"z":96},"requirements":{"minecraft:cobbled_deepslate":44,"minecraft:spruce_planks":14},"sha256":"eb0c4591abb6ad1c09e6abfbc09e78988780cb1994cc8e0aa547898e66f838fc","size":{"x":32,"y":1,"z":32}},{"blockCount":184,"bytes":1853,"file":"chunks/y014-z096-x320.json","offset":{"x":320,"y":14,"z":96},"requirements":{"minecraft:cobbled_deepslate":39,"minecraft:spruce_planks":1,"minecraft:stone_bricks":144},"sha256":"350fda56b9a04aace2210202e394c1dbb95b4f2d40adb72e4cceef25034847ac","size":{"x":32,"y":1,"z":32}},{"blockCount":242,"bytes":977,"file":"chunks/y014-z096-x352.json","offset":{"x":352,"y":14,"z":96},"requirements":{"minecraft:stone_bricks":242},"sha256":"f674e829e79f3794ccd303e1ae4e783cf3b7947e8f6bcb1ef0a22ca4bfd26b8e","size":{"x":32,"y":1,"z":32}},{"blockCount":12,"bytes":818,"file":"chunks/y014-z096-x384.json","offset":{"x":384,"y":14,"z":96},"requirements":{"minecraft:stone_bricks":12},"sha256":"7e0297a8e0943af9769f0ba2ebcf008948c0e5e24b9254760047182a0db9b797","size":{"x":32,"y":1,"z":32}},{"blockCount":56,"bytes":1559,"file":"chunks/y014-z128-x032.json","offset":{"x":32,"y":14,"z":128},"requirements":{"minecraft:stone_bricks":56},"sha256":"e68394ec6fdb3c4466dd4044e18d151060d1377036f5a0430258712fc1a73c74","size":{"x":32,"y":1,"z":32}},{"blockCount":71,"bytes":1792,"file":"chunks/y014-z128-x064.json","offset":{"x":64,"y":14,"z":128},"requirements":{"minecraft:stone_bricks":71},"sha256":"af9b0092f5c03cd6c79232ad29a8fc752dd82443f5b2be35003609950b689f64","size":{"x":32,"y":1,"z":32}},{"blockCount":89,"bytes":1999,"file":"chunks/y014-z128-x096.json","offset":{"x":96,"y":14,"z":128},"requirements":{"minecraft:stone_bricks":89},"sha256":"c4b15a1d761a0da84fcf918b24b8d833aced465e296b2dbd1b3fb2bfb9c25b24","size":{"x":32,"y":1,"z":32}},{"blockCount":106,"bytes":2499,"file":"chunks/y014-z128-x128.json","offset":{"x":128,"y":14,"z":128},"requirements":{"minecraft:stone_bricks":106},"sha256":"4b5818d5559e73bc4c576716682461c3d2aff06c2ff29a8b7c4a0fa9515d28e7","size":{"x":32,"y":1,"z":32}},{"blockCount":131,"bytes":3489,"file":"chunks/y014-z128-x160.json","offset":{"x":160,"y":14,"z":128},"requirements":{"minecraft:cobbled_deepslate":21,"minecraft:glass":9,"minecraft:spruce_planks":6,"minecraft:stone_bricks":95},"sha256":"f4da73604bcaf73ef34b55521ca9875898d3e80627b7277e96d72ffee8cbed78","size":{"x":32,"y":1,"z":32}},{"blockCount":105,"bytes":2860,"file":"chunks/y014-z128-x192.json","offset":{"x":192,"y":14,"z":128},"requirements":{"minecraft:bricks":12,"minecraft:cobbled_deepslate":10,"minecraft:stone_bricks":83},"sha256":"d21e9c22ea9a55627c14a143173272c92701eda00f004eeebca39b4c605b2c60","size":{"x":32,"y":1,"z":32}},{"blockCount":122,"bytes":3467,"file":"chunks/y014-z128-x224.json","offset":{"x":224,"y":14,"z":128},"requirements":{"minecraft:bricks":30,"minecraft:cobbled_deepslate":1,"minecraft:polished_diorite":2,"minecraft:stone_bricks":89},"sha256":"491a240d15f5011d5f10a23ba41d0d7084deaa7579b6102015e02962fea933c9","size":{"x":32,"y":1,"z":32}},{"blockCount":110,"bytes":3593,"file":"chunks/y014-z128-x256.json","offset":{"x":256,"y":14,"z":128},"requirements":{"minecraft:cobbled_deepslate":36,"minecraft:glass":4,"minecraft:polished_diorite":6,"minecraft:spruce_planks":5,"minecraft:stone_bricks":59},"sha256":"dec8e5d4816fdf5c2523319e575369f0e601755fb052caa4d91406e5f587c963","size":{"x":32,"y":1,"z":32}},{"blockCount":102,"bytes":3594,"file":"chunks/y014-z128-x288.json","offset":{"x":288,"y":14,"z":128},"requirements":{"minecraft:cobbled_deepslate":86,"minecraft:glass":7,"minecraft:spruce_planks":9},"sha256":"002e8c57da0f61f9f2ad94375128245512a5a45510158fb5339ad38feccb840f","size":{"x":32,"y":1,"z":32}},{"blockCount":44,"bytes":2340,"file":"chunks/y014-z128-x320.json","offset":{"x":320,"y":14,"z":128},"requirements":{"minecraft:cobbled_deepslate":32,"minecraft:stone_bricks":12},"sha256":"e2bbf836bf4d4b1abd292ccc40339f17fc65352b988028beb05cfea23753ecb6","size":{"x":32,"y":1,"z":32}},{"blockCount":45,"bytes":1734,"file":"chunks/y014-z160-x032.json","offset":{"x":32,"y":14,"z":160},"requirements":{"minecraft:stone_bricks":45},"sha256":"e5b86ab4dfc856510bb26c733699406de8c51b90c549e54c0fe99e110abeeaab","size":{"x":32,"y":1,"z":32}},{"blockCount":155,"bytes":3037,"file":"chunks/y014-z160-x064.json","offset":{"x":64,"y":14,"z":160},"requirements":{"minecraft:stone_bricks":155},"sha256":"74dc5d3fedf4c7afe08c26721a6527cc8fd9513b1f8f7fefda9bc156d6b499df","size":{"x":32,"y":1,"z":32}},{"blockCount":158,"bytes":3142,"file":"chunks/y014-z160-x096.json","offset":{"x":96,"y":14,"z":160},"requirements":{"minecraft:stone_bricks":158},"sha256":"3ff587e95fa2c696198490d8e99f7b061eb6075f7841e90ff5b79201bc7aa0a5","size":{"x":32,"y":1,"z":32}},{"blockCount":127,"bytes":2738,"file":"chunks/y014-z160-x128.json","offset":{"x":128,"y":14,"z":160},"requirements":{"minecraft:stone_bricks":127},"sha256":"0c91abe07fe1c9b7abe6606aa37c320ad57c93146c2d26aeda3cb3e973817dda","size":{"x":32,"y":1,"z":32}},{"blockCount":135,"bytes":4747,"file":"chunks/y014-z160-x160.json","offset":{"x":160,"y":14,"z":160},"requirements":{"minecraft:cobbled_deepslate":30,"minecraft:glass":9,"minecraft:stone_bricks":96},"sha256":"2d9e371186f961bac704292265636884119ab834692c2729e961a999c2e80364","size":{"x":32,"y":1,"z":32}},{"blockCount":95,"bytes":1475,"file":"chunks/y014-z160-x192.json","offset":{"x":192,"y":14,"z":160},"requirements":{"minecraft:bricks":8,"minecraft:glass":5,"minecraft:stone_bricks":82},"sha256":"b5f23532dd2fc36444c07f67ad573a87b696e4877ef10251f8e74ffe0fe27d2d","size":{"x":32,"y":1,"z":32}},{"blockCount":1,"bytes":637,"file":"chunks/y014-z160-x224.json","offset":{"x":224,"y":14,"z":160},"requirements":{"minecraft:bricks":1},"sha256":"798f8c0ab19965f53895ac1bb49d1396763638f0dd5a9226d974d4e7a99851c2","size":{"x":32,"y":1,"z":32}},{"blockCount":213,"bytes":3667,"file":"chunks/y014-z160-x256.json","offset":{"x":256,"y":14,"z":160},"requirements":{"minecraft:oak_planks":12,"minecraft:sandstone":50,"minecraft:spruce_planks":127,"minecraft:stone_bricks":24},"sha256":"8c0b5f23cfc64e55e5137da99a3c8ae89364f5703260d62733ef0f9f83a44e84","size":{"x":32,"y":1,"z":32}},{"blockCount":50,"bytes":2034,"file":"chunks/y014-z160-x288.json","offset":{"x":288,"y":14,"z":160},"requirements":{"minecraft:cobbled_deepslate":7,"minecraft:oak_planks":1,"minecraft:sandstone":23,"minecraft:spruce_planks":8,"minecraft:stone_bricks":11},"sha256":"f7410e6eb73487437cca8b1a7735f7084c06ae69e1cb0586a54b59bb56c1344d","size":{"x":32,"y":1,"z":32}},{"blockCount":182,"bytes":4739,"file":"chunks/y014-z160-x320.json","offset":{"x":320,"y":14,"z":160},"requirements":{"minecraft:cobbled_deepslate":25,"minecraft:glass":14,"minecraft:spruce_planks":3,"minecraft:stone_bricks":140},"sha256":"7ce49d0f8f2f288a137c71027219357b7aa670ec76097c59f4f9b08b82968913","size":{"x":32,"y":1,"z":32}},{"blockCount":310,"bytes":10204,"file":"chunks/y014-z160-x352.json","offset":{"x":352,"y":14,"z":160},"requirements":{"minecraft:glass":22,"minecraft:stone_bricks":288},"sha256":"aac68b07fcd57bb31cecfb5650372c7d5196392e1d055c6d4d4004a2966b36bf","size":{"x":32,"y":1,"z":32}},{"blockCount":5,"bytes":642,"file":"chunks/y014-z192-x064.json","offset":{"x":64,"y":14,"z":192},"requirements":{"minecraft:stone_bricks":5},"sha256":"7e6fe7e3dce4a85df3e9d1c0131e5ecea55bc64505bbe4b718feefc51ee95327","size":{"x":32,"y":1,"z":32}},{"blockCount":37,"bytes":1009,"file":"chunks/y014-z192-x096.json","offset":{"x":96,"y":14,"z":192},"requirements":{"minecraft:stone_bricks":37},"sha256":"2300b4aaefff4fe7ddf4ea34122738af396c9737d619dfb664b5a20d7d5ab410","size":{"x":32,"y":1,"z":32}},{"blockCount":15,"bytes":876,"file":"chunks/y014-z192-x128.json","offset":{"x":128,"y":14,"z":192},"requirements":{"minecraft:stone_bricks":15},"sha256":"7c99868278ece1c807d541ded2adf5580c88a5e2df6d630fae81e3d92047a4cd","size":{"x":32,"y":1,"z":32}},{"blockCount":80,"bytes":2067,"file":"chunks/y014-z192-x160.json","offset":{"x":160,"y":14,"z":192},"requirements":{"minecraft:cobbled_deepslate":43,"minecraft:stone_bricks":37},"sha256":"1dd4ad95fe2fe8686f337a4c7337b17be4445381d4178b547e6f70a790637c80","size":{"x":32,"y":1,"z":32}},{"blockCount":61,"bytes":1237,"file":"chunks/y014-z192-x192.json","offset":{"x":192,"y":14,"z":192},"requirements":{"minecraft:cobbled_deepslate":32,"minecraft:glass":4,"minecraft:stone_bricks":25},"sha256":"7ed8705ecfe06362b9f34102d7950b581a2cedd3952644d9bce0a3e85bc246c5","size":{"x":32,"y":1,"z":32}},{"blockCount":19,"bytes":651,"file":"chunks/y014-z192-x224.json","offset":{"x":224,"y":14,"z":192},"requirements":{"minecraft:cobbled_deepslate":19},"sha256":"ffd442ebbf8798333ae9d2b5c2839319aef0e1f709b9cdb5e4c0d8285e4f5d99","size":{"x":32,"y":1,"z":32}},{"blockCount":117,"bytes":2394,"file":"chunks/y014-z192-x256.json","offset":{"x":256,"y":14,"z":192},"requirements":{"minecraft:cobbled_deepslate":22,"minecraft:spruce_planks":42,"minecraft:stone_bricks":53},"sha256":"16f04f6edfccfa005b2042d93d265656ea1631feae2ab0001aa8f462f2ead7de","size":{"x":32,"y":1,"z":32}},{"blockCount":58,"bytes":2253,"file":"chunks/y014-z192-x288.json","offset":{"x":288,"y":14,"z":192},"requirements":{"minecraft:cobbled_deepslate":7,"minecraft:spruce_planks":18,"minecraft:stone_bricks":33},"sha256":"43b2ba57d960b1f8e7e4f38745a72ffe98b86f4a1972e4661030099458b9155c","size":{"x":32,"y":1,"z":32}},{"blockCount":240,"bytes":7326,"file":"chunks/y014-z192-x320.json","offset":{"x":320,"y":14,"z":192},"requirements":{"minecraft:glass":16,"minecraft:stone_bricks":224},"sha256":"9acffdd21a895ec04fcaf8594ea65b2b37f7d3c898db4fd51061ad8d49f3daec","size":{"x":32,"y":1,"z":32}},{"blockCount":480,"bytes":17630,"file":"chunks/y014-z192-x352.json","offset":{"x":352,"y":14,"z":192},"requirements":{"minecraft:glass":16,"minecraft:stone_bricks":464},"sha256":"d3fd404b2ade3417a7003ef4817be80f075fc46a6f392ab6a668a83c50c724f4","size":{"x":32,"y":1,"z":32}},{"blockCount":22,"bytes":997,"file":"chunks/y014-z224-x256.json","offset":{"x":256,"y":14,"z":224},"requirements":{"minecraft:spruce_planks":22},"sha256":"845f4301b51e886d39d23514c4fb183049389238eeec72421adf7c68ed1d478c","size":{"x":32,"y":1,"z":15}},{"blockCount":10,"bytes":976,"file":"chunks/y014-z224-x288.json","offset":{"x":288,"y":14,"z":224},"requirements":{"minecraft:spruce_planks":10},"sha256":"522d60ab421f3d7d5f65310858d8c11bbee1773c1e5a88a0cfeab42127d68b9c","size":{"x":32,"y":1,"z":15}},{"blockCount":32,"bytes":915,"file":"chunks/y014-z224-x320.json","offset":{"x":320,"y":14,"z":224},"requirements":{"minecraft:glass":5,"minecraft:stone_bricks":27},"sha256":"d34c7b3e4ba98129367bbca977bff80020bc7e7b5ef71e47f371762998dab9cd","size":{"x":32,"y":1,"z":15}},{"blockCount":81,"bytes":1218,"file":"chunks/y014-z224-x352.json","offset":{"x":352,"y":14,"z":224},"requirements":{"minecraft:glass":13,"minecraft:stone_bricks":68},"sha256":"cc5e1cb2672286d6766f26a8671db3fc1b59de96ef52c7a27d684c35dbcfb70c","size":{"x":32,"y":1,"z":15}},{"blockCount":25,"bytes":991,"file":"chunks/y015-z000-x320.json","offset":{"x":320,"y":15,"z":0},"requirements":{"minecraft:sandstone":25},"sha256":"d82871b4ee8830319352d9ea5c300dd1071631f039862722497a9c5e7ffb7496","size":{"x":32,"y":1,"z":32}},{"blockCount":32,"bytes":641,"file":"chunks/y015-z000-x352.json","offset":{"x":352,"y":15,"z":0},"requirements":{"minecraft:sandstone":32},"sha256":"ba6cfeeb54f479acdd349ede4ceb07396d1c172995059e53ddc308efd7e68ba1","size":{"x":32,"y":1,"z":32}},{"blockCount":14,"bytes":990,"file":"chunks/y015-z000-x384.json","offset":{"x":384,"y":15,"z":0},"requirements":{"minecraft:sandstone":14},"sha256":"8e9f91d4ebd525c300286a882b953246af681eddafb9fb27377cdc8885e8ddac","size":{"x":32,"y":1,"z":32}},{"blockCount":60,"bytes":2661,"file":"chunks/y015-z032-x320.json","offset":{"x":320,"y":15,"z":32},"requirements":{"minecraft:bricks":21,"minecraft:glass":8,"minecraft:sandstone":9,"minecraft:spruce_planks":22},"sha256":"7612df15b5c0e14df0ed1be950d1949b21cd2e1d74245bcc429a3ce7a55b9a3b","size":{"x":32,"y":1,"z":32}},{"blockCount":78,"bytes":2686,"file":"chunks/y015-z032-x352.json","offset":{"x":352,"y":15,"z":32},"requirements":{"minecraft:bricks":6,"minecraft:cobbled_deepslate":16,"minecraft:glass":18,"minecraft:sandstone":1,"minecraft:spruce_planks":37},"sha256":"61e3cb28b663e4d9dd8345ecb864ae84670609b7cfe1283389a4e74337a80c36","size":{"x":32,"y":1,"z":32}},{"blockCount":167,"bytes":4207,"file":"chunks/y015-z032-x384.json","offset":{"x":384,"y":15,"z":32},"requirements":{"minecraft:bricks":11,"minecraft:cobbled_deepslate":5,"minecraft:sandstone":11,"minecraft:spruce_planks":16,"minecraft:stone_bricks":124},"sha256":"61ba34795eaa3484f608424b5c4fd336b53b417cf21f158b28d7c4763b605f06","size":{"x":32,"y":1,"z":32}},{"blockCount":6,"bytes":757,"file":"chunks/y015-z064-x032.json","offset":{"x":32,"y":15,"z":64},"requirements":{"minecraft:stone_bricks":6},"sha256":"ba82ce40c8f84430d4f2c3004766cb9879265b1a463bcebf3ff5d5bfb3054eab","size":{"x":32,"y":1,"z":32}},{"blockCount":48,"bytes":1069,"file":"chunks/y015-z064-x064.json","offset":{"x":64,"y":15,"z":64},"requirements":{"minecraft:stone_bricks":48},"sha256":"043847aa9d640b98086533b4a43997785104948a59bea8e5d567f98d871a7c6e","size":{"x":32,"y":1,"z":32}},{"blockCount":76,"bytes":1717,"file":"chunks/y015-z064-x096.json","offset":{"x":96,"y":15,"z":64},"requirements":{"minecraft:stone_bricks":76},"sha256":"0179fef62c5dbbbd33d199b436ec66bafc2ba02e0d3423c3bcfaf29caac37e71","size":{"x":32,"y":1,"z":32}},{"blockCount":35,"bytes":1187,"file":"chunks/y015-z064-x128.json","offset":{"x":128,"y":15,"z":64},"requirements":{"minecraft:stone_bricks":35},"sha256":"7ba554b0b08365fbacde2c0c91aa71a851f5f252a4b56a63a4b0e2ae70b2f9ab","size":{"x":32,"y":1,"z":32}},{"blockCount":112,"bytes":2077,"file":"chunks/y015-z064-x320.json","offset":{"x":320,"y":15,"z":64},"requirements":{"minecraft:bricks":9,"minecraft:sandstone":34,"minecraft:spruce_planks":6,"minecraft:stone_bricks":63},"sha256":"2c25a325de4c526eb972f12dbc784ba0d61815682131922c6ba137db7b9d57e6","size":{"x":32,"y":1,"z":32}},{"blockCount":288,"bytes":1503,"file":"chunks/y015-z064-x352.json","offset":{"x":352,"y":15,"z":64},"requirements":{"minecraft:bricks":6,"minecraft:cobbled_deepslate":16,"minecraft:sandstone":33,"minecraft:spruce_planks":9,"minecraft:stone_bricks":224},"sha256":"9ae7c1bc28fac8c780d43c7b1b230093a5e1c8dc5abb860ae69a9f5b55442de3","size":{"x":32,"y":1,"z":32}},{"blockCount":76,"bytes":2169,"file":"chunks/y015-z064-x384.json","offset":{"x":384,"y":15,"z":64},"requirements":{"minecraft:bricks":5,"minecraft:sandstone":25,"minecraft:spruce_planks":2,"minecraft:stone_bricks":44},"sha256":"c17ab937e653c946db618d8592a4360d772b2f3deaf6037ef973e1858ac7e237","size":{"x":32,"y":1,"z":32}},{"blockCount":131,"bytes":2230,"file":"chunks/y015-z096-x032.json","offset":{"x":32,"y":15,"z":96},"requirements":{"minecraft:stone_bricks":131},"sha256":"0ae76f63a2a6fa92e87e1c42a0beff73e1c0ab19639db8854642f5c57c979e37","size":{"x":32,"y":1,"z":32}},{"blockCount":189,"bytes":3504,"file":"chunks/y015-z096-x064.json","offset":{"x":64,"y":15,"z":96},"requirements":{"minecraft:stone_bricks":189},"sha256":"3e0b431ddb0fa51fa23b19197c9fcf359c6dd759be4d594973bbc4ed8ee82793","size":{"x":32,"y":1,"z":32}},{"blockCount":197,"bytes":3105,"file":"chunks/y015-z096-x096.json","offset":{"x":96,"y":15,"z":96},"requirements":{"minecraft:stone_bricks":197},"sha256":"4cae1a0fb62bc608f15d72700f885c5a0d148221086fc0008534bb2bc91e59c9","size":{"x":32,"y":1,"z":32}},{"blockCount":188,"bytes":3230,"file":"chunks/y015-z096-x128.json","offset":{"x":128,"y":15,"z":96},"requirements":{"minecraft:stone_bricks":188},"sha256":"4fa98f0fba24a937d77db8aa1bf523ac36c273b87c749478e1ecb1fd33bd2ad0","size":{"x":32,"y":1,"z":32}},{"blockCount":14,"bytes":1025,"file":"chunks/y015-z096-x192.json","offset":{"x":192,"y":15,"z":96},"requirements":{"minecraft:bricks":14},"sha256":"bcbd079a0849e3f94ce75e01ab66fb78e5c83412870284a387222ef38a578bc1","size":{"x":32,"y":1,"z":32}},{"blockCount":17,"bytes":1254,"file":"chunks/y015-z096-x224.json","offset":{"x":224,"y":15,"z":96},"requirements":{"minecraft:bricks":17},"sha256":"d5812e0adc7ff3714aff3510d39ac64ffc79ca621c45fc0eaa60f7df56fab1a3","size":{"x":32,"y":1,"z":32}},{"blockCount":14,"bytes":774,"file":"chunks/y015-z096-x256.json","offset":{"x":256,"y":15,"z":96},"requirements":{"minecraft:cobbled_deepslate":13,"minecraft:spruce_planks":1},"sha256":"2f8a491885eddff955631a54909fbd86112139c5783a921eb18ad28b4e03562c","size":{"x":32,"y":1,"z":32}},{"blockCount":46,"bytes":1177,"file":"chunks/y015-z096-x288.json","offset":{"x":288,"y":15,"z":96},"requirements":{"minecraft:cobbled_deepslate":44,"minecraft:spruce_planks":2},"sha256":"967dc7d4c8b91d140e414e43f8facebcde5a7af39cbcc8f05d0d4630261d1b93","size":{"x":32,"y":1,"z":32}},{"blockCount":184,"bytes":1853,"file":"chunks/y015-z096-x320.json","offset":{"x":320,"y":15,"z":96},"requirements":{"minecraft:cobbled_deepslate":39,"minecraft:spruce_planks":1,"minecraft:stone_bricks":144},"sha256":"317618e7465b6f1292f116d8ca809212b390a61e62043e0f156d50dd5761ec3b","size":{"x":32,"y":1,"z":32}},{"blockCount":242,"bytes":977,"file":"chunks/y015-z096-x352.json","offset":{"x":352,"y":15,"z":96},"requirements":{"minecraft:stone_bricks":242},"sha256":"7783d4814981249e811959ff624bbbeec0f5d1106078e4921eebfb66be730958","size":{"x":32,"y":1,"z":32}},{"blockCount":12,"bytes":818,"file":"chunks/y015-z096-x384.json","offset":{"x":384,"y":15,"z":96},"requirements":{"minecraft:stone_bricks":12},"sha256":"55bda0e1436a2d60a7a261d998793ad5d498fbfca5aaaef348d2bb7f2bb77dd7","size":{"x":32,"y":1,"z":32}},{"blockCount":90,"bytes":1749,"file":"chunks/y015-z128-x032.json","offset":{"x":32,"y":15,"z":128},"requirements":{"minecraft:stone_bricks":90},"sha256":"5e54f1be9409801b0579855f8ea480e1d26c8616bc4fbae39b5318a48608b0a8","size":{"x":32,"y":1,"z":32}},{"blockCount":78,"bytes":1906,"file":"chunks/y015-z128-x064.json","offset":{"x":64,"y":15,"z":128},"requirements":{"minecraft:stone_bricks":78},"sha256":"4605b17b4826244fe7cb5ad0ac7e9742d77ee3d4f6148d2b1f2702b8c31e6825","size":{"x":32,"y":1,"z":32}},{"blockCount":92,"bytes":2228,"file":"chunks/y015-z128-x096.json","offset":{"x":96,"y":15,"z":128},"requirements":{"minecraft:stone_bricks":92},"sha256":"32707b4f4d2ac3d98e282c1f98a2a3169e140ead24d82654d2663a1100b78fbc","size":{"x":32,"y":1,"z":32}}],"schema":1}
