{"entries":[{"blockCount":108,"bytes":2573,"file":"chunks/y015-z128-x128.json","offset":{"x":128,"y":15,"z":128},"requirements":{"minecraft:stone_bricks":108},"sha256":"c17963442403db6f2836eec37a8bcf6341a99279e1c59febb3301a3c8330fa82","size":{"x":32,"y":1,"z":32}},{"blockCount":134,"bytes":3224,"file":"chunks/y015-z128-x160.json","offset":{"x":160,"y":15,"z":128},"requirements":{"minecraft:cobbled_deepslate":21,"minecraft:glass":5,"minecraft:spruce_planks":6,"minecraft:stone_bricks":102},"sha256":"5f528ea8ae6764d9978940ec457f9359fe49fc21b45804ca1e5e4fb43a61e9ab","size":{"x":32,"y":1,"z":32}},{"blockCount":94,"bytes":2513,"file":"chunks/y015-z128-x192.json","offset":{"x":192,"y":15,"z":128},"requirements":{"minecraft:bricks":14,"minecraft:cobbled_deepslate":10,"minecraft:stone_bricks":70},"sha256":"8e194adfa2d031ab9c771e0e81b3b6198e7a861e577520cc0228fc44726d9a78","size":{"x":32,"y":1,"z":32}},{"blockCount":113,"bytes":3121,"file":"chunks/y015-z128-x224.json","offset":{"x":224,"y":15,"z":128},"requirements":{"minecraft:bricks":25,"minecraft:cobbled_deepslate":6,"minecraft:polished_diorite":4,"minecraft:stone_bricks":78},"sha256":"1d362f233821ed48f33dd87bcf7d5d78532bb0f2f3dc9df992ccfef54e57634f","size":{"x":32,"y":1,"z":32}},{"blockCount":130,"bytes":3556,"file":"chunks/y015-z128-x256.json","offset":{"x":256,"y":15,"z":128},"requirements":{"minecraft:cobbled_deepslate":36,"minecraft:glass":4,"minecraft:polished_diorite":12,"minecraft:spruce_planks":5,"minecraft:stone_bricks":73},"sha256":"a3fcc8803726c763166c5f837cbf341ce3b641f055a0bdad87c2de234ad3a7cd","size":{"x":32,"y":1,"z":32}},{"blockCount":102,"bytes":3594,"file":"chunks/y015-z128-x288.json","offset":{"x":288,"y":15,"z":128},"requirements":{"minecraft:cobbled_deepslate":86,"minecraft:glass":7,"minecraft:spruce_planks":9},"sha256":"b50da3a8aef36c076bc738423d3691f7aa02e63f2b24ca5c5cd1232a5e2d2010","size":{"x":32,"y":1,"z":32}},{"blockCount":48,"bytes":2494,"file":"chunks/y015-z128-x320.json","offset":{"x":320,"y":15,"z":128},"requirements":{"minecraft:cobbled_deepslate":32,"minecraft:stone_bricks":16},"sha256":"47f1095bca2741a9a3a9920f4711750968bd0c27e3773b9e8ba977ba576927ff","size":{"x":32,"y":1,"z":32}},{"blockCount":85,"bytes":1924,"file":"chunks/y015-z160-x032.json","offset":{"x":32,"y":15,"z":160},"requirements":{"minecraft:stone_bricks":85},"sha256":"905ecba462c0f9330f1f1f6cf5a3abe8af48160487926b9299d84fa03c0e6a6c","size":{"x":32,"y":1,"z":32}},{"blockCount":174,"bytes":3075,"file":"chunks/y015-z160-x064.json","offset":{"x":64,"y":15,"z":160},"requirements":{"minecraft:stone_bricks":174},"sha256":"886ae6861ddc90a396377540c120766aaf6b806ba2ef4c152e72a4a3a8ad0698","size":{"x":32,"y":1,"z":32}},{"blockCount":200,"bytes":3372,"file":"chunks/y015-z160-x096.json","offset":{"x":96,"y":15,"z":160},"requirements":{"minecraft:stone_bricks":200},"sha256":"36520e56f1c5575aecc33790f78002411dff8b55bb11ccaa664d9dcdf204008f","size":{"x":32,"y":1,"z":32}},{"blockCount":149,"bytes":2853,"file":"chunks/y015-z160-x128.json","offset":{"x":128,"y":15,"z":160},"requirements":{"minecraft:stone_bricks":149},"sha256":"ff1793e2c445e8dfed11a97685978a109cb20738ec057e1f0ff7d2af7b2c2a9c","size":{"x":32,"y":1,"z":32}},{"blockCount":141,"bytes":4447,"file":"chunks/y015-z160-x160.json","offset":{"x":160,"y":15,"z":160},"requirements":{"minecraft:cobbled_deepslate":30,"minecraft:glass":4,"minecraft:stone_bricks":107},"sha256":"f4d12d61b6f00e139e878f4a7b37e7a699151426ff28cb9f6432a52bd3d98585","size":{"x":32,"y":1,"z":32}},{"blockCount":73,"bytes":2159,"file":"chunks/y015-z160-x192.json","offset":{"x":192,"y":15,"z":160},"requirements":{"minecraft:bricks":10,"minecraft:glass":24,"minecraft:stone_bricks":39},"sha256":"e530609f7677eec011619775b5f78cbc9e7b1cb4140b6b35d894c6722bf01efc","size":{"x":32,"y":1,"z":32}},{"blockCount":9,"bytes":934,"file":"chunks/y015-z160-x224.json","offset":{"x":224,"y":15,"z":160},"requirements":{"minecraft:bricks":5,"minecraft:stone_bricks":4},"sha256":"1b21d2cdf1c287e0167ac27248af3c905a305060abb61ac0808510eb72f521bd","size":{"x":32,"y":1,"z":32}},{"blockCount":238,"bytes":2653,"file":"chunks/y015-z160-x256.json","offset":{"x":256,"y":15,"z":160},"requirements":{"minecraft:oak_planks":164,"minecraft:sandstone":25,"minecraft:spruce_planks":45,"minecraft:stone_bricks":4},"sha256":"87f74d6effa327c7ce129f0fcea1a57c4cc0f6ef5dbed09b958edf6856820f48","size":{"x":32,"y":1,"z":32}},{"blockCount":42,"bytes":1842,"file":"chunks/y015-z160-x288.json","offset":{"x":288,"y":15,"z":160},"requirements":{"minecraft:cobbled_deepslate":7,"minecraft:oak_planks":1,"minecraft:sandstone":23,"minecraft:spruce_planks":10,"minecraft:stone_bricks":1},"sha256":"a96a2ff4d9de02334f91b0d771433a3a51419178a4cb8cde42ed3973f0c03b98","size":{"x":32,"y":1,"z":32}},{"blockCount":256,"bytes":2086,"file":"chunks/y015-z160-x320.json","offset":{"x":320,"y":15,"z":160},"requirements":{"minecraft:cobbled_deepslate":25,"minecraft:glass":14,"minecraft:spruce_planks":1,"minecraft:stone_bricks":216},"sha256":"4fa50e42791888b830e859909aed941b112f449e795620e597f07558d7777619","size":{"x":32,"y":1,"z":32}},{"blockCount":531,"bytes":2241,"file":"chunks/y015-z160-x352.json","offset":{"x":352,"y":15,"z":160},"requirements":{"minecraft:glass":22,"minecraft:stone_bricks":509},"sha256":"0e5b392ee5455cc76189b26d6e964e8251807c8167dec1a029f95bb02a4f7495","size":{"x":32,"y":1,"z":32}},{"blockCount":5,"bytes":642,"file":"chunks/y015-z192-x064.json","offset":{"x":64,"y":15,"z":192},"requirements":{"minecraft:stone_bricks":5},"sha256":"b11ba5659e9f23cca093207a2beae64f697f8e578a2fd1bbe87c56ecd3af4a30","size":{"x":32,"y":1,"z":32}},{"blockCount":52,"bytes":1161,"file":"chunks/y015-z192-x096.json","offset":{"x":96,"y":15,"z":192},"requirements":{"minecraft:stone_bricks":52},"sha256":"2c46495ddaae9f1b2058fea0864c0de1a42337e02ababa3ff57fc75d81615d49","size":{"x":32,"y":1,"z":32}},{"blockCount":21,"bytes":914,"file":"chunks/y015-z192-x128.json","offset":{"x":128,"y":15,"z":192},"requirements":{"minecraft:stone_bricks":21},"sha256":"92022c22aa267295fbb10ab2b5ec45248e3989ee02b040781ec93d4deaa21ae3","size":{"x":32,"y":1,"z":32}},{"blockCount":71,"bytes":1990,"file":"chunks/y015-z192-x160.json","offset":{"x":160,"y":15,"z":192},"requirements":{"minecraft:cobbled_deepslate":43,"minecraft:stone_bricks":28},"sha256":"5595a03a4162e5236f99ddbaffaab6c8d6076e15fb1dc47c39fded61ad8acd95","size":{"x":32,"y":1,"z":32}},{"blockCount":66,"bytes":1388,"file":"chunks/y015-z192-x192.json","offset":{"x":192,"y":15,"z":192},"requirements":{"minecraft:cobbled_deepslate":32,"minecraft:glass":4,"minecraft:stone_bricks":30},"sha256":"5999fdb40f3466b026be03763253a40ce3d1ec307c71df5c455c27b72119e01f","size":{"x":32,"y":1,"z":32}},{"blockCount":19,"bytes":651,"file":"chunks/y015-z192-x224.json","offset":{"x":224,"y":15,"z":192},"requirements":{"minecraft:cobbled_deepslate":19},"sha256":"2394e8121c3e0f8d02a000ed13c7db0b24871abe857fbdcf1dcda2d2daf07fe7","size":{"x":32,"y":1,"z":32}},{"blockCount":306,"bytes":2428,"file":"chunks/y015-z192-x256.json","offset":{"x":256,"y":15,"z":192},"requirements":{"minecraft:cobbled_deepslate":66,"minecraft:spruce_planks":206,"minecraft:stone_bricks":34},"sha256":"6ee40e3192c4d9b2e0ebbc04f55d9a17ea6606a338a9889094dba4efabcc553f","size":{"x":32,"y":1,"z":32}},{"blockCount":62,"bytes":1909,"file":"chunks/y015-z192-x288.json","offset":{"x":288,"y":15,"z":192},"requirements":{"minecraft:cobbled_deepslate":11,"minecraft:spruce_planks":38,"minecraft:stone_bricks":13},"sha256":"32becb58b7b1d2c3cb72d94a5fdd5b75291564b5bfdecb5a33f0bbdc1d609a33","size":{"x":32,"y":1,"z":32}},{"blockCount":384,"bytes":2478,"file":"chunks/y015-z192-x320.json","offset":{"x":320,"y":15,"z":192},"requirements":{"minecraft:glass":16,"minecraft:stone_bricks":368},"sha256":"b511ec91c978e9ae6a745ff0bb8f60a74b9e8973339787d4e7ce4ad0290cf873","size":{"x":32,"y":1,"z":32}},{"blockCount":896,"bytes":2462,"file":"chunks/y015-z192-x352.json","offset":{"x":352,"y":15,"z":192},"requirements":{"minecraft:glass":16,"minecraft:stone_bricks":880},"sha256":"7abd8d14c79a280e3da27361064b4bfcd66f6d000ab9038f7cd49774215ed44a","size":{"x":32,"y":1,"z":32}},{"blockCount":130,"bytes":1007,"file":"chunks/y015-z224-x256.json","offset":{"x":256,"y":15,"z":224},"requirements":{"minecraft:spruce_planks":130},"sha256":"b5ecfea94c9e44919d18da4cd2233991d0b7d7b9f4fab4c7a25ce5dbaad5828e","size":{"x":32,"y":1,"z":15}},{"blockCount":10,"bytes":976,"file":"chunks/y015-z224-x288.json","offset":{"x":288,"y":15,"z":224},"requirements":{"minecraft:spruce_planks":10},"sha256":"6850ff98be1ac7f66bd2b74b313f9e21476087560c960b7a9a93b1c527cc7550","size":{"x":32,"y":1,"z":15}},{"blockCount":32,"bytes":915,"file":"chunks/y015-z224-x320.json","offset":{"x":320,"y":15,"z":224},"requirements":{"minecraft:glass":5,"minecraft:stone_bricks":27},"sha256":"552d09c0594b7d3183a4f383357f3bebd634a85aa2031adb39e110a119b3936e","size":{"x":32,"y":1,"z":15}},{"blockCount":81,"bytes":1218,"file":"chunks/y015-z224-x352.json","offset":{"x":352,"y":15,"z":224},"requirements":{"minecraft:glass":13,"minecraft:stone_bricks":68},"sha256":"da7191e8b2675fa1fa056c3d1274773660b61562d387c4d016b490b1c3e4b327","size":{"x":32,"y":1,"z":15}},{"blockCount":25,"bytes":991,"file":"chunks/y016-z000-x320.json","offset":{"x":320,"y":16,"z":0},"requirements":{"minecraft:sandstone":25},"sha256":"6bba14d64e7c4636eab15fc6a05cb97b5b20a62c19d7df5bc0a96bb6488c275d","size":{"x":32,"y":1,"z":32}},{"blockCount":32,"bytes":641,"file":"chunks/y016-z000-x352.json","offset":{"x":352,"y":16,"z":0},"requirements":{"minecraft:sandstone":32},"sha256":"e2934536b52c7abe3c920011b0e5b3576043a0e47954171c8e2497e66f54f9bc","size":{"x":32,"y":1,"z":32}},{"blockCount":14,"bytes":990,"file":"chunks/y016-z000-x384.json","offset":{"x":384,"y":16,"z":0},"requirements":{"minecraft:sandstone":14},"sha256":"225e486b86e99463d65477843428c34129eb00d8fd86d40ec64165772418caa8","size":{"x":32,"y":1,"z":32}},{"blockCount":64,"bytes":2794,"file":"chunks/y016-z032-x320.json","offset":{"x":320,"y":16,"z":32},"requirements":{"minecraft:bricks":21,"minecraft:glass":8,"minecraft:sandstone":9,"minecraft:spruce_planks":26},"sha256":"70beaaae1e2c72019d88e6d409a822e8656e8bec83cf49a7d6999d24987280c7","size":{"x":32,"y":1,"z":32}},{"blockCount":74,"bytes":2930,"file":"chunks/y016-z032-x352.json","offset":{"x":352,"y":16,"z":32},"requirements":{"minecraft:bricks":6,"minecraft:cobbled_deepslate":4,"minecraft:glass":23,"minecraft:sandstone":1,"minecraft:spruce_planks":40},"sha256":"7d70895ef7bab1140fd812536522b86a7ff657985926f65e6526a3ad6a71a74d","size":{"x":32,"y":1,"z":32}},{"blockCount":168,"bytes":4249,"file":"chunks/y016-z032-x384.json","offset":{"x":384,"y":16,"z":32},"requirements":{"minecraft:bricks":17,"minecraft:sandstone":11,"minecraft:spruce_planks":16,"minecraft:stone_bricks":124},"sha256":"a58d030ae8c9bfa99ecd40b44a80f1a1db14445a381fa164421024490f105f91","size":{"x":32,"y":1,"z":32}},{"blockCount":6,"bytes":757,"file":"chunks/y016-z064-x032.json","offset":{"x":32,"y":16,"z":64},"requirements":{"minecraft:stone_bricks":6},"sha256":"4da064c95aa7feb301ad14c65049172a3bbdb2afd723cc5f634bf2294302140b","size":{"x":32,"y":1,"z":32}},{"blockCount":55,"bytes":1068,"file":"chunks/y016-z064-x064.json","offset":{"x":64,"y":16,"z":64},"requirements":{"minecraft:stone_bricks":55},"sha256":"2891e5f4fc61f6ddecf3f3e450b314f8241d1da9edc62371b5e470dfc6466e2f","size":{"x":32,"y":1,"z":32}},{"blockCount":166,"bytes":2776,"file":"chunks/y016-z064-x096.json","offset":{"x":96,"y":16,"z":64},"requirements":{"minecraft:stone_bricks":166},"sha256":"d24807f50c2445c6d32392ebc7fc4b054dd22bd73088d638ba3e25dfe844fc9f","size":{"x":32,"y":1,"z":32}},{"blockCount":62,"bytes":1453,"file":"chunks/y016-z064-x128.json","offset":{"x":128,"y":16,"z":64},"requirements":{"minecraft:stone_bricks":62},"sha256":"96ec3817b3ffacae4e7ccab7800a3cedfa7e0d2eef2cffcf010dc66efa948759","size":{"x":32,"y":1,"z":32}},{"blockCount":116,"bytes":2211,"file":"chunks/y016-z064-x320.json","offset":{"x":320,"y":16,"z":64},"requirements":{"minecraft:bricks":9,"minecraft:sandstone":34,"minecraft:spruce_planks":10,"minecraft:stone_bricks":63},"sha256":"f6322d0c65bea9b0bca5e49e3de17533002c680373b3117b3df40b54e2af96d7","size":{"x":32,"y":1,"z":32}},{"blockCount":98,"bytes":1904,"file":"chunks/y016-z064-x352.json","offset":{"x":352,"y":16,"z":64},"requirements":{"minecraft:bricks":6,"minecraft:cobbled_deepslate":4,"minecraft:sandstone":33,"minecraft:spruce_planks":17,"minecraft:stone_bricks":38},"sha256":"860a80945cd916ce608c8a28e90540778fc7da0d4563bffd7d0e1764063795eb","size":{"x":32,"y":1,"z":32}},{"blockCount":61,"bytes":1858,"file":"chunks/y016-z064-x384.json","offset":{"x":384,"y":16,"z":64},"requirements":{"minecraft:bricks":4,"minecraft:sandstone":25,"minecraft:spruce_planks":2,"minecraft:stone_bricks":30},"sha256":"e296ac4a81113e6b2e9a957e816b068a694873b1c6ce37d28adae3f01b05fd21","size":{"x":32,"y":1,"z":32}},{"blockCount":103,"bytes":2738,"file":"chunks/y016-z096-x032.json","offset":{"x":32,"y":16,"z":96},"requirements":{"minecraft:bricks":1,"minecraft:polished_diorite":1,"minecraft:stone_bricks":101},"sha256":"5375d23d33db9819e7e16f2b948c7de789a44dbd61477f03c3f67ec16de4298c","size":{"x":32,"y":1,"z":32}},{"blockCount":197,"bytes":3582,"file":"chunks/y016-z096-x064.json","offset":{"x":64,"y":16,"z":96},"requirements":{"minecraft:stone_bricks":197},"sha256":"1d9b70da0f97887e478ff3325ac75abd7ed7845708de025acbb8d60426cfca23","size":{"x":32,"y":1,"z":32}},{"blockCount":274,"bytes":3975,"file":"chunks/y016-z096-x096.json","offset":{"x":96,"y":16,"z":96},"requirements":{"minecraft:stone_bricks":274},"sha256":"35388ed2c7f25427f227dd179391b159008095c11fc7ec34e8819b06e0338a76","size":{"x":32,"y":1,"z":32}},{"blockCount":210,"bytes":3571,"file":"chunks/y016-z096-x128.json","offset":{"x":128,"y":16,"z":96},"requirements":{"minecraft:stone_bricks":210},"sha256":"6fd9a17bbe4063c1c84a9114fb5c31fd23e0c13f2112c1f47e34c1b8e23171b3","size":{"x":32,"y":1,"z":32}},{"blockCount":16,"bytes":1176,"file":"chunks/y016-z096-x192.json","offset":{"x":192,"y":16,"z":96},"requirements":{"minecraft:bricks":16},"sha256":"ab46eb1f30dcaf83d90f8578e95082b333bb63612da83b2df7b427c4aef6b2e6","size":{"x":32,"y":1,"z":32}},{"blockCount":8,"bytes":906,"file":"chunks/y016-z096-x224.json","offset":{"x":224,"y":16,"z":96},"requirements":{"minecraft:bricks":8},"sha256":"b806b6cc1683b8a75ca0b971f2c9ca2cebb96c69f2a19664a43a3460d732a0cd","size":{"x":32,"y":1,"z":32}},{"blockCount":24,"bytes":837,"file":"chunks/y016-z096-x256.json","offset":{"x":256,"y":16,"z":96},"requirements":{"minecraft:cobbled_deepslate":3,"minecraft:oak_planks":10,"minecraft:spruce_planks":11},"sha256":"d466bdc6705a85a803bebd7eab91977a76e8c2adc14a7d01c2fe400a08bf9b86","size":{"x":32,"y":1,"z":32}},{"blockCount":81,"bytes":1402,"file":"chunks/y016-z096-x288.json","offset":{"x":288,"y":16,"z":96},"requirements":{"minecraft:cobbled_deepslate":6,"minecraft:oak_planks":23,"minecraft:spruce_planks":37,"minecraft:stone_bricks":15},"sha256":"1d5f37717e381e107acad033ff31dc2056aaa7e0f4d3c81acba1dca65da711ea","size":{"x":32,"y":1,"z":32}},{"blockCount":215,"bytes":2005,"file":"chunks/y016-z096-x320.json","offset":{"x":320,"y":16,"z":96},"requirements":{"minecraft:cobbled_deepslate":6,"minecraft:spruce_planks":34,"minecraft:stone_bricks":175},"sha256":"6ce8dd45b4f8207fbd8c6baf37ab3c5b7a3a5569f71e75e4409fe753239756ca","size":{"x":32,"y":1,"z":32}},{"blockCount":80,"bytes":1208,"file":"chunks/y016-z096-x352.json","offset":{"x":352,"y":16,"z":96},"requirements":{"minecraft:stone_bricks":80},"sha256":"f2d1bbd2572f18c854aba999e1df1546274c277cc8db1356b053965fe0a48ba2","size":{"x":32,"y":1,"z":32}},{"blockCount":83,"bytes":1901,"file":"chunks/y016-z128-x032.json","offset":{"x":32,"y":16,"z":128},"requirements":{"minecraft:stone_bricks":83},"sha256":"f4f189e2f8a194b1a827aa0b2839c6e95205836968ade36aa492b9e3b492dfc2","size":{"x":32,"y":1,"z":32}},{"blockCount":82,"bytes":2100,"file":"chunks/y016-z128-x064.json","offset":{"x":64,"y":16,"z":128},"requirements":{"minecraft:stone_bricks":82},"sha256":"574039ca1919580d126ffdfa2eab6b220eb419744523b8c71a9e7c6b9fe5f91c","size":{"x":32,"y":1,"z":32}},{"blockCount":102,"bytes":2422,"file":"chunks/y016-z128-x096.json","offset":{"x":96,"y":16,"z":128},"requirements":{"minecraft:stone_bricks":102},"sha256":"ed7bca120363b4523c813a3a69347233b8e389b6c072c556364c9f33a37c5737","size":{"x":32,"y":1,"z":32}},{"blockCount":251,"bytes":2692,"file":"chunks/y016-z128-x128.json","offset":{"x":128,"y":16,"z":128},"requirements":{"minecraft:stone_bricks":251},"sha256":"84d4a47128088c14089b493f117a2568976a17852634d38e04e3372ca8b5d804","size":{"x":32,"y":1,"z":32}},{"blockCount":281,"bytes":3403,"file":"chunks/y016-z128-x160.json","offset":{"x":160,"y":16,"z":128},"requirements":{"minecraft:cobbled_deepslate":21,"minecraft:stone_bricks":260},"sha256":"61a9e53aa777c55fbbaa5d8b4d8188953dea51154a792b6a89b70868d22be60e","size":{"x":32,"y":1,"z":32}},{"blockCount":102,"bytes":2477,"file":"chunks/y016-z128-x192.json","offset":{"x":192,"y":16,"z":128},"requirements":{"minecraft:bricks":15,"minecraft:cobbled_deepslate":10,"minecraft:stone_bricks":77},"sha256":"bba169026c7846a5b26d27f3c164ff924c6e665756f0ff5fba13017c0ad73de6","size":{"x":32,"y":1,"z":32}},{"blockCount":74,"bytes":2791,"file":"chunks/y016-z128-x224.json","offset":{"x":224,"y":16,"z":128},"requirements":{"minecraft:bricks":23,"minecraft:cobbled_deepslate":8,"minecraft:polished_diorite":4,"minecraft:stone_bricks":39},"sha256":"2db52a90b6527fe5a967e14d1d40674cb02f8f6463da3cbcd4d3022e58466dd1","size":{"x":32,"y":1,"z":32}},{"blockCount":120,"bytes":3810,"file":"chunks/y016-z128-x256.json","offset":{"x":256,"y":16,"z":128},"requirements":{"minecraft:cobbled_deepslate":1,"minecraft:glass":4,"minecraft:oak_planks":30,"minecraft:polished_diorite":12,"minecraft:spruce_planks":35,"minecraft:stone_bricks":38},"sha256":"1e86e8fb1a9df8e109be06f9314db6854d23725b52c6de996a3de3732459293f","size":{"x":32,"y":1,"z":32}},{"blockCount":185,"bytes":4864,"file":"chunks/y016-z128-x288.json","offset":{"x":288,"y":16,"z":128},"requirements":{"minecraft:cobbled_deepslate":1,"minecraft:glass":7,"minecraft:oak_planks":48,"minecraft:spruce_planks":90,"minecraft:stone_bricks":39},"sha256":"632606c534599566522e0af43eb69182a5e1f4dc77c833d3200878ef428d1003","size":{"x":32,"y":1,"z":32}},{"blockCount":94,"bytes":3404,"file":"chunks/y016-z128-x320.json","offset":{"x":320,"y":16,"z":128},"requirements":{"minecraft:spruce_planks":32,"minecraft:stone_bricks":62},"sha256":"672f60eb21bdb8045d71080661ced4ef418ef50f3c2677ab0f7261cd9a751709","size":{"x":32,"y":1,"z":32}},{"blockCount":16,"bytes":761,"file":"chunks/y016-z128-x384.json","offset":{"x":384,"y":16,"z":128},"requirements":{"minecraft:stone_bricks":16},"sha256":"b2a5a6370752a4db334f64af4b48177c05f105277ac3fabb8e22c53139336544","size":{"x":32,"y":1,"z":32}},{"blockCount":66,"bytes":2280,"file":"chunks/y016-z160-x032.json","offset":{"x":32,"y":16,"z":160},"requirements":{"minecraft:bricks":1,"minecraft:polished_diorite":1,"minecraft:stone_bricks":64},"sha256":"2d63ae176a1906f9d1f56a5c0e2ac63479e45f010798fc5af789f66e7bd72671","size":{"x":32,"y":1,"z":32}},{"blockCount":188,"bytes":3112,"file":"chunks/y016-z160-x064.json","offset":{"x":64,"y":16,"z":160},"requirements":{"minecraft:stone_bricks":188},"sha256":"d5ad5073ec253c6d2b34185061a37996dc9d88f51a1299f5ab6baa1ada4bc374","size":{"x":32,"y":1,"z":32}},{"blockCount":340,"bytes":4899,"file":"chunks/y016-z160-x096.json","offset":{"x":96,"y":16,"z":160},"requirements":{"minecraft:stone_bricks":340},"sha256":"69f7226ff95497e077e43d7dc9997e772441f93a0d9d11d9ac32b14ae7bc7553","size":{"x":32,"y":1,"z":32}},{"blockCount":186,"bytes":3230,"file":"chunks/y016-z160-x128.json","offset":{"x":128,"y":16,"z":160},"requirements":{"minecraft:stone_bricks":186},"sha256":"7684d0577d316061c9402ef56cfc5619e0075c1287563fd430a95517b0c5dbac","size":{"x":32,"y":1,"z":32}},{"blockCount":102,"bytes":3394,"file":"chunks/y016-z160-x160.json","offset":{"x":160,"y":16,"z":160},"requirements":{"minecraft:cobbled_deepslate":30,"minecraft:glass":1,"minecraft:stone_bricks":71},"sha256":"72f4dae17689e643e115be8cf1772d9199d71755322640265d6ac36b080071b2","size":{"x":32,"y":1,"z":32}},{"blockCount":82,"bytes":1951,"file":"chunks/y016-z160-x192.json","offset":{"x":192,"y":16,"z":160},"requirements":{"minecraft:bricks":10,"minecraft:glass":26,"minecraft:stone_bricks":46},"sha256":"ac20f51682921ef1e97b28cb174942f62855c51a8107daf88c369518d97e89d7","size":{"x":32,"y":1,"z":32}},{"blockCount":99,"bytes":1778,"file":"chunks/y016-z160-x224.json","offset":{"x":224,"y":16,"z":160},"requirements":{"minecraft:bricks":7,"minecraft:stone_bricks":92},"sha256":"7274a860bf27c68c7c9f8ac8e7c8449aa4ee58fc54f8b25fcccceb683c559897","size":{"x":32,"y":1,"z":32}},{"blockCount":39,"bytes":1723,"file":"chunks/y016-z160-x256.json","offset":{"x":256,"y":16,"z":160},"requirements":{"minecraft:oak_planks":11,"minecraft:sandstone":25,"minecraft:stone_bricks":3},"sha256":"732ef61ff291da4112999cc81459891c70b70373467bec33e41043758be0302f","size":{"x":32,"y":1,"z":32}},{"blockCount":39,"bytes":1711,"file":"chunks/y016-z160-x288.json","offset":{"x":288,"y":16,"z":160},"requirements":{"minecraft:oak_planks":1,"minecraft:sandstone":23,"minecraft:spruce_planks":7,"minecraft:stone_bricks":8},"sha256":"f7291a4a43388472b64cd800bfde8ca29515a83f9d97c450063ccaa6eb4758bb","size":{"x":32,"y":1,"z":32}},{"blockCount":49,"bytes":903,"file":"chunks/y016-z160-x320.json","offset":{"x":320,"y":16,"z":160},"requirements":{"minecraft:spruce_planks":24,"minecraft:stone_bricks":25},"sha256":"aadfe07cd91eb8e5b094ec629a23a9861f65f78067c69061a6ac4fc956848ecc","size":{"x":32,"y":1,"z":32}},{"blockCount":8,"bytes":760,"file":"chunks/y016-z160-x352.json","offset":{"x":352,"y":16,"z":160},"requirements":{"minecraft:stone_bricks":8},"sha256":"4c454a7118fec1abedb9be4e13a11ac5ebe888018ac59ad614ced79cfce6689d","size":{"x":32,"y":1,"z":32}},{"blockCount":5,"bytes":642,"file":"chunks/y016-z192-x064.json","offset":{"x":64,"y":16,"z":192},"requirements":{"minecraft:stone_bricks":5},"sha256":"f23872f3312755a56fce62a8322fab430193e395c8066f8a5b26cbd1214ea834","size":{"x":32,"y":1,"z":32}},{"blockCount":75,"bytes":1465,"file":"chunks/y016-z192-x096.json","offset":{"x":96,"y":16,"z":192},"requirements":{"minecraft:stone_bricks":75},"sha256":"7d09c9869fb9679e6141c6fd8e756bc564b7375018f9bf31f8ae7a0f3cfa2b06","size":{"x":32,"y":1,"z":32}},{"blockCount":29,"bytes":990,"file":"chunks/y016-z192-x128.json","offset":{"x":128,"y":16,"z":192},"requirements":{"minecraft:stone_bricks":29},"sha256":"ce02893357bbbe7a306a6ede14b580410e14a1ce936c23e33614f85f04999ddb","size":{"x":32,"y":1,"z":32}},{"blockCount":70,"bytes":1762,"file":"chunks/y016-z192-x160.json","offset":{"x":160,"y":16,"z":192},"requirements":{"minecraft:cobbled_deepslate":43,"minecraft:stone_bricks":27},"sha256":"69fe0b73f3a8abee317783acc13ac7a19fec396eb0e1dc0abbe04159bb1ffb4a","size":{"x":32,"y":1,"z":32}},{"blockCount":68,"bytes":1427,"file":"chunks/y016-z192-x192.json","offset":{"x":192,"y":16,"z":192},"requirements":{"minecraft:cobbled_deepslate":32,"minecraft:glass":4,"minecraft:stone_bricks":32},"sha256":"aff0b5e8f5e7a7672289ac689ee89d70fe0b835cc2fa5d8501f482e57e74fd30","size":{"x":32,"y":1,"z":32}},{"blockCount":95,"bytes":1275,"file":"chunks/y016-z192-x224.json","offset":{"x":224,"y":16,"z":192},"requirements":{"minecraft:cobbled_deepslate":19,"minecraft:stone_bricks":76},"sha256":"6ac15df5d89843dcf37cd2b2ae9c4138d0ef3a7b697b53824e790d186dfca5b4","size":{"x":32,"y":1,"z":32}},{"blockCount":59,"bytes":1781,"file":"chunks/y016-z192-x256.json","offset":{"x":256,"y":16,"z":192},"requirements":{"minecraft:cobbled_deepslate":36,"minecraft:stone_bricks":23},"sha256":"4f69d476618387a91a5eed5ca78e76ece30594a1ee271a2b849ea1674e85b465","size":{"x":32,"y":1,"z":32}},{"blockCount":8,"bytes":910,"file":"chunks/y016-z192-x288.json","offset":{"x":288,"y":16,"z":192},"requirements":{"minecraft:cobbled_deepslate":6,"minecraft:stone_bricks":2},"sha256":"668d9926f49c998c7610a3d2a51f98e87af78344b5e52b1075926c483b26e8dc","size":{"x":32,"y":1,"z":32}},{"blockCount":1,"bytes":644,"file":"chunks/y016-z192-x352.json","offset":{"x":352,"y":16,"z":192},"requirements":{"minecraft:stone_bricks":1},"sha256":"a41486df5f0e84dee9ecbe13a4de514e32eff74d58d8a48bf3847f83223d4aca","size":{"x":32,"y":1,"z":32}},{"blockCount":40,"bytes":992,"file":"chunks/y017-z000-x320.json","offset":{"x":320,"y":17,"z":0},"requirements":{"minecraft:sandstone":40},"sha256":"29e070eaa03a144ae9129f935626bf56da1d149499f7d327576ecbb75fb97579","size":{"x":32,"y":1,"z":32}},{"blockCount":64,"bytes":641,"file":"chunks/y017-z000-x352.json","offset":{"x":352,"y":17,"z":0},"requirements":{"minecraft:sandstone":64},"sha256":"46b984d3ca0a21890eed3a51d79d8e71c101b66dc9f439c1eb9e8fc7c626a4f8","size":{"x":32,"y":1,"z":32}},{"blockCount":16,"bytes":990,"file":"chunks/y017-z000-x384.json","offset":{"x":384,"y":17,"z":0},"requirements":{"minecraft:sandstone":16},"sha256":"03864f7e2640eb57999ac0078aa2b92625dccc52abe6b6d5dad867581f2571f0","size":{"x":32,"y":1,"z":32}},{"blockCount":58,"bytes":2545,"file":"chunks/y017-z032-x320.json","offset":{"x":320,"y":17,"z":32},"requirements":{"minecraft:bricks":21,"minecraft:glass":8,"minecraft:sandstone":11,"minecraft:spruce_planks":18},"sha256":"fcc6136f276e08b6ea38002b556ff550f17a3a32ac54c85e5a5adf5eac77e7aa","size":{"x":32,"y":1,"z":32}},{"blockCount":65,"bytes":2572,"file":"chunks/y017-z032-x352.json","offset":{"x":352,"y":17,"z":32},"requirements":{"minecraft:bricks":6,"minecraft:cobbled_deepslate":9,"minecraft:glass":18,"minecraft:sandstone":3,"minecraft:spruce_planks":29},"sha256":"cf6bd4376e885b80e559c10eb3d2c82fec253869e061a5a09c0d2ec840ada127","size":{"x":32,"y":1,"z":32}},{"blockCount":168,"bytes":4325,"file":"chunks/y017-z032-x384.json","offset":{"x":384,"y":17,"z":32},"requirements":{"minecraft:bricks":19,"minecraft:sandstone":11,"minecraft:spruce_planks":15,"minecraft:stone_bricks":123},"sha256":"aa27b593d486e865c263d26b9543e1345a61b571c24c02fb676e7719019bfc52","size":{"x":32,"y":1,"z":32}},{"blockCount":6,"bytes":757,"file":"chunks/y017-z064-x032.json","offset":{"x":32,"y":17,"z":64},"requirements":{"minecraft:stone_bricks":6},"sha256":"8db32ecbb49db411d45fb7826344b5623e8c54174355487fc8d78826f57398a7","size":{"x":32,"y":1,"z":32}},{"blockCount":87,"bytes":1049,"file":"chunks/y017-z064-x064.json","offset":{"x":64,"y":17,"z":64},"requirements":{"minecraft:stone_bricks":87},"sha256":"8e371724023e1ee6e5fe7333f91f0dce426c65112c9560e52e0e831b626414cc","size":{"x":32,"y":1,"z":32}},{"blockCount":330,"bytes":1053,"file":"chunks/y017-z064-x096.json","offset":{"x":96,"y":17,"z":64},"requirements":{"minecraft:stone_bricks":330},"sha256":"4521a9174a73dde6735135838699d5b64d729c4f991b9eef6f80e731520474f9","size":{"x":32,"y":1,"z":32}},{"blockCount":162,"bytes":1307,"file":"chunks/y017-z064-x128.json","offset":{"x":128,"y":17,"z":64},"requirements":{"minecraft:stone_bricks":162},"sha256":"ce70a3bb2d94251adc82c364c3e6b8383a16948a047e126fb3ddd6d227646004","size":{"x":32,"y":1,"z":32}},{"blockCount":65,"bytes":1798,"file":"chunks/y017-z064-x320.json","offset":{"x":320,"y":17,"z":64},"requirements":{"minecraft:bricks":9,"minecraft:sandstone":51,"minecraft:spruce_planks":5},"sha256":"d747467e872416e61a3d5ed537b410a15caafd7fed841c0efa84b69a9ae035cb","size":{"x":32,"y":1,"z":32}},{"blockCount":90,"bytes":1398,"file":"chunks/y017-z064-x352.json","offset":{"x":352,"y":17,"z":64},"requirements":{"minecraft:bricks":6,"minecraft:cobbled_deepslate":9,"minecraft:sandstone":67,"minecraft:spruce_planks":8},"sha256":"4d11c4d6327dd3bbad938b1ba01794c62dd2448f6114d7c560b607217e0f3a56","size":{"x":32,"y":1,"z":32}},{"blockCount":62,"bytes":1820,"file":"chunks/y017-z064-x384.json","offset":{"x":384,"y":17,"z":64},"requirements":{"minecraft:bricks":4,"minecraft:sandstone":27,"minecraft:spruce_planks":1,"minecraft:stone_bricks":30},"sha256":"6baaf4e5af89791a6fc9be7e5441373dbc43087d86a1f8222479055140eb4ebe","size":{"x":32,"y":1,"z":32}},{"blockCount":107,"bytes":2755,"file":"chunks/y017-z096-x032.json","offset":{"x":32,"y":17,"z":96},"requirements":{"minecraft:polished_diorite":3,"minecraft:stone_bricks":104},"sha256":"7afa8cb7bd0b59e7fdcb8155f4652e0b8ca9a99ea7eaf1220ec7db1827affb44","size":{"x":32,"y":1,"z":32}},{"blockCount":321,"bytes":3424,"file":"chunks/y017-z096-x064.json","offset":{"x":64,"y":17,"z":96},"requirements":{"minecraft:stone_bricks":321},"sha256":"6cf813446f8dfc16b6625d55d611bdb400ff6d6a1a60f413faf1148c92b2209b","size":{"x":32,"y":1,"z":32}},{"blockCount":482,"bytes":2942,"file":"chunks/y017-z096-x096.json","offset":{"x":96,"y":17,"z":96},"requirements":{"minecraft:stone_bricks":482},"sha256":"43bda6268891fd5629f49824267c6cfd0c98880f3a18f8fb9480636bca9d0ad1","size":{"x":32,"y":1,"z":32}},{"blockCount":277,"bytes":3176,"file":"chunks/y017-z096-x128.json","offset":{"x":128,"y":17,"z":96},"requirements":{"minecraft:stone_bricks":277},"sha256":"5bb14e0a6538009bf019fbc8eaa2dc44adc56ef451824d13bbd83138883ab80b","size":{"x":32,"y":1,"z":32}},{"blockCount":20,"bytes":1217,"file":"chunks/y017-z096-x192.json","offset":{"x":192,"y":17,"z":96},"requirements":{"minecraft:bricks":20},"sha256":"e2a1e27aca2139fae2b87799260b0a7cde2e9a8afc3ef766ba3ec379c1a9d348","size":{"x":32,"y":1,"z":32}},{"blockCount":32,"bytes":1439,"file":"chunks/y017-z096-x224.json","offset":{"x":224,"y":17,"z":96},"requirements":{"minecraft:bricks":18,"minecraft:polished_diorite":14},"sha256":"0c3d48e94816ac1e168e26ed566d5ddf8e9dfdc1aa02847482d186a4c98ce74d","size":{"x":32,"y":1,"z":32}},{"blockCount":51,"bytes":1167,"file":"chunks/y017-z096-x256.json","offset":{"x":256,"y":17,"z":96},"requirements":{"minecraft:cobbled_deepslate":13,"minecraft:polished_diorite":27,"minecraft:spruce_planks":11},"sha256":"685b325f65b5d6bdd313233538e94a90c71c3d441175b80fa90a276364db7c2a","size":{"x":32,"y":1,"z":32}},{"blockCount":82,"bytes":1395,"file":"chunks/y017-z096-x288.json","offset":{"x":288,"y":17,"z":96},"requirements":{"minecraft:cobbled_deepslate":44,"minecraft:spruce_planks":37,"minecraft:stone_bricks":1},"sha256":"45aa5cdfdce185d4d184b4ace41e364db8d3a89a3cef5858c2118fb5e4fdc3ac","size":{"x":32,"y":1,"z":32}},{"blockCount":72,"bytes":1400,"file":"chunks/y017-z096-x320.json","offset":{"x":320,"y":17,"z":96},"requirements":{"minecraft:cobbled_deepslate":39,"minecraft:spruce_planks":32,"minecraft:stone_bricks":1},"sha256":"ab7487cfff92fb8dd66e5b2cdd19f813d24511ab99f47cc2e679fcc62fc1c529","size":{"x":32,"y":1,"z":32}},{"blockCount":98,"bytes":2205,"file":"chunks/y017-z128-x032.json","offset":{"x":32,"y":17,"z":128},"requirements":{"minecraft:stone_bricks":98},"sha256":"87e6eece247539a4e8eed417c3b1f9b797ad91ab210920b0c422c9fa3cf89b68","size":{"x":32,"y":1,"z":32}},{"blockCount":138,"bytes":1757,"file":"chunks/y017-z128-x064.json","offset":{"x":64,"y":17,"z":128},"requirements":{"minecraft:stone_bricks":138},"sha256":"cdb41520cdcd7464fa425a63a83d994ec2d1fdaa8f5cce9997bdf3d162580493","size":{"x":32,"y":1,"z":32}},{"blockCount":287,"bytes":3312,"file":"chunks/y017-z128-x096.json","offset":{"x":96,"y":17,"z":128},"requirements":{"minecraft:stone_bricks":287},"sha256":"8992249e29bbb67f1561e2a49e4affb6da2ce7d93c6a29d309c752a05e5b5930","size":{"x":32,"y":1,"z":32}},{"blockCount":281,"bytes":3005,"file":"chunks/y017-z128-x128.json","offset":{"x":128,"y":17,"z":128},"requirements":{"minecraft:glass":2,"minecraft:polished_diorite":6,"minecraft:stone_bricks":273},"sha256":"6703834dd8dd12402cd647cd393e9988afb1e556cc6628020d5215072c5592f4","size":{"x":32,"y":1,"z":32}},{"blockCount":312,"bytes":2571,"file":"chunks/y017-z128-x160.json","offset":{"x":160,"y":17,"z":128},"requirements":{"minecraft:cobbled_deepslate":16,"minecraft:glass":1,"minecraft:stone_bricks":295},"sha256":"617ee2c8add55866a4f8582fec294ed51dacc670fbcb17b23d38179edfd55e69","size":{"x":32,"y":1,"z":32}},{"blockCount":95,"bytes":2246,"file":"chunks/y017-z128-x192.json","offset":{"x":192,"y":17,"z":128},"requirements":{"minecraft:bricks":13,"minecraft:cobbled_deepslate":10,"minecraft:stone_bricks":72},"sha256":"c4a611d8fff820d5cb70b8ecb8c7c70d57420d6914f7ee150dcb49ee12d275af","size":{"x":32,"y":1,"z":32}},{"blockCount":156,"bytes":3971,"file":"chunks/y017-z128-x224.json","offset":{"x":224,"y":17,"z":128},"requirements":{"minecraft:bricks":13,"minecraft:cobbled_deepslate":6,"minecraft:polished_diorite":79,"minecraft:stone_bricks":58},"sha256":"5788551882b1af0d359909d7e8105a2a43a2ea4566f78296345e9681a17afe07","size":{"x":32,"y":1,"z":32}},{"blockCount":235,"bytes":5811,"file":"chunks/y017-z128-x256.json","offset":{"x":256,"y":17,"z":128},"requirements":{"minecraft:cobbled_deepslate":33,"minecraft:glass":4,"minecraft:polished_diorite":73,"minecraft:spruce_planks":35,"minecraft:stone_bricks":90},"sha256":"83d7deab691fb4862cafea132a408c24f661e04afb6fbfbdc36ce5e2b0bd8278","size":{"x":32,"y":1,"z":32}},{"blockCount":203,"bytes":5502,"file":"chunks/y017-z128-x288.json","offset":{"x":288,"y":17,"z":128},"requirements":{"minecraft:cobbled_deepslate":86,"minecraft:glass":1,"minecraft:spruce_planks":90,"minecraft:stone_bricks":26},"sha256":"7b2f2ce27db5ad9308813148d13bdfbd65cc8d1130683e6841ed5afb5e5fa9a3","size":{"x":32,"y":1,"z":32}},{"blockCount":153,"bytes":4796,"file":"chunks/y017-z128-x320.json","offset":{"x":320,"y":17,"z":128},"requirements":{"minecraft:cobbled_deepslate":32,"minecraft:polished_diorite":3,"minecraft:spruce_planks":32,"minecraft:stone_bricks":86},"sha256":"eb2921dc62666978169cec16188219c8d8eb8ecab865468332b6a63cd6535416","size":{"x":32,"y":1,"z":32}},{"blockCount":12,"bytes":837,"file":"chunks/y017-z128-x384.json","offset":{"x":384,"y":17,"z":128},"requirements":{"minecraft:stone_bricks":12},"sha256":"e65f7df542533cf53f1854caac297e143804955d1c844515571054697c8b7f26","size":{"x":32,"y":1,"z":32}},{"blockCount":67,"bytes":2221,"file":"chunks/y017-z160-x032.json","offset":{"x":32,"y":17,"z":160},"requirements":{"minecraft:polished_diorite":3,"minecraft:stone_bricks":64},"sha256":"0ecc7eb09b601a0453ecb9a7ad7eaaf22cb6d373d54241a6a54635ce6485e44f","size":{"x":32,"y":1,"z":32}},{"blockCount":345,"bytes":3098,"file":"chunks/y017-z160-x064.json","offset":{"x":64,"y":17,"z":160},"requirements":{"minecraft:polished_diorite":2,"minecraft:stone_bricks":343},"sha256":"e60437808a404edde9b7a21be4fa5a90f09ff3bfec38b4fcfe95b5ca903c59cb","size":{"x":32,"y":1,"z":32}},{"blockCount":650,"bytes":2596,"file":"chunks/y017-z160-x096.json","offset":{"x":96,"y":17,"z":160},"requirements":{"minecraft:stone_bricks":650},"sha256":"fb5b51bd23a7faa8cd28c0458c7a77c52954874e1257369ce81b66969328479f","size":{"x":32,"y":1,"z":32}},{"blockCount":343,"bytes":3012,"file":"chunks/y017-z160-x128.json","offset":{"x":128,"y":17,"z":160},"requirements":{"minecraft:stone_bricks":343},"sha256":"46b6f9f9b2e5be48f203781c03114aad628b5db4d843a5254ab71cd80933dff8","size":{"x":32,"y":1,"z":32}},{"blockCount":58,"bytes":2379,"file":"chunks/y017-z160-x160.json","offset":{"x":160,"y":17,"z":160},"requirements":{"minecraft:cobbled_deepslate":26,"minecraft:glass":2,"minecraft:stone_bricks":30},"sha256":"b7bb5c70907a3cf1bca101f015d7af60cf6f4c21e716eb751f416305ef05f172","size":{"x":32,"y":1,"z":32}},{"blockCount":89,"bytes":1740,"file":"chunks/y017-z160-x192.json","offset":{"x":192,"y":17,"z":160},"requirements":{"minecraft:bricks":9,"minecraft:glass":18,"minecraft:stone_bricks":62},"sha256":"782260333a56fc9194a383ddc97c07d5688a3e51fa91ceb8dc238d039f974ee1","size":{"x":32,"y":1,"z":32}},{"blockCount":81,"bytes":1514,"file":"chunks/y017-z160-x224.json","offset":{"x":224,"y":17,"z":160},"requirements":{"minecraft:bricks":2,"minecraft:stone_bricks":79},"sha256":"91921dc99a5f12e6089dbd0fba9cb0d232adffe28fb17a4edeb550d279fdbb8a","size":{"x":32,"y":1,"z":32}},{"blockCount":39,"bytes":1741,"file":"chunks/y017-z160-x256.json","offset":{"x":256,"y":17,"z":160},"requirements":{"minecraft:oak_planks":35,"minecraft:sandstone":1,"minecraft:stone_bricks":3},"sha256":"f0fbbb4f2bf25a319160af5a90013135f23e16b12b1acb4096ec29131b7879c8","size":{"x":32,"y":1,"z":32}},{"blockCount":39,"bytes":1762,"file":"chunks/y017-z160-x288.json","offset":{"x":288,"y":17,"z":160},"requirements":{"minecraft:cobbled_deepslate":7,"minecraft:oak_planks":23,"minecraft:sandstone":1,"minecraft:spruce_planks":7,"minecraft:stone_bricks":1},"sha256":"d34c6187ed29a4f54485bd17d9caf4ab4f79ef83c51e7418b8c3fa262ee565a3","size":{"x":32,"y":1,"z":32}}],"schema":1}
