{"entries":[{"blockCount":52,"bytes":794,"file":"chunks/y017-z160-x320.json","offset":{"x":320,"y":17,"z":160},"requirements":{"minecraft:cobbled_deepslate":25,"minecraft:spruce_planks":27},"sha256":"e1e08a2d9f88aeb0ebdbf196f8627632f6e6c36b290889fe9d6060db02a0f5f3","size":{"x":32,"y":1,"z":32}},{"blockCount":4,"bytes":760,"file":"chunks/y017-z160-x352.json","offset":{"x":352,"y":17,"z":160},"requirements":{"minecraft:stone_bricks":4},"sha256":"bd30b61d5cfeadbf9aeb5ae6059ce5fb85b821cb7cc5d2cfb0bac234e94af98c","size":{"x":32,"y":1,"z":32}},{"blockCount":9,"bytes":681,"file":"chunks/y017-z192-x064.json","offset":{"x":64,"y":17,"z":192},"requirements":{"minecraft:stone_bricks":9},"sha256":"a4321783aa338c449aa231a15e9f0e00349ea65cbdb6fc1a2736defb082c8975","size":{"x":32,"y":1,"z":32}},{"blockCount":123,"bytes":819,"file":"chunks/y017-z192-x096.json","offset":{"x":96,"y":17,"z":192},"requirements":{"minecraft:stone_bricks":123},"sha256":"897fa455f962ceaae5e73e18c027924cac13f0fdf4112c02dffee9b0247a696f","size":{"x":32,"y":1,"z":32}},{"blockCount":40,"bytes":780,"file":"chunks/y017-z192-x128.json","offset":{"x":128,"y":17,"z":192},"requirements":{"minecraft:stone_bricks":40},"sha256":"7f16708e1f3b3e328a5090ad6eb88aae0b341f33f2fe60124aebddcb121a1949","size":{"x":32,"y":1,"z":32}},{"blockCount":60,"bytes":1648,"file":"chunks/y017-z192-x160.json","offset":{"x":160,"y":17,"z":192},"requirements":{"minecraft:cobbled_deepslate":43,"minecraft:stone_bricks":17},"sha256":"72f1baa7ee36ab778b897c5a81e349edea6a19a19463144541cdb1c8887f88f7","size":{"x":32,"y":1,"z":32}},{"blockCount":71,"bytes":1254,"file":"chunks/y017-z192-x192.json","offset":{"x":192,"y":17,"z":192},"requirements":{"minecraft:cobbled_deepslate":32,"minecraft:stone_bricks":39},"sha256":"5107f963c7e8e0d491e4223017e20eecef62d14fd199645513d7e41d4d1211e1","size":{"x":32,"y":1,"z":32}},{"blockCount":101,"bytes":1428,"file":"chunks/y017-z192-x224.json","offset":{"x":224,"y":17,"z":192},"requirements":{"minecraft:cobbled_deepslate":19,"minecraft:stone_bricks":82},"sha256":"3925a13fd7ffd47a5dd32420c7392d30740a50960e50932fe81a7340ae1134d6","size":{"x":32,"y":1,"z":32}},{"blockCount":46,"bytes":1703,"file":"chunks/y017-z192-x256.json","offset":{"x":256,"y":17,"z":192},"requirements":{"minecraft:cobbled_deepslate":22,"minecraft:stone_bricks":24},"sha256":"c827aa44584e32d70c218cbf6b5fa99ce918b26ac5fcd85eff20a5231b3f2ef2","size":{"x":32,"y":1,"z":32}},{"blockCount":8,"bytes":910,"file":"chunks/y017-z192-x288.json","offset":{"x":288,"y":17,"z":192},"requirements":{"minecraft:cobbled_deepslate":3,"minecraft:stone_bricks":5},"sha256":"fb56385020558006ee5ad94f6caff03660f44814d81c13c8a474d6f78985e1dd","size":{"x":32,"y":1,"z":32}},{"blockCount":40,"bytes":992,"file":"chunks/y018-z000-x320.json","offset":{"x":320,"y":18,"z":0},"requirements":{"minecraft:sandstone":40},"sha256":"703dfa1867dc9e62d92322332dda5055e5220cc1eca07df89b5c91b6140cbad2","size":{"x":32,"y":1,"z":32}},{"blockCount":64,"bytes":641,"file":"chunks/y018-z000-x352.json","offset":{"x":352,"y":18,"z":0},"requirements":{"minecraft:sandstone":64},"sha256":"e199ee4b2b95523ae8335f8de513e21f85085b424f5cf5f492f36501ed30f03d","size":{"x":32,"y":1,"z":32}},{"blockCount":18,"bytes":1054,"file":"chunks/y018-z000-x384.json","offset":{"x":384,"y":18,"z":0},"requirements":{"minecraft:sandstone":16,"minecraft:stone_bricks":2},"sha256":"4c2f712eb4176b25e1cb940b955e54b7f684bd4d1e5347cc13cec39756d43461","size":{"x":32,"y":1,"z":32}},{"blockCount":62,"bytes":2678,"file":"chunks/y018-z032-x320.json","offset":{"x":320,"y":18,"z":32},"requirements":{"minecraft:bricks":21,"minecraft:glass":8,"minecraft:sandstone":11,"minecraft:spruce_planks":22},"sha256":"69ac0521baf0caf73d868d4cf96b37eeefc3967ff2dc44bbb394704e329d517d","size":{"x":32,"y":1,"z":32}},{"blockCount":57,"bytes":2378,"file":"chunks/y018-z032-x352.json","offset":{"x":352,"y":18,"z":32},"requirements":{"minecraft:bricks":6,"minecraft:glass":16,"minecraft:sandstone":3,"minecraft:spruce_planks":32},"sha256":"762a85fb444312aba18a9a9ef2202df15575e5486370480a863f8bdde8352be2","size":{"x":32,"y":1,"z":32}},{"blockCount":162,"bytes":4172,"file":"chunks/y018-z032-x384.json","offset":{"x":384,"y":18,"z":32},"requirements":{"minecraft:bricks":20,"minecraft:sandstone":11,"minecraft:spruce_planks":11,"minecraft:stone_bricks":120},"sha256":"87c4af407ccf73c883d088324fcddc5c950dad790f0a01f3d7f6902b98b1bd8e","size":{"x":32,"y":1,"z":32}},{"blockCount":6,"bytes":757,"file":"chunks/y018-z064-x032.json","offset":{"x":32,"y":18,"z":64},"requirements":{"minecraft:stone_bricks":6},"sha256":"ed1d5b30763b286876cd7016b0f593425e583375a77d91a50dc449062ff4cb4b","size":{"x":32,"y":1,"z":32}},{"blockCount":51,"bytes":1066,"file":"chunks/y018-z064-x064.json","offset":{"x":64,"y":18,"z":64},"requirements":{"minecraft:stone_bricks":51},"sha256":"27b717f89e0132762bd4be35d49f6d75769cec0a5b5cff08f848e3dc2df57708","size":{"x":32,"y":1,"z":32}},{"blockCount":500,"bytes":7024,"file":"chunks/y018-z064-x096.json","offset":{"x":96,"y":18,"z":64},"requirements":{"minecraft:stone_bricks":500},"sha256":"dcc5884020daaaba9fc5a3d3b421da8f3c10505490c35c5206ccd94196aa577f","size":{"x":32,"y":1,"z":32}},{"blockCount":213,"bytes":3798,"file":"chunks/y018-z064-x128.json","offset":{"x":128,"y":18,"z":64},"requirements":{"minecraft:stone_bricks":213},"sha256":"29c7182cdb9dfc7037960e96ef6bc78a904991709ef4bb573a4130658462f1d7","size":{"x":32,"y":1,"z":32}},{"blockCount":69,"bytes":1931,"file":"chunks/y018-z064-x320.json","offset":{"x":320,"y":18,"z":64},"requirements":{"minecraft:bricks":9,"minecraft:sandstone":51,"minecraft:spruce_planks":9},"sha256":"3cbdf55d7bcbb3da595397c12ddf7e3090d3d331af411b900f2525faefe7596b","size":{"x":32,"y":1,"z":32}},{"blockCount":89,"bytes":1476,"file":"chunks/y018-z064-x352.json","offset":{"x":352,"y":18,"z":64},"requirements":{"minecraft:bricks":6,"minecraft:sandstone":67,"minecraft:spruce_planks":16},"sha256":"aef35cb0cb4d28ea160c93fe80134a3dee463ee4f4c962db4aa8af5cd7d6bd4e","size":{"x":32,"y":1,"z":32}},{"blockCount":61,"bytes":1742,"file":"chunks/y018-z064-x384.json","offset":{"x":384,"y":18,"z":64},"requirements":{"minecraft:bricks":3,"minecraft:sandstone":27,"minecraft:spruce_planks":1,"minecraft:stone_bricks":30},"sha256":"67b8fc13a270b8b32516844dce20e9368d0a26216d93691e797dd9e1f9cef77c","size":{"x":32,"y":1,"z":32}},{"blockCount":101,"bytes":2687,"file":"chunks/y018-z096-x032.json","offset":{"x":32,"y":18,"z":96},"requirements":{"minecraft:stone_bricks":101},"sha256":"2e5d6d45007e98ed76be9cf748b7ecfe7fc258af7fdbc039f73be89e34338f15","size":{"x":32,"y":1,"z":32}},{"blockCount":297,"bytes":3767,"file":"chunks/y018-z096-x064.json","offset":{"x":64,"y":18,"z":96},"requirements":{"minecraft:stone_bricks":297},"sha256":"3d9889b4613f0b2cdea900004617aa3a034a6a4eef4ff2b94c7bcf353ebf3fb4","size":{"x":32,"y":1,"z":32}},{"blockCount":517,"bytes":3215,"file":"chunks/y018-z096-x096.json","offset":{"x":96,"y":18,"z":96},"requirements":{"minecraft:stone_bricks":517},"sha256":"0e4730d798102f47c14f20f2261921cd02f006c3eb94ccdc5ae213d453f43967","size":{"x":32,"y":1,"z":32}},{"blockCount":362,"bytes":3347,"file":"chunks/y018-z096-x128.json","offset":{"x":128,"y":18,"z":96},"requirements":{"minecraft:stone_bricks":362},"sha256":"b920471c6430016a3530c85565a66c4a4f0c4b2f5fe361226e42bd057fceb124","size":{"x":32,"y":1,"z":32}},{"blockCount":32,"bytes":624,"file":"chunks/y018-z096-x160.json","offset":{"x":160,"y":18,"z":96},"requirements":{"minecraft:stone_bricks":32},"sha256":"01f58a4ce6fbb85f4e1695b497f3917cf418bfcbf537d296b69fe2a5d7b6da51","size":{"x":32,"y":1,"z":32}},{"blockCount":32,"bytes":1438,"file":"chunks/y018-z096-x192.json","offset":{"x":192,"y":18,"z":96},"requirements":{"minecraft:bricks":21,"minecraft:stone_bricks":11},"sha256":"c425f58c4d6668b0ee07bff25a7afd35be477d358d7a9a49d32dd45473cd21a8","size":{"x":32,"y":1,"z":32}},{"blockCount":21,"bytes":1292,"file":"chunks/y018-z096-x224.json","offset":{"x":224,"y":18,"z":96},"requirements":{"minecraft:bricks":21},"sha256":"341a8e072c5028ea892d5fc9c14b81cfb27dba339c2a8da0fe246978999df5d2","size":{"x":32,"y":1,"z":32}},{"blockCount":17,"bytes":733,"file":"chunks/y018-z096-x256.json","offset":{"x":256,"y":18,"z":96},"requirements":{"minecraft:oak_planks":4,"minecraft:spruce_planks":9,"minecraft:stone_bricks":4},"sha256":"adee56fcfd474ff17d3adb59776c30da4f511f478a7738d672838d15778e0a30","size":{"x":32,"y":1,"z":32}},{"blockCount":130,"bytes":894,"file":"chunks/y018-z096-x288.json","offset":{"x":288,"y":18,"z":96},"requirements":{"minecraft:spruce_planks":22,"minecraft:stone_bricks":108},"sha256":"8064ae0db00570c1e6451f1ed6dd8743a8d90742e22c977ad1b47a4edfcd54c9","size":{"x":32,"y":1,"z":32}},{"blockCount":200,"bytes":917,"file":"chunks/y018-z096-x320.json","offset":{"x":320,"y":18,"z":96},"requirements":{"minecraft:stone_bricks":200},"sha256":"71d61aabf27840134da7a3b888fff4b36d673f1dbc6d8e41bc536434f6e09cdc","size":{"x":32,"y":1,"z":32}},{"blockCount":378,"bytes":3026,"file":"chunks/y018-z128-x032.json","offset":{"x":32,"y":18,"z":128},"requirements":{"minecraft:stone_bricks":378},"sha256":"179c3bb3e709df8c173e466020fbdfcd056f62b69afde35393d39ce701c90893","size":{"x":32,"y":1,"z":32}},{"blockCount":215,"bytes":1489,"file":"chunks/y018-z128-x064.json","offset":{"x":64,"y":18,"z":128},"requirements":{"minecraft:stone_bricks":215},"sha256":"709766e8fecd13456acc64364c927d45bc84807f83e1d8fcd09f2a8b150e298a","size":{"x":32,"y":1,"z":32}},{"blockCount":248,"bytes":3266,"file":"chunks/y018-z128-x096.json","offset":{"x":96,"y":18,"z":128},"requirements":{"minecraft:glass":74,"minecraft:stone_bricks":174},"sha256":"1ae22ebbc9a67a5223a38e7b4db42e7234ecd5d16f723c1239d210c14609f878","size":{"x":32,"y":1,"z":32}},{"blockCount":264,"bytes":3348,"file":"chunks/y018-z128-x128.json","offset":{"x":128,"y":18,"z":128},"requirements":{"minecraft:glass":28,"minecraft:polished_diorite":8,"minecraft:stone_bricks":228},"sha256":"b44126d76ed57d1cf87099b3d567f75ecbbb727158ae91d392a9560746b34a93","size":{"x":32,"y":1,"z":32}},{"blockCount":366,"bytes":3285,"file":"chunks/y018-z128-x160.json","offset":{"x":160,"y":18,"z":128},"requirements":{"minecraft:glass":14,"minecraft:stone_bricks":352},"sha256":"bf528b055c2a50be8fcd4a85e42b2d02d1892b1fae6ebff7204da9fa88026137","size":{"x":32,"y":1,"z":32}},{"blockCount":154,"bytes":2564,"file":"chunks/y018-z128-x192.json","offset":{"x":192,"y":18,"z":128},"requirements":{"minecraft:bricks":24,"minecraft:stone_bricks":130},"sha256":"3ed64a64e12fb69d36f1a7d0cbb2c200f1445ec3071c8dd532de2343ab79607f","size":{"x":32,"y":1,"z":32}},{"blockCount":51,"bytes":2164,"file":"chunks/y018-z128-x224.json","offset":{"x":224,"y":18,"z":128},"requirements":{"minecraft:bricks":22,"minecraft:cobbled_deepslate":3,"minecraft:stone_bricks":26},"sha256":"b1496939e19b6e0bdf64146e0002f2a7676a50611318b42c06c706483b490a2d","size":{"x":32,"y":1,"z":32}},{"blockCount":314,"bytes":3854,"file":"chunks/y018-z128-x256.json","offset":{"x":256,"y":18,"z":128},"requirements":{"minecraft:oak_planks":24,"minecraft:polished_diorite":37,"minecraft:spruce_planks":205,"minecraft:stone_bricks":48},"sha256":"6616288eeeaa2463ef899b7fcd7d9f36c48457780ceb68786239881ef5fef0ea","size":{"x":32,"y":1,"z":32}},{"blockCount":648,"bytes":2538,"file":"chunks/y018-z128-x288.json","offset":{"x":288,"y":18,"z":128},"requirements":{"minecraft:glass":7,"minecraft:polished_diorite":11,"minecraft:spruce_planks":324,"minecraft:stone_bricks":306},"sha256":"90ddfdc39dab109328662f7f8b8c0b20f38f1d25ad75ce892ea9ec12c2c33459","size":{"x":32,"y":1,"z":32}},{"blockCount":807,"bytes":3663,"file":"chunks/y018-z128-x320.json","offset":{"x":320,"y":18,"z":128},"requirements":{"minecraft:cobbled_deepslate":12,"minecraft:glass":329,"minecraft:polished_diorite":57,"minecraft:stone_bricks":409},"sha256":"e13a9d52c59debd0fc530bf7917953bdb93b01d1b871be2bf6b84be5c41f37d3","size":{"x":32,"y":1,"z":32}},{"blockCount":12,"bytes":837,"file":"chunks/y018-z128-x384.json","offset":{"x":384,"y":18,"z":128},"requirements":{"minecraft:stone_bricks":12},"sha256":"87a849793d5042d4613b177c7141130f453062d996ddfd2509c89f56a1535a24","size":{"x":32,"y":1,"z":32}},{"blockCount":63,"bytes":2152,"file":"chunks/y018-z160-x032.json","offset":{"x":32,"y":18,"z":160},"requirements":{"minecraft:stone_bricks":63},"sha256":"6005b36e8831c5988bec006c383580347927a4fb53e4bd26b7b87c6be3be75b8","size":{"x":32,"y":1,"z":32}},{"blockCount":301,"bytes":3485,"file":"chunks/y018-z160-x064.json","offset":{"x":64,"y":18,"z":160},"requirements":{"minecraft:stone_bricks":301},"sha256":"bb4a41d687721ca65bad4c69c10653b47b82ec04069759c8d3ae6ff3bb3ab372","size":{"x":32,"y":1,"z":32}},{"blockCount":611,"bytes":4369,"file":"chunks/y018-z160-x096.json","offset":{"x":96,"y":18,"z":160},"requirements":{"minecraft:stone_bricks":611},"sha256":"b93f0e5ddd1c269a2534f94c871739caf5ea7113e2285123eaabb00239ff7fb8","size":{"x":32,"y":1,"z":32}},{"blockCount":380,"bytes":3771,"file":"chunks/y018-z160-x128.json","offset":{"x":128,"y":18,"z":160},"requirements":{"minecraft:stone_bricks":380},"sha256":"db241671607ba08c052b0b5deeb3d766af0a6e0b55cea013b4e5aae77baa1b7c","size":{"x":32,"y":1,"z":32}},{"blockCount":43,"bytes":2056,"file":"chunks/y018-z160-x160.json","offset":{"x":160,"y":18,"z":160},"requirements":{"minecraft:cobbled_deepslate":26,"minecraft:glass":2,"minecraft:stone_bricks":15},"sha256":"d11bc0c1919290f2c45384c95c0bdf3332b686ccb2db6628951e352c105ecd98","size":{"x":32,"y":1,"z":32}},{"blockCount":77,"bytes":1549,"file":"chunks/y018-z160-x192.json","offset":{"x":192,"y":18,"z":160},"requirements":{"minecraft:bricks":8,"minecraft:glass":18,"minecraft:stone_bricks":51},"sha256":"27b17ae2a3169878e659d530773cb74931ed94c91b4db5fd6fbbc7eea3f8c1ab","size":{"x":32,"y":1,"z":32}},{"blockCount":65,"bytes":1932,"file":"chunks/y018-z160-x224.json","offset":{"x":224,"y":18,"z":160},"requirements":{"minecraft:bricks":8,"minecraft:stone_bricks":57},"sha256":"02d8f707353e0eaf6e5ef25486c35d0a134e53233cd54b61719608ea5dc4250d","size":{"x":32,"y":1,"z":32}},{"blockCount":69,"bytes":1646,"file":"chunks/y018-z160-x256.json","offset":{"x":256,"y":18,"z":160},"requirements":{"minecraft:oak_planks":61,"minecraft:sandstone":1,"minecraft:stone_bricks":7},"sha256":"1c1c2e65c00f7e24803dd974025b08327ab62e2fbbcfe98f9f57588509e8dc6d","size":{"x":32,"y":1,"z":32}},{"blockCount":50,"bytes":1588,"file":"chunks/y018-z160-x288.json","offset":{"x":288,"y":18,"z":160},"requirements":{"minecraft:oak_planks":43,"minecraft:sandstone":1,"minecraft:stone_bricks":6},"sha256":"0026cb243cd4bf58385f4561809a15f2c9b63fcb7ba19046bc668d11771fb48a","size":{"x":32,"y":1,"z":32}},{"blockCount":24,"bytes":626,"file":"chunks/y018-z160-x320.json","offset":{"x":320,"y":18,"z":160},"requirements":{"minecraft:stone_bricks":24},"sha256":"ba8f44ed5332165c4bd59c0e514da4b300a92893a9e37f4a71dbc02d93cb051a","size":{"x":32,"y":1,"z":32}},{"blockCount":4,"bytes":760,"file":"chunks/y018-z160-x352.json","offset":{"x":352,"y":18,"z":160},"requirements":{"minecraft:stone_bricks":4},"sha256":"c3256180e9c0b2008de34f761c7997db8bca61a12e44e181a44625e46d0902d3","size":{"x":32,"y":1,"z":32}},{"blockCount":349,"bytes":5368,"file":"chunks/y018-z192-x096.json","offset":{"x":96,"y":18,"z":192},"requirements":{"minecraft:stone_bricks":349},"sha256":"75ed19fb081eaeb02b125b40c81adc4592e71674ce59a533b897a2f09b4d97b3","size":{"x":32,"y":1,"z":32}},{"blockCount":135,"bytes":2665,"file":"chunks/y018-z192-x128.json","offset":{"x":128,"y":18,"z":192},"requirements":{"minecraft:stone_bricks":135},"sha256":"f45d74c0b161fc84bda5206abf57022a647117ab041129496a45878b8e5a09f2","size":{"x":32,"y":1,"z":32}},{"blockCount":56,"bytes":1648,"file":"chunks/y018-z192-x160.json","offset":{"x":160,"y":18,"z":192},"requirements":{"minecraft:cobbled_deepslate":43,"minecraft:stone_bricks":13},"sha256":"5f8a58c0d20fca50d68deee242e5ebe752209d5eb8206f847ed4e3346492fce3","size":{"x":32,"y":1,"z":32}},{"blockCount":63,"bytes":1140,"file":"chunks/y018-z192-x192.json","offset":{"x":192,"y":18,"z":192},"requirements":{"minecraft:cobbled_deepslate":32,"minecraft:stone_bricks":31},"sha256":"cf971c847c77698d443b206ab173f9bb23ebc2e871f88b5b1910e1c141b7618b","size":{"x":32,"y":1,"z":32}},{"blockCount":82,"bytes":1427,"file":"chunks/y018-z192-x224.json","offset":{"x":224,"y":18,"z":192},"requirements":{"minecraft:cobbled_deepslate":19,"minecraft:stone_bricks":63},"sha256":"b030a5cf64b98a3af1bf5c5ad2abf599b3ce91b8be2eac2ccd564bd9dcd8e3e3","size":{"x":32,"y":1,"z":32}},{"blockCount":38,"bytes":1740,"file":"chunks/y018-z192-x256.json","offset":{"x":256,"y":18,"z":192},"requirements":{"minecraft:cobbled_deepslate":20,"minecraft:stone_bricks":18},"sha256":"915b9f3b64f6b49eaebf385827556414c6f83e4ada5cdb4a01002dda5c0cdb85","size":{"x":32,"y":1,"z":32}},{"blockCount":8,"bytes":910,"file":"chunks/y018-z192-x288.json","offset":{"x":288,"y":18,"z":192},"requirements":{"minecraft:cobbled_deepslate":4,"minecraft:stone_bricks":4},"sha256":"292962ab465fc2f484e443bc06fe767f723d3b9615e7ab8fcc885bebee750644","size":{"x":32,"y":1,"z":32}},{"blockCount":40,"bytes":992,"file":"chunks/y019-z000-x320.json","offset":{"x":320,"y":19,"z":0},"requirements":{"minecraft:sandstone":40},"sha256":"14d0981705c9c0d6ac5fd0247605c1d2eb4b8d6506221844e0cd30cab3d1e85a","size":{"x":32,"y":1,"z":32}},{"blockCount":64,"bytes":641,"file":"chunks/y019-z000-x352.json","offset":{"x":352,"y":19,"z":0},"requirements":{"minecraft:sandstone":64},"sha256":"74df2ecdb33f29aeb9c1c9c682af8a2cae18112b8652cf660a6665bdda51b3a3","size":{"x":32,"y":1,"z":32}},{"blockCount":21,"bytes":1054,"file":"chunks/y019-z000-x384.json","offset":{"x":384,"y":19,"z":0},"requirements":{"minecraft:sandstone":14,"minecraft:stone_bricks":7},"sha256":"c78dfee838d7492be297492d0c0b45eaf64031bcd7b2afbb7f73a8429b06cdbd","size":{"x":32,"y":1,"z":32}},{"blockCount":59,"bytes":2564,"file":"chunks/y019-z032-x320.json","offset":{"x":320,"y":19,"z":32},"requirements":{"minecraft:bricks":21,"minecraft:glass":8,"minecraft:sandstone":12,"minecraft:spruce_planks":18},"sha256":"fca75e4789e16583b646ffc63e08bd0e334947501b8517a3419dab08ddf595a9","size":{"x":32,"y":1,"z":32}},{"blockCount":50,"bytes":2113,"file":"chunks/y019-z032-x352.json","offset":{"x":352,"y":19,"z":32},"requirements":{"minecraft:bricks":6,"minecraft:glass":16,"minecraft:sandstone":4,"minecraft:spruce_planks":24},"sha256":"d2e27128e2ab013c742a300efe72532cc44da069b75eaa0bcb80d68249ac940c","size":{"x":32,"y":1,"z":32}},{"blockCount":144,"bytes":4019,"file":"chunks/y019-z032-x384.json","offset":{"x":384,"y":19,"z":32},"requirements":{"minecraft:bricks":15,"minecraft:sandstone":11,"minecraft:spruce_planks":6,"minecraft:stone_bricks":112},"sha256":"5e33d188f22f4c757d09338963f04f0d358449c34c6ef76468abbd0060e99322","size":{"x":32,"y":1,"z":32}},{"blockCount":6,"bytes":757,"file":"chunks/y019-z064-x032.json","offset":{"x":32,"y":19,"z":64},"requirements":{"minecraft:stone_bricks":6},"sha256":"6519b83a73c20a56a20ebff00474dc532faa0fbb28b6bedd4fbb5593607f76c6","size":{"x":32,"y":1,"z":32}},{"blockCount":50,"bytes":1028,"file":"chunks/y019-z064-x064.json","offset":{"x":64,"y":19,"z":64},"requirements":{"minecraft:stone_bricks":50},"sha256":"5f61a71773e266a43277b202b00d9395fbbc04ef003d6fe4ce711d2205dedfdd","size":{"x":32,"y":1,"z":32}},{"blockCount":111,"bytes":2648,"file":"chunks/y019-z064-x096.json","offset":{"x":96,"y":19,"z":64},"requirements":{"minecraft:stone_bricks":111},"sha256":"b92b163ff61751ebef12fedec6afb03e488c942727b84e18e95dc24cd974c477","size":{"x":32,"y":1,"z":32}},{"blockCount":66,"bytes":1927,"file":"chunks/y019-z064-x128.json","offset":{"x":128,"y":19,"z":64},"requirements":{"minecraft:stone_bricks":66},"sha256":"488f234a42db0f3712ef68ef2aa14bd7f6c588cac63485c437305e7845bfc308","size":{"x":32,"y":1,"z":32}},{"blockCount":66,"bytes":1817,"file":"chunks/y019-z064-x320.json","offset":{"x":320,"y":19,"z":64},"requirements":{"minecraft:bricks":9,"minecraft:sandstone":52,"minecraft:spruce_planks":5},"sha256":"d6d3970b3050d5c57b00459c78cb276c73672866c1af4d10cb1baf43c183d7a9","size":{"x":32,"y":1,"z":32}},{"blockCount":82,"bytes":1210,"file":"chunks/y019-z064-x352.json","offset":{"x":352,"y":19,"z":64},"requirements":{"minecraft:bricks":6,"minecraft:sandstone":68,"minecraft:spruce_planks":8},"sha256":"31f85f80370db40e20a31a49d6588755caa2b688193ebc69ccc16c06757e9291","size":{"x":32,"y":1,"z":32}},{"blockCount":59,"bytes":1703,"file":"chunks/y019-z064-x384.json","offset":{"x":384,"y":19,"z":64},"requirements":{"minecraft:bricks":3,"minecraft:sandstone":25,"minecraft:spruce_planks":1,"minecraft:stone_bricks":30},"sha256":"833e9fbab190f75d9b58bba1c44e2481c4b2c3967d0bacb939f0112d12c39ddc","size":{"x":32,"y":1,"z":32}},{"blockCount":96,"bytes":2761,"file":"chunks/y019-z096-x032.json","offset":{"x":32,"y":19,"z":96},"requirements":{"minecraft:stone_bricks":96},"sha256":"90426d2f64375e25be494d8be40c64f9b11469241b27c08b63d0a9197c5b2417","size":{"x":32,"y":1,"z":32}},{"blockCount":237,"bytes":4301,"file":"chunks/y019-z096-x064.json","offset":{"x":64,"y":19,"z":96},"requirements":{"minecraft:stone_bricks":237},"sha256":"263b3ac1a0017b2c6645a1cbb07d54592238bb5eefc782e9833bb3369d67874e","size":{"x":32,"y":1,"z":32}},{"blockCount":182,"bytes":4054,"file":"chunks/y019-z096-x096.json","offset":{"x":96,"y":19,"z":96},"requirements":{"minecraft:glass":51,"minecraft:stone_bricks":131},"sha256":"edd61277e6fc5082fd9a43cfd096ee63386f73da9fc73a06b82d493d809b6170","size":{"x":32,"y":1,"z":32}},{"blockCount":203,"bytes":3860,"file":"chunks/y019-z096-x128.json","offset":{"x":128,"y":19,"z":96},"requirements":{"minecraft:glass":5,"minecraft:stone_bricks":198},"sha256":"29442057df6c69db8f3020ef7b44b8f0884d7eb14b0b90f43ebdb1b3973fd3cd","size":{"x":32,"y":1,"z":32}},{"blockCount":32,"bytes":624,"file":"chunks/y019-z096-x160.json","offset":{"x":160,"y":19,"z":96},"requirements":{"minecraft:stone_bricks":32},"sha256":"99f4c315ecfd4399ca7e46fe5de41d352105add80e447e972b9d457907472c39","size":{"x":32,"y":1,"z":32}},{"blockCount":28,"bytes":1324,"file":"chunks/y019-z096-x192.json","offset":{"x":192,"y":19,"z":96},"requirements":{"minecraft:bricks":17,"minecraft:stone_bricks":11},"sha256":"02f57a3bbfbb9f9a11c50e0327035406e66a2b0167677047ff8d91e115dabfe7","size":{"x":32,"y":1,"z":32}},{"blockCount":18,"bytes":1216,"file":"chunks/y019-z096-x224.json","offset":{"x":224,"y":19,"z":96},"requirements":{"minecraft:bricks":18},"sha256":"0f7394fcabae56066340cfacbad6edcce2df166e6ca1644a99ef8c2e740c1457","size":{"x":32,"y":1,"z":32}},{"blockCount":161,"bytes":3740,"file":"chunks/y019-z128-x032.json","offset":{"x":32,"y":19,"z":128},"requirements":{"minecraft:stone_bricks":161},"sha256":"215164924b561fd14f2121e727f63d0b406f45b5a3840132d04457fff226c48c","size":{"x":32,"y":1,"z":32}},{"blockCount":119,"bytes":1759,"file":"chunks/y019-z128-x064.json","offset":{"x":64,"y":19,"z":128},"requirements":{"minecraft:glass":60,"minecraft:stone_bricks":59},"sha256":"72a74f399261d6904a2359f8d488f9cefda0a74d1328a48fc552b1042c8d10cb","size":{"x":32,"y":1,"z":32}},{"blockCount":124,"bytes":3512,"file":"chunks/y019-z128-x096.json","offset":{"x":96,"y":19,"z":128},"requirements":{"minecraft:glass":98,"minecraft:stone_bricks":26},"sha256":"6852f78b9855d3f699b84128db2ae0d6803f08d77e234f52e5b6ea2cde8afaff","size":{"x":32,"y":1,"z":32}},{"blockCount":179,"bytes":3100,"file":"chunks/y019-z128-x128.json","offset":{"x":128,"y":19,"z":128},"requirements":{"minecraft:glass":61,"minecraft:polished_diorite":2,"minecraft:stone_bricks":116},"sha256":"6e57495ccc71997aba5bcd6ed2a13b8532b99dce3823885c3cb7d065a204bebc","size":{"x":32,"y":1,"z":32}},{"blockCount":346,"bytes":3277,"file":"chunks/y019-z128-x160.json","offset":{"x":160,"y":19,"z":128},"requirements":{"minecraft:glass":19,"minecraft:stone_bricks":327},"sha256":"8df85db3c7f7fbff6db0b101b11d5b4cae88b5985433a92adcee8dd06647ce38","size":{"x":32,"y":1,"z":32}},{"blockCount":164,"bytes":2793,"file":"chunks/y019-z128-x192.json","offset":{"x":192,"y":19,"z":128},"requirements":{"minecraft:bricks":26,"minecraft:stone_bricks":138},"sha256":"6e394c247b67610c83dae94b0add68fc9559aa7491abc4349faa639d0258b0a1","size":{"x":32,"y":1,"z":32}},{"blockCount":51,"bytes":2287,"file":"chunks/y019-z128-x224.json","offset":{"x":224,"y":19,"z":128},"requirements":{"minecraft:bricks":43,"minecraft:stone_bricks":8},"sha256":"5f7c22f666b9f7c9d543ef4902054f8d0a35d3648740b3395e60d118f267da91","size":{"x":32,"y":1,"z":32}},{"blockCount":49,"bytes":1788,"file":"chunks/y019-z128-x256.json","offset":{"x":256,"y":19,"z":128},"requirements":{"minecraft:spruce_planks":26,"minecraft:stone_bricks":23},"sha256":"bfd93c67ad4067a7fa7c50fdaef1d5a54191500e80728a1f6b865767bc6027da","size":{"x":32,"y":1,"z":32}},{"blockCount":259,"bytes":1549,"file":"chunks/y019-z128-x288.json","offset":{"x":288,"y":19,"z":128},"requirements":{"minecraft:cobbled_deepslate":11,"minecraft:spruce_planks":247,"minecraft:stone_bricks":1},"sha256":"296ae10839b387baf56264e9663d0a21e8902716447c2b58af18344403e32973","size":{"x":32,"y":1,"z":32}},{"blockCount":66,"bytes":2227,"file":"chunks/y019-z128-x320.json","offset":{"x":320,"y":19,"z":128},"requirements":{"minecraft:cobbled_deepslate":53,"minecraft:stone_bricks":13},"sha256":"211e709d84f34b7f95944cdc2909c03d85dc3b4f438b03da77994d87d24012a7","size":{"x":32,"y":1,"z":32}},{"blockCount":12,"bytes":837,"file":"chunks/y019-z128-x384.json","offset":{"x":384,"y":19,"z":128},"requirements":{"minecraft:stone_bricks":12},"sha256":"55c5c37000c974b0e5c6b2f7696cbe11b091d37682f656aae88dab94b32ff9d1","size":{"x":32,"y":1,"z":32}},{"blockCount":63,"bytes":2152,"file":"chunks/y019-z160-x032.json","offset":{"x":32,"y":19,"z":160},"requirements":{"minecraft:stone_bricks":63},"sha256":"67092fd681bb2e7873229a3bb37d00a51e7e708296add8cd9d29b1f7f072bd5e","size":{"x":32,"y":1,"z":32}},{"blockCount":239,"bytes":3934,"file":"chunks/y019-z160-x064.json","offset":{"x":64,"y":19,"z":160},"requirements":{"minecraft:polished_diorite":2,"minecraft:stone_bricks":237},"sha256":"769861b2680c6257bd64462402534663397855586d8f42ca66179f105a059406","size":{"x":32,"y":1,"z":32}},{"blockCount":171,"bytes":3709,"file":"chunks/y019-z160-x096.json","offset":{"x":96,"y":19,"z":160},"requirements":{"minecraft:glass":37,"minecraft:stone_bricks":134},"sha256":"6de448405c891a9c25a32cdc4a568d19e0493dae77948143d53af2f284514360","size":{"x":32,"y":1,"z":32}},{"blockCount":165,"bytes":3581,"file":"chunks/y019-z160-x128.json","offset":{"x":128,"y":19,"z":160},"requirements":{"minecraft:glass":5,"minecraft:stone_bricks":160},"sha256":"44aed8f844678f86d1c5073bd5b6d0795626b267d4ed891723f1c21e448aa766","size":{"x":32,"y":1,"z":32}},{"blockCount":43,"bytes":2094,"file":"chunks/y019-z160-x160.json","offset":{"x":160,"y":19,"z":160},"requirements":{"minecraft:cobbled_deepslate":26,"minecraft:stone_bricks":17},"sha256":"c4b9b6372e0c402cfadf390596c83bad3eb0b3c732b7849e04e23fd04fce4bab","size":{"x":32,"y":1,"z":32}},{"blockCount":87,"bytes":1471,"file":"chunks/y019-z160-x192.json","offset":{"x":192,"y":19,"z":160},"requirements":{"minecraft:bricks":7,"minecraft:stone_bricks":80},"sha256":"45c6f1aa985c3a8be832c5a41daefd75979daf2c0efdd2f5194ed2a8da59c2de","size":{"x":32,"y":1,"z":32}},{"blockCount":49,"bytes":1205,"file":"chunks/y019-z160-x224.json","offset":{"x":224,"y":19,"z":160},"requirements":{"minecraft:bricks":2,"minecraft:stone_bricks":47},"sha256":"1a492165244326fcaf910264006fb79f4e32fd64a0acdaa36502c23a431e6923","size":{"x":32,"y":1,"z":32}},{"blockCount":69,"bytes":1970,"file":"chunks/y019-z160-x256.json","offset":{"x":256,"y":19,"z":160},"requirements":{"minecraft:oak_planks":39,"minecraft:sandstone":29,"minecraft:stone_bricks":1},"sha256":"c14cbfe9ecc7bbe62442c74465ace09f04c6139076f753f0edcb614d5c649e7a","size":{"x":32,"y":1,"z":32}},{"blockCount":45,"bytes":1950,"file":"chunks/y019-z160-x288.json","offset":{"x":288,"y":19,"z":160},"requirements":{"minecraft:oak_planks":23,"minecraft:sandstone":21,"minecraft:stone_bricks":1},"sha256":"63f2da732a376cff4049e2ef79ac4b6ecc1ddd231ba7d143dfb306beed3e08b2","size":{"x":32,"y":1,"z":32}},{"blockCount":4,"bytes":760,"file":"chunks/y019-z160-x352.json","offset":{"x":352,"y":19,"z":160},"requirements":{"minecraft:stone_bricks":4},"sha256":"794e06a903a358eabcc9208406d654d576e003f47041d0e0dc96ff912d62c7fb","size":{"x":32,"y":1,"z":32}},{"blockCount":82,"bytes":2147,"file":"chunks/y019-z192-x096.json","offset":{"x":96,"y":19,"z":192},"requirements":{"minecraft:stone_bricks":82},"sha256":"1cb959f5a3001748945b353ff10d8c15fa16cce736a3982c80a0938d5c6ed366","size":{"x":32,"y":1,"z":32}},{"blockCount":37,"bytes":1384,"file":"chunks/y019-z192-x128.json","offset":{"x":128,"y":19,"z":192},"requirements":{"minecraft:stone_bricks":37},"sha256":"ea36f36104b496a5418800762ba691af563186de6fc83d666b3f8f864a9bf3e5","size":{"x":32,"y":1,"z":32}},{"blockCount":53,"bytes":1531,"file":"chunks/y019-z192-x160.json","offset":{"x":160,"y":19,"z":192},"requirements":{"minecraft:cobbled_deepslate":43,"minecraft:stone_bricks":10},"sha256":"0b3f7f3b4aee0d9db43102daaa22b61c2092963dbb2a0bc8f513987e173fb9b4","size":{"x":32,"y":1,"z":32}},{"blockCount":69,"bytes":1180,"file":"chunks/y019-z192-x192.json","offset":{"x":192,"y":19,"z":192},"requirements":{"minecraft:cobbled_deepslate":32,"minecraft:stone_bricks":37},"sha256":"dbec79b80fd2c1d8b5ac5bbd7af802e3890f1e3a948df4de352a9acd9184330b","size":{"x":32,"y":1,"z":32}},{"blockCount":78,"bytes":1182,"file":"chunks/y019-z192-x224.json","offset":{"x":224,"y":19,"z":192},"requirements":{"minecraft:cobbled_deepslate":19,"minecraft:stone_bricks":59},"sha256":"b8ffba7f72d9dbed1f04ce8eeb74d7f30b34243eda7456bb0c7cda7a54e4f656","size":{"x":32,"y":1,"z":32}},{"blockCount":36,"bytes":1664,"file":"chunks/y019-z192-x256.json","offset":{"x":256,"y":19,"z":192},"requirements":{"minecraft:cobbled_deepslate":21,"minecraft:stone_bricks":15},"sha256":"a08c4dfd928b234a296104bc253fa5d1cae1d3a469c786867e9af6a2a13ddaff","size":{"x":32,"y":1,"z":32}},{"blockCount":8,"bytes":910,"file":"chunks/y019-z192-x288.json","offset":{"x":288,"y":19,"z":192},"requirements":{"minecraft:cobbled_deepslate":3,"minecraft:stone_bricks":5},"sha256":"3526e7178fef188eaaf6ef6caf64ddcac0de5d13648b54ea0068a13604bb7077","size":{"x":32,"y":1,"z":32}},{"blockCount":13,"bytes":880,"file":"chunks/y019-z224-x224.json","offset":{"x":224,"y":19,"z":224},"requirements":{"minecraft:cobbled_deepslate":6,"minecraft:sandstone":7},"sha256":"4eaa0e55ac5ef709d50e957aa2091955717f4dfc135bb5eb05ba4c8b60c86428","size":{"x":32,"y":1,"z":15}},{"blockCount":3,"bytes":710,"file":"chunks/y019-z224-x256.json","offset":{"x":256,"y":19,"z":224},"requirements":{"minecraft:cobbled_deepslate":2,"minecraft:sandstone":1},"sha256":"3291d22b7092278b2f85793f45ceaa5815b58e67bc2444296b99ef5a61bc0a57","size":{"x":32,"y":1,"z":15}},{"blockCount":40,"bytes":992,"file":"chunks/y020-z000-x320.json","offset":{"x":320,"y":20,"z":0},"requirements":{"minecraft:sandstone":40},"sha256":"9c15989fbd5891735f91799ce65a3bb34d4458b22584d4e5a1996e0112e38e45","size":{"x":32,"y":1,"z":32}},{"blockCount":64,"bytes":641,"file":"chunks/y020-z000-x352.json","offset":{"x":352,"y":20,"z":0},"requirements":{"minecraft:sandstone":64},"sha256":"25ba8504c8e9561ec0b6849db77c4be5ba33a67af60a4b489b7d078b8952a7f9","size":{"x":32,"y":1,"z":32}},{"blockCount":25,"bytes":1093,"file":"chunks/y020-z000-x384.json","offset":{"x":384,"y":20,"z":0},"requirements":{"minecraft:sandstone":13,"minecraft:stone_bricks":12},"sha256":"171c3134074ed353e56d3ac647cf42b727211e43cde2645766074a3134b04469","size":{"x":32,"y":1,"z":32}},{"blockCount":63,"bytes":2678,"file":"chunks/y020-z032-x320.json","offset":{"x":320,"y":20,"z":32},"requirements":{"minecraft:bricks":21,"minecraft:glass":8,"minecraft:sandstone":12,"minecraft:spruce_planks":22},"sha256":"8ad42d55e0b41e7fbf89f056d55419be505f3ecd8d7b24938d390aa35e30db55","size":{"x":32,"y":1,"z":32}},{"blockCount":58,"bytes":2417,"file":"chunks/y020-z032-x352.json","offset":{"x":352,"y":20,"z":32},"requirements":{"minecraft:bricks":6,"minecraft:glass":16,"minecraft:sandstone":4,"minecraft:spruce_planks":32},"sha256":"f40c448895d2331cabf0aeb31a4091b68a663cd4a4ee63a2ed7c66d4586a0a6a","size":{"x":32,"y":1,"z":32}},{"blockCount":136,"bytes":4018,"file":"chunks/y020-z032-x384.json","offset":{"x":384,"y":20,"z":32},"requirements":{"minecraft:bricks":15,"minecraft:sandstone":11,"minecraft:spruce_planks":6,"minecraft:stone_bricks":104},"sha256":"465a86f10de2faa2d970b7b5b766e5bf1f5aea96e1f3a92bf3eb98783e5858c6","size":{"x":32,"y":1,"z":32}},{"blockCount":6,"bytes":757,"file":"chunks/y020-z064-x032.json","offset":{"x":32,"y":20,"z":64},"requirements":{"minecraft:stone_bricks":6},"sha256":"580c15ce2598e9a6613003cd9f0fa4ece08e47f8c1b76703bf9b777ef031a9ab","size":{"x":32,"y":1,"z":32}},{"blockCount":52,"bytes":1028,"file":"chunks/y020-z064-x064.json","offset":{"x":64,"y":20,"z":64},"requirements":{"minecraft:stone_bricks":52},"sha256":"718955c9611f511d5645501c101bb68a46ed96275259b29039f9f2e911e51133","size":{"x":32,"y":1,"z":32}},{"blockCount":109,"bytes":2648,"file":"chunks/y020-z064-x096.json","offset":{"x":96,"y":20,"z":64},"requirements":{"minecraft:stone_bricks":109},"sha256":"732e6a7101ba75a17f3775fbd35f3b25747a12c3431c0ee5cade5d70867f3859","size":{"x":32,"y":1,"z":32}},{"blockCount":66,"bytes":1927,"file":"chunks/y020-z064-x128.json","offset":{"x":128,"y":20,"z":64},"requirements":{"minecraft:stone_bricks":66},"sha256":"a305d28fcc659f0ae81e832cf0ab3fdf7a95ca264d8c811738d41775ac5ba6bc","size":{"x":32,"y":1,"z":32}},{"blockCount":70,"bytes":1931,"file":"chunks/y020-z064-x320.json","offset":{"x":320,"y":20,"z":64},"requirements":{"minecraft:bricks":9,"minecraft:sandstone":52,"minecraft:spruce_planks":9},"sha256":"893c1b3e78b010e06a4820a02251918e7caba9fa7ac82a392e0a5348ad27d387","size":{"x":32,"y":1,"z":32}},{"blockCount":90,"bytes":1514,"file":"chunks/y020-z064-x352.json","offset":{"x":352,"y":20,"z":64},"requirements":{"minecraft:bricks":6,"minecraft:sandstone":68,"minecraft:spruce_planks":16},"sha256":"e332541d75f4a65967a13115bfa09b631a44c5a6e5dc9d67cd611af31fe00d43","size":{"x":32,"y":1,"z":32}},{"blockCount":58,"bytes":1664,"file":"chunks/y020-z064-x384.json","offset":{"x":384,"y":20,"z":64},"requirements":{"minecraft:bricks":3,"minecraft:sandstone":24,"minecraft:spruce_planks":1,"minecraft:stone_bricks":30},"sha256":"cf4edc5cde32f61a14b2dd8dceb05f1b88d3b9ae1e49ee42fd469fe655611737","size":{"x":32,"y":1,"z":32}},{"blockCount":95,"bytes":2799,"file":"chunks/y020-z096-x032.json","offset":{"x":32,"y":20,"z":96},"requirements":{"minecraft:stone_bricks":95},"sha256":"4672a4ed8e4978fd3b51f5a1ef44b5bf90ca24c8f54eca760d288c9252928473","size":{"x":32,"y":1,"z":32}},{"blockCount":276,"bytes":4071,"file":"chunks/y020-z096-x064.json","offset":{"x":64,"y":20,"z":96},"requirements":{"minecraft:stone_bricks":276},"sha256":"e70a0abb04d8fb3161f4f62c166e80d13a2e1a15c1305fef045bc60653c052f8","size":{"x":32,"y":1,"z":32}},{"blockCount":154,"bytes":3273,"file":"chunks/y020-z096-x096.json","offset":{"x":96,"y":20,"z":96},"requirements":{"minecraft:glass":20,"minecraft:stone_bricks":134},"sha256":"99b91d407f4072ede0276a5aca8b5aef66dbac99b377e9c37236097412d52817","size":{"x":32,"y":1,"z":32}}],"schema":1}
