{"entries":[{"blockCount":193,"bytes":3745,"file":"chunks/y020-z096-x128.json","offset":{"x":128,"y":20,"z":96},"requirements":{"minecraft:stone_bricks":193},"sha256":"91e972074111beb51746d5dbc20fc65396d5440181f7a28840b788ffe6dde26c","size":{"x":32,"y":1,"z":32}},{"blockCount":32,"bytes":624,"file":"chunks/y020-z096-x160.json","offset":{"x":160,"y":20,"z":96},"requirements":{"minecraft:stone_bricks":32},"sha256":"31cb7f28a9bfe84815bb4715cbf005005a75cde8e8ad6d6aad37135ceb8aee44","size":{"x":32,"y":1,"z":32}},{"blockCount":36,"bytes":1514,"file":"chunks/y020-z096-x192.json","offset":{"x":192,"y":20,"z":96},"requirements":{"minecraft:bricks":25,"minecraft:stone_bricks":11},"sha256":"a4c6e733862a34f3ec59f535a3497f486f60d48a3612be6168ab881e2cf647b3","size":{"x":32,"y":1,"z":32}},{"blockCount":22,"bytes":1372,"file":"chunks/y020-z096-x224.json","offset":{"x":224,"y":20,"z":96},"requirements":{"minecraft:bricks":22},"sha256":"2a329de9181806df2d68c055576e9fc7cfac9cacdc09ccf8eca40fa7a2f45b32","size":{"x":32,"y":1,"z":32}},{"blockCount":238,"bytes":2039,"file":"chunks/y020-z096-x288.json","offset":{"x":288,"y":20,"z":96},"requirements":{"minecraft:stone_bricks":238},"sha256":"ef3e8d6ef22739e8d73ed61222732efb348bcf696355ff9aac260edd043a867a","size":{"x":32,"y":1,"z":32}},{"blockCount":398,"bytes":1530,"file":"chunks/y020-z096-x320.json","offset":{"x":320,"y":20,"z":96},"requirements":{"minecraft:stone_bricks":398},"sha256":"3b2cec8fb6e45ae37e3ef496a9982e4ab7a8a5a4b3db1e62c63d87c1031c0d5d","size":{"x":32,"y":1,"z":32}},{"blockCount":87,"bytes":1191,"file":"chunks/y020-z096-x352.json","offset":{"x":352,"y":20,"z":96},"requirements":{"minecraft:stone_bricks":87},"sha256":"eb48ad6187eba020b5272b2fe394fefbe8bc2acefc2d529fd7c49362dfc89633","size":{"x":32,"y":1,"z":32}},{"blockCount":6,"bytes":759,"file":"chunks/y020-z096-x384.json","offset":{"x":384,"y":20,"z":96},"requirements":{"minecraft:stone_bricks":6},"sha256":"3db55807b1e87157df035c818f5bbcd70fd840ae2e06b0f861fb40ef10cd666c","size":{"x":32,"y":1,"z":32}},{"blockCount":169,"bytes":3684,"file":"chunks/y020-z128-x032.json","offset":{"x":32,"y":20,"z":128},"requirements":{"minecraft:glass":4,"minecraft:stone_bricks":165},"sha256":"b0a765eda86eb60d32e5f0f16dc6d149e44a315e7d94de855d03655124686d5a","size":{"x":32,"y":1,"z":32}},{"blockCount":83,"bytes":2629,"file":"chunks/y020-z128-x064.json","offset":{"x":64,"y":20,"z":128},"requirements":{"minecraft:glass":30,"minecraft:stone_bricks":53},"sha256":"32e268d28ca037c4bb8fdbfb9976552b0edb8b778b28356410303980fa81720d","size":{"x":32,"y":1,"z":32}},{"blockCount":54,"bytes":2163,"file":"chunks/y020-z128-x096.json","offset":{"x":96,"y":20,"z":128},"requirements":{"minecraft:glass":32,"minecraft:stone_bricks":22},"sha256":"484f037455bf111518482dc5b51047cf30beed8cccc3a5d2cea72891d13f68a6","size":{"x":32,"y":1,"z":32}},{"blockCount":137,"bytes":3497,"file":"chunks/y020-z128-x128.json","offset":{"x":128,"y":20,"z":128},"requirements":{"minecraft:glass":28,"minecraft:polished_diorite":2,"minecraft:stone_bricks":107},"sha256":"7a8e4bea6764bba172ff67dd3266fdb523e04f8c2e50713ef3ae486946755538","size":{"x":32,"y":1,"z":32}},{"blockCount":330,"bytes":3089,"file":"chunks/y020-z128-x160.json","offset":{"x":160,"y":20,"z":128},"requirements":{"minecraft:glass":17,"minecraft:stone_bricks":313},"sha256":"f54bace29c6c8bde94090a2f6db6fe18e648105165d91ac048c9ba0375d2be50","size":{"x":32,"y":1,"z":32}},{"blockCount":166,"bytes":2943,"file":"chunks/y020-z128-x192.json","offset":{"x":192,"y":20,"z":128},"requirements":{"minecraft:bricks":25,"minecraft:stone_bricks":141},"sha256":"c150a3e0e882c295460be5f91e05d1dea9abf797eaac9a0cc13463badad12960","size":{"x":32,"y":1,"z":32}},{"blockCount":48,"bytes":2363,"file":"chunks/y020-z128-x224.json","offset":{"x":224,"y":20,"z":128},"requirements":{"minecraft:bricks":47,"minecraft:stone_bricks":1},"sha256":"75896c53aaf2881fb665a60fa28fb95034f01212d38c71b587dda27438ac6db2","size":{"x":32,"y":1,"z":32}},{"blockCount":3,"bytes":722,"file":"chunks/y020-z128-x256.json","offset":{"x":256,"y":20,"z":128},"requirements":{"minecraft:stone_bricks":3},"sha256":"f3b38e6e84bc9b6cf976aefd61f4d872b1d3a6b287540fd6870ab1f834484c4b","size":{"x":32,"y":1,"z":32}},{"blockCount":481,"bytes":4387,"file":"chunks/y020-z128-x288.json","offset":{"x":288,"y":20,"z":128},"requirements":{"minecraft:cobbled_deepslate":11,"minecraft:stone_bricks":470},"sha256":"46ff3a14d103588f3d47eb2e60c2f4235623b2bd55e3c1583484bdb882f63a49","size":{"x":32,"y":1,"z":32}},{"blockCount":567,"bytes":5015,"file":"chunks/y020-z128-x320.json","offset":{"x":320,"y":20,"z":128},"requirements":{"minecraft:cobbled_deepslate":51,"minecraft:stone_bricks":516},"sha256":"b7d017a9284fab114a09bcab03d40c6e4d748cbcee9059e1dde20419d3832ac6","size":{"x":32,"y":1,"z":32}},{"blockCount":154,"bytes":1833,"file":"chunks/y020-z128-x352.json","offset":{"x":352,"y":20,"z":128},"requirements":{"minecraft:stone_bricks":154},"sha256":"ec1a8c8a95f8e1918a036a040cd033ac2105a4a8130578ecf5b0274c3768a515","size":{"x":32,"y":1,"z":32}},{"blockCount":12,"bytes":837,"file":"chunks/y020-z128-x384.json","offset":{"x":384,"y":20,"z":128},"requirements":{"minecraft:stone_bricks":12},"sha256":"14f7cc44c275ee63d44fb3ef86f5fb3a7e4563b3aa9329cb748645908e990ec2","size":{"x":32,"y":1,"z":32}},{"blockCount":63,"bytes":2152,"file":"chunks/y020-z160-x032.json","offset":{"x":32,"y":20,"z":160},"requirements":{"minecraft:stone_bricks":63},"sha256":"26f2a634361bdde1de56797fe7458de961d0eaea3d994e940fc9b17286e5fd36","size":{"x":32,"y":1,"z":32}},{"blockCount":284,"bytes":3865,"file":"chunks/y020-z160-x064.json","offset":{"x":64,"y":20,"z":160},"requirements":{"minecraft:stone_bricks":284},"sha256":"8804f3f3ac5d8e6b13fa4c5e66fa246d49856b15f5992d910bd6f72736e1c7ea","size":{"x":32,"y":1,"z":32}},{"blockCount":151,"bytes":3160,"file":"chunks/y020-z160-x096.json","offset":{"x":96,"y":20,"z":160},"requirements":{"minecraft:glass":12,"minecraft:stone_bricks":139},"sha256":"f99923eb205d7014191cbd38503be2d6eb6fd9efd5d2dc3596710a0702cbda0b","size":{"x":32,"y":1,"z":32}},{"blockCount":165,"bytes":3543,"file":"chunks/y020-z160-x128.json","offset":{"x":128,"y":20,"z":160},"requirements":{"minecraft:stone_bricks":165},"sha256":"e3fab29d8a1fadf4d4f781df67403542a95e53bf6da741394e15a5379fae0a17","size":{"x":32,"y":1,"z":32}},{"blockCount":46,"bytes":2091,"file":"chunks/y020-z160-x160.json","offset":{"x":160,"y":20,"z":160},"requirements":{"minecraft:cobbled_deepslate":26,"minecraft:stone_bricks":20},"sha256":"310600addb496ccfd30facb8b6eabd7bdff68f74b4512cb7a647d06751030ad6","size":{"x":32,"y":1,"z":32}},{"blockCount":99,"bytes":1967,"file":"chunks/y020-z160-x192.json","offset":{"x":192,"y":20,"z":160},"requirements":{"minecraft:bricks":6,"minecraft:stone_bricks":93},"sha256":"ef58a08d059ad84d0f4323c97d43082c40576b8459d6d8ee0958ce1528dfcaba","size":{"x":32,"y":1,"z":32}},{"blockCount":71,"bytes":1875,"file":"chunks/y020-z160-x224.json","offset":{"x":224,"y":20,"z":160},"requirements":{"minecraft:bricks":11,"minecraft:cobbled_deepslate":4,"minecraft:sandstone":3,"minecraft:stone_bricks":53},"sha256":"b854f7d4d3b7006b8e8be58671edebefd432dcdae2574e51f78e072e0aff2bf3","size":{"x":32,"y":1,"z":32}},{"blockCount":207,"bytes":2435,"file":"chunks/y020-z160-x256.json","offset":{"x":256,"y":20,"z":160},"requirements":{"minecraft:glass":166,"minecraft:sandstone":41},"sha256":"4bac8c015f297426b2ce20d21088c9ee8d19662e20d6e29d6aaae9660f962aab","size":{"x":32,"y":1,"z":32}},{"blockCount":197,"bytes":2600,"file":"chunks/y020-z160-x288.json","offset":{"x":288,"y":20,"z":160},"requirements":{"minecraft:glass":22,"minecraft:sandstone":25,"minecraft:stone_bricks":150},"sha256":"d577ffb12ac56a9b65a21a546ed17ed80ae3ad96a09dc819a9c8eb41b0281e2c","size":{"x":32,"y":1,"z":32}},{"blockCount":244,"bytes":1088,"file":"chunks/y020-z160-x320.json","offset":{"x":320,"y":20,"z":160},"requirements":{"minecraft:stone_bricks":244},"sha256":"3b83182db3ce8a6417635140fe5969a0934ba371eae6d0260b31230db8f166c4","size":{"x":32,"y":1,"z":32}},{"blockCount":62,"bytes":1055,"file":"chunks/y020-z160-x352.json","offset":{"x":352,"y":20,"z":160},"requirements":{"minecraft:stone_bricks":62},"sha256":"585e5a774d213229d8deacf15aee138ac9956c9c31127302ae26b81e6e313164","size":{"x":32,"y":1,"z":32}},{"blockCount":82,"bytes":2147,"file":"chunks/y020-z192-x096.json","offset":{"x":96,"y":20,"z":192},"requirements":{"minecraft:stone_bricks":82},"sha256":"753418560b807054b60a05ccc20b48d57232e7001555b47ae7e2e43a1615909a","size":{"x":32,"y":1,"z":32}},{"blockCount":37,"bytes":1384,"file":"chunks/y020-z192-x128.json","offset":{"x":128,"y":20,"z":192},"requirements":{"minecraft:stone_bricks":37},"sha256":"86a852f345f32b17423da31986363d27480ac01936f345fb33f678ed02cab4d1","size":{"x":32,"y":1,"z":32}},{"blockCount":64,"bytes":1751,"file":"chunks/y020-z192-x160.json","offset":{"x":160,"y":20,"z":192},"requirements":{"minecraft:cobbled_deepslate":43,"minecraft:spruce_planks":1,"minecraft:stone_bricks":20},"sha256":"22436ed0aed72be1c9151c44060c20201b272cec8b97324b82e512d2429bc1d8","size":{"x":32,"y":1,"z":32}},{"blockCount":90,"bytes":1522,"file":"chunks/y020-z192-x192.json","offset":{"x":192,"y":20,"z":192},"requirements":{"minecraft:cobbled_deepslate":32,"minecraft:stone_bricks":58},"sha256":"bb94f7bf0cf282e4a68b844c8ffb2047fa9bc1008c2d7f179419bd92eb367fd2","size":{"x":32,"y":1,"z":32}},{"blockCount":79,"bytes":1394,"file":"chunks/y020-z192-x224.json","offset":{"x":224,"y":20,"z":192},"requirements":{"minecraft:cobbled_deepslate":21,"minecraft:sandstone":3,"minecraft:stone_bricks":55},"sha256":"86a4279ad70cb56e568306eeb0dc52d3c631bd36e6c042cb65ee5e9afe690058","size":{"x":32,"y":1,"z":32}},{"blockCount":32,"bytes":1588,"file":"chunks/y020-z192-x256.json","offset":{"x":256,"y":20,"z":192},"requirements":{"minecraft:cobbled_deepslate":19,"minecraft:stone_bricks":13},"sha256":"a661a4d3c78c22a66b51121d25bedaf1f610d94f8baae72340748de98f0fd627","size":{"x":32,"y":1,"z":32}},{"blockCount":6,"bytes":871,"file":"chunks/y020-z192-x288.json","offset":{"x":288,"y":20,"z":192},"requirements":{"minecraft:cobbled_deepslate":5,"minecraft:stone_bricks":1},"sha256":"502ea67fdf325441dc2311b037eccdb0e2c0f71dd041fc7d1852efc5d15ede92","size":{"x":32,"y":1,"z":32}},{"blockCount":7,"bytes":792,"file":"chunks/y020-z224-x224.json","offset":{"x":224,"y":20,"z":224},"requirements":{"minecraft:cobbled_deepslate":1,"minecraft:stone_bricks":6},"sha256":"48a2dafb0ffe3bedb8d068afb6f1071afdf555ee8b4ed79b01d088ccbc24eea0","size":{"x":32,"y":1,"z":15}},{"blockCount":1,"bytes":640,"file":"chunks/y020-z224-x256.json","offset":{"x":256,"y":20,"z":224},"requirements":{"minecraft:sandstone":1},"sha256":"1db51074269a4246cd0b540cface8f521ad84351df15387be5c1106aec1ea63f","size":{"x":32,"y":1,"z":15}},{"blockCount":24,"bytes":952,"file":"chunks/y021-z000-x320.json","offset":{"x":320,"y":21,"z":0},"requirements":{"minecraft:sandstone":24},"sha256":"15ce49d80af5f99c7e4472ee2c9f699c118ed33254cff87eb8a02ce8e41956d2","size":{"x":32,"y":1,"z":32}},{"blockCount":34,"bytes":746,"file":"chunks/y021-z000-x352.json","offset":{"x":352,"y":21,"z":0},"requirements":{"minecraft:sandstone":32,"minecraft:stone_bricks":2},"sha256":"83d19d3d816ecfe378ffe374496c8805f1ff7b04e6e9855088f3ed9ad584e052","size":{"x":32,"y":1,"z":32}},{"blockCount":86,"bytes":2506,"file":"chunks/y021-z000-x384.json","offset":{"x":384,"y":21,"z":0},"requirements":{"minecraft:sandstone":9,"minecraft:stone_bricks":77},"sha256":"c7eded0bb7bbe423c7e5adf9b3ead64568be830354a2425575219c21cd0c75fc","size":{"x":32,"y":1,"z":32}},{"blockCount":60,"bytes":2564,"file":"chunks/y021-z032-x320.json","offset":{"x":320,"y":21,"z":32},"requirements":{"minecraft:bricks":21,"minecraft:glass":8,"minecraft:sandstone":13,"minecraft:spruce_planks":18},"sha256":"4498927cc5425a053e32f53ac238d235d5035bd4797bdf94f18a6178101b7d63","size":{"x":32,"y":1,"z":32}},{"blockCount":51,"bytes":2152,"file":"chunks/y021-z032-x352.json","offset":{"x":352,"y":21,"z":32},"requirements":{"minecraft:bricks":6,"minecraft:glass":16,"minecraft:sandstone":5,"minecraft:spruce_planks":24},"sha256":"cb080f6a6e6ca0ce6bde37f82c679e2750410396d29c6876c703bb68d282ee67","size":{"x":32,"y":1,"z":32}},{"blockCount":130,"bytes":3864,"file":"chunks/y021-z032-x384.json","offset":{"x":384,"y":21,"z":32},"requirements":{"minecraft:bricks":15,"minecraft:sandstone":11,"minecraft:spruce_planks":6,"minecraft:stone_bricks":98},"sha256":"1b72f96c829d07bd1d1d163a3ca2898053adb91d5110af603c4883a6db2d0b37","size":{"x":32,"y":1,"z":32}},{"blockCount":7,"bytes":738,"file":"chunks/y021-z064-x032.json","offset":{"x":32,"y":21,"z":64},"requirements":{"minecraft:stone_bricks":7},"sha256":"af4941af344be207c3d500bda1ddbd538aff994e9de32b6b90d23f3b48214e87","size":{"x":32,"y":1,"z":32}},{"blockCount":55,"bytes":1142,"file":"chunks/y021-z064-x064.json","offset":{"x":64,"y":21,"z":64},"requirements":{"minecraft:stone_bricks":55},"sha256":"f0c5182bfb52fc4a26f7784ef4786e46ec47641dd3ee4ab8496422d95d96e0fe","size":{"x":32,"y":1,"z":32}},{"blockCount":79,"bytes":2191,"file":"chunks/y021-z064-x096.json","offset":{"x":96,"y":21,"z":64},"requirements":{"minecraft:stone_bricks":79},"sha256":"1b0fc044b551ae4a944f9f4e30d4fc7aabc9dc065221c0cd06da1fc14a5e775e","size":{"x":32,"y":1,"z":32}},{"blockCount":54,"bytes":1814,"file":"chunks/y021-z064-x128.json","offset":{"x":128,"y":21,"z":64},"requirements":{"minecraft:stone_bricks":54},"sha256":"e196f36fa13559d253cf3229579745b03843e428177681e3d774e0a73141b199","size":{"x":32,"y":1,"z":32}},{"blockCount":52,"bytes":1816,"file":"chunks/y021-z064-x320.json","offset":{"x":320,"y":21,"z":64},"requirements":{"minecraft:bricks":9,"minecraft:sandstone":38,"minecraft:spruce_planks":5},"sha256":"1b15f82d413f64713364b099794a9a9d7c909ac69bf42e6e2e93e985d846c75d","size":{"x":32,"y":1,"z":32}},{"blockCount":53,"bytes":1354,"file":"chunks/y021-z064-x352.json","offset":{"x":352,"y":21,"z":64},"requirements":{"minecraft:bricks":6,"minecraft:sandstone":37,"minecraft:spruce_planks":8,"minecraft:stone_bricks":2},"sha256":"3009085fc99bab0e154cfa5462ce1fddd916e2abf2d45787126ec56746cd1ee3","size":{"x":32,"y":1,"z":32}},{"blockCount":73,"bytes":1895,"file":"chunks/y021-z064-x384.json","offset":{"x":384,"y":21,"z":64},"requirements":{"minecraft:bricks":3,"minecraft:sandstone":20,"minecraft:spruce_planks":1,"minecraft:stone_bricks":49},"sha256":"9cc7a699a169e88449cee07346797eedf78fbc752ea5c39380c240ee354232cc","size":{"x":32,"y":1,"z":32}},{"blockCount":96,"bytes":2799,"file":"chunks/y021-z096-x032.json","offset":{"x":32,"y":21,"z":96},"requirements":{"minecraft:stone_bricks":96},"sha256":"4e9382cb6735596c0790c79778829c139f6b75ecf1219b461c1fe101648d997f","size":{"x":32,"y":1,"z":32}},{"blockCount":282,"bytes":5668,"file":"chunks/y021-z096-x064.json","offset":{"x":64,"y":21,"z":96},"requirements":{"minecraft:stone_bricks":282},"sha256":"4688ccb8361ecf8275402ebc132f1c6b4520993b0bc4644d795ac4dd23482a5f","size":{"x":32,"y":1,"z":32}},{"blockCount":128,"bytes":2717,"file":"chunks/y021-z096-x096.json","offset":{"x":96,"y":21,"z":96},"requirements":{"minecraft:stone_bricks":128},"sha256":"cd198b50306d768082e69a022850a197e2a316ce9674c3057b3b4c0b7dd3668d","size":{"x":32,"y":1,"z":32}},{"blockCount":198,"bytes":3897,"file":"chunks/y021-z096-x128.json","offset":{"x":128,"y":21,"z":96},"requirements":{"minecraft:stone_bricks":198},"sha256":"655887e258a7cd4a976a53b46969ced48fdf8b3268d72749af9fc9b07fb31d41","size":{"x":32,"y":1,"z":32}},{"blockCount":32,"bytes":624,"file":"chunks/y021-z096-x160.json","offset":{"x":160,"y":21,"z":96},"requirements":{"minecraft:stone_bricks":32},"sha256":"cca668ffecda7999b708c240fb03d911af13dadbf88ce9ee76919b9996440bcf","size":{"x":32,"y":1,"z":32}},{"blockCount":36,"bytes":1511,"file":"chunks/y021-z096-x192.json","offset":{"x":192,"y":21,"z":96},"requirements":{"minecraft:bricks":25,"minecraft:stone_bricks":11},"sha256":"42cba27fc6e1b58b976e1a5c7c59a8d9102dad7e31a952e22b39ffc1f56453a7","size":{"x":32,"y":1,"z":32}},{"blockCount":18,"bytes":1291,"file":"chunks/y021-z096-x224.json","offset":{"x":224,"y":21,"z":96},"requirements":{"minecraft:bricks":18},"sha256":"2429fc33543ec37744ac151f207874264aa57aada1e0ee8afb2a060617debc40","size":{"x":32,"y":1,"z":32}},{"blockCount":230,"bytes":2263,"file":"chunks/y021-z096-x288.json","offset":{"x":288,"y":21,"z":96},"requirements":{"minecraft:stone_bricks":230},"sha256":"a22e9ac5677904c412108d305b7df9283dc7743745fa9932f512de7b96cc0c0c","size":{"x":32,"y":1,"z":32}},{"blockCount":158,"bytes":921,"file":"chunks/y021-z096-x320.json","offset":{"x":320,"y":21,"z":96},"requirements":{"minecraft:glass":1,"minecraft:stone_bricks":157},"sha256":"157f66ed787d86dc81c30631eb750fcbebc9e97ced37797883d60a3a73aaad64","size":{"x":32,"y":1,"z":32}},{"blockCount":79,"bytes":2312,"file":"chunks/y021-z096-x352.json","offset":{"x":352,"y":21,"z":96},"requirements":{"minecraft:glass":1,"minecraft:stone_bricks":78},"sha256":"45a9651b0caf60eb1784e6308c18402606318e70212a03ad5fb10b7b33d41340","size":{"x":32,"y":1,"z":32}},{"blockCount":6,"bytes":759,"file":"chunks/y021-z096-x384.json","offset":{"x":384,"y":21,"z":96},"requirements":{"minecraft:stone_bricks":6},"sha256":"6049f86b5618a2e8e2f4d1f0bf9253e818078c4ec055bdd7acba9c4c9442f5ec","size":{"x":32,"y":1,"z":32}},{"blockCount":168,"bytes":3663,"file":"chunks/y021-z128-x032.json","offset":{"x":32,"y":21,"z":128},"requirements":{"minecraft:stone_bricks":168},"sha256":"110915b70d54306789caa05649d917043f0bb9b2973207e97ec9817c5fbe33cb","size":{"x":32,"y":1,"z":32}},{"blockCount":59,"bytes":1719,"file":"chunks/y021-z128-x064.json","offset":{"x":64,"y":21,"z":128},"requirements":{"minecraft:stone_bricks":59},"sha256":"cfcb4d0c4d99cb973a6e30829f08c14acda193ede02d17bad5321e12d84a1a24","size":{"x":32,"y":1,"z":32}},{"blockCount":26,"bytes":990,"file":"chunks/y021-z128-x096.json","offset":{"x":96,"y":21,"z":128},"requirements":{"minecraft:stone_bricks":26},"sha256":"6e6c0f3e81245427515e99e858ba3b053eaa27459b12195d069ab5cd99d384ab","size":{"x":32,"y":1,"z":32}},{"blockCount":116,"bytes":2699,"file":"chunks/y021-z128-x128.json","offset":{"x":128,"y":21,"z":128},"requirements":{"minecraft:glass":4,"minecraft:polished_diorite":2,"minecraft:stone_bricks":110},"sha256":"c72e2575c2401c38cc0bea22a4eec8681f1a7e8780b9f1153254d40e2dacf89d","size":{"x":32,"y":1,"z":32}},{"blockCount":294,"bytes":2762,"file":"chunks/y021-z128-x160.json","offset":{"x":160,"y":21,"z":128},"requirements":{"minecraft:glass":20,"minecraft:stone_bricks":274},"sha256":"4a5ddb338c82978ec58ee3c4dd06f4fb4ed7add036fa36a619d387a9ee92d3df","size":{"x":32,"y":1,"z":32}},{"blockCount":190,"bytes":2889,"file":"chunks/y021-z128-x192.json","offset":{"x":192,"y":21,"z":128},"requirements":{"minecraft:bricks":25,"minecraft:stone_bricks":165},"sha256":"65c5c0b6fcaf34b4f74f73cac3b784c7b11b05cd447085c399b2f3b8fd80b272","size":{"x":32,"y":1,"z":32}},{"blockCount":39,"bytes":2016,"file":"chunks/y021-z128-x224.json","offset":{"x":224,"y":21,"z":128},"requirements":{"minecraft:bricks":38,"minecraft:stone_bricks":1},"sha256":"edd7768f493a2713a427fc84029223e89a3a776cc67973bc98e824939c65b687","size":{"x":32,"y":1,"z":32}},{"blockCount":3,"bytes":722,"file":"chunks/y021-z128-x256.json","offset":{"x":256,"y":21,"z":128},"requirements":{"minecraft:stone_bricks":3},"sha256":"764cfbd71911f76266445536d0de6236d8053821a1a989c1a3d67552e53db68f","size":{"x":32,"y":1,"z":32}},{"blockCount":184,"bytes":3562,"file":"chunks/y021-z128-x288.json","offset":{"x":288,"y":21,"z":128},"requirements":{"minecraft:stone_bricks":184},"sha256":"ead51623372b56c3abbe3e47037790af6f425ed74ae4d7fc1b837906372130b1","size":{"x":32,"y":1,"z":32}},{"blockCount":124,"bytes":2312,"file":"chunks/y021-z128-x320.json","offset":{"x":320,"y":21,"z":128},"requirements":{"minecraft:stone_bricks":124},"sha256":"5615d780bcd81ab0bf42f1f4055181909433b421bd80c4aca689e025f66e2193","size":{"x":32,"y":1,"z":32}},{"blockCount":160,"bytes":3068,"file":"chunks/y021-z128-x352.json","offset":{"x":352,"y":21,"z":128},"requirements":{"minecraft:stone_bricks":160},"sha256":"edebb728e25131f65f3ebfca9a999ee7d9a81143e579e470cd16c2057c85084a","size":{"x":32,"y":1,"z":32}},{"blockCount":12,"bytes":837,"file":"chunks/y021-z128-x384.json","offset":{"x":384,"y":21,"z":128},"requirements":{"minecraft:stone_bricks":12},"sha256":"e51d390c20a372f546643ae5a9770dc4649d9e0113a8cb8bc63fffa0731babbe","size":{"x":32,"y":1,"z":32}},{"blockCount":64,"bytes":2152,"file":"chunks/y021-z160-x032.json","offset":{"x":32,"y":21,"z":160},"requirements":{"minecraft:stone_bricks":64},"sha256":"04505b3d46f2fde3dcbb019ffd2f9fac4849930a34fc2e7b5070d35aa22425eb","size":{"x":32,"y":1,"z":32}},{"blockCount":286,"bytes":5310,"file":"chunks/y021-z160-x064.json","offset":{"x":64,"y":21,"z":160},"requirements":{"minecraft:stone_bricks":286},"sha256":"5c8d39c148e119aa514f34d7591c4e76f27d4a5ef8c454560467b2ada72cb04c","size":{"x":32,"y":1,"z":32}},{"blockCount":119,"bytes":2682,"file":"chunks/y021-z160-x096.json","offset":{"x":96,"y":21,"z":160},"requirements":{"minecraft:stone_bricks":119},"sha256":"f0381d2ec34f06cacadabebff4cc5fa8f1f1240520ee2dbdf7767a6d23beb430","size":{"x":32,"y":1,"z":32}},{"blockCount":156,"bytes":3581,"file":"chunks/y021-z160-x128.json","offset":{"x":128,"y":21,"z":160},"requirements":{"minecraft:stone_bricks":156},"sha256":"ef048bbda2fd8af8e2b110ebaf25e3bf55c236e40349d68e48374fc0bb0f478f","size":{"x":32,"y":1,"z":32}},{"blockCount":54,"bytes":2108,"file":"chunks/y021-z160-x160.json","offset":{"x":160,"y":21,"z":160},"requirements":{"minecraft:cobbled_deepslate":26,"minecraft:stone_bricks":28},"sha256":"19f4b5db29fb205dd4c16993a9cdd52f72aca9fe64c1d98245660a8bc34a1036","size":{"x":32,"y":1,"z":32}},{"blockCount":238,"bytes":2538,"file":"chunks/y021-z160-x192.json","offset":{"x":192,"y":21,"z":160},"requirements":{"minecraft:bricks":5,"minecraft:stone_bricks":233},"sha256":"b3edcfc5a0b4dcb0840ba4b7599d1d4c369250da2edbf9e621ea4459ff7ec8d6","size":{"x":32,"y":1,"z":32}},{"blockCount":49,"bytes":1422,"file":"chunks/y021-z160-x224.json","offset":{"x":224,"y":21,"z":160},"requirements":{"minecraft:bricks":5,"minecraft:sandstone":1,"minecraft:stone_bricks":43},"sha256":"a040ff225422b6d69d5529e2c698c1461543e582867f28ac2012f2fe89f13cb2","size":{"x":32,"y":1,"z":32}},{"blockCount":220,"bytes":1483,"file":"chunks/y021-z160-x256.json","offset":{"x":256,"y":21,"z":160},"requirements":{"minecraft:sandstone":220},"sha256":"18138539144b20f347e40d73aca1b5340c318ad03b1456c600aa2d806618e2c3","size":{"x":32,"y":1,"z":32}},{"blockCount":239,"bytes":2496,"file":"chunks/y021-z160-x288.json","offset":{"x":288,"y":21,"z":160},"requirements":{"minecraft:sandstone":44,"minecraft:stone_bricks":195},"sha256":"9250624ea9367a891ab78ef24aebb59e3c14beaaeeceff6381c12b2ecd4ce2b0","size":{"x":32,"y":1,"z":32}},{"blockCount":158,"bytes":845,"file":"chunks/y021-z160-x320.json","offset":{"x":320,"y":21,"z":160},"requirements":{"minecraft:glass":1,"minecraft:stone_bricks":157},"sha256":"2e070d1539e3bdcfd0de63086ee9c7003db76be163834e2a88615e9a5f833024","size":{"x":32,"y":1,"z":32}},{"blockCount":48,"bytes":1927,"file":"chunks/y021-z160-x352.json","offset":{"x":352,"y":21,"z":160},"requirements":{"minecraft:glass":1,"minecraft:stone_bricks":47},"sha256":"8311a0a56d31d9235ce1e4b63598d9d94b2eb7cb716921e38c8cf0e5162b2be3","size":{"x":32,"y":1,"z":32}},{"blockCount":62,"bytes":1843,"file":"chunks/y021-z192-x096.json","offset":{"x":96,"y":21,"z":192},"requirements":{"minecraft:stone_bricks":62},"sha256":"be46876342e166420d71b7a4a4ba46495fefb2470247e0b2f083dc8ad97f397e","size":{"x":32,"y":1,"z":32}},{"blockCount":29,"bytes":1308,"file":"chunks/y021-z192-x128.json","offset":{"x":128,"y":21,"z":192},"requirements":{"minecraft:stone_bricks":29},"sha256":"514ab2378d2d2626332f4bf69c2ed55accf99eab06ee6e5a9b12b5b9d1f79518","size":{"x":32,"y":1,"z":32}},{"blockCount":60,"bytes":1749,"file":"chunks/y021-z192-x160.json","offset":{"x":160,"y":21,"z":192},"requirements":{"minecraft:cobbled_deepslate":43,"minecraft:spruce_planks":1,"minecraft:stone_bricks":16},"sha256":"6b094a5b8c207aeadd227f437da9a505d8cc38b78973a6e0d1ec2dc40dc9df95","size":{"x":32,"y":1,"z":32}},{"blockCount":186,"bytes":1882,"file":"chunks/y021-z192-x192.json","offset":{"x":192,"y":21,"z":192},"requirements":{"minecraft:cobbled_deepslate":32,"minecraft:stone_bricks":154},"sha256":"f48110e06f616e622f2197cadf8172a4d73d15bab4ae23468494a525cc224176","size":{"x":32,"y":1,"z":32}},{"blockCount":74,"bytes":1278,"file":"chunks/y021-z192-x224.json","offset":{"x":224,"y":21,"z":192},"requirements":{"minecraft:bricks":1,"minecraft:cobbled_deepslate":20,"minecraft:stone_bricks":53},"sha256":"ffbdd60e5b5037c9fdc869030da0d611b98ccd5f626ce2de16385f182bbcef35","size":{"x":32,"y":1,"z":32}},{"blockCount":32,"bytes":1568,"file":"chunks/y021-z192-x256.json","offset":{"x":256,"y":21,"z":192},"requirements":{"minecraft:cobbled_deepslate":23,"minecraft:stone_bricks":9},"sha256":"3f4e4c62aaa534d343435ebb0a8d74c8ec5c2c136460282f2220fa59b5f9c5dc","size":{"x":32,"y":1,"z":32}},{"blockCount":6,"bytes":871,"file":"chunks/y021-z192-x288.json","offset":{"x":288,"y":21,"z":192},"requirements":{"minecraft:cobbled_deepslate":3,"minecraft:stone_bricks":3},"sha256":"36bd37f2e6a1b82aea20bafe683997154eb62680cb339418020e26d6f3b9d57c","size":{"x":32,"y":1,"z":32}},{"blockCount":13,"bytes":785,"file":"chunks/y021-z224-x224.json","offset":{"x":224,"y":21,"z":224},"requirements":{"minecraft:sandstone":1,"minecraft:stone_bricks":12},"sha256":"fae78744d6c32a0110988cca7054b39a0c8aaed55116be8f10ec998acc22a583","size":{"x":32,"y":1,"z":15}},{"blockCount":1,"bytes":648,"file":"chunks/y021-z224-x256.json","offset":{"x":256,"y":21,"z":224},"requirements":{"minecraft:cobbled_deepslate":1},"sha256":"444ef4b8e1a79269cca0b31d012751467393d0ad464263172785b0a744aecb87","size":{"x":32,"y":1,"z":15}},{"blockCount":24,"bytes":952,"file":"chunks/y022-z000-x320.json","offset":{"x":320,"y":22,"z":0},"requirements":{"minecraft:sandstone":24},"sha256":"dc905e83055c6848b8f1233699bcf864bf039a0a1590dc3a9662a7f59eb803f7","size":{"x":32,"y":1,"z":32}},{"blockCount":37,"bytes":862,"file":"chunks/y022-z000-x352.json","offset":{"x":352,"y":22,"z":0},"requirements":{"minecraft:sandstone":32,"minecraft:stone_bricks":5},"sha256":"815d3775e055c224ebb69db0065543015d48890889497159418d3077611356db","size":{"x":32,"y":1,"z":32}},{"blockCount":80,"bytes":2477,"file":"chunks/y022-z000-x384.json","offset":{"x":384,"y":22,"z":0},"requirements":{"minecraft:cobbled_deepslate":21,"minecraft:glass":1,"minecraft:oak_planks":1,"minecraft:sandstone":8,"minecraft:stone_bricks":49},"sha256":"5244a30b8bdd056335e57c3ed26e084c4fbd2dd3a582616d563106251e01cdcb","size":{"x":32,"y":1,"z":32}},{"blockCount":64,"bytes":2697,"file":"chunks/y022-z032-x320.json","offset":{"x":320,"y":22,"z":32},"requirements":{"minecraft:bricks":21,"minecraft:glass":8,"minecraft:sandstone":13,"minecraft:spruce_planks":22},"sha256":"020cca4b10102a50d0580062b9d38e0a3842dca94b98170f223613d1ef17aa28","size":{"x":32,"y":1,"z":32}},{"blockCount":59,"bytes":2455,"file":"chunks/y022-z032-x352.json","offset":{"x":352,"y":22,"z":32},"requirements":{"minecraft:bricks":6,"minecraft:glass":16,"minecraft:sandstone":5,"minecraft:spruce_planks":32},"sha256":"0cdcfcf962590b6706f5fa89639ec26cc05455b80c664160b386a8a4f4c32639","size":{"x":32,"y":1,"z":32}},{"blockCount":122,"bytes":3673,"file":"chunks/y022-z032-x384.json","offset":{"x":384,"y":22,"z":32},"requirements":{"minecraft:bricks":14,"minecraft:sandstone":11,"minecraft:spruce_planks":6,"minecraft:stone_bricks":91},"sha256":"83c28a0b5700c6de6af55cff3434315b86b9470d076c53289617d4189ac69948","size":{"x":32,"y":1,"z":32}},{"blockCount":7,"bytes":738,"file":"chunks/y022-z064-x032.json","offset":{"x":32,"y":22,"z":64},"requirements":{"minecraft:stone_bricks":7},"sha256":"abc724cc515962e039cdc4c8091cea8729ff8080242ba0f1a67f46e476cf2aa9","size":{"x":32,"y":1,"z":32}},{"blockCount":59,"bytes":1142,"file":"chunks/y022-z064-x064.json","offset":{"x":64,"y":22,"z":64},"requirements":{"minecraft:stone_bricks":59},"sha256":"ee3ac8e4ce56ad86ff7bf957c3924591a0ce76b6e1e2d0039ddec23261f7c97b","size":{"x":32,"y":1,"z":32}},{"blockCount":79,"bytes":2191,"file":"chunks/y022-z064-x096.json","offset":{"x":96,"y":22,"z":64},"requirements":{"minecraft:stone_bricks":79},"sha256":"ac6358859a88f78e7a1856c207f3e8773d58feb26a08c510d2ca6452d70f98ff","size":{"x":32,"y":1,"z":32}},{"blockCount":54,"bytes":1814,"file":"chunks/y022-z064-x128.json","offset":{"x":128,"y":22,"z":64},"requirements":{"minecraft:stone_bricks":54},"sha256":"4b11f28c109c861f60c36d7baa0975b3e8bf0587880e65dde59065959ac1ca12","size":{"x":32,"y":1,"z":32}},{"blockCount":56,"bytes":1949,"file":"chunks/y022-z064-x320.json","offset":{"x":320,"y":22,"z":64},"requirements":{"minecraft:bricks":9,"minecraft:sandstone":38,"minecraft:spruce_planks":9},"sha256":"16a5030a3b5eae9866960086fa1959e53ea8f33126c0434bbf0341f55b3af5e0","size":{"x":32,"y":1,"z":32}},{"blockCount":63,"bytes":1736,"file":"chunks/y022-z064-x352.json","offset":{"x":352,"y":22,"z":64},"requirements":{"minecraft:bricks":6,"minecraft:sandstone":37,"minecraft:spruce_planks":16,"minecraft:stone_bricks":4},"sha256":"82650e7c4d8202a4461f84973ec91e6bedda9487535db7ee0c3c118a2da55981","size":{"x":32,"y":1,"z":32}},{"blockCount":55,"bytes":1586,"file":"chunks/y022-z064-x384.json","offset":{"x":384,"y":22,"z":64},"requirements":{"minecraft:bricks":2,"minecraft:sandstone":19,"minecraft:spruce_planks":1,"minecraft:stone_bricks":33},"sha256":"c90a3697746e240d6f5f0005a4e978ff755b37338d77538ba9eed6ebccec2d27","size":{"x":32,"y":1,"z":32}},{"blockCount":98,"bytes":2761,"file":"chunks/y022-z096-x032.json","offset":{"x":32,"y":22,"z":96},"requirements":{"minecraft:stone_bricks":98},"sha256":"365313d7384719ea363894ea4b785f284b16a86815cfee18de5ae666c43ea023","size":{"x":32,"y":1,"z":32}},{"blockCount":326,"bytes":5514,"file":"chunks/y022-z096-x064.json","offset":{"x":64,"y":22,"z":96},"requirements":{"minecraft:stone_bricks":326},"sha256":"7fa1606f62b491b64725bc36b8627994991f0145dd1282ae675a398124710992","size":{"x":32,"y":1,"z":32}},{"blockCount":122,"bytes":2640,"file":"chunks/y022-z096-x096.json","offset":{"x":96,"y":22,"z":96},"requirements":{"minecraft:stone_bricks":122},"sha256":"320523898fa818f1cb956e2f0b1140118522536a41426c123d1b01dc2fdc63ed","size":{"x":32,"y":1,"z":32}},{"blockCount":190,"bytes":3745,"file":"chunks/y022-z096-x128.json","offset":{"x":128,"y":22,"z":96},"requirements":{"minecraft:stone_bricks":190},"sha256":"d8e1afa4315fe76a904e6379d83dc87d597cd2196557d9dd24c9a60bbcc65c75","size":{"x":32,"y":1,"z":32}},{"blockCount":32,"bytes":624,"file":"chunks/y022-z096-x160.json","offset":{"x":160,"y":22,"z":96},"requirements":{"minecraft:stone_bricks":32},"sha256":"98ba9f31c7002d8ccc5ead66a0d4893bba773aa86c7fa1ec247524276cbe997a","size":{"x":32,"y":1,"z":32}},{"blockCount":31,"bytes":1322,"file":"chunks/y022-z096-x192.json","offset":{"x":192,"y":22,"z":96},"requirements":{"minecraft:bricks":20,"minecraft:stone_bricks":11},"sha256":"5cb64e348cf42f9a736794e7a6f17439092546edc448a9cfd8cc5180a8876ded","size":{"x":32,"y":1,"z":32}},{"blockCount":27,"bytes":1548,"file":"chunks/y022-z096-x224.json","offset":{"x":224,"y":22,"z":96},"requirements":{"minecraft:bricks":23,"minecraft:stone_bricks":4},"sha256":"ec52b5616b3404529b93a4fe22d2c66fe89f4f4d72a3e55f40f112eefa25a8ac","size":{"x":32,"y":1,"z":32}},{"blockCount":230,"bytes":1541,"file":"chunks/y022-z096-x288.json","offset":{"x":288,"y":22,"z":96},"requirements":{"minecraft:stone_bricks":230},"sha256":"900ce7f80daf35e62bd5a0b326bd7cc5f3448c019bf91310dfc64b7d985132c0","size":{"x":32,"y":1,"z":32}},{"blockCount":162,"bytes":1076,"file":"chunks/y022-z096-x320.json","offset":{"x":320,"y":22,"z":96},"requirements":{"minecraft:glass":3,"minecraft:stone_bricks":159},"sha256":"ab91c7bd7592318c21b3cce601b880049c352f6c1c71108fe73a209636eb1fcd","size":{"x":32,"y":1,"z":32}},{"blockCount":73,"bytes":1345,"file":"chunks/y022-z096-x352.json","offset":{"x":352,"y":22,"z":96},"requirements":{"minecraft:glass":3,"minecraft:stone_bricks":70},"sha256":"76ae85c9a4b1994d90be76dcb25921fb59d037884386fe0bf2ff5f0daa1e4b36","size":{"x":32,"y":1,"z":32}},{"blockCount":6,"bytes":759,"file":"chunks/y022-z096-x384.json","offset":{"x":384,"y":22,"z":96},"requirements":{"minecraft:stone_bricks":6},"sha256":"140273c0602cbf25fd6064bd34a582265dfe15dd9db5775b57d0913ed074e6e9","size":{"x":32,"y":1,"z":32}},{"blockCount":178,"bytes":3623,"file":"chunks/y022-z128-x032.json","offset":{"x":32,"y":22,"z":128},"requirements":{"minecraft:stone_bricks":178},"sha256":"26ddb01ef5b148e33401421779bb22a1be6e7a557bc48e7c49f43d2ad01ef427","size":{"x":32,"y":1,"z":32}},{"blockCount":55,"bytes":1565,"file":"chunks/y022-z128-x064.json","offset":{"x":64,"y":22,"z":128},"requirements":{"minecraft:stone_bricks":55},"sha256":"f4163062d161d290d1021111fe98a029bdad281387e2875b9765796de8fc3982","size":{"x":32,"y":1,"z":32}},{"blockCount":22,"bytes":913,"file":"chunks/y022-z128-x096.json","offset":{"x":96,"y":22,"z":128},"requirements":{"minecraft:stone_bricks":22},"sha256":"e79d2ac7297419716b198e6668dbdc8379cbd4b54646be9a82d31dfcad18e602","size":{"x":32,"y":1,"z":32}},{"blockCount":105,"bytes":2471,"file":"chunks/y022-z128-x128.json","offset":{"x":128,"y":22,"z":128},"requirements":{"minecraft:glass":2,"minecraft:polished_diorite":2,"minecraft:stone_bricks":101},"sha256":"be16b4e174cd95cbf359a04c642990132c076174b309fbf0672a196e13bbe245","size":{"x":32,"y":1,"z":32}},{"blockCount":321,"bytes":2539,"file":"chunks/y022-z128-x160.json","offset":{"x":160,"y":22,"z":128},"requirements":{"minecraft:glass":12,"minecraft:stone_bricks":309},"sha256":"c96edd9ecaecf37274b7f041605c2ab544d67678c19f14d88736eb4458dd7163","size":{"x":32,"y":1,"z":32}},{"blockCount":239,"bytes":2437,"file":"chunks/y022-z128-x192.json","offset":{"x":192,"y":22,"z":128},"requirements":{"minecraft:bricks":22,"minecraft:glass":12,"minecraft:stone_bricks":205},"sha256":"61bdc4597303b652e0a84ef92bccadc35199250695f140e98607421d7edf0945","size":{"x":32,"y":1,"z":32}},{"blockCount":35,"bytes":1941,"file":"chunks/y022-z128-x224.json","offset":{"x":224,"y":22,"z":128},"requirements":{"minecraft:bricks":33,"minecraft:stone_bricks":2},"sha256":"71ace34a8c4b85fa106632306b4314f9b45d2dfefaf69d1464902d04b7df0f15","size":{"x":32,"y":1,"z":32}},{"blockCount":160,"bytes":1852,"file":"chunks/y022-z128-x288.json","offset":{"x":288,"y":22,"z":128},"requirements":{"minecraft:stone_bricks":160},"sha256":"819cb669c2f519940591b6ac5e5e42ddde05ed738e08496e79e4c1b91d2d97f2","size":{"x":32,"y":1,"z":32}}],"schema":1}
