{"entries":[{"blockCount":29,"bytes":1228,"file":"chunks/y022-z128-x320.json","offset":{"x":320,"y":22,"z":128},"requirements":{"minecraft:stone_bricks":29},"sha256":"3de9a85b85b5f78db7005ec83a3135e3c19f3e99afd491c5dbe3c8c63c351bd4","size":{"x":32,"y":1,"z":32}},{"blockCount":160,"bytes":1852,"file":"chunks/y022-z128-x352.json","offset":{"x":352,"y":22,"z":128},"requirements":{"minecraft:stone_bricks":160},"sha256":"59cd12b9d16c3c22cfb6f8c8aac98e982aad605f7fc47ebb8807d3c7280d8eea","size":{"x":32,"y":1,"z":32}},{"blockCount":12,"bytes":837,"file":"chunks/y022-z128-x384.json","offset":{"x":384,"y":22,"z":128},"requirements":{"minecraft:stone_bricks":12},"sha256":"e50adce97f9ee8dd8c82d5993cfbec2b5aa42ef1ebddd14c7b5977d3e2d3ebc7","size":{"x":32,"y":1,"z":32}},{"blockCount":64,"bytes":2152,"file":"chunks/y022-z160-x032.json","offset":{"x":32,"y":22,"z":160},"requirements":{"minecraft:stone_bricks":64},"sha256":"d6959c7f5b5cab494093f1fcc4a639fa58e16415c3d75f2bcd2efffefc5cb6f9","size":{"x":32,"y":1,"z":32}},{"blockCount":338,"bytes":5310,"file":"chunks/y022-z160-x064.json","offset":{"x":64,"y":22,"z":160},"requirements":{"minecraft:stone_bricks":338},"sha256":"0896aeba171823e1cf7852abe99b545076d11c6ebb0b12972431b4e9441ec271","size":{"x":32,"y":1,"z":32}},{"blockCount":117,"bytes":2682,"file":"chunks/y022-z160-x096.json","offset":{"x":96,"y":22,"z":160},"requirements":{"minecraft:stone_bricks":117},"sha256":"328f98d785f8e58d2d01f1703cc9b81d7d5903132adeea8e4cd8c9013e37cab8","size":{"x":32,"y":1,"z":32}},{"blockCount":154,"bytes":3581,"file":"chunks/y022-z160-x128.json","offset":{"x":128,"y":22,"z":160},"requirements":{"minecraft:stone_bricks":154},"sha256":"202e831a56eaf7f8a9ad9f6b167cb31ee9f1092af3177fa5fa8d7bce8c9a6def","size":{"x":32,"y":1,"z":32}},{"blockCount":26,"bytes":1624,"file":"chunks/y022-z160-x160.json","offset":{"x":160,"y":22,"z":160},"requirements":{"minecraft:cobbled_deepslate":26},"sha256":"37336f203c4b7375eae4a22d02a2497467c7b5bd3f0ee722fb89becbef29f39a","size":{"x":32,"y":1,"z":32}},{"blockCount":16,"bytes":1204,"file":"chunks/y022-z160-x192.json","offset":{"x":192,"y":22,"z":160},"requirements":{"minecraft:bricks":8,"minecraft:stone_bricks":8},"sha256":"b54aab69d86424f13aba25fba2a5b6686ddde16c6166e0597b954e712bfd4cee","size":{"x":32,"y":1,"z":32}},{"blockCount":46,"bytes":1578,"file":"chunks/y022-z160-x224.json","offset":{"x":224,"y":22,"z":160},"requirements":{"minecraft:bricks":9,"minecraft:cobbled_deepslate":1,"minecraft:stone_bricks":36},"sha256":"c3de6b99823119d4fc475116e4f2908dfd342781f48ec436b84e41fa43d847d9","size":{"x":32,"y":1,"z":32}},{"blockCount":195,"bytes":1269,"file":"chunks/y022-z160-x288.json","offset":{"x":288,"y":22,"z":160},"requirements":{"minecraft:stone_bricks":195},"sha256":"8530218ff11ab62e1e9bff3ac0b9e2593dfdbe0296c72ea73616647f51f7c5f4","size":{"x":32,"y":1,"z":32}},{"blockCount":162,"bytes":1076,"file":"chunks/y022-z160-x320.json","offset":{"x":320,"y":22,"z":160},"requirements":{"minecraft:glass":3,"minecraft:stone_bricks":159},"sha256":"e05aa310a468a5ed30bf16a00dbd1ce92e09f39d14b76e6887445ac7ba07e3cd","size":{"x":32,"y":1,"z":32}},{"blockCount":53,"bytes":1615,"file":"chunks/y022-z160-x352.json","offset":{"x":352,"y":22,"z":160},"requirements":{"minecraft:bricks":13,"minecraft:glass":3,"minecraft:stone_bricks":37},"sha256":"338304eada9ff04a3e58685322542a881f8dd7827c39bc32fdd4f491bbae612d","size":{"x":32,"y":1,"z":32}},{"blockCount":62,"bytes":1843,"file":"chunks/y022-z192-x096.json","offset":{"x":96,"y":22,"z":192},"requirements":{"minecraft:stone_bricks":62},"sha256":"3b1bfbd39472c462296607590d67f910eb110106c72a85c0154fecc6efbbbd35","size":{"x":32,"y":1,"z":32}},{"blockCount":29,"bytes":1308,"file":"chunks/y022-z192-x128.json","offset":{"x":128,"y":22,"z":192},"requirements":{"minecraft:stone_bricks":29},"sha256":"6c8fb7c08193e9ce06a6c44476ca98f68b49b20cf4635270eebf45701b1aa430","size":{"x":32,"y":1,"z":32}},{"blockCount":45,"bytes":1417,"file":"chunks/y022-z192-x160.json","offset":{"x":160,"y":22,"z":192},"requirements":{"minecraft:cobbled_deepslate":43,"minecraft:spruce_planks":2},"sha256":"48a75fe9dd2371849e4a9ef10caf4f2d7f452bbe077f85ef7998d40f27e6e618","size":{"x":32,"y":1,"z":32}},{"blockCount":40,"bytes":912,"file":"chunks/y022-z192-x192.json","offset":{"x":192,"y":22,"z":192},"requirements":{"minecraft:cobbled_deepslate":32,"minecraft:stone_bricks":8},"sha256":"a4713bc09f19451e3e6f2cb34200edb60e29d3674372f9f41a66c9ea8a76e951","size":{"x":32,"y":1,"z":32}},{"blockCount":70,"bytes":1431,"file":"chunks/y022-z192-x224.json","offset":{"x":224,"y":22,"z":192},"requirements":{"minecraft:cobbled_deepslate":19,"minecraft:sandstone":1,"minecraft:stone_bricks":50},"sha256":"639486ee2f10378596654ba77e89e7d618171e2f73d9485f745caaafc1f828c5","size":{"x":32,"y":1,"z":32}},{"blockCount":32,"bytes":1549,"file":"chunks/y022-z192-x256.json","offset":{"x":256,"y":22,"z":192},"requirements":{"minecraft:cobbled_deepslate":25,"minecraft:stone_bricks":7},"sha256":"9453dc477a12d6dc4ed03c80abeed630707451ea0dfccdfc4b5fd0ada5a1c32d","size":{"x":32,"y":1,"z":32}},{"blockCount":6,"bytes":844,"file":"chunks/y022-z192-x288.json","offset":{"x":288,"y":22,"z":192},"requirements":{"minecraft:cobbled_deepslate":6},"sha256":"2f78d9098d4b3e64611b758ba5226a0d38c6c8be2d62cc9e5c6d6dec35e61019","size":{"x":32,"y":1,"z":32}},{"blockCount":15,"bytes":869,"file":"chunks/y022-z224-x224.json","offset":{"x":224,"y":22,"z":224},"requirements":{"minecraft:cobbled_deepslate":1,"minecraft:stone_bricks":14},"sha256":"a94e3967da367ab008ba923700a80e8f7651ad327c94eadabd4d3b80a89c16ac","size":{"x":32,"y":1,"z":15}},{"blockCount":1,"bytes":640,"file":"chunks/y022-z224-x256.json","offset":{"x":256,"y":22,"z":224},"requirements":{"minecraft:sandstone":1},"sha256":"d5b903f6837010702a16465c8574d04135842e3fcdac7b9025f2246c6276f551","size":{"x":32,"y":1,"z":15}},{"blockCount":40,"bytes":992,"file":"chunks/y023-z000-x320.json","offset":{"x":320,"y":23,"z":0},"requirements":{"minecraft:sandstone":40},"sha256":"24fc2a013dbdfae0c530e8d03982898dac27a6d22f16b55c506dda0ee28ac969","size":{"x":32,"y":1,"z":32}},{"blockCount":70,"bytes":901,"file":"chunks/y023-z000-x352.json","offset":{"x":352,"y":23,"z":0},"requirements":{"minecraft:sandstone":64,"minecraft:stone_bricks":6},"sha256":"743d7097ec368afcaf7e70ac9c597901493705fd9be606a183a5d66c76cfff58","size":{"x":32,"y":1,"z":32}},{"blockCount":78,"bytes":2188,"file":"chunks/y023-z000-x384.json","offset":{"x":384,"y":23,"z":0},"requirements":{"minecraft:cobbled_deepslate":12,"minecraft:sandstone":12,"minecraft:stone_bricks":54},"sha256":"adefc5f2c4efbba18b8a60e7a8ba5af2e74dfec3048ac03418a8b330fb70d3c6","size":{"x":32,"y":1,"z":32}},{"blockCount":65,"bytes":2735,"file":"chunks/y023-z032-x320.json","offset":{"x":320,"y":23,"z":32},"requirements":{"minecraft:bricks":21,"minecraft:glass":8,"minecraft:sandstone":14,"minecraft:spruce_planks":22},"sha256":"d686c7bf0ed05179a35441d9285ef144c39b016aff2aedc317037c910a82b72d","size":{"x":32,"y":1,"z":32}},{"blockCount":60,"bytes":2494,"file":"chunks/y023-z032-x352.json","offset":{"x":352,"y":23,"z":32},"requirements":{"minecraft:bricks":6,"minecraft:glass":16,"minecraft:sandstone":6,"minecraft:spruce_planks":32},"sha256":"a3d2b02dfc23d4c09bfd32618bda3a0a162159602c467b22b7a7fa65bf6bef82","size":{"x":32,"y":1,"z":32}},{"blockCount":115,"bytes":3558,"file":"chunks/y023-z032-x384.json","offset":{"x":384,"y":23,"z":32},"requirements":{"minecraft:bricks":13,"minecraft:sandstone":11,"minecraft:spruce_planks":6,"minecraft:stone_bricks":85},"sha256":"e307b4e6472ba5f34021b8eb95f12af8b2fb924aa7773a7d5aae555b3c7484fc","size":{"x":32,"y":1,"z":32}},{"blockCount":7,"bytes":738,"file":"chunks/y023-z064-x032.json","offset":{"x":32,"y":23,"z":64},"requirements":{"minecraft:stone_bricks":7},"sha256":"0963f14b5f70566ab3962b52a42236027d2c37c6ada558a3f9238b48cb167f23","size":{"x":32,"y":1,"z":32}},{"blockCount":73,"bytes":1214,"file":"chunks/y023-z064-x064.json","offset":{"x":64,"y":23,"z":64},"requirements":{"minecraft:stone_bricks":73},"sha256":"ebe03e950f2e287df00a21b3a7a65a35514950f3e1d3807345d6a929539ea7b9","size":{"x":32,"y":1,"z":32}},{"blockCount":81,"bytes":2191,"file":"chunks/y023-z064-x096.json","offset":{"x":96,"y":23,"z":64},"requirements":{"minecraft:stone_bricks":81},"sha256":"62eccd0b8383dce15106c917caa615bec5a6d1f7393d2e082cf94a2ee96d3501","size":{"x":32,"y":1,"z":32}},{"blockCount":54,"bytes":1814,"file":"chunks/y023-z064-x128.json","offset":{"x":128,"y":23,"z":64},"requirements":{"minecraft:stone_bricks":54},"sha256":"af7bddbe2f8a15e882fe7fa704bc160d33d18430044bb5367fc0477c3643caf5","size":{"x":32,"y":1,"z":32}},{"blockCount":1,"bytes":643,"file":"chunks/y023-z064-x192.json","offset":{"x":192,"y":23,"z":64},"requirements":{"minecraft:stone_bricks":1},"sha256":"ecc71a94fd4b276e9f627b502b926c31dc51a227e2eac718a96317a77b49607b","size":{"x":32,"y":1,"z":32}},{"blockCount":71,"bytes":1969,"file":"chunks/y023-z064-x320.json","offset":{"x":320,"y":23,"z":64},"requirements":{"minecraft:bricks":8,"minecraft:sandstone":54,"minecraft:spruce_planks":9},"sha256":"3e34c6e74f6d5178acfdf95c4095dbde78e11618cef72ebc78d11cff3b26378a","size":{"x":32,"y":1,"z":32}},{"blockCount":95,"bytes":1736,"file":"chunks/y023-z064-x352.json","offset":{"x":352,"y":23,"z":64},"requirements":{"minecraft:bricks":6,"minecraft:sandstone":70,"minecraft:spruce_planks":16,"minecraft:stone_bricks":3},"sha256":"6ac87d89a87a47d2a3736cbdd371e06a5fd43ba90f4fc2b00ba953fc4eb13b71","size":{"x":32,"y":1,"z":32}},{"blockCount":57,"bytes":1549,"file":"chunks/y023-z064-x384.json","offset":{"x":384,"y":23,"z":64},"requirements":{"minecraft:bricks":1,"minecraft:sandstone":23,"minecraft:spruce_planks":1,"minecraft:stone_bricks":32},"sha256":"3d44c14e2e89563d7ef609253f01b2eeb5dd87716b7a8841d15c3515d2385594","size":{"x":32,"y":1,"z":32}},{"blockCount":94,"bytes":2685,"file":"chunks/y023-z096-x032.json","offset":{"x":32,"y":23,"z":96},"requirements":{"minecraft:stone_bricks":94},"sha256":"362f60e193f0a56aff63cbc8cfdecd544a36826e064574346a03599ccea804a7","size":{"x":32,"y":1,"z":32}},{"blockCount":430,"bytes":6117,"file":"chunks/y023-z096-x064.json","offset":{"x":64,"y":23,"z":96},"requirements":{"minecraft:stone_bricks":430},"sha256":"3eec1eb6e1dc51bfab2dcb5848420573eedb81400408a76e32a4f7e848ec468e","size":{"x":32,"y":1,"z":32}},{"blockCount":134,"bytes":2640,"file":"chunks/y023-z096-x096.json","offset":{"x":96,"y":23,"z":96},"requirements":{"minecraft:stone_bricks":134},"sha256":"755717427c3efcf6fb9d287df90244f569b2a238cef96e93395c6df03fde8557","size":{"x":32,"y":1,"z":32}},{"blockCount":200,"bytes":3821,"file":"chunks/y023-z096-x128.json","offset":{"x":128,"y":23,"z":96},"requirements":{"minecraft:stone_bricks":200},"sha256":"33546960d69630313040a51eec2b40ad00c641c6710a401f2e0c37e9c0d8c037","size":{"x":32,"y":1,"z":32}},{"blockCount":32,"bytes":624,"file":"chunks/y023-z096-x160.json","offset":{"x":160,"y":23,"z":96},"requirements":{"minecraft:stone_bricks":32},"sha256":"ddea0d9a983ad2a6f6828679344ce9cb5e190e7a1a9133340b435119000e8b8e","size":{"x":32,"y":1,"z":32}},{"blockCount":35,"bytes":1513,"file":"chunks/y023-z096-x192.json","offset":{"x":192,"y":23,"z":96},"requirements":{"minecraft:bricks":21,"minecraft:stone_bricks":14},"sha256":"ff866c6a92e02b63a488d69ea15fad8d55e136707561a349d62dc0ff7848fba2","size":{"x":32,"y":1,"z":32}},{"blockCount":15,"bytes":1205,"file":"chunks/y023-z096-x224.json","offset":{"x":224,"y":23,"z":96},"requirements":{"minecraft:bricks":13,"minecraft:stone_bricks":2},"sha256":"f05379a7a4ab01e454e8d70bca5f2ae58a90710fbeb11fa926542d15f4443902","size":{"x":32,"y":1,"z":32}},{"blockCount":163,"bytes":2038,"file":"chunks/y023-z096-x288.json","offset":{"x":288,"y":23,"z":96},"requirements":{"minecraft:stone_bricks":163},"sha256":"3b7b53609627c02fe4a6be17a1254de21da6e941c441a0f98f0abf811aa3d94a","size":{"x":32,"y":1,"z":32}},{"blockCount":135,"bytes":1172,"file":"chunks/y023-z096-x320.json","offset":{"x":320,"y":23,"z":96},"requirements":{"minecraft:glass":8,"minecraft:stone_bricks":127},"sha256":"a8292eef275f66f2e1c22fb258689c09c2edc5aacee795fc322cced078520612","size":{"x":32,"y":1,"z":32}},{"blockCount":75,"bytes":1811,"file":"chunks/y023-z096-x352.json","offset":{"x":352,"y":23,"z":96},"requirements":{"minecraft:glass":8,"minecraft:stone_bricks":67},"sha256":"f4917736d6c420d5bd96e708a8f961ef6b56d67b24241206db4fb6f1fcafcb33","size":{"x":32,"y":1,"z":32}},{"blockCount":6,"bytes":759,"file":"chunks/y023-z096-x384.json","offset":{"x":384,"y":23,"z":96},"requirements":{"minecraft:stone_bricks":6},"sha256":"c9600e0a0ea9557bdda8965a091a8d4b0d6191c4a76acd53e239ba1788406250","size":{"x":32,"y":1,"z":32}},{"blockCount":100,"bytes":1385,"file":"chunks/y023-z128-x000.json","offset":{"x":0,"y":23,"z":128},"requirements":{"minecraft:stone_bricks":100},"sha256":"86132c6984c44cd56614bcf1800d1e7ae05e006bdcaa57e03a6599426f629421","size":{"x":32,"y":1,"z":32}},{"blockCount":282,"bytes":4035,"file":"chunks/y023-z128-x032.json","offset":{"x":32,"y":23,"z":128},"requirements":{"minecraft:stone_bricks":282},"sha256":"1fb444746c984a053553b3041d8742f63f71e545160d9dea1349aa5eb899fb3a","size":{"x":32,"y":1,"z":32}},{"blockCount":71,"bytes":2102,"file":"chunks/y023-z128-x064.json","offset":{"x":64,"y":23,"z":128},"requirements":{"minecraft:stone_bricks":71},"sha256":"3e417b08ccb9a7d3de9a73a451e0b710607773d5b62c7c10c301863ab8bbf60b","size":{"x":32,"y":1,"z":32}},{"blockCount":28,"bytes":1066,"file":"chunks/y023-z128-x096.json","offset":{"x":96,"y":23,"z":128},"requirements":{"minecraft:stone_bricks":28},"sha256":"9ea4c556e0c45a3bc10e0dee308c82be6076b99397f208448dafa39ca6302892","size":{"x":32,"y":1,"z":32}},{"blockCount":125,"bytes":3040,"file":"chunks/y023-z128-x128.json","offset":{"x":128,"y":23,"z":128},"requirements":{"minecraft:glass":5,"minecraft:polished_diorite":5,"minecraft:stone_bricks":115},"sha256":"71fddc8722548ed51103a3e60e57436cd80aa021d59c14f2134a67c91a71d24a","size":{"x":32,"y":1,"z":32}},{"blockCount":159,"bytes":2626,"file":"chunks/y023-z128-x160.json","offset":{"x":160,"y":23,"z":128},"requirements":{"minecraft:glass":31,"minecraft:stone_bricks":128},"sha256":"4010ff2546a76a732344e3f6936f9f5ddaa5cb44118626ec94a383e2e76a7538","size":{"x":32,"y":1,"z":32}},{"blockCount":119,"bytes":3110,"file":"chunks/y023-z128-x192.json","offset":{"x":192,"y":23,"z":128},"requirements":{"minecraft:bricks":24,"minecraft:glass":1,"minecraft:stone_bricks":94},"sha256":"a6eb449a3c5348d3aa419f1681cf547f7667a439c68b75d90ffc463a0d2a943b","size":{"x":32,"y":1,"z":32}},{"blockCount":42,"bytes":2231,"file":"chunks/y023-z128-x224.json","offset":{"x":224,"y":23,"z":128},"requirements":{"minecraft:bricks":34,"minecraft:stone_bricks":8},"sha256":"d7a8c152f984f2eced69856a55015f57c947b2e146fc844592e100b6497f8392","size":{"x":32,"y":1,"z":32}},{"blockCount":128,"bytes":1852,"file":"chunks/y023-z128-x288.json","offset":{"x":288,"y":23,"z":128},"requirements":{"minecraft:stone_bricks":128},"sha256":"148fa964dbf5e602ac51e260abc0635fe25513f4a94a3ae7d0cb33668cfdbf60","size":{"x":32,"y":1,"z":32}},{"blockCount":21,"bytes":1114,"file":"chunks/y023-z128-x320.json","offset":{"x":320,"y":23,"z":128},"requirements":{"minecraft:stone_bricks":21},"sha256":"27667049185f2a09a5b3d0b44c4f4ed58d44a6f742e042afa888c5e5f21c0bd3","size":{"x":32,"y":1,"z":32}},{"blockCount":128,"bytes":1853,"file":"chunks/y023-z128-x352.json","offset":{"x":352,"y":23,"z":128},"requirements":{"minecraft:stone_bricks":128},"sha256":"8abba8dffb0b1b67b84ad43463ea8c4a8af286ef43e685e38f0e7151d6e29203","size":{"x":32,"y":1,"z":32}},{"blockCount":12,"bytes":837,"file":"chunks/y023-z128-x384.json","offset":{"x":384,"y":23,"z":128},"requirements":{"minecraft:stone_bricks":12},"sha256":"66526f329282f06837611b4d68769ade79be013f73c1b83ca52e622c53c1bef4","size":{"x":32,"y":1,"z":32}},{"blockCount":64,"bytes":2152,"file":"chunks/y023-z160-x032.json","offset":{"x":32,"y":23,"z":160},"requirements":{"minecraft:stone_bricks":64},"sha256":"9609f4121c91a1d1c8f5475b3b4ae91c43c5842cf119879ccccd6c27a6a238ed","size":{"x":32,"y":1,"z":32}},{"blockCount":452,"bytes":5814,"file":"chunks/y023-z160-x064.json","offset":{"x":64,"y":23,"z":160},"requirements":{"minecraft:stone_bricks":452},"sha256":"8e66b67d86b8e1627d323a21d2de2ececb0b5e2398c3f986e2fdbbd8a4b0c748","size":{"x":32,"y":1,"z":32}},{"blockCount":129,"bytes":2681,"file":"chunks/y023-z160-x096.json","offset":{"x":96,"y":23,"z":160},"requirements":{"minecraft:stone_bricks":129},"sha256":"d3adf074c87bbece4e9e2e24189f8cd9a065c658ed4c0dde6e6a896f68776e6e","size":{"x":32,"y":1,"z":32}},{"blockCount":160,"bytes":3581,"file":"chunks/y023-z160-x128.json","offset":{"x":128,"y":23,"z":160},"requirements":{"minecraft:stone_bricks":160},"sha256":"c757e3f8e34b53889913895aa8b08aaf8ef6b753a3de44f24be44ba9258f1586","size":{"x":32,"y":1,"z":32}},{"blockCount":26,"bytes":1624,"file":"chunks/y023-z160-x160.json","offset":{"x":160,"y":23,"z":160},"requirements":{"minecraft:cobbled_deepslate":26},"sha256":"bbacd307d5e744f6695a3adb45ba829735a32ab74ab59a1a0c368175b931bd85","size":{"x":32,"y":1,"z":32}},{"blockCount":12,"bytes":974,"file":"chunks/y023-z160-x192.json","offset":{"x":192,"y":23,"z":160},"requirements":{"minecraft:bricks":3,"minecraft:stone_bricks":9},"sha256":"6258e257830fa61a6186b06273ac710a11d4bf0e39e7c445e74e4e58f8276d82","size":{"x":32,"y":1,"z":32}},{"blockCount":50,"bytes":1686,"file":"chunks/y023-z160-x224.json","offset":{"x":224,"y":23,"z":160},"requirements":{"minecraft:bricks":7,"minecraft:sandstone":1,"minecraft:stone_bricks":42},"sha256":"1754436488c9105101cc66ddad271ef82934a0f23563f01358bdfa422dd6d0f1","size":{"x":32,"y":1,"z":32}},{"blockCount":135,"bytes":1767,"file":"chunks/y023-z160-x288.json","offset":{"x":288,"y":23,"z":160},"requirements":{"minecraft:stone_bricks":135},"sha256":"3e8f1fd1d2a35e3dbb76274fca372d892d8ea6b906087e743126e288f3b98855","size":{"x":32,"y":1,"z":32}},{"blockCount":135,"bytes":1173,"file":"chunks/y023-z160-x320.json","offset":{"x":320,"y":23,"z":160},"requirements":{"minecraft:glass":8,"minecraft:stone_bricks":127},"sha256":"76f40b86c5c5b0750e025e4d83f664908a4ac304b29448afa95e308b161a035d","size":{"x":32,"y":1,"z":32}},{"blockCount":50,"bytes":1641,"file":"chunks/y023-z160-x352.json","offset":{"x":352,"y":23,"z":160},"requirements":{"minecraft:glass":8,"minecraft:oak_planks":2,"minecraft:stone_bricks":40},"sha256":"7ba4829d338eb2d1e02734b98595f439842e1c9518b7e00d53277f77ee2a6eaa","size":{"x":32,"y":1,"z":32}},{"blockCount":62,"bytes":1843,"file":"chunks/y023-z192-x096.json","offset":{"x":96,"y":23,"z":192},"requirements":{"minecraft:stone_bricks":62},"sha256":"cb4de194ed6b7d10b3b108a68e1257ca35144f921037c703411d7ef1d1ccd2d5","size":{"x":32,"y":1,"z":32}},{"blockCount":29,"bytes":1308,"file":"chunks/y023-z192-x128.json","offset":{"x":128,"y":23,"z":192},"requirements":{"minecraft:stone_bricks":29},"sha256":"53e469299f76ee5d82bdd446eec4860f39373e37dab62977c2ce085831f4cb04","size":{"x":32,"y":1,"z":32}},{"blockCount":43,"bytes":1312,"file":"chunks/y023-z192-x160.json","offset":{"x":160,"y":23,"z":192},"requirements":{"minecraft:cobbled_deepslate":43},"sha256":"99807abddcb6a4f3da4ba38f9f0c1353456f41152f603009c624d9c2fd84f4fd","size":{"x":32,"y":1,"z":32}},{"blockCount":41,"bytes":873,"file":"chunks/y023-z192-x192.json","offset":{"x":192,"y":23,"z":192},"requirements":{"minecraft:cobbled_deepslate":32,"minecraft:stone_bricks":9},"sha256":"a499d3d1e174d9fda46dfba4d10e4a0c8431faec717e812767ad973b19622049","size":{"x":32,"y":1,"z":32}},{"blockCount":77,"bytes":1522,"file":"chunks/y023-z192-x224.json","offset":{"x":224,"y":23,"z":192},"requirements":{"minecraft:cobbled_deepslate":20,"minecraft:stone_bricks":57},"sha256":"3389c0305c31aab5eac05753167cd599782557e8833a2e39eb3b0d189be9ba1c","size":{"x":32,"y":1,"z":32}},{"blockCount":114,"bytes":2152,"file":"chunks/y023-z192-x256.json","offset":{"x":256,"y":23,"z":192},"requirements":{"minecraft:cobbled_deepslate":66,"minecraft:stone_bricks":48},"sha256":"1f6e182d568b792fc2ce1b262f9a7b0147ac03007abaa688b28ff52258037100","size":{"x":32,"y":1,"z":32}},{"blockCount":9,"bytes":860,"file":"chunks/y023-z224-x224.json","offset":{"x":224,"y":23,"z":224},"requirements":{"minecraft:sandstone":1,"minecraft:stone_bricks":8},"sha256":"147dfa38bae8e83c03a44301f5b7b695bccb44d4123438efa9e7b3849184ca04","size":{"x":32,"y":1,"z":15}},{"blockCount":1,"bytes":648,"file":"chunks/y023-z224-x256.json","offset":{"x":256,"y":23,"z":224},"requirements":{"minecraft:cobbled_deepslate":1},"sha256":"ebbfbf8f32ebbb9f11b8d34aab019c5c09016c1406d2fde4a6b8b591f17e44f8","size":{"x":32,"y":1,"z":15}},{"blockCount":25,"bytes":991,"file":"chunks/y024-z000-x320.json","offset":{"x":320,"y":24,"z":0},"requirements":{"minecraft:sandstone":25},"sha256":"44aa81f466033aaaf6304f8327a5f65dd101ee58cae99cb62e5aa83560ccc77c","size":{"x":32,"y":1,"z":32}},{"blockCount":38,"bytes":901,"file":"chunks/y024-z000-x352.json","offset":{"x":352,"y":24,"z":0},"requirements":{"minecraft:sandstone":32,"minecraft:stone_bricks":6},"sha256":"333d2397d5a789d068f86e5328c28cfca05fa0a607ae69782062d370bd8e8b22","size":{"x":32,"y":1,"z":32}},{"blockCount":74,"bytes":2357,"file":"chunks/y024-z000-x384.json","offset":{"x":384,"y":24,"z":0},"requirements":{"minecraft:cobbled_deepslate":2,"minecraft:sandstone":8,"minecraft:stone_bricks":64},"sha256":"ec037fd392294ccd0ee103b6ce6eb36d82a6afce8f90ed51e81a14fe7801d872","size":{"x":32,"y":1,"z":32}},{"blockCount":99,"bytes":3172,"file":"chunks/y024-z032-x320.json","offset":{"x":320,"y":24,"z":32},"requirements":{"minecraft:bricks":21,"minecraft:glass":8,"minecraft:sandstone":15,"minecraft:spruce_planks":55},"sha256":"5e95e2c1d7786a71c80e73dc06eedda134267515f50ba999f69475d3dec63726","size":{"x":32,"y":1,"z":32}},{"blockCount":135,"bytes":3310,"file":"chunks/y024-z032-x352.json","offset":{"x":352,"y":24,"z":32},"requirements":{"minecraft:bricks":6,"minecraft:glass":16,"minecraft:sandstone":7,"minecraft:spruce_planks":106},"sha256":"b703d2a45861bc6d41e0adfbdd4bf36343afb0c6ffc67a7d92b91239aaa72443","size":{"x":32,"y":1,"z":32}},{"blockCount":150,"bytes":3218,"file":"chunks/y024-z032-x384.json","offset":{"x":384,"y":24,"z":32},"requirements":{"minecraft:bricks":12,"minecraft:sandstone":16,"minecraft:spruce_planks":5,"minecraft:stone_bricks":117},"sha256":"3dfc602daeb1f9d1f531aa402b11038e1f6ad7917951612dabac655dbebe6375","size":{"x":32,"y":1,"z":32}},{"blockCount":5,"bytes":757,"file":"chunks/y024-z064-x032.json","offset":{"x":32,"y":24,"z":64},"requirements":{"minecraft:stone_bricks":5},"sha256":"e7b2412f9e5f269783115647c4ce5ef7243b510495b4f9ec4f07b647cd32e759","size":{"x":32,"y":1,"z":32}},{"blockCount":75,"bytes":1366,"file":"chunks/y024-z064-x064.json","offset":{"x":64,"y":24,"z":64},"requirements":{"minecraft:stone_bricks":75},"sha256":"516272118b36f6267605815907678f5a789984d27f59656dc87d9621ce8a0308","size":{"x":32,"y":1,"z":32}},{"blockCount":83,"bytes":2191,"file":"chunks/y024-z064-x096.json","offset":{"x":96,"y":24,"z":64},"requirements":{"minecraft:stone_bricks":83},"sha256":"2000b1dc2fcc5c5e4efa1e7be9846745ed765e480246b1a87b6b5aa2eac04c4f","size":{"x":32,"y":1,"z":32}},{"blockCount":54,"bytes":1814,"file":"chunks/y024-z064-x128.json","offset":{"x":128,"y":24,"z":64},"requirements":{"minecraft:stone_bricks":54},"sha256":"927c620adb943e3419726de7b850100b42be74f9520120493bf3e51aee1fa4b9","size":{"x":32,"y":1,"z":32}},{"blockCount":1,"bytes":643,"file":"chunks/y024-z064-x192.json","offset":{"x":192,"y":24,"z":64},"requirements":{"minecraft:stone_bricks":1},"sha256":"f8cf7dca84517f52083c86a3eec8aedb494b7e4dc8f82c879efecbe137871340","size":{"x":32,"y":1,"z":32}},{"blockCount":56,"bytes":1968,"file":"chunks/y024-z064-x320.json","offset":{"x":320,"y":24,"z":64},"requirements":{"minecraft:bricks":7,"minecraft:sandstone":40,"minecraft:spruce_planks":9},"sha256":"b512783e088bb04b011badd48d1ba3a310cf2e20f58e39418908b1a1f1a95cdc","size":{"x":32,"y":1,"z":32}},{"blockCount":64,"bytes":1775,"file":"chunks/y024-z064-x352.json","offset":{"x":352,"y":24,"z":64},"requirements":{"minecraft:bricks":6,"minecraft:sandstone":39,"minecraft:spruce_planks":16,"minecraft:stone_bricks":3},"sha256":"a08ed4b41aa11341acd634bc3d1ac2965993bd4dd1c74d63907d04ba2a2ff24b","size":{"x":32,"y":1,"z":32}},{"blockCount":64,"bytes":1253,"file":"chunks/y024-z064-x384.json","offset":{"x":384,"y":24,"z":64},"requirements":{"minecraft:sandstone":19,"minecraft:stone_bricks":45},"sha256":"ceb70cc7a11d93d8719c2458ca9cc584382f18dd45f853a6279ed3822ae5c667","size":{"x":32,"y":1,"z":32}},{"blockCount":91,"bytes":2647,"file":"chunks/y024-z096-x032.json","offset":{"x":32,"y":24,"z":96},"requirements":{"minecraft:stone_bricks":91},"sha256":"173a7455ffd529a67ea2cfd7da2436caaa67751be8533f900dca201d6a2626ed","size":{"x":32,"y":1,"z":32}},{"blockCount":418,"bytes":6383,"file":"chunks/y024-z096-x064.json","offset":{"x":64,"y":24,"z":96},"requirements":{"minecraft:stone_bricks":418},"sha256":"2a54cec01ed99c62ebf20db668dd647d9611a1352baafb4749394f06c081e86d","size":{"x":32,"y":1,"z":32}},{"blockCount":143,"bytes":2488,"file":"chunks/y024-z096-x096.json","offset":{"x":96,"y":24,"z":96},"requirements":{"minecraft:stone_bricks":143},"sha256":"c0154ab0f6254f863468b329e5f748d837217792c8ab42c3463423dcbc44425c","size":{"x":32,"y":1,"z":32}},{"blockCount":199,"bytes":3665,"file":"chunks/y024-z096-x128.json","offset":{"x":128,"y":24,"z":96},"requirements":{"minecraft:stone_bricks":199},"sha256":"36dbc2865f66e3e857b9925ab9ca8b525ccf97eb8ad9f29ee75e4bf4274883f3","size":{"x":32,"y":1,"z":32}},{"blockCount":32,"bytes":624,"file":"chunks/y024-z096-x160.json","offset":{"x":160,"y":24,"z":96},"requirements":{"minecraft:stone_bricks":32},"sha256":"e52482ba81d3c0eb1adf3597f97512b65b3cb71323ae2c07c0425e0bfbd87dd0","size":{"x":32,"y":1,"z":32}},{"blockCount":41,"bytes":1667,"file":"chunks/y024-z096-x192.json","offset":{"x":192,"y":24,"z":96},"requirements":{"minecraft:bricks":27,"minecraft:stone_bricks":14},"sha256":"7b07e83e3a1a0de0ab7f4d0bd2493e3f34f91f3345f20f87de050935195f271b","size":{"x":32,"y":1,"z":32}},{"blockCount":21,"bytes":1397,"file":"chunks/y024-z096-x224.json","offset":{"x":224,"y":24,"z":96},"requirements":{"minecraft:bricks":20,"minecraft:stone_bricks":1},"sha256":"c02e359f4f512a7deaa461e7513891cdd9e6daaab427657afd9881b7dafe0367","size":{"x":32,"y":1,"z":32}},{"blockCount":18,"bytes":935,"file":"chunks/y024-z096-x256.json","offset":{"x":256,"y":24,"z":96},"requirements":{"minecraft:stone_bricks":18},"sha256":"44b6e4e5d9702d2f00daf7380c22332327bbca551cbb76fe60a46f54abafcda3","size":{"x":32,"y":1,"z":32}},{"blockCount":123,"bytes":2160,"file":"chunks/y024-z096-x288.json","offset":{"x":288,"y":24,"z":96},"requirements":{"minecraft:stone_bricks":123},"sha256":"4e22f4fb13f23d23b9003f1e700402f98c1fb927ca78d2f5befd030078199b89","size":{"x":32,"y":1,"z":32}},{"blockCount":135,"bytes":997,"file":"chunks/y024-z096-x320.json","offset":{"x":320,"y":24,"z":96},"requirements":{"minecraft:glass":9,"minecraft:stone_bricks":126},"sha256":"8c9caf86aeb984f3e337918d9742a583a1983dc7cd9b80f6192add7df9deab7f","size":{"x":32,"y":1,"z":32}},{"blockCount":141,"bytes":1968,"file":"chunks/y024-z096-x352.json","offset":{"x":352,"y":24,"z":96},"requirements":{"minecraft:glass":9,"minecraft:stone_bricks":132},"sha256":"425326010d5eb84262305602fb752f58ae19885ee99c2c28238f4fe84f3496d4","size":{"x":32,"y":1,"z":32}},{"blockCount":6,"bytes":759,"file":"chunks/y024-z096-x384.json","offset":{"x":384,"y":24,"z":96},"requirements":{"minecraft:stone_bricks":6},"sha256":"10d5902a476edc5f77795cc2ddedbe080f58f8455a3eb33b2a45409eef8f8936","size":{"x":32,"y":1,"z":32}},{"blockCount":100,"bytes":1385,"file":"chunks/y024-z128-x000.json","offset":{"x":0,"y":24,"z":128},"requirements":{"minecraft:stone_bricks":100},"sha256":"4b7f06379cae7b76ca7058b94f90d0f34e3d93171164c211be334b3c3fb44507","size":{"x":32,"y":1,"z":32}},{"blockCount":271,"bytes":3882,"file":"chunks/y024-z128-x032.json","offset":{"x":32,"y":24,"z":128},"requirements":{"minecraft:stone_bricks":271},"sha256":"8005c9dd61d4c969b825bb9267ecc83ba8ba0225ec742470a776fb5f33131d05","size":{"x":32,"y":1,"z":32}},{"blockCount":77,"bytes":2296,"file":"chunks/y024-z128-x064.json","offset":{"x":64,"y":24,"z":128},"requirements":{"minecraft:stone_bricks":77},"sha256":"b58d84276645054696b94fd7fd8802cd90ffd29d3f59671437993ba8a499663e","size":{"x":32,"y":1,"z":32}},{"blockCount":30,"bytes":1144,"file":"chunks/y024-z128-x096.json","offset":{"x":96,"y":24,"z":128},"requirements":{"minecraft:stone_bricks":30},"sha256":"d2a4c30a3d8bee2a2bea0f8d605ab406ea706ffdfc14c68533fe099185d3db84","size":{"x":32,"y":1,"z":32}},{"blockCount":133,"bytes":3133,"file":"chunks/y024-z128-x128.json","offset":{"x":128,"y":24,"z":128},"requirements":{"minecraft:glass":6,"minecraft:polished_diorite":7,"minecraft:stone_bricks":120},"sha256":"6de152b17f0b41406b124bd28792f0b3973377d12df2388de9b17a46408ef209","size":{"x":32,"y":1,"z":32}},{"blockCount":134,"bytes":2172,"file":"chunks/y024-z128-x160.json","offset":{"x":160,"y":24,"z":128},"requirements":{"minecraft:glass":22,"minecraft:stone_bricks":112},"sha256":"f36536080a02c30a70abcde68dfa96dfb6190d258ee230c9e1f94b0659487c8d","size":{"x":32,"y":1,"z":32}},{"blockCount":104,"bytes":2653,"file":"chunks/y024-z128-x192.json","offset":{"x":192,"y":24,"z":128},"requirements":{"minecraft:bricks":26,"minecraft:glass":1,"minecraft:stone_bricks":77},"sha256":"6ec9ffe3674df1f99fabeff89370a6724f4f64e0f3cc140d653c8e6aa1015f72","size":{"x":32,"y":1,"z":32}},{"blockCount":43,"bytes":2116,"file":"chunks/y024-z128-x224.json","offset":{"x":224,"y":24,"z":128},"requirements":{"minecraft:bricks":36,"minecraft:stone_bricks":7},"sha256":"d7b15784b519a3aa049e2a50d153d6e25cc99131927f49e80b899ff7301b94f1","size":{"x":32,"y":1,"z":32}},{"blockCount":64,"bytes":1832,"file":"chunks/y024-z128-x256.json","offset":{"x":256,"y":24,"z":128},"requirements":{"minecraft:stone_bricks":64},"sha256":"c671f7d461f9618d5aa2d7f23cfac89f353f5b6a94c48a3fb5e2af1573984fc3","size":{"x":32,"y":1,"z":32}},{"blockCount":64,"bytes":1832,"file":"chunks/y024-z128-x288.json","offset":{"x":288,"y":24,"z":128},"requirements":{"minecraft:stone_bricks":64},"sha256":"ea33f50318aed1a8153ff247bdf5a7a43f9835a1964b287e2fe3c2058c4dcb98","size":{"x":32,"y":1,"z":32}},{"blockCount":16,"bytes":1075,"file":"chunks/y024-z128-x320.json","offset":{"x":320,"y":24,"z":128},"requirements":{"minecraft:stone_bricks":16},"sha256":"1c7da18540d40ba1abb3eeda95f8b9f2f83114c687a981fd3fa82cad8a105ba6","size":{"x":32,"y":1,"z":32}},{"blockCount":128,"bytes":1853,"file":"chunks/y024-z128-x352.json","offset":{"x":352,"y":24,"z":128},"requirements":{"minecraft:stone_bricks":128},"sha256":"941afb54613ac515be78a3e8a07073d07a8c54c430b2a04a61001f3ad2b4d363","size":{"x":32,"y":1,"z":32}},{"blockCount":12,"bytes":837,"file":"chunks/y024-z128-x384.json","offset":{"x":384,"y":24,"z":128},"requirements":{"minecraft:stone_bricks":12},"sha256":"ccf0540423f1453a7ffa3b3edc94ba71248e1d81100b3d3b44636709eaf2b257","size":{"x":32,"y":1,"z":32}},{"blockCount":59,"bytes":2190,"file":"chunks/y024-z160-x032.json","offset":{"x":32,"y":24,"z":160},"requirements":{"minecraft:stone_bricks":59},"sha256":"26d1eda369cc37a75b8bf710524e32e18e899ade6992b3269f5ce24327d0c345","size":{"x":32,"y":1,"z":32}},{"blockCount":446,"bytes":6384,"file":"chunks/y024-z160-x064.json","offset":{"x":64,"y":24,"z":160},"requirements":{"minecraft:stone_bricks":446},"sha256":"a590dfb0a28e8835f0866263fda6837b953348dd4e822c219a25f9e1515b9173","size":{"x":32,"y":1,"z":32}},{"blockCount":142,"bytes":2605,"file":"chunks/y024-z160-x096.json","offset":{"x":96,"y":24,"z":160},"requirements":{"minecraft:stone_bricks":142},"sha256":"e39200ac2581f971d90b19333158a29ac7a20c0b140a4918017dd2c5a7ac246d","size":{"x":32,"y":1,"z":32}},{"blockCount":166,"bytes":3542,"file":"chunks/y024-z160-x128.json","offset":{"x":128,"y":24,"z":160},"requirements":{"minecraft:stone_bricks":166},"sha256":"0b78cc99d4d5bf4041f4cdb76b5afcb18a1624705d69e0ea93ed4cfcc6640c36","size":{"x":32,"y":1,"z":32}},{"blockCount":26,"bytes":1624,"file":"chunks/y024-z160-x160.json","offset":{"x":160,"y":24,"z":160},"requirements":{"minecraft:cobbled_deepslate":26},"sha256":"2eecaaf552e5e182cf231deff86a7836cd6a82f3e02d6eb0e0a881b4c1a52c71","size":{"x":32,"y":1,"z":32}},{"blockCount":17,"bytes":1091,"file":"chunks/y024-z160-x192.json","offset":{"x":192,"y":24,"z":160},"requirements":{"minecraft:bricks":5,"minecraft:stone_bricks":12},"sha256":"01dd703e1f5cf2eb041c7dfa6a8d32b452ea1be2a1dd6c29590f33b7f412567a","size":{"x":32,"y":1,"z":32}},{"blockCount":63,"bytes":1620,"file":"chunks/y024-z160-x224.json","offset":{"x":224,"y":24,"z":160},"requirements":{"minecraft:bricks":4,"minecraft:cobbled_deepslate":1,"minecraft:stone_bricks":58},"sha256":"0924f1b0babbf3dc3346c8c38b8a42b4708817e83fee90e1e45d7b73bc1a2673","size":{"x":32,"y":1,"z":32}},{"blockCount":4,"bytes":682,"file":"chunks/y024-z160-x256.json","offset":{"x":256,"y":24,"z":160},"requirements":{"minecraft:stone_bricks":4},"sha256":"3f70cf8c00d3575cc23929d1a35dcce20b25fdb4930b879fe5e957ebebe5c501","size":{"x":32,"y":1,"z":32}},{"blockCount":109,"bytes":1869,"file":"chunks/y024-z160-x288.json","offset":{"x":288,"y":24,"z":160},"requirements":{"minecraft:stone_bricks":109},"sha256":"a67e862d2ab494ba36954bc0973595dfa2d9e59fa1330fef43efb4bf48216ded","size":{"x":32,"y":1,"z":32}},{"blockCount":135,"bytes":1036,"file":"chunks/y024-z160-x320.json","offset":{"x":320,"y":24,"z":160},"requirements":{"minecraft:glass":9,"minecraft:stone_bricks":126},"sha256":"1d48e907ff069f97f30b33686edcb38f8e21e34126ea89fb1d734b7ec9daee03","size":{"x":32,"y":1,"z":32}},{"blockCount":116,"bytes":1817,"file":"chunks/y024-z160-x352.json","offset":{"x":352,"y":24,"z":160},"requirements":{"minecraft:glass":9,"minecraft:oak_planks":1,"minecraft:stone_bricks":106},"sha256":"a4f49e3b27409a9c771aa46f8adcd360bd4a13ff5f73ccc4933fbc0d36941a9d","size":{"x":32,"y":1,"z":32}},{"blockCount":62,"bytes":1843,"file":"chunks/y024-z192-x096.json","offset":{"x":96,"y":24,"z":192},"requirements":{"minecraft:stone_bricks":62},"sha256":"274e5a13e193fc6ef38a9fb0409fdacce003e89df73888c054cf0340c331a0d2","size":{"x":32,"y":1,"z":32}}],"schema":1}
