{"entries":[{"blockCount":29,"bytes":1308,"file":"chunks/y024-z192-x128.json","offset":{"x":128,"y":24,"z":192},"requirements":{"minecraft:stone_bricks":29},"sha256":"0c1aaa1f74d296af4d9ad5059f18ddf57ce4b918ad744c447d7329915a3ee069","size":{"x":32,"y":1,"z":32}},{"blockCount":43,"bytes":1312,"file":"chunks/y024-z192-x160.json","offset":{"x":160,"y":24,"z":192},"requirements":{"minecraft:cobbled_deepslate":43},"sha256":"855b5ca6356982fc9fbee51c05eec5cdcf24a3db0686a6711f8141d77341bf83","size":{"x":32,"y":1,"z":32}},{"blockCount":43,"bytes":913,"file":"chunks/y024-z192-x192.json","offset":{"x":192,"y":24,"z":192},"requirements":{"minecraft:cobbled_deepslate":32,"minecraft:stone_bricks":11},"sha256":"aef15a6ac05527e7ba64d63e1c5b26ba9cfd4a3ecff184e91530fb4a6b1be8b4","size":{"x":32,"y":1,"z":32}},{"blockCount":91,"bytes":1471,"file":"chunks/y024-z192-x224.json","offset":{"x":224,"y":24,"z":192},"requirements":{"minecraft:cobbled_deepslate":19,"minecraft:sandstone":1,"minecraft:stone_bricks":71},"sha256":"994f0b51c4016008ec0699878e7d9ea1443313ef06ed06363765f71597fa306b","size":{"x":32,"y":1,"z":32}},{"blockCount":13,"bytes":793,"file":"chunks/y024-z224-x224.json","offset":{"x":224,"y":24,"z":224},"requirements":{"minecraft:cobbled_deepslate":1,"minecraft:stone_bricks":12},"sha256":"286d30e3954994ca1eaf4b229ffb12b00ea3dcacafb404fbb9d946559acb6441","size":{"x":32,"y":1,"z":15}},{"blockCount":1,"bytes":640,"file":"chunks/y024-z224-x256.json","offset":{"x":256,"y":24,"z":224},"requirements":{"minecraft:sandstone":1},"sha256":"429a40dbdc52787ac77f96c9a6ce4019af499607b42e44e19551aea230b92593","size":{"x":32,"y":1,"z":15}},{"blockCount":1,"bytes":642,"file":"chunks/y025-z000-x288.json","offset":{"x":288,"y":25,"z":0},"requirements":{"minecraft:stone_bricks":1},"sha256":"3dd8eaee165abee0855e22ca26fa56e9dd2cc3e48e964069e43c7540c80d995d","size":{"x":32,"y":1,"z":32}},{"blockCount":25,"bytes":1019,"file":"chunks/y025-z000-x320.json","offset":{"x":320,"y":25,"z":0},"requirements":{"minecraft:sandstone":10,"minecraft:spruce_planks":15},"sha256":"75a68f3dcebff87dccaefce966daa5630237767dbcd92c8e063cd7c45998979e","size":{"x":32,"y":1,"z":32}},{"blockCount":39,"bytes":925,"file":"chunks/y025-z000-x352.json","offset":{"x":352,"y":25,"z":0},"requirements":{"minecraft:spruce_planks":32,"minecraft:stone_bricks":7},"sha256":"501bc4f3cfd04aa5acca812a38ddd9f54185b0164b63660ae09c0ba6263788b7","size":{"x":32,"y":1,"z":32}},{"blockCount":90,"bytes":2713,"file":"chunks/y025-z000-x384.json","offset":{"x":384,"y":25,"z":0},"requirements":{"minecraft:spruce_planks":4,"minecraft:stone_bricks":86},"sha256":"08dce26c272d52f4e0962055c39ba85e6169d0cc7a509fbb1ec9dd5a0565e49b","size":{"x":32,"y":1,"z":32}},{"blockCount":444,"bytes":2936,"file":"chunks/y025-z032-x320.json","offset":{"x":320,"y":25,"z":32},"requirements":{"minecraft:bricks":10,"minecraft:sandstone":7,"minecraft:spruce_planks":414,"minecraft:stone_bricks":13},"sha256":"d5251d6791fd9eaeb46f782cf2a645fff8c02fcaccef99d31844b2385ad5bbb7","size":{"x":32,"y":1,"z":32}},{"blockCount":946,"bytes":1916,"file":"chunks/y025-z032-x352.json","offset":{"x":352,"y":25,"z":32},"requirements":{"minecraft:spruce_planks":914,"minecraft:stone_bricks":32},"sha256":"db9ef5d5bcb9cfae54b02a34fea742ef9ac85e818b80c3a4f6e70db425afff77","size":{"x":32,"y":1,"z":32}},{"blockCount":492,"bytes":2682,"file":"chunks/y025-z032-x384.json","offset":{"x":384,"y":25,"z":32},"requirements":{"minecraft:bricks":12,"minecraft:spruce_planks":54,"minecraft:stone_bricks":426},"sha256":"1445d9258b12fd42a5dfc594f4a3645f3c38adb80eb0eb93bbc7c3398647dc80","size":{"x":32,"y":1,"z":32}},{"blockCount":5,"bytes":757,"file":"chunks/y025-z064-x032.json","offset":{"x":32,"y":25,"z":64},"requirements":{"minecraft:stone_bricks":5},"sha256":"3022fdf18b0a13d7a9dca66060cfc2ac9f2f7cc946e44aabcffeaa9c31baafef","size":{"x":32,"y":1,"z":32}},{"blockCount":92,"bytes":1214,"file":"chunks/y025-z064-x064.json","offset":{"x":64,"y":25,"z":64},"requirements":{"minecraft:stone_bricks":92},"sha256":"e5e22f5fa0ae2b7f6253cc74fd3f833c2ba2988aec622da961677b7b9ef2c106","size":{"x":32,"y":1,"z":32}},{"blockCount":99,"bytes":2191,"file":"chunks/y025-z064-x096.json","offset":{"x":96,"y":25,"z":64},"requirements":{"minecraft:stone_bricks":99},"sha256":"8cb464d718ff97795d61d222a8066012112f6e1d8c3acfb5b3d5430abc8547ef","size":{"x":32,"y":1,"z":32}},{"blockCount":54,"bytes":1814,"file":"chunks/y025-z064-x128.json","offset":{"x":128,"y":25,"z":64},"requirements":{"minecraft:stone_bricks":54},"sha256":"e424a7d652a7290ae498ef18aa1215d9f09f48421481e9ea8b4f070c87e1a546","size":{"x":32,"y":1,"z":32}},{"blockCount":1,"bytes":643,"file":"chunks/y025-z064-x192.json","offset":{"x":192,"y":25,"z":64},"requirements":{"minecraft:stone_bricks":1},"sha256":"2301b2aabae5e9348d6f231e89b31841ff13c6db512b63b9aad4e1d985feeafe","size":{"x":32,"y":1,"z":32}},{"blockCount":35,"bytes":704,"file":"chunks/y025-z064-x288.json","offset":{"x":288,"y":25,"z":64},"requirements":{"minecraft:stone_bricks":35},"sha256":"bdb98474615416029bc6727c455a350fba82fbea2c161ef49b52ae6d2bea9c83","size":{"x":32,"y":1,"z":32}},{"blockCount":347,"bytes":1823,"file":"chunks/y025-z064-x320.json","offset":{"x":320,"y":25,"z":64},"requirements":{"minecraft:sandstone":17,"minecraft:spruce_planks":221,"minecraft:stone_bricks":109},"sha256":"3356f96c245b832aaf1b03aff6a7d8d920d090f1d76acb826fb2d13155c60f32","size":{"x":32,"y":1,"z":32}},{"blockCount":540,"bytes":970,"file":"chunks/y025-z064-x352.json","offset":{"x":352,"y":25,"z":64},"requirements":{"minecraft:spruce_planks":480,"minecraft:stone_bricks":60},"sha256":"14dfa30e298ec35a54ca7308b275fede7ee3466d8bcfeb2c847fc0574ba338ed","size":{"x":32,"y":1,"z":32}},{"blockCount":67,"bytes":1411,"file":"chunks/y025-z064-x384.json","offset":{"x":384,"y":25,"z":64},"requirements":{"minecraft:spruce_planks":56,"minecraft:stone_bricks":11},"sha256":"fce968392c838b19e9077ab6b9c6f665aa28f308ecadc71cbb1fd687c3220a79","size":{"x":32,"y":1,"z":32}},{"blockCount":125,"bytes":2192,"file":"chunks/y025-z096-x032.json","offset":{"x":32,"y":25,"z":96},"requirements":{"minecraft:stone_bricks":125},"sha256":"be4660a10f39ed8191256d68e44b6210260806539bc54e1d57cf6c1db60965c6","size":{"x":32,"y":1,"z":32}},{"blockCount":441,"bytes":5509,"file":"chunks/y025-z096-x064.json","offset":{"x":64,"y":25,"z":96},"requirements":{"minecraft:stone_bricks":441},"sha256":"e9c699862a2783c6394f8527673ba9a39db3cf3c8cf2c960af4b81c72a001e14","size":{"x":32,"y":1,"z":32}},{"blockCount":154,"bytes":2490,"file":"chunks/y025-z096-x096.json","offset":{"x":96,"y":25,"z":96},"requirements":{"minecraft:stone_bricks":154},"sha256":"2320446d7478995e4604726b317c1901a6f6c8a15bed60056e22a7689e84ec4b","size":{"x":32,"y":1,"z":32}},{"blockCount":200,"bytes":3665,"file":"chunks/y025-z096-x128.json","offset":{"x":128,"y":25,"z":96},"requirements":{"minecraft:stone_bricks":200},"sha256":"045166d4ed0f6879eb178146df67d55fc202f9132a49cef488527d5d9fde5571","size":{"x":32,"y":1,"z":32}},{"blockCount":32,"bytes":624,"file":"chunks/y025-z096-x160.json","offset":{"x":160,"y":25,"z":96},"requirements":{"minecraft:stone_bricks":32},"sha256":"718c770b5b6b008c47613c75eb599ec20df20706bc278a9ffc4bc92a2eb1f8e1","size":{"x":32,"y":1,"z":32}},{"blockCount":29,"bytes":1301,"file":"chunks/y025-z096-x192.json","offset":{"x":192,"y":25,"z":96},"requirements":{"minecraft:bricks":15,"minecraft:stone_bricks":14},"sha256":"d761e413b632d66b5fc89464b8bc739b1f914383369edfee209c8c10b3c574dd","size":{"x":32,"y":1,"z":32}},{"blockCount":17,"bytes":1253,"file":"chunks/y025-z096-x224.json","offset":{"x":224,"y":25,"z":96},"requirements":{"minecraft:bricks":17},"sha256":"e9bf4546c4ac72eb667bd4cf098349e5922ff5ac4d5809244472b4c095944748","size":{"x":32,"y":1,"z":32}},{"blockCount":38,"bytes":1069,"file":"chunks/y025-z096-x256.json","offset":{"x":256,"y":25,"z":96},"requirements":{"minecraft:stone_bricks":38},"sha256":"9c4f3ed93e59d9d31c07a6db0b8f8ecda78804b4bfcecd5e91ac65d33719a584","size":{"x":32,"y":1,"z":32}},{"blockCount":71,"bytes":1960,"file":"chunks/y025-z096-x288.json","offset":{"x":288,"y":25,"z":96},"requirements":{"minecraft:stone_bricks":71},"sha256":"3aeb2a1a67724b1afb02cacb9a4cc32c01b979066409449118fa9dbc6614b1f2","size":{"x":32,"y":1,"z":32}},{"blockCount":37,"bytes":819,"file":"chunks/y025-z096-x320.json","offset":{"x":320,"y":25,"z":96},"requirements":{"minecraft:glass":4,"minecraft:stone_bricks":33},"sha256":"ffaf17690a72df6dd2042d45f6ef740f5d5e77feea34ab987b6e95b910689051","size":{"x":32,"y":1,"z":32}},{"blockCount":172,"bytes":2766,"file":"chunks/y025-z096-x352.json","offset":{"x":352,"y":25,"z":96},"requirements":{"minecraft:glass":41,"minecraft:stone_bricks":131},"sha256":"e68c510207f6454e15e18b1c5c80daa0a3226c7a99c6b97cc1b5e1d32ed83970","size":{"x":32,"y":1,"z":32}},{"blockCount":6,"bytes":759,"file":"chunks/y025-z096-x384.json","offset":{"x":384,"y":25,"z":96},"requirements":{"minecraft:stone_bricks":6},"sha256":"243686ee92febef3db4f4dfcf204b01afe595abbef10dc81d9e1b71a0941d6d7","size":{"x":32,"y":1,"z":32}},{"blockCount":99,"bytes":1384,"file":"chunks/y025-z128-x000.json","offset":{"x":0,"y":25,"z":128},"requirements":{"minecraft:stone_bricks":99},"sha256":"fa252cbb7f9372c3fc7a9b30077028333ad9485c07ec46b220146adc3c1a48c0","size":{"x":32,"y":1,"z":32}},{"blockCount":259,"bytes":3236,"file":"chunks/y025-z128-x032.json","offset":{"x":32,"y":25,"z":128},"requirements":{"minecraft:stone_bricks":259},"sha256":"e6e5bf2be88d61f9a538d56e3469292b421e1198e38c46560f4dec2ab50d436e","size":{"x":32,"y":1,"z":32}},{"blockCount":75,"bytes":2296,"file":"chunks/y025-z128-x064.json","offset":{"x":64,"y":25,"z":128},"requirements":{"minecraft:stone_bricks":75},"sha256":"2064bfbd96e416162842a86a0f138551caaeb005c5171ebdab82bf92b294dba7","size":{"x":32,"y":1,"z":32}},{"blockCount":30,"bytes":1145,"file":"chunks/y025-z128-x096.json","offset":{"x":96,"y":25,"z":128},"requirements":{"minecraft:stone_bricks":30},"sha256":"5aacaaa0ba702ace085afd6107d54b59c78b6e6afe5958956da737b75a3c0653","size":{"x":32,"y":1,"z":32}},{"blockCount":134,"bytes":3167,"file":"chunks/y025-z128-x128.json","offset":{"x":128,"y":25,"z":128},"requirements":{"minecraft:cobbled_deepslate":2,"minecraft:glass":2,"minecraft:polished_diorite":3,"minecraft:stone_bricks":127},"sha256":"cb318569381b3f18e94ba134a42f2dd81e5f27499d07d0cabf816a1370ed65d2","size":{"x":32,"y":1,"z":32}},{"blockCount":119,"bytes":1884,"file":"chunks/y025-z128-x160.json","offset":{"x":160,"y":25,"z":128},"requirements":{"minecraft:glass":10,"minecraft:stone_bricks":109},"sha256":"ce7caa9a0a114ed6ba2c7dd41866aa7752a0a21549115f4b50375a6017eb422b","size":{"x":32,"y":1,"z":32}},{"blockCount":93,"bytes":2541,"file":"chunks/y025-z128-x192.json","offset":{"x":192,"y":25,"z":128},"requirements":{"minecraft:bricks":21,"minecraft:glass":3,"minecraft:stone_bricks":69},"sha256":"4fa96a602fee16a780c0284fdff40ddb7f786383b501760213448081484f6c9e","size":{"x":32,"y":1,"z":32}},{"blockCount":45,"bytes":2278,"file":"chunks/y025-z128-x224.json","offset":{"x":224,"y":25,"z":128},"requirements":{"minecraft:bricks":44,"minecraft:glass":1},"sha256":"b43241bece128dff223a93dd8381ad8e876beae83b4277ecda526a9ced0acc58","size":{"x":32,"y":1,"z":32}},{"blockCount":134,"bytes":2024,"file":"chunks/y025-z128-x256.json","offset":{"x":256,"y":25,"z":128},"requirements":{"minecraft:glass":6,"minecraft:stone_bricks":128},"sha256":"08fd5812b974e913003bf7e50a423975143845bf57be2776caffe26b211d08b8","size":{"x":32,"y":1,"z":32}},{"blockCount":4,"bytes":684,"file":"chunks/y025-z128-x288.json","offset":{"x":288,"y":25,"z":128},"requirements":{"minecraft:stone_bricks":4},"sha256":"9027a7e6ab4971cce11814aa367f3028f3b3890fff37aa504a52429ba2aa9ab6","size":{"x":32,"y":1,"z":32}},{"blockCount":37,"bytes":1502,"file":"chunks/y025-z128-x320.json","offset":{"x":320,"y":25,"z":128},"requirements":{"minecraft:stone_bricks":37},"sha256":"1f9748686c09f5946bfc9b6f14e02c1551d9657cfdd0203c98923bfcc708f8c2","size":{"x":32,"y":1,"z":32}},{"blockCount":128,"bytes":1852,"file":"chunks/y025-z128-x352.json","offset":{"x":352,"y":25,"z":128},"requirements":{"minecraft:stone_bricks":128},"sha256":"87d2efebd424f229d0f345ff5ff46af6e4c6110d7b9578985c9bd1e4b9b7240d","size":{"x":32,"y":1,"z":32}},{"blockCount":12,"bytes":837,"file":"chunks/y025-z128-x384.json","offset":{"x":384,"y":25,"z":128},"requirements":{"minecraft:stone_bricks":12},"sha256":"c8d955a5577b2b25ea9b325d55fad2a11d4ace9faff2a98754ae16b9e3a83c64","size":{"x":32,"y":1,"z":32}},{"blockCount":85,"bytes":1962,"file":"chunks/y025-z160-x032.json","offset":{"x":32,"y":25,"z":160},"requirements":{"minecraft:stone_bricks":85},"sha256":"e150c58d139be1308e0a9a1ac5b0b41650dd40c8d9ab13839a398fd10c10a7ac","size":{"x":32,"y":1,"z":32}},{"blockCount":486,"bytes":5358,"file":"chunks/y025-z160-x064.json","offset":{"x":64,"y":25,"z":160},"requirements":{"minecraft:stone_bricks":486},"sha256":"4095c22f2dc5d692386db8bbf0c172ba6d628d28cee20480392fecf106510458","size":{"x":32,"y":1,"z":32}},{"blockCount":159,"bytes":2607,"file":"chunks/y025-z160-x096.json","offset":{"x":96,"y":25,"z":160},"requirements":{"minecraft:stone_bricks":159},"sha256":"7cd5a6c7103c5caf51b0d70c706d1d76246731d0d906dea023ffd99f000c29bc","size":{"x":32,"y":1,"z":32}},{"blockCount":167,"bytes":3542,"file":"chunks/y025-z160-x128.json","offset":{"x":128,"y":25,"z":160},"requirements":{"minecraft:stone_bricks":167},"sha256":"f5854ba0a203aea86719f833f4e503b2355b66ffa39870649cd7b415bd37d635","size":{"x":32,"y":1,"z":32}},{"blockCount":26,"bytes":1624,"file":"chunks/y025-z160-x160.json","offset":{"x":160,"y":25,"z":160},"requirements":{"minecraft:cobbled_deepslate":26},"sha256":"90078b705619f4ce1cffb881ea2135ec35b723e5e94828fced113c871cda6865","size":{"x":32,"y":1,"z":32}},{"blockCount":10,"bytes":993,"file":"chunks/y025-z160-x192.json","offset":{"x":192,"y":25,"z":160},"requirements":{"minecraft:bricks":6,"minecraft:stone_bricks":4},"sha256":"47b99cd4b651aab43798968a0d491ba3ccc99d8095c10181fb14dfc173ab4b8c","size":{"x":32,"y":1,"z":32}},{"blockCount":116,"bytes":1649,"file":"chunks/y025-z160-x224.json","offset":{"x":224,"y":25,"z":160},"requirements":{"minecraft:bricks":5,"minecraft:cobbled_deepslate":3,"minecraft:sandstone":4,"minecraft:stone_bricks":104},"sha256":"f9115b15da54255455d3c201031dddd081fd7b035d8850e733c74c164ac4ef5d","size":{"x":32,"y":1,"z":32}},{"blockCount":10,"bytes":798,"file":"chunks/y025-z160-x256.json","offset":{"x":256,"y":25,"z":160},"requirements":{"minecraft:stone_bricks":10},"sha256":"ebb9b524ff4e3617b30f1698cf35e0e6d3b2c4287ff651d8e54b026828aeab6f","size":{"x":32,"y":1,"z":32}},{"blockCount":106,"bytes":2082,"file":"chunks/y025-z160-x288.json","offset":{"x":288,"y":25,"z":160},"requirements":{"minecraft:stone_bricks":106},"sha256":"198ea5171e5ec2d07b39d3ce4f286399d5ef745de0da36cdfd7e4c9c06cb17ef","size":{"x":32,"y":1,"z":32}},{"blockCount":133,"bytes":843,"file":"chunks/y025-z160-x320.json","offset":{"x":320,"y":25,"z":160},"requirements":{"minecraft:glass":4,"minecraft:stone_bricks":129},"sha256":"c0d86f621de0b672ad4a32e31c6e6619c9a237980aca87ff73f7d8b33f76d4f1","size":{"x":32,"y":1,"z":32}},{"blockCount":173,"bytes":2792,"file":"chunks/y025-z160-x352.json","offset":{"x":352,"y":25,"z":160},"requirements":{"minecraft:glass":41,"minecraft:oak_planks":3,"minecraft:stone_bricks":129},"sha256":"916846c8b2df5e742dfe866aa5a8225735dc7b25b3d8f774c1d731e61d4eb4ca","size":{"x":32,"y":1,"z":32}},{"blockCount":72,"bytes":1843,"file":"chunks/y025-z192-x096.json","offset":{"x":96,"y":25,"z":192},"requirements":{"minecraft:stone_bricks":72},"sha256":"d6d4ff14113b78a331b08a6fc14dba454e203e82c2d22f0740330c49d294d1e5","size":{"x":32,"y":1,"z":32}},{"blockCount":29,"bytes":1308,"file":"chunks/y025-z192-x128.json","offset":{"x":128,"y":25,"z":192},"requirements":{"minecraft:stone_bricks":29},"sha256":"c8c2676febc96de4f2f79abd24eaf200d1cd94f08e8bd201e594c2ad119bc6d1","size":{"x":32,"y":1,"z":32}},{"blockCount":43,"bytes":1312,"file":"chunks/y025-z192-x160.json","offset":{"x":160,"y":25,"z":192},"requirements":{"minecraft:cobbled_deepslate":43},"sha256":"88bcb398bf7bc5377df32248169146925a4cc449f085ed7fb883a3ccecd83bca","size":{"x":32,"y":1,"z":32}},{"blockCount":35,"bytes":795,"file":"chunks/y025-z192-x192.json","offset":{"x":192,"y":25,"z":192},"requirements":{"minecraft:cobbled_deepslate":32,"minecraft:stone_bricks":3},"sha256":"7d450298cef921eaeebbd48016c1b06eff6f412468cca9d9495d965663bff602","size":{"x":32,"y":1,"z":32}},{"blockCount":77,"bytes":1090,"file":"chunks/y025-z192-x224.json","offset":{"x":224,"y":25,"z":192},"requirements":{"minecraft:cobbled_deepslate":22,"minecraft:sandstone":2,"minecraft:stone_bricks":53},"sha256":"c9510fe6b57937a78b1cc9ff5e6bd0eb5324898e5b0914703f7ce048ad2ae05d","size":{"x":32,"y":1,"z":32}},{"blockCount":1,"bytes":640,"file":"chunks/y025-z224-x224.json","offset":{"x":224,"y":25,"z":224},"requirements":{"minecraft:sandstone":1},"sha256":"38ae118cdb28763a20d5bb8384b054ab268149be80f9a34682cd1ab7fbf3311e","size":{"x":32,"y":1,"z":15}},{"blockCount":1,"bytes":648,"file":"chunks/y025-z224-x256.json","offset":{"x":256,"y":25,"z":224},"requirements":{"minecraft:cobbled_deepslate":1},"sha256":"d424f138212e0f8d4b5e2a19b71a4d671c592819fd8058aee7d3adb2c8f5605f","size":{"x":32,"y":1,"z":15}},{"blockCount":124,"bytes":2692,"file":"chunks/y026-z000-x000.json","offset":{"x":0,"y":26,"z":0},"requirements":{"minecraft:cobbled_deepslate":61,"minecraft:sandstone":63},"sha256":"9e9326c75f3e4ff4acda34869fd8368f692e389383fb79b0b7e0dfec511e00d5","size":{"x":32,"y":1,"z":32}},{"blockCount":64,"bytes":1259,"file":"chunks/y026-z000-x032.json","offset":{"x":32,"y":26,"z":0},"requirements":{"minecraft:cobbled_deepslate":32,"minecraft:sandstone":32},"sha256":"162f9cefcf3d829e107f458d22218633905caff66743feca9544603ee742ad0a","size":{"x":32,"y":1,"z":32}},{"blockCount":64,"bytes":1259,"file":"chunks/y026-z000-x064.json","offset":{"x":64,"y":26,"z":0},"requirements":{"minecraft:cobbled_deepslate":32,"minecraft:sandstone":32},"sha256":"a667397665db09435ac0ba0a532179972a95467a04235ea70f0d71995c65b238","size":{"x":32,"y":1,"z":32}},{"blockCount":64,"bytes":1259,"file":"chunks/y026-z000-x096.json","offset":{"x":96,"y":26,"z":0},"requirements":{"minecraft:cobbled_deepslate":32,"minecraft:sandstone":32},"sha256":"d04611bb6b8a85709e4a600c7cd7eb088954c367fa31620940abeacb6f0fc4b4","size":{"x":32,"y":1,"z":32}},{"blockCount":64,"bytes":1260,"file":"chunks/y026-z000-x128.json","offset":{"x":128,"y":26,"z":0},"requirements":{"minecraft:cobbled_deepslate":32,"minecraft:sandstone":32},"sha256":"d0266cd88d5a32493ea2d8d7ca352ac0f7becdbbe7112b980eb3d6e7227d2dd2","size":{"x":32,"y":1,"z":32}},{"blockCount":64,"bytes":1260,"file":"chunks/y026-z000-x160.json","offset":{"x":160,"y":26,"z":0},"requirements":{"minecraft:cobbled_deepslate":32,"minecraft:sandstone":32},"sha256":"ff3055066d1422dc085e27b6cb52bc684f59a7240423e1ae1c349d0eb3c6e2ce","size":{"x":32,"y":1,"z":32}},{"blockCount":64,"bytes":1260,"file":"chunks/y026-z000-x192.json","offset":{"x":192,"y":26,"z":0},"requirements":{"minecraft:cobbled_deepslate":32,"minecraft:sandstone":32},"sha256":"232dc51d99486d72c826507a8c4d475c6c17050f3ba235140a87bcb79186a2fd","size":{"x":32,"y":1,"z":32}},{"blockCount":64,"bytes":1260,"file":"chunks/y026-z000-x224.json","offset":{"x":224,"y":26,"z":0},"requirements":{"minecraft:cobbled_deepslate":32,"minecraft:sandstone":32},"sha256":"c8ecb31155a011e784173edf56a067a25ddfa4f70dbe8f959c9193205ba6118f","size":{"x":32,"y":1,"z":32}},{"blockCount":64,"bytes":1260,"file":"chunks/y026-z000-x256.json","offset":{"x":256,"y":26,"z":0},"requirements":{"minecraft:cobbled_deepslate":32,"minecraft:sandstone":32},"sha256":"7ca189c7b9db1909a35b563906382bb9a5aa98b2c6e694cada89fd4d32b97f75","size":{"x":32,"y":1,"z":32}},{"blockCount":64,"bytes":1260,"file":"chunks/y026-z000-x288.json","offset":{"x":288,"y":26,"z":0},"requirements":{"minecraft:cobbled_deepslate":32,"minecraft:sandstone":32},"sha256":"2e7e5b128774c6385196ad295f36904b0b778cfcb752ae9c77f8962676962c39","size":{"x":32,"y":1,"z":32}},{"blockCount":64,"bytes":1260,"file":"chunks/y026-z000-x320.json","offset":{"x":320,"y":26,"z":0},"requirements":{"minecraft:cobbled_deepslate":32,"minecraft:sandstone":32},"sha256":"0121b2887f557b6aa1c0cdbbee8c9d854dfb0d2a08f8c44f8ac88a6c69f725b6","size":{"x":32,"y":1,"z":32}},{"blockCount":68,"bytes":1445,"file":"chunks/y026-z000-x352.json","offset":{"x":352,"y":26,"z":0},"requirements":{"minecraft:cobbled_deepslate":32,"minecraft:sandstone":32,"minecraft:stone_bricks":4},"sha256":"df3e5765214b73b92c1aaec09924751e895965586750b6173817d2c5efc5aed3","size":{"x":32,"y":1,"z":32}},{"blockCount":228,"bytes":5190,"file":"chunks/y026-z000-x384.json","offset":{"x":384,"y":26,"z":0},"requirements":{"minecraft:cobbled_deepslate":63,"minecraft:sandstone":61,"minecraft:stone_bricks":104},"sha256":"af752115944451e2523728e66aae165079a6badf0fdb02d58ab9daefb50fb1ae","size":{"x":32,"y":1,"z":32}},{"blockCount":64,"bytes":2163,"file":"chunks/y026-z032-x000.json","offset":{"x":0,"y":26,"z":32},"requirements":{"minecraft:cobbled_deepslate":32,"minecraft:sandstone":32},"sha256":"429e7e677c744bd81fb9a0212e233c44388f53df7377bc633586a2197457c354","size":{"x":32,"y":1,"z":32}},{"blockCount":240,"bytes":9384,"file":"chunks/y026-z032-x352.json","offset":{"x":352,"y":26,"z":32},"requirements":{"minecraft:stone_bricks":240},"sha256":"48c692c613ce455249f60a6bfac353f4ac8745dd6b49f5837d96501c9088ea87","size":{"x":32,"y":1,"z":32}},{"blockCount":337,"bytes":9105,"file":"chunks/y026-z032-x384.json","offset":{"x":384,"y":26,"z":32},"requirements":{"minecraft:cobbled_deepslate":32,"minecraft:glass":1,"minecraft:sandstone":32,"minecraft:stone_bricks":272},"sha256":"c735e6366f687ba66896818d48e1b637cbb52185b562331fd6bb4cda3c27646d","size":{"x":32,"y":1,"z":32}},{"blockCount":64,"bytes":2163,"file":"chunks/y026-z064-x000.json","offset":{"x":0,"y":26,"z":64},"requirements":{"minecraft:cobbled_deepslate":32,"minecraft:sandstone":32},"sha256":"ad912634fe8df3ab6cde1e66c906cec4562793f8aad1e81d8ae63135c483ee46","size":{"x":32,"y":1,"z":32}},{"blockCount":30,"bytes":817,"file":"chunks/y026-z064-x064.json","offset":{"x":64,"y":26,"z":64},"requirements":{"minecraft:stone_bricks":30},"sha256":"32df741e43e399f3f17a0011409c4d0095baf7058a54fc8531d88d6a172b9dc9","size":{"x":32,"y":1,"z":32}},{"blockCount":146,"bytes":2536,"file":"chunks/y026-z064-x096.json","offset":{"x":96,"y":26,"z":64},"requirements":{"minecraft:stone_bricks":146},"sha256":"1d8e8770ce82f0dc0217496f6a9cfda98f34356e47b82a4f5d7880314598ef04","size":{"x":32,"y":1,"z":32}},{"blockCount":115,"bytes":1701,"file":"chunks/y026-z064-x128.json","offset":{"x":128,"y":26,"z":64},"requirements":{"minecraft:stone_bricks":115},"sha256":"fd6c8dd955114b17b516b0fb7363affe1e639f8166e4dd7940a7d4f21a9ad6fd","size":{"x":32,"y":1,"z":32}},{"blockCount":1,"bytes":643,"file":"chunks/y026-z064-x192.json","offset":{"x":192,"y":26,"z":64},"requirements":{"minecraft:stone_bricks":1},"sha256":"2394b38ef45b3ef9985db68d075f6efb1285af96a6c0477389591570fda5e38a","size":{"x":32,"y":1,"z":32}},{"blockCount":1,"bytes":623,"file":"chunks/y026-z064-x224.json","offset":{"x":224,"y":26,"z":64},"requirements":{"minecraft:stone_bricks":1},"sha256":"326fb58a488eeeda1261451a6c5f917ef8a69bd82bf4618e2c5daf3a7bb94812","size":{"x":32,"y":1,"z":32}},{"blockCount":233,"bytes":9288,"file":"chunks/y026-z064-x256.json","offset":{"x":256,"y":26,"z":64},"requirements":{"minecraft:stone_bricks":233},"sha256":"437cda2f8e306f6b0884d0af56d0a0ec625aa95a25dbb18294d1a879574b1675","size":{"x":32,"y":1,"z":32}},{"blockCount":271,"bytes":7225,"file":"chunks/y026-z064-x288.json","offset":{"x":288,"y":26,"z":64},"requirements":{"minecraft:stone_bricks":271},"sha256":"b4da77e90fa2ab20859aeb756bb057ad256e061fe471b2b018c05958c18bc6fe","size":{"x":32,"y":1,"z":32}},{"blockCount":267,"bytes":4712,"file":"chunks/y026-z064-x320.json","offset":{"x":320,"y":26,"z":64},"requirements":{"minecraft:stone_bricks":267},"sha256":"3ae8505949a6444cba86be97ffc941d29e7781bb95b639bb45e95857f8c63b2a","size":{"x":32,"y":1,"z":32}},{"blockCount":241,"bytes":8348,"file":"chunks/y026-z064-x352.json","offset":{"x":352,"y":26,"z":64},"requirements":{"minecraft:stone_bricks":241},"sha256":"74bd9db6a9df0978f0ef2b6f05bedf23d5c18d31ad8cdf5ca1ff148681d36b53","size":{"x":32,"y":1,"z":32}},{"blockCount":79,"bytes":2743,"file":"chunks/y026-z064-x384.json","offset":{"x":384,"y":26,"z":64},"requirements":{"minecraft:cobbled_deepslate":32,"minecraft:sandstone":32,"minecraft:stone_bricks":15},"sha256":"1ce2b1107f56b8971898a22fa69d320d8dbc960bf9fa105b907eed4b95008176","size":{"x":32,"y":1,"z":32}},{"blockCount":64,"bytes":2163,"file":"chunks/y026-z096-x000.json","offset":{"x":0,"y":26,"z":96},"requirements":{"minecraft:cobbled_deepslate":32,"minecraft:sandstone":32},"sha256":"86992c393f220411921d1e2602c954af8e75227d95341cfb71f95b453eb0308e","size":{"x":32,"y":1,"z":32}},{"blockCount":21,"bytes":914,"file":"chunks/y026-z096-x032.json","offset":{"x":32,"y":26,"z":96},"requirements":{"minecraft:stone_bricks":21},"sha256":"635544749cf189c42e1120c7fb3af517cce0af05026a97e27bde905da2e9aae5","size":{"x":32,"y":1,"z":32}},{"blockCount":130,"bytes":1962,"file":"chunks/y026-z096-x064.json","offset":{"x":64,"y":26,"z":96},"requirements":{"minecraft:stone_bricks":130},"sha256":"855aca2d4b175e1c8ee35ea40487aa8e8d85f0dd6db2067e8dd6b548e6479450","size":{"x":32,"y":1,"z":32}},{"blockCount":172,"bytes":2281,"file":"chunks/y026-z096-x096.json","offset":{"x":96,"y":26,"z":96},"requirements":{"minecraft:stone_bricks":172},"sha256":"c69453c0acd2d749ab7fd5c973ae7a9c5e8f9a9c753458d94217c8e760c01e6f","size":{"x":32,"y":1,"z":32}},{"blockCount":240,"bytes":3363,"file":"chunks/y026-z096-x128.json","offset":{"x":128,"y":26,"z":96},"requirements":{"minecraft:stone_bricks":240},"sha256":"683076315add2a8e9786e808ac09647a94af61eb72029df778593a2fb4aed34e","size":{"x":32,"y":1,"z":32}},{"blockCount":32,"bytes":624,"file":"chunks/y026-z096-x160.json","offset":{"x":160,"y":26,"z":96},"requirements":{"minecraft:stone_bricks":32},"sha256":"db106e6cb4d88ca126278f6d350e0dfaffc3a0b60f02f6cdfde6d6dc02a6ca14","size":{"x":32,"y":1,"z":32}},{"blockCount":41,"bytes":1855,"file":"chunks/y026-z096-x192.json","offset":{"x":192,"y":26,"z":96},"requirements":{"minecraft:bricks":29,"minecraft:stone_bricks":12},"sha256":"fe50e6f826b10387bfc30cef2e8730f2caca6459021d7f9b37e1895b2a2f7633","size":{"x":32,"y":1,"z":32}},{"blockCount":34,"bytes":1784,"file":"chunks/y026-z096-x224.json","offset":{"x":224,"y":26,"z":96},"requirements":{"minecraft:bricks":26,"minecraft:stone_bricks":8},"sha256":"687c1f5fe815114ed8aa405b1211bb1741b7b2354c6de39921f2befc2fb35d85","size":{"x":32,"y":1,"z":32}},{"blockCount":545,"bytes":16413,"file":"chunks/y026-z096-x256.json","offset":{"x":256,"y":26,"z":96},"requirements":{"minecraft:stone_bricks":545},"sha256":"5fc38ea1ca32c0fced46fa41f3196206cbb8a8677b6bcf8f27ee9acfb976a759","size":{"x":32,"y":1,"z":32}},{"blockCount":151,"bytes":4828,"file":"chunks/y026-z096-x288.json","offset":{"x":288,"y":26,"z":96},"requirements":{"minecraft:stone_bricks":151},"sha256":"4317faa396a564711ac64ec6502c5be4e19db588f303630555b562c8ca565a42","size":{"x":32,"y":1,"z":32}},{"blockCount":1,"bytes":643,"file":"chunks/y026-z096-x320.json","offset":{"x":320,"y":26,"z":96},"requirements":{"minecraft:stone_bricks":1},"sha256":"0a6b3ca4cc381ebe86e998a8126346a60b88378103cbb3a7259777af6ed44b45","size":{"x":32,"y":1,"z":32}},{"blockCount":209,"bytes":5531,"file":"chunks/y026-z096-x352.json","offset":{"x":352,"y":26,"z":96},"requirements":{"minecraft:glass":19,"minecraft:polished_diorite":3,"minecraft:stone_bricks":187},"sha256":"be775cdaa9195a453e43ef67b851522fa20ce1ccf2f2591b0f37072ef77165a1","size":{"x":32,"y":1,"z":32}},{"blockCount":136,"bytes":4682,"file":"chunks/y026-z096-x384.json","offset":{"x":384,"y":26,"z":96},"requirements":{"minecraft:cobbled_deepslate":32,"minecraft:sandstone":32,"minecraft:stone_bricks":72},"sha256":"ae3a75ed842bbaecf9bec2e266cb6a7677ab373382e2979d434ce4e4f4282439","size":{"x":32,"y":1,"z":32}},{"blockCount":184,"bytes":2725,"file":"chunks/y026-z128-x000.json","offset":{"x":0,"y":26,"z":128},"requirements":{"minecraft:cobbled_deepslate":32,"minecraft:sandstone":32,"minecraft:stone_bricks":120},"sha256":"d73afd765db968319b3de21973ac119ef12b84dbac99b4c0e552818d3aa72aa6","size":{"x":32,"y":1,"z":32}},{"blockCount":242,"bytes":3124,"file":"chunks/y026-z128-x032.json","offset":{"x":32,"y":26,"z":128},"requirements":{"minecraft:stone_bricks":242},"sha256":"acdff3e1b989dc6c7c9ba600107f07dfd2cbfe7514aba1ace48b76c9bd3d0294","size":{"x":32,"y":1,"z":32}},{"blockCount":91,"bytes":2225,"file":"chunks/y026-z128-x064.json","offset":{"x":64,"y":26,"z":128},"requirements":{"minecraft:stone_bricks":91},"sha256":"4f674ceed0c246eec53aec2561c451e34a10e7205fe3090a1d077510ccd83759","size":{"x":32,"y":1,"z":32}},{"blockCount":36,"bytes":1299,"file":"chunks/y026-z128-x096.json","offset":{"x":96,"y":26,"z":128},"requirements":{"minecraft:stone_bricks":36},"sha256":"6e77a08d7a8f7131e224f084308fe5b7d5cfaf861f4c4b95fa7cce8309ccd7aa","size":{"x":32,"y":1,"z":32}},{"blockCount":143,"bytes":3435,"file":"chunks/y026-z128-x128.json","offset":{"x":128,"y":26,"z":128},"requirements":{"minecraft:cobbled_deepslate":2,"minecraft:glass":2,"minecraft:polished_diorite":5,"minecraft:stone_bricks":134},"sha256":"80f4efd54042a36b5403f53462157726ffc163df984a9e95430094c342cc3906","size":{"x":32,"y":1,"z":32}},{"blockCount":118,"bytes":1745,"file":"chunks/y026-z128-x160.json","offset":{"x":160,"y":26,"z":128},"requirements":{"minecraft:glass":11,"minecraft:stone_bricks":107},"sha256":"eae9f1594a3ff03f5f7f33302ed1015779312b420bc3689f83f72c7967e9041b","size":{"x":32,"y":1,"z":32}},{"blockCount":95,"bytes":2671,"file":"chunks/y026-z128-x192.json","offset":{"x":192,"y":26,"z":128},"requirements":{"minecraft:bricks":23,"minecraft:glass":4,"minecraft:stone_bricks":68},"sha256":"85cda3a458c79f8e3c61d4863a215b4e31909fd5390d0b5c76262cd8ce4712ad","size":{"x":32,"y":1,"z":32}},{"blockCount":42,"bytes":1999,"file":"chunks/y026-z128-x224.json","offset":{"x":224,"y":26,"z":128},"requirements":{"minecraft:bricks":38,"minecraft:glass":3,"minecraft:stone_bricks":1},"sha256":"7e85f9a7a6d26e06e7e0511d1ca3ba6719d9a93b0d91384bad4ac5edbc17abba","size":{"x":32,"y":1,"z":32}},{"blockCount":518,"bytes":12236,"file":"chunks/y026-z128-x256.json","offset":{"x":256,"y":26,"z":128},"requirements":{"minecraft:glass":1,"minecraft:stone_bricks":517},"sha256":"fb26b2a83df152c3cb391f9f1b33262e73502dcb55b15aec1ccaf321cbc120ba","size":{"x":32,"y":1,"z":32}},{"blockCount":28,"bytes":1230,"file":"chunks/y026-z128-x320.json","offset":{"x":320,"y":26,"z":128},"requirements":{"minecraft:stone_bricks":28},"sha256":"7fe9f261db8671345beba1617073853e880f2324b2c1ce63067df249cd7346af","size":{"x":32,"y":1,"z":32}},{"blockCount":176,"bytes":3049,"file":"chunks/y026-z128-x352.json","offset":{"x":352,"y":26,"z":128},"requirements":{"minecraft:stone_bricks":176},"sha256":"4eb58548694987073cd1d63b449dd81cc055a006cac658d867cd98c4d4bef2ab","size":{"x":32,"y":1,"z":32}},{"blockCount":162,"bytes":5520,"file":"chunks/y026-z128-x384.json","offset":{"x":384,"y":26,"z":128},"requirements":{"minecraft:cobbled_deepslate":29,"minecraft:sandstone":29,"minecraft:stone_bricks":104},"sha256":"97b9addd814d523bbe17f45c6f5d784e030a4af412fedfb80b12ea4bdbe5eeb4","size":{"x":32,"y":1,"z":32}},{"blockCount":64,"bytes":2164,"file":"chunks/y026-z160-x000.json","offset":{"x":0,"y":26,"z":160},"requirements":{"minecraft:cobbled_deepslate":32,"minecraft:sandstone":32},"sha256":"73ec2db91bb9beaea1eae348ff809b3898535339736672e6f0b27f3a7168b6f8","size":{"x":32,"y":1,"z":32}},{"blockCount":3,"bytes":642,"file":"chunks/y026-z160-x032.json","offset":{"x":32,"y":26,"z":160},"requirements":{"minecraft:stone_bricks":3},"sha256":"03b33da521f50c566ef1ecaf618d051be1b0b96d799ad1308c57f1e5e771d4c4","size":{"x":32,"y":1,"z":32}},{"blockCount":103,"bytes":1832,"file":"chunks/y026-z160-x064.json","offset":{"x":64,"y":26,"z":160},"requirements":{"minecraft:stone_bricks":103},"sha256":"111e5b654d2dd5a95509dabb88173aef7685f106d4aa9fa6477a33e38d997fc8","size":{"x":32,"y":1,"z":32}},{"blockCount":204,"bytes":2418,"file":"chunks/y026-z160-x096.json","offset":{"x":96,"y":26,"z":160},"requirements":{"minecraft:stone_bricks":204},"sha256":"47813314560c193283ea68c6516497991a06ef3cb27a60f6b486c353f060aa09","size":{"x":32,"y":1,"z":32}},{"blockCount":255,"bytes":3161,"file":"chunks/y026-z160-x128.json","offset":{"x":128,"y":26,"z":160},"requirements":{"minecraft:stone_bricks":255},"sha256":"74ebac6ae1a4dd0c9cba877680ae326c46b5b3f312bd41bc33d68424e2e3e46a","size":{"x":32,"y":1,"z":32}},{"blockCount":18,"bytes":1313,"file":"chunks/y026-z160-x160.json","offset":{"x":160,"y":26,"z":160},"requirements":{"minecraft:cobbled_deepslate":18},"sha256":"c99750589d7d7652de0b643cc1e983a1291fb4f0ef7cee28aa901c8249c2fab2","size":{"x":32,"y":1,"z":32}},{"blockCount":5,"bytes":754,"file":"chunks/y026-z160-x192.json","offset":{"x":192,"y":26,"z":160},"requirements":{"minecraft:bricks":5},"sha256":"9d6f5e742b7c2ad3bbbcf109be355fdc116251c12e35308863bcf620ca68e0a8","size":{"x":32,"y":1,"z":32}},{"blockCount":23,"bytes":1439,"file":"chunks/y026-z160-x224.json","offset":{"x":224,"y":26,"z":160},"requirements":{"minecraft:bricks":13,"minecraft:stone_bricks":10},"sha256":"fbbf613ae5baae7b538f18faf962954b6246cdbda853333c2c9eb2f30ad60791","size":{"x":32,"y":1,"z":32}},{"blockCount":509,"bytes":16607,"file":"chunks/y026-z160-x256.json","offset":{"x":256,"y":26,"z":160},"requirements":{"minecraft:stone_bricks":509},"sha256":"ad0352b11eeee4c19c77494940e5dbf0ec42b9c8fbab40a1a1536063b4d3e800","size":{"x":32,"y":1,"z":32}},{"blockCount":251,"bytes":7041,"file":"chunks/y026-z160-x288.json","offset":{"x":288,"y":26,"z":160},"requirements":{"minecraft:stone_bricks":251},"sha256":"a2b8586e122a08326b218bcba86300f3dfb1d1ce48e1af2e725f249cc54472f2","size":{"x":32,"y":1,"z":32}},{"blockCount":127,"bytes":686,"file":"chunks/y026-z160-x320.json","offset":{"x":320,"y":26,"z":160},"requirements":{"minecraft:stone_bricks":127},"sha256":"f48f2ce05097b974412b43181060179eedc4a965534e4954e0fdee0d2914946b","size":{"x":32,"y":1,"z":32}}],"schema":1}
