{"entries":[{"blockCount":256,"bytes":6927,"file":"chunks/y026-z160-x352.json","offset":{"x":352,"y":26,"z":160},"requirements":{"minecraft:glass":18,"minecraft:oak_planks":4,"minecraft:stone_bricks":234},"sha256":"b99a2cf9350647162f52595533738f7a05f195705607198065bac0d0f4da427f","size":{"x":32,"y":1,"z":32}},{"blockCount":115,"bytes":3942,"file":"chunks/y026-z160-x384.json","offset":{"x":384,"y":26,"z":160},"requirements":{"minecraft:cobbled_deepslate":32,"minecraft:sandstone":32,"minecraft:stone_bricks":51},"sha256":"9989aca6959a2dccd8489bbddaec3acc86267234e7085fb9e32283addf900017","size":{"x":32,"y":1,"z":32}},{"blockCount":64,"bytes":2164,"file":"chunks/y026-z192-x000.json","offset":{"x":0,"y":26,"z":192},"requirements":{"minecraft:cobbled_deepslate":32,"minecraft:sandstone":32},"sha256":"299fff1fc1a4870b5af046bc56ba596c929537899266a35536ea9e6a3d10ff59","size":{"x":32,"y":1,"z":32}},{"blockCount":90,"bytes":2147,"file":"chunks/y026-z192-x096.json","offset":{"x":96,"y":26,"z":192},"requirements":{"minecraft:stone_bricks":90},"sha256":"3602d86328b590c00ba03d3747788242a11c4207b2f18c8a4a2a1af67a7110ee","size":{"x":32,"y":1,"z":32}},{"blockCount":37,"bytes":1384,"file":"chunks/y026-z192-x128.json","offset":{"x":128,"y":26,"z":192},"requirements":{"minecraft:stone_bricks":37},"sha256":"e2d8d9bb10b8e104c445f8e746dab901aa114ee03c222166770c23ac8595cd58","size":{"x":32,"y":1,"z":32}},{"blockCount":1,"bytes":643,"file":"chunks/y026-z192-x160.json","offset":{"x":160,"y":26,"z":192},"requirements":{"minecraft:stone_bricks":1},"sha256":"5b90896e38694207e7491538e0e1d53a274288d1717f77a878e5f41e64991c2c","size":{"x":32,"y":1,"z":32}},{"blockCount":120,"bytes":5166,"file":"chunks/y026-z192-x256.json","offset":{"x":256,"y":26,"z":192},"requirements":{"minecraft:stone_bricks":120},"sha256":"b22c30c83660b34a2a9365efcd959ff084caec4df64251304e906947fcb9b94c","size":{"x":32,"y":1,"z":32}},{"blockCount":127,"bytes":4314,"file":"chunks/y026-z192-x288.json","offset":{"x":288,"y":26,"z":192},"requirements":{"minecraft:stone_bricks":127},"sha256":"a875ae8b0c317257d47ad3565513d79019c4ef63999b52ff2dc09bf1e03841c2","size":{"x":32,"y":1,"z":32}},{"blockCount":128,"bytes":4199,"file":"chunks/y026-z192-x320.json","offset":{"x":320,"y":26,"z":192},"requirements":{"minecraft:stone_bricks":128},"sha256":"0da26323e5ada78a7c775d1bb054a2dcd4389e5259faad3a2326085dfa7b24d7","size":{"x":32,"y":1,"z":32}},{"blockCount":64,"bytes":2949,"file":"chunks/y026-z192-x352.json","offset":{"x":352,"y":26,"z":192},"requirements":{"minecraft:stone_bricks":64},"sha256":"e023b98d8365621ba00da2439889e6ed8ae5687b6aac995375a7a44cb78818b5","size":{"x":32,"y":1,"z":32}},{"blockCount":64,"bytes":2166,"file":"chunks/y026-z192-x384.json","offset":{"x":384,"y":26,"z":192},"requirements":{"minecraft:cobbled_deepslate":32,"minecraft:sandstone":32},"sha256":"f5affed6f39501e1aa1423e79b2b368c16b2b32a799e5154217461f32d6c7f42","size":{"x":32,"y":1,"z":32}},{"blockCount":90,"bytes":1822,"file":"chunks/y026-z224-x000.json","offset":{"x":0,"y":26,"z":224},"requirements":{"minecraft:cobbled_deepslate":44,"minecraft:sandstone":46},"sha256":"b45ce963f15c7d37b3263a66f7ceb2a87f74b077a970ef9d14fe39fbfdeddf14","size":{"x":32,"y":1,"z":15}},{"blockCount":64,"bytes":1261,"file":"chunks/y026-z224-x032.json","offset":{"x":32,"y":26,"z":224},"requirements":{"minecraft:cobbled_deepslate":32,"minecraft:sandstone":32},"sha256":"e37ecc93e20af473786c64c9ef247aa25b89a23b724b8efe6fe287a2030ac15d","size":{"x":32,"y":1,"z":15}},{"blockCount":64,"bytes":1261,"file":"chunks/y026-z224-x064.json","offset":{"x":64,"y":26,"z":224},"requirements":{"minecraft:cobbled_deepslate":32,"minecraft:sandstone":32},"sha256":"7d403bd1c8d0a3bf76e958ae9249aac9d8d4272bead2f1389e641b6f1ee1d6f7","size":{"x":32,"y":1,"z":15}},{"blockCount":64,"bytes":1261,"file":"chunks/y026-z224-x096.json","offset":{"x":96,"y":26,"z":224},"requirements":{"minecraft:cobbled_deepslate":32,"minecraft:sandstone":32},"sha256":"e14350f3d5770f89407e5806cc44601cf8bc8fd28256c989f56e88c180c84030","size":{"x":32,"y":1,"z":15}},{"blockCount":64,"bytes":1262,"file":"chunks/y026-z224-x128.json","offset":{"x":128,"y":26,"z":224},"requirements":{"minecraft:cobbled_deepslate":32,"minecraft:sandstone":32},"sha256":"1f175cd020b2ecabc400efe30c6c72c0cc96af6c623c15d1cfb5e6510941a16d","size":{"x":32,"y":1,"z":15}},{"blockCount":64,"bytes":1262,"file":"chunks/y026-z224-x160.json","offset":{"x":160,"y":26,"z":224},"requirements":{"minecraft:cobbled_deepslate":32,"minecraft:sandstone":32},"sha256":"be2ae12d10674eccc6a129f3df41f2051b9f28def9d8b6eab97b1ca6d38a8bf7","size":{"x":32,"y":1,"z":15}},{"blockCount":64,"bytes":1262,"file":"chunks/y026-z224-x192.json","offset":{"x":192,"y":26,"z":224},"requirements":{"minecraft:cobbled_deepslate":32,"minecraft:sandstone":32},"sha256":"9d5949cc7bb1660139726deba4cd8f11e4ef0febe4f03121812b4c85b72e4509","size":{"x":32,"y":1,"z":15}},{"blockCount":64,"bytes":1262,"file":"chunks/y026-z224-x224.json","offset":{"x":224,"y":26,"z":224},"requirements":{"minecraft:cobbled_deepslate":32,"minecraft:sandstone":32},"sha256":"a441b086c392ef966423851fa272a90aa045c92429ad673926a54b57ab3bc8a1","size":{"x":32,"y":1,"z":15}},{"blockCount":64,"bytes":1262,"file":"chunks/y026-z224-x256.json","offset":{"x":256,"y":26,"z":224},"requirements":{"minecraft:cobbled_deepslate":32,"minecraft:sandstone":32},"sha256":"3579d2c355d7c1b8f25dd242f8034834396e21173a5b9abd711bfdd66c6b7bee","size":{"x":32,"y":1,"z":15}},{"blockCount":64,"bytes":1262,"file":"chunks/y026-z224-x288.json","offset":{"x":288,"y":26,"z":224},"requirements":{"minecraft:cobbled_deepslate":32,"minecraft:sandstone":32},"sha256":"f598e8d3f9c762b6104d22276a72b2c766d9fbba21d2a30d9ca454151fc413a7","size":{"x":32,"y":1,"z":15}},{"blockCount":64,"bytes":1262,"file":"chunks/y026-z224-x320.json","offset":{"x":320,"y":26,"z":224},"requirements":{"minecraft:cobbled_deepslate":32,"minecraft:sandstone":32},"sha256":"7f1ade89deb4db05cf37e4a6aa63cf60474587e588dda0eea87ec98b17f4f7e6","size":{"x":32,"y":1,"z":15}},{"blockCount":64,"bytes":1262,"file":"chunks/y026-z224-x352.json","offset":{"x":352,"y":26,"z":224},"requirements":{"minecraft:cobbled_deepslate":32,"minecraft:sandstone":32},"sha256":"e7ea54d70469167d1d727e7a1ac309512ee862d77fcf9fc4e18e98b281612771","size":{"x":32,"y":1,"z":15}},{"blockCount":90,"bytes":1881,"file":"chunks/y026-z224-x384.json","offset":{"x":384,"y":26,"z":224},"requirements":{"minecraft:cobbled_deepslate":45,"minecraft:sandstone":45},"sha256":"014dd755bf88b5ddd0ac24bc0717d0711d749add9ee64d4c7167d70d7ece29bb","size":{"x":32,"y":1,"z":15}},{"blockCount":118,"bytes":3423,"file":"chunks/y027-z000-x352.json","offset":{"x":352,"y":27,"z":0},"requirements":{"minecraft:stone_bricks":118},"sha256":"ea2beab6250cda2948141408f7c3962a5d58eb88613ce0c9bdea37ace1215870","size":{"x":32,"y":1,"z":32}},{"blockCount":60,"bytes":1909,"file":"chunks/y027-z000-x384.json","offset":{"x":384,"y":27,"z":0},"requirements":{"minecraft:spruce_planks":2,"minecraft:stone_bricks":58},"sha256":"18442f3cb2e6132fe08725e88f2b3b85f01a299a8de65f3fae0a687cdc4678f4","size":{"x":32,"y":1,"z":32}},{"blockCount":92,"bytes":1746,"file":"chunks/y027-z032-x064.json","offset":{"x":64,"y":27,"z":32},"requirements":{"minecraft:bricks":5,"minecraft:stone_bricks":87},"sha256":"76bd9d6a5252a604db7050096770f54f92514e4a8844d409d0cd7dbd97e002d4","size":{"x":32,"y":1,"z":32}},{"blockCount":159,"bytes":708,"file":"chunks/y027-z032-x096.json","offset":{"x":96,"y":27,"z":32},"requirements":{"minecraft:bricks":31,"minecraft:stone_bricks":128},"sha256":"d4391b9c2fc95abbef1df9692a936f1e0c25470484b2f608bb82d826cacc7417","size":{"x":32,"y":1,"z":32}},{"blockCount":155,"bytes":1132,"file":"chunks/y027-z032-x128.json","offset":{"x":128,"y":27,"z":32},"requirements":{"minecraft:bricks":26,"minecraft:stone_bricks":129},"sha256":"815e9d8eede921ce6224eb9362d3d4579407887b39290800910246d5db1ce246","size":{"x":32,"y":1,"z":32}},{"blockCount":37,"bytes":1189,"file":"chunks/y027-z032-x160.json","offset":{"x":160,"y":27,"z":32},"requirements":{"minecraft:stone_bricks":37},"sha256":"05b051108bc7c43682f7ed4598dafe94b97accada7a89dec6a4560d98618535b","size":{"x":32,"y":1,"z":32}},{"blockCount":143,"bytes":2465,"file":"chunks/y027-z032-x352.json","offset":{"x":352,"y":27,"z":32},"requirements":{"minecraft:stone_bricks":143},"sha256":"01f627c730f8683adc4138dc22b884c926729be3ec8b8ff6f7319519cdad803d","size":{"x":32,"y":1,"z":32}},{"blockCount":175,"bytes":4107,"file":"chunks/y027-z032-x384.json","offset":{"x":384,"y":27,"z":32},"requirements":{"minecraft:stone_bricks":175},"sha256":"53721ce57c543d97bbcb6ef78b2ae71a804e4082bdca104144601682fbd6e2f4","size":{"x":32,"y":1,"z":32}},{"blockCount":49,"bytes":1889,"file":"chunks/y027-z064-x064.json","offset":{"x":64,"y":27,"z":64},"requirements":{"minecraft:stone_bricks":49},"sha256":"51d6b0a1422718eb08f71cb4a446839bf7d60e7cdda6cd9060bc34b8088e5eff","size":{"x":32,"y":1,"z":32}},{"blockCount":150,"bytes":3101,"file":"chunks/y027-z064-x096.json","offset":{"x":96,"y":27,"z":64},"requirements":{"minecraft:stone_bricks":150},"sha256":"3b7683ddb61ff8fdc62cf1dcae55630dca86b95f938978406be74f8a0834e130","size":{"x":32,"y":1,"z":32}},{"blockCount":61,"bytes":1694,"file":"chunks/y027-z064-x128.json","offset":{"x":128,"y":27,"z":64},"requirements":{"minecraft:stone_bricks":61},"sha256":"bd6c9402046f3da64e900bf058c8c553bd0c5f9eb943c14e31a1f8280d5a2680","size":{"x":32,"y":1,"z":32}},{"blockCount":52,"bytes":1850,"file":"chunks/y027-z064-x160.json","offset":{"x":160,"y":27,"z":64},"requirements":{"minecraft:stone_bricks":52},"sha256":"572264305fed09038129cd6300e69c282c33d23789e1a89c735b3f2ecc937639","size":{"x":32,"y":1,"z":32}},{"blockCount":33,"bytes":1181,"file":"chunks/y027-z064-x192.json","offset":{"x":192,"y":27,"z":64},"requirements":{"minecraft:stone_bricks":33},"sha256":"8142b51576f5f8e21cd69659f0f4b826f569f9919d01e32f43cd4371474c9772","size":{"x":32,"y":1,"z":32}},{"blockCount":53,"bytes":1504,"file":"chunks/y027-z064-x224.json","offset":{"x":224,"y":27,"z":64},"requirements":{"minecraft:stone_bricks":53},"sha256":"18ec9d299cda2c2779bd1ebd5b04d43f454f88c31d50938f18d2c3bdc05aec3a","size":{"x":32,"y":1,"z":32}},{"blockCount":20,"bytes":1027,"file":"chunks/y027-z064-x288.json","offset":{"x":288,"y":27,"z":64},"requirements":{"minecraft:stone_bricks":20},"sha256":"fbafb3349377bb11b594ec442bed01cd243e5f11ff8d3e7c4d8a119d4dbde1ac","size":{"x":32,"y":1,"z":32}},{"blockCount":2,"bytes":647,"file":"chunks/y027-z064-x320.json","offset":{"x":320,"y":27,"z":64},"requirements":{"minecraft:polished_diorite":2},"sha256":"1a2e16a2a95478a67ad3756eb071a239669f5cadef545d07e7162b8c9f9b2950","size":{"x":32,"y":1,"z":32}},{"blockCount":18,"bytes":881,"file":"chunks/y027-z064-x352.json","offset":{"x":352,"y":27,"z":64},"requirements":{"minecraft:polished_diorite":18},"sha256":"5230496e8a3efc8777196f7d467714cad35174bf528e2fc2d5cf1d08a100346c","size":{"x":32,"y":1,"z":32}},{"blockCount":64,"bytes":2077,"file":"chunks/y027-z096-x000.json","offset":{"x":0,"y":27,"z":96},"requirements":{"minecraft:stone_bricks":64},"sha256":"55ab25c5c35c772270f1f7b5755556d274b3a44e0aa23a3a22840e7c1b80a67a","size":{"x":32,"y":1,"z":32}},{"blockCount":70,"bytes":1657,"file":"chunks/y027-z096-x032.json","offset":{"x":32,"y":27,"z":96},"requirements":{"minecraft:stone_bricks":70},"sha256":"2ad58141b67cffa19c2cd7ee2714bf10bf9ead9449ed8818fc4bc1a69d87d9e5","size":{"x":32,"y":1,"z":32}},{"blockCount":137,"bytes":2209,"file":"chunks/y027-z096-x064.json","offset":{"x":64,"y":27,"z":96},"requirements":{"minecraft:stone_bricks":137},"sha256":"e53180408735021faac538140954b1cee7edf7b8279841fff20ea193ce6e122c","size":{"x":32,"y":1,"z":32}},{"blockCount":175,"bytes":2832,"file":"chunks/y027-z096-x096.json","offset":{"x":96,"y":27,"z":96},"requirements":{"minecraft:stone_bricks":175},"sha256":"084619a325bdbd3ec3f7992d5544fca750a23a4e325b6fcf77742df6ad711f25","size":{"x":32,"y":1,"z":32}},{"blockCount":201,"bytes":3758,"file":"chunks/y027-z096-x128.json","offset":{"x":128,"y":27,"z":96},"requirements":{"minecraft:stone_bricks":201},"sha256":"c07c4cb78336f3f3cde0340ecb71b2dafec442f6fe0602dd0eed8234c0f44321","size":{"x":32,"y":1,"z":32}},{"blockCount":73,"bytes":1310,"file":"chunks/y027-z096-x160.json","offset":{"x":160,"y":27,"z":96},"requirements":{"minecraft:stone_bricks":73},"sha256":"6bc4eba893ab19fbd8567aa10a30cd1f1844f8ce50782f05081f16dedcea46a7","size":{"x":32,"y":1,"z":32}},{"blockCount":54,"bytes":1799,"file":"chunks/y027-z096-x192.json","offset":{"x":192,"y":27,"z":96},"requirements":{"minecraft:bricks":20,"minecraft:stone_bricks":34},"sha256":"62083678fa91eaa5ef44348152eeafb39be11b8c0c4c1fe063759430f51cc75b","size":{"x":32,"y":1,"z":32}},{"blockCount":129,"bytes":2617,"file":"chunks/y027-z096-x224.json","offset":{"x":224,"y":27,"z":96},"requirements":{"minecraft:bricks":22,"minecraft:stone_bricks":107},"sha256":"26c81aaf904771075b7c5d47e8056ae60c62404a3d7c5a5df22075b96bfba22e","size":{"x":32,"y":1,"z":32}},{"blockCount":30,"bytes":1182,"file":"chunks/y027-z096-x256.json","offset":{"x":256,"y":27,"z":96},"requirements":{"minecraft:stone_bricks":30},"sha256":"b791d7d4a43124cd34e40e8e2eec3d2478827a01e54a2b6573f60f2de0638b33","size":{"x":32,"y":1,"z":32}},{"blockCount":16,"bytes":942,"file":"chunks/y027-z096-x288.json","offset":{"x":288,"y":27,"z":96},"requirements":{"minecraft:spruce_planks":6,"minecraft:stone_bricks":10},"sha256":"91112e27857ffb84bd5c46908198fb71f9a677753a385bee49b23e606bf01a53","size":{"x":32,"y":1,"z":32}},{"blockCount":25,"bytes":1544,"file":"chunks/y027-z096-x352.json","offset":{"x":352,"y":27,"z":96},"requirements":{"minecraft:polished_diorite":25},"sha256":"59d347a5c9a3e149357eea71489e34b9bb790e1453cab60c6b8c2f22440b0421","size":{"x":32,"y":1,"z":32}},{"blockCount":89,"bytes":2780,"file":"chunks/y027-z128-x000.json","offset":{"x":0,"y":27,"z":128},"requirements":{"minecraft:stone_bricks":89},"sha256":"d79fadbf95b96ba35b46b9e3fda39ca25eb24bd7e723252c887c337f997c3940","size":{"x":32,"y":1,"z":32}},{"blockCount":166,"bytes":3238,"file":"chunks/y027-z128-x032.json","offset":{"x":32,"y":27,"z":128},"requirements":{"minecraft:stone_bricks":166},"sha256":"a6e326d201f81cb64d9f6edf3a731599b0469e2da9123414e4344f4da35b3c1c","size":{"x":32,"y":1,"z":32}},{"blockCount":90,"bytes":2224,"file":"chunks/y027-z128-x064.json","offset":{"x":64,"y":27,"z":128},"requirements":{"minecraft:stone_bricks":90},"sha256":"a7651aa62e8132b20da8b2c97e91939705b1363f5ad8ba851934b88fc937eccd","size":{"x":32,"y":1,"z":32}},{"blockCount":40,"bytes":1357,"file":"chunks/y027-z128-x096.json","offset":{"x":96,"y":27,"z":128},"requirements":{"minecraft:stone_bricks":40},"sha256":"3e2da1f49bba3160d98ce5701e9d3126df211352f446bfdb3e0d01260c738859","size":{"x":32,"y":1,"z":32}},{"blockCount":135,"bytes":3384,"file":"chunks/y027-z128-x128.json","offset":{"x":128,"y":27,"z":128},"requirements":{"minecraft:glass":1,"minecraft:polished_diorite":5,"minecraft:stone_bricks":129},"sha256":"a4594776d81089d7a05a8173b95eb7952a117b7067cbf6f01f67768d6bb77605","size":{"x":32,"y":1,"z":32}},{"blockCount":145,"bytes":1498,"file":"chunks/y027-z128-x160.json","offset":{"x":160,"y":27,"z":128},"requirements":{"minecraft:glass":8,"minecraft:stone_bricks":137},"sha256":"8e8f86ad216acb479608472deca7b2b81e8b99cfb030aa8160f40cc5d3f1a032","size":{"x":32,"y":1,"z":32}},{"blockCount":101,"bytes":2771,"file":"chunks/y027-z128-x192.json","offset":{"x":192,"y":27,"z":128},"requirements":{"minecraft:bricks":22,"minecraft:glass":10,"minecraft:stone_bricks":69},"sha256":"2db7658e2fac3b9b15f90aabb2ca54aae416b32f0cc2e04f9cdc1959ed060303","size":{"x":32,"y":1,"z":32}},{"blockCount":190,"bytes":3762,"file":"chunks/y027-z128-x224.json","offset":{"x":224,"y":27,"z":128},"requirements":{"minecraft:bricks":50,"minecraft:glass":5,"minecraft:stone_bricks":135},"sha256":"ef84e94bf4da4b1bc9cf7df0b176d98efa1dfe439f6815ec03237239b196f336","size":{"x":32,"y":1,"z":32}},{"blockCount":2,"bytes":684,"file":"chunks/y027-z128-x288.json","offset":{"x":288,"y":27,"z":128},"requirements":{"minecraft:stone_bricks":2},"sha256":"d4fec47abd004d54077d105942e85809c8eb2d9815cc8792d36973cfd0dcffd3","size":{"x":32,"y":1,"z":32}},{"blockCount":22,"bytes":1337,"file":"chunks/y027-z128-x320.json","offset":{"x":320,"y":27,"z":128},"requirements":{"minecraft:polished_diorite":4,"minecraft:stone_bricks":18},"sha256":"d93a30a992e5610beb9d30e773a0b9609a447856caf6fa6a86292e9d93c8ad6c","size":{"x":32,"y":1,"z":32}},{"blockCount":4,"bytes":760,"file":"chunks/y027-z128-x384.json","offset":{"x":384,"y":27,"z":128},"requirements":{"minecraft:stone_bricks":4},"sha256":"998df930ac998b6833d4657fbdcc579671a4ee4d9274ca1da33be0ba1ab987a6","size":{"x":32,"y":1,"z":32}},{"blockCount":50,"bytes":1692,"file":"chunks/y027-z160-x000.json","offset":{"x":0,"y":27,"z":160},"requirements":{"minecraft:stone_bricks":50},"sha256":"d8230ce493d115fb2c6980102d2bb385aac9f72bfa5dca7e60224555fbbf0d17","size":{"x":32,"y":1,"z":32}},{"blockCount":51,"bytes":1445,"file":"chunks/y027-z160-x032.json","offset":{"x":32,"y":27,"z":160},"requirements":{"minecraft:stone_bricks":51},"sha256":"47898e98e9ada520b7619b5c4a9395b9141da74ba5edb3fb9636647c16121934","size":{"x":32,"y":1,"z":32}},{"blockCount":90,"bytes":2174,"file":"chunks/y027-z160-x064.json","offset":{"x":64,"y":27,"z":160},"requirements":{"minecraft:stone_bricks":90},"sha256":"8dae3e66f027851394eda1b724b2111efa899388973b6d1d5d1d698decddf5db","size":{"x":32,"y":1,"z":32}},{"blockCount":177,"bytes":3176,"file":"chunks/y027-z160-x096.json","offset":{"x":96,"y":27,"z":160},"requirements":{"minecraft:stone_bricks":177},"sha256":"ca27f4b7eb7255d64b233e9a6f46dd92001e7d5990ef7c3314c744ba331e472b","size":{"x":32,"y":1,"z":32}},{"blockCount":163,"bytes":3530,"file":"chunks/y027-z160-x128.json","offset":{"x":128,"y":27,"z":160},"requirements":{"minecraft:stone_bricks":163},"sha256":"14f3e0f3abe91c3c30a167153d2fcbca262c490f48af335cfd6000ff0c84b082","size":{"x":32,"y":1,"z":32}},{"blockCount":68,"bytes":2258,"file":"chunks/y027-z160-x160.json","offset":{"x":160,"y":27,"z":160},"requirements":{"minecraft:cobbled_deepslate":17,"minecraft:stone_bricks":51},"sha256":"08c6da132848c4d42b9ed1eb372a0261b870fd7a0678d86b079b9f196d44d6de","size":{"x":32,"y":1,"z":32}},{"blockCount":60,"bytes":1874,"file":"chunks/y027-z160-x192.json","offset":{"x":192,"y":27,"z":160},"requirements":{"minecraft:bricks":8,"minecraft:stone_bricks":52},"sha256":"dd8b99a6aad778ce5ece4a74c85201b6d4fbf25c33117efc19376b5e3541cac0","size":{"x":32,"y":1,"z":32}},{"blockCount":156,"bytes":3017,"file":"chunks/y027-z160-x224.json","offset":{"x":224,"y":27,"z":160},"requirements":{"minecraft:bricks":13,"minecraft:stone_bricks":143},"sha256":"7af92dfa6443fdaff366fdd40301dba89ef8d0e940f753045492aeb6e24f442d","size":{"x":32,"y":1,"z":32}},{"blockCount":31,"bytes":1221,"file":"chunks/y027-z160-x256.json","offset":{"x":256,"y":27,"z":160},"requirements":{"minecraft:stone_bricks":31},"sha256":"b71af8d8c2576470b5edd9b5071de0fc0f2d6f0cfe71b6ec5e3131d08d8f7d51","size":{"x":32,"y":1,"z":32}},{"blockCount":37,"bytes":1405,"file":"chunks/y027-z160-x288.json","offset":{"x":288,"y":27,"z":160},"requirements":{"minecraft:spruce_planks":6,"minecraft:stone_bricks":31},"sha256":"22e0dd518653fe09700530d6f33b01f626e5ed5c4afa421b7ff03ebcc588dc71","size":{"x":32,"y":1,"z":32}},{"blockCount":2,"bytes":628,"file":"chunks/y027-z160-x320.json","offset":{"x":320,"y":27,"z":160},"requirements":{"minecraft:polished_diorite":2},"sha256":"84ab46dc6b5016563a7c25e9bfe3fb3d2096ce2869a229827dc316646a7bf23c","size":{"x":32,"y":1,"z":32}},{"blockCount":67,"bytes":2488,"file":"chunks/y027-z160-x352.json","offset":{"x":352,"y":27,"z":160},"requirements":{"minecraft:oak_planks":16,"minecraft:polished_diorite":43,"minecraft:stone_bricks":8},"sha256":"d704cf3fe7f0f73ba0882b148ab92730ed202ff9b9b3a48871ff04e333808bc3","size":{"x":32,"y":1,"z":32}},{"blockCount":47,"bytes":1851,"file":"chunks/y027-z192-x064.json","offset":{"x":64,"y":27,"z":192},"requirements":{"minecraft:stone_bricks":47},"sha256":"bbe793456b25e8a7f06a92bf43ca06f449eb56ea35991247b4babf8239842d1c","size":{"x":32,"y":1,"z":32}},{"blockCount":120,"bytes":2450,"file":"chunks/y027-z192-x096.json","offset":{"x":96,"y":27,"z":192},"requirements":{"minecraft:stone_bricks":120},"sha256":"49adfbb8234f208183455c06e88e590ffbbb7b7b603799110197945d817ce88e","size":{"x":32,"y":1,"z":32}},{"blockCount":45,"bytes":1384,"file":"chunks/y027-z192-x128.json","offset":{"x":128,"y":27,"z":192},"requirements":{"minecraft:stone_bricks":45},"sha256":"1ef58d0d1c6f4e818e00585346c0f02770162da82cba8b24ea66c73648b2fe49","size":{"x":32,"y":1,"z":32}},{"blockCount":48,"bytes":1851,"file":"chunks/y027-z192-x160.json","offset":{"x":160,"y":27,"z":192},"requirements":{"minecraft:stone_bricks":48},"sha256":"9fcae54ca3956db06cb3ef4d407d560ca6dd9e01111588c53f3275233007bf3a","size":{"x":32,"y":1,"z":32}},{"blockCount":2,"bytes":642,"file":"chunks/y027-z224-x064.json","offset":{"x":64,"y":27,"z":224},"requirements":{"minecraft:stone_bricks":2},"sha256":"ee93b23b8bf9cabaa825d39cd5cbeab47f54a7bb120ef8b6a27bf5f550f6ec74","size":{"x":32,"y":1,"z":15}},{"blockCount":2,"bytes":642,"file":"chunks/y027-z224-x160.json","offset":{"x":160,"y":27,"z":224},"requirements":{"minecraft:stone_bricks":2},"sha256":"70e0424e463c1c3d3707e4a7e8b13713c86f7d4e5e1cf71fa8344facab3134b9","size":{"x":32,"y":1,"z":15}},{"blockCount":384,"bytes":4718,"file":"chunks/y028-z000-x352.json","offset":{"x":352,"y":28,"z":0},"requirements":{"minecraft:bricks":24,"minecraft:polished_diorite":45,"minecraft:sandstone":31,"minecraft:spruce_planks":7,"minecraft:stone_bricks":277},"sha256":"bb5d5a333593c2d94a3f08815401afee2a08e2bf4c87b3fd3cbe1116eabdf2ec","size":{"x":32,"y":1,"z":32}},{"blockCount":394,"bytes":5543,"file":"chunks/y028-z000-x384.json","offset":{"x":384,"y":28,"z":0},"requirements":{"minecraft:bricks":3,"minecraft:glass":2,"minecraft:polished_diorite":49,"minecraft:sandstone":35,"minecraft:spruce_planks":9,"minecraft:stone_bricks":296},"sha256":"09b4bf2bb52e689df66fb5144f954885083e3a252c6cf76643dd9873209df815","size":{"x":32,"y":1,"z":32}},{"blockCount":77,"bytes":1898,"file":"chunks/y028-z032-x064.json","offset":{"x":64,"y":28,"z":32},"requirements":{"minecraft:bricks":6,"minecraft:stone_bricks":71},"sha256":"4b6ac800e341ce2e51aa466d1ba7fbc569e4ec8cd8fcbe0e9441f7c36a554878","size":{"x":32,"y":1,"z":32}},{"blockCount":128,"bytes":646,"file":"chunks/y028-z032-x096.json","offset":{"x":96,"y":28,"z":32},"requirements":{"minecraft:stone_bricks":128},"sha256":"10097396ba12f1ab4bafb73c22a5f82407475fa2e732a0a8ba68ff9f400f2961","size":{"x":32,"y":1,"z":32}},{"blockCount":121,"bytes":1322,"file":"chunks/y028-z032-x128.json","offset":{"x":128,"y":28,"z":32},"requirements":{"minecraft:bricks":6,"minecraft:stone_bricks":115},"sha256":"b6bf92c2290e517ca5a949a028aa3382f92205acf80f53a0faa8ee69ec9d4d35","size":{"x":32,"y":1,"z":32}},{"blockCount":48,"bytes":1189,"file":"chunks/y028-z032-x160.json","offset":{"x":160,"y":28,"z":32},"requirements":{"minecraft:stone_bricks":48},"sha256":"395402562792a24bafc12e3a11af20ba76162954b933b693f3a58f37d1998ec3","size":{"x":32,"y":1,"z":32}},{"blockCount":311,"bytes":2303,"file":"chunks/y028-z032-x352.json","offset":{"x":352,"y":28,"z":32},"requirements":{"minecraft:bricks":38,"minecraft:glass":1,"minecraft:polished_diorite":4,"minecraft:spruce_planks":3,"minecraft:stone_bricks":265},"sha256":"6176f4284b43caabfe20eeca556fdfebdbafd7ed3db09144ed17fa53191db828","size":{"x":32,"y":1,"z":32}},{"blockCount":129,"bytes":2272,"file":"chunks/y028-z032-x384.json","offset":{"x":384,"y":28,"z":32},"requirements":{"minecraft:glass":7,"minecraft:spruce_planks":3,"minecraft:stone_bricks":119},"sha256":"8ee7e3635a6aac81fe6286fff9f13016cefb8ca9ab795a17e61aab96bbbf3b64","size":{"x":32,"y":1,"z":32}},{"blockCount":54,"bytes":1889,"file":"chunks/y028-z064-x064.json","offset":{"x":64,"y":28,"z":64},"requirements":{"minecraft:stone_bricks":54},"sha256":"a1337aa5c35ce4dae0983cbd26f5a6e873d34e29e864166fe031f5e2cfd5a58f","size":{"x":32,"y":1,"z":32}},{"blockCount":222,"bytes":3349,"file":"chunks/y028-z064-x096.json","offset":{"x":96,"y":28,"z":64},"requirements":{"minecraft:stone_bricks":222},"sha256":"3f2f2d9b3414022ab4ae7ac13a4610eee174db37827d5171943c781fc6230c42","size":{"x":32,"y":1,"z":32}},{"blockCount":85,"bytes":1583,"file":"chunks/y028-z064-x128.json","offset":{"x":128,"y":28,"z":64},"requirements":{"minecraft:stone_bricks":85},"sha256":"575972dd59d726a2f057e5f5e8a59fb21bec39c3c97431433816ca1c33b6734c","size":{"x":32,"y":1,"z":32}},{"blockCount":58,"bytes":1850,"file":"chunks/y028-z064-x160.json","offset":{"x":160,"y":28,"z":64},"requirements":{"minecraft:stone_bricks":58},"sha256":"175c5719e2ee48b0abac5b32d369a38e2b755ea4ef11fbace8fadc33f6f36a30","size":{"x":32,"y":1,"z":32}},{"blockCount":34,"bytes":1219,"file":"chunks/y028-z064-x192.json","offset":{"x":192,"y":28,"z":64},"requirements":{"minecraft:stone_bricks":34},"sha256":"9c9d0bf30d11a1c6ef53920a37891348afe0fe806ac789ee73c96796b30e6b42","size":{"x":32,"y":1,"z":32}},{"blockCount":55,"bytes":1542,"file":"chunks/y028-z064-x224.json","offset":{"x":224,"y":28,"z":64},"requirements":{"minecraft:stone_bricks":55},"sha256":"054e9aed654833a56d22297757232fdcf67e3b2d6b28f2f9638d1653b6b1b41d","size":{"x":32,"y":1,"z":32}},{"blockCount":12,"bytes":978,"file":"chunks/y028-z064-x288.json","offset":{"x":288,"y":28,"z":64},"requirements":{"minecraft:glass":3,"minecraft:spruce_planks":1,"minecraft:stone_bricks":8},"sha256":"bb6092dac69462a0b9d2b05566fbfb7787a45396b6065218e043548b4b2c97f2","size":{"x":32,"y":1,"z":32}},{"blockCount":1,"bytes":647,"file":"chunks/y028-z064-x320.json","offset":{"x":320,"y":28,"z":64},"requirements":{"minecraft:polished_diorite":1},"sha256":"bf6be2d0f4ead4cbd130f3c08fcacdaa446739e151650ad4195cc4760cd932c8","size":{"x":32,"y":1,"z":32}},{"blockCount":6,"bytes":841,"file":"chunks/y028-z064-x352.json","offset":{"x":352,"y":28,"z":64},"requirements":{"minecraft:polished_diorite":6},"sha256":"b71257976332809a2cd705768df4eaaf47ad97e7b56e491cdfd39cd112a67ce2","size":{"x":32,"y":1,"z":32}},{"blockCount":75,"bytes":2077,"file":"chunks/y028-z096-x000.json","offset":{"x":0,"y":28,"z":96},"requirements":{"minecraft:stone_bricks":75},"sha256":"23f72f3f0a72ef9d55456bc1bc149c4b5cc1c4dbb811869d7928257e0f5f7ed2","size":{"x":32,"y":1,"z":32}},{"blockCount":76,"bytes":1714,"file":"chunks/y028-z096-x032.json","offset":{"x":32,"y":28,"z":96},"requirements":{"minecraft:stone_bricks":76},"sha256":"464ec651b9a9918f61212989a6f807277fe742da4097161ae0de0e1a2cadd15e","size":{"x":32,"y":1,"z":32}},{"blockCount":164,"bytes":2755,"file":"chunks/y028-z096-x064.json","offset":{"x":64,"y":28,"z":96},"requirements":{"minecraft:stone_bricks":164},"sha256":"ccef2de147b666e242fad0fd2442557e5cbdb0d3148b26c88e54057d59479e88","size":{"x":32,"y":1,"z":32}},{"blockCount":350,"bytes":7188,"file":"chunks/y028-z096-x096.json","offset":{"x":96,"y":28,"z":96},"requirements":{"minecraft:stone_bricks":350},"sha256":"8cd4802afeaf4cc864b64e997e90ab5fcf0e0fb05f766fc40efbc89e7c7e74ea","size":{"x":32,"y":1,"z":32}},{"blockCount":281,"bytes":5526,"file":"chunks/y028-z096-x128.json","offset":{"x":128,"y":28,"z":96},"requirements":{"minecraft:stone_bricks":281},"sha256":"7a4a71881a693d0e41892215a6c0f41dbb4b7d16f0be23e826df5eeb8817c743","size":{"x":32,"y":1,"z":32}},{"blockCount":78,"bytes":1347,"file":"chunks/y028-z096-x160.json","offset":{"x":160,"y":28,"z":96},"requirements":{"minecraft:stone_bricks":78},"sha256":"5600c5f67177e15b032f050e5ebc0a09b4b08141b4fcf040a30dd8639c3b7525","size":{"x":32,"y":1,"z":32}},{"blockCount":59,"bytes":1740,"file":"chunks/y028-z096-x192.json","offset":{"x":192,"y":28,"z":96},"requirements":{"minecraft:bricks":19,"minecraft:stone_bricks":40},"sha256":"e58dde917c3a09675881c03a61478fd444d37303f3a5a643f69087a7c1035424","size":{"x":32,"y":1,"z":32}},{"blockCount":111,"bytes":2731,"file":"chunks/y028-z096-x224.json","offset":{"x":224,"y":28,"z":96},"requirements":{"minecraft:bricks":24,"minecraft:stone_bricks":87},"sha256":"176cf458c5d8404ca0435942c88edcf0acfca396ac21203f6d3b08151b671b64","size":{"x":32,"y":1,"z":32}},{"blockCount":16,"bytes":1057,"file":"chunks/y028-z096-x256.json","offset":{"x":256,"y":28,"z":96},"requirements":{"minecraft:glass":3,"minecraft:spruce_planks":1,"minecraft:stone_bricks":12},"sha256":"033b9e7d0d86ec7606d59747a04ae9aed0553ece1bf7a751e1439b9ed43c2cb2","size":{"x":32,"y":1,"z":32}},{"blockCount":6,"bytes":758,"file":"chunks/y028-z096-x288.json","offset":{"x":288,"y":28,"z":96},"requirements":{"minecraft:stone_bricks":6},"sha256":"21f40d3e3df279e4f92991ab834a77c914f2d2bc0dafb0520ce10f9cca207e47","size":{"x":32,"y":1,"z":32}},{"blockCount":8,"bytes":919,"file":"chunks/y028-z096-x352.json","offset":{"x":352,"y":28,"z":96},"requirements":{"minecraft:polished_diorite":8},"sha256":"b1b661f7914718225e0872e7f3a2baf7529b9a67d84e48cef9d2f60aa931e866","size":{"x":32,"y":1,"z":32}},{"blockCount":95,"bytes":2818,"file":"chunks/y028-z128-x000.json","offset":{"x":0,"y":28,"z":128},"requirements":{"minecraft:stone_bricks":95},"sha256":"4df9aafd4dcf49083c994402c22128c105954410b976fec55d0fa0d30446cfec","size":{"x":32,"y":1,"z":32}},{"blockCount":177,"bytes":3354,"file":"chunks/y028-z128-x032.json","offset":{"x":32,"y":28,"z":128},"requirements":{"minecraft:stone_bricks":177},"sha256":"9e1d1edeba2c1215571c8c57342f67b74bb4c7f96415e6c16a5f8fd14e13e04b","size":{"x":32,"y":1,"z":32}},{"blockCount":347,"bytes":3048,"file":"chunks/y028-z128-x064.json","offset":{"x":64,"y":28,"z":128},"requirements":{"minecraft:stone_bricks":347},"sha256":"2e70ed87690ca248146eefb05b616f0265ac1c137d1a7f08711dc612112954cf","size":{"x":32,"y":1,"z":32}},{"blockCount":427,"bytes":6455,"file":"chunks/y028-z128-x096.json","offset":{"x":96,"y":28,"z":128},"requirements":{"minecraft:stone_bricks":427},"sha256":"80dd38616a24b82978fbd74848bc67f7cd2c246383649636c923516387d67016","size":{"x":32,"y":1,"z":32}},{"blockCount":386,"bytes":5765,"file":"chunks/y028-z128-x128.json","offset":{"x":128,"y":28,"z":128},"requirements":{"minecraft:glass":2,"minecraft:polished_diorite":3,"minecraft:stone_bricks":381},"sha256":"5bf8d69af0f42cfc726564b69994d1718ddeee0315ea6d28645c6a3fd861318f","size":{"x":32,"y":1,"z":32}},{"blockCount":189,"bytes":2572,"file":"chunks/y028-z128-x160.json","offset":{"x":160,"y":28,"z":128},"requirements":{"minecraft:glass":17,"minecraft:stone_bricks":172},"sha256":"3d38c9a26491f0baf4815fe02500feb2e00fda87acad9a59440e10835c1f5e64","size":{"x":32,"y":1,"z":32}},{"blockCount":143,"bytes":3227,"file":"chunks/y028-z128-x192.json","offset":{"x":192,"y":28,"z":128},"requirements":{"minecraft:bricks":33,"minecraft:glass":15,"minecraft:stone_bricks":95},"sha256":"60214801c84c86426366d5212b63dfb1ac36d333c3ba05b6b14dfb96828cd685","size":{"x":32,"y":1,"z":32}},{"blockCount":151,"bytes":3573,"file":"chunks/y028-z128-x224.json","offset":{"x":224,"y":28,"z":128},"requirements":{"minecraft:bricks":42,"minecraft:glass":7,"minecraft:stone_bricks":102},"sha256":"54950877165d897ae72c2e40bc62da2f3cb47b46d3d8751a756fe6416e9f0305","size":{"x":32,"y":1,"z":32}},{"blockCount":4,"bytes":764,"file":"chunks/y028-z128-x320.json","offset":{"x":320,"y":28,"z":128},"requirements":{"minecraft:polished_diorite":4},"sha256":"efd46c01524fd91d84c0f1f16b145206791eb62a53d7978c4c99c6c74248b2db","size":{"x":32,"y":1,"z":32}},{"blockCount":56,"bytes":1768,"file":"chunks/y028-z160-x000.json","offset":{"x":0,"y":28,"z":160},"requirements":{"minecraft:stone_bricks":56},"sha256":"02729594a0653c0cfbbd83b031ddc4fc91ed2f0b75e477786f0a1c0f523685be","size":{"x":32,"y":1,"z":32}},{"blockCount":54,"bytes":1444,"file":"chunks/y028-z160-x032.json","offset":{"x":32,"y":28,"z":160},"requirements":{"minecraft:stone_bricks":54},"sha256":"cc69b448440e009d476ebb707fc1da4cd968a84b0357749bfd98bb5ee939bc1d","size":{"x":32,"y":1,"z":32}},{"blockCount":101,"bytes":2497,"file":"chunks/y028-z160-x064.json","offset":{"x":64,"y":28,"z":160},"requirements":{"minecraft:stone_bricks":101},"sha256":"bf77493eb7145308eee32905ea4e7315b8ec37617451e9bdef6e2c8035d9a7bc","size":{"x":32,"y":1,"z":32}},{"blockCount":311,"bytes":6527,"file":"chunks/y028-z160-x096.json","offset":{"x":96,"y":28,"z":160},"requirements":{"minecraft:stone_bricks":311},"sha256":"23c8d512742ca0f9c0eee47d06dfa877c4d13d04e736292a427952a365e83f6c","size":{"x":32,"y":1,"z":32}},{"blockCount":228,"bytes":4792,"file":"chunks/y028-z160-x128.json","offset":{"x":128,"y":28,"z":160},"requirements":{"minecraft:stone_bricks":228},"sha256":"3c788eaaa5c1ca947bc449b173cdbe5084db18f603b05922ebbec301b6a9a7b6","size":{"x":32,"y":1,"z":32}},{"blockCount":75,"bytes":2295,"file":"chunks/y028-z160-x160.json","offset":{"x":160,"y":28,"z":160},"requirements":{"minecraft:cobbled_deepslate":17,"minecraft:stone_bricks":58},"sha256":"5e12b779e60aadddd519457cc0e71c4389ed79111f8ce07dfa348c8b65cdc4f3","size":{"x":32,"y":1,"z":32}},{"blockCount":66,"bytes":1875,"file":"chunks/y028-z160-x192.json","offset":{"x":192,"y":28,"z":160},"requirements":{"minecraft:bricks":8,"minecraft:stone_bricks":58},"sha256":"0776868920c22946a713144c259f4f8753eca490272437a6fe5f97a378f4f1c9","size":{"x":32,"y":1,"z":32}},{"blockCount":146,"bytes":3053,"file":"chunks/y028-z160-x224.json","offset":{"x":224,"y":28,"z":160},"requirements":{"minecraft:bricks":18,"minecraft:stone_bricks":128},"sha256":"677add5020a673be27423511e104fbb2f136585e8443130b9397f9f34831c022","size":{"x":32,"y":1,"z":32}},{"blockCount":15,"bytes":1039,"file":"chunks/y028-z160-x256.json","offset":{"x":256,"y":28,"z":160},"requirements":{"minecraft:glass":2,"minecraft:spruce_planks":1,"minecraft:stone_bricks":12},"sha256":"1a1372460531be22958359e2b38a40f8dca86d8b95f192ddd972957a1212c5de","size":{"x":32,"y":1,"z":32}},{"blockCount":18,"bytes":1137,"file":"chunks/y028-z160-x288.json","offset":{"x":288,"y":28,"z":160},"requirements":{"minecraft:glass":3,"minecraft:spruce_planks":1,"minecraft:stone_bricks":14},"sha256":"2aa22d1cc2a9c58a9d11038764b3cd9967b966c8e6f0acad5b065aa966f6b5dc","size":{"x":32,"y":1,"z":32}}],"schema":1}
