{"entries":[{"blockCount":1,"bytes":628,"file":"chunks/y028-z160-x320.json","offset":{"x":320,"y":28,"z":160},"requirements":{"minecraft:polished_diorite":1},"sha256":"bf1d47aae77cbb09370cb8291ddb4c5d43251db6ef3ab0667ae9baa186008607","size":{"x":32,"y":1,"z":32}},{"blockCount":33,"bytes":1672,"file":"chunks/y028-z160-x352.json","offset":{"x":352,"y":28,"z":160},"requirements":{"minecraft:oak_planks":14,"minecraft:polished_diorite":14,"minecraft:stone_bricks":5},"sha256":"f97d745ceb54f88cf3594a8872644e055115f93c2b8b7c95a161080844ba1942","size":{"x":32,"y":1,"z":32}},{"blockCount":54,"bytes":1851,"file":"chunks/y028-z192-x064.json","offset":{"x":64,"y":28,"z":192},"requirements":{"minecraft:stone_bricks":54},"sha256":"84f418e027f7c652ed82f8833005bb7d38f2e88c6098fa35b9758028e4f4045f","size":{"x":32,"y":1,"z":32}},{"blockCount":172,"bytes":2640,"file":"chunks/y028-z192-x096.json","offset":{"x":96,"y":28,"z":192},"requirements":{"minecraft:stone_bricks":172},"sha256":"f998f3a7633c9cefc666fab2ad8fb2e3ffcc7adb7815839829007134dab26024","size":{"x":32,"y":1,"z":32}},{"blockCount":62,"bytes":1309,"file":"chunks/y028-z192-x128.json","offset":{"x":128,"y":28,"z":192},"requirements":{"minecraft:stone_bricks":62},"sha256":"b7ba9bfc65623e33d2669ca4b4279625b3ef1c3559d33a5d5d852961107c1b65","size":{"x":32,"y":1,"z":32}},{"blockCount":53,"bytes":1851,"file":"chunks/y028-z192-x160.json","offset":{"x":160,"y":28,"z":192},"requirements":{"minecraft:stone_bricks":53},"sha256":"9cf2aff0afce445caa104cf6d5d76d912740c6bb5bb1d3eb4cfad2115df3a5b6","size":{"x":32,"y":1,"z":32}},{"blockCount":1,"bytes":642,"file":"chunks/y028-z224-x064.json","offset":{"x":64,"y":28,"z":224},"requirements":{"minecraft:stone_bricks":1},"sha256":"a956e6a6743ecafe34b2f97190ec95b8ae8a9741fef47214a2e0ce1f1e89506d","size":{"x":32,"y":1,"z":15}},{"blockCount":1,"bytes":642,"file":"chunks/y028-z224-x160.json","offset":{"x":160,"y":28,"z":224},"requirements":{"minecraft:stone_bricks":1},"sha256":"7bc10c9b9bb0777bf2413e04fa994b2da18500a228c6f0c0ba7b3e48c8b660c3","size":{"x":32,"y":1,"z":15}},{"blockCount":197,"bytes":4884,"file":"chunks/y029-z000-x352.json","offset":{"x":352,"y":29,"z":0},"requirements":{"minecraft:bricks":20,"minecraft:glass":6,"minecraft:oak_planks":1,"minecraft:polished_diorite":75,"minecraft:spruce_planks":15,"minecraft:stone_bricks":80},"sha256":"26a0fa2d68ee98d9e867ff47876a07f5103a338c844e5eec9698ea77e1dfde6c","size":{"x":32,"y":1,"z":32}},{"blockCount":353,"bytes":4710,"file":"chunks/y029-z000-x384.json","offset":{"x":384,"y":29,"z":0},"requirements":{"minecraft:bricks":10,"minecraft:cobbled_deepslate":2,"minecraft:glass":11,"minecraft:oak_planks":63,"minecraft:polished_diorite":28,"minecraft:spruce_planks":12,"minecraft:stone_bricks":227},"sha256":"aa618045b48e8b8fc1e6b99a6ed7578ab2f0285baac6922fcf6e34e14cdc734f","size":{"x":32,"y":1,"z":32}},{"blockCount":83,"bytes":2045,"file":"chunks/y029-z032-x064.json","offset":{"x":64,"y":29,"z":32},"requirements":{"minecraft:bricks":5,"minecraft:cobbled_deepslate":4,"minecraft:stone_bricks":74},"sha256":"2dfe10d0c67be543401653bad01de6d12206426c9aa37c020f33545f26157723","size":{"x":32,"y":1,"z":32}},{"blockCount":190,"bytes":778,"file":"chunks/y029-z032-x096.json","offset":{"x":96,"y":29,"z":32},"requirements":{"minecraft:bricks":31,"minecraft:cobbled_deepslate":31,"minecraft:stone_bricks":128},"sha256":"fdd1fb6fe5694d94c3a431126dc264f233811fc448f1386748abdde610bafa15","size":{"x":32,"y":1,"z":32}},{"blockCount":167,"bytes":1473,"file":"chunks/y029-z032-x128.json","offset":{"x":128,"y":29,"z":32},"requirements":{"minecraft:bricks":26,"minecraft:cobbled_deepslate":24,"minecraft:stone_bricks":117},"sha256":"dba8bb36c305df98b872168b5ae94071e1e3b511a2fc83959ba849121201f266","size":{"x":32,"y":1,"z":32}},{"blockCount":36,"bytes":1189,"file":"chunks/y029-z032-x160.json","offset":{"x":160,"y":29,"z":32},"requirements":{"minecraft:stone_bricks":36},"sha256":"22cbc4748e83362fd3818b5ee0b4b2b930eeb31789ff84739b95e901a324556b","size":{"x":32,"y":1,"z":32}},{"blockCount":142,"bytes":3687,"file":"chunks/y029-z032-x352.json","offset":{"x":352,"y":29,"z":32},"requirements":{"minecraft:bricks":14,"minecraft:glass":10,"minecraft:oak_planks":9,"minecraft:polished_diorite":54,"minecraft:spruce_planks":18,"minecraft:stone_bricks":37},"sha256":"dd6758fadce7285c7d0fa6aa7bd6aeb5c601018dc1b4c614d3fced76a06fbecc","size":{"x":32,"y":1,"z":32}},{"blockCount":112,"bytes":2270,"file":"chunks/y029-z032-x384.json","offset":{"x":384,"y":29,"z":32},"requirements":{"minecraft:glass":4,"minecraft:oak_planks":2,"minecraft:stone_bricks":106},"sha256":"458d680e8e8f3a52da898fb2d01f1f4d1046bac50874c0eed20258c22b1179ba","size":{"x":32,"y":1,"z":32}},{"blockCount":49,"bytes":1889,"file":"chunks/y029-z064-x064.json","offset":{"x":64,"y":29,"z":64},"requirements":{"minecraft:stone_bricks":49},"sha256":"590ac5d460df53d2ed3008e3073ac929311285c0dc81fa265eddf52336bc9145","size":{"x":32,"y":1,"z":32}},{"blockCount":599,"bytes":1521,"file":"chunks/y029-z064-x096.json","offset":{"x":96,"y":29,"z":64},"requirements":{"minecraft:stone_bricks":599},"sha256":"e297904fca1200230640634d4bc428166ae8da5d4b64289bd1e2e28cb706b1d4","size":{"x":32,"y":1,"z":32}},{"blockCount":238,"bytes":1563,"file":"chunks/y029-z064-x128.json","offset":{"x":128,"y":29,"z":64},"requirements":{"minecraft:stone_bricks":238},"sha256":"55b92fced69edcf4638dfc95873bd8066f351dd38e858d1f0db80b05746d2a98","size":{"x":32,"y":1,"z":32}},{"blockCount":52,"bytes":1850,"file":"chunks/y029-z064-x160.json","offset":{"x":160,"y":29,"z":64},"requirements":{"minecraft:stone_bricks":52},"sha256":"a0eeb45441e5e27e26a6c0ee12e45fdb17fcd164f7c1390635b43b125ac863b7","size":{"x":32,"y":1,"z":32}},{"blockCount":33,"bytes":1181,"file":"chunks/y029-z064-x192.json","offset":{"x":192,"y":29,"z":64},"requirements":{"minecraft:stone_bricks":33},"sha256":"e61ea4f7bbafe092e8d270eb0f7eb88c6ae0b48fed8e6ac2d94baf7b03e5c8c8","size":{"x":32,"y":1,"z":32}},{"blockCount":49,"bytes":1427,"file":"chunks/y029-z064-x224.json","offset":{"x":224,"y":29,"z":64},"requirements":{"minecraft:stone_bricks":49},"sha256":"92dc61051824377cc7d486dcb9307d0a59abcf35a76411fa2fc973b40d24d47c","size":{"x":32,"y":1,"z":32}},{"blockCount":14,"bytes":933,"file":"chunks/y029-z064-x288.json","offset":{"x":288,"y":29,"z":64},"requirements":{"minecraft:glass":13,"minecraft:spruce_planks":1},"sha256":"e2e5598e9d214805aa25c1ca1ac5c157508e6b5512519c590a9d536f66190248","size":{"x":32,"y":1,"z":32}},{"blockCount":1,"bytes":647,"file":"chunks/y029-z064-x320.json","offset":{"x":320,"y":29,"z":64},"requirements":{"minecraft:polished_diorite":1},"sha256":"cf8ccd6c133260c94cd4621f712ff5acb86654abe31470a1e1097187ec296b63","size":{"x":32,"y":1,"z":32}},{"blockCount":6,"bytes":841,"file":"chunks/y029-z064-x352.json","offset":{"x":352,"y":29,"z":64},"requirements":{"minecraft:polished_diorite":6},"sha256":"ee4344d69aef1f77794c60bb8b5f862f00ba98794fcf9b9d5347f4af5a8b119d","size":{"x":32,"y":1,"z":32}},{"blockCount":63,"bytes":2039,"file":"chunks/y029-z096-x000.json","offset":{"x":0,"y":29,"z":96},"requirements":{"minecraft:stone_bricks":63},"sha256":"7dd4fbd4abe29ac221250e40e9463e87bcc1f85b08d89f7b806f839e165fea6f","size":{"x":32,"y":1,"z":32}},{"blockCount":75,"bytes":1638,"file":"chunks/y029-z096-x032.json","offset":{"x":32,"y":29,"z":96},"requirements":{"minecraft:stone_bricks":75},"sha256":"7ae0ca923f94ae79ec97a5d24f1be02a489fda0f66e667b3ce1bda17e9458c58","size":{"x":32,"y":1,"z":32}},{"blockCount":285,"bytes":1224,"file":"chunks/y029-z096-x064.json","offset":{"x":64,"y":29,"z":96},"requirements":{"minecraft:stone_bricks":285},"sha256":"75220b6126a97ab6b34ffbee9ef1408f8644c0ed0a4df4245c702ecbc915fd9c","size":{"x":32,"y":1,"z":32}},{"blockCount":916,"bytes":1210,"file":"chunks/y029-z096-x096.json","offset":{"x":96,"y":29,"z":96},"requirements":{"minecraft:stone_bricks":916},"sha256":"92acdb88bc06dae4e8e3adbddb7194507d4c8912c08e53c8d11f753b0a547479","size":{"x":32,"y":1,"z":32}},{"blockCount":568,"bytes":1811,"file":"chunks/y029-z096-x128.json","offset":{"x":128,"y":29,"z":96},"requirements":{"minecraft:stone_bricks":568},"sha256":"8d0d1b273e12b8ff636236adbfe5e03a0bbae985a8f1f8b7071a01550663fbce","size":{"x":32,"y":1,"z":32}},{"blockCount":41,"bytes":1290,"file":"chunks/y029-z096-x160.json","offset":{"x":160,"y":29,"z":96},"requirements":{"minecraft:stone_bricks":41},"sha256":"9f8c366747fcac0717399d621826eab0e1a4439b70646eb1dcb54703205fac95","size":{"x":32,"y":1,"z":32}},{"blockCount":41,"bytes":1683,"file":"chunks/y029-z096-x192.json","offset":{"x":192,"y":29,"z":96},"requirements":{"minecraft:bricks":16,"minecraft:stone_bricks":25},"sha256":"5081e3929f9f33440516858d7c27e0a3c7b4f071bdeaed8f0d4b6b78372894c2","size":{"x":32,"y":1,"z":32}},{"blockCount":142,"bytes":3165,"file":"chunks/y029-z096-x224.json","offset":{"x":224,"y":29,"z":96},"requirements":{"minecraft:bricks":29,"minecraft:cobbled_deepslate":24,"minecraft:stone_bricks":89},"sha256":"d77fc6a46f17e38291ba826012b3f7ad3397db2455693520ec2adb763164b488","size":{"x":32,"y":1,"z":32}},{"blockCount":17,"bytes":973,"file":"chunks/y029-z096-x256.json","offset":{"x":256,"y":29,"z":96},"requirements":{"minecraft:glass":16,"minecraft:spruce_planks":1},"sha256":"8207e475f47886b116fc11588f2f58d2bc7ea1094aaf9db17b0512302cbc9abd","size":{"x":32,"y":1,"z":32}},{"blockCount":3,"bytes":636,"file":"chunks/y029-z096-x288.json","offset":{"x":288,"y":29,"z":96},"requirements":{"minecraft:glass":3},"sha256":"60e2f9fea2bb4e30ce4fff8889fc24221c9d5ccd8b563b60df309ebf31b7a9ad","size":{"x":32,"y":1,"z":32}},{"blockCount":8,"bytes":919,"file":"chunks/y029-z096-x352.json","offset":{"x":352,"y":29,"z":96},"requirements":{"minecraft:polished_diorite":8},"sha256":"eef827f9f13853ff247c1324747763a5ac743ef0e37a25d8dc54723870acf422","size":{"x":32,"y":1,"z":32}},{"blockCount":90,"bytes":2780,"file":"chunks/y029-z128-x000.json","offset":{"x":0,"y":29,"z":128},"requirements":{"minecraft:stone_bricks":90},"sha256":"525e5a05a47e7d4a5f92830a775cb19164af3a5dbc567b0b52035400eebfa119","size":{"x":32,"y":1,"z":32}},{"blockCount":216,"bytes":3315,"file":"chunks/y029-z128-x032.json","offset":{"x":32,"y":29,"z":128},"requirements":{"minecraft:stone_bricks":216},"sha256":"127bef08cd53df876e89c32ea3ea7b2e1cfb3e542a10bda77bd2ad6ba368ccf9","size":{"x":32,"y":1,"z":32}},{"blockCount":1024,"bytes":607,"file":"chunks/y029-z128-x064.json","offset":{"x":64,"y":29,"z":128},"requirements":{"minecraft:stone_bricks":1024},"sha256":"777131ca8410dddb60b90ca48a1ec1e0d027a104a81e82bd487cbf866bb28aae","size":{"x":32,"y":1,"z":32}},{"blockCount":1024,"bytes":607,"file":"chunks/y029-z128-x096.json","offset":{"x":96,"y":29,"z":128},"requirements":{"minecraft:stone_bricks":1024},"sha256":"54baba50b805c0c21a3170d688f7a2fb49b43daa1f04465619553345ae52b204","size":{"x":32,"y":1,"z":32}},{"blockCount":946,"bytes":1522,"file":"chunks/y029-z128-x128.json","offset":{"x":128,"y":29,"z":128},"requirements":{"minecraft:stone_bricks":946},"sha256":"cda6dbcf66c6af22176daae1c57224b47543dd49dd5cb58452f24642e8cb5a26","size":{"x":32,"y":1,"z":32}},{"blockCount":736,"bytes":647,"file":"chunks/y029-z128-x160.json","offset":{"x":160,"y":29,"z":128},"requirements":{"minecraft:stone_bricks":736},"sha256":"e64ca50fc153a18ba7d4ae013fcba24482a7e220866df1e7efd5abfb0c01edaf","size":{"x":32,"y":1,"z":32}},{"blockCount":326,"bytes":3833,"file":"chunks/y029-z128-x192.json","offset":{"x":192,"y":29,"z":128},"requirements":{"minecraft:bricks":73,"minecraft:stone_bricks":253},"sha256":"0f17a27c135c7dc2c8f758f7e4d0fdd55e33abc4da510682a5a31fa2f0505a19","size":{"x":32,"y":1,"z":32}},{"blockCount":183,"bytes":4628,"file":"chunks/y029-z128-x224.json","offset":{"x":224,"y":29,"z":128},"requirements":{"minecraft:bricks":65,"minecraft:cobbled_deepslate":9,"minecraft:glass":1,"minecraft:stone_bricks":108},"sha256":"ec6570269df5c7386cd185fed32683930394ba8b692c8bc4205be1a640e43062","size":{"x":32,"y":1,"z":32}},{"blockCount":4,"bytes":764,"file":"chunks/y029-z128-x320.json","offset":{"x":320,"y":29,"z":128},"requirements":{"minecraft:polished_diorite":4},"sha256":"4ffc07baae02cc7f5b638439243d8f54b09647c1408d7cf992a3e9ace5cafaea","size":{"x":32,"y":1,"z":32}},{"blockCount":48,"bytes":1692,"file":"chunks/y029-z160-x000.json","offset":{"x":0,"y":29,"z":160},"requirements":{"minecraft:stone_bricks":48},"sha256":"0d3776aa3c52416148d409fcbdf6012e0ea152b581469ccd536fee6eaf595f5f","size":{"x":32,"y":1,"z":32}},{"blockCount":51,"bytes":1445,"file":"chunks/y029-z160-x032.json","offset":{"x":32,"y":29,"z":160},"requirements":{"minecraft:stone_bricks":51},"sha256":"f7842e1835a9fecde6f8608af62e3b116df42db5c60087fa3a0c12b9c4474371","size":{"x":32,"y":1,"z":32}},{"blockCount":96,"bytes":1554,"file":"chunks/y029-z160-x064.json","offset":{"x":64,"y":29,"z":160},"requirements":{"minecraft:stone_bricks":96},"sha256":"6b32d63e16a57de4ae692b91a9911e939bf7fd9b7a1f6243426717da64cf6ae5","size":{"x":32,"y":1,"z":32}},{"blockCount":867,"bytes":1542,"file":"chunks/y029-z160-x096.json","offset":{"x":96,"y":29,"z":160},"requirements":{"minecraft:stone_bricks":867},"sha256":"b5a6f71b1530982b66c9d3c3a31ca587a1df7430825b904258fe972bd0e7b93c","size":{"x":32,"y":1,"z":32}},{"blockCount":462,"bytes":1817,"file":"chunks/y029-z160-x128.json","offset":{"x":128,"y":29,"z":160},"requirements":{"minecraft:stone_bricks":462},"sha256":"f1253a5e68f05a36a856f86a9db32d00ea17432910b1377164bffa0e4d19da0b","size":{"x":32,"y":1,"z":32}},{"blockCount":508,"bytes":2316,"file":"chunks/y029-z160-x160.json","offset":{"x":160,"y":29,"z":160},"requirements":{"minecraft:cobbled_deepslate":457,"minecraft:stone_bricks":51},"sha256":"a173cb87a3ff881b544a22746bcd1df361959a5f6fb519a1c67ea17472829890","size":{"x":32,"y":1,"z":32}},{"blockCount":346,"bytes":2702,"file":"chunks/y029-z160-x192.json","offset":{"x":192,"y":29,"z":160},"requirements":{"minecraft:bricks":10,"minecraft:cobbled_deepslate":284,"minecraft:stone_bricks":52},"sha256":"ae61e27cff6e54e770a54e926cb768100f206234ab8aa5f798a013946df6ea8b","size":{"x":32,"y":1,"z":32}},{"blockCount":198,"bytes":3834,"file":"chunks/y029-z160-x224.json","offset":{"x":224,"y":29,"z":160},"requirements":{"minecraft:bricks":14,"minecraft:cobbled_deepslate":60,"minecraft:stone_bricks":124},"sha256":"d15e38711f5e0a53314fc3072734599c91285d5c5b82f46e5f62c7d450b1ca9a","size":{"x":32,"y":1,"z":32}},{"blockCount":17,"bytes":974,"file":"chunks/y029-z160-x256.json","offset":{"x":256,"y":29,"z":160},"requirements":{"minecraft:glass":16,"minecraft:spruce_planks":1},"sha256":"1aca16d7587a4b4493d527a593f93cc4dd75697d5a81053c7346cc8b8da0686e","size":{"x":32,"y":1,"z":32}},{"blockCount":17,"bytes":974,"file":"chunks/y029-z160-x288.json","offset":{"x":288,"y":29,"z":160},"requirements":{"minecraft:glass":16,"minecraft:spruce_planks":1},"sha256":"2b4ffb27d2163bbbc4a9529c6585dcf4800fd93a5a070882564305453e332740","size":{"x":32,"y":1,"z":32}},{"blockCount":1,"bytes":628,"file":"chunks/y029-z160-x320.json","offset":{"x":320,"y":29,"z":160},"requirements":{"minecraft:polished_diorite":1},"sha256":"9e47faea9532793b4757fd0ad3aeac25765f2add3ac8ef6a03597637265e4f76","size":{"x":32,"y":1,"z":32}},{"blockCount":35,"bytes":1860,"file":"chunks/y029-z160-x352.json","offset":{"x":352,"y":29,"z":160},"requirements":{"minecraft:oak_planks":17,"minecraft:polished_diorite":14,"minecraft:stone_bricks":4},"sha256":"022ba25d007183d771c54be5db309f2cb294e4ebd69bb4ce0c08536338013d03","size":{"x":32,"y":1,"z":32}},{"blockCount":47,"bytes":1851,"file":"chunks/y029-z192-x064.json","offset":{"x":64,"y":29,"z":192},"requirements":{"minecraft:stone_bricks":47},"sha256":"9cae7a6bc8957c6e8ba7031a2f8bc6666db8f824db699dee14281f5d27eac150","size":{"x":32,"y":1,"z":32}},{"blockCount":424,"bytes":1268,"file":"chunks/y029-z192-x096.json","offset":{"x":96,"y":29,"z":192},"requirements":{"minecraft:stone_bricks":424},"sha256":"38b19576c8cdf780bae396a331dc2e896b0fa9d6851a5dce3dd0a3a69e1debae","size":{"x":32,"y":1,"z":32}},{"blockCount":169,"bytes":1265,"file":"chunks/y029-z192-x128.json","offset":{"x":128,"y":29,"z":192},"requirements":{"minecraft:stone_bricks":169},"sha256":"6a7e926f741938445bee72d5307e4841299c4fc3ef88c8fca75642824581d87c","size":{"x":32,"y":1,"z":32}},{"blockCount":48,"bytes":1851,"file":"chunks/y029-z192-x160.json","offset":{"x":160,"y":29,"z":192},"requirements":{"minecraft:stone_bricks":48},"sha256":"9bf1c9e3070ece78b2c07b11dd1ae2f8fa362a105e93e0ca660819f8c2760d81","size":{"x":32,"y":1,"z":32}},{"blockCount":2,"bytes":642,"file":"chunks/y029-z224-x064.json","offset":{"x":64,"y":29,"z":224},"requirements":{"minecraft:stone_bricks":2},"sha256":"7f3d0beda53b9452b769977d426fc86a25d42af3a1ee6e69a12f4f85e385b2d9","size":{"x":32,"y":1,"z":15}},{"blockCount":2,"bytes":642,"file":"chunks/y029-z224-x160.json","offset":{"x":160,"y":29,"z":224},"requirements":{"minecraft:stone_bricks":2},"sha256":"e181dbb7f11303bfc57dfe0102f99f467edde854d4135209191ee64ab78752a8","size":{"x":32,"y":1,"z":15}},{"blockCount":173,"bytes":4375,"file":"chunks/y030-z000-x352.json","offset":{"x":352,"y":30,"z":0},"requirements":{"minecraft:bricks":14,"minecraft:glass":6,"minecraft:oak_planks":2,"minecraft:polished_diorite":70,"minecraft:sandstone":9,"minecraft:spruce_planks":9,"minecraft:stone_bricks":63},"sha256":"2fd3d3249b8ab6f2f44b9334a4f1531ca883b989a6b3b97ab2da8d27f78115b9","size":{"x":32,"y":1,"z":32}},{"blockCount":421,"bytes":5793,"file":"chunks/y030-z000-x384.json","offset":{"x":384,"y":30,"z":0},"requirements":{"minecraft:bricks":7,"minecraft:glass":4,"minecraft:oak_planks":35,"minecraft:polished_diorite":41,"minecraft:spruce_planks":10,"minecraft:stone_bricks":324},"sha256":"749b1285ac07bff26f2e8495ee6fc3d6a6f8319ccfad911ffad2ffa759e95606","size":{"x":32,"y":1,"z":32}},{"blockCount":64,"bytes":1787,"file":"chunks/y030-z032-x064.json","offset":{"x":64,"y":30,"z":32},"requirements":{"minecraft:stone_bricks":64},"sha256":"6b4496c345ede88dfe1f2036d371f05991ea5ac049c83b229c221b49d13c7da9","size":{"x":32,"y":1,"z":32}},{"blockCount":128,"bytes":625,"file":"chunks/y030-z032-x096.json","offset":{"x":96,"y":30,"z":32},"requirements":{"minecraft:stone_bricks":128},"sha256":"47da1e70cd4ce110733e24770babcb042e5d1d5d0ec350d097495b9e25aaa620","size":{"x":32,"y":1,"z":32}},{"blockCount":113,"bytes":1267,"file":"chunks/y030-z032-x128.json","offset":{"x":128,"y":30,"z":32},"requirements":{"minecraft:stone_bricks":113},"sha256":"3b1fba786c232dfbc7db1cb519c02d136e78331677b380bb065fa34cc7328fc1","size":{"x":32,"y":1,"z":32}},{"blockCount":19,"bytes":1189,"file":"chunks/y030-z032-x160.json","offset":{"x":160,"y":30,"z":32},"requirements":{"minecraft:stone_bricks":19},"sha256":"5a777a61196a58e0944e6ff8f3baa7f2d26458223543af8ab405b392371b6a69","size":{"x":32,"y":1,"z":32}},{"blockCount":97,"bytes":3325,"file":"chunks/y030-z032-x352.json","offset":{"x":352,"y":30,"z":32},"requirements":{"minecraft:bricks":14,"minecraft:glass":25,"minecraft:oak_planks":1,"minecraft:polished_diorite":28,"minecraft:spruce_planks":3,"minecraft:stone_bricks":26},"sha256":"34cb28b4f3762bdef1169b0da2cf66f72877f61b2494f76ba2fd438030cb2dc2","size":{"x":32,"y":1,"z":32}},{"blockCount":148,"bytes":1516,"file":"chunks/y030-z032-x384.json","offset":{"x":384,"y":30,"z":32},"requirements":{"minecraft:glass":21,"minecraft:sandstone":4,"minecraft:stone_bricks":123},"sha256":"3d1079b780158777d12f249c3bac594d26fa8739da7c45666fbd2d36bd745d19","size":{"x":32,"y":1,"z":32}},{"blockCount":327,"bytes":3035,"file":"chunks/y030-z064-x064.json","offset":{"x":64,"y":30,"z":64},"requirements":{"minecraft:stone_bricks":327},"sha256":"dacf7b322490c096500ed3f04d2ad7c584c1350a91b09bc2927c5c340a0a4449","size":{"x":32,"y":1,"z":32}},{"blockCount":745,"bytes":1268,"file":"chunks/y030-z064-x096.json","offset":{"x":96,"y":30,"z":64},"requirements":{"minecraft:bricks":5,"minecraft:stone_bricks":740},"sha256":"a2a09e8064fd77f53b575e60519bf76d52c71e88014e1dbd8b0ab2fd16be504b","size":{"x":32,"y":1,"z":32}},{"blockCount":738,"bytes":2038,"file":"chunks/y030-z064-x128.json","offset":{"x":128,"y":30,"z":64},"requirements":{"minecraft:stone_bricks":738},"sha256":"f9b29ca829721adebe34c57fefa38b9d581aa085e6e85e6158e03da75fa2c359","size":{"x":32,"y":1,"z":32}},{"blockCount":40,"bytes":1850,"file":"chunks/y030-z064-x160.json","offset":{"x":160,"y":30,"z":64},"requirements":{"minecraft:stone_bricks":40},"sha256":"23c741737b737d6c7d0ab85131ac1ddc496b3751eb407c725bdfe2ed283b1c6c","size":{"x":32,"y":1,"z":32}},{"blockCount":34,"bytes":1085,"file":"chunks/y030-z064-x192.json","offset":{"x":192,"y":30,"z":64},"requirements":{"minecraft:stone_bricks":34},"sha256":"1d735d3e6cdc6ac495c9814f567282cd9608166e88c2af1844a836102bde3514","size":{"x":32,"y":1,"z":32}},{"blockCount":65,"bytes":1540,"file":"chunks/y030-z064-x224.json","offset":{"x":224,"y":30,"z":64},"requirements":{"minecraft:stone_bricks":65},"sha256":"bfbf8ccddc906d0531c3e9ca6302c5bf45843176b3cfc9aeead3437dfaa99bc0","size":{"x":32,"y":1,"z":32}},{"blockCount":7,"bytes":891,"file":"chunks/y030-z064-x288.json","offset":{"x":288,"y":30,"z":64},"requirements":{"minecraft:glass":6,"minecraft:oak_planks":1},"sha256":"ddc3807c75656f779208512612c3cfd71ab46819989622171a225daf78115dca","size":{"x":32,"y":1,"z":32}},{"blockCount":2,"bytes":647,"file":"chunks/y030-z064-x320.json","offset":{"x":320,"y":30,"z":64},"requirements":{"minecraft:polished_diorite":2},"sha256":"60aeb8e09a36f233af940920d4fa087660f24b514dff918a94f8b1d61a44e5e1","size":{"x":32,"y":1,"z":32}},{"blockCount":13,"bytes":919,"file":"chunks/y030-z064-x352.json","offset":{"x":352,"y":30,"z":64},"requirements":{"minecraft:polished_diorite":13},"sha256":"1338db2ff9382ed14665ad76de9b445ab92e71343b2d3d8556c102c31f81595d","size":{"x":32,"y":1,"z":32}},{"blockCount":204,"bytes":2528,"file":"chunks/y030-z096-x000.json","offset":{"x":0,"y":30,"z":96},"requirements":{"minecraft:stone_bricks":204},"sha256":"4eb6eb7ad346833a5539ce2613bec8a0bd7f85c94f9fcb426f716144f971287c","size":{"x":32,"y":1,"z":32}},{"blockCount":328,"bytes":2930,"file":"chunks/y030-z096-x032.json","offset":{"x":32,"y":30,"z":96},"requirements":{"minecraft:stone_bricks":328},"sha256":"b41482f25ee125f9226df2e9cbbd1dd5f3b431355411f4b481e1b23ecbda0eef","size":{"x":32,"y":1,"z":32}},{"blockCount":594,"bytes":1989,"file":"chunks/y030-z096-x064.json","offset":{"x":64,"y":30,"z":96},"requirements":{"minecraft:stone_bricks":594},"sha256":"06c94241b88ba38464e56b6fb35cbc425af5f9aa0a0e5384aabdce1bc157772a","size":{"x":32,"y":1,"z":32}},{"blockCount":879,"bytes":1833,"file":"chunks/y030-z096-x096.json","offset":{"x":96,"y":30,"z":96},"requirements":{"minecraft:bricks":6,"minecraft:stone_bricks":873},"sha256":"864c1d6c4961ac492cb752e9837d9b9cdee729d19312c225a0f32c5fe5949a07","size":{"x":32,"y":1,"z":32}},{"blockCount":1002,"bytes":879,"file":"chunks/y030-z096-x128.json","offset":{"x":128,"y":30,"z":96},"requirements":{"minecraft:stone_bricks":1002},"sha256":"067b68712976b80912e12a991872928b364c8ece7d4f4597508a187e6b569eae","size":{"x":32,"y":1,"z":32}},{"blockCount":775,"bytes":1047,"file":"chunks/y030-z096-x160.json","offset":{"x":160,"y":30,"z":96},"requirements":{"minecraft:stone_bricks":775},"sha256":"ee3a6ee8e81a4e4a75499413e7777d5a22de10abb717d49c5d55fec13792d7a2","size":{"x":32,"y":1,"z":32}},{"blockCount":830,"bytes":1562,"file":"chunks/y030-z096-x192.json","offset":{"x":192,"y":30,"z":96},"requirements":{"minecraft:sandstone":2,"minecraft:stone_bricks":828},"sha256":"26bfd647cb0d99ba9c599ab4e6f0d36e54a42121c8cb745058cca967ace6978b","size":{"x":32,"y":1,"z":32}},{"blockCount":505,"bytes":4483,"file":"chunks/y030-z096-x224.json","offset":{"x":224,"y":30,"z":96},"requirements":{"minecraft:stone_bricks":505},"sha256":"98151e2a8bc3763f300a32cc0e7481c5c353569c8bda75ba04115b5d8f3fefa3","size":{"x":32,"y":1,"z":32}},{"blockCount":9,"bytes":969,"file":"chunks/y030-z096-x256.json","offset":{"x":256,"y":30,"z":96},"requirements":{"minecraft:glass":8,"minecraft:oak_planks":1},"sha256":"d1d0eda0e04d5b949bcadab6dbb6c8fdb0bea78eedd0213314fa4fea449d1f8b","size":{"x":32,"y":1,"z":32}},{"blockCount":2,"bytes":674,"file":"chunks/y030-z096-x288.json","offset":{"x":288,"y":30,"z":96},"requirements":{"minecraft:glass":2},"sha256":"44860afdb3780d9566e084bb2e6b27bc2a30ebf77b97691a092c8745fc652a72","size":{"x":32,"y":1,"z":32}},{"blockCount":16,"bytes":1232,"file":"chunks/y030-z096-x352.json","offset":{"x":352,"y":30,"z":96},"requirements":{"minecraft:polished_diorite":16},"sha256":"1d95db2baced832e07802851cb63554220d6ff50d9f09e96863cdfd13f568ced","size":{"x":32,"y":1,"z":32}},{"blockCount":434,"bytes":3261,"file":"chunks/y030-z128-x000.json","offset":{"x":0,"y":30,"z":128},"requirements":{"minecraft:stone_bricks":434},"sha256":"7e13abb1a68abac1c5b1ec2278eb576021714c27e8c8cd3ca1ef890c183e6d37","size":{"x":32,"y":1,"z":32}},{"blockCount":359,"bytes":3607,"file":"chunks/y030-z128-x032.json","offset":{"x":32,"y":30,"z":128},"requirements":{"minecraft:stone_bricks":359},"sha256":"1d2cf52205d88b19c942f81bff76a25afc2c8168a1ad13b0f8098a4d4da6b652","size":{"x":32,"y":1,"z":32}},{"blockCount":516,"bytes":2051,"file":"chunks/y030-z128-x064.json","offset":{"x":64,"y":30,"z":128},"requirements":{"minecraft:bricks":5,"minecraft:stone_bricks":511},"sha256":"b413e14198461ed448f67fca3411785399bc84ac8dcab538cf240e7bfaad6566","size":{"x":32,"y":1,"z":32}},{"blockCount":959,"bytes":1346,"file":"chunks/y030-z128-x096.json","offset":{"x":96,"y":30,"z":128},"requirements":{"minecraft:bricks":10,"minecraft:polished_diorite":2,"minecraft:sandstone":1,"minecraft:spruce_planks":2,"minecraft:stone_bricks":944},"sha256":"22add069ebd9c7b6f05a8d75968705c89b652f4f777eade20758720568a883ce","size":{"x":32,"y":1,"z":32}},{"blockCount":904,"bytes":1012,"file":"chunks/y030-z128-x128.json","offset":{"x":128,"y":30,"z":128},"requirements":{"minecraft:bricks":5,"minecraft:polished_diorite":1,"minecraft:sandstone":1,"minecraft:stone_bricks":897},"sha256":"481531374151c7ac690e7327a6632b22ff3071caa110b5e2f2abfb432a4d6665","size":{"x":32,"y":1,"z":32}},{"blockCount":864,"bytes":648,"file":"chunks/y030-z128-x160.json","offset":{"x":160,"y":30,"z":128},"requirements":{"minecraft:stone_bricks":864},"sha256":"1c3a0b1c636e71a26901b0abbd5dfe6b6d35ce150c1546686fb791c8085b242a","size":{"x":32,"y":1,"z":32}},{"blockCount":849,"bytes":2041,"file":"chunks/y030-z128-x192.json","offset":{"x":192,"y":30,"z":128},"requirements":{"minecraft:bricks":15,"minecraft:oak_planks":2,"minecraft:sandstone":1,"minecraft:spruce_planks":49,"minecraft:stone_bricks":782},"sha256":"a953378d77eea32c983b4fc36ec801cdd26aa1a29510ec50a34d116d5c75f16d","size":{"x":32,"y":1,"z":32}},{"blockCount":320,"bytes":4648,"file":"chunks/y030-z128-x224.json","offset":{"x":224,"y":30,"z":128},"requirements":{"minecraft:stone_bricks":320},"sha256":"58b2035450a882cf236b871c43a469fd10127fd5ae84d7f8c0457497bfe1fec6","size":{"x":32,"y":1,"z":32}},{"blockCount":4,"bytes":764,"file":"chunks/y030-z128-x320.json","offset":{"x":320,"y":30,"z":128},"requirements":{"minecraft:polished_diorite":4},"sha256":"a7068620e9d3fe350b2a6bdd575e65a2aa6e25dcf486de4059b79bf9e4541d7b","size":{"x":32,"y":1,"z":32}},{"blockCount":103,"bytes":2005,"file":"chunks/y030-z160-x000.json","offset":{"x":0,"y":30,"z":160},"requirements":{"minecraft:stone_bricks":103},"sha256":"64d55ab80e5bbe28b236d57a7c7d5b4a01d01d06a599de0875f2090fec087cb6","size":{"x":32,"y":1,"z":32}},{"blockCount":258,"bytes":1719,"file":"chunks/y030-z160-x032.json","offset":{"x":32,"y":30,"z":160},"requirements":{"minecraft:stone_bricks":258},"sha256":"0ae75660137253d2b64f4ed46b3e2da3c9300173279a055352f38216b8882c42","size":{"x":32,"y":1,"z":32}},{"blockCount":551,"bytes":2237,"file":"chunks/y030-z160-x064.json","offset":{"x":64,"y":30,"z":160},"requirements":{"minecraft:stone_bricks":551},"sha256":"98dad21883edb7f30cf731d981ee9b44b67c8400f5cb2e737edf5f2d02260e4e","size":{"x":32,"y":1,"z":32}},{"blockCount":864,"bytes":1917,"file":"chunks/y030-z160-x096.json","offset":{"x":96,"y":30,"z":160},"requirements":{"minecraft:spruce_planks":1,"minecraft:stone_bricks":863},"sha256":"188536a32c5380129e9e083c8ff9a0f20a520b122eb20a74ac85db9cd2476b56","size":{"x":32,"y":1,"z":32}},{"blockCount":974,"bytes":1132,"file":"chunks/y030-z160-x128.json","offset":{"x":128,"y":30,"z":160},"requirements":{"minecraft:stone_bricks":974},"sha256":"51f8bbd6dba4a77444523904537c86bf19b43d7acf71accae5cb07ae66182f6d","size":{"x":32,"y":1,"z":32}},{"blockCount":560,"bytes":1282,"file":"chunks/y030-z160-x160.json","offset":{"x":160,"y":30,"z":160},"requirements":{"minecraft:stone_bricks":560},"sha256":"47629709b282409a87bac5eff0526f3d3902262418b424e0cb0869a51f213eb6","size":{"x":32,"y":1,"z":32}},{"blockCount":669,"bytes":1755,"file":"chunks/y030-z160-x192.json","offset":{"x":192,"y":30,"z":160},"requirements":{"minecraft:sandstone":2,"minecraft:stone_bricks":667},"sha256":"a3acdaffe1b40879c1ffc77bfd9ee2d3b27042c367d183e0bb6c950dbd0e40e3","size":{"x":32,"y":1,"z":32}},{"blockCount":502,"bytes":3970,"file":"chunks/y030-z160-x224.json","offset":{"x":224,"y":30,"z":160},"requirements":{"minecraft:stone_bricks":502},"sha256":"61f3e4fd4ac509e8a6777a0b7dd69aad18e1c0f2686f0d1b603623b20b7e05a0","size":{"x":32,"y":1,"z":32}},{"blockCount":9,"bytes":970,"file":"chunks/y030-z160-x256.json","offset":{"x":256,"y":30,"z":160},"requirements":{"minecraft:glass":8,"minecraft:oak_planks":1},"sha256":"ba296895aeefff791ac09de6bc50bd6fafd230f7cf682298ceb3a76f0ec17a48","size":{"x":32,"y":1,"z":32}},{"blockCount":9,"bytes":970,"file":"chunks/y030-z160-x288.json","offset":{"x":288,"y":30,"z":160},"requirements":{"minecraft:glass":8,"minecraft:oak_planks":1},"sha256":"ad61fffdc3fb2c5bb7760dd793041fa23ab5da874259571fcf2975e0a057d2f8","size":{"x":32,"y":1,"z":32}},{"blockCount":2,"bytes":628,"file":"chunks/y030-z160-x320.json","offset":{"x":320,"y":30,"z":160},"requirements":{"minecraft:polished_diorite":2},"sha256":"c24b7d052b5ee192dd7cb4e7f47589b45ea64043ac3aff6596500395967b2a56","size":{"x":32,"y":1,"z":32}},{"blockCount":52,"bytes":2169,"file":"chunks/y030-z160-x352.json","offset":{"x":352,"y":30,"z":160},"requirements":{"minecraft:oak_planks":22,"minecraft:polished_diorite":29,"minecraft:stone_bricks":1},"sha256":"cbe99a9287043373a7760e928237236eb17580bce209ab6333fa0daca1157327","size":{"x":32,"y":1,"z":32}},{"blockCount":255,"bytes":2821,"file":"chunks/y030-z192-x064.json","offset":{"x":64,"y":30,"z":192},"requirements":{"minecraft:stone_bricks":255},"sha256":"2a30b665cd2b5234d8db71f35520e6921c39a6d197b99b58ffc765624cb397c3","size":{"x":32,"y":1,"z":32}},{"blockCount":572,"bytes":1227,"file":"chunks/y030-z192-x096.json","offset":{"x":96,"y":30,"z":192},"requirements":{"minecraft:bricks":5,"minecraft:stone_bricks":567},"sha256":"e3f4f81fb3eeb21c8d3f8589f4b132d9d8afefd7e55bc61e0a0c151bf64c4ba0","size":{"x":32,"y":1,"z":32}},{"blockCount":554,"bytes":2094,"file":"chunks/y030-z192-x128.json","offset":{"x":128,"y":30,"z":192},"requirements":{"minecraft:stone_bricks":554},"sha256":"af22b8907728e731aae5c6de079fbc262d9584f5b4bacef8432bac28227cbd86","size":{"x":32,"y":1,"z":32}},{"blockCount":44,"bytes":1927,"file":"chunks/y030-z192-x160.json","offset":{"x":160,"y":30,"z":192},"requirements":{"minecraft:stone_bricks":44},"sha256":"fd3261c1eedebc858bbdaaefd0b81b431bc2141b63b9f6fd1a5d65591f42fb05","size":{"x":32,"y":1,"z":32}},{"blockCount":1,"bytes":642,"file":"chunks/y030-z224-x064.json","offset":{"x":64,"y":30,"z":224},"requirements":{"minecraft:stone_bricks":1},"sha256":"77e23be783cd2ded946d3d21937c88efdfc9446d4c0a6e3a3e19a7d853e7362b","size":{"x":32,"y":1,"z":15}},{"blockCount":1,"bytes":642,"file":"chunks/y030-z224-x160.json","offset":{"x":160,"y":30,"z":224},"requirements":{"minecraft:stone_bricks":1},"sha256":"3ea97253d36047cfd98163fcd0d3004524802f0ad15fe7a71339064146ed717e","size":{"x":32,"y":1,"z":15}},{"blockCount":166,"bytes":4214,"file":"chunks/y031-z000-x352.json","offset":{"x":352,"y":31,"z":0},"requirements":{"minecraft:bricks":17,"minecraft:glass":7,"minecraft:polished_diorite":63,"minecraft:sandstone":8,"minecraft:spruce_planks":8,"minecraft:stone_bricks":63},"sha256":"7d4cacd9b25d0c71408c58a5b7271f6bf116643feec3707e271308093ca325ab","size":{"x":32,"y":1,"z":32}},{"blockCount":281,"bytes":5819,"file":"chunks/y031-z000-x384.json","offset":{"x":384,"y":31,"z":0},"requirements":{"minecraft:bricks":62,"minecraft:glass":20,"minecraft:oak_planks":40,"minecraft:polished_diorite":76,"minecraft:sandstone":6,"minecraft:spruce_planks":52,"minecraft:stone_bricks":25},"sha256":"9d3a5d7d9976725ece014203a3ef3ddfb5887997fb2e68055fd0a49fafeb6d89","size":{"x":32,"y":1,"z":32}},{"blockCount":9,"bytes":816,"file":"chunks/y031-z032-x064.json","offset":{"x":64,"y":31,"z":32},"requirements":{"minecraft:glass":4,"minecraft:stone_bricks":5},"sha256":"776678a8e765cec5c1832fb11473318d140115af0959d6034f8ae756997cbb30","size":{"x":32,"y":1,"z":32}},{"blockCount":9,"bytes":817,"file":"chunks/y031-z032-x128.json","offset":{"x":128,"y":31,"z":32},"requirements":{"minecraft:glass":4,"minecraft:stone_bricks":5},"sha256":"6b791ed84441b0e315bd2841677663adf4be1c7e0cc0eb1b3167a1390681519c","size":{"x":32,"y":1,"z":32}},{"blockCount":111,"bytes":3415,"file":"chunks/y031-z032-x352.json","offset":{"x":352,"y":31,"z":32},"requirements":{"minecraft:bricks":14,"minecraft:glass":22,"minecraft:polished_diorite":29,"minecraft:spruce_planks":16,"minecraft:stone_bricks":30},"sha256":"ff7fc210bd4788787e35568b5e5e604e7f9b52e2c5d38260207daff71c108b81","size":{"x":32,"y":1,"z":32}},{"blockCount":73,"bytes":2014,"file":"chunks/y031-z032-x384.json","offset":{"x":384,"y":31,"z":32},"requirements":{"minecraft:bricks":18,"minecraft:cobbled_deepslate":1,"minecraft:glass":15,"minecraft:polished_diorite":13,"minecraft:sandstone":1,"minecraft:spruce_planks":11,"minecraft:stone_bricks":14},"sha256":"a5f0693a477a6dded9cbd3967eab8c2d274f074cafe06585f43cbd2723e9eec4","size":{"x":32,"y":1,"z":32}},{"blockCount":214,"bytes":4370,"file":"chunks/y031-z064-x064.json","offset":{"x":64,"y":31,"z":64},"requirements":{"minecraft:bricks":21,"minecraft:oak_planks":5,"minecraft:polished_diorite":95,"minecraft:spruce_planks":12,"minecraft:stone_bricks":81},"sha256":"4d85998d5f327cb968e3db6e9457d3ae23b041b30d559b71c18f21e90475ff29","size":{"x":32,"y":1,"z":32}},{"blockCount":250,"bytes":4046,"file":"chunks/y031-z064-x096.json","offset":{"x":96,"y":31,"z":64},"requirements":{"minecraft:bricks":48,"minecraft:oak_planks":10,"minecraft:polished_diorite":23,"minecraft:spruce_planks":59,"minecraft:stone_bricks":110},"sha256":"986ba044ac5352ce6c889accc90922cd535de68d2d32a445a163c14e0e3019fe","size":{"x":32,"y":1,"z":32}},{"blockCount":383,"bytes":5624,"file":"chunks/y031-z064-x128.json","offset":{"x":128,"y":31,"z":64},"requirements":{"minecraft:bricks":70,"minecraft:oak_planks":5,"minecraft:polished_diorite":124,"minecraft:spruce_planks":36,"minecraft:stone_bricks":148},"sha256":"e1594a9c3c5f3e0384ca2faf101053c4b4616e2204c083be3de91599382f6875","size":{"x":32,"y":1,"z":32}},{"blockCount":19,"bytes":1142,"file":"chunks/y031-z064-x160.json","offset":{"x":160,"y":31,"z":64},"requirements":{"minecraft:polished_diorite":2,"minecraft:stone_bricks":17},"sha256":"c2d0872d4657fc967861a94af5458c3ae14206feae9a38b8dd1095fae1dc49de","size":{"x":32,"y":1,"z":32}}],"schema":1}
