{"entries":[{"blockCount":25,"bytes":1094,"file":"chunks/y031-z064-x192.json","offset":{"x":192,"y":31,"z":64},"requirements":{"minecraft:polished_diorite":4,"minecraft:stone_bricks":21},"sha256":"d0a3d69cafdb7140797fc24c8b6ee476bbf3caf8baa1da1dad0559931c3fc4b7","size":{"x":32,"y":1,"z":32}},{"blockCount":32,"bytes":1211,"file":"chunks/y031-z064-x224.json","offset":{"x":224,"y":31,"z":64},"requirements":{"minecraft:bricks":1,"minecraft:polished_diorite":5,"minecraft:stone_bricks":26},"sha256":"49ccf8bc48dcf890518c1d20d409d3511df2875334c8c933b4ab8931e5457e3f","size":{"x":32,"y":1,"z":32}},{"blockCount":1,"bytes":640,"file":"chunks/y031-z064-x288.json","offset":{"x":288,"y":31,"z":64},"requirements":{"minecraft:oak_planks":1},"sha256":"49f69eabe981187fff0b3c2dc7690d2a67c2ed4519075cbe82c29b6519a80c18","size":{"x":32,"y":1,"z":32}},{"blockCount":1,"bytes":647,"file":"chunks/y031-z064-x320.json","offset":{"x":320,"y":31,"z":64},"requirements":{"minecraft:polished_diorite":1},"sha256":"a866972bf61e36aa019087c430b8f76642d5702faf9685ce2032ae59cd1b04cd","size":{"x":32,"y":1,"z":32}},{"blockCount":12,"bytes":919,"file":"chunks/y031-z064-x352.json","offset":{"x":352,"y":31,"z":64},"requirements":{"minecraft:polished_diorite":12},"sha256":"e0cb36af77303afeac8fc28bcf2d3c40b6b534b2f871935a20b67c7b7f23e837","size":{"x":32,"y":1,"z":32}},{"blockCount":93,"bytes":2729,"file":"chunks/y031-z096-x000.json","offset":{"x":0,"y":31,"z":96},"requirements":{"minecraft:polished_diorite":34,"minecraft:stone_bricks":59},"sha256":"b265c6da428f589cb93b38d9c128b157eef1e344e763c54b0767b9fe51c2d94c","size":{"x":32,"y":1,"z":32}},{"blockCount":233,"bytes":4519,"file":"chunks/y031-z096-x032.json","offset":{"x":32,"y":31,"z":96},"requirements":{"minecraft:polished_diorite":105,"minecraft:stone_bricks":128},"sha256":"263c9037c548bb725e8476368fcb2f6c64eb86f943f4f10959dc86b4ad264e68","size":{"x":32,"y":1,"z":32}},{"blockCount":337,"bytes":4439,"file":"chunks/y031-z096-x064.json","offset":{"x":64,"y":31,"z":96},"requirements":{"minecraft:bricks":19,"minecraft:polished_diorite":88,"minecraft:spruce_planks":3,"minecraft:stone_bricks":227},"sha256":"3596c8c485676d00ee3665c6a42c48bcda328114c2a79f2df6ecbfbe3d2f0d27","size":{"x":32,"y":1,"z":32}},{"blockCount":325,"bytes":5140,"file":"chunks/y031-z096-x096.json","offset":{"x":96,"y":31,"z":96},"requirements":{"minecraft:bricks":19,"minecraft:polished_diorite":11,"minecraft:spruce_planks":231,"minecraft:stone_bricks":64},"sha256":"a93951a5db06ed11407ac1b540387896e915adb85a203b99120cfd4733c466ae","size":{"x":32,"y":1,"z":32}},{"blockCount":271,"bytes":5217,"file":"chunks/y031-z096-x128.json","offset":{"x":128,"y":31,"z":96},"requirements":{"minecraft:bricks":11,"minecraft:polished_diorite":48,"minecraft:spruce_planks":130,"minecraft:stone_bricks":82},"sha256":"76910d6cb72b0371d938028188281b1de45303dd8565a78b82c7b9eab4299a34","size":{"x":32,"y":1,"z":32}},{"blockCount":311,"bytes":5108,"file":"chunks/y031-z096-x160.json","offset":{"x":160,"y":31,"z":96},"requirements":{"minecraft:bricks":15,"minecraft:polished_diorite":116,"minecraft:spruce_planks":64,"minecraft:stone_bricks":116},"sha256":"4a163dff347822fb149885dd1740988c359976f1047b33417edbaf3bc374f2e7","size":{"x":32,"y":1,"z":32}},{"blockCount":396,"bytes":5861,"file":"chunks/y031-z096-x192.json","offset":{"x":192,"y":31,"z":96},"requirements":{"minecraft:bricks":121,"minecraft:glass":5,"minecraft:polished_diorite":115,"minecraft:spruce_planks":63,"minecraft:stone_bricks":92},"sha256":"47025a48b705e991c4cb61b8384ed05a366c85b25c1efb5f6e59846011ea0f42","size":{"x":32,"y":1,"z":32}},{"blockCount":223,"bytes":4678,"file":"chunks/y031-z096-x224.json","offset":{"x":224,"y":31,"z":96},"requirements":{"minecraft:bricks":79,"minecraft:glass":4,"minecraft:oak_planks":5,"minecraft:polished_diorite":40,"minecraft:spruce_planks":16,"minecraft:stone_bricks":79},"sha256":"686783abd8d4e1d99518111caa59158dc121e1598f23db03522a298ece050049","size":{"x":32,"y":1,"z":32}},{"blockCount":1,"bytes":641,"file":"chunks/y031-z096-x256.json","offset":{"x":256,"y":31,"z":96},"requirements":{"minecraft:oak_planks":1},"sha256":"62459eededc247576137c107e5bee7636bd0b177de831c8b59ff77f0c1cedcf9","size":{"x":32,"y":1,"z":32}},{"blockCount":16,"bytes":1232,"file":"chunks/y031-z096-x352.json","offset":{"x":352,"y":31,"z":96},"requirements":{"minecraft:polished_diorite":16},"sha256":"eeadac869619d09e3e424dece2149c0fb2483ab866c138102f591818f52a8199","size":{"x":32,"y":1,"z":32}},{"blockCount":153,"bytes":3917,"file":"chunks/y031-z128-x000.json","offset":{"x":0,"y":31,"z":128},"requirements":{"minecraft:polished_diorite":53,"minecraft:stone_bricks":100},"sha256":"02162b51dcf1aebc1fdf779b6674a03343ccd39511aad87cb96380ce869229bc","size":{"x":32,"y":1,"z":32}},{"blockCount":239,"bytes":4370,"file":"chunks/y031-z128-x032.json","offset":{"x":32,"y":31,"z":128},"requirements":{"minecraft:polished_diorite":10,"minecraft:stone_bricks":229},"sha256":"f740343d0410ef08bcbce9c8585fcce65a01247a0f93e0cee41ea012fab1cc2c","size":{"x":32,"y":1,"z":32}},{"blockCount":307,"bytes":4295,"file":"chunks/y031-z128-x064.json","offset":{"x":64,"y":31,"z":128},"requirements":{"minecraft:bricks":32,"minecraft:oak_planks":2,"minecraft:polished_diorite":4,"minecraft:spruce_planks":59,"minecraft:stone_bricks":210},"sha256":"62225be83b13381ad34e40cc5842ec6d8a499dcde3a234cc002f0ba54358f28e","size":{"x":32,"y":1,"z":32}},{"blockCount":582,"bytes":3597,"file":"chunks/y031-z128-x096.json","offset":{"x":96,"y":31,"z":128},"requirements":{"minecraft:bricks":394,"minecraft:polished_diorite":4,"minecraft:sandstone":3,"minecraft:spruce_planks":27,"minecraft:stone_bricks":154},"sha256":"09fee15df9a1c3ab7851d0580baff78e9641edcdb6d9ae9b9b26f5db6d901cdc","size":{"x":32,"y":1,"z":32}},{"blockCount":385,"bytes":7939,"file":"chunks/y031-z128-x128.json","offset":{"x":128,"y":31,"z":128},"requirements":{"minecraft:bricks":50,"minecraft:polished_diorite":8,"minecraft:spruce_planks":228,"minecraft:stone_bricks":99},"sha256":"74e43060c96e11829a8cb5fbe2d0ee6dda839d01702675f3d7930184e44c3c57","size":{"x":32,"y":1,"z":32}},{"blockCount":368,"bytes":9143,"file":"chunks/y031-z128-x160.json","offset":{"x":160,"y":31,"z":128},"requirements":{"minecraft:polished_diorite":9,"minecraft:spruce_planks":325,"minecraft:stone_bricks":34},"sha256":"2756aa157646900b9019ac476ec06071a262dcc9e0f596058cd6a0870c85f975","size":{"x":32,"y":1,"z":32}},{"blockCount":181,"bytes":4196,"file":"chunks/y031-z128-x192.json","offset":{"x":192,"y":31,"z":128},"requirements":{"minecraft:bricks":62,"minecraft:glass":2,"minecraft:polished_diorite":22,"minecraft:sandstone":2,"minecraft:spruce_planks":45,"minecraft:stone_bricks":48},"sha256":"6edd87a372b70535ad91fb76a7a7ddfd3b588240ad436d62d0ba75d25a88c977","size":{"x":32,"y":1,"z":32}},{"blockCount":182,"bytes":3309,"file":"chunks/y031-z128-x224.json","offset":{"x":224,"y":31,"z":128},"requirements":{"minecraft:bricks":47,"minecraft:oak_planks":10,"minecraft:polished_diorite":28,"minecraft:stone_bricks":97},"sha256":"dd6115fc82d149e0ff3807e9d1b14055a4dffa8288fae00461cb2b478aad9bdd","size":{"x":32,"y":1,"z":32}},{"blockCount":4,"bytes":764,"file":"chunks/y031-z128-x320.json","offset":{"x":320,"y":31,"z":128},"requirements":{"minecraft:polished_diorite":4},"sha256":"7106301d9755a3c86725aa92f884cc4c5bbd911802f4a89b2a21f302e0b8d00f","size":{"x":32,"y":1,"z":32}},{"blockCount":65,"bytes":2135,"file":"chunks/y031-z160-x000.json","offset":{"x":0,"y":31,"z":160},"requirements":{"minecraft:polished_diorite":25,"minecraft:stone_bricks":40},"sha256":"d045af7feabf6d2746bd9aa0a47021ab1e2f225ae928d4ff7a319043c14156b1","size":{"x":32,"y":1,"z":32}},{"blockCount":196,"bytes":3603,"file":"chunks/y031-z160-x032.json","offset":{"x":32,"y":31,"z":160},"requirements":{"minecraft:polished_diorite":98,"minecraft:stone_bricks":98},"sha256":"ad803870ea66747fb26f60760b5493fb3e71633a9a09c6b78df5cb17c44f0932","size":{"x":32,"y":1,"z":32}},{"blockCount":310,"bytes":4116,"file":"chunks/y031-z160-x064.json","offset":{"x":64,"y":31,"z":160},"requirements":{"minecraft:bricks":14,"minecraft:polished_diorite":107,"minecraft:spruce_planks":7,"minecraft:stone_bricks":182},"sha256":"b4cd304395ef417ec3e1341d020ac541887eca48a07a6318b42dc29519fd6470","size":{"x":32,"y":1,"z":32}},{"blockCount":317,"bytes":5197,"file":"chunks/y031-z160-x096.json","offset":{"x":96,"y":31,"z":160},"requirements":{"minecraft:bricks":7,"minecraft:polished_diorite":9,"minecraft:spruce_planks":267,"minecraft:stone_bricks":34},"sha256":"c4ae0cf4b29ab32278976431e53739c51218adfc2a073241c286a4e1cf92c517","size":{"x":32,"y":1,"z":32}},{"blockCount":278,"bytes":4972,"file":"chunks/y031-z160-x128.json","offset":{"x":128,"y":31,"z":160},"requirements":{"minecraft:bricks":14,"minecraft:polished_diorite":64,"minecraft:spruce_planks":127,"minecraft:stone_bricks":73},"sha256":"02d8f261792b4b1df4c28afb493cb8e123c3a14972063981078c3dc1f8c5d351","size":{"x":32,"y":1,"z":32}},{"blockCount":231,"bytes":3589,"file":"chunks/y031-z160-x160.json","offset":{"x":160,"y":31,"z":160},"requirements":{"minecraft:bricks":15,"minecraft:polished_diorite":108,"minecraft:spruce_planks":24,"minecraft:stone_bricks":84},"sha256":"4b44a2dc43ee9607380f96b55df0d5719f53ffcb5aba9bafb8b47a087a630faa","size":{"x":32,"y":1,"z":32}},{"blockCount":323,"bytes":4817,"file":"chunks/y031-z160-x192.json","offset":{"x":192,"y":31,"z":160},"requirements":{"minecraft:bricks":106,"minecraft:glass":5,"minecraft:polished_diorite":96,"minecraft:spruce_planks":36,"minecraft:stone_bricks":80},"sha256":"be9201a3b352b4937e7b52ed2d77491622293fc4079659e69417ffee2a19d9ec","size":{"x":32,"y":1,"z":32}},{"blockCount":167,"bytes":3880,"file":"chunks/y031-z160-x224.json","offset":{"x":224,"y":31,"z":160},"requirements":{"minecraft:bricks":61,"minecraft:glass":4,"minecraft:oak_planks":5,"minecraft:polished_diorite":24,"minecraft:spruce_planks":15,"minecraft:stone_bricks":58},"sha256":"161a050d754bc9a82a888ee8311605cbeafb04d8740cc7e71c30eeaf9404044a","size":{"x":32,"y":1,"z":32}},{"blockCount":1,"bytes":642,"file":"chunks/y031-z160-x256.json","offset":{"x":256,"y":31,"z":160},"requirements":{"minecraft:oak_planks":1},"sha256":"713bc644a4f5fbffc782555b39da95ae467d8b1bd80029cbafc9385f517bc17a","size":{"x":32,"y":1,"z":32}},{"blockCount":1,"bytes":645,"file":"chunks/y031-z160-x288.json","offset":{"x":288,"y":31,"z":160},"requirements":{"minecraft:spruce_planks":1},"sha256":"651fd416297a4d5075aea2807168c95c08d9c5dbe0cebccf142752d1de987ad5","size":{"x":32,"y":1,"z":32}},{"blockCount":1,"bytes":628,"file":"chunks/y031-z160-x320.json","offset":{"x":320,"y":31,"z":160},"requirements":{"minecraft:polished_diorite":1},"sha256":"80695f4030fff96d7c4ac5cac320c12cb40e23dd0f53e473ba0b6b5e2b257a7d","size":{"x":32,"y":1,"z":32}},{"blockCount":49,"bytes":2226,"file":"chunks/y031-z160-x352.json","offset":{"x":352,"y":31,"z":160},"requirements":{"minecraft:oak_planks":21,"minecraft:polished_diorite":28},"sha256":"f350b41536fc35bcc0c00e628fd75361e5dbd082766f10fb5066cb154702fc50","size":{"x":32,"y":1,"z":32}},{"blockCount":167,"bytes":3700,"file":"chunks/y031-z192-x064.json","offset":{"x":64,"y":31,"z":192},"requirements":{"minecraft:bricks":18,"minecraft:oak_planks":5,"minecraft:polished_diorite":72,"minecraft:spruce_planks":5,"minecraft:stone_bricks":67},"sha256":"518dd9042f5ebeef2e17c62a814beea17565e91b7a966c412117737a3eafd138","size":{"x":32,"y":1,"z":32}},{"blockCount":186,"bytes":3222,"file":"chunks/y031-z192-x096.json","offset":{"x":96,"y":31,"z":192},"requirements":{"minecraft:bricks":48,"minecraft:oak_planks":10,"minecraft:polished_diorite":22,"minecraft:spruce_planks":5,"minecraft:stone_bricks":101},"sha256":"9a29c11b7d97a5a4f2210081cccdd37868a01f2d8536d71505ccb9d9daa69fdf","size":{"x":32,"y":1,"z":32}},{"blockCount":313,"bytes":4688,"file":"chunks/y031-z192-x128.json","offset":{"x":128,"y":31,"z":192},"requirements":{"minecraft:bricks":67,"minecraft:oak_planks":5,"minecraft:polished_diorite":100,"minecraft:spruce_planks":11,"minecraft:stone_bricks":130},"sha256":"4e56ff81e7de6af6aeb8ff004b0c7e29b833140a537d5b939e2bd6e4f466a905","size":{"x":32,"y":1,"z":32}},{"blockCount":16,"bytes":1066,"file":"chunks/y031-z192-x160.json","offset":{"x":160,"y":31,"z":192},"requirements":{"minecraft:polished_diorite":2,"minecraft:stone_bricks":14},"sha256":"28d7a92e354d765227e378e9d0564ea95b5e83a18189ca2b54d4c78070cdadc5","size":{"x":32,"y":1,"z":32}},{"blockCount":154,"bytes":4127,"file":"chunks/y032-z000-x352.json","offset":{"x":352,"y":32,"z":0},"requirements":{"minecraft:bricks":17,"minecraft:glass":17,"minecraft:oak_planks":3,"minecraft:polished_diorite":50,"minecraft:sandstone":5,"minecraft:spruce_planks":9,"minecraft:stone_bricks":53},"sha256":"519f8b48efb4419bfc0d9065ff725f98a72509136d1c1dbc3049271aa95b8568","size":{"x":32,"y":1,"z":32}},{"blockCount":276,"bytes":5842,"file":"chunks/y032-z000-x384.json","offset":{"x":384,"y":32,"z":0},"requirements":{"minecraft:bricks":54,"minecraft:glass":19,"minecraft:oak_planks":22,"minecraft:polished_diorite":57,"minecraft:sandstone":11,"minecraft:spruce_planks":52,"minecraft:stone_bricks":61},"sha256":"19e51f22665e92330f57bf0f2ccbbdc249ae78190c8125a4b01cf71a3477a4f8","size":{"x":32,"y":1,"z":32}},{"blockCount":9,"bytes":816,"file":"chunks/y032-z032-x064.json","offset":{"x":64,"y":32,"z":32},"requirements":{"minecraft:glass":4,"minecraft:stone_bricks":5},"sha256":"deb6b6fdec3236d44127e7552b92f3c1b3c066a6a89a15c0dd53d8941d83a7c4","size":{"x":32,"y":1,"z":32}},{"blockCount":9,"bytes":817,"file":"chunks/y032-z032-x128.json","offset":{"x":128,"y":32,"z":32},"requirements":{"minecraft:glass":4,"minecraft:stone_bricks":5},"sha256":"760d76b5599455ddab5451c27cabdcb4458a3bd2d47e91544fc52055f2c3c656","size":{"x":32,"y":1,"z":32}},{"blockCount":103,"bytes":3362,"file":"chunks/y032-z032-x352.json","offset":{"x":352,"y":32,"z":32},"requirements":{"minecraft:bricks":14,"minecraft:glass":20,"minecraft:polished_diorite":28,"minecraft:spruce_planks":12,"minecraft:stone_bricks":29},"sha256":"6fccb0edc5321efce7e707a0ce708f640ee9ca49579408d8d8d9aebb85813412","size":{"x":32,"y":1,"z":32}},{"blockCount":61,"bytes":1786,"file":"chunks/y032-z032-x384.json","offset":{"x":384,"y":32,"z":32},"requirements":{"minecraft:bricks":16,"minecraft:polished_diorite":14,"minecraft:sandstone":1,"minecraft:spruce_planks":5,"minecraft:stone_bricks":25},"sha256":"9114012c0e135dd1c5fa7c8aa04955cb09fcbd23f2ef3ba57a8adf85ae6ac795","size":{"x":32,"y":1,"z":32}},{"blockCount":193,"bytes":4782,"file":"chunks/y032-z064-x064.json","offset":{"x":64,"y":32,"z":64},"requirements":{"minecraft:bricks":40,"minecraft:polished_diorite":50,"minecraft:spruce_planks":12,"minecraft:stone_bricks":91},"sha256":"888232a69bf7d5728200a7c212154b9ba6c97fe26a89e75f031cd9381e6f265f","size":{"x":32,"y":1,"z":32}},{"blockCount":200,"bytes":3729,"file":"chunks/y032-z064-x096.json","offset":{"x":96,"y":32,"z":64},"requirements":{"minecraft:bricks":48,"minecraft:polished_diorite":24,"minecraft:spruce_planks":36,"minecraft:stone_bricks":92},"sha256":"a96e245d84c36d4f7301dfd93c362615fb093b3754a03f4b76c0e99fef8da3ac","size":{"x":32,"y":1,"z":32}},{"blockCount":339,"bytes":5924,"file":"chunks/y032-z064-x128.json","offset":{"x":128,"y":32,"z":64},"requirements":{"minecraft:bricks":89,"minecraft:polished_diorite":74,"minecraft:spruce_planks":22,"minecraft:stone_bricks":154},"sha256":"e2636a819c782b5eb9b3e0205f48bc7d5c5236ee59bc0f50025a7156b05e0ee0","size":{"x":32,"y":1,"z":32}},{"blockCount":19,"bytes":1199,"file":"chunks/y032-z064-x160.json","offset":{"x":160,"y":32,"z":64},"requirements":{"minecraft:polished_diorite":5,"minecraft:stone_bricks":14},"sha256":"e9076fe490bcdfde5754513f96f116655c525f4185e1b547fa14f5e132981e50","size":{"x":32,"y":1,"z":32}},{"blockCount":29,"bytes":1113,"file":"chunks/y032-z064-x192.json","offset":{"x":192,"y":32,"z":64},"requirements":{"minecraft:polished_diorite":8,"minecraft:stone_bricks":21},"sha256":"7654554fbeb75057380ef0b6df25527b601b7e11f978e649b83648e6dfd4e195","size":{"x":32,"y":1,"z":32}},{"blockCount":36,"bytes":1230,"file":"chunks/y032-z064-x224.json","offset":{"x":224,"y":32,"z":64},"requirements":{"minecraft:bricks":1,"minecraft:polished_diorite":9,"minecraft:stone_bricks":26},"sha256":"1933dc0abaf63536d5402d576dda52c7a75a98f59a164a303069627af56fda9a","size":{"x":32,"y":1,"z":32}},{"blockCount":3,"bytes":687,"file":"chunks/y032-z064-x288.json","offset":{"x":288,"y":32,"z":64},"requirements":{"minecraft:oak_planks":1,"minecraft:spruce_planks":2},"sha256":"60c9992f17b7ee8b079f99ebe811d9d0837da35490805af5a3a24dc6eb9e3c06","size":{"x":32,"y":1,"z":32}},{"blockCount":1,"bytes":647,"file":"chunks/y032-z064-x320.json","offset":{"x":320,"y":32,"z":64},"requirements":{"minecraft:polished_diorite":1},"sha256":"ffeeb246fc0aaaf8c3d2cf948ce071c837b29faca24b6442ac220acf79c1fe2d","size":{"x":32,"y":1,"z":32}},{"blockCount":6,"bytes":841,"file":"chunks/y032-z064-x352.json","offset":{"x":352,"y":32,"z":64},"requirements":{"minecraft:polished_diorite":6},"sha256":"21a3730d5038e55cf05e9c6419751e2da3c6fe4c5d9dec3da48740960895b2b5","size":{"x":32,"y":1,"z":32}},{"blockCount":229,"bytes":2948,"file":"chunks/y032-z096-x000.json","offset":{"x":0,"y":32,"z":96},"requirements":{"minecraft:bricks":1,"minecraft:polished_diorite":34,"minecraft:stone_bricks":194},"sha256":"79eac1e03c9c7779dbb8c0e407cb7f5540103797292988d7073de686a95bf1a2","size":{"x":32,"y":1,"z":32}},{"blockCount":807,"bytes":2173,"file":"chunks/y032-z096-x032.json","offset":{"x":32,"y":32,"z":96},"requirements":{"minecraft:oak_planks":1,"minecraft:polished_diorite":50,"minecraft:stone_bricks":756},"sha256":"e512f2b9174186fc8429274bd4d7620e18cd48a40f9501608328aac26d57536b","size":{"x":32,"y":1,"z":32}},{"blockCount":498,"bytes":4075,"file":"chunks/y032-z096-x064.json","offset":{"x":64,"y":32,"z":96},"requirements":{"minecraft:bricks":28,"minecraft:polished_diorite":45,"minecraft:spruce_planks":9,"minecraft:stone_bricks":416},"sha256":"2f4442a4a5434aa763d8abdd5d1739f008c3c88d14c9f1e8db7e3b058ebbb8d3","size":{"x":32,"y":1,"z":32}},{"blockCount":179,"bytes":5142,"file":"chunks/y032-z096-x096.json","offset":{"x":96,"y":32,"z":96},"requirements":{"minecraft:bricks":3,"minecraft:oak_planks":1,"minecraft:spruce_planks":131,"minecraft:stone_bricks":44},"sha256":"56b1f6db30fe09f6c64d00548681e46d7413acdea0180bc22d13a9c2ab0af8f4","size":{"x":32,"y":1,"z":32}},{"blockCount":190,"bytes":4839,"file":"chunks/y032-z096-x128.json","offset":{"x":128,"y":32,"z":96},"requirements":{"minecraft:bricks":20,"minecraft:glass":1,"minecraft:polished_diorite":15,"minecraft:spruce_planks":66,"minecraft:stone_bricks":88},"sha256":"43d822f4fd06e2adc59d76fc4a31f27853f039bd7b214ed240f4135dd88017d3","size":{"x":32,"y":1,"z":32}},{"blockCount":275,"bytes":4505,"file":"chunks/y032-z096-x160.json","offset":{"x":160,"y":32,"z":96},"requirements":{"minecraft:bricks":17,"minecraft:polished_diorite":79,"minecraft:spruce_planks":44,"minecraft:stone_bricks":135},"sha256":"a4b20458d57f3b66ad9f3be6cda280b3a527f4c6988f78ba0d25bfe929f90b65","size":{"x":32,"y":1,"z":32}},{"blockCount":351,"bytes":5012,"file":"chunks/y032-z096-x192.json","offset":{"x":192,"y":32,"z":96},"requirements":{"minecraft:bricks":124,"minecraft:glass":6,"minecraft:polished_diorite":77,"minecraft:sandstone":2,"minecraft:spruce_planks":27,"minecraft:stone_bricks":115},"sha256":"c260e681eff7d4bf325909d168cf339a522620ae019c4d19667ab3bc08fe4527","size":{"x":32,"y":1,"z":32}},{"blockCount":226,"bytes":4308,"file":"chunks/y032-z096-x224.json","offset":{"x":224,"y":32,"z":96},"requirements":{"minecraft:bricks":79,"minecraft:glass":4,"minecraft:polished_diorite":43,"minecraft:spruce_planks":12,"minecraft:stone_bricks":88},"sha256":"f09e1bfb62b7358d136614ea4a1bfaca2a19a7edf203bcb2ee7ffcedc90a8cc4","size":{"x":32,"y":1,"z":32}},{"blockCount":1,"bytes":641,"file":"chunks/y032-z096-x256.json","offset":{"x":256,"y":32,"z":96},"requirements":{"minecraft:oak_planks":1},"sha256":"bf1a10c94595882729a8088a683efb0ff496a75cbefe5db23705c2ca5ff84523","size":{"x":32,"y":1,"z":32}},{"blockCount":8,"bytes":919,"file":"chunks/y032-z096-x352.json","offset":{"x":352,"y":32,"z":96},"requirements":{"minecraft:polished_diorite":8},"sha256":"71e84544d4b4969c24af3c747286d9ba5637ace4c8dbdbf28acde206bc46d15b","size":{"x":32,"y":1,"z":32}},{"blockCount":506,"bytes":3434,"file":"chunks/y032-z128-x000.json","offset":{"x":0,"y":32,"z":128},"requirements":{"minecraft:polished_diorite":41,"minecraft:stone_bricks":465},"sha256":"00bccf01349cf73933db28c2a190bf2c639fcbb5608c3c5048f78dc8ec990213","size":{"x":32,"y":1,"z":32}},{"blockCount":918,"bytes":1542,"file":"chunks/y032-z128-x032.json","offset":{"x":32,"y":32,"z":128},"requirements":{"minecraft:stone_bricks":918},"sha256":"68dfeb2ea4e080a20a222649d3bb9a1b5fe4d8dfe846b77e4f119498eca78500","size":{"x":32,"y":1,"z":32}},{"blockCount":587,"bytes":3988,"file":"chunks/y032-z128-x064.json","offset":{"x":64,"y":32,"z":128},"requirements":{"minecraft:bricks":34,"minecraft:oak_planks":1,"minecraft:spruce_planks":61,"minecraft:stone_bricks":491},"sha256":"a3fc2f6ad39a85d68c76fb1cd42a38648e6013163f3c13bdfbbc9153f038d3fe","size":{"x":32,"y":1,"z":32}},{"blockCount":46,"bytes":1801,"file":"chunks/y032-z128-x096.json","offset":{"x":96,"y":32,"z":128},"requirements":{"minecraft:bricks":18,"minecraft:glass":1,"minecraft:polished_diorite":1,"minecraft:sandstone":3,"minecraft:spruce_planks":13,"minecraft:stone_bricks":10},"sha256":"3ed6a77dbe540451727dc0bdb8816570f171b5c7e94d39487875dc62357121ca","size":{"x":32,"y":1,"z":32}},{"blockCount":136,"bytes":4260,"file":"chunks/y032-z128-x128.json","offset":{"x":128,"y":32,"z":128},"requirements":{"minecraft:spruce_planks":106,"minecraft:stone_bricks":30},"sha256":"1b96e70cc500710d77563625113dccef0e17954b6f6e54e7596880caa22608f1","size":{"x":32,"y":1,"z":32}},{"blockCount":191,"bytes":5874,"file":"chunks/y032-z128-x160.json","offset":{"x":160,"y":32,"z":128},"requirements":{"minecraft:glass":2,"minecraft:spruce_planks":153,"minecraft:stone_bricks":36},"sha256":"775cb382944de4f2cb0b3243b29e084674481c750977ae8bc085d128a72b6607","size":{"x":32,"y":1,"z":32}},{"blockCount":172,"bytes":3721,"file":"chunks/y032-z128-x192.json","offset":{"x":192,"y":32,"z":128},"requirements":{"minecraft:bricks":75,"minecraft:glass":4,"minecraft:polished_diorite":7,"minecraft:sandstone":6,"minecraft:spruce_planks":19,"minecraft:stone_bricks":61},"sha256":"c51ab586956badb7427d8b2609022166337739f581086cd4811b61d43830373c","size":{"x":32,"y":1,"z":32}},{"blockCount":189,"bytes":3161,"file":"chunks/y032-z128-x224.json","offset":{"x":224,"y":32,"z":128},"requirements":{"minecraft:bricks":47,"minecraft:polished_diorite":31,"minecraft:spruce_planks":10,"minecraft:stone_bricks":101},"sha256":"46814763af4d334238f25931bfbf5f4ee2e238497e8ffe5a756d05fa8ccfae86","size":{"x":32,"y":1,"z":32}},{"blockCount":4,"bytes":764,"file":"chunks/y032-z128-x320.json","offset":{"x":320,"y":32,"z":128},"requirements":{"minecraft:polished_diorite":4},"sha256":"0411769f747d6c69d8e2a13b5520113576f32b63f6f8adfafc51dfd21bd88b90","size":{"x":32,"y":1,"z":32}},{"blockCount":116,"bytes":2213,"file":"chunks/y032-z160-x000.json","offset":{"x":0,"y":32,"z":160},"requirements":{"minecraft:bricks":1,"minecraft:polished_diorite":20,"minecraft:stone_bricks":95},"sha256":"49c5e7be60f1d1999d8879bd7b391efed59c7eaa0deae05e775250a346be50f2","size":{"x":32,"y":1,"z":32}},{"blockCount":583,"bytes":2130,"file":"chunks/y032-z160-x032.json","offset":{"x":32,"y":32,"z":160},"requirements":{"minecraft:polished_diorite":64,"minecraft:stone_bricks":519},"sha256":"ae9e3dba15da4c6a78ee2150533c5c8376adc18944c96c7d2235bcbe9684d224","size":{"x":32,"y":1,"z":32}},{"blockCount":409,"bytes":4165,"file":"chunks/y032-z160-x064.json","offset":{"x":64,"y":32,"z":160},"requirements":{"minecraft:bricks":31,"minecraft:polished_diorite":70,"minecraft:spruce_planks":4,"minecraft:stone_bricks":304},"sha256":"1646c45a6d740ab3e0fc3af880de4e3c4b6780a577bf5f93b273fe01e3f8f4ca","size":{"x":32,"y":1,"z":32}},{"blockCount":196,"bytes":5996,"file":"chunks/y032-z160-x096.json","offset":{"x":96,"y":32,"z":160},"requirements":{"minecraft:bricks":7,"minecraft:polished_diorite":1,"minecraft:sandstone":2,"minecraft:spruce_planks":152,"minecraft:stone_bricks":34},"sha256":"3af87589594912a29a4fbbf4b366a9c83e93becd5a7cc9ed4f14035a8ddb5409","size":{"x":32,"y":1,"z":32}},{"blockCount":197,"bytes":5130,"file":"chunks/y032-z160-x128.json","offset":{"x":128,"y":32,"z":160},"requirements":{"minecraft:bricks":29,"minecraft:polished_diorite":26,"minecraft:sandstone":2,"minecraft:spruce_planks":59,"minecraft:stone_bricks":81},"sha256":"3e6184002cffa17f1881954d8129e1223e4eae715ecfe95c3bd98a683a4adf16","size":{"x":32,"y":1,"z":32}},{"blockCount":212,"bytes":3288,"file":"chunks/y032-z160-x160.json","offset":{"x":160,"y":32,"z":160},"requirements":{"minecraft:bricks":17,"minecraft:polished_diorite":80,"minecraft:spruce_planks":14,"minecraft:stone_bricks":101},"sha256":"95bfafc8fc1e6b7dd6dbd246e812b6b6e4dfa2acee6525e8ce1941a461633a4e","size":{"x":32,"y":1,"z":32}},{"blockCount":294,"bytes":4289,"file":"chunks/y032-z160-x192.json","offset":{"x":192,"y":32,"z":160},"requirements":{"minecraft:bricks":103,"minecraft:glass":4,"minecraft:polished_diorite":76,"minecraft:sandstone":2,"minecraft:spruce_planks":11,"minecraft:stone_bricks":98},"sha256":"148075c209ee259d7fbbf4987646a75f310fe7dce2d5e9b1cac974c6b59c1246","size":{"x":32,"y":1,"z":32}},{"blockCount":164,"bytes":3757,"file":"chunks/y032-z160-x224.json","offset":{"x":224,"y":32,"z":160},"requirements":{"minecraft:bricks":61,"minecraft:glass":4,"minecraft:polished_diorite":27,"minecraft:spruce_planks":12,"minecraft:stone_bricks":60},"sha256":"50dce658ba97fcb1a0ab240698883502d0ca7c5971c37d3dc25b9f8b737deda0","size":{"x":32,"y":1,"z":32}},{"blockCount":1,"bytes":642,"file":"chunks/y032-z160-x256.json","offset":{"x":256,"y":32,"z":160},"requirements":{"minecraft:oak_planks":1},"sha256":"9aa1ecb1c77fcef46a27a97c98b9cca63796cb6b49f3f6d21e829b5358457a1c","size":{"x":32,"y":1,"z":32}},{"blockCount":1,"bytes":642,"file":"chunks/y032-z160-x288.json","offset":{"x":288,"y":32,"z":160},"requirements":{"minecraft:oak_planks":1},"sha256":"ae8d21daea158cc867615ce72c12b1acf703369c633cd8a4556dcd92e9c4b185","size":{"x":32,"y":1,"z":32}},{"blockCount":1,"bytes":628,"file":"chunks/y032-z160-x320.json","offset":{"x":320,"y":32,"z":160},"requirements":{"minecraft:polished_diorite":1},"sha256":"6048d5faeb0147d2a25888399170bcce66871a82f5a6f987768bfaf9801912f3","size":{"x":32,"y":1,"z":32}},{"blockCount":22,"bytes":1412,"file":"chunks/y032-z160-x352.json","offset":{"x":352,"y":32,"z":160},"requirements":{"minecraft:oak_planks":8,"minecraft:polished_diorite":14},"sha256":"53ae9426cfac2c4eee4863ac89a112aa1f5ad5183124c6a11e63f0880ccd1f20","size":{"x":32,"y":1,"z":32}},{"blockCount":149,"bytes":3884,"file":"chunks/y032-z192-x064.json","offset":{"x":64,"y":32,"z":192},"requirements":{"minecraft:bricks":31,"minecraft:polished_diorite":38,"minecraft:spruce_planks":8,"minecraft:stone_bricks":72},"sha256":"5fad6239e06af27721e23bd489b00de5a964de457f5a33b82bc4c44de9180c56","size":{"x":32,"y":1,"z":32}},{"blockCount":170,"bytes":2797,"file":"chunks/y032-z192-x096.json","offset":{"x":96,"y":32,"z":192},"requirements":{"minecraft:bricks":48,"minecraft:polished_diorite":24,"minecraft:spruce_planks":10,"minecraft:stone_bricks":88},"sha256":"ff46715a58d3c29393e0fdbd8c4292cd9f493e713ba2b18da4b16ae01db65b63","size":{"x":32,"y":1,"z":32}},{"blockCount":278,"bytes":4704,"file":"chunks/y032-z192-x128.json","offset":{"x":128,"y":32,"z":192},"requirements":{"minecraft:bricks":80,"minecraft:polished_diorite":63,"minecraft:spruce_planks":8,"minecraft:stone_bricks":127},"sha256":"0e2fef84cc234c8145560c97d427365333b0214bfec7197a58e4d1a93acaaf1e","size":{"x":32,"y":1,"z":32}},{"blockCount":16,"bytes":1104,"file":"chunks/y032-z192-x160.json","offset":{"x":160,"y":32,"z":192},"requirements":{"minecraft:polished_diorite":4,"minecraft:stone_bricks":12},"sha256":"3de7882816717a4e3d2c285a27bb49595d4bee221ca17d7b73df0f31d30b6bed","size":{"x":32,"y":1,"z":32}},{"blockCount":150,"bytes":4103,"file":"chunks/y033-z000-x352.json","offset":{"x":352,"y":33,"z":0},"requirements":{"minecraft:bricks":17,"minecraft:cobbled_deepslate":1,"minecraft:glass":10,"minecraft:oak_planks":3,"minecraft:polished_diorite":57,"minecraft:sandstone":5,"minecraft:spruce_planks":7,"minecraft:stone_bricks":50},"sha256":"17f8adcb1267b0f7af3d89773f278d92f0e46d5dba906908fe83653da6b563ed","size":{"x":32,"y":1,"z":32}},{"blockCount":252,"bytes":5653,"file":"chunks/y033-z000-x384.json","offset":{"x":384,"y":33,"z":0},"requirements":{"minecraft:bricks":41,"minecraft:cobbled_deepslate":1,"minecraft:glass":27,"minecraft:oak_planks":26,"minecraft:polished_diorite":59,"minecraft:sandstone":6,"minecraft:spruce_planks":47,"minecraft:stone_bricks":45},"sha256":"481d00a74b8d41b08e0b461cc4238cdac9b93505a28d1711f5c61c2b53123061","size":{"x":32,"y":1,"z":32}},{"blockCount":9,"bytes":816,"file":"chunks/y033-z032-x064.json","offset":{"x":64,"y":33,"z":32},"requirements":{"minecraft:glass":4,"minecraft:stone_bricks":5},"sha256":"4237725e74b4a2411585d2d15f07c30a788eb044cd2fedc2339dbecae14103c9","size":{"x":32,"y":1,"z":32}},{"blockCount":9,"bytes":817,"file":"chunks/y033-z032-x128.json","offset":{"x":128,"y":33,"z":32},"requirements":{"minecraft:glass":4,"minecraft:stone_bricks":5},"sha256":"802b030b7c10fe9acb2934d9ae430263ef1f0ef3c1646f545724754b1af35194","size":{"x":32,"y":1,"z":32}},{"blockCount":124,"bytes":3593,"file":"chunks/y033-z032-x352.json","offset":{"x":352,"y":33,"z":32},"requirements":{"minecraft:bricks":21,"minecraft:glass":31,"minecraft:polished_diorite":39,"minecraft:spruce_planks":12,"minecraft:stone_bricks":21},"sha256":"9fbf5e7f1fa71f035bc19b0d849147b506674adc53f9fbcca47fcdfdec26462b","size":{"x":32,"y":1,"z":32}},{"blockCount":37,"bytes":1624,"file":"chunks/y033-z032-x384.json","offset":{"x":384,"y":33,"z":32},"requirements":{"minecraft:bricks":11,"minecraft:cobbled_deepslate":1,"minecraft:glass":5,"minecraft:polished_diorite":9,"minecraft:spruce_planks":1,"minecraft:stone_bricks":10},"sha256":"68134cc4d90b69bef9d377b678ebbdb572335b20fe00d4c166dac8a7959373f6","size":{"x":32,"y":1,"z":32}},{"blockCount":159,"bytes":4730,"file":"chunks/y033-z064-x064.json","offset":{"x":64,"y":33,"z":64},"requirements":{"minecraft:bricks":35,"minecraft:oak_planks":5,"minecraft:polished_diorite":57,"minecraft:spruce_planks":3,"minecraft:stone_bricks":59},"sha256":"92e8c7ee043c3183fe695c979c83ff170097b4d646cda9c2fb793f29e23a2e3a","size":{"x":32,"y":1,"z":32}},{"blockCount":177,"bytes":3966,"file":"chunks/y033-z064-x096.json","offset":{"x":96,"y":33,"z":64},"requirements":{"minecraft:bricks":50,"minecraft:glass":1,"minecraft:oak_planks":10,"minecraft:polished_diorite":41,"minecraft:spruce_planks":14,"minecraft:stone_bricks":61},"sha256":"a328d0fbafd94ff6f5947bec2019e14ac732e0cadc6c3c1052d1c9579c194d5c","size":{"x":32,"y":1,"z":32}},{"blockCount":282,"bytes":6271,"file":"chunks/y033-z064-x128.json","offset":{"x":128,"y":33,"z":64},"requirements":{"minecraft:bricks":74,"minecraft:glass":1,"minecraft:oak_planks":5,"minecraft:polished_diorite":98,"minecraft:spruce_planks":9,"minecraft:stone_bricks":95},"sha256":"c595599845e59b2fc4c1977a3e43c1877e58922146456bc15c5109e261bf9363","size":{"x":32,"y":1,"z":32}},{"blockCount":17,"bytes":1199,"file":"chunks/y033-z064-x160.json","offset":{"x":160,"y":33,"z":64},"requirements":{"minecraft:polished_diorite":5,"minecraft:stone_bricks":12},"sha256":"579ff2fdf5909fa1ded76679942da8ab7fb7f2029084fe3d4551464c075f4c06","size":{"x":32,"y":1,"z":32}},{"blockCount":24,"bytes":1246,"file":"chunks/y033-z064-x192.json","offset":{"x":192,"y":33,"z":64},"requirements":{"minecraft:polished_diorite":9,"minecraft:stone_bricks":15},"sha256":"390591eb986d6d00e94656208d324cea6c8ceed6f8afcbca25ecd1f12b8bc06e","size":{"x":32,"y":1,"z":32}},{"blockCount":29,"bytes":1381,"file":"chunks/y033-z064-x224.json","offset":{"x":224,"y":33,"z":64},"requirements":{"minecraft:polished_diorite":11,"minecraft:stone_bricks":18},"sha256":"84865850426eef25584c880f8f81ecb12bbf95724ea03a2b6ca49ec46a092270","size":{"x":32,"y":1,"z":32}},{"blockCount":10,"bytes":926,"file":"chunks/y033-z064-x288.json","offset":{"x":288,"y":33,"z":64},"requirements":{"minecraft:oak_planks":4,"minecraft:spruce_planks":3,"minecraft:stone_bricks":3},"sha256":"ebedecb3f8000d8d5b24aacc5611b64716aaf181bdd40a64137f589580c3d0bc","size":{"x":32,"y":1,"z":32}},{"blockCount":1,"bytes":647,"file":"chunks/y033-z064-x320.json","offset":{"x":320,"y":33,"z":64},"requirements":{"minecraft:polished_diorite":1},"sha256":"2ff5bc5eb49af92b7e6497960f2100f1bcbb682471e4017ebf70f612a1b1d5ce","size":{"x":32,"y":1,"z":32}},{"blockCount":3,"bytes":725,"file":"chunks/y033-z064-x352.json","offset":{"x":352,"y":33,"z":64},"requirements":{"minecraft:polished_diorite":3},"sha256":"a835965630eb5b1133b2201bedd07a4ec404c4d403b10f0e81500c03a0990c0e","size":{"x":32,"y":1,"z":32}},{"blockCount":109,"bytes":3398,"file":"chunks/y033-z096-x000.json","offset":{"x":0,"y":33,"z":96},"requirements":{"minecraft:bricks":17,"minecraft:polished_diorite":36,"minecraft:stone_bricks":56},"sha256":"b9068386265683efe9bc2e753e486ac44fc5a8553244db6fed31ab450f7db7ba","size":{"x":32,"y":1,"z":32}},{"blockCount":269,"bytes":5942,"file":"chunks/y033-z096-x032.json","offset":{"x":32,"y":33,"z":96},"requirements":{"minecraft:bricks":46,"minecraft:glass":8,"minecraft:oak_planks":11,"minecraft:polished_diorite":57,"minecraft:spruce_planks":40,"minecraft:stone_bricks":107},"sha256":"ecf43f478b845e87b4c86bd13e362e5c1cab3283e2ba4a4f998a6c79f8b8d703","size":{"x":32,"y":1,"z":32}},{"blockCount":216,"bytes":4726,"file":"chunks/y033-z096-x064.json","offset":{"x":64,"y":33,"z":96},"requirements":{"minecraft:bricks":54,"minecraft:oak_planks":5,"minecraft:polished_diorite":45,"minecraft:spruce_planks":15,"minecraft:stone_bricks":97},"sha256":"c76ec1975e168ee498049876b31db039e78895477f98ca15b4b65acf9ee3ef42","size":{"x":32,"y":1,"z":32}},{"blockCount":121,"bytes":4114,"file":"chunks/y033-z096-x096.json","offset":{"x":96,"y":33,"z":96},"requirements":{"minecraft:bricks":4,"minecraft:glass":1,"minecraft:oak_planks":1,"minecraft:spruce_planks":71,"minecraft:stone_bricks":44},"sha256":"ec1ead99f4104737dec3ead098e4517b56cdc0f014b23f8992b9996491902513","size":{"x":32,"y":1,"z":32}},{"blockCount":140,"bytes":3961,"file":"chunks/y033-z096-x128.json","offset":{"x":128,"y":33,"z":96},"requirements":{"minecraft:bricks":20,"minecraft:glass":1,"minecraft:polished_diorite":11,"minecraft:spruce_planks":34,"minecraft:stone_bricks":74},"sha256":"975156845a2f99de5297390d45d01acfec1761468b6620e4aa60a44598db2112","size":{"x":32,"y":1,"z":32}},{"blockCount":206,"bytes":4216,"file":"chunks/y033-z096-x160.json","offset":{"x":160,"y":33,"z":96},"requirements":{"minecraft:bricks":39,"minecraft:polished_diorite":55,"minecraft:spruce_planks":16,"minecraft:stone_bricks":96},"sha256":"f0cb8cd3554c93450c42777bd3f450cc826fe459b16ec504b0d673c3e02b3eef","size":{"x":32,"y":1,"z":32}},{"blockCount":319,"bytes":5183,"file":"chunks/y033-z096-x192.json","offset":{"x":192,"y":33,"z":96},"requirements":{"minecraft:bricks":158,"minecraft:glass":8,"minecraft:polished_diorite":40,"minecraft:sandstone":8,"minecraft:spruce_planks":34,"minecraft:stone_bricks":71},"sha256":"64fb1e7afb0d98dd52a845454dc6585167f0d8c9215f62344b61724f472bf0f0","size":{"x":32,"y":1,"z":32}},{"blockCount":187,"bytes":4450,"file":"chunks/y033-z096-x224.json","offset":{"x":224,"y":33,"z":96},"requirements":{"minecraft:bricks":79,"minecraft:glass":4,"minecraft:oak_planks":5,"minecraft:polished_diorite":51,"minecraft:spruce_planks":3,"minecraft:stone_bricks":45},"sha256":"89d50cf9d66fdc8ce213132a94e1fa0f9692a53d87f6530569cbbcf2ad6af12a","size":{"x":32,"y":1,"z":32}},{"blockCount":1,"bytes":641,"file":"chunks/y033-z096-x256.json","offset":{"x":256,"y":33,"z":96},"requirements":{"minecraft:oak_planks":1},"sha256":"f1b3813d48e933d3a2818230b5a31f2bda90af55f64bc0e81f2147313f86b4d4","size":{"x":32,"y":1,"z":32}},{"blockCount":1,"bytes":643,"file":"chunks/y033-z096-x288.json","offset":{"x":288,"y":33,"z":96},"requirements":{"minecraft:stone_bricks":1},"sha256":"9401d59657126bdec3de64185284e5c09d95e94784d4ccae28bdd7fcc9f28bfa","size":{"x":32,"y":1,"z":32}},{"blockCount":4,"bytes":767,"file":"chunks/y033-z096-x352.json","offset":{"x":352,"y":33,"z":96},"requirements":{"minecraft:polished_diorite":4},"sha256":"78ea9836f0785780097cd77ba95aae55c9ed9e56855e1c8f2541fee7d5fff79b","size":{"x":32,"y":1,"z":32}},{"blockCount":193,"bytes":5186,"file":"chunks/y033-z128-x000.json","offset":{"x":0,"y":33,"z":128},"requirements":{"minecraft:bricks":28,"minecraft:glass":12,"minecraft:polished_diorite":48,"minecraft:stone_bricks":105},"sha256":"687f197495b848c8a3bb3333105e8b8d6d69f7dc07785739762ab1d96dbff8e0","size":{"x":32,"y":1,"z":32}},{"blockCount":301,"bytes":5344,"file":"chunks/y033-z128-x032.json","offset":{"x":32,"y":33,"z":128},"requirements":{"minecraft:bricks":111,"minecraft:cobbled_deepslate":10,"minecraft:glass":8,"minecraft:oak_planks":4,"minecraft:spruce_planks":18,"minecraft:stone_bricks":150},"sha256":"27d05c7fe721d9085898204bed6480e2e3561591b27c0dbdea42a5b3e8c84ce4","size":{"x":32,"y":1,"z":32}},{"blockCount":164,"bytes":4102,"file":"chunks/y033-z128-x064.json","offset":{"x":64,"y":33,"z":128},"requirements":{"minecraft:bricks":61,"minecraft:cobbled_deepslate":1,"minecraft:glass":4,"minecraft:oak_planks":5,"minecraft:polished_diorite":1,"minecraft:spruce_planks":30,"minecraft:stone_bricks":62},"sha256":"a2d7335b622178377291d4206960ec3b6fbc430612ed7526ec8ce1ffd73a5d68","size":{"x":32,"y":1,"z":32}},{"blockCount":37,"bytes":1648,"file":"chunks/y033-z128-x096.json","offset":{"x":96,"y":33,"z":128},"requirements":{"minecraft:bricks":18,"minecraft:glass":5,"minecraft:polished_diorite":1,"minecraft:sandstone":1,"minecraft:spruce_planks":6,"minecraft:stone_bricks":6},"sha256":"3319afed0ad66515264f79377a5d51563b6449d2663597937be22a2644e88aba","size":{"x":32,"y":1,"z":32}},{"blockCount":93,"bytes":3420,"file":"chunks/y033-z128-x128.json","offset":{"x":128,"y":33,"z":128},"requirements":{"minecraft:spruce_planks":63,"minecraft:stone_bricks":30},"sha256":"3399ba426a8714784a78f72f1d65634c88919d018b12cd07b360aaed08b75b2b","size":{"x":32,"y":1,"z":32}},{"blockCount":128,"bytes":4657,"file":"chunks/y033-z128-x160.json","offset":{"x":160,"y":33,"z":128},"requirements":{"minecraft:glass":1,"minecraft:spruce_planks":91,"minecraft:stone_bricks":36},"sha256":"c6aa370844d04b68ed5b813025f6c3a5fa8c823e569667b54aafb0f0201f6296","size":{"x":32,"y":1,"z":32}},{"blockCount":104,"bytes":2847,"file":"chunks/y033-z128-x192.json","offset":{"x":192,"y":33,"z":128},"requirements":{"minecraft:bricks":47,"minecraft:glass":11,"minecraft:polished_diorite":8,"minecraft:sandstone":5,"minecraft:spruce_planks":1,"minecraft:stone_bricks":32},"sha256":"5cc0ba226f61ab7b1ac7e1e3de8fa9f219f05c7ab7494b5a8d7cb13dcb38615c","size":{"x":32,"y":1,"z":32}},{"blockCount":146,"bytes":3405,"file":"chunks/y033-z128-x224.json","offset":{"x":224,"y":33,"z":128},"requirements":{"minecraft:bricks":49,"minecraft:oak_planks":10,"minecraft:polished_diorite":45,"minecraft:stone_bricks":42},"sha256":"cbc01c2f9d462a365533956e36a2b604ecb358fa13ad06afd3e9716efe5b58b0","size":{"x":32,"y":1,"z":32}},{"blockCount":5,"bytes":791,"file":"chunks/y033-z128-x320.json","offset":{"x":320,"y":33,"z":128},"requirements":{"minecraft:polished_diorite":4,"minecraft:stone_bricks":1},"sha256":"d9853df654383eeddab8edcae6c803baed6f0da134e1f3ac70f78f7bc2c82b3c","size":{"x":32,"y":1,"z":32}},{"blockCount":76,"bytes":2670,"file":"chunks/y033-z160-x000.json","offset":{"x":0,"y":33,"z":160},"requirements":{"minecraft:bricks":12,"minecraft:polished_diorite":24,"minecraft:stone_bricks":40},"sha256":"b1a0ed789e4af7063549dd09d0c321df2b0562173c97a782c2b324d8905bda2a","size":{"x":32,"y":1,"z":32}},{"blockCount":176,"bytes":3857,"file":"chunks/y033-z160-x032.json","offset":{"x":32,"y":33,"z":160},"requirements":{"minecraft:bricks":36,"minecraft:polished_diorite":57,"minecraft:spruce_planks":8,"minecraft:stone_bricks":75},"sha256":"5ac852863fd4b56310c61b8bde7996cf4820862de4a09c1be11ba85c21f3f817","size":{"x":32,"y":1,"z":32}},{"blockCount":166,"bytes":3761,"file":"chunks/y033-z160-x064.json","offset":{"x":64,"y":33,"z":160},"requirements":{"minecraft:bricks":48,"minecraft:polished_diorite":53,"minecraft:spruce_planks":2,"minecraft:stone_bricks":63},"sha256":"0f1a53dc579b5157aca235d103a1fcf4b5fef50c94f22f20e16e0cd0a06ed945","size":{"x":32,"y":1,"z":32}}],"schema":1}
