{"entries":[{"blockCount":123,"bytes":4447,"file":"chunks/y033-z160-x096.json","offset":{"x":96,"y":33,"z":160},"requirements":{"minecraft:bricks":6,"minecraft:polished_diorite":1,"minecraft:sandstone":3,"minecraft:spruce_planks":79,"minecraft:stone_bricks":34},"sha256":"76b1b82593cfa84031eb13930d61da6c78a1680fad28dba181319580f085faed","size":{"x":32,"y":1,"z":32}},{"blockCount":150,"bytes":4425,"file":"chunks/y033-z160-x128.json","offset":{"x":128,"y":33,"z":160},"requirements":{"minecraft:bricks":28,"minecraft:glass":2,"minecraft:polished_diorite":22,"minecraft:sandstone":2,"minecraft:spruce_planks":35,"minecraft:stone_bricks":61},"sha256":"a75ac8606e53a8cc1c57e8c0aaf0d09800b5eee7b24aa36354ee7ca88df79efe","size":{"x":32,"y":1,"z":32}},{"blockCount":163,"bytes":3378,"file":"chunks/y033-z160-x160.json","offset":{"x":160,"y":33,"z":160},"requirements":{"minecraft:bricks":39,"minecraft:polished_diorite":56,"minecraft:spruce_planks":6,"minecraft:stone_bricks":62},"sha256":"80eca29535cf6979a59ea180888b11e0b8065f2e18cd66e833e6d37c29b1c43b","size":{"x":32,"y":1,"z":32}},{"blockCount":267,"bytes":4708,"file":"chunks/y033-z160-x192.json","offset":{"x":192,"y":33,"z":160},"requirements":{"minecraft:bricks":133,"minecraft:glass":6,"minecraft:polished_diorite":49,"minecraft:sandstone":3,"minecraft:spruce_planks":7,"minecraft:stone_bricks":69},"sha256":"271cf0a1243c9056a1bbbdcc925425ae2a0ef924a0fc3452c9d0e93fa505786e","size":{"x":32,"y":1,"z":32}},{"blockCount":148,"bytes":3936,"file":"chunks/y033-z160-x224.json","offset":{"x":224,"y":33,"z":160},"requirements":{"minecraft:bricks":61,"minecraft:glass":4,"minecraft:oak_planks":5,"minecraft:polished_diorite":32,"minecraft:spruce_planks":3,"minecraft:stone_bricks":43},"sha256":"7325c9b4183eae2a7ffb5b8ba5f9e630c0f0dfd5c2a8efeb31818c563a3d7ee1","size":{"x":32,"y":1,"z":32}},{"blockCount":1,"bytes":642,"file":"chunks/y033-z160-x256.json","offset":{"x":256,"y":33,"z":160},"requirements":{"minecraft:oak_planks":1},"sha256":"53fc00a024bd89c74636f085668a9cb54030fd266ff43313d619424dce5c5b04","size":{"x":32,"y":1,"z":32}},{"blockCount":8,"bytes":852,"file":"chunks/y033-z160-x288.json","offset":{"x":288,"y":33,"z":160},"requirements":{"minecraft:oak_planks":3,"minecraft:spruce_planks":4,"minecraft:stone_bricks":1},"sha256":"41adf2130edebc775595fd81e7659b9ee5855dd1910233568f337f1689cb1c74","size":{"x":32,"y":1,"z":32}},{"blockCount":1,"bytes":628,"file":"chunks/y033-z160-x320.json","offset":{"x":320,"y":33,"z":160},"requirements":{"minecraft:polished_diorite":1},"sha256":"9189c5cd1f3dcadc131d3491b2de398395ac1e2dc2efce6d3d11ea6ed8b33e01","size":{"x":32,"y":1,"z":32}},{"blockCount":15,"bytes":1102,"file":"chunks/y033-z160-x352.json","offset":{"x":352,"y":33,"z":160},"requirements":{"minecraft:oak_planks":8,"minecraft:polished_diorite":7},"sha256":"c20785d26b29b286cb716e5d579345a5a61b3d6fcfd8dbe4979243f5989bb534","size":{"x":32,"y":1,"z":32}},{"blockCount":125,"bytes":3947,"file":"chunks/y033-z192-x064.json","offset":{"x":64,"y":33,"z":192},"requirements":{"minecraft:bricks":27,"minecraft:oak_planks":5,"minecraft:polished_diorite":45,"minecraft:spruce_planks":1,"minecraft:stone_bricks":47},"sha256":"cdae662047af4a04c2d5fac2995e8c3ef8642dac7e16579e3570d884808e077c","size":{"x":32,"y":1,"z":32}},{"blockCount":159,"bytes":3271,"file":"chunks/y033-z192-x096.json","offset":{"x":96,"y":33,"z":192},"requirements":{"minecraft:bricks":50,"minecraft:glass":1,"minecraft:oak_planks":10,"minecraft:polished_diorite":41,"minecraft:stone_bricks":57},"sha256":"7f1b816fb3898a0e01dbdd39a3ae1edcb122172e70e40cac751614aff200680b","size":{"x":32,"y":1,"z":32}},{"blockCount":235,"bytes":5223,"file":"chunks/y033-z192-x128.json","offset":{"x":128,"y":33,"z":192},"requirements":{"minecraft:bricks":66,"minecraft:glass":1,"minecraft:oak_planks":5,"minecraft:polished_diorite":87,"minecraft:spruce_planks":1,"minecraft:stone_bricks":75},"sha256":"d0799cbafefd5f94d64ad592bcf7897451e8da1aadf52fad48c4cb624cd106c4","size":{"x":32,"y":1,"z":32}},{"blockCount":14,"bytes":1104,"file":"chunks/y033-z192-x160.json","offset":{"x":160,"y":33,"z":192},"requirements":{"minecraft:polished_diorite":4,"minecraft:stone_bricks":10},"sha256":"29831080c8e6151058e2c9c994b923e7469ea16b55792dad5ecff77cde948201","size":{"x":32,"y":1,"z":32}},{"blockCount":158,"bytes":4014,"file":"chunks/y034-z000-x352.json","offset":{"x":352,"y":34,"z":0},"requirements":{"minecraft:bricks":19,"minecraft:glass":6,"minecraft:oak_planks":3,"minecraft:polished_diorite":58,"minecraft:sandstone":5,"minecraft:spruce_planks":5,"minecraft:stone_bricks":62},"sha256":"39a5223035869bacf3a1c490bcec04c8523613b4f3fef5f57f4f9a792de3f38c","size":{"x":32,"y":1,"z":32}},{"blockCount":223,"bytes":5430,"file":"chunks/y034-z000-x384.json","offset":{"x":384,"y":34,"z":0},"requirements":{"minecraft:bricks":42,"minecraft:glass":47,"minecraft:oak_planks":15,"minecraft:polished_diorite":57,"minecraft:sandstone":10,"minecraft:spruce_planks":7,"minecraft:stone_bricks":45},"sha256":"acb0c8fdfa99f72facb5b5a36184a4ff13b9a3b4ec68c7b65a397b6bd48201b8","size":{"x":32,"y":1,"z":32}},{"blockCount":1,"bytes":647,"file":"chunks/y034-z032-x064.json","offset":{"x":64,"y":34,"z":32},"requirements":{"minecraft:cobbled_deepslate":1},"sha256":"0988268011f82c02d11afbcc010108e1e6d12fc2f54ed8e40a50fbc704e2c8a1","size":{"x":32,"y":1,"z":32}},{"blockCount":1,"bytes":648,"file":"chunks/y034-z032-x128.json","offset":{"x":128,"y":34,"z":32},"requirements":{"minecraft:cobbled_deepslate":1},"sha256":"a1fde01db113af5cdac3d227bedae369d2e561d1337505fe443d8754abad5b72","size":{"x":32,"y":1,"z":32}},{"blockCount":137,"bytes":3783,"file":"chunks/y034-z032-x352.json","offset":{"x":352,"y":34,"z":32},"requirements":{"minecraft:bricks":18,"minecraft:glass":38,"minecraft:polished_diorite":40,"minecraft:spruce_planks":4,"minecraft:stone_bricks":37},"sha256":"35f181bd804fa30602bf6aa99b0ec7666457e2cce6fc935a88bd71b37c055ca9","size":{"x":32,"y":1,"z":32}},{"blockCount":38,"bytes":1520,"file":"chunks/y034-z032-x384.json","offset":{"x":384,"y":34,"z":32},"requirements":{"minecraft:bricks":11,"minecraft:cobbled_deepslate":1,"minecraft:glass":6,"minecraft:polished_diorite":11,"minecraft:stone_bricks":9},"sha256":"82f4242aa90dd4c6f8c618973d3b9e2f33cadf212bba15f288f53e7614c9a474","size":{"x":32,"y":1,"z":32}},{"blockCount":150,"bytes":4018,"file":"chunks/y034-z064-x064.json","offset":{"x":64,"y":34,"z":64},"requirements":{"minecraft:bricks":36,"minecraft:glass":2,"minecraft:oak_planks":5,"minecraft:polished_diorite":72,"minecraft:stone_bricks":35},"sha256":"58f253e95914ac22663cd9c77def90ce0b5abe8a9d08eb0fc373df4d6ba35ee3","size":{"x":32,"y":1,"z":32}},{"blockCount":170,"bytes":3024,"file":"chunks/y034-z064-x096.json","offset":{"x":96,"y":34,"z":64},"requirements":{"minecraft:bricks":54,"minecraft:glass":4,"minecraft:oak_planks":10,"minecraft:polished_diorite":42,"minecraft:stone_bricks":60},"sha256":"027e8745ca06f571f07c895963ac7ee828443e1d52df7a946c58a6baf4844144","size":{"x":32,"y":1,"z":32}},{"blockCount":283,"bytes":5050,"file":"chunks/y034-z064-x128.json","offset":{"x":128,"y":34,"z":64},"requirements":{"minecraft:bricks":78,"minecraft:glass":4,"minecraft:oak_planks":5,"minecraft:polished_diorite":109,"minecraft:stone_bricks":87},"sha256":"e499fd67225c7c99da23a5644b27198514cf7bae4edcd23fca5910efcc9078f1","size":{"x":32,"y":1,"z":32}},{"blockCount":7,"bytes":881,"file":"chunks/y034-z064-x160.json","offset":{"x":160,"y":34,"z":64},"requirements":{"minecraft:polished_diorite":7},"sha256":"fc051d2482ce298e39eb8f2a85e387d5f879a2cf0daa7d2b637856a65913e222","size":{"x":32,"y":1,"z":32}},{"blockCount":17,"bytes":941,"file":"chunks/y034-z064-x192.json","offset":{"x":192,"y":34,"z":64},"requirements":{"minecraft:polished_diorite":14,"minecraft:stone_bricks":3},"sha256":"8c03b67b8a84d0fd0f03070a17e8a862bc810e37d920be1a324f606c59fa47b7","size":{"x":32,"y":1,"z":32}},{"blockCount":20,"bytes":980,"file":"chunks/y034-z064-x224.json","offset":{"x":224,"y":34,"z":64},"requirements":{"minecraft:polished_diorite":17,"minecraft:stone_bricks":3},"sha256":"6d66497292e6d62c46fbb016da3f461027f51473a5301b9a55b8eaa7a6203054","size":{"x":32,"y":1,"z":32}},{"blockCount":8,"bytes":927,"file":"chunks/y034-z064-x288.json","offset":{"x":288,"y":34,"z":64},"requirements":{"minecraft:oak_planks":2,"minecraft:spruce_planks":1,"minecraft:stone_bricks":5},"sha256":"f3198242f470261e392de26423bdb15b1565e0aa907164046c522546156bcee9","size":{"x":32,"y":1,"z":32}},{"blockCount":1,"bytes":647,"file":"chunks/y034-z064-x320.json","offset":{"x":320,"y":34,"z":64},"requirements":{"minecraft:polished_diorite":1},"sha256":"59a631b4866671f75b68a3aa23bbe8792051e7c90a0ac6a2f3470e2b836db132","size":{"x":32,"y":1,"z":32}},{"blockCount":3,"bytes":725,"file":"chunks/y034-z064-x352.json","offset":{"x":352,"y":34,"z":64},"requirements":{"minecraft:polished_diorite":3},"sha256":"af1d0cf14dc796753cf023773126f5b05884bf6b3ee5eb7458588627c70769a8","size":{"x":32,"y":1,"z":32}},{"blockCount":98,"bytes":2674,"file":"chunks/y034-z096-x000.json","offset":{"x":0,"y":34,"z":96},"requirements":{"minecraft:bricks":17,"minecraft:polished_diorite":61,"minecraft:stone_bricks":20},"sha256":"755fa9a9ffa6985b8c0e970b8a412879b84946bca79d1b98cdb43195444bd724","size":{"x":32,"y":1,"z":32}},{"blockCount":249,"bytes":4517,"file":"chunks/y034-z096-x032.json","offset":{"x":32,"y":34,"z":96},"requirements":{"minecraft:bricks":47,"minecraft:glass":22,"minecraft:oak_planks":11,"minecraft:polished_diorite":75,"minecraft:spruce_planks":14,"minecraft:stone_bricks":80},"sha256":"6306311b5f282024292cba452220405017fe178cbb75829c2757ddd4c7c5a77a","size":{"x":32,"y":1,"z":32}},{"blockCount":196,"bytes":3562,"file":"chunks/y034-z096-x064.json","offset":{"x":64,"y":34,"z":96},"requirements":{"minecraft:bricks":44,"minecraft:oak_planks":5,"minecraft:polished_diorite":54,"minecraft:spruce_planks":8,"minecraft:stone_bricks":85},"sha256":"a61dc883750fc395c0272b056985737d7fd4904e234e38f9d292f392b40ab89c","size":{"x":32,"y":1,"z":32}},{"blockCount":61,"bytes":1529,"file":"chunks/y034-z096-x096.json","offset":{"x":96,"y":34,"z":96},"requirements":{"minecraft:bricks":3,"minecraft:glass":2,"minecraft:oak_planks":1,"minecraft:spruce_planks":3,"minecraft:stone_bricks":52},"sha256":"6f0319b3b447814ac0ca6106ef25d2da3c99f26cc293de84b76ce9d52f55450d","size":{"x":32,"y":1,"z":32}},{"blockCount":118,"bytes":2575,"file":"chunks/y034-z096-x128.json","offset":{"x":128,"y":34,"z":96},"requirements":{"minecraft:bricks":20,"minecraft:polished_diorite":12,"minecraft:spruce_planks":3,"minecraft:stone_bricks":83},"sha256":"5386c47836a672dee1741fcf5332ca0df7b06500dad623eb799d7f25dfc86de0","size":{"x":32,"y":1,"z":32}},{"blockCount":187,"bytes":2458,"file":"chunks/y034-z096-x160.json","offset":{"x":160,"y":34,"z":96},"requirements":{"minecraft:bricks":39,"minecraft:polished_diorite":69,"minecraft:stone_bricks":79},"sha256":"687d11edbd4c95ca8ea5417a3a29bd9e095378cbe1268599c2fbf8a843952e1c","size":{"x":32,"y":1,"z":32}},{"blockCount":325,"bytes":4179,"file":"chunks/y034-z096-x192.json","offset":{"x":192,"y":34,"z":96},"requirements":{"minecraft:bricks":154,"minecraft:glass":8,"minecraft:polished_diorite":51,"minecraft:sandstone":8,"minecraft:spruce_planks":41,"minecraft:stone_bricks":63},"sha256":"742c4149aaeff5a5f1f673b0156e31ebe10da84ad65b5ae09c7c437886c95eab","size":{"x":32,"y":1,"z":32}},{"blockCount":165,"bytes":3849,"file":"chunks/y034-z096-x224.json","offset":{"x":224,"y":34,"z":96},"requirements":{"minecraft:bricks":79,"minecraft:cobbled_deepslate":1,"minecraft:glass":2,"minecraft:oak_planks":5,"minecraft:polished_diorite":58,"minecraft:stone_bricks":20},"sha256":"ab226ad2c1a5142bbcf61a89b24804d2bd48695641bf415d71e8d6d3506461f9","size":{"x":32,"y":1,"z":32}},{"blockCount":3,"bytes":747,"file":"chunks/y034-z096-x256.json","offset":{"x":256,"y":34,"z":96},"requirements":{"minecraft:oak_planks":2,"minecraft:spruce_planks":1},"sha256":"1eef87acaef63e1cb5ea6810ec78cd6479f715d085a8d89d9a7d47581cf24837","size":{"x":32,"y":1,"z":32}},{"blockCount":4,"bytes":767,"file":"chunks/y034-z096-x352.json","offset":{"x":352,"y":34,"z":96},"requirements":{"minecraft:polished_diorite":4},"sha256":"37780cacf1bd0fd76f3285c522900660871f1a53e360ccfe4fec3d748efac81a","size":{"x":32,"y":1,"z":32}},{"blockCount":163,"bytes":4305,"file":"chunks/y034-z128-x000.json","offset":{"x":0,"y":34,"z":128},"requirements":{"minecraft:bricks":40,"minecraft:polished_diorite":62,"minecraft:stone_bricks":61},"sha256":"8c8c62d163147b44f7146ee59290156a941a2b279a1d9b62234a20ec69b3b0fd","size":{"x":32,"y":1,"z":32}},{"blockCount":267,"bytes":5329,"file":"chunks/y034-z128-x032.json","offset":{"x":32,"y":34,"z":128},"requirements":{"minecraft:bricks":73,"minecraft:cobbled_deepslate":22,"minecraft:glass":3,"minecraft:oak_planks":4,"minecraft:sandstone":4,"minecraft:spruce_planks":10,"minecraft:stone_bricks":151},"sha256":"7f6e02e48ae212cf58e814a46147fe70e9cbce1e7bad706b55935030a4d45d54","size":{"x":32,"y":1,"z":32}},{"blockCount":137,"bytes":3254,"file":"chunks/y034-z128-x064.json","offset":{"x":64,"y":34,"z":128},"requirements":{"minecraft:bricks":33,"minecraft:glass":4,"minecraft:oak_planks":5,"minecraft:polished_diorite":38,"minecraft:spruce_planks":4,"minecraft:stone_bricks":53},"sha256":"9e1dc0bc956fadf50c14dd75e6f38eb6cb21d6f208e3eda2f18cbca244c2dcd1","size":{"x":32,"y":1,"z":32}},{"blockCount":23,"bytes":1297,"file":"chunks/y034-z128-x096.json","offset":{"x":96,"y":34,"z":128},"requirements":{"minecraft:bricks":15,"minecraft:glass":4,"minecraft:stone_bricks":4},"sha256":"41690b29464b683238e6b064e74562edb13b0897d92f4b4079b9341c52ded83d","size":{"x":32,"y":1,"z":32}},{"blockCount":34,"bytes":988,"file":"chunks/y034-z128-x128.json","offset":{"x":128,"y":34,"z":128},"requirements":{"minecraft:stone_bricks":34},"sha256":"797b2a86ae52190a194f516e7eda4fce125b46efc298a9b631fa788b6dc303c9","size":{"x":32,"y":1,"z":32}},{"blockCount":41,"bytes":1120,"file":"chunks/y034-z128-x160.json","offset":{"x":160,"y":34,"z":128},"requirements":{"minecraft:stone_bricks":41},"sha256":"84b1697918a6844283a1c07a938cba8e7d558d17919b3136c7c1b7217bb32918","size":{"x":32,"y":1,"z":32}},{"blockCount":109,"bytes":2929,"file":"chunks/y034-z128-x192.json","offset":{"x":192,"y":34,"z":128},"requirements":{"minecraft:bricks":49,"minecraft:polished_diorite":7,"minecraft:sandstone":5,"minecraft:spruce_planks":5,"minecraft:stone_bricks":43},"sha256":"3ed150d54a5a20cd33006171fa70f0635b09e41bc3d582695fe50628cf3622bd","size":{"x":32,"y":1,"z":32}},{"blockCount":141,"bytes":3256,"file":"chunks/y034-z128-x224.json","offset":{"x":224,"y":34,"z":128},"requirements":{"minecraft:bricks":53,"minecraft:glass":4,"minecraft:oak_planks":10,"minecraft:polished_diorite":48,"minecraft:stone_bricks":26},"sha256":"3526aaf6367392fba5450faa2806396f6f85a3465a6927010af8fbbae2884bab","size":{"x":32,"y":1,"z":32}},{"blockCount":4,"bytes":764,"file":"chunks/y034-z128-x320.json","offset":{"x":320,"y":34,"z":128},"requirements":{"minecraft:polished_diorite":4},"sha256":"ab039f7e690e5125cd1c040c0baaddcaccdaa109dec92204dd0598cbc50ef786","size":{"x":32,"y":1,"z":32}},{"blockCount":72,"bytes":2244,"file":"chunks/y034-z160-x000.json","offset":{"x":0,"y":34,"z":160},"requirements":{"minecraft:bricks":12,"minecraft:cobbled_deepslate":2,"minecraft:polished_diorite":43,"minecraft:stone_bricks":15},"sha256":"b6f0e09821f8f19fc8a0642e7b19a1f79a2977678d8a40506e324df36fa59c12","size":{"x":32,"y":1,"z":32}},{"blockCount":170,"bytes":2839,"file":"chunks/y034-z160-x032.json","offset":{"x":32,"y":34,"z":160},"requirements":{"minecraft:bricks":37,"minecraft:cobbled_deepslate":5,"minecraft:glass":2,"minecraft:polished_diorite":75,"minecraft:stone_bricks":51},"sha256":"bd853c81d8f0f519ae4a2001f1ae948ee41eedf6ced4b07e875f2b27ece30a8f","size":{"x":32,"y":1,"z":32}},{"blockCount":158,"bytes":2918,"file":"chunks/y034-z160-x064.json","offset":{"x":64,"y":34,"z":160},"requirements":{"minecraft:bricks":48,"minecraft:polished_diorite":65,"minecraft:stone_bricks":45},"sha256":"6ccfb47c435c84408fa11eeb8e8c7d70d2624d13cb8f233d029a2ee0f36902b7","size":{"x":32,"y":1,"z":32}},{"blockCount":49,"bytes":1385,"file":"chunks/y034-z160-x096.json","offset":{"x":96,"y":34,"z":160},"requirements":{"minecraft:bricks":5,"minecraft:sandstone":4,"minecraft:stone_bricks":40},"sha256":"83887ec918b7da4da1302cd52e9c48c1b29664a75b98dfb5cffe76c1e94cecfd","size":{"x":32,"y":1,"z":32}},{"blockCount":124,"bytes":2866,"file":"chunks/y034-z160-x128.json","offset":{"x":128,"y":34,"z":160},"requirements":{"minecraft:bricks":28,"minecraft:polished_diorite":26,"minecraft:sandstone":2,"minecraft:spruce_planks":3,"minecraft:stone_bricks":65},"sha256":"8594d9333e0c43db1e5c30f557e5f247c07866d735e50b38e270f296bc7ed29e","size":{"x":32,"y":1,"z":32}},{"blockCount":148,"bytes":1985,"file":"chunks/y034-z160-x160.json","offset":{"x":160,"y":34,"z":160},"requirements":{"minecraft:bricks":39,"minecraft:polished_diorite":71,"minecraft:stone_bricks":38},"sha256":"6514e1379701a3dade706f01e298ae8711eb09a3bf08d20fe117507629765edc","size":{"x":32,"y":1,"z":32}},{"blockCount":252,"bytes":3475,"file":"chunks/y034-z160-x192.json","offset":{"x":192,"y":34,"z":160},"requirements":{"minecraft:bricks":129,"minecraft:glass":8,"minecraft:polished_diorite":65,"minecraft:sandstone":3,"minecraft:spruce_planks":7,"minecraft:stone_bricks":40},"sha256":"5acd11e7a09df921f7194d44c6261041f345fe31cd5a5887c8c2137f95fc5e61","size":{"x":32,"y":1,"z":32}},{"blockCount":124,"bytes":3239,"file":"chunks/y034-z160-x224.json","offset":{"x":224,"y":34,"z":160},"requirements":{"minecraft:bricks":60,"minecraft:cobbled_deepslate":1,"minecraft:glass":2,"minecraft:oak_planks":5,"minecraft:polished_diorite":45,"minecraft:stone_bricks":11},"sha256":"28f49d2d9aa429cdf0018c75294422d57f0fe97c749a01c5fa0c5c42d7634b8e","size":{"x":32,"y":1,"z":32}},{"blockCount":3,"bytes":748,"file":"chunks/y034-z160-x256.json","offset":{"x":256,"y":34,"z":160},"requirements":{"minecraft:oak_planks":2,"minecraft:spruce_planks":1},"sha256":"75d60ed5840df0436500b08ffc55b7eca1c3dbe58b64f8d54d41427224c18075","size":{"x":32,"y":1,"z":32}},{"blockCount":12,"bytes":1005,"file":"chunks/y034-z160-x288.json","offset":{"x":288,"y":34,"z":160},"requirements":{"minecraft:oak_planks":4,"minecraft:spruce_planks":3,"minecraft:stone_bricks":5},"sha256":"d95fc94379c9e0911416e39df0101b4cff68a5493cc24828b612d8086a77c282","size":{"x":32,"y":1,"z":32}},{"blockCount":1,"bytes":628,"file":"chunks/y034-z160-x320.json","offset":{"x":320,"y":34,"z":160},"requirements":{"minecraft:polished_diorite":1},"sha256":"59d3f405cc073adbd4f7a2c606e443b6a86da9076b916174504ee3f945e54ac7","size":{"x":32,"y":1,"z":32}},{"blockCount":10,"bytes":987,"file":"chunks/y034-z160-x352.json","offset":{"x":352,"y":34,"z":160},"requirements":{"minecraft:oak_planks":3,"minecraft:polished_diorite":7},"sha256":"07f57f78ca3cc1cdab02966521c1e94017e654f0f146a7c89a9ca1f46a2aca55","size":{"x":32,"y":1,"z":32}},{"blockCount":119,"bytes":3387,"file":"chunks/y034-z192-x064.json","offset":{"x":64,"y":34,"z":192},"requirements":{"minecraft:bricks":28,"minecraft:glass":2,"minecraft:oak_planks":5,"minecraft:polished_diorite":57,"minecraft:stone_bricks":27},"sha256":"5314de4631c5b206f9d9c44510cbe653a67f4f198fecd7d480befe9d26c40469","size":{"x":32,"y":1,"z":32}},{"blockCount":162,"bytes":2947,"file":"chunks/y034-z192-x096.json","offset":{"x":96,"y":34,"z":192},"requirements":{"minecraft:bricks":54,"minecraft:glass":4,"minecraft:oak_planks":10,"minecraft:polished_diorite":42,"minecraft:stone_bricks":52},"sha256":"e9e2572eaf0358ba951be22418d99e5e99c2b9093e74224754a2365645a2cf36","size":{"x":32,"y":1,"z":32}},{"blockCount":245,"bytes":4417,"file":"chunks/y034-z192-x128.json","offset":{"x":128,"y":34,"z":192},"requirements":{"minecraft:bricks":70,"minecraft:glass":4,"minecraft:oak_planks":5,"minecraft:polished_diorite":95,"minecraft:stone_bricks":71},"sha256":"7444bb1edc3b6ffe0eac9d941a204ce8c1d0aa428131d1f53756f597617bc7fb","size":{"x":32,"y":1,"z":32}},{"blockCount":6,"bytes":844,"file":"chunks/y034-z192-x160.json","offset":{"x":160,"y":34,"z":192},"requirements":{"minecraft:polished_diorite":6},"sha256":"35bd110c15d3c4ef15127f5cebae9fd984014da4c9c5f4221b6cb822e490fc7a","size":{"x":32,"y":1,"z":32}},{"blockCount":211,"bytes":4695,"file":"chunks/y035-z000-x352.json","offset":{"x":352,"y":35,"z":0},"requirements":{"minecraft:bricks":17,"minecraft:cobbled_deepslate":1,"minecraft:glass":14,"minecraft:oak_planks":3,"minecraft:polished_diorite":97,"minecraft:sandstone":8,"minecraft:spruce_planks":5,"minecraft:stone_bricks":66},"sha256":"d56f57f08c40fb9031757e262b35d3bca5a22feb3fc32c93fdfa119971914f0a","size":{"x":32,"y":1,"z":32}},{"blockCount":212,"bytes":5387,"file":"chunks/y035-z000-x384.json","offset":{"x":384,"y":35,"z":0},"requirements":{"minecraft:bricks":44,"minecraft:cobbled_deepslate":1,"minecraft:glass":41,"minecraft:oak_planks":8,"minecraft:polished_diorite":61,"minecraft:sandstone":9,"minecraft:spruce_planks":2,"minecraft:stone_bricks":46},"sha256":"3bab9b16aab3a9d93bb7146edc0d6b24b01ef9566a9c68f0c7622f675a8cc1c9","size":{"x":32,"y":1,"z":32}},{"blockCount":176,"bytes":3882,"file":"chunks/y035-z032-x352.json","offset":{"x":352,"y":35,"z":32},"requirements":{"minecraft:bricks":50,"minecraft:glass":13,"minecraft:oak_planks":3,"minecraft:polished_diorite":54,"minecraft:spruce_planks":1,"minecraft:stone_bricks":55},"sha256":"d899378c65d6c6f639e98ff927213d43be19393245cd40c3666b08d0d46ca775","size":{"x":32,"y":1,"z":32}},{"blockCount":39,"bytes":1594,"file":"chunks/y035-z032-x384.json","offset":{"x":384,"y":35,"z":32},"requirements":{"minecraft:bricks":11,"minecraft:cobbled_deepslate":1,"minecraft:glass":9,"minecraft:polished_diorite":9,"minecraft:stone_bricks":9},"sha256":"195b90d1fe25b369559c89dd402c087c7cdf8d27af017acccf96c54f79b4ee23","size":{"x":32,"y":1,"z":32}},{"blockCount":141,"bytes":3909,"file":"chunks/y035-z064-x064.json","offset":{"x":64,"y":35,"z":64},"requirements":{"minecraft:bricks":20,"minecraft:oak_planks":5,"minecraft:polished_diorite":74,"minecraft:sandstone":18,"minecraft:stone_bricks":24},"sha256":"ffeb033810b1cf08868283df604ec2a7738519232e4447b0a7fd7fbfff3eda01","size":{"x":32,"y":1,"z":32}},{"blockCount":161,"bytes":3105,"file":"chunks/y035-z064-x096.json","offset":{"x":96,"y":35,"z":64},"requirements":{"minecraft:bricks":59,"minecraft:oak_planks":10,"minecraft:polished_diorite":45,"minecraft:sandstone":29,"minecraft:stone_bricks":18},"sha256":"09fd62d8920247fd463a122955c492a9b294f22dc84d3d4cebe37c78fa97bd75","size":{"x":32,"y":1,"z":32}},{"blockCount":263,"bytes":4996,"file":"chunks/y035-z064-x128.json","offset":{"x":128,"y":35,"z":64},"requirements":{"minecraft:bricks":67,"minecraft:oak_planks":5,"minecraft:polished_diorite":112,"minecraft:sandstone":47,"minecraft:stone_bricks":32},"sha256":"fd111e6499bf393e6ee290041dadb61ec9143abe466b89ffc14ce8c50e620633","size":{"x":32,"y":1,"z":32}},{"blockCount":7,"bytes":881,"file":"chunks/y035-z064-x160.json","offset":{"x":160,"y":35,"z":64},"requirements":{"minecraft:polished_diorite":7},"sha256":"50ae78599733a66cfd33c9b1cbbd38163e4a72dfc3ec0fc87b437894e23c0053","size":{"x":32,"y":1,"z":32}},{"blockCount":16,"bytes":895,"file":"chunks/y035-z064-x192.json","offset":{"x":192,"y":35,"z":64},"requirements":{"minecraft:glass":7,"minecraft:polished_diorite":9},"sha256":"3acc322e1896e7fb4bc5ba9344ae28bc00d8428e84edded266cf7b1c704dce87","size":{"x":32,"y":1,"z":32}},{"blockCount":19,"bytes":935,"file":"chunks/y035-z064-x224.json","offset":{"x":224,"y":35,"z":64},"requirements":{"minecraft:glass":7,"minecraft:polished_diorite":12},"sha256":"9632aeae9e03f99c5ded896b7d26447b8f253f33ea27a597a32fc642cb7a7b48","size":{"x":32,"y":1,"z":32}},{"blockCount":3,"bytes":745,"file":"chunks/y035-z064-x288.json","offset":{"x":288,"y":35,"z":64},"requirements":{"minecraft:oak_planks":2,"minecraft:stone_bricks":1},"sha256":"034b3623d390492823b1651427e1e701eeac82fdf3f8f25078579b4df3cdcfcf","size":{"x":32,"y":1,"z":32}},{"blockCount":1,"bytes":647,"file":"chunks/y035-z064-x320.json","offset":{"x":320,"y":35,"z":64},"requirements":{"minecraft:polished_diorite":1},"sha256":"27433de8692b3cd4c23736d084fcdd789806ce47364a3b4e5b55019e140b253a","size":{"x":32,"y":1,"z":32}},{"blockCount":3,"bytes":725,"file":"chunks/y035-z064-x352.json","offset":{"x":352,"y":35,"z":64},"requirements":{"minecraft:polished_diorite":3},"sha256":"7dd6fa0ae5eddae51831d879f2d59905d0a0e1ed99bb8a48e466f45873ee69dd","size":{"x":32,"y":1,"z":32}},{"blockCount":104,"bytes":2642,"file":"chunks/y035-z096-x000.json","offset":{"x":0,"y":35,"z":96},"requirements":{"minecraft:bricks":4,"minecraft:polished_diorite":67,"minecraft:sandstone":16,"minecraft:stone_bricks":17},"sha256":"bef9ae7d923516bb2d4ae99c4d5e2f2848971b40b9d8674f6c7148c3c742ec06","size":{"x":32,"y":1,"z":32}},{"blockCount":224,"bytes":4039,"file":"chunks/y035-z096-x032.json","offset":{"x":32,"y":35,"z":96},"requirements":{"minecraft:bricks":29,"minecraft:glass":29,"minecraft:polished_diorite":75,"minecraft:sandstone":59,"minecraft:spruce_planks":6,"minecraft:stone_bricks":26},"sha256":"7595daa0a655ab841d1816bc750263c2efde344e9b386ee0c680b692c4f2adae","size":{"x":32,"y":1,"z":32}},{"blockCount":181,"bytes":3440,"file":"chunks/y035-z096-x064.json","offset":{"x":64,"y":35,"z":96},"requirements":{"minecraft:bricks":39,"minecraft:glass":9,"minecraft:polished_diorite":55,"minecraft:sandstone":54,"minecraft:stone_bricks":24},"sha256":"99522426ddd8ca404dd9128f60d0f189d3020802c3c520a6d742fb6f55ec080c","size":{"x":32,"y":1,"z":32}},{"blockCount":59,"bytes":1233,"file":"chunks/y035-z096-x096.json","offset":{"x":96,"y":35,"z":96},"requirements":{"minecraft:bricks":3,"minecraft:sandstone":55,"minecraft:spruce_planks":1},"sha256":"8ccf47a7dc6e9cb8ec03a45c816a57ae516ed34ef5c3fdecdc3a47545aefd8e4","size":{"x":32,"y":1,"z":32}},{"blockCount":113,"bytes":2284,"file":"chunks/y035-z096-x128.json","offset":{"x":128,"y":35,"z":96},"requirements":{"minecraft:bricks":20,"minecraft:polished_diorite":12,"minecraft:sandstone":76,"minecraft:stone_bricks":5},"sha256":"3dd4bc4a1d698f74d6d60cb57aa49853f35a9f34ce9a239518ac215f1c175acb","size":{"x":32,"y":1,"z":32}},{"blockCount":180,"bytes":2669,"file":"chunks/y035-z096-x160.json","offset":{"x":160,"y":35,"z":96},"requirements":{"minecraft:bricks":21,"minecraft:polished_diorite":72,"minecraft:sandstone":68,"minecraft:stone_bricks":19},"sha256":"9f0081411c2cb0a31310f98a4af26b3ad82c0f0a7a9e18656934ddad43eabaed","size":{"x":32,"y":1,"z":32}},{"blockCount":308,"bytes":4480,"file":"chunks/y035-z096-x192.json","offset":{"x":192,"y":35,"z":96},"requirements":{"minecraft:bricks":134,"minecraft:glass":14,"minecraft:polished_diorite":55,"minecraft:sandstone":25,"minecraft:spruce_planks":50,"minecraft:stone_bricks":30},"sha256":"52f9b9087953da682a1d7f4d97a0a3a63188fa306ddf09f1ab2433240f935086","size":{"x":32,"y":1,"z":32}},{"blockCount":158,"bytes":3930,"file":"chunks/y035-z096-x224.json","offset":{"x":224,"y":35,"z":96},"requirements":{"minecraft:bricks":69,"minecraft:glass":15,"minecraft:oak_planks":5,"minecraft:polished_diorite":55,"minecraft:stone_bricks":14},"sha256":"a343814cbd6178f18c1ed8b7093cfc5d541ba813face70a417cfa144ba181923","size":{"x":32,"y":1,"z":32}},{"blockCount":7,"bytes":883,"file":"chunks/y035-z096-x256.json","offset":{"x":256,"y":35,"z":96},"requirements":{"minecraft:oak_planks":2,"minecraft:spruce_planks":5},"sha256":"e619f735ffcec48f891b4c3b78dd107a0a196e242807ad4e20d7bbb660e1755f","size":{"x":32,"y":1,"z":32}},{"blockCount":1,"bytes":644,"file":"chunks/y035-z096-x288.json","offset":{"x":288,"y":35,"z":96},"requirements":{"minecraft:spruce_planks":1},"sha256":"ed3a15ab537c1ab137cdc5c46faddd6fdd91a5dabf1ec332d0ab91844628df94","size":{"x":32,"y":1,"z":32}},{"blockCount":4,"bytes":767,"file":"chunks/y035-z096-x352.json","offset":{"x":352,"y":35,"z":96},"requirements":{"minecraft:polished_diorite":4},"sha256":"1fdbc0079adc165c5431381e27e10d3a96b5a272cb4af470e925da70e9afa205","size":{"x":32,"y":1,"z":32}},{"blockCount":141,"bytes":3506,"file":"chunks/y035-z128-x000.json","offset":{"x":0,"y":35,"z":128},"requirements":{"minecraft:bricks":18,"minecraft:glass":4,"minecraft:polished_diorite":71,"minecraft:sandstone":24,"minecraft:stone_bricks":24},"sha256":"e3da77932f4fdce599f7e21602136a069e343630f828fcaf88a5b8da17ddb15e","size":{"x":32,"y":1,"z":32}},{"blockCount":241,"bytes":4622,"file":"chunks/y035-z128-x032.json","offset":{"x":32,"y":35,"z":128},"requirements":{"minecraft:bricks":92,"minecraft:cobbled_deepslate":23,"minecraft:glass":6,"minecraft:sandstone":77,"minecraft:spruce_planks":10,"minecraft:stone_bricks":33},"sha256":"9f533866a7ba918f03618c8af70db945a56f0325adc0c79e209f82d59dde2816","size":{"x":32,"y":1,"z":32}},{"blockCount":77,"bytes":2002,"file":"chunks/y035-z128-x064.json","offset":{"x":64,"y":35,"z":128},"requirements":{"minecraft:bricks":26,"minecraft:glass":9,"minecraft:sandstone":39,"minecraft:stone_bricks":3},"sha256":"baa8544d453224ad09e78c83610ea4b6f8509407303b110f7dd48e0ee2de5cec","size":{"x":32,"y":1,"z":32}},{"blockCount":18,"bytes":1187,"file":"chunks/y035-z128-x096.json","offset":{"x":96,"y":35,"z":128},"requirements":{"minecraft:bricks":11,"minecraft:glass":2,"minecraft:sandstone":1,"minecraft:stone_bricks":4},"sha256":"fa41640d4b50513b7c68317b31552a852cc0aee0ed393bb65e0dcc45ecf88e0c","size":{"x":32,"y":1,"z":32}},{"blockCount":36,"bytes":909,"file":"chunks/y035-z128-x128.json","offset":{"x":128,"y":35,"z":128},"requirements":{"minecraft:sandstone":36},"sha256":"d0d5608c7761037e5c6343a7cdda85c480ea238f63712a59601e3b13f6d7afe1","size":{"x":32,"y":1,"z":32}},{"blockCount":43,"bytes":1041,"file":"chunks/y035-z128-x160.json","offset":{"x":160,"y":35,"z":128},"requirements":{"minecraft:sandstone":43},"sha256":"dbc632b64c01f4ed2351832bfb33f64e5d5826964dc47ee1219dcfcb276b30a2","size":{"x":32,"y":1,"z":32}},{"blockCount":87,"bytes":2647,"file":"chunks/y035-z128-x192.json","offset":{"x":192,"y":35,"z":128},"requirements":{"minecraft:bricks":57,"minecraft:glass":5,"minecraft:polished_diorite":7,"minecraft:sandstone":11,"minecraft:stone_bricks":7},"sha256":"9515e00ce99a4173e530b9a4431b01a99586b695be79ef2c1cb75dfb3e2e30bf","size":{"x":32,"y":1,"z":32}},{"blockCount":138,"bytes":3158,"file":"chunks/y035-z128-x224.json","offset":{"x":224,"y":35,"z":128},"requirements":{"minecraft:bricks":53,"minecraft:oak_planks":10,"minecraft:polished_diorite":50,"minecraft:stone_bricks":25},"sha256":"0516a4199cbdbdfb57cf0c3b058512f937e0619560067a733f6b89f5038c868d","size":{"x":32,"y":1,"z":32}},{"blockCount":5,"bytes":791,"file":"chunks/y035-z128-x320.json","offset":{"x":320,"y":35,"z":128},"requirements":{"minecraft:polished_diorite":4,"minecraft:stone_bricks":1},"sha256":"ea60896f07a4346e8bf0a886fda57797033beeb98a1f3694306392762a5786e1","size":{"x":32,"y":1,"z":32}},{"blockCount":74,"bytes":2135,"file":"chunks/y035-z160-x000.json","offset":{"x":0,"y":35,"z":160},"requirements":{"minecraft:bricks":4,"minecraft:cobbled_deepslate":2,"minecraft:polished_diorite":49,"minecraft:sandstone":9,"minecraft:stone_bricks":10},"sha256":"f8853c8a27b6844687040893d3295c74c160696f546c6775205c6d4e60117462","size":{"x":32,"y":1,"z":32}},{"blockCount":146,"bytes":2860,"file":"chunks/y035-z160-x032.json","offset":{"x":32,"y":35,"z":160},"requirements":{"minecraft:bricks":15,"minecraft:cobbled_deepslate":5,"minecraft:glass":1,"minecraft:polished_diorite":75,"minecraft:sandstone":26,"minecraft:stone_bricks":24},"sha256":"9dc5d56f341d90c223bde8783198ff9180350024103222e16be8bcd5d4c866cb","size":{"x":32,"y":1,"z":32}},{"blockCount":144,"bytes":3057,"file":"chunks/y035-z160-x064.json","offset":{"x":64,"y":35,"z":160},"requirements":{"minecraft:bricks":34,"minecraft:polished_diorite":67,"minecraft:sandstone":20,"minecraft:stone_bricks":23},"sha256":"6ddaa5ccc0412b95433802a0f48a18b4fb0d9bc823e16ea4124522a59e654a4a","size":{"x":32,"y":1,"z":32}},{"blockCount":56,"bytes":1328,"file":"chunks/y035-z160-x096.json","offset":{"x":96,"y":35,"z":160},"requirements":{"minecraft:bricks":6,"minecraft:sandstone":45,"minecraft:stone_bricks":5},"sha256":"446b8acd5c2d491255593b6ce177b2bb682b9c55186c4997003dfb342cec4ff1","size":{"x":32,"y":1,"z":32}},{"blockCount":113,"bytes":2591,"file":"chunks/y035-z160-x128.json","offset":{"x":128,"y":35,"z":160},"requirements":{"minecraft:bricks":23,"minecraft:polished_diorite":27,"minecraft:sandstone":55,"minecraft:stone_bricks":8},"sha256":"80a29f2aa9cf9b29e05c53a12364566f443bcd0fa2a450d6230b5f472fdf0576","size":{"x":32,"y":1,"z":32}},{"blockCount":138,"bytes":2253,"file":"chunks/y035-z160-x160.json","offset":{"x":160,"y":35,"z":160},"requirements":{"minecraft:bricks":21,"minecraft:polished_diorite":73,"minecraft:sandstone":25,"minecraft:stone_bricks":19},"sha256":"d59c2986135acb35e5092e48ce5838d191d44014b78c5e8b7eea72d0b319890a","size":{"x":32,"y":1,"z":32}},{"blockCount":229,"bytes":3692,"file":"chunks/y035-z160-x192.json","offset":{"x":192,"y":35,"z":160},"requirements":{"minecraft:bricks":108,"minecraft:glass":16,"minecraft:polished_diorite":64,"minecraft:sandstone":14,"minecraft:stone_bricks":27},"sha256":"e4dbf36b97982651a17d5e3807a058cdeaccbd59d6723d954e422d7230167b80","size":{"x":32,"y":1,"z":32}},{"blockCount":117,"bytes":3205,"file":"chunks/y035-z160-x224.json","offset":{"x":224,"y":35,"z":160},"requirements":{"minecraft:bricks":50,"minecraft:glass":22,"minecraft:oak_planks":5,"minecraft:polished_diorite":37,"minecraft:stone_bricks":3},"sha256":"907376132bec7e2dca43a1d993e1c692f6dc64b824ab5c0a4feb32b3512f01e1","size":{"x":32,"y":1,"z":32}},{"blockCount":7,"bytes":884,"file":"chunks/y035-z160-x256.json","offset":{"x":256,"y":35,"z":160},"requirements":{"minecraft:oak_planks":2,"minecraft:spruce_planks":5},"sha256":"0e045e87aa8acf4f26fd960a73eee933c1311e317e0a3ed802272280f5ebe742","size":{"x":32,"y":1,"z":32}},{"blockCount":7,"bytes":890,"file":"chunks/y035-z160-x288.json","offset":{"x":288,"y":35,"z":160},"requirements":{"minecraft:oak_planks":2,"minecraft:spruce_planks":1,"minecraft:stone_bricks":4},"sha256":"2cdcd5c2c14e1001347a440cd5efac0a4e798ba26131a6bbe26387fd4384b9b5","size":{"x":32,"y":1,"z":32}},{"blockCount":1,"bytes":628,"file":"chunks/y035-z160-x320.json","offset":{"x":320,"y":35,"z":160},"requirements":{"minecraft:polished_diorite":1},"sha256":"8517804014eca8406645800e19fb1fc171fdb4700ffb393f51bf89c373003d00","size":{"x":32,"y":1,"z":32}},{"blockCount":10,"bytes":1026,"file":"chunks/y035-z160-x352.json","offset":{"x":352,"y":35,"z":160},"requirements":{"minecraft:oak_planks":3,"minecraft:polished_diorite":7},"sha256":"872da964ec2c3795df34854e13d007d3806f789b0678b3aaef08e2494f386a95","size":{"x":32,"y":1,"z":32}},{"blockCount":112,"bytes":3335,"file":"chunks/y035-z192-x064.json","offset":{"x":64,"y":35,"z":192},"requirements":{"minecraft:bricks":17,"minecraft:oak_planks":5,"minecraft:polished_diorite":58,"minecraft:sandstone":13,"minecraft:stone_bricks":19},"sha256":"e1efceb5f653316f5cce57cd16ab33df272d79ea8f911aba70a52378f400ee6d","size":{"x":32,"y":1,"z":32}},{"blockCount":153,"bytes":3009,"file":"chunks/y035-z192-x096.json","offset":{"x":96,"y":35,"z":192},"requirements":{"minecraft:bricks":59,"minecraft:oak_planks":10,"minecraft:polished_diorite":45,"minecraft:sandstone":21,"minecraft:stone_bricks":18},"sha256":"14e16aeccfe11c30142391309c40c99e0bcd5047ae48f221ad355dfbfd88f26c","size":{"x":32,"y":1,"z":32}},{"blockCount":227,"bytes":4402,"file":"chunks/y035-z192-x128.json","offset":{"x":128,"y":35,"z":192},"requirements":{"minecraft:bricks":64,"minecraft:oak_planks":5,"minecraft:polished_diorite":97,"minecraft:sandstone":34,"minecraft:stone_bricks":27},"sha256":"137a4f44a2d113302b09857c667286d896f159cdfc22b6345ae8b8b4330b2a7c","size":{"x":32,"y":1,"z":32}},{"blockCount":6,"bytes":844,"file":"chunks/y035-z192-x160.json","offset":{"x":160,"y":35,"z":192},"requirements":{"minecraft:polished_diorite":6},"sha256":"12cf5ee232cb6c75f1015f00a883b469b9e78296eece4a041f2df8ef5e8d1eb5","size":{"x":32,"y":1,"z":32}},{"blockCount":342,"bytes":4009,"file":"chunks/y036-z000-x352.json","offset":{"x":352,"y":36,"z":0},"requirements":{"minecraft:bricks":71,"minecraft:cobbled_deepslate":3,"minecraft:glass":2,"minecraft:oak_planks":2,"minecraft:polished_diorite":138,"minecraft:sandstone":17,"minecraft:stone_bricks":109},"sha256":"d53b5f0d8d10885ce2758275b3c6870b337d046fa65471856247500ca824e8ea","size":{"x":32,"y":1,"z":32}},{"blockCount":223,"bytes":5458,"file":"chunks/y036-z000-x384.json","offset":{"x":384,"y":36,"z":0},"requirements":{"minecraft:bricks":44,"minecraft:cobbled_deepslate":3,"minecraft:glass":47,"minecraft:oak_planks":8,"minecraft:polished_diorite":74,"minecraft:sandstone":9,"minecraft:spruce_planks":4,"minecraft:stone_bricks":34},"sha256":"3ff6f407c5fc2514041547241c22919bc68b2870389bd514e405d12e51b0ad00","size":{"x":32,"y":1,"z":32}},{"blockCount":1,"bytes":647,"file":"chunks/y036-z032-x064.json","offset":{"x":64,"y":36,"z":32},"requirements":{"minecraft:cobbled_deepslate":1},"sha256":"49e592de03196e661acdffdd24959ccef92c796f9a6eb0503e7b2468cafd690b","size":{"x":32,"y":1,"z":32}},{"blockCount":1,"bytes":648,"file":"chunks/y036-z032-x128.json","offset":{"x":128,"y":36,"z":32},"requirements":{"minecraft:cobbled_deepslate":1},"sha256":"40056b9ccc15be2dbd5e7702e378fd902a648a2518d2bd023fb54d513ccc32a0","size":{"x":32,"y":1,"z":32}},{"blockCount":203,"bytes":3780,"file":"chunks/y036-z032-x352.json","offset":{"x":352,"y":36,"z":32},"requirements":{"minecraft:glass":1,"minecraft:oak_planks":40,"minecraft:polished_diorite":93,"minecraft:sandstone":20,"minecraft:stone_bricks":49},"sha256":"18c651e16c8e405c7fba5eb99da1227432e8872d8b980c949b30b32f6777452a","size":{"x":32,"y":1,"z":32}},{"blockCount":39,"bytes":1448,"file":"chunks/y036-z032-x384.json","offset":{"x":384,"y":36,"z":32},"requirements":{"minecraft:bricks":11,"minecraft:glass":8,"minecraft:polished_diorite":11,"minecraft:stone_bricks":9},"sha256":"8d7635af24f62b09e57c42c9a2903437226fa84942bbfd3214daab96c3729322","size":{"x":32,"y":1,"z":32}},{"blockCount":120,"bytes":4062,"file":"chunks/y036-z064-x064.json","offset":{"x":64,"y":36,"z":64},"requirements":{"minecraft:bricks":19,"minecraft:glass":26,"minecraft:oak_planks":8,"minecraft:polished_diorite":44,"minecraft:sandstone":7,"minecraft:stone_bricks":16},"sha256":"5bc0d11df161bece31973b8cf61e356e73a55ea16c002f5da4297116d7587e31","size":{"x":32,"y":1,"z":32}},{"blockCount":151,"bytes":3045,"file":"chunks/y036-z064-x096.json","offset":{"x":96,"y":36,"z":64},"requirements":{"minecraft:bricks":59,"minecraft:glass":7,"minecraft:oak_planks":11,"minecraft:polished_diorite":47,"minecraft:sandstone":13,"minecraft:stone_bricks":14},"sha256":"46628c9a51437f72d0ccc90de442452e12aca7324498068ba402e79e249d3693","size":{"x":32,"y":1,"z":32}},{"blockCount":235,"bytes":5128,"file":"chunks/y036-z064-x128.json","offset":{"x":128,"y":36,"z":64},"requirements":{"minecraft:bricks":66,"minecraft:glass":33,"minecraft:oak_planks":8,"minecraft:polished_diorite":86,"minecraft:sandstone":20,"minecraft:stone_bricks":22},"sha256":"0d1f46f50692bcdea08eb656504e044d248c3af850928feb0ca01e53335c6888","size":{"x":32,"y":1,"z":32}},{"blockCount":7,"bytes":881,"file":"chunks/y036-z064-x160.json","offset":{"x":160,"y":36,"z":64},"requirements":{"minecraft:polished_diorite":7},"sha256":"f96b9c4e3e3a89dafaae07be23058c304d42eee49f83c659f69886be347f5a3e","size":{"x":32,"y":1,"z":32}},{"blockCount":16,"bytes":895,"file":"chunks/y036-z064-x192.json","offset":{"x":192,"y":36,"z":64},"requirements":{"minecraft:glass":7,"minecraft:polished_diorite":9},"sha256":"9dd0a362b835aaa5f3938043c107eac0e8a92cdb266e5145d84388c4f7c669d9","size":{"x":32,"y":1,"z":32}},{"blockCount":19,"bytes":935,"file":"chunks/y036-z064-x224.json","offset":{"x":224,"y":36,"z":64},"requirements":{"minecraft:glass":7,"minecraft:polished_diorite":12},"sha256":"60ec9b82001cc939a75f853061928daee2765346cec39543ba199d320a22efbb","size":{"x":32,"y":1,"z":32}},{"blockCount":1,"bytes":640,"file":"chunks/y036-z064-x288.json","offset":{"x":288,"y":36,"z":64},"requirements":{"minecraft:oak_planks":1},"sha256":"2d1a80de14c981489a91a1c5dc45d14b8df18496e672fd36d261c45df16a95b7","size":{"x":32,"y":1,"z":32}},{"blockCount":1,"bytes":647,"file":"chunks/y036-z064-x320.json","offset":{"x":320,"y":36,"z":64},"requirements":{"minecraft:polished_diorite":1},"sha256":"b835abe4956521c16c8b43919c7d7dba1bd5ad933aebc6ea713ac30729388820","size":{"x":32,"y":1,"z":32}},{"blockCount":3,"bytes":725,"file":"chunks/y036-z064-x352.json","offset":{"x":352,"y":36,"z":64},"requirements":{"minecraft:polished_diorite":3},"sha256":"a47b2bfd6c9644e29e8e5bcbeb6d61fbc42cbcbb3bc0c93ba8a0cbe4de019f0c","size":{"x":32,"y":1,"z":32}},{"blockCount":82,"bytes":2795,"file":"chunks/y036-z096-x000.json","offset":{"x":0,"y":36,"z":96},"requirements":{"minecraft:bricks":5,"minecraft:glass":38,"minecraft:polished_diorite":26,"minecraft:sandstone":2,"minecraft:stone_bricks":11},"sha256":"5a9dd0edc10c2e47a4b0e9caaced2b70dea718d1050073a79b84dd1efe5dbd62","size":{"x":32,"y":1,"z":32}}],"schema":1}
