{"entries":[{"blockCount":164,"bytes":4042,"file":"chunks/y036-z096-x032.json","offset":{"x":32,"y":36,"z":96},"requirements":{"minecraft:bricks":29,"minecraft:glass":51,"minecraft:oak_planks":2,"minecraft:polished_diorite":45,"minecraft:sandstone":16,"minecraft:spruce_planks":8,"minecraft:stone_bricks":13},"sha256":"9c14c1e942023702860b890a76b0482b93d6c8690c08595b58f7474b28e53f71","size":{"x":32,"y":1,"z":32}},{"blockCount":136,"bytes":3518,"file":"chunks/y036-z096-x064.json","offset":{"x":64,"y":36,"z":96},"requirements":{"minecraft:bricks":38,"minecraft:glass":26,"minecraft:oak_planks":2,"minecraft:polished_diorite":36,"minecraft:sandstone":13,"minecraft:stone_bricks":21},"sha256":"a075c15f870bf68bbd6fa06fcf4c4b29684e08c1b630e5a23f399478be47b603","size":{"x":32,"y":1,"z":32}},{"blockCount":27,"bytes":1249,"file":"chunks/y036-z096-x096.json","offset":{"x":96,"y":36,"z":96},"requirements":{"minecraft:bricks":2,"minecraft:glass":10,"minecraft:sandstone":14,"minecraft:stone_bricks":1},"sha256":"490f1abb07f8e8c130a726b0dc46f9b91ea7a39c3ece6b91ead4548d198e955c","size":{"x":32,"y":1,"z":32}},{"blockCount":76,"bytes":2358,"file":"chunks/y036-z096-x128.json","offset":{"x":128,"y":36,"z":96},"requirements":{"minecraft:bricks":20,"minecraft:glass":14,"minecraft:polished_diorite":12,"minecraft:sandstone":19,"minecraft:stone_bricks":11},"sha256":"4726f971a34730b599a87912bb8188fc40baa4515414254518dae9ee7ab885c9","size":{"x":32,"y":1,"z":32}},{"blockCount":135,"bytes":3060,"file":"chunks/y036-z096-x160.json","offset":{"x":160,"y":36,"z":96},"requirements":{"minecraft:bricks":21,"minecraft:glass":36,"minecraft:oak_planks":4,"minecraft:polished_diorite":42,"minecraft:sandstone":17,"minecraft:stone_bricks":15},"sha256":"98f17b4e6089a1630ac1aa31ded983a304d7c814b4edabd78fe53e9305e4aa89","size":{"x":32,"y":1,"z":32}},{"blockCount":288,"bytes":4964,"file":"chunks/y036-z096-x192.json","offset":{"x":192,"y":36,"z":96},"requirements":{"minecraft:bricks":143,"minecraft:glass":50,"minecraft:oak_planks":1,"minecraft:polished_diorite":38,"minecraft:sandstone":12,"minecraft:spruce_planks":16,"minecraft:stone_bricks":28},"sha256":"14dcc8c0e6256fafd813895cf43ea0bac3b84f56dd40b3171ea400622ecc7cec","size":{"x":32,"y":1,"z":32}},{"blockCount":161,"bytes":4001,"file":"chunks/y036-z096-x224.json","offset":{"x":224,"y":36,"z":96},"requirements":{"minecraft:bricks":70,"minecraft:cobbled_deepslate":1,"minecraft:glass":15,"minecraft:oak_planks":5,"minecraft:polished_diorite":59,"minecraft:stone_bricks":11},"sha256":"5b4ca8113fdff46abbbe5a3a671c9cfae6f9d93b04f9a1aa05639095becd671d","size":{"x":32,"y":1,"z":32}},{"blockCount":6,"bytes":890,"file":"chunks/y036-z096-x256.json","offset":{"x":256,"y":36,"z":96},"requirements":{"minecraft:oak_planks":1,"minecraft:spruce_planks":2,"minecraft:stone_bricks":3},"sha256":"5cff8ba9138435363fcaecde657d23ca2130c2e233786bae8ddeac3ed0124a93","size":{"x":32,"y":1,"z":32}},{"blockCount":4,"bytes":792,"file":"chunks/y036-z096-x288.json","offset":{"x":288,"y":36,"z":96},"requirements":{"minecraft:oak_planks":1,"minecraft:spruce_planks":1,"minecraft:stone_bricks":2},"sha256":"a24f6be7f6d8054d26b9f1096d4a47223d095aa7f843ac788d954779c51af383","size":{"x":32,"y":1,"z":32}},{"blockCount":4,"bytes":767,"file":"chunks/y036-z096-x352.json","offset":{"x":352,"y":36,"z":96},"requirements":{"minecraft:polished_diorite":4},"sha256":"887cc660432d72dd70114a345a1b2ac5978e2e5702d0601025db33308e278053","size":{"x":32,"y":1,"z":32}},{"blockCount":117,"bytes":3810,"file":"chunks/y036-z128-x000.json","offset":{"x":0,"y":36,"z":128},"requirements":{"minecraft:bricks":18,"minecraft:glass":45,"minecraft:polished_diorite":30,"minecraft:sandstone":6,"minecraft:stone_bricks":18},"sha256":"e56307f2ab3d758d9ddc477c3e0f2f6c42182d11364bbf6c5b900493a779497f","size":{"x":32,"y":1,"z":32}},{"blockCount":191,"bytes":4727,"file":"chunks/y036-z128-x032.json","offset":{"x":32,"y":36,"z":128},"requirements":{"minecraft:bricks":96,"minecraft:cobbled_deepslate":23,"minecraft:glass":22,"minecraft:oak_planks":2,"minecraft:sandstone":22,"minecraft:spruce_planks":12,"minecraft:stone_bricks":14},"sha256":"0f656a476b249c5e681bd79d3def0f39df36fc8fb3c48a5aa83e39f0084b6488","size":{"x":32,"y":1,"z":32}},{"blockCount":41,"bytes":1907,"file":"chunks/y036-z128-x064.json","offset":{"x":64,"y":36,"z":128},"requirements":{"minecraft:bricks":13,"minecraft:glass":13,"minecraft:sandstone":10,"minecraft:stone_bricks":5},"sha256":"e1af93b39d2b056e6ae25b3929ccc98e7e1d366ef0ee524a36130f88e388974e","size":{"x":32,"y":1,"z":32}},{"blockCount":15,"bytes":1148,"file":"chunks/y036-z128-x096.json","offset":{"x":96,"y":36,"z":128},"requirements":{"minecraft:bricks":8,"minecraft:glass":3,"minecraft:sandstone":2,"minecraft:stone_bricks":2},"sha256":"27756dc3d6ed2f2c6c22145d4646a8fa13029dbc411c72b96eec4bd5889d4be1","size":{"x":32,"y":1,"z":32}},{"blockCount":18,"bytes":1004,"file":"chunks/y036-z128-x128.json","offset":{"x":128,"y":36,"z":128},"requirements":{"minecraft:glass":8,"minecraft:sandstone":10},"sha256":"4615874fa54ce01582ba0b77ebb377d19d22df9a14b541477f66a531d0702baa","size":{"x":32,"y":1,"z":32}},{"blockCount":21,"bytes":1104,"file":"chunks/y036-z128-x160.json","offset":{"x":160,"y":36,"z":128},"requirements":{"minecraft:glass":10,"minecraft:sandstone":11},"sha256":"44ae72dc8f73f8c91e4b7cce7b0f6333bca0d2e22553f07060476039379278e2","size":{"x":32,"y":1,"z":32}},{"blockCount":153,"bytes":2486,"file":"chunks/y036-z128-x192.json","offset":{"x":192,"y":36,"z":128},"requirements":{"minecraft:bricks":130,"minecraft:glass":7,"minecraft:sandstone":11,"minecraft:stone_bricks":5},"sha256":"c87ac8c06234b672c7e5414e8077ecf34382d4531d03cd96b82cbe5ef4643162","size":{"x":32,"y":1,"z":32}},{"blockCount":139,"bytes":3044,"file":"chunks/y036-z128-x224.json","offset":{"x":224,"y":36,"z":128},"requirements":{"minecraft:bricks":53,"minecraft:oak_planks":10,"minecraft:polished_diorite":54,"minecraft:stone_bricks":22},"sha256":"b3c7f1340e0f368215d9c9714cfe9116fec86263675899832bcfc7db35ef223b","size":{"x":32,"y":1,"z":32}},{"blockCount":4,"bytes":764,"file":"chunks/y036-z128-x320.json","offset":{"x":320,"y":36,"z":128},"requirements":{"minecraft:polished_diorite":4},"sha256":"38a58bbda4381ef03bcba678e8686d5558ab8a668afe220495e103f4553e2569","size":{"x":32,"y":1,"z":32}},{"blockCount":57,"bytes":2250,"file":"chunks/y036-z160-x000.json","offset":{"x":0,"y":36,"z":160},"requirements":{"minecraft:bricks":5,"minecraft:cobbled_deepslate":2,"minecraft:glass":24,"minecraft:polished_diorite":19,"minecraft:sandstone":1,"minecraft:stone_bricks":6},"sha256":"0853a187baffc7ca4e05711da8744fa81a2f9c95f4a0ac152f33bd1fd9f9a614","size":{"x":32,"y":1,"z":32}},{"blockCount":117,"bytes":3150,"file":"chunks/y036-z160-x032.json","offset":{"x":32,"y":36,"z":160},"requirements":{"minecraft:bricks":15,"minecraft:cobbled_deepslate":5,"minecraft:glass":30,"minecraft:oak_planks":2,"minecraft:polished_diorite":45,"minecraft:sandstone":6,"minecraft:stone_bricks":14},"sha256":"6bf6b2768c2743ce84431171e138d66f787803e7b2d82e509c8900858175bd16","size":{"x":32,"y":1,"z":32}},{"blockCount":129,"bytes":3326,"file":"chunks/y036-z160-x064.json","offset":{"x":64,"y":36,"z":160},"requirements":{"minecraft:bricks":34,"minecraft:glass":20,"minecraft:oak_planks":3,"minecraft:polished_diorite":43,"minecraft:sandstone":5,"minecraft:stone_bricks":24},"sha256":"343fd967522da5c4dde0871b9bfb449dde6a59682b21f94d13ca9b82696f1943","size":{"x":32,"y":1,"z":32}},{"blockCount":28,"bytes":1306,"file":"chunks/y036-z160-x096.json","offset":{"x":96,"y":36,"z":160},"requirements":{"minecraft:bricks":5,"minecraft:glass":8,"minecraft:sandstone":12,"minecraft:stone_bricks":3},"sha256":"f076d9101a337f73cef5a2d250f7e04425421e048f169f885695fabc118c45ed","size":{"x":32,"y":1,"z":32}},{"blockCount":84,"bytes":2691,"file":"chunks/y036-z160-x128.json","offset":{"x":128,"y":36,"z":160},"requirements":{"minecraft:bricks":23,"minecraft:glass":15,"minecraft:oak_planks":1,"minecraft:polished_diorite":18,"minecraft:sandstone":14,"minecraft:stone_bricks":13},"sha256":"6a261f0965ea5a396acbfd04f8fc3e51169f6eb1a94800511ca4e0cbb8784b4c","size":{"x":32,"y":1,"z":32}},{"blockCount":115,"bytes":2619,"file":"chunks/y036-z160-x160.json","offset":{"x":160,"y":36,"z":160},"requirements":{"minecraft:bricks":21,"minecraft:glass":26,"minecraft:oak_planks":4,"minecraft:polished_diorite":43,"minecraft:sandstone":6,"minecraft:stone_bricks":15},"sha256":"f908a912053c2f7ad952b65f662cea77b023af2b8c333ea6d5e90e3a5a891c50","size":{"x":32,"y":1,"z":32}},{"blockCount":223,"bytes":3945,"file":"chunks/y036-z160-x192.json","offset":{"x":192,"y":36,"z":160},"requirements":{"minecraft:bricks":115,"minecraft:glass":30,"minecraft:oak_planks":2,"minecraft:polished_diorite":47,"minecraft:sandstone":5,"minecraft:stone_bricks":24},"sha256":"d1bcd15d104d591bba25642d0141521985a4124d3d7772552fe7d786e78d8dc4","size":{"x":32,"y":1,"z":32}},{"blockCount":119,"bytes":3314,"file":"chunks/y036-z160-x224.json","offset":{"x":224,"y":36,"z":160},"requirements":{"minecraft:bricks":51,"minecraft:cobbled_deepslate":1,"minecraft:glass":22,"minecraft:oak_planks":5,"minecraft:polished_diorite":37,"minecraft:stone_bricks":3},"sha256":"5f909506548b214433367eaeff690ed2a8fb5a97f15d8a772e228e1646e4a5d4","size":{"x":32,"y":1,"z":32}},{"blockCount":5,"bytes":852,"file":"chunks/y036-z160-x256.json","offset":{"x":256,"y":36,"z":160},"requirements":{"minecraft:oak_planks":1,"minecraft:spruce_planks":2,"minecraft:stone_bricks":2},"sha256":"d6b80b39af21599f6a70a84b71fee5bb6e256c9a3cacc6ce4071b7e9d606bca0","size":{"x":32,"y":1,"z":32}},{"blockCount":4,"bytes":793,"file":"chunks/y036-z160-x288.json","offset":{"x":288,"y":36,"z":160},"requirements":{"minecraft:oak_planks":1,"minecraft:spruce_planks":1,"minecraft:stone_bricks":2},"sha256":"075a4ee16ae3fb874a944b1e3d7e7240100288f3c9e0082098a83a7ac317c261","size":{"x":32,"y":1,"z":32}},{"blockCount":1,"bytes":628,"file":"chunks/y036-z160-x320.json","offset":{"x":320,"y":36,"z":160},"requirements":{"minecraft:polished_diorite":1},"sha256":"3ef32ae82aa83a07096bc3a31d922d3072c8c0b96a22e69167fbfa1ad78b4294","size":{"x":32,"y":1,"z":32}},{"blockCount":7,"bytes":884,"file":"chunks/y036-z160-x352.json","offset":{"x":352,"y":36,"z":160},"requirements":{"minecraft:polished_diorite":7},"sha256":"292c392401a9db996806d009534226f29e38cd6e20c5e50ce02d6b5c341ae136","size":{"x":32,"y":1,"z":32}},{"blockCount":96,"bytes":3412,"file":"chunks/y036-z192-x064.json","offset":{"x":64,"y":36,"z":192},"requirements":{"minecraft:bricks":16,"minecraft:glass":19,"minecraft:oak_planks":7,"minecraft:polished_diorite":37,"minecraft:sandstone":5,"minecraft:stone_bricks":12},"sha256":"9f4e20519c27d781ee247f3fa702652aeda813620a3ce2b846b7412d89ede9f6","size":{"x":32,"y":1,"z":32}},{"blockCount":148,"bytes":2950,"file":"chunks/y036-z192-x096.json","offset":{"x":96,"y":36,"z":192},"requirements":{"minecraft:bricks":59,"minecraft:glass":5,"minecraft:oak_planks":11,"minecraft:polished_diorite":47,"minecraft:sandstone":12,"minecraft:stone_bricks":14},"sha256":"85aa823ab05a9ea0f5a0cd7163bbcac3b7cfe00bc5707e927b2abf1317658042","size":{"x":32,"y":1,"z":32}},{"blockCount":210,"bytes":4479,"file":"chunks/y036-z192-x128.json","offset":{"x":128,"y":36,"z":192},"requirements":{"minecraft:bricks":63,"minecraft:glass":24,"minecraft:oak_planks":8,"minecraft:polished_diorite":80,"minecraft:sandstone":17,"minecraft:stone_bricks":18},"sha256":"b801ea0cff76c7acecd8890633db8b283e8ffc3679f0e5f7f44c5e9cc09bd6e2","size":{"x":32,"y":1,"z":32}},{"blockCount":6,"bytes":844,"file":"chunks/y036-z192-x160.json","offset":{"x":160,"y":36,"z":192},"requirements":{"minecraft:polished_diorite":6},"sha256":"68a0ecc01f579f4c8cd6911d66be00721d2c79b06499ee0edcad450df71ca2b6","size":{"x":32,"y":1,"z":32}},{"blockCount":219,"bytes":4409,"file":"chunks/y037-z000-x352.json","offset":{"x":352,"y":37,"z":0},"requirements":{"minecraft:bricks":6,"minecraft:cobbled_deepslate":1,"minecraft:oak_planks":28,"minecraft:polished_diorite":52,"minecraft:sandstone":13,"minecraft:spruce_planks":31,"minecraft:stone_bricks":88},"sha256":"33b195e0d566bc2334de2568b32a2d32ad48be26003af4b60fd3bee2ff3e3ef8","size":{"x":32,"y":1,"z":32}},{"blockCount":268,"bytes":5526,"file":"chunks/y037-z000-x384.json","offset":{"x":384,"y":37,"z":0},"requirements":{"minecraft:bricks":40,"minecraft:glass":35,"minecraft:oak_planks":16,"minecraft:polished_diorite":110,"minecraft:sandstone":8,"minecraft:spruce_planks":4,"minecraft:stone_bricks":55},"sha256":"b1b4b651e913deee5ae169a353aa0d640e458a19e70dc902670cb4bee7a354e1","size":{"x":32,"y":1,"z":32}},{"blockCount":1,"bytes":647,"file":"chunks/y037-z032-x064.json","offset":{"x":64,"y":37,"z":32},"requirements":{"minecraft:cobbled_deepslate":1},"sha256":"ebb05901c0de1f7e9f803261b244c58afd146580d13ee27db84a96efb5926795","size":{"x":32,"y":1,"z":32}},{"blockCount":1,"bytes":648,"file":"chunks/y037-z032-x128.json","offset":{"x":128,"y":37,"z":32},"requirements":{"minecraft:cobbled_deepslate":1},"sha256":"36e069a415b72154fdebd324d3c452225facf6a2b907e4ed3cc309071159c9af","size":{"x":32,"y":1,"z":32}},{"blockCount":241,"bytes":2873,"file":"chunks/y037-z032-x352.json","offset":{"x":352,"y":37,"z":32},"requirements":{"minecraft:oak_planks":20,"minecraft:spruce_planks":76,"minecraft:stone_bricks":145},"sha256":"a49d06e8a7f364a84ee52233c1311d9f8b0c42686426eee39958956a1584cdaa","size":{"x":32,"y":1,"z":32}},{"blockCount":58,"bytes":1565,"file":"chunks/y037-z032-x384.json","offset":{"x":384,"y":37,"z":32},"requirements":{"minecraft:bricks":13,"minecraft:glass":6,"minecraft:polished_diorite":15,"minecraft:stone_bricks":24},"sha256":"16ff8ddebdfc79cb94d25451612a95e9d561d30c88f17556ec326e016d5ddbf4","size":{"x":32,"y":1,"z":32}},{"blockCount":124,"bytes":4177,"file":"chunks/y037-z064-x064.json","offset":{"x":64,"y":37,"z":64},"requirements":{"minecraft:bricks":19,"minecraft:glass":26,"minecraft:oak_planks":5,"minecraft:polished_diorite":46,"minecraft:sandstone":10,"minecraft:stone_bricks":18},"sha256":"3b7b73468ac27028bf7314eaaf0b490ece4265c43f3f842bc4e77a434baded8b","size":{"x":32,"y":1,"z":32}},{"blockCount":161,"bytes":3027,"file":"chunks/y037-z064-x096.json","offset":{"x":96,"y":37,"z":64},"requirements":{"minecraft:bricks":59,"minecraft:glass":6,"minecraft:oak_planks":10,"minecraft:polished_diorite":50,"minecraft:sandstone":20,"minecraft:stone_bricks":16},"sha256":"224c6b639c157e4b380c43ae5cbb98db8632e8408f7b696d4ded388b530a790c","size":{"x":32,"y":1,"z":32}},{"blockCount":242,"bytes":5108,"file":"chunks/y037-z064-x128.json","offset":{"x":128,"y":37,"z":64},"requirements":{"minecraft:bricks":66,"minecraft:glass":32,"minecraft:oak_planks":5,"minecraft:polished_diorite":86,"minecraft:sandstone":29,"minecraft:stone_bricks":24},"sha256":"11168d49ccc76650f07bcafc09b70136a548e8996c248d2924a8d392b1fb6e4a","size":{"x":32,"y":1,"z":32}},{"blockCount":7,"bytes":881,"file":"chunks/y037-z064-x160.json","offset":{"x":160,"y":37,"z":64},"requirements":{"minecraft:polished_diorite":7},"sha256":"21c3532168ec5cc4e834fb9c297b9d0c696ce66ae09a9e5d9f0259e7b1796b98","size":{"x":32,"y":1,"z":32}},{"blockCount":12,"bytes":1009,"file":"chunks/y037-z064-x192.json","offset":{"x":192,"y":37,"z":64},"requirements":{"minecraft:glass":3,"minecraft:polished_diorite":9},"sha256":"64dec2dde09096fd50ef10349868ffda57572448845a680d0b0f31ca1df29f89","size":{"x":32,"y":1,"z":32}},{"blockCount":15,"bytes":1049,"file":"chunks/y037-z064-x224.json","offset":{"x":224,"y":37,"z":64},"requirements":{"minecraft:glass":3,"minecraft:polished_diorite":12},"sha256":"3c8b1ce7a408501d72f772d48e020e8b2629747dd9bb1a2ade0076034bad0694","size":{"x":32,"y":1,"z":32}},{"blockCount":8,"bytes":850,"file":"chunks/y037-z064-x288.json","offset":{"x":288,"y":37,"z":64},"requirements":{"minecraft:oak_planks":4,"minecraft:spruce_planks":2,"minecraft:stone_bricks":2},"sha256":"920156334ae0207ce42ad9531342ced8116b21639a540ed4f0711847d67136ad","size":{"x":32,"y":1,"z":32}},{"blockCount":1,"bytes":647,"file":"chunks/y037-z064-x320.json","offset":{"x":320,"y":37,"z":64},"requirements":{"minecraft:polished_diorite":1},"sha256":"fc5713ba55230e09881bee2a8d0d673667f96928a0f8c66cd5c95cca741138ae","size":{"x":32,"y":1,"z":32}},{"blockCount":3,"bytes":725,"file":"chunks/y037-z064-x352.json","offset":{"x":352,"y":37,"z":64},"requirements":{"minecraft:polished_diorite":3},"sha256":"ed43110c64042bad7b6ee928b9ff006c17c393cd6ca713edb5f07462b9892e6c","size":{"x":32,"y":1,"z":32}},{"blockCount":82,"bytes":2794,"file":"chunks/y037-z096-x000.json","offset":{"x":0,"y":37,"z":96},"requirements":{"minecraft:bricks":5,"minecraft:glass":38,"minecraft:polished_diorite":28,"minecraft:sandstone":2,"minecraft:stone_bricks":9},"sha256":"610f4b1da15088b043825a6fda7c86b112a126b4577995fc7511830d02bc781b","size":{"x":32,"y":1,"z":32}},{"blockCount":158,"bytes":3903,"file":"chunks/y037-z096-x032.json","offset":{"x":32,"y":37,"z":96},"requirements":{"minecraft:bricks":29,"minecraft:glass":49,"minecraft:polished_diorite":47,"minecraft:sandstone":18,"minecraft:spruce_planks":4,"minecraft:stone_bricks":11},"sha256":"d4eebc55de70b9b49ae16e23bb1710f6b6ef3df47fe350aea92c19d986dc42c0","size":{"x":32,"y":1,"z":32}},{"blockCount":122,"bytes":3266,"file":"chunks/y037-z096-x064.json","offset":{"x":64,"y":37,"z":96},"requirements":{"minecraft:bricks":31,"minecraft:glass":27,"minecraft:polished_diorite":37,"minecraft:sandstone":15,"minecraft:stone_bricks":12},"sha256":"277a59b9abd27f5c6eefbad0a237f9d6e90b5561dc1af19f40ae0137fd82d60b","size":{"x":32,"y":1,"z":32}},{"blockCount":25,"bytes":1163,"file":"chunks/y037-z096-x096.json","offset":{"x":96,"y":37,"z":96},"requirements":{"minecraft:glass":11,"minecraft:sandstone":14},"sha256":"072f6dcc87035cb5c07857b38782a1b3ea7833721f67615c1a9362fa2b783b06","size":{"x":32,"y":1,"z":32}},{"blockCount":70,"bytes":2300,"file":"chunks/y037-z096-x128.json","offset":{"x":128,"y":37,"z":96},"requirements":{"minecraft:bricks":20,"minecraft:glass":14,"minecraft:polished_diorite":12,"minecraft:sandstone":19,"minecraft:stone_bricks":5},"sha256":"3226c25efdc8ca556aec2ea487d96a0bd10418817b30dac7215153c6acffbec5","size":{"x":32,"y":1,"z":32}},{"blockCount":133,"bytes":3073,"file":"chunks/y037-z096-x160.json","offset":{"x":160,"y":37,"z":96},"requirements":{"minecraft:bricks":21,"minecraft:glass":36,"minecraft:polished_diorite":44,"minecraft:sandstone":21,"minecraft:stone_bricks":11},"sha256":"83de3ba56c80b8cc46a430e0fbd9827e2632c9e89f14f7072356219616fbae62","size":{"x":32,"y":1,"z":32}},{"blockCount":282,"bytes":4748,"file":"chunks/y037-z096-x192.json","offset":{"x":192,"y":37,"z":96},"requirements":{"minecraft:bricks":152,"minecraft:glass":42,"minecraft:polished_diorite":41,"minecraft:sandstone":14,"minecraft:spruce_planks":4,"minecraft:stone_bricks":29},"sha256":"e39d7dea56622ce03481defda53e8e25ea2899f025ff4b371d470623a6d5fcde","size":{"x":32,"y":1,"z":32}},{"blockCount":152,"bytes":3888,"file":"chunks/y037-z096-x224.json","offset":{"x":224,"y":37,"z":96},"requirements":{"minecraft:bricks":72,"minecraft:cobbled_deepslate":1,"minecraft:glass":11,"minecraft:oak_planks":5,"minecraft:polished_diorite":55,"minecraft:stone_bricks":8},"sha256":"c6c301c514e45440c4020896fe34d681620f34398494d35ee50d8eb07f772b5c","size":{"x":32,"y":1,"z":32}},{"blockCount":6,"bytes":792,"file":"chunks/y037-z096-x256.json","offset":{"x":256,"y":37,"z":96},"requirements":{"minecraft:oak_planks":2,"minecraft:spruce_planks":2,"minecraft:stone_bricks":2},"sha256":"bcb96048a16be1d0d9f111146b425870f021f770dd896b394fc861ff8638c229","size":{"x":32,"y":1,"z":32}},{"blockCount":4,"bytes":767,"file":"chunks/y037-z096-x352.json","offset":{"x":352,"y":37,"z":96},"requirements":{"minecraft:polished_diorite":4},"sha256":"cc55a82266395512fd67781cae35ac3f067440d4c0a419eae8e8af614791a972","size":{"x":32,"y":1,"z":32}},{"blockCount":118,"bytes":3753,"file":"chunks/y037-z128-x000.json","offset":{"x":0,"y":37,"z":128},"requirements":{"minecraft:bricks":18,"minecraft:glass":43,"minecraft:polished_diorite":31,"minecraft:sandstone":7,"minecraft:stone_bricks":19},"sha256":"c1d1805b0aa41dce0e62c276710571a5634a4f4020164dc77106fe35ad499ada","size":{"x":32,"y":1,"z":32}},{"blockCount":180,"bytes":4611,"file":"chunks/y037-z128-x032.json","offset":{"x":32,"y":37,"z":128},"requirements":{"minecraft:bricks":102,"minecraft:cobbled_deepslate":23,"minecraft:glass":20,"minecraft:oak_planks":4,"minecraft:sandstone":21,"minecraft:spruce_planks":2,"minecraft:stone_bricks":8},"sha256":"878503a1a2b7f27a45ba6bcf1bdc4fbd64e4db3c646690c69b0e1055c7b5bc4e","size":{"x":32,"y":1,"z":32}},{"blockCount":29,"bytes":1460,"file":"chunks/y037-z128-x064.json","offset":{"x":64,"y":37,"z":128},"requirements":{"minecraft:glass":18,"minecraft:sandstone":10,"minecraft:stone_bricks":1},"sha256":"adaa2eb2de18748d865f150a6b3d02b58f34bf405ec8f479a869f4c5427182e7","size":{"x":32,"y":1,"z":32}},{"blockCount":17,"bytes":1129,"file":"chunks/y037-z128-x096.json","offset":{"x":96,"y":37,"z":128},"requirements":{"minecraft:bricks":7,"minecraft:glass":3,"minecraft:sandstone":4,"minecraft:stone_bricks":3},"sha256":"7b5b0e424e3413a4cd8ba37ab85bfe9cdfdca354cb5b61b3b9a21ee95d9c4bda","size":{"x":32,"y":1,"z":32}},{"blockCount":18,"bytes":1004,"file":"chunks/y037-z128-x128.json","offset":{"x":128,"y":37,"z":128},"requirements":{"minecraft:glass":8,"minecraft:sandstone":10},"sha256":"fc2daed218fac5cb29181b264ecdee86414499e19c8b901888565cb888bfd39c","size":{"x":32,"y":1,"z":32}},{"blockCount":21,"bytes":1104,"file":"chunks/y037-z128-x160.json","offset":{"x":160,"y":37,"z":128},"requirements":{"minecraft:glass":10,"minecraft:sandstone":11},"sha256":"8ee5f6b80fcefe87b87f90807da4510aaf767d914d127e052b032efcf4f8ccd2","size":{"x":32,"y":1,"z":32}},{"blockCount":116,"bytes":2711,"file":"chunks/y037-z128-x192.json","offset":{"x":192,"y":37,"z":128},"requirements":{"minecraft:bricks":56,"minecraft:glass":7,"minecraft:polished_diorite":32,"minecraft:sandstone":14,"minecraft:stone_bricks":7},"sha256":"5aa539ab9828b1d1dd14a014694f0ced220940baf781f4ae18b713b391952557","size":{"x":32,"y":1,"z":32}},{"blockCount":134,"bytes":3006,"file":"chunks/y037-z128-x224.json","offset":{"x":224,"y":37,"z":128},"requirements":{"minecraft:bricks":53,"minecraft:oak_planks":10,"minecraft:polished_diorite":54,"minecraft:stone_bricks":17},"sha256":"5a876d9b3618b699c552fccf16ba1f1cbcee30123db45c4c45639a8bcb419729","size":{"x":32,"y":1,"z":32}},{"blockCount":5,"bytes":791,"file":"chunks/y037-z128-x320.json","offset":{"x":320,"y":37,"z":128},"requirements":{"minecraft:polished_diorite":4,"minecraft:stone_bricks":1},"sha256":"31b6cb2aee29ecea3de531d82985019004106e5e38fd2811f24dbd2d12dc0249","size":{"x":32,"y":1,"z":32}},{"blockCount":57,"bytes":2250,"file":"chunks/y037-z160-x000.json","offset":{"x":0,"y":37,"z":160},"requirements":{"minecraft:bricks":5,"minecraft:cobbled_deepslate":2,"minecraft:glass":24,"minecraft:polished_diorite":20,"minecraft:sandstone":1,"minecraft:stone_bricks":5},"sha256":"9b57ab6934e7ae0d084320e41aaf37fff1b82d0acc9add71a5b6d5e4139c7758","size":{"x":32,"y":1,"z":32}},{"blockCount":117,"bytes":3125,"file":"chunks/y037-z160-x032.json","offset":{"x":32,"y":37,"z":160},"requirements":{"minecraft:bricks":15,"minecraft:cobbled_deepslate":5,"minecraft:glass":30,"minecraft:polished_diorite":47,"minecraft:sandstone":8,"minecraft:stone_bricks":12},"sha256":"8c1b0d922920519016e7d519c44599d48c88078545ab2135ed0e42d080201e68","size":{"x":32,"y":1,"z":32}},{"blockCount":121,"bytes":3265,"file":"chunks/y037-z160-x064.json","offset":{"x":64,"y":37,"z":160},"requirements":{"minecraft:bricks":34,"minecraft:glass":20,"minecraft:polished_diorite":45,"minecraft:sandstone":8,"minecraft:stone_bricks":14},"sha256":"a744973bc238d3f770c2f339a99a0ca2eda8733ccd686d16da6a1fcfe765183b","size":{"x":32,"y":1,"z":32}},{"blockCount":28,"bytes":1287,"file":"chunks/y037-z160-x096.json","offset":{"x":96,"y":37,"z":160},"requirements":{"minecraft:bricks":3,"minecraft:glass":8,"minecraft:sandstone":11,"minecraft:stone_bricks":6},"sha256":"6e60b7de605062c42082beaa6ba4711d09c241d3fd7eb8d6315229529adee2da","size":{"x":32,"y":1,"z":32}},{"blockCount":80,"bytes":2646,"file":"chunks/y037-z160-x128.json","offset":{"x":128,"y":37,"z":160},"requirements":{"minecraft:bricks":23,"minecraft:glass":15,"minecraft:polished_diorite":19,"minecraft:sandstone":15,"minecraft:stone_bricks":8},"sha256":"cb254f6069a911ff172c0ad59079d8df29047114e0e98167bb583d73518bfe61","size":{"x":32,"y":1,"z":32}},{"blockCount":113,"bytes":2614,"file":"chunks/y037-z160-x160.json","offset":{"x":160,"y":37,"z":160},"requirements":{"minecraft:bricks":21,"minecraft:glass":26,"minecraft:polished_diorite":45,"minecraft:sandstone":10,"minecraft:stone_bricks":11},"sha256":"c76b890b2d0a4c8b9a1a2ffebde28531fb7ea4cff7c7846ab788431202ad76bd","size":{"x":32,"y":1,"z":32}},{"blockCount":229,"bytes":4072,"file":"chunks/y037-z160-x192.json","offset":{"x":192,"y":37,"z":160},"requirements":{"minecraft:bricks":120,"minecraft:glass":26,"minecraft:polished_diorite":50,"minecraft:sandstone":7,"minecraft:stone_bricks":26},"sha256":"133f85ad3eedc8ec3b7a3f71bd77f71da64e32b042db05d76c3e2aee7c3d783d","size":{"x":32,"y":1,"z":32}},{"blockCount":115,"bytes":3430,"file":"chunks/y037-z160-x224.json","offset":{"x":224,"y":37,"z":160},"requirements":{"minecraft:bricks":53,"minecraft:cobbled_deepslate":1,"minecraft:glass":14,"minecraft:oak_planks":5,"minecraft:polished_diorite":37,"minecraft:stone_bricks":5},"sha256":"e4b89f2a68a3e2cb05fc13c0e7bd196c6c2dcc476473ed0e40bc57600aaa373b","size":{"x":32,"y":1,"z":32}},{"blockCount":6,"bytes":793,"file":"chunks/y037-z160-x256.json","offset":{"x":256,"y":37,"z":160},"requirements":{"minecraft:oak_planks":2,"minecraft:spruce_planks":2,"minecraft:stone_bricks":2},"sha256":"f203c749b4b2b19e74a04e760dcfea86f0c55be757aaa5ee69bb55d9e56cdddb","size":{"x":32,"y":1,"z":32}},{"blockCount":11,"bytes":927,"file":"chunks/y037-z160-x288.json","offset":{"x":288,"y":37,"z":160},"requirements":{"minecraft:oak_planks":4,"minecraft:spruce_planks":3,"minecraft:stone_bricks":4},"sha256":"f8cf6804e54c789535e2b05b6e9bb0f8190004383428fa38ef1f46a6cc422fb3","size":{"x":32,"y":1,"z":32}},{"blockCount":1,"bytes":628,"file":"chunks/y037-z160-x320.json","offset":{"x":320,"y":37,"z":160},"requirements":{"minecraft:polished_diorite":1},"sha256":"264b6d3a9b8d2a63425316f7a6cf96c7fcf2dabd7390265f018c84905acf9251","size":{"x":32,"y":1,"z":32}},{"blockCount":7,"bytes":884,"file":"chunks/y037-z160-x352.json","offset":{"x":352,"y":37,"z":160},"requirements":{"minecraft:polished_diorite":7},"sha256":"b0976bf4502775d89356d0576648169c0a63a6829703bac9bd159c54809b14c1","size":{"x":32,"y":1,"z":32}},{"blockCount":100,"bytes":3526,"file":"chunks/y037-z192-x064.json","offset":{"x":64,"y":37,"z":192},"requirements":{"minecraft:bricks":16,"minecraft:glass":19,"minecraft:oak_planks":5,"minecraft:polished_diorite":38,"minecraft:sandstone":7,"minecraft:stone_bricks":15},"sha256":"3bfd064811a3f7d8af4b6940ee85ba901563280000782428d260599073f87505","size":{"x":32,"y":1,"z":32}},{"blockCount":158,"bytes":2932,"file":"chunks/y037-z192-x096.json","offset":{"x":96,"y":37,"z":192},"requirements":{"minecraft:bricks":59,"minecraft:glass":4,"minecraft:oak_planks":10,"minecraft:polished_diorite":50,"minecraft:sandstone":19,"minecraft:stone_bricks":16},"sha256":"68c94542aede0154cbe612934f02d2cae55bfa1bfe7969af09e95a475475d08e","size":{"x":32,"y":1,"z":32}},{"blockCount":217,"bytes":4459,"file":"chunks/y037-z192-x128.json","offset":{"x":128,"y":37,"z":192},"requirements":{"minecraft:bricks":63,"minecraft:glass":23,"minecraft:oak_planks":5,"minecraft:polished_diorite":79,"minecraft:sandstone":26,"minecraft:stone_bricks":21},"sha256":"a5604a41f8475ea3737458961ea5d88944b5ba35e91b86df8a9af1b3bcf155ac","size":{"x":32,"y":1,"z":32}},{"blockCount":6,"bytes":844,"file":"chunks/y037-z192-x160.json","offset":{"x":160,"y":37,"z":192},"requirements":{"minecraft:polished_diorite":6},"sha256":"e3686f8a3a35caa225df1b3baf2bd2fd669c4d6e144a32e58ad4a48d28e75ce6","size":{"x":32,"y":1,"z":32}},{"blockCount":288,"bytes":4961,"file":"chunks/y038-z000-x352.json","offset":{"x":352,"y":38,"z":0},"requirements":{"minecraft:bricks":5,"minecraft:cobbled_deepslate":2,"minecraft:glass":4,"minecraft:oak_planks":50,"minecraft:polished_diorite":30,"minecraft:sandstone":24,"minecraft:spruce_planks":41,"minecraft:stone_bricks":132},"sha256":"676da477cbe49aaad269c210541fb3ead798e928f8c1e02d84ecc90eab114e86","size":{"x":32,"y":1,"z":32}},{"blockCount":289,"bytes":5766,"file":"chunks/y038-z000-x384.json","offset":{"x":384,"y":38,"z":0},"requirements":{"minecraft:bricks":58,"minecraft:cobbled_deepslate":1,"minecraft:glass":27,"minecraft:oak_planks":27,"minecraft:polished_diorite":103,"minecraft:sandstone":11,"minecraft:spruce_planks":19,"minecraft:stone_bricks":43},"sha256":"c776b4e7c2fda0393024ed6b7be6a94b0b423e529a6eed1d9c25958b19212cbe","size":{"x":32,"y":1,"z":32}},{"blockCount":1,"bytes":647,"file":"chunks/y038-z032-x064.json","offset":{"x":64,"y":38,"z":32},"requirements":{"minecraft:cobbled_deepslate":1},"sha256":"6fa0ef2e23d36312d01f6150463ce678909e7280dfc74634734a2e7dffb7214b","size":{"x":32,"y":1,"z":32}},{"blockCount":1,"bytes":648,"file":"chunks/y038-z032-x128.json","offset":{"x":128,"y":38,"z":32},"requirements":{"minecraft:cobbled_deepslate":1},"sha256":"3884979c36e90af2b97d10539e1eb312c6a01e01d20ee5505b1db90a4ecede2a","size":{"x":32,"y":1,"z":32}},{"blockCount":356,"bytes":2997,"file":"chunks/y038-z032-x352.json","offset":{"x":352,"y":38,"z":32},"requirements":{"minecraft:oak_planks":54,"minecraft:spruce_planks":249,"minecraft:stone_bricks":53},"sha256":"5e0c793c692f57a83e872ec233635f547fca91f48df93ce4cb34364d7ee4849e","size":{"x":32,"y":1,"z":32}},{"blockCount":117,"bytes":1535,"file":"chunks/y038-z032-x384.json","offset":{"x":384,"y":38,"z":32},"requirements":{"minecraft:bricks":20,"minecraft:cobbled_deepslate":5,"minecraft:glass":1,"minecraft:polished_diorite":16,"minecraft:stone_bricks":75},"sha256":"87e345ff73f1873a2ff637d876e2029bb41c84bc29b1e2b1033e2ad73ce5edb8","size":{"x":32,"y":1,"z":32}},{"blockCount":111,"bytes":3743,"file":"chunks/y038-z064-x064.json","offset":{"x":64,"y":38,"z":64},"requirements":{"minecraft:bricks":19,"minecraft:glass":18,"minecraft:polished_diorite":45,"minecraft:sandstone":10,"minecraft:spruce_planks":5,"minecraft:stone_bricks":14},"sha256":"2654e0a96ee5f24bb6d3ec5502a9bd29a359192c7f5eafe83f1a09cb6041de0f","size":{"x":32,"y":1,"z":32}},{"blockCount":166,"bytes":3032,"file":"chunks/y038-z064-x096.json","offset":{"x":96,"y":38,"z":64},"requirements":{"minecraft:bricks":59,"minecraft:glass":1,"minecraft:polished_diorite":42,"minecraft:sandstone":42,"minecraft:spruce_planks":10,"minecraft:stone_bricks":12},"sha256":"1f533d0446bd3017480b7ba22c3bd37f7c647b6794ec3abfc89a60b569427e29","size":{"x":32,"y":1,"z":32}},{"blockCount":244,"bytes":4792,"file":"chunks/y038-z064-x128.json","offset":{"x":128,"y":38,"z":64},"requirements":{"minecraft:bricks":66,"minecraft:glass":19,"minecraft:polished_diorite":83,"minecraft:sandstone":51,"minecraft:spruce_planks":5,"minecraft:stone_bricks":20},"sha256":"f88ce762b2e8f2af6e8b9f0fbf5b4d223b11d793a8c04a0b5cf5a7d6403979aa","size":{"x":32,"y":1,"z":32}},{"blockCount":7,"bytes":881,"file":"chunks/y038-z064-x160.json","offset":{"x":160,"y":38,"z":64},"requirements":{"minecraft:polished_diorite":7},"sha256":"8e90db090104cb12dc7fc6d889472f85308d2da8c1a0cf669176695d9d647be8","size":{"x":32,"y":1,"z":32}},{"blockCount":9,"bytes":875,"file":"chunks/y038-z064-x192.json","offset":{"x":192,"y":38,"z":64},"requirements":{"minecraft:polished_diorite":9},"sha256":"9ba3d07d08494db0e5139f789aa62cf50eef49a1dd7160c04fb2a5bb92584905","size":{"x":32,"y":1,"z":32}},{"blockCount":13,"bytes":955,"file":"chunks/y038-z064-x224.json","offset":{"x":224,"y":38,"z":64},"requirements":{"minecraft:bricks":1,"minecraft:polished_diorite":12},"sha256":"04f6da88db61f4ab82d9debcec1efe953742c8203bcd9f3ca0c348cc43c1779c","size":{"x":32,"y":1,"z":32}},{"blockCount":8,"bytes":927,"file":"chunks/y038-z064-x288.json","offset":{"x":288,"y":38,"z":64},"requirements":{"minecraft:oak_planks":2,"minecraft:spruce_planks":3,"minecraft:stone_bricks":3},"sha256":"b318f23a868dd667756ea15e6c227cca7fc2deb8bf13255dc8a16c3182cec7dd","size":{"x":32,"y":1,"z":32}},{"blockCount":1,"bytes":647,"file":"chunks/y038-z064-x320.json","offset":{"x":320,"y":38,"z":64},"requirements":{"minecraft:polished_diorite":1},"sha256":"3c0c4d94160c5c14e06e667d746c198d3a40864a94af1e1f3747c2ca392b2126","size":{"x":32,"y":1,"z":32}},{"blockCount":3,"bytes":725,"file":"chunks/y038-z064-x352.json","offset":{"x":352,"y":38,"z":64},"requirements":{"minecraft:polished_diorite":3},"sha256":"4ec44c34a5874019244232692dd773fd89337a0cd0abbe6c426a360471e4563d","size":{"x":32,"y":1,"z":32}},{"blockCount":69,"bytes":2737,"file":"chunks/y038-z096-x000.json","offset":{"x":0,"y":38,"z":96},"requirements":{"minecraft:bricks":5,"minecraft:glass":25,"minecraft:polished_diorite":28,"minecraft:sandstone":2,"minecraft:stone_bricks":9},"sha256":"fb2024a7ffc9228ccecbeb0b05f6df59e0cf773bdfba6d73ad85071721e67e70","size":{"x":32,"y":1,"z":32}},{"blockCount":162,"bytes":4144,"file":"chunks/y038-z096-x032.json","offset":{"x":32,"y":38,"z":96},"requirements":{"minecraft:bricks":25,"minecraft:glass":32,"minecraft:polished_diorite":47,"minecraft:sandstone":47,"minecraft:stone_bricks":11},"sha256":"3baa817fe6993c317b96623b567f3bd7e8db1b3cac0262703101518ca8cf0020","size":{"x":32,"y":1,"z":32}},{"blockCount":152,"bytes":3376,"file":"chunks/y038-z096-x064.json","offset":{"x":64,"y":38,"z":96},"requirements":{"minecraft:bricks":31,"minecraft:glass":15,"minecraft:polished_diorite":37,"minecraft:sandstone":50,"minecraft:stone_bricks":19},"sha256":"cc336bda009e8108ef15f2b5b38c2782b1538373f17b1202d75ef81e9627fed6","size":{"x":32,"y":1,"z":32}},{"blockCount":55,"bytes":1108,"file":"chunks/y038-z096-x096.json","offset":{"x":96,"y":38,"z":96},"requirements":{"minecraft:sandstone":55},"sha256":"8f86a2e51d291e2ef4999a141e92a06e4807d9ee899ebf0fe681c56558bed91f","size":{"x":32,"y":1,"z":32}},{"blockCount":119,"bytes":2304,"file":"chunks/y038-z096-x128.json","offset":{"x":128,"y":38,"z":96},"requirements":{"minecraft:bricks":20,"minecraft:polished_diorite":12,"minecraft:sandstone":76,"minecraft:stone_bricks":11},"sha256":"8b6b691dda3c602ccb925a785545a248e7a0c1a794bb3fb9085acd8dcc4be141","size":{"x":32,"y":1,"z":32}},{"blockCount":156,"bytes":3336,"file":"chunks/y038-z096-x160.json","offset":{"x":160,"y":38,"z":96},"requirements":{"minecraft:bricks":21,"minecraft:glass":18,"minecraft:polished_diorite":44,"minecraft:sandstone":60,"minecraft:stone_bricks":13},"sha256":"37cbd160d0aef3a8135b9524fec11b305674ae99c12ab30dd4de7f5b69436be4","size":{"x":32,"y":1,"z":32}},{"blockCount":271,"bytes":4853,"file":"chunks/y038-z096-x192.json","offset":{"x":192,"y":38,"z":96},"requirements":{"minecraft:bricks":148,"minecraft:glass":25,"minecraft:polished_diorite":43,"minecraft:sandstone":33,"minecraft:stone_bricks":22},"sha256":"280eb7b12c61c03fb4c857c9ff13dbc68fad770a785dc3b6b6c5ff445f228738","size":{"x":32,"y":1,"z":32}},{"blockCount":145,"bytes":3700,"file":"chunks/y038-z096-x224.json","offset":{"x":224,"y":38,"z":96},"requirements":{"minecraft:bricks":72,"minecraft:cobbled_deepslate":1,"minecraft:glass":8,"minecraft:polished_diorite":54,"minecraft:spruce_planks":5,"minecraft:stone_bricks":5},"sha256":"2d757b51c0cda6b821dd20d57c9c982db5e59a7058fae5edcc6f6d7f9de4699d","size":{"x":32,"y":1,"z":32}},{"blockCount":8,"bytes":831,"file":"chunks/y038-z096-x256.json","offset":{"x":256,"y":38,"z":96},"requirements":{"minecraft:oak_planks":3,"minecraft:spruce_planks":3,"minecraft:stone_bricks":2},"sha256":"396c90350389575777554b3c0e7900c4b0a6c09170cdb36ca5f29a5bc98eeb42","size":{"x":32,"y":1,"z":32}},{"blockCount":4,"bytes":767,"file":"chunks/y038-z096-x352.json","offset":{"x":352,"y":38,"z":96},"requirements":{"minecraft:polished_diorite":4},"sha256":"c2c0f66c84d177f14c993b2238197ca9649dbd17deafd6736e577e2b7e773bd5","size":{"x":32,"y":1,"z":32}},{"blockCount":110,"bytes":3734,"file":"chunks/y038-z128-x000.json","offset":{"x":0,"y":38,"z":128},"requirements":{"minecraft:bricks":18,"minecraft:glass":32,"minecraft:polished_diorite":31,"minecraft:sandstone":6,"minecraft:stone_bricks":23},"sha256":"6e9adaa190c684ab2037955627a709cc3fc24941b2cee5e5d875c6005e3eb223","size":{"x":32,"y":1,"z":32}},{"blockCount":193,"bytes":4588,"file":"chunks/y038-z128-x032.json","offset":{"x":32,"y":38,"z":128},"requirements":{"minecraft:bricks":80,"minecraft:cobbled_deepslate":25,"minecraft:glass":4,"minecraft:oak_planks":1,"minecraft:sandstone":76,"minecraft:spruce_planks":1,"minecraft:stone_bricks":6},"sha256":"96f543758d5931fec1af1f579189342902e05fdb47b8f22fce428c85ebc4f6c2","size":{"x":32,"y":1,"z":32}},{"blockCount":45,"bytes":1231,"file":"chunks/y038-z128-x064.json","offset":{"x":64,"y":38,"z":128},"requirements":{"minecraft:glass":6,"minecraft:sandstone":39},"sha256":"fa4fdf6295154cb32c2e520b32fe7dc929aa9c7f313fdccb6080cd96ebe26f7d","size":{"x":32,"y":1,"z":32}},{"blockCount":24,"bytes":1225,"file":"chunks/y038-z128-x096.json","offset":{"x":96,"y":38,"z":128},"requirements":{"minecraft:bricks":10,"minecraft:glass":2,"minecraft:sandstone":9,"minecraft:stone_bricks":3},"sha256":"a5679026efb79d06ea9fbb6e52f4500ca722566fb465c64f839dc760ebbb3f7c","size":{"x":32,"y":1,"z":32}},{"blockCount":36,"bytes":909,"file":"chunks/y038-z128-x128.json","offset":{"x":128,"y":38,"z":128},"requirements":{"minecraft:sandstone":36},"sha256":"676cc28002f8bb2db83a8d808195883fa80c6fc851a24b38a23d7ba9da48114d","size":{"x":32,"y":1,"z":32}},{"blockCount":43,"bytes":1041,"file":"chunks/y038-z128-x160.json","offset":{"x":160,"y":38,"z":128},"requirements":{"minecraft:sandstone":43},"sha256":"e5a5b54457f807edbc85067d02208f362cff93ff0696ead1cf49eb6447bcf36d","size":{"x":32,"y":1,"z":32}},{"blockCount":101,"bytes":2674,"file":"chunks/y038-z128-x192.json","offset":{"x":192,"y":38,"z":128},"requirements":{"minecraft:bricks":48,"minecraft:glass":5,"minecraft:polished_diorite":16,"minecraft:sandstone":28,"minecraft:stone_bricks":4},"sha256":"6873846c6422bae1898af1d5bf5145f9c2c3c45cbbc14c27286c30dc0c5719c0","size":{"x":32,"y":1,"z":32}},{"blockCount":127,"bytes":2933,"file":"chunks/y038-z128-x224.json","offset":{"x":224,"y":38,"z":128},"requirements":{"minecraft:bricks":53,"minecraft:polished_diorite":50,"minecraft:spruce_planks":10,"minecraft:stone_bricks":14},"sha256":"be7e9469708e83186034ebe4ac7860182c5b35eb032caee0b62c69fbf4a247eb","size":{"x":32,"y":1,"z":32}},{"blockCount":4,"bytes":764,"file":"chunks/y038-z128-x320.json","offset":{"x":320,"y":38,"z":128},"requirements":{"minecraft:polished_diorite":4},"sha256":"a926b0ed53a763bef2ae2525061fb491d80839d0304880472ba39af838f2ce56","size":{"x":32,"y":1,"z":32}},{"blockCount":52,"bytes":2288,"file":"chunks/y038-z160-x000.json","offset":{"x":0,"y":38,"z":160},"requirements":{"minecraft:bricks":5,"minecraft:cobbled_deepslate":2,"minecraft:glass":15,"minecraft:polished_diorite":20,"minecraft:sandstone":1,"minecraft:stone_bricks":9},"sha256":"4a349a39691147414b0b279661c53aa5df69c00f38f536550baf5a543d1a26c3","size":{"x":32,"y":1,"z":32}},{"blockCount":125,"bytes":3584,"file":"chunks/y038-z160-x032.json","offset":{"x":32,"y":38,"z":160},"requirements":{"minecraft:bricks":15,"minecraft:cobbled_deepslate":5,"minecraft:glass":21,"minecraft:polished_diorite":47,"minecraft:sandstone":14,"minecraft:stone_bricks":23},"sha256":"2f5c0bb1592c2fa042314735462c5900209c54d589c3e3de7417ceccb8180920","size":{"x":32,"y":1,"z":32}},{"blockCount":129,"bytes":3343,"file":"chunks/y038-z160-x064.json","offset":{"x":64,"y":38,"z":160},"requirements":{"minecraft:bricks":34,"minecraft:glass":14,"minecraft:polished_diorite":45,"minecraft:sandstone":14,"minecraft:stone_bricks":22},"sha256":"ca6c92fa456ce516f62b7c952c13f2760d0190bf44a3c7ee1cfdccff2f866629","size":{"x":32,"y":1,"z":32}},{"blockCount":45,"bytes":1157,"file":"chunks/y038-z160-x096.json","offset":{"x":96,"y":38,"z":160},"requirements":{"minecraft:bricks":2,"minecraft:sandstone":42,"minecraft:stone_bricks":1},"sha256":"f2802c982586174b57fd4166bcad8e90f130b17db4241ef1322c93cb5942c613","size":{"x":32,"y":1,"z":32}},{"blockCount":114,"bytes":2669,"file":"chunks/y038-z160-x128.json","offset":{"x":128,"y":38,"z":160},"requirements":{"minecraft:bricks":23,"minecraft:glass":5,"minecraft:polished_diorite":19,"minecraft:sandstone":53,"minecraft:stone_bricks":14},"sha256":"4c7e7f670082e6d8ed5c63b53f50471ae9a092ac6be1f98a24b5e6c643963644","size":{"x":32,"y":1,"z":32}},{"blockCount":114,"bytes":2939,"file":"chunks/y038-z160-x160.json","offset":{"x":160,"y":38,"z":160},"requirements":{"minecraft:bricks":21,"minecraft:glass":18,"minecraft:polished_diorite":45,"minecraft:sandstone":17,"minecraft:stone_bricks":13},"sha256":"4ad874b27a80c9424bcb59ebfcf0dfe9b6b63a32cc9c110314dc9b88475187e7","size":{"x":32,"y":1,"z":32}},{"blockCount":220,"bytes":4245,"file":"chunks/y038-z160-x192.json","offset":{"x":192,"y":38,"z":160},"requirements":{"minecraft:bricks":120,"minecraft:glass":16,"minecraft:polished_diorite":52,"minecraft:sandstone":12,"minecraft:stone_bricks":20},"sha256":"dd2363a42a233aea58ccd3a1a7651408f995ab21d6b3378ee5e528a5e86c6f82","size":{"x":32,"y":1,"z":32}},{"blockCount":106,"bytes":3166,"file":"chunks/y038-z160-x224.json","offset":{"x":224,"y":38,"z":160},"requirements":{"minecraft:bricks":53,"minecraft:cobbled_deepslate":1,"minecraft:glass":8,"minecraft:polished_diorite":36,"minecraft:spruce_planks":5,"minecraft:stone_bricks":3},"sha256":"dfb6c11fc4ed0d8cf68a6b3935d6c366c70828d38e81274157426bfadb25fd57","size":{"x":32,"y":1,"z":32}},{"blockCount":7,"bytes":794,"file":"chunks/y038-z160-x256.json","offset":{"x":256,"y":38,"z":160},"requirements":{"minecraft:oak_planks":3,"minecraft:spruce_planks":3,"minecraft:stone_bricks":1},"sha256":"46231d3ef0a2935b157cefca18a436c8b2108aba9c0d5200d5187c321ed5e53f","size":{"x":32,"y":1,"z":32}}],"schema":1}
