{"entries":[{"blockCount":13,"bytes":1063,"file":"chunks/y038-z160-x288.json","offset":{"x":288,"y":38,"z":160},"requirements":{"minecraft:oak_planks":4,"minecraft:spruce_planks":2,"minecraft:stone_bricks":7},"sha256":"c06bbb9db2524967844c14d052914d8ab5865de452a6425f73336285bc378f02","size":{"x":32,"y":1,"z":32}},{"blockCount":1,"bytes":628,"file":"chunks/y038-z160-x320.json","offset":{"x":320,"y":38,"z":160},"requirements":{"minecraft:polished_diorite":1},"sha256":"f2d042835e9410deef37dc067537bd7ed285a5f41a3efdfd751885ca420f9bed","size":{"x":32,"y":1,"z":32}},{"blockCount":7,"bytes":884,"file":"chunks/y038-z160-x352.json","offset":{"x":352,"y":38,"z":160},"requirements":{"minecraft:polished_diorite":7},"sha256":"4c985e283da5be8f852292f2afa3f091c13cbd523c68544d62855e5b5ff17125","size":{"x":32,"y":1,"z":32}},{"blockCount":89,"bytes":3168,"file":"chunks/y038-z192-x064.json","offset":{"x":64,"y":38,"z":192},"requirements":{"minecraft:bricks":16,"minecraft:glass":13,"minecraft:polished_diorite":37,"minecraft:sandstone":7,"minecraft:spruce_planks":5,"minecraft:stone_bricks":11},"sha256":"cddc0f7acf7a5d7d7d089fb898dc5c145d517d3e78a45e755932c25707126ec9","size":{"x":32,"y":1,"z":32}},{"blockCount":158,"bytes":2918,"file":"chunks/y038-z192-x096.json","offset":{"x":96,"y":38,"z":192},"requirements":{"minecraft:bricks":59,"minecraft:glass":1,"minecraft:polished_diorite":42,"minecraft:sandstone":34,"minecraft:spruce_planks":10,"minecraft:stone_bricks":12},"sha256":"4903554231c5c174b118279ea4b4ad80cc0dcad679010709f54762f7dbbb3e74","size":{"x":32,"y":1,"z":32}},{"blockCount":216,"bytes":4218,"file":"chunks/y038-z192-x128.json","offset":{"x":128,"y":38,"z":192},"requirements":{"minecraft:bricks":63,"minecraft:glass":14,"minecraft:polished_diorite":76,"minecraft:sandstone":41,"minecraft:spruce_planks":5,"minecraft:stone_bricks":17},"sha256":"ad8350f6978a0334339e5380d764a94e0ee369691718eab8643d6438b67c5fd9","size":{"x":32,"y":1,"z":32}},{"blockCount":6,"bytes":844,"file":"chunks/y038-z192-x160.json","offset":{"x":160,"y":38,"z":192},"requirements":{"minecraft:polished_diorite":6},"sha256":"07f34368bb57ec9443d3782ba12a745f2ac465e7a2d2ed22d9a5b33bf872d8a5","size":{"x":32,"y":1,"z":32}},{"blockCount":217,"bytes":4812,"file":"chunks/y039-z000-x352.json","offset":{"x":352,"y":39,"z":0},"requirements":{"minecraft:bricks":16,"minecraft:cobbled_deepslate":37,"minecraft:glass":12,"minecraft:oak_planks":18,"minecraft:polished_diorite":22,"minecraft:sandstone":31,"minecraft:spruce_planks":15,"minecraft:stone_bricks":66},"sha256":"90ffb6cc66ec98fc79853f05d8625b16f5a45d5d04760b3260c0d07655c086fd","size":{"x":32,"y":1,"z":32}},{"blockCount":534,"bytes":4630,"file":"chunks/y039-z000-x384.json","offset":{"x":384,"y":39,"z":0},"requirements":{"minecraft:bricks":4,"minecraft:cobbled_deepslate":31,"minecraft:glass":16,"minecraft:oak_planks":17,"minecraft:polished_diorite":112,"minecraft:sandstone":9,"minecraft:spruce_planks":10,"minecraft:stone_bricks":335},"sha256":"92e0f8a0ebd45b4efd592f99190037fe5980a555ac3377552ecad8f82bb5824a","size":{"x":32,"y":1,"z":32}},{"blockCount":137,"bytes":3618,"file":"chunks/y039-z032-x352.json","offset":{"x":352,"y":39,"z":32},"requirements":{"minecraft:cobbled_deepslate":16,"minecraft:glass":46,"minecraft:oak_planks":20,"minecraft:sandstone":11,"minecraft:spruce_planks":24,"minecraft:stone_bricks":20},"sha256":"e1edd40f5c7846b4a4888119b935d98df0f04bf650cb17094b899d0920801b73","size":{"x":32,"y":1,"z":32}},{"blockCount":92,"bytes":1721,"file":"chunks/y039-z032-x384.json","offset":{"x":384,"y":39,"z":32},"requirements":{"minecraft:cobbled_deepslate":1,"minecraft:glass":1,"minecraft:polished_diorite":20,"minecraft:sandstone":23,"minecraft:stone_bricks":47},"sha256":"0e840ec6eea751260c6487314442fcfbb63528b6c44a01b13d1e71b224c7b66d","size":{"x":32,"y":1,"z":32}},{"blockCount":105,"bytes":3549,"file":"chunks/y039-z064-x064.json","offset":{"x":64,"y":39,"z":64},"requirements":{"minecraft:bricks":20,"minecraft:glass":12,"minecraft:oak_planks":5,"minecraft:polished_diorite":46,"minecraft:sandstone":6,"minecraft:stone_bricks":16},"sha256":"6caff7e892331d7ae6152e8711a5f6425ee6ae3f3a643043e1ac3c03af8833b2","size":{"x":32,"y":1,"z":32}},{"blockCount":142,"bytes":3353,"file":"chunks/y039-z064-x096.json","offset":{"x":96,"y":39,"z":64},"requirements":{"minecraft:bricks":58,"minecraft:glass":1,"minecraft:oak_planks":10,"minecraft:polished_diorite":37,"minecraft:sandstone":17,"minecraft:stone_bricks":19},"sha256":"a6b90f58b262530d7f626edbdf817d495811f0279fa82917c2ff630860f470ef","size":{"x":32,"y":1,"z":32}},{"blockCount":209,"bytes":4824,"file":"chunks/y039-z064-x128.json","offset":{"x":128,"y":39,"z":64},"requirements":{"minecraft:bricks":66,"minecraft:glass":16,"minecraft:oak_planks":5,"minecraft:polished_diorite":80,"minecraft:sandstone":20,"minecraft:stone_bricks":22},"sha256":"a174d444c0868b5c04aa02a22e434053c14e99120b6a34b505623b951ae30417","size":{"x":32,"y":1,"z":32}},{"blockCount":7,"bytes":881,"file":"chunks/y039-z064-x160.json","offset":{"x":160,"y":39,"z":64},"requirements":{"minecraft:polished_diorite":7},"sha256":"61f60724fc8e82cfb620510ca86b841725dda521088091eff4707973a52727e3","size":{"x":32,"y":1,"z":32}},{"blockCount":9,"bytes":875,"file":"chunks/y039-z064-x192.json","offset":{"x":192,"y":39,"z":64},"requirements":{"minecraft:polished_diorite":9},"sha256":"8488953744f24309d68447535b3765d6cf0d52aebc84b1b2f560c370b46fcd83","size":{"x":32,"y":1,"z":32}},{"blockCount":13,"bytes":955,"file":"chunks/y039-z064-x224.json","offset":{"x":224,"y":39,"z":64},"requirements":{"minecraft:bricks":1,"minecraft:polished_diorite":12},"sha256":"05f694c3da4a658624c649930b21110641d8295287cf2e5a0d59e943d70269b0","size":{"x":32,"y":1,"z":32}},{"blockCount":4,"bytes":772,"file":"chunks/y039-z064-x288.json","offset":{"x":288,"y":39,"z":64},"requirements":{"minecraft:oak_planks":2,"minecraft:spruce_planks":1,"minecraft:stone_bricks":1},"sha256":"cc79c56bd02dd37626dc75ea7f1275649f40c2b20575aee8582ae1de8c0aaf89","size":{"x":32,"y":1,"z":32}},{"blockCount":1,"bytes":647,"file":"chunks/y039-z064-x320.json","offset":{"x":320,"y":39,"z":64},"requirements":{"minecraft:polished_diorite":1},"sha256":"e414761485440cdc9af60445ad2ee6a8948f8232eb1a3f420877615df4d9a6de","size":{"x":32,"y":1,"z":32}},{"blockCount":3,"bytes":725,"file":"chunks/y039-z064-x352.json","offset":{"x":352,"y":39,"z":64},"requirements":{"minecraft:polished_diorite":3},"sha256":"46680632c2af477aec4dffd3fd2a8bc4cf202796005efc363f930e8da4267507","size":{"x":32,"y":1,"z":32}},{"blockCount":57,"bytes":2336,"file":"chunks/y039-z096-x000.json","offset":{"x":0,"y":39,"z":96},"requirements":{"minecraft:bricks":5,"minecraft:glass":13,"minecraft:polished_diorite":28,"minecraft:sandstone":2,"minecraft:stone_bricks":9},"sha256":"bf347b93087c13886e76fae2995a590ca60c86b6399497c1d7668d5b044652b0","size":{"x":32,"y":1,"z":32}},{"blockCount":143,"bytes":3880,"file":"chunks/y039-z096-x032.json","offset":{"x":32,"y":39,"z":96},"requirements":{"minecraft:bricks":46,"minecraft:glass":25,"minecraft:polished_diorite":47,"minecraft:sandstone":14,"minecraft:stone_bricks":11},"sha256":"7a8d6cd579937918383b27680eaf17094eaa785ca07d57864b595a9ddfe59e78","size":{"x":32,"y":1,"z":32}},{"blockCount":119,"bytes":3483,"file":"chunks/y039-z096-x064.json","offset":{"x":64,"y":39,"z":96},"requirements":{"minecraft:bricks":43,"minecraft:glass":11,"minecraft:oak_planks":4,"minecraft:polished_diorite":37,"minecraft:sandstone":15,"minecraft:stone_bricks":9},"sha256":"9fb591323cc0f41c07a65b84aebdcd250eca469099facebb8b35f056689ca15e","size":{"x":32,"y":1,"z":32}},{"blockCount":32,"bytes":1434,"file":"chunks/y039-z096-x096.json","offset":{"x":96,"y":39,"z":96},"requirements":{"minecraft:bricks":22,"minecraft:sandstone":10},"sha256":"1efca12ae5c33164438accc98da15237d74e444d38a26fdfd026ca7bc098287d","size":{"x":32,"y":1,"z":32}},{"blockCount":81,"bytes":2787,"file":"chunks/y039-z096-x128.json","offset":{"x":128,"y":39,"z":96},"requirements":{"minecraft:bricks":46,"minecraft:glass":6,"minecraft:oak_planks":3,"minecraft:polished_diorite":12,"minecraft:sandstone":11,"minecraft:stone_bricks":3},"sha256":"e72f7f0fc20a02b7d1bb1f49a373790e6e110498fed4b7832dc4681840f047da","size":{"x":32,"y":1,"z":32}},{"blockCount":122,"bytes":3365,"file":"chunks/y039-z096-x160.json","offset":{"x":160,"y":39,"z":96},"requirements":{"minecraft:bricks":37,"minecraft:glass":16,"minecraft:oak_planks":1,"minecraft:polished_diorite":44,"minecraft:sandstone":13,"minecraft:stone_bricks":11},"sha256":"e83f006c345a913e59487fcffead59b4a5ecba342e5e2505e30495bb024291b3","size":{"x":32,"y":1,"z":32}},{"blockCount":250,"bytes":4670,"file":"chunks/y039-z096-x192.json","offset":{"x":192,"y":39,"z":96},"requirements":{"minecraft:bricks":155,"minecraft:glass":16,"minecraft:oak_planks":2,"minecraft:polished_diorite":39,"minecraft:sandstone":14,"minecraft:stone_bricks":24},"sha256":"28afa48cfdf84b1df7237beec5e120e81ad7b3ae4036d36d2ed9259640b2fa86","size":{"x":32,"y":1,"z":32}},{"blockCount":145,"bytes":3689,"file":"chunks/y039-z096-x224.json","offset":{"x":224,"y":39,"z":96},"requirements":{"minecraft:bricks":68,"minecraft:glass":8,"minecraft:oak_planks":5,"minecraft:polished_diorite":55,"minecraft:sandstone":5,"minecraft:stone_bricks":4},"sha256":"a82b88957409ecf712f3754884b8640b31e591aac4e7d57c421ab3334eda57ea","size":{"x":32,"y":1,"z":32}},{"blockCount":4,"bytes":773,"file":"chunks/y039-z096-x256.json","offset":{"x":256,"y":39,"z":96},"requirements":{"minecraft:oak_planks":1,"minecraft:spruce_planks":2,"minecraft:stone_bricks":1},"sha256":"9c6af8c500a03672870887eb053a566bd88eb86a0d0afed7f1120d91d6c1f530","size":{"x":32,"y":1,"z":32}},{"blockCount":4,"bytes":772,"file":"chunks/y039-z096-x288.json","offset":{"x":288,"y":39,"z":96},"requirements":{"minecraft:oak_planks":1,"minecraft:spruce_planks":1,"minecraft:stone_bricks":2},"sha256":"fe502fb8c1df485f74f9b15b22f9405a8019eba9103db48a205708d3913a1b0d","size":{"x":32,"y":1,"z":32}},{"blockCount":4,"bytes":767,"file":"chunks/y039-z096-x352.json","offset":{"x":352,"y":39,"z":96},"requirements":{"minecraft:polished_diorite":4},"sha256":"356e7d439df218d6e001206e50f7a13c54f2c83daaa9be37f107a791d9ad10ad","size":{"x":32,"y":1,"z":32}},{"blockCount":100,"bytes":3469,"file":"chunks/y039-z128-x000.json","offset":{"x":0,"y":39,"z":128},"requirements":{"minecraft:bricks":18,"minecraft:glass":23,"minecraft:polished_diorite":31,"minecraft:sandstone":6,"minecraft:stone_bricks":22},"sha256":"43510594ac94383ba6360a5ba4120272484f9ed42e4888cf7ee4e2e150ecc0d0","size":{"x":32,"y":1,"z":32}},{"blockCount":225,"bytes":4696,"file":"chunks/y039-z128-x032.json","offset":{"x":32,"y":39,"z":128},"requirements":{"minecraft:bricks":158,"minecraft:cobbled_deepslate":27,"minecraft:glass":5,"minecraft:oak_planks":15,"minecraft:sandstone":17,"minecraft:stone_bricks":3},"sha256":"5dfa96851cf4fcf5139081d1dc73bc84557024b24346092c851556716ee11ddf","size":{"x":32,"y":1,"z":32}},{"blockCount":29,"bytes":1331,"file":"chunks/y039-z128-x064.json","offset":{"x":64,"y":39,"z":128},"requirements":{"minecraft:bricks":16,"minecraft:glass":5,"minecraft:sandstone":8},"sha256":"2965a6d0b9a3b62049d3529a69687f3ed9fe3dc77897da85d96079f43d2c0068","size":{"x":32,"y":1,"z":32}},{"blockCount":38,"bytes":1283,"file":"chunks/y039-z128-x096.json","offset":{"x":96,"y":39,"z":128},"requirements":{"minecraft:bricks":23,"minecraft:glass":1,"minecraft:sandstone":6,"minecraft:stone_bricks":8},"sha256":"ba477c6ef6fa7dc1808e2f94fb62478d8f1689d4742d4dd57d2e7f7884e1e085","size":{"x":32,"y":1,"z":32}},{"blockCount":22,"bytes":1159,"file":"chunks/y039-z128-x128.json","offset":{"x":128,"y":39,"z":128},"requirements":{"minecraft:bricks":14,"minecraft:sandstone":8},"sha256":"6f09d9f1b59ef19e5307f5027dd14dbbc1a4142e242b062b4dbc3ca6159f594d","size":{"x":32,"y":1,"z":32}},{"blockCount":26,"bytes":1257,"file":"chunks/y039-z128-x160.json","offset":{"x":160,"y":39,"z":128},"requirements":{"minecraft:bricks":16,"minecraft:sandstone":10},"sha256":"a48d6749fab30ccab160083b836801758b15bf8a38dea3dbaf958655e0e840ed","size":{"x":32,"y":1,"z":32}},{"blockCount":75,"bytes":2193,"file":"chunks/y039-z128-x192.json","offset":{"x":192,"y":39,"z":128},"requirements":{"minecraft:bricks":40,"minecraft:glass":5,"minecraft:oak_planks":2,"minecraft:polished_diorite":16,"minecraft:sandstone":6,"minecraft:stone_bricks":6},"sha256":"bfc64309c85a36279a98c6cb2a34905d8016fc0c7e8cf1b13b35fcdde4db030e","size":{"x":32,"y":1,"z":32}},{"blockCount":131,"bytes":3050,"file":"chunks/y039-z128-x224.json","offset":{"x":224,"y":39,"z":128},"requirements":{"minecraft:bricks":42,"minecraft:oak_planks":10,"minecraft:polished_diorite":47,"minecraft:sandstone":11,"minecraft:stone_bricks":21},"sha256":"669f690a82c06e5b56af906be55a21a755ebcc338208f3cdebbc7749a47812c0","size":{"x":32,"y":1,"z":32}},{"blockCount":5,"bytes":791,"file":"chunks/y039-z128-x320.json","offset":{"x":320,"y":39,"z":128},"requirements":{"minecraft:polished_diorite":4,"minecraft:stone_bricks":1},"sha256":"8acb04d1caa39abad302d32acd3a804d8c24d55a071f37a4e51285f434d4f81c","size":{"x":32,"y":1,"z":32}},{"blockCount":40,"bytes":1873,"file":"chunks/y039-z160-x000.json","offset":{"x":0,"y":39,"z":160},"requirements":{"minecraft:bricks":5,"minecraft:glass":7,"minecraft:polished_diorite":20,"minecraft:sandstone":1,"minecraft:stone_bricks":7},"sha256":"aeff7e3046899204e7dff5946f53ccdd36e263ef42a89d854bf99d295f7f2188","size":{"x":32,"y":1,"z":32}},{"blockCount":100,"bytes":3056,"file":"chunks/y039-z160-x032.json","offset":{"x":32,"y":39,"z":160},"requirements":{"minecraft:bricks":17,"minecraft:glass":14,"minecraft:polished_diorite":47,"minecraft:sandstone":6,"minecraft:stone_bricks":16},"sha256":"3744d03a325d5add29ec730a1df3d30509bc794c4aab14d18835146c61e9fb6c","size":{"x":32,"y":1,"z":32}},{"blockCount":109,"bytes":3272,"file":"chunks/y039-z160-x064.json","offset":{"x":64,"y":39,"z":160},"requirements":{"minecraft:bricks":30,"minecraft:glass":9,"minecraft:oak_planks":4,"minecraft:polished_diorite":45,"minecraft:sandstone":9,"minecraft:stone_bricks":12},"sha256":"3f9f86704fab711e00b553a1a0c8a82c7657d1aaefa5aa7d757a23584e812f0b","size":{"x":32,"y":1,"z":32}},{"blockCount":25,"bytes":1308,"file":"chunks/y039-z160-x096.json","offset":{"x":96,"y":39,"z":160},"requirements":{"minecraft:bricks":16,"minecraft:sandstone":8,"minecraft:stone_bricks":1},"sha256":"6d2251abf61111586d6a642b49bbdaac7b51dc8148244cbda1703a89ccc8f29e","size":{"x":32,"y":1,"z":32}},{"blockCount":83,"bytes":2847,"file":"chunks/y039-z160-x128.json","offset":{"x":128,"y":39,"z":160},"requirements":{"minecraft:bricks":37,"minecraft:glass":3,"minecraft:oak_planks":3,"minecraft:polished_diorite":19,"minecraft:sandstone":15,"minecraft:stone_bricks":6},"sha256":"7c1c042aefc8054758dbcb8d1e2dc248a9cb3e928febc3d90c6d100443a6ddc4","size":{"x":32,"y":1,"z":32}},{"blockCount":97,"bytes":2772,"file":"chunks/y039-z160-x160.json","offset":{"x":160,"y":39,"z":160},"requirements":{"minecraft:bricks":21,"minecraft:glass":12,"minecraft:oak_planks":1,"minecraft:polished_diorite":45,"minecraft:sandstone":7,"minecraft:stone_bricks":11},"sha256":"66d6ccb48a59eb517dd926777076cc7ba9924135140ad7b727607ddf95f44f83","size":{"x":32,"y":1,"z":32}},{"blockCount":218,"bytes":4150,"file":"chunks/y039-z160-x192.json","offset":{"x":192,"y":39,"z":160},"requirements":{"minecraft:bricks":129,"minecraft:glass":11,"minecraft:polished_diorite":48,"minecraft:sandstone":8,"minecraft:stone_bricks":22},"sha256":"6dc3d8bd472a0c68db2a2e8153713faca5a5f6e1d3171d0e5dd1585889373780","size":{"x":32,"y":1,"z":32}},{"blockCount":106,"bytes":3074,"file":"chunks/y039-z160-x224.json","offset":{"x":224,"y":39,"z":160},"requirements":{"minecraft:bricks":54,"minecraft:glass":8,"minecraft:oak_planks":5,"minecraft:polished_diorite":37,"minecraft:stone_bricks":2},"sha256":"62e1ba7bca7a2016ac316ed7b319048b6da99e8961ba9b1c9dfbbc621e268002","size":{"x":32,"y":1,"z":32}},{"blockCount":4,"bytes":774,"file":"chunks/y039-z160-x256.json","offset":{"x":256,"y":39,"z":160},"requirements":{"minecraft:oak_planks":1,"minecraft:spruce_planks":2,"minecraft:stone_bricks":1},"sha256":"8f10b7ac2b5b1c5c03bf36884e2141b7d3bc8bb1ca7772e6c9812f92e106975c","size":{"x":32,"y":1,"z":32}},{"blockCount":6,"bytes":851,"file":"chunks/y039-z160-x288.json","offset":{"x":288,"y":39,"z":160},"requirements":{"minecraft:oak_planks":2,"minecraft:spruce_planks":1,"minecraft:stone_bricks":3},"sha256":"850d496aff74f03d7552115de0805acb801a9db852b504b2cbc0472e07800823","size":{"x":32,"y":1,"z":32}},{"blockCount":1,"bytes":628,"file":"chunks/y039-z160-x320.json","offset":{"x":320,"y":39,"z":160},"requirements":{"minecraft:polished_diorite":1},"sha256":"f43a8f2a6e99730fd84d8f0aa81cfaca19d677562a938a9ed4e6f182241af71c","size":{"x":32,"y":1,"z":32}},{"blockCount":7,"bytes":884,"file":"chunks/y039-z160-x352.json","offset":{"x":352,"y":39,"z":160},"requirements":{"minecraft:polished_diorite":7},"sha256":"3c9786e2b5fa658816c92d3c241d7b1544ceefe9d50214a939cf19ed0203a163","size":{"x":32,"y":1,"z":32}},{"blockCount":86,"bytes":3069,"file":"chunks/y039-z192-x064.json","offset":{"x":64,"y":39,"z":192},"requirements":{"minecraft:bricks":17,"minecraft:glass":9,"minecraft:oak_planks":5,"minecraft:polished_diorite":38,"minecraft:sandstone":4,"minecraft:stone_bricks":13},"sha256":"875e01bf076abca2ee5c1a0a9914ae3fa28a5e2efd1b55c748163b4f883ad374","size":{"x":32,"y":1,"z":32}},{"blockCount":138,"bytes":3218,"file":"chunks/y039-z192-x096.json","offset":{"x":96,"y":39,"z":192},"requirements":{"minecraft:bricks":56,"minecraft:glass":1,"minecraft:oak_planks":10,"minecraft:polished_diorite":37,"minecraft:sandstone":15,"minecraft:stone_bricks":19},"sha256":"ee6507379dd1dfab77472a4f7b89bf385bb09f3150d71e3035b0349c75e2edfd","size":{"x":32,"y":1,"z":32}},{"blockCount":187,"bytes":4288,"file":"chunks/y039-z192-x128.json","offset":{"x":128,"y":39,"z":192},"requirements":{"minecraft:bricks":61,"minecraft:glass":10,"minecraft:oak_planks":5,"minecraft:polished_diorite":73,"minecraft:sandstone":19,"minecraft:stone_bricks":19},"sha256":"a46f402eca844e87b75af90de0e7119686e50fbc0145aec88fa311fb7abe8f37","size":{"x":32,"y":1,"z":32}},{"blockCount":6,"bytes":844,"file":"chunks/y039-z192-x160.json","offset":{"x":160,"y":39,"z":192},"requirements":{"minecraft:polished_diorite":6},"sha256":"5d723d383871f15477c19c4a01983414dcc71c165aa05ba7eec85b72675b4946","size":{"x":32,"y":1,"z":32}},{"blockCount":208,"bytes":4449,"file":"chunks/y040-z000-x352.json","offset":{"x":352,"y":40,"z":0},"requirements":{"minecraft:bricks":17,"minecraft:cobbled_deepslate":54,"minecraft:glass":9,"minecraft:oak_planks":9,"minecraft:polished_diorite":11,"minecraft:sandstone":13,"minecraft:spruce_planks":48,"minecraft:stone_bricks":47},"sha256":"5b26105b84c3eb2bb98829d58dd06c655ac13d5712fb8bcce2ce5ef006e07612","size":{"x":32,"y":1,"z":32}},{"blockCount":403,"bytes":6032,"file":"chunks/y040-z000-x384.json","offset":{"x":384,"y":40,"z":0},"requirements":{"minecraft:bricks":4,"minecraft:cobbled_deepslate":34,"minecraft:glass":20,"minecraft:oak_planks":108,"minecraft:polished_diorite":25,"minecraft:sandstone":45,"minecraft:spruce_planks":23,"minecraft:stone_bricks":144},"sha256":"9c662df70979c0162485978058c8f9e2e54ed961ad1b738c58a15eaa9edd3ec3","size":{"x":32,"y":1,"z":32}},{"blockCount":107,"bytes":3280,"file":"chunks/y040-z032-x352.json","offset":{"x":352,"y":40,"z":32},"requirements":{"minecraft:cobbled_deepslate":16,"minecraft:glass":46,"minecraft:oak_planks":20,"minecraft:sandstone":3,"minecraft:spruce_planks":3,"minecraft:stone_bricks":19},"sha256":"7dc413eb565fc5a2e437cc37a1331cb783c07a338e24cb5b2cecb3c38de15299","size":{"x":32,"y":1,"z":32}},{"blockCount":94,"bytes":2313,"file":"chunks/y040-z032-x384.json","offset":{"x":384,"y":40,"z":32},"requirements":{"minecraft:cobbled_deepslate":2,"minecraft:glass":7,"minecraft:oak_planks":36,"minecraft:sandstone":18,"minecraft:spruce_planks":2,"minecraft:stone_bricks":29},"sha256":"b95f84975510360d8b35867db7395cebe79e3363a2da2fafc523274a903d06c3","size":{"x":32,"y":1,"z":32}},{"blockCount":104,"bytes":3296,"file":"chunks/y040-z064-x064.json","offset":{"x":64,"y":40,"z":64},"requirements":{"minecraft:bricks":20,"minecraft:glass":12,"minecraft:polished_diorite":45,"minecraft:sandstone":6,"minecraft:stone_bricks":21},"sha256":"09d593fbb6579f059721621b71507edfa7733347ba485ef9d45eb6d71766e4ad","size":{"x":32,"y":1,"z":32}},{"blockCount":165,"bytes":2619,"file":"chunks/y040-z064-x096.json","offset":{"x":96,"y":40,"z":64},"requirements":{"minecraft:bricks":72,"minecraft:cobbled_deepslate":1,"minecraft:glass":7,"minecraft:oak_planks":3,"minecraft:polished_diorite":40,"minecraft:sandstone":9,"minecraft:stone_bricks":33},"sha256":"6af240aa2adc25a718b8db434347dac38f5d6f383375a5dc2977ceb905750dd1","size":{"x":32,"y":1,"z":32}},{"blockCount":203,"bytes":4438,"file":"chunks/y040-z064-x128.json","offset":{"x":128,"y":40,"z":64},"requirements":{"minecraft:bricks":59,"minecraft:cobbled_deepslate":1,"minecraft:glass":19,"minecraft:oak_planks":3,"minecraft:polished_diorite":82,"minecraft:sandstone":16,"minecraft:stone_bricks":23},"sha256":"9a43d152f431390dcb5692f6ee60d6449a968d04d92b4c676cda9eb0408b4f39","size":{"x":32,"y":1,"z":32}},{"blockCount":7,"bytes":881,"file":"chunks/y040-z064-x160.json","offset":{"x":160,"y":40,"z":64},"requirements":{"minecraft:polished_diorite":7},"sha256":"73883621e5ad21487a053378b888d7c4dbb2403ade3386a484bcc81e7de767c9","size":{"x":32,"y":1,"z":32}},{"blockCount":9,"bytes":875,"file":"chunks/y040-z064-x192.json","offset":{"x":192,"y":40,"z":64},"requirements":{"minecraft:polished_diorite":9},"sha256":"3edf8ebac5f7ba60086e31a0df43b835d4125f918ae107b4bb804dced13bec4e","size":{"x":32,"y":1,"z":32}},{"blockCount":12,"bytes":915,"file":"chunks/y040-z064-x224.json","offset":{"x":224,"y":40,"z":64},"requirements":{"minecraft:polished_diorite":12},"sha256":"8b752db5da77dd95b3ec82d6bac461e54ac05bb5300185ab28e6140737fad613","size":{"x":32,"y":1,"z":32}},{"blockCount":3,"bytes":773,"file":"chunks/y040-z064-x288.json","offset":{"x":288,"y":40,"z":64},"requirements":{"minecraft:oak_planks":1,"minecraft:spruce_planks":1,"minecraft:stone_bricks":1},"sha256":"059dc3748abc6c0e9c3c182150790c8ffa9e471401390562d4816c0ab85a184b","size":{"x":32,"y":1,"z":32}},{"blockCount":1,"bytes":647,"file":"chunks/y040-z064-x320.json","offset":{"x":320,"y":40,"z":64},"requirements":{"minecraft:polished_diorite":1},"sha256":"f9635d2c6757ea9ae07ac1c701b134317db2cdf8011462ca76e76552797632ef","size":{"x":32,"y":1,"z":32}},{"blockCount":3,"bytes":725,"file":"chunks/y040-z064-x352.json","offset":{"x":352,"y":40,"z":64},"requirements":{"minecraft:polished_diorite":3},"sha256":"4944ac1f9869d4f5a2fe66bcd6df3775c68b4053aa37a17f2e994b4e17901f18","size":{"x":32,"y":1,"z":32}},{"blockCount":57,"bytes":2336,"file":"chunks/y040-z096-x000.json","offset":{"x":0,"y":40,"z":96},"requirements":{"minecraft:bricks":5,"minecraft:glass":13,"minecraft:polished_diorite":28,"minecraft:sandstone":2,"minecraft:stone_bricks":9},"sha256":"4178278c5c962283903759d69c8dcba8decc99ff522bd61a726fe38fa5b4ec87","size":{"x":32,"y":1,"z":32}},{"blockCount":147,"bytes":3828,"file":"chunks/y040-z096-x032.json","offset":{"x":32,"y":40,"z":96},"requirements":{"minecraft:bricks":27,"minecraft:glass":42,"minecraft:oak_planks":3,"minecraft:polished_diorite":47,"minecraft:sandstone":6,"minecraft:stone_bricks":22},"sha256":"f9ef844d3ca484db508cd04e2221c5d4eeb274540115d6c3c09a6db6def74377","size":{"x":32,"y":1,"z":32}},{"blockCount":114,"bytes":3175,"file":"chunks/y040-z096-x064.json","offset":{"x":64,"y":40,"z":96},"requirements":{"minecraft:bricks":34,"minecraft:glass":23,"minecraft:oak_planks":4,"minecraft:polished_diorite":37,"minecraft:sandstone":7,"minecraft:stone_bricks":9},"sha256":"715866c5caa8113db74a752debdaf02bdd919013306cf537dc53b10ad7bcbdc8","size":{"x":32,"y":1,"z":32}},{"blockCount":21,"bytes":1235,"file":"chunks/y040-z096-x096.json","offset":{"x":96,"y":40,"z":96},"requirements":{"minecraft:bricks":11,"minecraft:glass":10},"sha256":"a38caad5d9457e2d97e2e2120848afeaddadd006d9b0779b3176effc1e86b5c4","size":{"x":32,"y":1,"z":32}},{"blockCount":66,"bytes":2514,"file":"chunks/y040-z096-x128.json","offset":{"x":128,"y":40,"z":96},"requirements":{"minecraft:bricks":31,"minecraft:glass":14,"minecraft:oak_planks":3,"minecraft:polished_diorite":12,"minecraft:sandstone":3,"minecraft:stone_bricks":3},"sha256":"0734b419448052590eb73da73e2490d9ee88bfdead202abba9bcb1c3383f13f6","size":{"x":32,"y":1,"z":32}},{"blockCount":113,"bytes":3211,"file":"chunks/y040-z096-x160.json","offset":{"x":160,"y":40,"z":96},"requirements":{"minecraft:bricks":28,"minecraft:glass":22,"minecraft:oak_planks":1,"minecraft:polished_diorite":44,"minecraft:sandstone":7,"minecraft:stone_bricks":11},"sha256":"63d25025335bbcf119211b16eda70f73c4fbf0ea6f167c1c2b71bb42e87372ea","size":{"x":32,"y":1,"z":32}},{"blockCount":256,"bytes":4671,"file":"chunks/y040-z096-x192.json","offset":{"x":192,"y":40,"z":96},"requirements":{"minecraft:bricks":158,"minecraft:glass":18,"minecraft:oak_planks":2,"minecraft:polished_diorite":39,"minecraft:sandstone":12,"minecraft:stone_bricks":27},"sha256":"6365400d09a8914da411eaf79f023528aadf5ae92b16a3d78a46db0780d99e69","size":{"x":32,"y":1,"z":32}},{"blockCount":155,"bytes":3903,"file":"chunks/y040-z096-x224.json","offset":{"x":224,"y":40,"z":96},"requirements":{"minecraft:bricks":66,"minecraft:glass":9,"minecraft:oak_planks":1,"minecraft:polished_diorite":58,"minecraft:sandstone":5,"minecraft:stone_bricks":16},"sha256":"989361f494509a858e8b61e38f158ea7e19e6368eb2e5e2a3b9c62a43d0acec8","size":{"x":32,"y":1,"z":32}},{"blockCount":9,"bytes":910,"file":"chunks/y040-z096-x256.json","offset":{"x":256,"y":40,"z":96},"requirements":{"minecraft:oak_planks":3,"minecraft:spruce_planks":4,"minecraft:stone_bricks":2},"sha256":"4e262359547c4834dc5faef832bf4a64d3de786bdac774b9e2be0f7f2662bcc3","size":{"x":32,"y":1,"z":32}},{"blockCount":1,"bytes":644,"file":"chunks/y040-z096-x288.json","offset":{"x":288,"y":40,"z":96},"requirements":{"minecraft:spruce_planks":1},"sha256":"d09c39a6ce6598c1e91f3475538433038dc6ebe4a94947bad6a133ea301b942e","size":{"x":32,"y":1,"z":32}},{"blockCount":4,"bytes":767,"file":"chunks/y040-z096-x352.json","offset":{"x":352,"y":40,"z":96},"requirements":{"minecraft:polished_diorite":4},"sha256":"9c24c8e181dbc21d0c1fe58d41af130bd33acd99ebaf9625c0f85550bd38a670","size":{"x":32,"y":1,"z":32}},{"blockCount":93,"bytes":3279,"file":"chunks/y040-z128-x000.json","offset":{"x":0,"y":40,"z":128},"requirements":{"minecraft:bricks":18,"minecraft:glass":20,"minecraft:polished_diorite":31,"minecraft:sandstone":6,"minecraft:stone_bricks":18},"sha256":"bc3551a5f620a8e06423438e2479c6d4c09869260abea731cf66b5bbbd785476","size":{"x":32,"y":1,"z":32}},{"blockCount":232,"bytes":5814,"file":"chunks/y040-z128-x032.json","offset":{"x":32,"y":40,"z":128},"requirements":{"minecraft:bricks":46,"minecraft:cobbled_deepslate":45,"minecraft:glass":25,"minecraft:oak_planks":49,"minecraft:sandstone":1,"minecraft:stone_bricks":66},"sha256":"4f05eefee11ea894790a34aa5ccf5154bb39fedbc1e576db3901842097f5a139","size":{"x":32,"y":1,"z":32}},{"blockCount":26,"bytes":1078,"file":"chunks/y040-z128-x064.json","offset":{"x":64,"y":40,"z":128},"requirements":{"minecraft:bricks":9,"minecraft:glass":17},"sha256":"5982ebfa3f8b302a99f4c7fb0b9b9f31c888c450687333b901df5d0191c5b2fd","size":{"x":32,"y":1,"z":32}},{"blockCount":27,"bytes":1382,"file":"chunks/y040-z128-x096.json","offset":{"x":96,"y":40,"z":128},"requirements":{"minecraft:bricks":15,"minecraft:glass":7,"minecraft:spruce_planks":1,"minecraft:stone_bricks":4},"sha256":"36bf34b3b525a963823e1220dbe1eac6170e698af4f1c4c77b63ef2c0aeb545b","size":{"x":32,"y":1,"z":32}},{"blockCount":16,"bytes":1076,"file":"chunks/y040-z128-x128.json","offset":{"x":128,"y":40,"z":128},"requirements":{"minecraft:bricks":8,"minecraft:glass":8},"sha256":"16203a4a76a4e6bf7c18ba1263420be275f4f7a2f84a8070455177f5136e36ba","size":{"x":32,"y":1,"z":32}},{"blockCount":19,"bytes":1176,"file":"chunks/y040-z128-x160.json","offset":{"x":160,"y":40,"z":128},"requirements":{"minecraft:bricks":9,"minecraft:glass":10},"sha256":"6691734529478cb02fbdab2c4eca9309f77926e9b628ee15a0d3017ba6a96057","size":{"x":32,"y":1,"z":32}},{"blockCount":77,"bytes":2695,"file":"chunks/y040-z128-x192.json","offset":{"x":192,"y":40,"z":128},"requirements":{"minecraft:bricks":48,"minecraft:glass":7,"minecraft:oak_planks":2,"minecraft:polished_diorite":12,"minecraft:sandstone":4,"minecraft:stone_bricks":4},"sha256":"bd2e2b87d3dcb2c212a4bb8d6837188ca61354f5320a6f7f8e53e1cfd514b7da","size":{"x":32,"y":1,"z":32}},{"blockCount":156,"bytes":3476,"file":"chunks/y040-z128-x224.json","offset":{"x":224,"y":40,"z":128},"requirements":{"minecraft:bricks":49,"minecraft:glass":1,"minecraft:oak_planks":3,"minecraft:polished_diorite":58,"minecraft:sandstone":11,"minecraft:stone_bricks":34},"sha256":"2808c16f333291ef9e6abaabc8c171381ba144796923826b5729dbff9eb40d71","size":{"x":32,"y":1,"z":32}},{"blockCount":4,"bytes":764,"file":"chunks/y040-z128-x320.json","offset":{"x":320,"y":40,"z":128},"requirements":{"minecraft:polished_diorite":4},"sha256":"04bf70266662d3ede2e0bbaea2b7d4d553af1e0fd5cb0e2d4de5ad50b4a27dae","size":{"x":32,"y":1,"z":32}},{"blockCount":38,"bytes":1797,"file":"chunks/y040-z160-x000.json","offset":{"x":0,"y":40,"z":160},"requirements":{"minecraft:bricks":5,"minecraft:glass":7,"minecraft:polished_diorite":20,"minecraft:sandstone":1,"minecraft:stone_bricks":5},"sha256":"c98b0ee16880cc242145e6196a93559d4fcfadfdc0bb4b1f4b95f61ac89bf343","size":{"x":32,"y":1,"z":32}},{"blockCount":95,"bytes":2862,"file":"chunks/y040-z160-x032.json","offset":{"x":32,"y":40,"z":160},"requirements":{"minecraft:bricks":15,"minecraft:glass":14,"minecraft:polished_diorite":47,"minecraft:sandstone":6,"minecraft:stone_bricks":13},"sha256":"a13d4525a21dff066dca25c3140f46105cf966c6cafe19b30b40f5c4cc236bb5","size":{"x":32,"y":1,"z":32}},{"blockCount":107,"bytes":3194,"file":"chunks/y040-z160-x064.json","offset":{"x":64,"y":40,"z":160},"requirements":{"minecraft:bricks":28,"minecraft:glass":9,"minecraft:oak_planks":4,"minecraft:polished_diorite":45,"minecraft:sandstone":9,"minecraft:stone_bricks":12},"sha256":"a01ae7e7e4cfcd43d4c90900d94a1284a9d145e3f1ea166a18510fe50bcdb5e5","size":{"x":32,"y":1,"z":32}},{"blockCount":16,"bytes":1081,"file":"chunks/y040-z160-x096.json","offset":{"x":96,"y":40,"z":160},"requirements":{"minecraft:bricks":8,"minecraft:glass":8},"sha256":"13787b69750dfe29585056406c9ccaf6fdb40bdcbe490b2f878fcb90cbacdd3a","size":{"x":32,"y":1,"z":32}},{"blockCount":73,"bytes":2613,"file":"chunks/y040-z160-x128.json","offset":{"x":128,"y":40,"z":160},"requirements":{"minecraft:bricks":27,"minecraft:glass":11,"minecraft:oak_planks":3,"minecraft:polished_diorite":19,"minecraft:sandstone":7,"minecraft:stone_bricks":6},"sha256":"69a19373bf0948b28fc4c66c1db904db418ac70909c8c313169594034ac907b8","size":{"x":32,"y":1,"z":32}},{"blockCount":95,"bytes":2695,"file":"chunks/y040-z160-x160.json","offset":{"x":160,"y":40,"z":160},"requirements":{"minecraft:bricks":19,"minecraft:glass":12,"minecraft:oak_planks":1,"minecraft:polished_diorite":45,"minecraft:sandstone":7,"minecraft:stone_bricks":11},"sha256":"04c9cea1908eb9c210b419797d75a900896a16fc2b991ca4be076df132ad9222","size":{"x":32,"y":1,"z":32}},{"blockCount":226,"bytes":4208,"file":"chunks/y040-z160-x192.json","offset":{"x":192,"y":40,"z":160},"requirements":{"minecraft:bricks":134,"minecraft:glass":11,"minecraft:polished_diorite":48,"minecraft:sandstone":8,"minecraft:stone_bricks":25},"sha256":"31a018839ffc13913a6344f3a60c6b08249016fda37ec84a603df4e7338327f1","size":{"x":32,"y":1,"z":32}},{"blockCount":113,"bytes":3263,"file":"chunks/y040-z160-x224.json","offset":{"x":224,"y":40,"z":160},"requirements":{"minecraft:bricks":54,"minecraft:glass":8,"minecraft:polished_diorite":37,"minecraft:stone_bricks":14},"sha256":"b8da7f3c22892e907a77d9e4edff8d39e192ac756b087c07f786891f00bb379a","size":{"x":32,"y":1,"z":32}},{"blockCount":9,"bytes":911,"file":"chunks/y040-z160-x256.json","offset":{"x":256,"y":40,"z":160},"requirements":{"minecraft:oak_planks":3,"minecraft:spruce_planks":4,"minecraft:stone_bricks":2},"sha256":"0b1bff624a08af215b615568b12e126cf522772879adde605ff468e30449f783","size":{"x":32,"y":1,"z":32}},{"blockCount":6,"bytes":872,"file":"chunks/y040-z160-x288.json","offset":{"x":288,"y":40,"z":160},"requirements":{"minecraft:oak_planks":3,"minecraft:spruce_planks":2,"minecraft:stone_bricks":1},"sha256":"5fa9b69dd6e0ae9de1086d2dbac1dc0afc37d24e896a07d7c9ef2cea8fe7ba2d","size":{"x":32,"y":1,"z":32}},{"blockCount":1,"bytes":628,"file":"chunks/y040-z160-x320.json","offset":{"x":320,"y":40,"z":160},"requirements":{"minecraft:polished_diorite":1},"sha256":"4dd2ecc9baa48207dec0101a573b19e55a36aa9b6f692eda481605eccc935e97","size":{"x":32,"y":1,"z":32}},{"blockCount":7,"bytes":884,"file":"chunks/y040-z160-x352.json","offset":{"x":352,"y":40,"z":160},"requirements":{"minecraft:polished_diorite":7},"sha256":"6b7da3f01f668d6de83eb4a9b1658bc7eb703bff836c0bc00e455dd89aaeabe9","size":{"x":32,"y":1,"z":32}},{"blockCount":85,"bytes":2816,"file":"chunks/y040-z192-x064.json","offset":{"x":64,"y":40,"z":192},"requirements":{"minecraft:bricks":17,"minecraft:glass":9,"minecraft:polished_diorite":37,"minecraft:sandstone":4,"minecraft:stone_bricks":18},"sha256":"37eb309f29ddfbcba4ee5b17970595d4ae0e68522483e47cdfc321d8c3a8ad1f","size":{"x":32,"y":1,"z":32}},{"blockCount":162,"bytes":2523,"file":"chunks/y040-z192-x096.json","offset":{"x":96,"y":40,"z":192},"requirements":{"minecraft:bricks":71,"minecraft:cobbled_deepslate":1,"minecraft:glass":5,"minecraft:oak_planks":3,"minecraft:polished_diorite":40,"minecraft:sandstone":9,"minecraft:stone_bricks":33},"sha256":"6048fe211c360d0cc8a9516d83acb82c47f1e0c581bf6c9783a546ea3f2c7c9c","size":{"x":32,"y":1,"z":32}},{"blockCount":182,"bytes":3960,"file":"chunks/y040-z192-x128.json","offset":{"x":128,"y":40,"z":192},"requirements":{"minecraft:bricks":55,"minecraft:cobbled_deepslate":1,"minecraft:glass":14,"minecraft:oak_planks":3,"minecraft:polished_diorite":75,"minecraft:sandstone":14,"minecraft:stone_bricks":20},"sha256":"6521a15ddb448eaceab994b211995e3c64311927cf7324bce1a4a4ef05ac243c","size":{"x":32,"y":1,"z":32}},{"blockCount":6,"bytes":844,"file":"chunks/y040-z192-x160.json","offset":{"x":160,"y":40,"z":192},"requirements":{"minecraft:polished_diorite":6},"sha256":"c72583eb06069891bbb2295a7eb167069533b2a34ae899823b3580a5359fb4a4","size":{"x":32,"y":1,"z":32}},{"blockCount":185,"bytes":4624,"file":"chunks/y041-z000-x352.json","offset":{"x":352,"y":41,"z":0},"requirements":{"minecraft:bricks":18,"minecraft:cobbled_deepslate":2,"minecraft:glass":23,"minecraft:oak_planks":22,"minecraft:polished_diorite":22,"minecraft:sandstone":11,"minecraft:spruce_planks":62,"minecraft:stone_bricks":25},"sha256":"4463e431bb2e2ad26da9a9302b0dfbbc5339b4eb22cab5fb38a04eb7b696f1c2","size":{"x":32,"y":1,"z":32}},{"blockCount":268,"bytes":5902,"file":"chunks/y041-z000-x384.json","offset":{"x":384,"y":41,"z":0},"requirements":{"minecraft:bricks":2,"minecraft:glass":26,"minecraft:oak_planks":51,"minecraft:polished_diorite":18,"minecraft:sandstone":51,"minecraft:spruce_planks":82,"minecraft:stone_bricks":38},"sha256":"c647af953cf31482f304f0957bc638f46cb2e7af1e3029b453ae90e55bff12eb","size":{"x":32,"y":1,"z":32}},{"blockCount":5,"bytes":647,"file":"chunks/y041-z032-x064.json","offset":{"x":64,"y":41,"z":32},"requirements":{"minecraft:cobbled_deepslate":5},"sha256":"d12d2e355179253dbf5d2419e8446b989dd71540689f16ff98218a44aa99caa8","size":{"x":32,"y":1,"z":32}},{"blockCount":1,"bytes":647,"file":"chunks/y041-z032-x096.json","offset":{"x":96,"y":41,"z":32},"requirements":{"minecraft:cobbled_deepslate":1},"sha256":"f4bb1a454a510aae957009f1e63d43c637c3d38d434fdafc7adf666605b90d52","size":{"x":32,"y":1,"z":32}},{"blockCount":5,"bytes":687,"file":"chunks/y041-z032-x128.json","offset":{"x":128,"y":41,"z":32},"requirements":{"minecraft:cobbled_deepslate":5},"sha256":"041391dc245e889cededcfdddef99ed8e1d24f4f8268f675fb25f776c3cec52c","size":{"x":32,"y":1,"z":32}},{"blockCount":1,"bytes":648,"file":"chunks/y041-z032-x160.json","offset":{"x":160,"y":41,"z":32},"requirements":{"minecraft:cobbled_deepslate":1},"sha256":"129626ca1ce600e94106cc07c0e0fe75cb523b9fd2fba94f5baeb6f604909135","size":{"x":32,"y":1,"z":32}},{"blockCount":107,"bytes":3186,"file":"chunks/y041-z032-x352.json","offset":{"x":352,"y":41,"z":32},"requirements":{"minecraft:glass":46,"minecraft:oak_planks":20,"minecraft:spruce_planks":22,"minecraft:stone_bricks":19},"sha256":"12c09bc0fb62769ce7d784ca6486fd182237b75d9c3b2e9c983f58f6c9ddc7aa","size":{"x":32,"y":1,"z":32}},{"blockCount":71,"bytes":2424,"file":"chunks/y041-z032-x384.json","offset":{"x":384,"y":41,"z":32},"requirements":{"minecraft:cobbled_deepslate":1,"minecraft:glass":10,"minecraft:oak_planks":7,"minecraft:sandstone":17,"minecraft:spruce_planks":12,"minecraft:stone_bricks":24},"sha256":"5f64ec2b4b29697d89de120b35431a195ad5e8f9266d97017e6795716a4a19db","size":{"x":32,"y":1,"z":32}},{"blockCount":117,"bytes":3391,"file":"chunks/y041-z064-x064.json","offset":{"x":64,"y":41,"z":64},"requirements":{"minecraft:bricks":25,"minecraft:glass":12,"minecraft:polished_diorite":43,"minecraft:sandstone":6,"minecraft:stone_bricks":31},"sha256":"7e35e9b4ea5516f7b4e1d4e23f6775cad2484d716c0ecfb8deafef57c28cdd7a","size":{"x":32,"y":1,"z":32}},{"blockCount":160,"bytes":2867,"file":"chunks/y041-z064-x096.json","offset":{"x":96,"y":41,"z":64},"requirements":{"minecraft:bricks":63,"minecraft:cobbled_deepslate":4,"minecraft:glass":7,"minecraft:oak_planks":3,"minecraft:polished_diorite":50,"minecraft:sandstone":9,"minecraft:stone_bricks":24},"sha256":"347364e76aac19162139e27e9e476d6ccc3849e451e200009c30a66657250044","size":{"x":32,"y":1,"z":32}},{"blockCount":219,"bytes":4589,"file":"chunks/y041-z064-x128.json","offset":{"x":128,"y":41,"z":64},"requirements":{"minecraft:bricks":64,"minecraft:cobbled_deepslate":4,"minecraft:glass":19,"minecraft:oak_planks":3,"minecraft:polished_diorite":80,"minecraft:sandstone":16,"minecraft:stone_bricks":33},"sha256":"5a6f05873a38b67b2e4f3d8dc4923c076e3c5cf8f93117b3e4faab77aef38634","size":{"x":32,"y":1,"z":32}},{"blockCount":7,"bytes":881,"file":"chunks/y041-z064-x160.json","offset":{"x":160,"y":41,"z":64},"requirements":{"minecraft:polished_diorite":7},"sha256":"a40af9dd61387d2c7b9dee30979f9aaf969cdf25cc662ac227f097c88a8eb95e","size":{"x":32,"y":1,"z":32}},{"blockCount":9,"bytes":875,"file":"chunks/y041-z064-x192.json","offset":{"x":192,"y":41,"z":64},"requirements":{"minecraft:polished_diorite":9},"sha256":"8b1c4fbb1decc1afed5a968bd8cc38c59e668bb94c2a475897af7799452b5935","size":{"x":32,"y":1,"z":32}},{"blockCount":12,"bytes":915,"file":"chunks/y041-z064-x224.json","offset":{"x":224,"y":41,"z":64},"requirements":{"minecraft:polished_diorite":12},"sha256":"afea3cde2834200c9f9aa56342a8932e4893d92a7b879bb54ca5072c4b9a931c","size":{"x":32,"y":1,"z":32}},{"blockCount":4,"bytes":765,"file":"chunks/y041-z064-x288.json","offset":{"x":288,"y":41,"z":64},"requirements":{"minecraft:oak_planks":2,"minecraft:spruce_planks":2},"sha256":"73b39beb8900889caff0606ac6d91dc48af623b85370237e61d3d6f8454f47c2","size":{"x":32,"y":1,"z":32}},{"blockCount":1,"bytes":647,"file":"chunks/y041-z064-x320.json","offset":{"x":320,"y":41,"z":64},"requirements":{"minecraft:polished_diorite":1},"sha256":"fb4cb0a699529138a796f4863995a75b6bb0d13041848713101559639a09a224","size":{"x":32,"y":1,"z":32}},{"blockCount":3,"bytes":725,"file":"chunks/y041-z064-x352.json","offset":{"x":352,"y":41,"z":64},"requirements":{"minecraft:polished_diorite":3},"sha256":"ad0d55c0f869fe7e495288a82efa743fd81447116cb6efd186242136bf17533b","size":{"x":32,"y":1,"z":32}},{"blockCount":64,"bytes":2432,"file":"chunks/y041-z096-x000.json","offset":{"x":0,"y":41,"z":96},"requirements":{"minecraft:bricks":5,"minecraft:glass":12,"minecraft:polished_diorite":28,"minecraft:sandstone":3,"minecraft:stone_bricks":16},"sha256":"5c9a6b57520e02b85334188c9c2ee142e11650b1240fb7529e4c487dd3da6c03","size":{"x":32,"y":1,"z":32}},{"blockCount":140,"bytes":3796,"file":"chunks/y041-z096-x032.json","offset":{"x":32,"y":41,"z":96},"requirements":{"minecraft:bricks":31,"minecraft:glass":21,"minecraft:oak_planks":1,"minecraft:polished_diorite":46,"minecraft:sandstone":7,"minecraft:spruce_planks":11,"minecraft:stone_bricks":23},"sha256":"8685c8fbc894d3716dc419db362a71af461419838a4b5268b269a964fe5a3d9e","size":{"x":32,"y":1,"z":32}},{"blockCount":122,"bytes":3120,"file":"chunks/y041-z096-x064.json","offset":{"x":64,"y":41,"z":96},"requirements":{"minecraft:bricks":26,"minecraft:glass":14,"minecraft:polished_diorite":40,"minecraft:sandstone":7,"minecraft:spruce_planks":5,"minecraft:stone_bricks":30},"sha256":"ce8ed9b529ce3bc9da15f807995254a86104514ee8a330933112c183a50bc1b8","size":{"x":32,"y":1,"z":32}},{"blockCount":21,"bytes":1235,"file":"chunks/y041-z096-x096.json","offset":{"x":96,"y":41,"z":96},"requirements":{"minecraft:bricks":11,"minecraft:glass":10},"sha256":"8b0e5061c633480e149c12a9875098c32b0fdda1b197d78129782565c030961f","size":{"x":32,"y":1,"z":32}},{"blockCount":72,"bytes":2452,"file":"chunks/y041-z096-x128.json","offset":{"x":128,"y":41,"z":96},"requirements":{"minecraft:bricks":24,"minecraft:glass":14,"minecraft:polished_diorite":15,"minecraft:sandstone":3,"minecraft:stone_bricks":16},"sha256":"94b8d43a94d07fbfcf74f9caec57b34c649184d45dfa92d0594801f326b1bde9","size":{"x":32,"y":1,"z":32}},{"blockCount":123,"bytes":2939,"file":"chunks/y041-z096-x160.json","offset":{"x":160,"y":41,"z":96},"requirements":{"minecraft:bricks":27,"minecraft:glass":22,"minecraft:polished_diorite":43,"minecraft:sandstone":7,"minecraft:stone_bricks":24},"sha256":"6d7a729f6eec13d9d819555d44724350dcdb34c04fd557dc8e9af7edfbfb731c","size":{"x":32,"y":1,"z":32}}],"schema":1}
