{"entries":[{"blockCount":268,"bytes":4532,"file":"chunks/y041-z096-x192.json","offset":{"x":192,"y":41,"z":96},"requirements":{"minecraft:bricks":154,"minecraft:glass":18,"minecraft:polished_diorite":44,"minecraft:sandstone":13,"minecraft:stone_bricks":39},"sha256":"edf8d3c489a3cf477b5d6b0038d6d3fa78159d0b2627037509b06f6787d7ac87","size":{"x":32,"y":1,"z":32}},{"blockCount":157,"bytes":4258,"file":"chunks/y041-z096-x224.json","offset":{"x":224,"y":41,"z":96},"requirements":{"minecraft:bricks":73,"minecraft:cobbled_deepslate":5,"minecraft:glass":10,"minecraft:oak_planks":1,"minecraft:polished_diorite":54,"minecraft:sandstone":5,"minecraft:stone_bricks":9},"sha256":"e442e73dcfc3764d0607210227a617d14cd1a1fb0aed46ed70432ebc08ca61e8","size":{"x":32,"y":1,"z":32}},{"blockCount":9,"bytes":947,"file":"chunks/y041-z096-x256.json","offset":{"x":256,"y":41,"z":96},"requirements":{"minecraft:oak_planks":1,"minecraft:spruce_planks":4,"minecraft:stone_bricks":4},"sha256":"d58d3636c41a647de6f4a49d203dddb2ab5b9e74f5a50d09dba076bd4f29d3e6","size":{"x":32,"y":1,"z":32}},{"blockCount":4,"bytes":767,"file":"chunks/y041-z096-x352.json","offset":{"x":352,"y":41,"z":96},"requirements":{"minecraft:polished_diorite":4},"sha256":"998a846dec8007a04635bb55261a05078639111662f9580b18b56fbd1593f6d4","size":{"x":32,"y":1,"z":32}},{"blockCount":97,"bytes":3203,"file":"chunks/y041-z128-x000.json","offset":{"x":0,"y":41,"z":128},"requirements":{"minecraft:bricks":18,"minecraft:glass":18,"minecraft:polished_diorite":31,"minecraft:sandstone":6,"minecraft:stone_bricks":24},"sha256":"3f7e42b8588f3b1f2e51194064df8708965087f3ede662a1fbad8fad69fa9a41","size":{"x":32,"y":1,"z":32}},{"blockCount":183,"bytes":5250,"file":"chunks/y041-z128-x032.json","offset":{"x":32,"y":41,"z":128},"requirements":{"minecraft:bricks":66,"minecraft:cobbled_deepslate":45,"minecraft:glass":16,"minecraft:oak_planks":36,"minecraft:polished_diorite":2,"minecraft:sandstone":1,"minecraft:spruce_planks":5,"minecraft:stone_bricks":12},"sha256":"a52d7e08fb2b3e8eb8b85df1096de3d274cb41a3a2492c2d39f2414549db195a","size":{"x":32,"y":1,"z":32}},{"blockCount":22,"bytes":1257,"file":"chunks/y041-z128-x064.json","offset":{"x":64,"y":41,"z":128},"requirements":{"minecraft:bricks":9,"minecraft:glass":8,"minecraft:spruce_planks":5},"sha256":"67c7e484b76a3de6b6dc2ebb832463ff091b31a7b5f00a6a02b3361e250b027a","size":{"x":32,"y":1,"z":32}},{"blockCount":16,"bytes":1144,"file":"chunks/y041-z128-x096.json","offset":{"x":96,"y":41,"z":128},"requirements":{"minecraft:bricks":4,"minecraft:glass":6,"minecraft:spruce_planks":6},"sha256":"b1ac5fa71c67b1c4ebebd04cc3fd772309625671a487a5f1109fd2a4bbd09913","size":{"x":32,"y":1,"z":32}},{"blockCount":16,"bytes":1076,"file":"chunks/y041-z128-x128.json","offset":{"x":128,"y":41,"z":128},"requirements":{"minecraft:bricks":8,"minecraft:glass":8},"sha256":"37683e9ece329c89777d37d9bc2b292e8e14619ec790d14c6b643f17c84ebc8b","size":{"x":32,"y":1,"z":32}},{"blockCount":19,"bytes":1176,"file":"chunks/y041-z128-x160.json","offset":{"x":160,"y":41,"z":128},"requirements":{"minecraft:bricks":9,"minecraft:glass":10},"sha256":"90b532daf9bfd9caeab167f14b63746acbec5fc8ad19575db5a017669a523f46","size":{"x":32,"y":1,"z":32}},{"blockCount":83,"bytes":2501,"file":"chunks/y041-z128-x192.json","offset":{"x":192,"y":41,"z":128},"requirements":{"minecraft:bricks":42,"minecraft:glass":7,"minecraft:polished_diorite":10,"minecraft:sandstone":4,"minecraft:stone_bricks":20},"sha256":"03220d9e7e91666a4e4e579da572b9b4d067cc01931794f70c378795a0068ed6","size":{"x":32,"y":1,"z":32}},{"blockCount":149,"bytes":3476,"file":"chunks/y041-z128-x224.json","offset":{"x":224,"y":41,"z":128},"requirements":{"minecraft:bricks":40,"minecraft:glass":2,"minecraft:oak_planks":3,"minecraft:polished_diorite":72,"minecraft:sandstone":11,"minecraft:stone_bricks":21},"sha256":"1771c4d356dfd521f918af63f4185893a626e55ed9a42ab87ab18b9736e3c04a","size":{"x":32,"y":1,"z":32}},{"blockCount":5,"bytes":791,"file":"chunks/y041-z128-x320.json","offset":{"x":320,"y":41,"z":128},"requirements":{"minecraft:polished_diorite":4,"minecraft:stone_bricks":1},"sha256":"6facbe2d22461910c9411d4127e415175cb599abbb7c34e7505cc7a86715fd3c","size":{"x":32,"y":1,"z":32}},{"blockCount":42,"bytes":1854,"file":"chunks/y041-z160-x000.json","offset":{"x":0,"y":41,"z":160},"requirements":{"minecraft:bricks":5,"minecraft:glass":6,"minecraft:polished_diorite":20,"minecraft:sandstone":2,"minecraft:stone_bricks":9},"sha256":"26e4aa0b97853cb5921d8c9109b68749efbd745b30d63f00cfea74f4e5962c17","size":{"x":32,"y":1,"z":32}},{"blockCount":102,"bytes":2670,"file":"chunks/y041-z160-x032.json","offset":{"x":32,"y":41,"z":160},"requirements":{"minecraft:bricks":15,"minecraft:glass":13,"minecraft:polished_diorite":46,"minecraft:sandstone":7,"minecraft:stone_bricks":21},"sha256":"ec36932576b8e10ad0ba76b75d7bc379a98c2454c35a83fd055d6661e9a50506","size":{"x":32,"y":1,"z":32}},{"blockCount":121,"bytes":2997,"file":"chunks/y041-z160-x064.json","offset":{"x":64,"y":41,"z":160},"requirements":{"minecraft:bricks":20,"minecraft:glass":9,"minecraft:polished_diorite":47,"minecraft:sandstone":9,"minecraft:stone_bricks":36},"sha256":"d449323bbc139c66806b5f37279ea91e39a2f8cd654f60a628875a600d26712f","size":{"x":32,"y":1,"z":32}},{"blockCount":16,"bytes":1081,"file":"chunks/y041-z160-x096.json","offset":{"x":96,"y":41,"z":160},"requirements":{"minecraft:bricks":8,"minecraft:glass":8},"sha256":"bca69fc9e103a981eea743c39105a54b96fef64ce8b9c9b1b6e49410b41870b5","size":{"x":32,"y":1,"z":32}},{"blockCount":81,"bytes":2589,"file":"chunks/y041-z160-x128.json","offset":{"x":128,"y":41,"z":160},"requirements":{"minecraft:bricks":20,"minecraft:glass":11,"minecraft:polished_diorite":21,"minecraft:sandstone":7,"minecraft:stone_bricks":22},"sha256":"360cf91c4be089407b6c4a849174b9b945af45e599761f95cfd06d7b620914fc","size":{"x":32,"y":1,"z":32}},{"blockCount":105,"bytes":2442,"file":"chunks/y041-z160-x160.json","offset":{"x":160,"y":41,"z":160},"requirements":{"minecraft:bricks":18,"minecraft:glass":12,"minecraft:polished_diorite":44,"minecraft:sandstone":7,"minecraft:stone_bricks":24},"sha256":"c2718dc91649bd3ca4d0cc3626fbeccdeeb84ee770badc11fa727018db3e52bd","size":{"x":32,"y":1,"z":32}},{"blockCount":230,"bytes":4188,"file":"chunks/y041-z160-x192.json","offset":{"x":192,"y":41,"z":160},"requirements":{"minecraft:bricks":134,"minecraft:glass":11,"minecraft:polished_diorite":53,"minecraft:sandstone":9,"minecraft:stone_bricks":23},"sha256":"d7a37ada713e88f58cdbbfcc06572541a3284650bc8f9920a916b40b547c28ae","size":{"x":32,"y":1,"z":32}},{"blockCount":117,"bytes":3541,"file":"chunks/y041-z160-x224.json","offset":{"x":224,"y":41,"z":160},"requirements":{"minecraft:bricks":61,"minecraft:cobbled_deepslate":5,"minecraft:glass":8,"minecraft:polished_diorite":36,"minecraft:stone_bricks":7},"sha256":"0ac97901b2c3b555d127470d712fb69141fb5f33b651795b65f87dd713ae67b4","size":{"x":32,"y":1,"z":32}},{"blockCount":9,"bytes":948,"file":"chunks/y041-z160-x256.json","offset":{"x":256,"y":41,"z":160},"requirements":{"minecraft:oak_planks":1,"minecraft:spruce_planks":4,"minecraft:stone_bricks":4},"sha256":"7573925063b418569fd7df639ac90ec3d5bea3549fbbfce5438b87db57899730","size":{"x":32,"y":1,"z":32}},{"blockCount":13,"bytes":1025,"file":"chunks/y041-z160-x288.json","offset":{"x":288,"y":41,"z":160},"requirements":{"minecraft:oak_planks":5,"minecraft:spruce_planks":3,"minecraft:stone_bricks":5},"sha256":"664f02f7df54c7149af5a485b5dba6e7fe3b75088e7dc49f114cd00c28bf7545","size":{"x":32,"y":1,"z":32}},{"blockCount":1,"bytes":628,"file":"chunks/y041-z160-x320.json","offset":{"x":320,"y":41,"z":160},"requirements":{"minecraft:polished_diorite":1},"sha256":"1a0f0ddb7904ca483321a7c09ebd156a7bec4518675aa1f8411f446ef07681ce","size":{"x":32,"y":1,"z":32}},{"blockCount":7,"bytes":884,"file":"chunks/y041-z160-x352.json","offset":{"x":352,"y":41,"z":160},"requirements":{"minecraft:polished_diorite":7},"sha256":"080236c8108fb89f75915a2fbd1a97c52b8bc18eaa0502ac51e26376379d331d","size":{"x":32,"y":1,"z":32}},{"blockCount":96,"bytes":2873,"file":"chunks/y041-z192-x064.json","offset":{"x":64,"y":41,"z":192},"requirements":{"minecraft:bricks":22,"minecraft:glass":9,"minecraft:polished_diorite":36,"minecraft:sandstone":4,"minecraft:stone_bricks":25},"sha256":"9c7897e5b64ebc3e45cbf8acbd137fdab86febbfd5c2484702a5ca21815856b1","size":{"x":32,"y":1,"z":32}},{"blockCount":158,"bytes":2791,"file":"chunks/y041-z192-x096.json","offset":{"x":96,"y":41,"z":192},"requirements":{"minecraft:bricks":62,"minecraft:cobbled_deepslate":5,"minecraft:glass":5,"minecraft:oak_planks":3,"minecraft:polished_diorite":50,"minecraft:sandstone":9,"minecraft:stone_bricks":24},"sha256":"51a2cad566146fe45c24410c9ce6b0baea78aac10656cdee2b8d465fd65c200c","size":{"x":32,"y":1,"z":32}},{"blockCount":197,"bytes":4111,"file":"chunks/y041-z192-x128.json","offset":{"x":128,"y":41,"z":192},"requirements":{"minecraft:bricks":60,"minecraft:cobbled_deepslate":5,"minecraft:glass":14,"minecraft:oak_planks":3,"minecraft:polished_diorite":74,"minecraft:sandstone":14,"minecraft:stone_bricks":27},"sha256":"1cead58ad2b561f5ab361919ddfe94a4310b69e75849e5b8d94d25b7f73fae76","size":{"x":32,"y":1,"z":32}},{"blockCount":6,"bytes":844,"file":"chunks/y041-z192-x160.json","offset":{"x":160,"y":41,"z":192},"requirements":{"minecraft:polished_diorite":6},"sha256":"bfb935c92431bb427ef548b746ea09c6f1d8fffdc8d2900800433658ad0d9f1f","size":{"x":32,"y":1,"z":32}},{"blockCount":187,"bytes":4892,"file":"chunks/y042-z000-x352.json","offset":{"x":352,"y":42,"z":0},"requirements":{"minecraft:bricks":22,"minecraft:cobbled_deepslate":2,"minecraft:glass":27,"minecraft:oak_planks":9,"minecraft:polished_diorite":65,"minecraft:sandstone":16,"minecraft:spruce_planks":21,"minecraft:stone_bricks":25},"sha256":"c9003bd7efc1d5c42340126c24ca66fee8af74b1316d3093f514147269e2b1b3","size":{"x":32,"y":1,"z":32}},{"blockCount":258,"bytes":5469,"file":"chunks/y042-z000-x384.json","offset":{"x":384,"y":42,"z":0},"requirements":{"minecraft:bricks":4,"minecraft:glass":34,"minecraft:oak_planks":58,"minecraft:polished_diorite":31,"minecraft:sandstone":80,"minecraft:spruce_planks":19,"minecraft:stone_bricks":32},"sha256":"b9a84018e28073aed4155c40386b51024cc5f58a565c428934127474cfe35330","size":{"x":32,"y":1,"z":32}},{"blockCount":1,"bytes":647,"file":"chunks/y042-z032-x064.json","offset":{"x":64,"y":42,"z":32},"requirements":{"minecraft:cobbled_deepslate":1},"sha256":"203c2f353117e8ad6f3a67b871e587ad7c0dc7b62ac323cac9a806ba86513b30","size":{"x":32,"y":1,"z":32}},{"blockCount":1,"bytes":648,"file":"chunks/y042-z032-x128.json","offset":{"x":128,"y":42,"z":32},"requirements":{"minecraft:cobbled_deepslate":1},"sha256":"a47f43dd02f0bcfd5c21bdf1ba31e4d60111d47d3654010e2be7d7dd463dd12c","size":{"x":32,"y":1,"z":32}},{"blockCount":109,"bytes":3198,"file":"chunks/y042-z032-x352.json","offset":{"x":352,"y":42,"z":32},"requirements":{"minecraft:glass":46,"minecraft:oak_planks":20,"minecraft:polished_diorite":16,"minecraft:spruce_planks":9,"minecraft:stone_bricks":18},"sha256":"9366d7a8ae3628015112a87c89bcc84c4f2b139cc0a132e74eb6c648bfba9856","size":{"x":32,"y":1,"z":32}},{"blockCount":40,"bytes":1620,"file":"chunks/y042-z032-x384.json","offset":{"x":384,"y":42,"z":32},"requirements":{"minecraft:glass":11,"minecraft:oak_planks":14,"minecraft:sandstone":12,"minecraft:stone_bricks":3},"sha256":"b69dc4c5fcfd3d911812f39dfc9121317acd0ccf64031a40491d083c8af2fa1c","size":{"x":32,"y":1,"z":32}},{"blockCount":112,"bytes":3163,"file":"chunks/y042-z064-x064.json","offset":{"x":64,"y":42,"z":64},"requirements":{"minecraft:bricks":25,"minecraft:glass":12,"minecraft:polished_diorite":52,"minecraft:sandstone":6,"minecraft:stone_bricks":17},"sha256":"e7015cfb9c3047ad910ce75043ed75e8eed7410b638883d42b92ba225ba50bd3","size":{"x":32,"y":1,"z":32}},{"blockCount":148,"bytes":2794,"file":"chunks/y042-z064-x096.json","offset":{"x":96,"y":42,"z":64},"requirements":{"minecraft:bricks":57,"minecraft:glass":7,"minecraft:oak_planks":3,"minecraft:polished_diorite":46,"minecraft:sandstone":9,"minecraft:stone_bricks":26},"sha256":"6dda6bc0191e14243f31567b2ece038f279c8ec657e8c58c4df638863d0f70b0","size":{"x":32,"y":1,"z":32}},{"blockCount":206,"bytes":4387,"file":"chunks/y042-z064-x128.json","offset":{"x":128,"y":42,"z":64},"requirements":{"minecraft:bricks":62,"minecraft:glass":19,"minecraft:oak_planks":3,"minecraft:polished_diorite":83,"minecraft:sandstone":16,"minecraft:stone_bricks":23},"sha256":"769620f1e83a382975db48d80d8a2a74067ffa0f96ce2b4721f6784514e38a51","size":{"x":32,"y":1,"z":32}},{"blockCount":7,"bytes":881,"file":"chunks/y042-z064-x160.json","offset":{"x":160,"y":42,"z":64},"requirements":{"minecraft:polished_diorite":7},"sha256":"21eb0a7796a69ecf137581b50005113485926a52e8420a2f2cadd270e0a6b58c","size":{"x":32,"y":1,"z":32}},{"blockCount":9,"bytes":875,"file":"chunks/y042-z064-x192.json","offset":{"x":192,"y":42,"z":64},"requirements":{"minecraft:polished_diorite":9},"sha256":"a8b5917adf127755d362f666f2469108a6286a09a6646ff373fdf88fc9a61a81","size":{"x":32,"y":1,"z":32}},{"blockCount":12,"bytes":915,"file":"chunks/y042-z064-x224.json","offset":{"x":224,"y":42,"z":64},"requirements":{"minecraft:polished_diorite":12},"sha256":"5a0eb621f2a41a762abd344125a07384bcf55e85fb80b20d9852796473677f8b","size":{"x":32,"y":1,"z":32}},{"blockCount":6,"bytes":831,"file":"chunks/y042-z064-x288.json","offset":{"x":288,"y":42,"z":64},"requirements":{"minecraft:oak_planks":2,"minecraft:spruce_planks":2,"minecraft:stone_bricks":2},"sha256":"9133351d146c6c5ef030cc9cddd0d30ade8dd292c9df1d9cb5ef21bd83cc5771","size":{"x":32,"y":1,"z":32}},{"blockCount":1,"bytes":647,"file":"chunks/y042-z064-x320.json","offset":{"x":320,"y":42,"z":64},"requirements":{"minecraft:polished_diorite":1},"sha256":"b6c3c349150499b61445806305fb2f8801ba7e4f2d5fa1e817e42769273ab670","size":{"x":32,"y":1,"z":32}},{"blockCount":3,"bytes":725,"file":"chunks/y042-z064-x352.json","offset":{"x":352,"y":42,"z":64},"requirements":{"minecraft:polished_diorite":3},"sha256":"e9eca77c1efc1e47b3bee08bf4a270a55fb661d6fe6cd8d3d9d8d0305bbf7e2e","size":{"x":32,"y":1,"z":32}},{"blockCount":57,"bytes":2336,"file":"chunks/y042-z096-x000.json","offset":{"x":0,"y":42,"z":96},"requirements":{"minecraft:bricks":5,"minecraft:glass":13,"minecraft:polished_diorite":28,"minecraft:sandstone":2,"minecraft:stone_bricks":9},"sha256":"429e5ef8e99e63e1deb29229f2f1eb5cd0f1040b216cd0991e89cd6c4833745d","size":{"x":32,"y":1,"z":32}},{"blockCount":144,"bytes":4059,"file":"chunks/y042-z096-x032.json","offset":{"x":32,"y":42,"z":96},"requirements":{"minecraft:bricks":37,"minecraft:glass":33,"minecraft:polished_diorite":47,"minecraft:sandstone":6,"minecraft:spruce_planks":9,"minecraft:stone_bricks":12},"sha256":"0efe1682ce8ab7b17528991466380709469c0abfb1a0db24b68cd2b3f0fd4eb4","size":{"x":32,"y":1,"z":32}},{"blockCount":120,"bytes":3272,"file":"chunks/y042-z096-x064.json","offset":{"x":64,"y":42,"z":96},"requirements":{"minecraft:bricks":26,"minecraft:glass":19,"minecraft:polished_diorite":41,"minecraft:sandstone":7,"minecraft:spruce_planks":4,"minecraft:stone_bricks":23},"sha256":"ffaaabdd8c11e9216c38a8692144a5ef0d50509721bdb253aba219627478e402","size":{"x":32,"y":1,"z":32}},{"blockCount":21,"bytes":1235,"file":"chunks/y042-z096-x096.json","offset":{"x":96,"y":42,"z":96},"requirements":{"minecraft:bricks":11,"minecraft:glass":10},"sha256":"0e61597513558c48b66acb5bf62589c8e2e0918e0bb423b42f4a2b003276a378","size":{"x":32,"y":1,"z":32}},{"blockCount":70,"bytes":2452,"file":"chunks/y042-z096-x128.json","offset":{"x":128,"y":42,"z":96},"requirements":{"minecraft:bricks":24,"minecraft:glass":14,"minecraft:polished_diorite":15,"minecraft:sandstone":3,"minecraft:stone_bricks":14},"sha256":"a45ea1ff61cd46b16ad50ac76512691ff7d2447555a38dbfaec96fc7684c818e","size":{"x":32,"y":1,"z":32}},{"blockCount":115,"bytes":3167,"file":"chunks/y042-z096-x160.json","offset":{"x":160,"y":42,"z":96},"requirements":{"minecraft:bricks":27,"minecraft:glass":22,"minecraft:polished_diorite":45,"minecraft:sandstone":7,"minecraft:stone_bricks":14},"sha256":"63ef6c42e46e3400740ce16660b63dab2bbab832d584becd756c7f43bbb7f35c","size":{"x":32,"y":1,"z":32}},{"blockCount":269,"bytes":4740,"file":"chunks/y042-z096-x192.json","offset":{"x":192,"y":42,"z":96},"requirements":{"minecraft:bricks":158,"minecraft:glass":18,"minecraft:polished_diorite":45,"minecraft:sandstone":13,"minecraft:stone_bricks":35},"sha256":"11e3a297de6b7996b5592df0e63a326b348a0667d0a871d3a2eac9b0ef248a76","size":{"x":32,"y":1,"z":32}},{"blockCount":158,"bytes":4162,"file":"chunks/y042-z096-x224.json","offset":{"x":224,"y":42,"z":96},"requirements":{"minecraft:bricks":75,"minecraft:cobbled_deepslate":2,"minecraft:glass":9,"minecraft:oak_planks":1,"minecraft:polished_diorite":59,"minecraft:sandstone":5,"minecraft:stone_bricks":7},"sha256":"afa8d34f5c1b98f0ae6a81c8bc91063fecc93658c7555d6666155dc745139cf2","size":{"x":32,"y":1,"z":32}},{"blockCount":10,"bytes":806,"file":"chunks/y042-z096-x256.json","offset":{"x":256,"y":42,"z":96},"requirements":{"minecraft:spruce_planks":6,"minecraft:stone_bricks":4},"sha256":"7d78be49a51ea8648a3e8c632c7d807fea9e1904dd41974581c92701a640c744","size":{"x":32,"y":1,"z":32}},{"blockCount":1,"bytes":643,"file":"chunks/y042-z096-x288.json","offset":{"x":288,"y":42,"z":96},"requirements":{"minecraft:stone_bricks":1},"sha256":"9f7b72ee1d13f6181137412323b56a0d60f828be372d9521baf9790f8ec2c5d8","size":{"x":32,"y":1,"z":32}},{"blockCount":4,"bytes":767,"file":"chunks/y042-z096-x352.json","offset":{"x":352,"y":42,"z":96},"requirements":{"minecraft:polished_diorite":4},"sha256":"95ccebe00734dd00ad9649e62ec28e3d318fb2cf71e38a5c69f199bd605eabca","size":{"x":32,"y":1,"z":32}},{"blockCount":86,"bytes":3013,"file":"chunks/y042-z128-x000.json","offset":{"x":0,"y":42,"z":128},"requirements":{"minecraft:bricks":18,"minecraft:glass":18,"minecraft:polished_diorite":31,"minecraft:sandstone":6,"minecraft:stone_bricks":13},"sha256":"12977bb80ee93d0fafdfd0e534a4cedbb876a725c44f8aeaa68552a4f9803018","size":{"x":32,"y":1,"z":32}},{"blockCount":192,"bytes":5352,"file":"chunks/y042-z128-x032.json","offset":{"x":32,"y":42,"z":128},"requirements":{"minecraft:bricks":76,"minecraft:cobbled_deepslate":40,"minecraft:glass":21,"minecraft:oak_planks":36,"minecraft:sandstone":5,"minecraft:spruce_planks":4,"minecraft:stone_bricks":10},"sha256":"0654cad1586583c34956acade5727a2c7c64317325204a5cfb75f9a6edfb3345","size":{"x":32,"y":1,"z":32}},{"blockCount":26,"bytes":1258,"file":"chunks/y042-z128-x064.json","offset":{"x":64,"y":42,"z":128},"requirements":{"minecraft:bricks":9,"minecraft:glass":13,"minecraft:spruce_planks":4},"sha256":"c4735a6383293af84bd45234ded3cfd938361d413d701433eadcec8326165819","size":{"x":32,"y":1,"z":32}},{"blockCount":14,"bytes":1079,"file":"chunks/y042-z128-x096.json","offset":{"x":96,"y":42,"z":128},"requirements":{"minecraft:bricks":4,"minecraft:glass":10},"sha256":"c6518a396d7c4e57405cd74e3edc52830413fba0b5370546a9052954418b1f62","size":{"x":32,"y":1,"z":32}},{"blockCount":16,"bytes":1076,"file":"chunks/y042-z128-x128.json","offset":{"x":128,"y":42,"z":128},"requirements":{"minecraft:bricks":8,"minecraft:glass":8},"sha256":"c3215d2543f831018c979ea4503255b2c9567dba389357077736b9c79123c3be","size":{"x":32,"y":1,"z":32}},{"blockCount":19,"bytes":1176,"file":"chunks/y042-z128-x160.json","offset":{"x":160,"y":42,"z":128},"requirements":{"minecraft:bricks":9,"minecraft:glass":10},"sha256":"27122d77f66f38d217d752637f9faba86ba333153a823cda75bc67a1e8b674fe","size":{"x":32,"y":1,"z":32}},{"blockCount":100,"bytes":2923,"file":"chunks/y042-z128-x192.json","offset":{"x":192,"y":42,"z":128},"requirements":{"minecraft:bricks":42,"minecraft:glass":7,"minecraft:polished_diorite":28,"minecraft:sandstone":6,"minecraft:stone_bricks":17},"sha256":"950eecf0bca5fa98d3ae5ed1372b6a84e8cf50ebaac01934e51ea5bf924ee74f","size":{"x":32,"y":1,"z":32}},{"blockCount":136,"bytes":3717,"file":"chunks/y042-z128-x224.json","offset":{"x":224,"y":42,"z":128},"requirements":{"minecraft:bricks":32,"minecraft:cobbled_deepslate":1,"minecraft:glass":1,"minecraft:oak_planks":3,"minecraft:polished_diorite":60,"minecraft:sandstone":11,"minecraft:stone_bricks":28},"sha256":"28cf8447304d4df6ee45a6787ed25351a6b8ed63b9cbb9fb8f5433b1d291deb0","size":{"x":32,"y":1,"z":32}},{"blockCount":4,"bytes":764,"file":"chunks/y042-z128-x320.json","offset":{"x":320,"y":42,"z":128},"requirements":{"minecraft:polished_diorite":4},"sha256":"5f4007a663c60738850b7739df61cd2be0b3f30c8dc31d5ab8d9526e29e8d440","size":{"x":32,"y":1,"z":32}},{"blockCount":38,"bytes":1797,"file":"chunks/y042-z160-x000.json","offset":{"x":0,"y":42,"z":160},"requirements":{"minecraft:bricks":5,"minecraft:glass":7,"minecraft:polished_diorite":20,"minecraft:sandstone":1,"minecraft:stone_bricks":5},"sha256":"837c7b3a28f8a98ce9dca67df15014858fd5e5a4ea3e01a45396f99d93f108a5","size":{"x":32,"y":1,"z":32}},{"blockCount":93,"bytes":2784,"file":"chunks/y042-z160-x032.json","offset":{"x":32,"y":42,"z":160},"requirements":{"minecraft:bricks":15,"minecraft:glass":14,"minecraft:polished_diorite":47,"minecraft:sandstone":6,"minecraft:stone_bricks":11},"sha256":"c171f4a9a48ecf3ba012b9477bc99f38412149d655009b309e34d015a8bd00b7","size":{"x":32,"y":1,"z":32}},{"blockCount":113,"bytes":3111,"file":"chunks/y042-z160-x064.json","offset":{"x":64,"y":42,"z":160},"requirements":{"minecraft:bricks":20,"minecraft:glass":9,"minecraft:polished_diorite":49,"minecraft:sandstone":9,"minecraft:stone_bricks":26},"sha256":"4712c23884eafb828a053c9c74d64b17da8f42ebe3d53f0eb30845bb54ff1612","size":{"x":32,"y":1,"z":32}},{"blockCount":16,"bytes":1081,"file":"chunks/y042-z160-x096.json","offset":{"x":96,"y":42,"z":160},"requirements":{"minecraft:bricks":8,"minecraft:glass":8},"sha256":"c934c5ba130193c3a1238ab3c957a7d192ee51e92a9d735efecfff45243027bd","size":{"x":32,"y":1,"z":32}},{"blockCount":77,"bytes":2551,"file":"chunks/y042-z160-x128.json","offset":{"x":128,"y":42,"z":160},"requirements":{"minecraft:bricks":20,"minecraft:glass":11,"minecraft:polished_diorite":22,"minecraft:sandstone":7,"minecraft:stone_bricks":17},"sha256":"653d708f0d01f3b2659ed1e4b739e6a9021b43041003b9fbe8388f38b4257b55","size":{"x":32,"y":1,"z":32}},{"blockCount":97,"bytes":2670,"file":"chunks/y042-z160-x160.json","offset":{"x":160,"y":42,"z":160},"requirements":{"minecraft:bricks":18,"minecraft:glass":12,"minecraft:polished_diorite":46,"minecraft:sandstone":7,"minecraft:stone_bricks":14},"sha256":"cb51e93fc8cac08b923470e45fe16e82969836765e590fb33c16c8a9ca275986","size":{"x":32,"y":1,"z":32}},{"blockCount":232,"bytes":4359,"file":"chunks/y042-z160-x192.json","offset":{"x":192,"y":42,"z":160},"requirements":{"minecraft:bricks":138,"minecraft:glass":11,"minecraft:polished_diorite":54,"minecraft:sandstone":9,"minecraft:stone_bricks":20},"sha256":"889b52fca8d5ae821ca65e78488b6c6626dd7385e7ad0617d613b611b7e8a11b","size":{"x":32,"y":1,"z":32}},{"blockCount":118,"bytes":3446,"file":"chunks/y042-z160-x224.json","offset":{"x":224,"y":42,"z":160},"requirements":{"minecraft:bricks":63,"minecraft:cobbled_deepslate":1,"minecraft:glass":8,"minecraft:polished_diorite":41,"minecraft:stone_bricks":5},"sha256":"46c8f3d61827c1557c4bc3b665a36ce63816af53263d2410eb8c7d635a341b2e","size":{"x":32,"y":1,"z":32}},{"blockCount":10,"bytes":807,"file":"chunks/y042-z160-x256.json","offset":{"x":256,"y":42,"z":160},"requirements":{"minecraft:spruce_planks":6,"minecraft:stone_bricks":4},"sha256":"ab15161c3aa0e1bfc016cd32d51e5abbc2f684ec0bc0bd0fd8ee6c142dd1a8a8","size":{"x":32,"y":1,"z":32}},{"blockCount":7,"bytes":909,"file":"chunks/y042-z160-x288.json","offset":{"x":288,"y":42,"z":160},"requirements":{"minecraft:oak_planks":2,"minecraft:spruce_planks":1,"minecraft:stone_bricks":4},"sha256":"ba778e92fbdb5e0a3f2d766b4c2537c66c6c2ee8e597a942eaba56b398f1a0ce","size":{"x":32,"y":1,"z":32}},{"blockCount":3,"bytes":666,"file":"chunks/y042-z160-x320.json","offset":{"x":320,"y":42,"z":160},"requirements":{"minecraft:polished_diorite":3},"sha256":"96f5253930b9ce95f92d0c43b2264bb4b37c0ff7671a4c8dae7247c97c23ca47","size":{"x":32,"y":1,"z":32}},{"blockCount":8,"bytes":923,"file":"chunks/y042-z160-x352.json","offset":{"x":352,"y":42,"z":160},"requirements":{"minecraft:polished_diorite":8},"sha256":"a1e16de0caa9151ded360a0b86db5c2ee9b35df31df68948d11b609fcb53dd92","size":{"x":32,"y":1,"z":32}},{"blockCount":93,"bytes":2683,"file":"chunks/y042-z192-x064.json","offset":{"x":64,"y":42,"z":192},"requirements":{"minecraft:bricks":22,"minecraft:glass":9,"minecraft:polished_diorite":44,"minecraft:sandstone":4,"minecraft:stone_bricks":14},"sha256":"50a7039b6bc1af22d227675908d416dff85372bf235a751f32ccd95ffced7707","size":{"x":32,"y":1,"z":32}},{"blockCount":145,"bytes":2698,"file":"chunks/y042-z192-x096.json","offset":{"x":96,"y":42,"z":192},"requirements":{"minecraft:bricks":56,"minecraft:glass":5,"minecraft:oak_planks":3,"minecraft:polished_diorite":46,"minecraft:sandstone":9,"minecraft:stone_bricks":26},"sha256":"1d28740267ed9056ca2475da7ec0702b0e916b41af3512a5fa0f7645012ddf1c","size":{"x":32,"y":1,"z":32}},{"blockCount":185,"bytes":3890,"file":"chunks/y042-z192-x128.json","offset":{"x":128,"y":42,"z":192},"requirements":{"minecraft:bricks":58,"minecraft:glass":14,"minecraft:oak_planks":3,"minecraft:polished_diorite":76,"minecraft:sandstone":14,"minecraft:stone_bricks":20},"sha256":"499edb6ee212120303436865ff4bca0328bd4c65b0f12d409b488b2c58e0a924","size":{"x":32,"y":1,"z":32}},{"blockCount":6,"bytes":844,"file":"chunks/y042-z192-x160.json","offset":{"x":160,"y":42,"z":192},"requirements":{"minecraft:polished_diorite":6},"sha256":"e1eae840c617bef9a5192ff2b39ab53afa372c8c9b0d1ba80266dca636ab99ad","size":{"x":32,"y":1,"z":32}},{"blockCount":1,"bytes":647,"file":"chunks/y042-z192-x320.json","offset":{"x":320,"y":42,"z":192},"requirements":{"minecraft:polished_diorite":1},"sha256":"f1bbaa6bef65e9defccec0631cca1640e757c85fc662ef308447ef941ab847d2","size":{"x":32,"y":1,"z":32}},{"blockCount":186,"bytes":4892,"file":"chunks/y043-z000-x352.json","offset":{"x":352,"y":43,"z":0},"requirements":{"minecraft:bricks":20,"minecraft:cobbled_deepslate":2,"minecraft:glass":23,"minecraft:oak_planks":20,"minecraft:polished_diorite":63,"minecraft:sandstone":17,"minecraft:spruce_planks":14,"minecraft:stone_bricks":27},"sha256":"0306c852e461f3b36cc1c6037dec841ebcb638e4dd4553a173af1ae886da4c58","size":{"x":32,"y":1,"z":32}},{"blockCount":242,"bytes":4945,"file":"chunks/y043-z000-x384.json","offset":{"x":384,"y":43,"z":0},"requirements":{"minecraft:bricks":4,"minecraft:glass":26,"minecraft:oak_planks":36,"minecraft:polished_diorite":32,"minecraft:sandstone":85,"minecraft:spruce_planks":6,"minecraft:stone_bricks":53},"sha256":"15b4269518db6f649541952586d992b910418a83a403aa3dfa1593915405ae33","size":{"x":32,"y":1,"z":32}},{"blockCount":8,"bytes":897,"file":"chunks/y043-z032-x064.json","offset":{"x":64,"y":43,"z":32},"requirements":{"minecraft:cobbled_deepslate":2,"minecraft:glass":6},"sha256":"b1df2a00ae4488cee574cfc78e2c91522d82f673bf1e8c7a827784acc8bcdc75","size":{"x":32,"y":1,"z":32}},{"blockCount":1,"bytes":647,"file":"chunks/y043-z032-x096.json","offset":{"x":96,"y":43,"z":32},"requirements":{"minecraft:cobbled_deepslate":1},"sha256":"9b569014d852d5d2a9423c22c611c2eb227d8b8cf027496fc5d698944e7cfe84","size":{"x":32,"y":1,"z":32}},{"blockCount":5,"bytes":804,"file":"chunks/y043-z032-x128.json","offset":{"x":128,"y":43,"z":32},"requirements":{"minecraft:cobbled_deepslate":2,"minecraft:glass":3},"sha256":"0034630727070db9ef2995dee9a5e9864898dfdf81c8913885b7c84633d5eb66","size":{"x":32,"y":1,"z":32}},{"blockCount":4,"bytes":765,"file":"chunks/y043-z032-x160.json","offset":{"x":160,"y":43,"z":32},"requirements":{"minecraft:cobbled_deepslate":1,"minecraft:glass":3},"sha256":"72b5e402c14915acda633b72bdc652f67e245f80e7ed0f93ebb26afce8d2fb05","size":{"x":32,"y":1,"z":32}},{"blockCount":106,"bytes":3198,"file":"chunks/y043-z032-x352.json","offset":{"x":352,"y":43,"z":32},"requirements":{"minecraft:glass":49,"minecraft:oak_planks":20,"minecraft:polished_diorite":16,"minecraft:spruce_planks":3,"minecraft:stone_bricks":18},"sha256":"cef08a9550c1287661bf10c741ddd4abcefdebb9f18fbf06652e277c89043ce0","size":{"x":32,"y":1,"z":32}},{"blockCount":41,"bytes":1492,"file":"chunks/y043-z032-x384.json","offset":{"x":384,"y":43,"z":32},"requirements":{"minecraft:glass":7,"minecraft:oak_planks":7,"minecraft:polished_diorite":9,"minecraft:sandstone":12,"minecraft:stone_bricks":6},"sha256":"750d5046b4dc5ac28e38d1c6cea8e778e5819b0897adb9a7ad81b65b0cfb23cb","size":{"x":32,"y":1,"z":32}},{"blockCount":111,"bytes":3315,"file":"chunks/y043-z064-x064.json","offset":{"x":64,"y":43,"z":64},"requirements":{"minecraft:bricks":25,"minecraft:glass":12,"minecraft:polished_diorite":50,"minecraft:sandstone":6,"minecraft:stone_bricks":18},"sha256":"9cfb68a093b971dd46a9dfcdb46234ec7bcb9ad3423a90a2b237b717abf256c0","size":{"x":32,"y":1,"z":32}},{"blockCount":180,"bytes":2944,"file":"chunks/y043-z064-x096.json","offset":{"x":96,"y":43,"z":64},"requirements":{"minecraft:bricks":67,"minecraft:cobbled_deepslate":4,"minecraft:glass":7,"minecraft:oak_planks":3,"minecraft:polished_diorite":63,"minecraft:sandstone":9,"minecraft:stone_bricks":27},"sha256":"ddf9e079c9fde5449885a30609694d4dcc0e37bf913b7d0d4a43a2f87161d02d","size":{"x":32,"y":1,"z":32}},{"blockCount":209,"bytes":4532,"file":"chunks/y043-z064-x128.json","offset":{"x":128,"y":43,"z":64},"requirements":{"minecraft:bricks":62,"minecraft:cobbled_deepslate":4,"minecraft:glass":19,"minecraft:oak_planks":3,"minecraft:polished_diorite":85,"minecraft:sandstone":16,"minecraft:stone_bricks":20},"sha256":"c1a7fc9b51e6ed78ceec08adc5cf17ebcaacc3eab84d2c333855936bb25b256f","size":{"x":32,"y":1,"z":32}},{"blockCount":7,"bytes":881,"file":"chunks/y043-z064-x160.json","offset":{"x":160,"y":43,"z":64},"requirements":{"minecraft:polished_diorite":7},"sha256":"c2a0893a9a11ccd141e37af74ac1f3b0b9824243c7748af80d9a36eb07fa7e42","size":{"x":32,"y":1,"z":32}},{"blockCount":9,"bytes":875,"file":"chunks/y043-z064-x192.json","offset":{"x":192,"y":43,"z":64},"requirements":{"minecraft:polished_diorite":9},"sha256":"e076def9415297125b9fb547c0b4bc902a435bfbca2dcd7fc69fde107372f330","size":{"x":32,"y":1,"z":32}},{"blockCount":12,"bytes":915,"file":"chunks/y043-z064-x224.json","offset":{"x":224,"y":43,"z":64},"requirements":{"minecraft:polished_diorite":12},"sha256":"fa414a712ef0c775d2b3e2c961a730288bbd339a7061ad489fb531c4e7c8b3b9","size":{"x":32,"y":1,"z":32}},{"blockCount":8,"bytes":849,"file":"chunks/y043-z064-x288.json","offset":{"x":288,"y":43,"z":64},"requirements":{"minecraft:oak_planks":3,"minecraft:spruce_planks":1,"minecraft:stone_bricks":4},"sha256":"9a811e525dc736f13edbb1d8fa452bf37d7196f79c7cde62a83b37be8b94e216","size":{"x":32,"y":1,"z":32}},{"blockCount":4,"bytes":771,"file":"chunks/y043-z064-x320.json","offset":{"x":320,"y":43,"z":64},"requirements":{"minecraft:polished_diorite":3,"minecraft:stone_bricks":1},"sha256":"d970ad8ac7e26add18142b918eed33130ed1df231b9cd0a34003a99be12913ba","size":{"x":32,"y":1,"z":32}},{"blockCount":15,"bytes":1098,"file":"chunks/y043-z064-x352.json","offset":{"x":352,"y":43,"z":64},"requirements":{"minecraft:polished_diorite":12,"minecraft:stone_bricks":3},"sha256":"dd2987111d494bf69f8059a2a4276bf51670d13944bf964a6b79919d6d66b548","size":{"x":32,"y":1,"z":32}},{"blockCount":57,"bytes":2336,"file":"chunks/y043-z096-x000.json","offset":{"x":0,"y":43,"z":96},"requirements":{"minecraft:bricks":5,"minecraft:glass":13,"minecraft:polished_diorite":28,"minecraft:sandstone":2,"minecraft:stone_bricks":9},"sha256":"13a52484bd80ced4db809485e6ff83858f5b1aaeffe1d3b756326eccb470fcec","size":{"x":32,"y":1,"z":32}},{"blockCount":131,"bytes":3861,"file":"chunks/y043-z096-x032.json","offset":{"x":32,"y":43,"z":96},"requirements":{"minecraft:bricks":35,"minecraft:glass":31,"minecraft:oak_planks":1,"minecraft:polished_diorite":47,"minecraft:sandstone":6,"minecraft:stone_bricks":11},"sha256":"65c8da135b0acd238c386c0431d2690db70daff125163e561c37ba029eedc7a1","size":{"x":32,"y":1,"z":32}},{"blockCount":108,"bytes":3347,"file":"chunks/y043-z096-x064.json","offset":{"x":64,"y":43,"z":96},"requirements":{"minecraft:bricks":29,"minecraft:glass":18,"minecraft:oak_planks":4,"minecraft:polished_diorite":37,"minecraft:sandstone":9,"minecraft:stone_bricks":11},"sha256":"b6ac52338d5ddd784ac0966faaf182ab312d58ac0a3e732b3b2e7403f2eece6b","size":{"x":32,"y":1,"z":32}},{"blockCount":21,"bytes":1235,"file":"chunks/y043-z096-x096.json","offset":{"x":96,"y":43,"z":96},"requirements":{"minecraft:bricks":11,"minecraft:glass":10},"sha256":"469a735654294f89c338c78a8088ce9aa0898a6599d7aa2e34f35962b7555e26","size":{"x":32,"y":1,"z":32}},{"blockCount":66,"bytes":2533,"file":"chunks/y043-z096-x128.json","offset":{"x":128,"y":43,"z":96},"requirements":{"minecraft:bricks":27,"minecraft:glass":14,"minecraft:oak_planks":3,"minecraft:polished_diorite":12,"minecraft:sandstone":5,"minecraft:stone_bricks":5},"sha256":"12ab931acf66df6f0d9865b597eebde8621015c6270852a8df4b4a028615d7a6","size":{"x":32,"y":1,"z":32}},{"blockCount":113,"bytes":3211,"file":"chunks/y043-z096-x160.json","offset":{"x":160,"y":43,"z":96},"requirements":{"minecraft:bricks":28,"minecraft:glass":22,"minecraft:oak_planks":1,"minecraft:polished_diorite":44,"minecraft:sandstone":7,"minecraft:stone_bricks":11},"sha256":"026528901b0f78c24f995b14b1d2af02fcf9fb1de755206c0afaf5aedd2f90b7","size":{"x":32,"y":1,"z":32}},{"blockCount":255,"bytes":4880,"file":"chunks/y043-z096-x192.json","offset":{"x":192,"y":43,"z":96},"requirements":{"minecraft:bricks":158,"minecraft:glass":19,"minecraft:oak_planks":2,"minecraft:polished_diorite":39,"minecraft:sandstone":11,"minecraft:stone_bricks":26},"sha256":"dc6d15e9eb77fe451f379452658dbd3d06c9d0a28038fa10562965b15f5e1221","size":{"x":32,"y":1,"z":32}},{"blockCount":161,"bytes":4296,"file":"chunks/y043-z096-x224.json","offset":{"x":224,"y":43,"z":96},"requirements":{"minecraft:bricks":69,"minecraft:cobbled_deepslate":6,"minecraft:glass":15,"minecraft:oak_planks":1,"minecraft:polished_diorite":61,"minecraft:sandstone":5,"minecraft:stone_bricks":4},"sha256":"a10369c4a82be87f21be610051b3cbb8ff1fb06ceaca03220dfc02b0242f1a08","size":{"x":32,"y":1,"z":32}},{"blockCount":7,"bytes":830,"file":"chunks/y043-z096-x256.json","offset":{"x":256,"y":43,"z":96},"requirements":{"minecraft:oak_planks":1,"minecraft:spruce_planks":4,"minecraft:stone_bricks":2},"sha256":"229693977c4020a0fe62ef9c8193a0398dca9a99112aa3487443020abf294357","size":{"x":32,"y":1,"z":32}},{"blockCount":2,"bytes":686,"file":"chunks/y043-z096-x288.json","offset":{"x":288,"y":43,"z":96},"requirements":{"minecraft:oak_planks":1,"minecraft:stone_bricks":1},"sha256":"384585269204544df9ac67cffe2641648c119e3bef7a6ec65ef648913be51f40","size":{"x":32,"y":1,"z":32}},{"blockCount":21,"bytes":1298,"file":"chunks/y043-z096-x352.json","offset":{"x":352,"y":43,"z":96},"requirements":{"minecraft:polished_diorite":17,"minecraft:stone_bricks":4},"sha256":"b5fea97183dc9c19a9a7dc4bd454a491329c699e2dfb77f2a259425f2465d128","size":{"x":32,"y":1,"z":32}},{"blockCount":86,"bytes":3013,"file":"chunks/y043-z128-x000.json","offset":{"x":0,"y":43,"z":128},"requirements":{"minecraft:bricks":18,"minecraft:glass":18,"minecraft:polished_diorite":31,"minecraft:sandstone":6,"minecraft:stone_bricks":13},"sha256":"e893f4d07416fbc585d1fe6c06be3dc86306c169db59eea61af8268e5530329b","size":{"x":32,"y":1,"z":32}},{"blockCount":224,"bytes":5183,"file":"chunks/y043-z128-x032.json","offset":{"x":32,"y":43,"z":128},"requirements":{"minecraft:bricks":84,"minecraft:cobbled_deepslate":81,"minecraft:glass":20,"minecraft:oak_planks":31,"minecraft:polished_diorite":2,"minecraft:sandstone":1,"minecraft:stone_bricks":5},"sha256":"028bc9850298300e5eab054725c4ab289e4ad519e8416a69a3ac0ee8e306021d","size":{"x":32,"y":1,"z":32}},{"blockCount":20,"bytes":1230,"file":"chunks/y043-z128-x064.json","offset":{"x":64,"y":43,"z":128},"requirements":{"minecraft:bricks":8,"minecraft:glass":12},"sha256":"c150f839899937c3acccadd23dbc0e339fd9c454d118d9fe5fd01ea85c52ab80","size":{"x":32,"y":1,"z":32}},{"blockCount":14,"bytes":1079,"file":"chunks/y043-z128-x096.json","offset":{"x":96,"y":43,"z":128},"requirements":{"minecraft:bricks":4,"minecraft:glass":10},"sha256":"450c35246190e3f9d6a3d0d72456befc0e89127490861982c76f32d339dcccab","size":{"x":32,"y":1,"z":32}},{"blockCount":16,"bytes":1076,"file":"chunks/y043-z128-x128.json","offset":{"x":128,"y":43,"z":128},"requirements":{"minecraft:bricks":8,"minecraft:glass":8},"sha256":"9ae90961a8c2c59a56afa857fead5ec484ddd325b07274b60f2ec3b18266dd07","size":{"x":32,"y":1,"z":32}},{"blockCount":19,"bytes":1176,"file":"chunks/y043-z128-x160.json","offset":{"x":160,"y":43,"z":128},"requirements":{"minecraft:bricks":9,"minecraft:glass":10},"sha256":"1ad2b1f2299fe62dfc57c6814aed5f73ad0d5675b21fb5c898a8ba1c760292c6","size":{"x":32,"y":1,"z":32}},{"blockCount":103,"bytes":3042,"file":"chunks/y043-z128-x192.json","offset":{"x":192,"y":43,"z":128},"requirements":{"minecraft:bricks":56,"minecraft:glass":9,"minecraft:oak_planks":2,"minecraft:polished_diorite":24,"minecraft:sandstone":3,"minecraft:stone_bricks":9},"sha256":"23cce991ec7b86ee9c8433b2fb489dde8a51118b9c294529248e3f277ed65fd9","size":{"x":32,"y":1,"z":32}},{"blockCount":152,"bytes":3584,"file":"chunks/y043-z128-x224.json","offset":{"x":224,"y":43,"z":128},"requirements":{"minecraft:bricks":32,"minecraft:cobbled_deepslate":6,"minecraft:glass":1,"minecraft:oak_planks":3,"minecraft:polished_diorite":76,"minecraft:sandstone":11,"minecraft:stone_bricks":23},"sha256":"b87a5967c95444e78ba73981b020b3dcc5e9d2082ece6b21e603913c2a2ac1ec","size":{"x":32,"y":1,"z":32}},{"blockCount":5,"bytes":791,"file":"chunks/y043-z128-x320.json","offset":{"x":320,"y":43,"z":128},"requirements":{"minecraft:polished_diorite":4,"minecraft:stone_bricks":1},"sha256":"ee492fdba2007970a92990221952620d45a835aee4bb794a4ddf7d553a023262","size":{"x":32,"y":1,"z":32}},{"blockCount":38,"bytes":1797,"file":"chunks/y043-z160-x000.json","offset":{"x":0,"y":43,"z":160},"requirements":{"minecraft:bricks":5,"minecraft:glass":7,"minecraft:polished_diorite":20,"minecraft:sandstone":1,"minecraft:stone_bricks":5},"sha256":"03fa5367203e8e7089c09f0300cadcaf52524399dbd3ecc55b3b205d4f93cbc4","size":{"x":32,"y":1,"z":32}},{"blockCount":93,"bytes":2784,"file":"chunks/y043-z160-x032.json","offset":{"x":32,"y":43,"z":160},"requirements":{"minecraft:bricks":15,"minecraft:glass":14,"minecraft:polished_diorite":47,"minecraft:sandstone":6,"minecraft:stone_bricks":11},"sha256":"86e60b1a137413dcdd5aceb4a926d94e8e3098e33c71dcc4db4c01626d8e31e8","size":{"x":32,"y":1,"z":32}},{"blockCount":107,"bytes":3214,"file":"chunks/y043-z160-x064.json","offset":{"x":64,"y":43,"z":160},"requirements":{"minecraft:bricks":24,"minecraft:glass":9,"minecraft:oak_planks":4,"minecraft:polished_diorite":45,"minecraft:sandstone":11,"minecraft:stone_bricks":14},"sha256":"9c49075ad4221017404e9664cdde172835a47a8739bff5a6de4445da9c5c4eff","size":{"x":32,"y":1,"z":32}},{"blockCount":16,"bytes":1081,"file":"chunks/y043-z160-x096.json","offset":{"x":96,"y":43,"z":160},"requirements":{"minecraft:bricks":8,"minecraft:glass":8},"sha256":"65e14becd96e9de34452e08a2b1c2094960d8586bda78db69f5bf5a53cf345d6","size":{"x":32,"y":1,"z":32}},{"blockCount":73,"bytes":2632,"file":"chunks/y043-z160-x128.json","offset":{"x":128,"y":43,"z":160},"requirements":{"minecraft:bricks":23,"minecraft:glass":11,"minecraft:oak_planks":3,"minecraft:polished_diorite":19,"minecraft:sandstone":9,"minecraft:stone_bricks":8},"sha256":"cc61f4597d561a0245c954124f8ace9d2bb61b8ae2a9779a670c0d48d0b4df4c","size":{"x":32,"y":1,"z":32}},{"blockCount":94,"bytes":2657,"file":"chunks/y043-z160-x160.json","offset":{"x":160,"y":43,"z":160},"requirements":{"minecraft:bricks":19,"minecraft:glass":12,"minecraft:oak_planks":1,"minecraft:polished_diorite":44,"minecraft:sandstone":7,"minecraft:stone_bricks":11},"sha256":"56fa175229cb615eaceb2c01d636dd6bbf88dcd598ff1594536c673e81b51e28","size":{"x":32,"y":1,"z":32}},{"blockCount":225,"bytes":4417,"file":"chunks/y043-z160-x192.json","offset":{"x":192,"y":43,"z":160},"requirements":{"minecraft:bricks":134,"minecraft:glass":12,"minecraft:polished_diorite":48,"minecraft:sandstone":8,"minecraft:stone_bricks":23},"sha256":"2ea23088a9148d361dd9dfb12ec55db62adfb8d537917d12889dbad5ba015579","size":{"x":32,"y":1,"z":32}},{"blockCount":118,"bytes":3542,"file":"chunks/y043-z160-x224.json","offset":{"x":224,"y":43,"z":160},"requirements":{"minecraft:bricks":57,"minecraft:cobbled_deepslate":2,"minecraft:glass":14,"minecraft:polished_diorite":43,"minecraft:stone_bricks":2},"sha256":"4ad50f685a6a1c282df5f0e5ede0ca24697a7a214d74a199bd73f504c744a2ae","size":{"x":32,"y":1,"z":32}},{"blockCount":7,"bytes":831,"file":"chunks/y043-z160-x256.json","offset":{"x":256,"y":43,"z":160},"requirements":{"minecraft:oak_planks":1,"minecraft:spruce_planks":4,"minecraft:stone_bricks":2},"sha256":"7f437c66a3370a9e1736424d36836e97d1aefd12cc2339e12a2b7952fee99f70","size":{"x":32,"y":1,"z":32}},{"blockCount":2,"bytes":681,"file":"chunks/y043-z160-x288.json","offset":{"x":288,"y":43,"z":160},"requirements":{"minecraft:oak_planks":2},"sha256":"2cbc3bcdf994fa5d5f4df538f241d3dcd0e5fb6d9d23f74e46dfd4af9afbc3fc","size":{"x":32,"y":1,"z":32}}],"schema":1}
