{"entries":[{"blockCount":3,"bytes":712,"file":"chunks/y043-z160-x320.json","offset":{"x":320,"y":43,"z":160},"requirements":{"minecraft:polished_diorite":2,"minecraft:stone_bricks":1},"sha256":"7e640f6736036ae1264519c8cc1f9fc7fd7bee84ad4c71b234549f86c85bc0e8","size":{"x":32,"y":1,"z":32}},{"blockCount":36,"bytes":1760,"file":"chunks/y043-z160-x352.json","offset":{"x":352,"y":43,"z":160},"requirements":{"minecraft:polished_diorite":29,"minecraft:stone_bricks":7},"sha256":"9029cd9d7c0eadadaf6d24680286ad6aee803c02c445f2ec3570da7fb6faae4c","size":{"x":32,"y":1,"z":32}},{"blockCount":92,"bytes":2835,"file":"chunks/y043-z192-x064.json","offset":{"x":64,"y":43,"z":192},"requirements":{"minecraft:bricks":22,"minecraft:glass":9,"minecraft:polished_diorite":42,"minecraft:sandstone":4,"minecraft:stone_bricks":15},"sha256":"0d94925594ba539f19bc1e4834b035a25b0d4643f9916fc533be1eb3a99d8f83","size":{"x":32,"y":1,"z":32}},{"blockCount":178,"bytes":2886,"file":"chunks/y043-z192-x096.json","offset":{"x":96,"y":43,"z":192},"requirements":{"minecraft:bricks":66,"minecraft:cobbled_deepslate":5,"minecraft:glass":5,"minecraft:oak_planks":3,"minecraft:polished_diorite":63,"minecraft:sandstone":9,"minecraft:stone_bricks":27},"sha256":"961128ebfb344f6e8b8fc1a0912c9614fe73513b1178d8cd14ecbc09904dc5a7","size":{"x":32,"y":1,"z":32}},{"blockCount":189,"bytes":4092,"file":"chunks/y043-z192-x128.json","offset":{"x":128,"y":43,"z":192},"requirements":{"minecraft:bricks":58,"minecraft:cobbled_deepslate":5,"minecraft:glass":14,"minecraft:oak_planks":3,"minecraft:polished_diorite":78,"minecraft:sandstone":14,"minecraft:stone_bricks":17},"sha256":"f5595dab8fdd2ca68f0706c115f7693cec4b85eb0794aa75ca7226411a13c893","size":{"x":32,"y":1,"z":32}},{"blockCount":6,"bytes":844,"file":"chunks/y043-z192-x160.json","offset":{"x":160,"y":43,"z":192},"requirements":{"minecraft:polished_diorite":6},"sha256":"29bfd4c11742e20a7310ce2fcf8c7f825ea570f20887e6c4253654550e2aee7d","size":{"x":32,"y":1,"z":32}},{"blockCount":1,"bytes":647,"file":"chunks/y043-z192-x320.json","offset":{"x":320,"y":43,"z":192},"requirements":{"minecraft:polished_diorite":1},"sha256":"83bd0bddc2b6e0285615d952864ac449876e6114dd13025380917fe63af6fd31","size":{"x":32,"y":1,"z":32}},{"blockCount":176,"bytes":4475,"file":"chunks/y044-z000-x352.json","offset":{"x":352,"y":44,"z":0},"requirements":{"minecraft:bricks":24,"minecraft:cobbled_deepslate":3,"minecraft:glass":15,"minecraft:oak_planks":13,"minecraft:polished_diorite":77,"minecraft:sandstone":21,"minecraft:spruce_planks":5,"minecraft:stone_bricks":18},"sha256":"9472baeac33aa32aa9024f1f27ad486b96e23808a0bdb90e4df5c08ebf4a317f","size":{"x":32,"y":1,"z":32}},{"blockCount":253,"bytes":5081,"file":"chunks/y044-z000-x384.json","offset":{"x":384,"y":44,"z":0},"requirements":{"minecraft:glass":35,"minecraft:oak_planks":20,"minecraft:polished_diorite":37,"minecraft:sandstone":95,"minecraft:spruce_planks":15,"minecraft:stone_bricks":51},"sha256":"e3fdfcb769dbdee8a09ffced293c42edae0b0f1c0ef638da49d75aa48b9ebeef","size":{"x":32,"y":1,"z":32}},{"blockCount":11,"bytes":1012,"file":"chunks/y044-z032-x064.json","offset":{"x":64,"y":44,"z":32},"requirements":{"minecraft:cobbled_deepslate":1,"minecraft:glass":10},"sha256":"0952f7532c32c15016c35310602e6f5fa57d9639342a12c6fe3829014c4a51c0","size":{"x":32,"y":1,"z":32}},{"blockCount":8,"bytes":898,"file":"chunks/y044-z032-x128.json","offset":{"x":128,"y":44,"z":32},"requirements":{"minecraft:cobbled_deepslate":1,"minecraft:glass":7},"sha256":"73df355b509d2f0479c4b10f6ff542b0b163fa52f8911a6ab539a9ff77d4a44a","size":{"x":32,"y":1,"z":32}},{"blockCount":3,"bytes":714,"file":"chunks/y044-z032-x160.json","offset":{"x":160,"y":44,"z":32},"requirements":{"minecraft:glass":3},"sha256":"36bfeacb929054550a9ae593af6dd7bf0842a457cd014a749aebe66779e6dd60","size":{"x":32,"y":1,"z":32}},{"blockCount":140,"bytes":3709,"file":"chunks/y044-z032-x352.json","offset":{"x":352,"y":44,"z":32},"requirements":{"minecraft:glass":44,"minecraft:oak_planks":20,"minecraft:polished_diorite":36,"minecraft:sandstone":22,"minecraft:stone_bricks":18},"sha256":"6c20f07384fa15cb967bc97da73cec0789abece9d3c47517ac10c91a821af1a6","size":{"x":32,"y":1,"z":32}},{"blockCount":39,"bytes":1549,"file":"chunks/y044-z032-x384.json","offset":{"x":384,"y":44,"z":32},"requirements":{"minecraft:glass":11,"minecraft:oak_planks":5,"minecraft:polished_diorite":7,"minecraft:sandstone":12,"minecraft:stone_bricks":4},"sha256":"8a6319be4b983cc6416c524876d563a81d841fad01a43b373522f4a6395eca4b","size":{"x":32,"y":1,"z":32}},{"blockCount":107,"bytes":3182,"file":"chunks/y044-z064-x064.json","offset":{"x":64,"y":44,"z":64},"requirements":{"minecraft:bricks":27,"minecraft:glass":12,"minecraft:polished_diorite":50,"minecraft:sandstone":6,"minecraft:stone_bricks":12},"sha256":"8ab980f443cb972153f28c1965417fd3023260edb927687494a8b0422c004c82","size":{"x":32,"y":1,"z":32}},{"blockCount":173,"bytes":2659,"file":"chunks/y044-z064-x096.json","offset":{"x":96,"y":44,"z":64},"requirements":{"minecraft:bricks":72,"minecraft:cobbled_deepslate":1,"minecraft:glass":7,"minecraft:oak_planks":3,"minecraft:polished_diorite":53,"minecraft:sandstone":9,"minecraft:stone_bricks":28},"sha256":"a6bebded5a29cbe5960de255120a79a55a639645b8cbdbee599b310c9f1dd836","size":{"x":32,"y":1,"z":32}},{"blockCount":205,"bytes":4437,"file":"chunks/y044-z064-x128.json","offset":{"x":128,"y":44,"z":64},"requirements":{"minecraft:bricks":64,"minecraft:cobbled_deepslate":1,"minecraft:glass":19,"minecraft:oak_planks":3,"minecraft:polished_diorite":82,"minecraft:sandstone":16,"minecraft:stone_bricks":20},"sha256":"3dfd6a9c8f03120e464bc0d33a40ba081597098086c58bad47e427f03ff1be14","size":{"x":32,"y":1,"z":32}},{"blockCount":7,"bytes":881,"file":"chunks/y044-z064-x160.json","offset":{"x":160,"y":44,"z":64},"requirements":{"minecraft:polished_diorite":7},"sha256":"42f571a71edf0e2d7f9acb87b2abc0ede33d4d869c1dea27ecee9ca97ec60604","size":{"x":32,"y":1,"z":32}},{"blockCount":9,"bytes":875,"file":"chunks/y044-z064-x192.json","offset":{"x":192,"y":44,"z":64},"requirements":{"minecraft:polished_diorite":9},"sha256":"2b3ff793491ed558071ed6b9a97946bf707ed5e722d61a3fdd52d5018e85597f","size":{"x":32,"y":1,"z":32}},{"blockCount":12,"bytes":915,"file":"chunks/y044-z064-x224.json","offset":{"x":224,"y":44,"z":64},"requirements":{"minecraft:polished_diorite":12},"sha256":"73ae5f25c638bfaafb5e9ff333ec3e8708030ad7bc999471852a28fbb1d6d9a4","size":{"x":32,"y":1,"z":32}},{"blockCount":4,"bytes":764,"file":"chunks/y044-z064-x288.json","offset":{"x":288,"y":44,"z":64},"requirements":{"minecraft:oak_planks":1,"minecraft:stone_bricks":3},"sha256":"bd0d64f9f44bfd3ae7ba8caf62f25f065a0f15f27e77c7549cc74424c6b4db24","size":{"x":32,"y":1,"z":32}},{"blockCount":1,"bytes":643,"file":"chunks/y044-z064-x320.json","offset":{"x":320,"y":44,"z":64},"requirements":{"minecraft:stone_bricks":1},"sha256":"fc84bbfe2ef626c13f9c1d44ba067a07842020a55ed906d5c2b5413ba400241f","size":{"x":32,"y":1,"z":32}},{"blockCount":3,"bytes":721,"file":"chunks/y044-z064-x352.json","offset":{"x":352,"y":44,"z":64},"requirements":{"minecraft:stone_bricks":3},"sha256":"03d2cbc2a656fa600fbf1acaeb6493be91a3876d242232cae4ddbcf63c67090a","size":{"x":32,"y":1,"z":32}},{"blockCount":57,"bytes":2336,"file":"chunks/y044-z096-x000.json","offset":{"x":0,"y":44,"z":96},"requirements":{"minecraft:bricks":5,"minecraft:glass":13,"minecraft:polished_diorite":28,"minecraft:sandstone":2,"minecraft:stone_bricks":9},"sha256":"2477d1db85c2fb1adb1339991f93245d6ee4c2c842b051c98961761a648e4991","size":{"x":32,"y":1,"z":32}},{"blockCount":137,"bytes":4052,"file":"chunks/y044-z096-x032.json","offset":{"x":32,"y":44,"z":96},"requirements":{"minecraft:bricks":37,"minecraft:glass":31,"minecraft:oak_planks":1,"minecraft:polished_diorite":47,"minecraft:sandstone":6,"minecraft:stone_bricks":15},"sha256":"e5aaa664290693f48542b63476ed4b1126b7236c97d9723d626fcd5088654004","size":{"x":32,"y":1,"z":32}},{"blockCount":106,"bytes":3289,"file":"chunks/y044-z096-x064.json","offset":{"x":64,"y":44,"z":96},"requirements":{"minecraft:bricks":29,"minecraft:glass":18,"minecraft:oak_planks":4,"minecraft:polished_diorite":37,"minecraft:sandstone":9,"minecraft:stone_bricks":9},"sha256":"c4df7ea3b41dd42e72f590f542c8fd5ba8f23e6454da8faad7f373f1fca95a03","size":{"x":32,"y":1,"z":32}},{"blockCount":21,"bytes":1235,"file":"chunks/y044-z096-x096.json","offset":{"x":96,"y":44,"z":96},"requirements":{"minecraft:bricks":11,"minecraft:glass":10},"sha256":"3212bbab82854e8a6c2bff804660312aeab6ef355860a7f1b037be2c834a7158","size":{"x":32,"y":1,"z":32}},{"blockCount":64,"bytes":2476,"file":"chunks/y044-z096-x128.json","offset":{"x":128,"y":44,"z":96},"requirements":{"minecraft:bricks":27,"minecraft:glass":14,"minecraft:oak_planks":3,"minecraft:polished_diorite":12,"minecraft:sandstone":5,"minecraft:stone_bricks":3},"sha256":"655b91b901bdf09760f1db3ce727eb99a01681d0cd696cb1188f6ea70147d90d","size":{"x":32,"y":1,"z":32}},{"blockCount":113,"bytes":3211,"file":"chunks/y044-z096-x160.json","offset":{"x":160,"y":44,"z":96},"requirements":{"minecraft:bricks":28,"minecraft:glass":22,"minecraft:oak_planks":1,"minecraft:polished_diorite":44,"minecraft:sandstone":7,"minecraft:stone_bricks":11},"sha256":"7c6ddbd6dad06b82dcd12e26be2599dca30dbebaefe33f16cd0271637f6e860a","size":{"x":32,"y":1,"z":32}},{"blockCount":246,"bytes":4956,"file":"chunks/y044-z096-x192.json","offset":{"x":192,"y":44,"z":96},"requirements":{"minecraft:bricks":154,"minecraft:glass":22,"minecraft:oak_planks":2,"minecraft:polished_diorite":39,"minecraft:sandstone":11,"minecraft:stone_bricks":18},"sha256":"3a75890319bba4af952c53dca07aff17180d7ed985ac29e775f3dead4707b71b","size":{"x":32,"y":1,"z":32}},{"blockCount":168,"bytes":4296,"file":"chunks/y044-z096-x224.json","offset":{"x":224,"y":44,"z":96},"requirements":{"minecraft:bricks":75,"minecraft:cobbled_deepslate":1,"minecraft:glass":19,"minecraft:oak_planks":1,"minecraft:polished_diorite":65,"minecraft:sandstone":5,"minecraft:stone_bricks":2},"sha256":"483314aefb8219d1192b8c5f8fcbf499ea471b98ff5c892d754fa39dd0b74382","size":{"x":32,"y":1,"z":32}},{"blockCount":9,"bytes":967,"file":"chunks/y044-z096-x256.json","offset":{"x":256,"y":44,"z":96},"requirements":{"minecraft:oak_planks":1,"minecraft:spruce_planks":4,"minecraft:stone_bricks":4},"sha256":"51e44cc14e31dbc981cd4a3a2cdf3cdcb6543a1f57dcfbbc81d0879bec7ea89f","size":{"x":32,"y":1,"z":32}},{"blockCount":4,"bytes":763,"file":"chunks/y044-z096-x352.json","offset":{"x":352,"y":44,"z":96},"requirements":{"minecraft:stone_bricks":4},"sha256":"0fd8662bc5004949086233523d87249f8a8c6267cdfb17147fb874a3d247cc76","size":{"x":32,"y":1,"z":32}},{"blockCount":86,"bytes":3013,"file":"chunks/y044-z128-x000.json","offset":{"x":0,"y":44,"z":128},"requirements":{"minecraft:bricks":18,"minecraft:glass":18,"minecraft:polished_diorite":31,"minecraft:sandstone":6,"minecraft:stone_bricks":13},"sha256":"fd9e260832e4cbe5455dfb7c36253b902e97bb5335a48f5294a929fe20904d15","size":{"x":32,"y":1,"z":32}},{"blockCount":168,"bytes":5267,"file":"chunks/y044-z128-x032.json","offset":{"x":32,"y":44,"z":128},"requirements":{"minecraft:bricks":78,"minecraft:cobbled_deepslate":26,"minecraft:glass":20,"minecraft:oak_planks":31,"minecraft:sandstone":1,"minecraft:stone_bricks":12},"sha256":"c43afecfb577d91a5d546d570f4a1814a0a7ec1bc53331dd82057bebe7de3593","size":{"x":32,"y":1,"z":32}},{"blockCount":20,"bytes":1230,"file":"chunks/y044-z128-x064.json","offset":{"x":64,"y":44,"z":128},"requirements":{"minecraft:bricks":8,"minecraft:glass":12},"sha256":"84cd4fc38735199e45de643f8f7d6109a4dbc65d7427c7b9308ebe117acf396b","size":{"x":32,"y":1,"z":32}},{"blockCount":18,"bytes":1127,"file":"chunks/y044-z128-x096.json","offset":{"x":96,"y":44,"z":128},"requirements":{"minecraft:bricks":4,"minecraft:glass":4,"minecraft:spruce_planks":10},"sha256":"00c8c123a1f7a50e77abe5b51e00d0614a3cd49e668a1e8ecd2cca691bd3e79e","size":{"x":32,"y":1,"z":32}},{"blockCount":16,"bytes":1076,"file":"chunks/y044-z128-x128.json","offset":{"x":128,"y":44,"z":128},"requirements":{"minecraft:bricks":8,"minecraft:glass":8},"sha256":"09bc79ee6a56a9fe3f55ff5b15c2d5aa2711840bdfaa0f2b4020d76a740b5d54","size":{"x":32,"y":1,"z":32}},{"blockCount":19,"bytes":1176,"file":"chunks/y044-z128-x160.json","offset":{"x":160,"y":44,"z":128},"requirements":{"minecraft:bricks":9,"minecraft:glass":10},"sha256":"7879cd7635c26c3e5a8fdace015e6d88f5461cd9df8517567e72ff8e68df1122","size":{"x":32,"y":1,"z":32}},{"blockCount":86,"bytes":2966,"file":"chunks/y044-z128-x192.json","offset":{"x":192,"y":44,"z":128},"requirements":{"minecraft:bricks":48,"minecraft:glass":9,"minecraft:oak_planks":2,"minecraft:polished_diorite":20,"minecraft:sandstone":3,"minecraft:stone_bricks":4},"sha256":"2dc24f00f2fb2a1cefbd57049167b5131c565869c8150a79a121703aaac153de","size":{"x":32,"y":1,"z":32}},{"blockCount":157,"bytes":3837,"file":"chunks/y044-z128-x224.json","offset":{"x":224,"y":44,"z":128},"requirements":{"minecraft:bricks":45,"minecraft:glass":1,"minecraft:oak_planks":3,"minecraft:polished_diorite":69,"minecraft:sandstone":11,"minecraft:stone_bricks":28},"sha256":"6bec21e7bd2c392de12589debb440d2a97ad958d4522d8f3cb38ae7c43426fb2","size":{"x":32,"y":1,"z":32}},{"blockCount":4,"bytes":764,"file":"chunks/y044-z128-x320.json","offset":{"x":320,"y":44,"z":128},"requirements":{"minecraft:polished_diorite":4},"sha256":"448a1f81e7c811d746f2ed955446456b6f0e1871b7577a8887f38c65a15c9a9b","size":{"x":32,"y":1,"z":32}},{"blockCount":38,"bytes":1797,"file":"chunks/y044-z160-x000.json","offset":{"x":0,"y":44,"z":160},"requirements":{"minecraft:bricks":5,"minecraft:glass":7,"minecraft:polished_diorite":20,"minecraft:sandstone":1,"minecraft:stone_bricks":5},"sha256":"afb4112de018ed8752b1fcb18b1e49107ad1041d3c0f41bb32338a040b385bf7","size":{"x":32,"y":1,"z":32}},{"blockCount":93,"bytes":2784,"file":"chunks/y044-z160-x032.json","offset":{"x":32,"y":44,"z":160},"requirements":{"minecraft:bricks":15,"minecraft:glass":14,"minecraft:polished_diorite":47,"minecraft:sandstone":6,"minecraft:stone_bricks":11},"sha256":"86cb7e2533ebab89f515161eab162b787b9cd4565f3006436dd4d47507ec2f57","size":{"x":32,"y":1,"z":32}},{"blockCount":105,"bytes":3157,"file":"chunks/y044-z160-x064.json","offset":{"x":64,"y":44,"z":160},"requirements":{"minecraft:bricks":24,"minecraft:glass":9,"minecraft:oak_planks":4,"minecraft:polished_diorite":45,"minecraft:sandstone":11,"minecraft:stone_bricks":12},"sha256":"c56137036fec120eff56a80d77bdbe703aee2b94ef1013773a35be2814cb5e5f","size":{"x":32,"y":1,"z":32}},{"blockCount":16,"bytes":1081,"file":"chunks/y044-z160-x096.json","offset":{"x":96,"y":44,"z":160},"requirements":{"minecraft:bricks":8,"minecraft:glass":8},"sha256":"61c0d3ac7ceb715fa91bf9aa6c46f3ff7bf8f73375fc3001c7c35ac642dee36c","size":{"x":32,"y":1,"z":32}},{"blockCount":71,"bytes":2575,"file":"chunks/y044-z160-x128.json","offset":{"x":128,"y":44,"z":160},"requirements":{"minecraft:bricks":23,"minecraft:glass":11,"minecraft:oak_planks":3,"minecraft:polished_diorite":19,"minecraft:sandstone":9,"minecraft:stone_bricks":6},"sha256":"e9b0cb3c47bbf1abe0b7a1d4774d1fd8953b820cbda89c1432e89b13d48949f9","size":{"x":32,"y":1,"z":32}},{"blockCount":95,"bytes":2695,"file":"chunks/y044-z160-x160.json","offset":{"x":160,"y":44,"z":160},"requirements":{"minecraft:bricks":19,"minecraft:glass":12,"minecraft:oak_planks":1,"minecraft:polished_diorite":45,"minecraft:sandstone":7,"minecraft:stone_bricks":11},"sha256":"0646dbdf896077f5f548de2f32deb968a42721884318ba58d86248a4426ad2a8","size":{"x":32,"y":1,"z":32}},{"blockCount":217,"bytes":4531,"file":"chunks/y044-z160-x192.json","offset":{"x":192,"y":44,"z":160},"requirements":{"minecraft:bricks":130,"minecraft:glass":15,"minecraft:polished_diorite":48,"minecraft:sandstone":8,"minecraft:stone_bricks":16},"sha256":"1910dd11f054d79ad0381c4eb1e665b9a12f330c8972201721ac144228fddfa1","size":{"x":32,"y":1,"z":32}},{"blockCount":123,"bytes":3667,"file":"chunks/y044-z160-x224.json","offset":{"x":224,"y":44,"z":160},"requirements":{"minecraft:bricks":63,"minecraft:cobbled_deepslate":1,"minecraft:glass":18,"minecraft:polished_diorite":41},"sha256":"c26908326881e5b4f41c39e7905dd3fc673f224c1b269d2023070b449b1dade5","size":{"x":32,"y":1,"z":32}},{"blockCount":10,"bytes":987,"file":"chunks/y044-z160-x256.json","offset":{"x":256,"y":44,"z":160},"requirements":{"minecraft:oak_planks":1,"minecraft:spruce_planks":5,"minecraft:stone_bricks":4},"sha256":"5bf284e34fbdf73e78a420a73c5ffbd755cf6db3f3491d317683580fc34d3f0d","size":{"x":32,"y":1,"z":32}},{"blockCount":10,"bytes":928,"file":"chunks/y044-z160-x288.json","offset":{"x":288,"y":44,"z":160},"requirements":{"minecraft:oak_planks":5,"minecraft:spruce_planks":2,"minecraft:stone_bricks":3},"sha256":"b8a1c6d913a61bf402b8b5df78f791144d7ba5189d3edc5a18108029c4132cfa","size":{"x":32,"y":1,"z":32}},{"blockCount":1,"bytes":624,"file":"chunks/y044-z160-x320.json","offset":{"x":320,"y":44,"z":160},"requirements":{"minecraft:stone_bricks":1},"sha256":"26aa4f841de2a55639f17e03e12c3f409a05672900549cb3368bb859b496da75","size":{"x":32,"y":1,"z":32}},{"blockCount":7,"bytes":880,"file":"chunks/y044-z160-x352.json","offset":{"x":352,"y":44,"z":160},"requirements":{"minecraft:stone_bricks":7},"sha256":"96e20e5a577b146afbdde55d6ef227ed2cf92cb4b72534f5d7e73d9f7a0dad08","size":{"x":32,"y":1,"z":32}},{"blockCount":88,"bytes":2701,"file":"chunks/y044-z192-x064.json","offset":{"x":64,"y":44,"z":192},"requirements":{"minecraft:bricks":24,"minecraft:glass":9,"minecraft:polished_diorite":42,"minecraft:sandstone":4,"minecraft:stone_bricks":9},"sha256":"08e482054d868ab9b5d1c9f8b3265be93b6aa0a91943dae683f071bdd014bee9","size":{"x":32,"y":1,"z":32}},{"blockCount":170,"bytes":2563,"file":"chunks/y044-z192-x096.json","offset":{"x":96,"y":44,"z":192},"requirements":{"minecraft:bricks":71,"minecraft:cobbled_deepslate":1,"minecraft:glass":5,"minecraft:oak_planks":3,"minecraft:polished_diorite":53,"minecraft:sandstone":9,"minecraft:stone_bricks":28},"sha256":"7b4b65d3dee52a470bc89cba1a99123e5c335ea55c7753a3286c4a3bfe9fc998","size":{"x":32,"y":1,"z":32}},{"blockCount":184,"bytes":3941,"file":"chunks/y044-z192-x128.json","offset":{"x":128,"y":44,"z":192},"requirements":{"minecraft:bricks":60,"minecraft:cobbled_deepslate":1,"minecraft:glass":14,"minecraft:oak_planks":3,"minecraft:polished_diorite":75,"minecraft:sandstone":14,"minecraft:stone_bricks":17},"sha256":"d4e34e2072dbe86bba6044561e17126c3e4039d17417de0682599ee281d3d407","size":{"x":32,"y":1,"z":32}},{"blockCount":6,"bytes":844,"file":"chunks/y044-z192-x160.json","offset":{"x":160,"y":44,"z":192},"requirements":{"minecraft:polished_diorite":6},"sha256":"05f2594491051354369e75f461b42843d64e7e7505262d5aeba8cf779191b072","size":{"x":32,"y":1,"z":32}},{"blockCount":224,"bytes":4344,"file":"chunks/y045-z000-x352.json","offset":{"x":352,"y":45,"z":0},"requirements":{"minecraft:bricks":28,"minecraft:cobbled_deepslate":3,"minecraft:glass":14,"minecraft:oak_planks":12,"minecraft:polished_diorite":49,"minecraft:sandstone":21,"minecraft:spruce_planks":64,"minecraft:stone_bricks":33},"sha256":"d4ad6a0a1b8b3c541534510060235b5cd9b03ac95e15c8780c00695f3ef32efb","size":{"x":32,"y":1,"z":32}},{"blockCount":251,"bytes":4613,"file":"chunks/y045-z000-x384.json","offset":{"x":384,"y":45,"z":0},"requirements":{"minecraft:glass":19,"minecraft:oak_planks":75,"minecraft:polished_diorite":38,"minecraft:sandstone":82,"minecraft:stone_bricks":37},"sha256":"6cda752183325de6b20b6f41a8b4d5d6b6f74883477e4444a57f8296ec36f49c","size":{"x":32,"y":1,"z":32}},{"blockCount":4,"bytes":751,"file":"chunks/y045-z032-x064.json","offset":{"x":64,"y":45,"z":32},"requirements":{"minecraft:glass":4},"sha256":"95c76e2554e3905b203a523c85493ae234b261698070c0463c08e1809df41b8b","size":{"x":32,"y":1,"z":32}},{"blockCount":1,"bytes":647,"file":"chunks/y045-z032-x096.json","offset":{"x":96,"y":45,"z":32},"requirements":{"minecraft:cobbled_deepslate":1},"sha256":"14fac9df18a8dd4558b61e5844334c6eaba15d94689be50082ff08a2956cf9b0","size":{"x":32,"y":1,"z":32}},{"blockCount":5,"bytes":823,"file":"chunks/y045-z032-x128.json","offset":{"x":128,"y":45,"z":32},"requirements":{"minecraft:cobbled_deepslate":1,"minecraft:glass":4},"sha256":"92ccc288a84d2f36fa7b58523b1f4684e6351c16a7e1a7aa271b18f9ad5e34f9","size":{"x":32,"y":1,"z":32}},{"blockCount":202,"bytes":3898,"file":"chunks/y045-z032-x352.json","offset":{"x":352,"y":45,"z":32},"requirements":{"minecraft:glass":12,"minecraft:oak_planks":38,"minecraft:sandstone":20,"minecraft:spruce_planks":56,"minecraft:stone_bricks":76},"sha256":"fc3936c999039b4ce7cabfe63c1c3135208ad3b6cdd191f89920e1a4a68d1d4a","size":{"x":32,"y":1,"z":32}},{"blockCount":35,"bytes":1511,"file":"chunks/y045-z032-x384.json","offset":{"x":384,"y":45,"z":32},"requirements":{"minecraft:glass":9,"minecraft:oak_planks":5,"minecraft:polished_diorite":7,"minecraft:sandstone":12,"minecraft:stone_bricks":2},"sha256":"a908a91d98d4ccc502d58fc7fbbf4e7ae9418ea944cd29563e90cb24a4f19942","size":{"x":32,"y":1,"z":32}},{"blockCount":112,"bytes":3258,"file":"chunks/y045-z064-x064.json","offset":{"x":64,"y":45,"z":64},"requirements":{"minecraft:bricks":26,"minecraft:glass":12,"minecraft:polished_diorite":52,"minecraft:sandstone":6,"minecraft:stone_bricks":16},"sha256":"564f4a825d9b38d1fd633c6e9083cbf580ba0d327ec7fdc23d82b917ca5799ba","size":{"x":32,"y":1,"z":32}},{"blockCount":177,"bytes":2888,"file":"chunks/y045-z064-x096.json","offset":{"x":96,"y":45,"z":64},"requirements":{"minecraft:bricks":73,"minecraft:cobbled_deepslate":3,"minecraft:glass":7,"minecraft:oak_planks":3,"minecraft:polished_diorite":65,"minecraft:sandstone":9,"minecraft:stone_bricks":17},"sha256":"9332d007fae2b5643c9aeb3f658a024bbb50f4b6eb0488eb412c3b879c0ac4b5","size":{"x":32,"y":1,"z":32}},{"blockCount":211,"bytes":4550,"file":"chunks/y045-z064-x128.json","offset":{"x":128,"y":45,"z":64},"requirements":{"minecraft:bricks":63,"minecraft:cobbled_deepslate":3,"minecraft:glass":19,"minecraft:oak_planks":3,"minecraft:polished_diorite":84,"minecraft:sandstone":16,"minecraft:stone_bricks":23},"sha256":"ba7b7261f9af5d35f3961efb99914d236eab9f6a005d9b7f7628da1f319411fd","size":{"x":32,"y":1,"z":32}},{"blockCount":7,"bytes":881,"file":"chunks/y045-z064-x160.json","offset":{"x":160,"y":45,"z":64},"requirements":{"minecraft:polished_diorite":7},"sha256":"d713e3000e22f6661569758b5469d09d18eb382a0b275e7b7c247dc54120b68a","size":{"x":32,"y":1,"z":32}},{"blockCount":9,"bytes":875,"file":"chunks/y045-z064-x192.json","offset":{"x":192,"y":45,"z":64},"requirements":{"minecraft:polished_diorite":9},"sha256":"b08e782d362b1fdb70d592da60eb7aa426683acdca49c13e7486fb35523289f2","size":{"x":32,"y":1,"z":32}},{"blockCount":12,"bytes":915,"file":"chunks/y045-z064-x224.json","offset":{"x":224,"y":45,"z":64},"requirements":{"minecraft:polished_diorite":12},"sha256":"8149496b43fcec4121d54e159274ab0a4613fcb2987eda2c1aac9b54c59eab88","size":{"x":32,"y":1,"z":32}},{"blockCount":4,"bytes":764,"file":"chunks/y045-z064-x288.json","offset":{"x":288,"y":45,"z":64},"requirements":{"minecraft:oak_planks":1,"minecraft:stone_bricks":3},"sha256":"07e040c8a19be4951b517bea9e6d8c09b18be8e51cf6b8e16b1e5b6a7401f06f","size":{"x":32,"y":1,"z":32}},{"blockCount":1,"bytes":648,"file":"chunks/y045-z064-x320.json","offset":{"x":320,"y":45,"z":64},"requirements":{"minecraft:cobbled_deepslate":1},"sha256":"e5c2bdbd5122a05f7799a13d5b6c049b0302028c47a6326d3162b471c4908a04","size":{"x":32,"y":1,"z":32}},{"blockCount":3,"bytes":726,"file":"chunks/y045-z064-x352.json","offset":{"x":352,"y":45,"z":64},"requirements":{"minecraft:cobbled_deepslate":3},"sha256":"b1dd66b96e658d3e3aec845acb117436d4d7cab83872821fd99ee6f6e3bd2fda","size":{"x":32,"y":1,"z":32}},{"blockCount":57,"bytes":2336,"file":"chunks/y045-z096-x000.json","offset":{"x":0,"y":45,"z":96},"requirements":{"minecraft:bricks":5,"minecraft:glass":13,"minecraft:polished_diorite":28,"minecraft:sandstone":2,"minecraft:stone_bricks":9},"sha256":"5921d967a31e431716823a4865a0c1d71f6703a76cf4c8d41d31f471b2287918","size":{"x":32,"y":1,"z":32}},{"blockCount":126,"bytes":3765,"file":"chunks/y045-z096-x032.json","offset":{"x":32,"y":45,"z":96},"requirements":{"minecraft:bricks":31,"minecraft:glass":22,"minecraft:oak_planks":1,"minecraft:polished_diorite":47,"minecraft:sandstone":6,"minecraft:stone_bricks":19},"sha256":"de52a8176286fe40f439c1f35f6b5c262692254239f9871b8009cd48ea2bc053","size":{"x":32,"y":1,"z":32}},{"blockCount":102,"bytes":3138,"file":"chunks/y045-z096-x064.json","offset":{"x":64,"y":45,"z":96},"requirements":{"minecraft:bricks":29,"minecraft:glass":14,"minecraft:oak_planks":4,"minecraft:polished_diorite":37,"minecraft:sandstone":9,"minecraft:stone_bricks":9},"sha256":"2106439205e71e36f6cf35439f3171513ab0c7ab8912a3082c4d553d36aaa5e5","size":{"x":32,"y":1,"z":32}},{"blockCount":21,"bytes":1235,"file":"chunks/y045-z096-x096.json","offset":{"x":96,"y":45,"z":96},"requirements":{"minecraft:bricks":11,"minecraft:glass":10},"sha256":"4f87407b10a60835c7b670d10ce9f1c2e72524061c27a19c303d6a99602777c6","size":{"x":32,"y":1,"z":32}},{"blockCount":64,"bytes":2476,"file":"chunks/y045-z096-x128.json","offset":{"x":128,"y":45,"z":96},"requirements":{"minecraft:bricks":27,"minecraft:glass":14,"minecraft:oak_planks":3,"minecraft:polished_diorite":12,"minecraft:sandstone":5,"minecraft:stone_bricks":3},"sha256":"a32d614df681a1a47b92bba42e90bcb20cc25b5b7dc03cc7260d3e51a5e728c1","size":{"x":32,"y":1,"z":32}},{"blockCount":113,"bytes":3211,"file":"chunks/y045-z096-x160.json","offset":{"x":160,"y":45,"z":96},"requirements":{"minecraft:bricks":28,"minecraft:glass":22,"minecraft:oak_planks":1,"minecraft:polished_diorite":44,"minecraft:sandstone":7,"minecraft:stone_bricks":11},"sha256":"8620f0de90ff4fd5c50dbeaa35f86a6a6ae20a9178a1d9ec94d56b925db0bdb5","size":{"x":32,"y":1,"z":32}},{"blockCount":271,"bytes":4823,"file":"chunks/y045-z096-x192.json","offset":{"x":192,"y":45,"z":96},"requirements":{"minecraft:bricks":164,"minecraft:glass":26,"minecraft:oak_planks":2,"minecraft:polished_diorite":44,"minecraft:sandstone":11,"minecraft:stone_bricks":24},"sha256":"d4592e3ef911416aac3d0bc119a30b735ea089dacc0b75d14284c36d090b35ee","size":{"x":32,"y":1,"z":32}},{"blockCount":162,"bytes":4239,"file":"chunks/y045-z096-x224.json","offset":{"x":224,"y":45,"z":96},"requirements":{"minecraft:bricks":72,"minecraft:cobbled_deepslate":4,"minecraft:glass":13,"minecraft:oak_planks":1,"minecraft:polished_diorite":65,"minecraft:sandstone":5,"minecraft:stone_bricks":2},"sha256":"3838ad1af0ca0f710ee1fd820ac15dba863cb7608dff9782bef2f0008742e727","size":{"x":32,"y":1,"z":32}},{"blockCount":8,"bytes":929,"file":"chunks/y045-z096-x256.json","offset":{"x":256,"y":45,"z":96},"requirements":{"minecraft:oak_planks":1,"minecraft:spruce_planks":2,"minecraft:stone_bricks":5},"sha256":"ea9be0e53841776a81c545a7453ccb8c1e561d69fd43fd65c50c16dfbb86fc00","size":{"x":32,"y":1,"z":32}},{"blockCount":4,"bytes":768,"file":"chunks/y045-z096-x352.json","offset":{"x":352,"y":45,"z":96},"requirements":{"minecraft:cobbled_deepslate":4},"sha256":"b21ff7b5c4549185850bcd11986d2a9050d6b02b7703d1b62a27a6e7b95aeffb","size":{"x":32,"y":1,"z":32}},{"blockCount":86,"bytes":3013,"file":"chunks/y045-z128-x000.json","offset":{"x":0,"y":45,"z":128},"requirements":{"minecraft:bricks":18,"minecraft:glass":18,"minecraft:polished_diorite":31,"minecraft:sandstone":6,"minecraft:stone_bricks":13},"sha256":"82daa8191b96ff3f2f2d6d52a5cc80fda745c6546dbce2b1d518dfbe23d6e1fe","size":{"x":32,"y":1,"z":32}},{"blockCount":164,"bytes":5103,"file":"chunks/y045-z128-x032.json","offset":{"x":32,"y":45,"z":128},"requirements":{"minecraft:bricks":76,"minecraft:cobbled_deepslate":21,"minecraft:glass":16,"minecraft:oak_planks":31,"minecraft:polished_diorite":6,"minecraft:stone_bricks":14},"sha256":"e38cfd69d47f5e688d6883f8b385eac7fd66f71ada02dd0fe22a670fdf82b2d3","size":{"x":32,"y":1,"z":32}},{"blockCount":16,"bytes":1078,"file":"chunks/y045-z128-x064.json","offset":{"x":64,"y":45,"z":128},"requirements":{"minecraft:bricks":8,"minecraft:glass":8},"sha256":"6d6bc018cddfc158ae8daae1dfd49164b27a8a8e7c794e29d2f15fa962e834c9","size":{"x":32,"y":1,"z":32}},{"blockCount":26,"bytes":1013,"file":"chunks/y045-z128-x096.json","offset":{"x":96,"y":45,"z":128},"requirements":{"minecraft:bricks":4,"minecraft:glass":3,"minecraft:spruce_planks":19},"sha256":"2d5e16b8296c57167d5d160c38d185cbe1cee81038a7c9c53433446935301618","size":{"x":32,"y":1,"z":32}},{"blockCount":16,"bytes":1076,"file":"chunks/y045-z128-x128.json","offset":{"x":128,"y":45,"z":128},"requirements":{"minecraft:bricks":8,"minecraft:glass":8},"sha256":"87595a4352ee49059dcb4c0f955f333c2bc407a4ba170a64bb333200ef020655","size":{"x":32,"y":1,"z":32}},{"blockCount":19,"bytes":1176,"file":"chunks/y045-z128-x160.json","offset":{"x":160,"y":45,"z":128},"requirements":{"minecraft:bricks":9,"minecraft:glass":10},"sha256":"d9074649ee5a7126c4ab1fe341b7173ba969ff5f0816d94c3886062e5a7bd651","size":{"x":32,"y":1,"z":32}},{"blockCount":97,"bytes":2966,"file":"chunks/y045-z128-x192.json","offset":{"x":192,"y":45,"z":128},"requirements":{"minecraft:bricks":53,"minecraft:glass":9,"minecraft:oak_planks":2,"minecraft:polished_diorite":22,"minecraft:sandstone":3,"minecraft:stone_bricks":8},"sha256":"a3e378bd57b3dc50df5fc40540cb4bad50cf11748c450e82805c9709a2cb648c","size":{"x":32,"y":1,"z":32}},{"blockCount":159,"bytes":3869,"file":"chunks/y045-z128-x224.json","offset":{"x":224,"y":45,"z":128},"requirements":{"minecraft:bricks":45,"minecraft:cobbled_deepslate":6,"minecraft:glass":1,"minecraft:oak_planks":3,"minecraft:polished_diorite":79,"minecraft:sandstone":11,"minecraft:stone_bricks":14},"sha256":"e606d8b02e98a40a6a074ad6e702f63b963c81b924ceef23d9397840eab7f48f","size":{"x":32,"y":1,"z":32}},{"blockCount":5,"bytes":791,"file":"chunks/y045-z128-x320.json","offset":{"x":320,"y":45,"z":128},"requirements":{"minecraft:polished_diorite":4,"minecraft:stone_bricks":1},"sha256":"024699487a854254e1f4009cc85239d173396bedcfe192fc38f8a3276a4177f2","size":{"x":32,"y":1,"z":32}},{"blockCount":38,"bytes":1797,"file":"chunks/y045-z160-x000.json","offset":{"x":0,"y":45,"z":160},"requirements":{"minecraft:bricks":5,"minecraft:glass":7,"minecraft:polished_diorite":20,"minecraft:sandstone":1,"minecraft:stone_bricks":5},"sha256":"d5a4539d986d3554a6d5cbaf0ee11951323583f9b1d967b8e0b5c04ba9d468a6","size":{"x":32,"y":1,"z":32}},{"blockCount":93,"bytes":2784,"file":"chunks/y045-z160-x032.json","offset":{"x":32,"y":45,"z":160},"requirements":{"minecraft:bricks":15,"minecraft:glass":14,"minecraft:polished_diorite":47,"minecraft:sandstone":6,"minecraft:stone_bricks":11},"sha256":"7b21da61c08cca62a721fe3c131d09996d1e777d8122f0110c5204b3e321a748","size":{"x":32,"y":1,"z":32}},{"blockCount":105,"bytes":3157,"file":"chunks/y045-z160-x064.json","offset":{"x":64,"y":45,"z":160},"requirements":{"minecraft:bricks":24,"minecraft:glass":9,"minecraft:oak_planks":4,"minecraft:polished_diorite":45,"minecraft:sandstone":11,"minecraft:stone_bricks":12},"sha256":"e4b855e1e21c8473792dfdb9c864f93f4356b6255c729a343c2a59805bbdd4a0","size":{"x":32,"y":1,"z":32}},{"blockCount":16,"bytes":1081,"file":"chunks/y045-z160-x096.json","offset":{"x":96,"y":45,"z":160},"requirements":{"minecraft:bricks":8,"minecraft:glass":8},"sha256":"8bb7816980ba537450ec287e19ab854e03420383295d60220641f2228d13cbff","size":{"x":32,"y":1,"z":32}},{"blockCount":71,"bytes":2575,"file":"chunks/y045-z160-x128.json","offset":{"x":128,"y":45,"z":160},"requirements":{"minecraft:bricks":23,"minecraft:glass":11,"minecraft:oak_planks":3,"minecraft:polished_diorite":19,"minecraft:sandstone":9,"minecraft:stone_bricks":6},"sha256":"f16f6b9d2d17469aae1b224aac67bcf0613e2d3cc6f03f7ab630379a082b69fa","size":{"x":32,"y":1,"z":32}},{"blockCount":95,"bytes":2695,"file":"chunks/y045-z160-x160.json","offset":{"x":160,"y":45,"z":160},"requirements":{"minecraft:bricks":19,"minecraft:glass":12,"minecraft:oak_planks":1,"minecraft:polished_diorite":45,"minecraft:sandstone":7,"minecraft:stone_bricks":11},"sha256":"8609636e144190bd10618ad273e4cdc23c74b1a5e8dc1dfaf8de487d8b2db265","size":{"x":32,"y":1,"z":32}},{"blockCount":238,"bytes":4436,"file":"chunks/y045-z160-x192.json","offset":{"x":192,"y":45,"z":160},"requirements":{"minecraft:bricks":136,"minecraft:glass":19,"minecraft:polished_diorite":53,"minecraft:sandstone":8,"minecraft:stone_bricks":22},"sha256":"733a1e2b0c881ca69fc2dc1452c95a7cb1c18c937d245a123d1e71a4a087a270","size":{"x":32,"y":1,"z":32}},{"blockCount":115,"bytes":3426,"file":"chunks/y045-z160-x224.json","offset":{"x":224,"y":45,"z":160},"requirements":{"minecraft:bricks":60,"minecraft:glass":12,"minecraft:polished_diorite":43},"sha256":"4679d984dacab0a93b33addb042efa4b6b0bac602fa560b796841d97a1e09fc5","size":{"x":32,"y":1,"z":32}},{"blockCount":8,"bytes":930,"file":"chunks/y045-z160-x256.json","offset":{"x":256,"y":45,"z":160},"requirements":{"minecraft:oak_planks":1,"minecraft:spruce_planks":2,"minecraft:stone_bricks":5},"sha256":"ba39fb242d1215cc1c98065a956129134c2257c79ac0f3843fe2c320b477faa0","size":{"x":32,"y":1,"z":32}},{"blockCount":11,"bytes":1005,"file":"chunks/y045-z160-x288.json","offset":{"x":288,"y":45,"z":160},"requirements":{"minecraft:oak_planks":3,"minecraft:spruce_planks":2,"minecraft:stone_bricks":6},"sha256":"fea6fb5e89b8591fa341b3c76092020152c6c20a1fbdb584ed3f7048a49c7036","size":{"x":32,"y":1,"z":32}},{"blockCount":1,"bytes":629,"file":"chunks/y045-z160-x320.json","offset":{"x":320,"y":45,"z":160},"requirements":{"minecraft:cobbled_deepslate":1},"sha256":"b66eb13664f0d2bcf3c9c2df716079be28cefee3bf2d888db52a6b9e146c5c95","size":{"x":32,"y":1,"z":32}},{"blockCount":7,"bytes":885,"file":"chunks/y045-z160-x352.json","offset":{"x":352,"y":45,"z":160},"requirements":{"minecraft:cobbled_deepslate":7},"sha256":"abdb22c5016d82f41edebb9d412631b5919ceb8eeaa0f6c579432e8c802234cc","size":{"x":32,"y":1,"z":32}},{"blockCount":93,"bytes":2778,"file":"chunks/y045-z192-x064.json","offset":{"x":64,"y":45,"z":192},"requirements":{"minecraft:bricks":23,"minecraft:glass":9,"minecraft:polished_diorite":44,"minecraft:sandstone":4,"minecraft:stone_bricks":13},"sha256":"377371bfed78fc4e7bc84cae31725c839dc48d502f9028f890f7ecc81b2962ec","size":{"x":32,"y":1,"z":32}},{"blockCount":175,"bytes":2831,"file":"chunks/y045-z192-x096.json","offset":{"x":96,"y":45,"z":192},"requirements":{"minecraft:bricks":72,"minecraft:cobbled_deepslate":4,"minecraft:glass":5,"minecraft:oak_planks":3,"minecraft:polished_diorite":65,"minecraft:sandstone":9,"minecraft:stone_bricks":17},"sha256":"7687dd2734554a9a02e6c1b7028cc1bad2bcf8e7ee5b69361da3ea4aeed62c1b","size":{"x":32,"y":1,"z":32}},{"blockCount":192,"bytes":4092,"file":"chunks/y045-z192-x128.json","offset":{"x":128,"y":45,"z":192},"requirements":{"minecraft:bricks":59,"minecraft:cobbled_deepslate":4,"minecraft:glass":14,"minecraft:oak_planks":3,"minecraft:polished_diorite":77,"minecraft:sandstone":14,"minecraft:stone_bricks":21},"sha256":"610a88fb3193843e6da8325fa7b478502cc3cf09912e9e8a5e4485821a658dc9","size":{"x":32,"y":1,"z":32}},{"blockCount":6,"bytes":844,"file":"chunks/y045-z192-x160.json","offset":{"x":160,"y":45,"z":192},"requirements":{"minecraft:polished_diorite":6},"sha256":"47ce230fafe186a639c8ac3f298cd19007e426dfc13bf35a0010f808f7d5bd6c","size":{"x":32,"y":1,"z":32}},{"blockCount":233,"bytes":4890,"file":"chunks/y046-z000-x352.json","offset":{"x":352,"y":46,"z":0},"requirements":{"minecraft:bricks":29,"minecraft:cobbled_deepslate":24,"minecraft:glass":22,"minecraft:oak_planks":1,"minecraft:polished_diorite":67,"minecraft:sandstone":24,"minecraft:spruce_planks":23,"minecraft:stone_bricks":43},"sha256":"b2bb3be8a8d222cb5ce815016b7476f0a21eae7da9a45f6b462da419cfaab47c","size":{"x":32,"y":1,"z":32}},{"blockCount":340,"bytes":5080,"file":"chunks/y046-z000-x384.json","offset":{"x":384,"y":46,"z":0},"requirements":{"minecraft:glass":13,"minecraft:oak_planks":19,"minecraft:polished_diorite":66,"minecraft:sandstone":93,"minecraft:spruce_planks":91,"minecraft:stone_bricks":58},"sha256":"1f7bf52e41a569ecc6f13018feefd0bf87e1f6b215a45b65ec680b9a88372824","size":{"x":32,"y":1,"z":32}},{"blockCount":162,"bytes":4105,"file":"chunks/y046-z032-x352.json","offset":{"x":352,"y":46,"z":32},"requirements":{"minecraft:cobbled_deepslate":30,"minecraft:glass":16,"minecraft:oak_planks":12,"minecraft:sandstone":16,"minecraft:spruce_planks":10,"minecraft:stone_bricks":78},"sha256":"d49a488e6de8c6f4518609f3bc4cd14e93093d23f2dd0156d4625a0d170dd423","size":{"x":32,"y":1,"z":32}},{"blockCount":49,"bytes":1301,"file":"chunks/y046-z032-x384.json","offset":{"x":384,"y":46,"z":32},"requirements":{"minecraft:oak_planks":5,"minecraft:polished_diorite":18,"minecraft:sandstone":24,"minecraft:stone_bricks":2},"sha256":"d8652745c9d7e1968cefd5d987fd4d64fc1548f389ea7a5d9eb1e6a3f4ab4736","size":{"x":32,"y":1,"z":32}},{"blockCount":120,"bytes":3429,"file":"chunks/y046-z064-x064.json","offset":{"x":64,"y":46,"z":64},"requirements":{"minecraft:bricks":29,"minecraft:glass":12,"minecraft:polished_diorite":48,"minecraft:sandstone":7,"minecraft:stone_bricks":24},"sha256":"9afefb2c65078ca30f9112cc81d973ce3850f3276892f4fbcfbcce2851b24736","size":{"x":32,"y":1,"z":32}},{"blockCount":159,"bytes":2906,"file":"chunks/y046-z064-x096.json","offset":{"x":96,"y":46,"z":64},"requirements":{"minecraft:bricks":67,"minecraft:cobbled_deepslate":1,"minecraft:glass":7,"minecraft:oak_planks":3,"minecraft:polished_diorite":55,"minecraft:sandstone":11,"minecraft:stone_bricks":15},"sha256":"67b5e2a3cb6f124500c7d2daf1509039a4818b9eaaad8f8702b82f270e3dbbb8","size":{"x":32,"y":1,"z":32}},{"blockCount":218,"bytes":4665,"file":"chunks/y046-z064-x128.json","offset":{"x":128,"y":46,"z":64},"requirements":{"minecraft:bricks":66,"minecraft:cobbled_deepslate":1,"minecraft:glass":19,"minecraft:oak_planks":3,"minecraft:polished_diorite":80,"minecraft:sandstone":17,"minecraft:stone_bricks":32},"sha256":"e542f09c2f932d84aacd6e2636f67e4c97ec901bcfc8b3c95191f9de75481c34","size":{"x":32,"y":1,"z":32}},{"blockCount":7,"bytes":881,"file":"chunks/y046-z064-x160.json","offset":{"x":160,"y":46,"z":64},"requirements":{"minecraft:polished_diorite":7},"sha256":"c06f4dc1b380a2ccc3de6e3d1440b2074204b8a8de83e5b6316eb29c2090f37d","size":{"x":32,"y":1,"z":32}},{"blockCount":9,"bytes":875,"file":"chunks/y046-z064-x192.json","offset":{"x":192,"y":46,"z":64},"requirements":{"minecraft:polished_diorite":9},"sha256":"9ecebe45d020404e4c146948c2601314d8eb0ed9a45f6a0bfee826b4e0eed151","size":{"x":32,"y":1,"z":32}},{"blockCount":12,"bytes":915,"file":"chunks/y046-z064-x224.json","offset":{"x":224,"y":46,"z":64},"requirements":{"minecraft:polished_diorite":12},"sha256":"a1b2b15aca336d0c6c51ced0218d873ca340a363dbaa0d6b5c1831b7144f7b34","size":{"x":32,"y":1,"z":32}},{"blockCount":4,"bytes":718,"file":"chunks/y046-z064-x320.json","offset":{"x":320,"y":46,"z":64},"requirements":{"minecraft:cobbled_deepslate":2,"minecraft:polished_diorite":2},"sha256":"54e6c8295666e11d4452064a520fae54badd60873e82c73e00b886ba7a2380d5","size":{"x":32,"y":1,"z":32}},{"blockCount":20,"bytes":952,"file":"chunks/y046-z064-x352.json","offset":{"x":352,"y":46,"z":64},"requirements":{"minecraft:cobbled_deepslate":10,"minecraft:polished_diorite":10},"sha256":"9d39bf751596c30e958d1f249fbe40563b62a61f9507fbe3fffb10b249c4e40d","size":{"x":32,"y":1,"z":32}},{"blockCount":64,"bytes":2432,"file":"chunks/y046-z096-x000.json","offset":{"x":0,"y":46,"z":96},"requirements":{"minecraft:bricks":5,"minecraft:glass":12,"minecraft:polished_diorite":28,"minecraft:sandstone":3,"minecraft:stone_bricks":16},"sha256":"1a76b0e9933025ad0c303aaddedeb8acf61a7c8e5ddfe9ed8da30f2bc4f31263","size":{"x":32,"y":1,"z":32}},{"blockCount":137,"bytes":3622,"file":"chunks/y046-z096-x032.json","offset":{"x":32,"y":46,"z":96},"requirements":{"minecraft:bricks":33,"minecraft:glass":21,"minecraft:oak_planks":2,"minecraft:polished_diorite":46,"minecraft:sandstone":7,"minecraft:spruce_planks":1,"minecraft:stone_bricks":27},"sha256":"c88b44ed9a6522af3c3ab24a9f15cc22686a4e167a6fa3398db4de1738106337","size":{"x":32,"y":1,"z":32}},{"blockCount":108,"bytes":3103,"file":"chunks/y046-z096-x064.json","offset":{"x":64,"y":46,"z":96},"requirements":{"minecraft:bricks":29,"minecraft:glass":16,"minecraft:oak_planks":4,"minecraft:polished_diorite":36,"minecraft:sandstone":9,"minecraft:stone_bricks":14},"sha256":"5b19ea72633d0c39f81b887530c39cb18d6da87a9b257fff6e2a7612f072bf8f","size":{"x":32,"y":1,"z":32}},{"blockCount":23,"bytes":1311,"file":"chunks/y046-z096-x096.json","offset":{"x":96,"y":46,"z":96},"requirements":{"minecraft:bricks":11,"minecraft:glass":12},"sha256":"609b64a6fb52266c04318428c42e859abb23a3edb0e23e95f4aaae1ab4c7a31c","size":{"x":32,"y":1,"z":32}},{"blockCount":67,"bytes":2591,"file":"chunks/y046-z096-x128.json","offset":{"x":128,"y":46,"z":96},"requirements":{"minecraft:bricks":27,"minecraft:glass":17,"minecraft:oak_planks":3,"minecraft:polished_diorite":12,"minecraft:sandstone":5,"minecraft:stone_bricks":3},"sha256":"c1afa05e9f04d70c0487944c08c00b48862bf17be29defa1e508e1dc067e557e","size":{"x":32,"y":1,"z":32}},{"blockCount":123,"bytes":3061,"file":"chunks/y046-z096-x160.json","offset":{"x":160,"y":46,"z":96},"requirements":{"minecraft:bricks":28,"minecraft:glass":24,"minecraft:oak_planks":1,"minecraft:polished_diorite":42,"minecraft:sandstone":7,"minecraft:stone_bricks":21},"sha256":"cc26d2dca80ed4843ff0f91230ec851fbf5579fcd691ac9fcd2e00547b980c78","size":{"x":32,"y":1,"z":32}},{"blockCount":269,"bytes":5064,"file":"chunks/y046-z096-x192.json","offset":{"x":192,"y":46,"z":96},"requirements":{"minecraft:bricks":157,"minecraft:cobbled_deepslate":5,"minecraft:glass":23,"minecraft:oak_planks":2,"minecraft:polished_diorite":41,"minecraft:sandstone":14,"minecraft:stone_bricks":27},"sha256":"eb0ea8112db0b849f20dbea2154441b607a0af21f4cf21a2435d20978c917667","size":{"x":32,"y":1,"z":32}}],"schema":1}
