{"entries":[{"blockCount":156,"bytes":3991,"file":"chunks/y046-z096-x224.json","offset":{"x":224,"y":46,"z":96},"requirements":{"minecraft:bricks":68,"minecraft:cobbled_deepslate":1,"minecraft:glass":9,"minecraft:oak_planks":1,"minecraft:polished_diorite":66,"minecraft:sandstone":5,"minecraft:stone_bricks":6},"sha256":"d895277be7d08bdbb3cedf8f12bb417025c52910df380652f17fb01dfe77c013","size":{"x":32,"y":1,"z":32}},{"blockCount":10,"bytes":889,"file":"chunks/y046-z096-x256.json","offset":{"x":256,"y":46,"z":96},"requirements":{"minecraft:oak_planks":2,"minecraft:spruce_planks":1,"minecraft:stone_bricks":7},"sha256":"40d3ceb8512ccf90cb96022f88789c1e1e2a48028a8375c2642ec697eca84eaa","size":{"x":32,"y":1,"z":32}},{"blockCount":24,"bytes":1341,"file":"chunks/y046-z096-x352.json","offset":{"x":352,"y":46,"z":96},"requirements":{"minecraft:cobbled_deepslate":12,"minecraft:polished_diorite":12},"sha256":"2947761758226d8ebcecf5d5c05dfb9f3eb820ec48f9138bdb7564a6b61098bf","size":{"x":32,"y":1,"z":32}},{"blockCount":97,"bytes":3203,"file":"chunks/y046-z128-x000.json","offset":{"x":0,"y":46,"z":128},"requirements":{"minecraft:bricks":18,"minecraft:glass":18,"minecraft:polished_diorite":31,"minecraft:sandstone":6,"minecraft:stone_bricks":24},"sha256":"8e2b4fc6088a554bb05699725e189a4bfe15245c628726fd96758f3832555307","size":{"x":32,"y":1,"z":32}},{"blockCount":180,"bytes":5131,"file":"chunks/y046-z128-x032.json","offset":{"x":32,"y":46,"z":128},"requirements":{"minecraft:bricks":80,"minecraft:cobbled_deepslate":20,"minecraft:glass":16,"minecraft:oak_planks":32,"minecraft:polished_diorite":12,"minecraft:spruce_planks":1,"minecraft:stone_bricks":19},"sha256":"c3c6c2d8484245a7fdd8fa276dbbbc398f87c1b0e75113cf3c04786270beda5b","size":{"x":32,"y":1,"z":32}},{"blockCount":16,"bytes":1078,"file":"chunks/y046-z128-x064.json","offset":{"x":64,"y":46,"z":128},"requirements":{"minecraft:bricks":8,"minecraft:glass":8},"sha256":"447b6217f64608dd7e74f73e8d4d61d07cd8b38fc986512fef4db71f236c71ae","size":{"x":32,"y":1,"z":32}},{"blockCount":13,"bytes":1038,"file":"chunks/y046-z128-x096.json","offset":{"x":96,"y":46,"z":128},"requirements":{"minecraft:bricks":4,"minecraft:glass":3,"minecraft:spruce_planks":4,"minecraft:stone_bricks":2},"sha256":"15efecbd43c699fa22af5177b6845cc6e58601fca6352519f56b89eb7e72f9f9","size":{"x":32,"y":1,"z":32}},{"blockCount":16,"bytes":1076,"file":"chunks/y046-z128-x128.json","offset":{"x":128,"y":46,"z":128},"requirements":{"minecraft:bricks":8,"minecraft:glass":8},"sha256":"116b9e0d4caac291304759b5dc3c0c5b3cc5293d2c403a8a0ea5c08c6469a2fc","size":{"x":32,"y":1,"z":32}},{"blockCount":19,"bytes":1176,"file":"chunks/y046-z128-x160.json","offset":{"x":160,"y":46,"z":128},"requirements":{"minecraft:bricks":9,"minecraft:glass":10},"sha256":"44d103d5bf983950d3a4c843f190c2f3447c0830fb2377e8fc4d5f9560566d8e","size":{"x":32,"y":1,"z":32}},{"blockCount":73,"bytes":2538,"file":"chunks/y046-z128-x192.json","offset":{"x":192,"y":46,"z":128},"requirements":{"minecraft:bricks":45,"minecraft:glass":9,"minecraft:oak_planks":2,"minecraft:polished_diorite":8,"minecraft:sandstone":5,"minecraft:stone_bricks":4},"sha256":"2d8a7473044c53d45fd2cad82b73c6f532401003c1b585f0ee6779623992fa43","size":{"x":32,"y":1,"z":32}},{"blockCount":151,"bytes":3717,"file":"chunks/y046-z128-x224.json","offset":{"x":224,"y":46,"z":128},"requirements":{"minecraft:bricks":43,"minecraft:cobbled_deepslate":1,"minecraft:glass":1,"minecraft:oak_planks":3,"minecraft:polished_diorite":73,"minecraft:sandstone":13,"minecraft:stone_bricks":17},"sha256":"d7e0f1bb2bec70cbbdb31a33b52c831cd5165a9885d7a20ea3a9cfafc73ded56","size":{"x":32,"y":1,"z":32}},{"blockCount":4,"bytes":764,"file":"chunks/y046-z128-x320.json","offset":{"x":320,"y":46,"z":128},"requirements":{"minecraft:polished_diorite":4},"sha256":"2f9d3e4c86ed322d85e59081db66ac4e6e096c369b8877462166f8e650f2df8d","size":{"x":32,"y":1,"z":32}},{"blockCount":42,"bytes":1854,"file":"chunks/y046-z160-x000.json","offset":{"x":0,"y":46,"z":160},"requirements":{"minecraft:bricks":5,"minecraft:glass":6,"minecraft:polished_diorite":20,"minecraft:sandstone":2,"minecraft:stone_bricks":9},"sha256":"40acf2d960175ef292ec2ff8edb23d7d1d93d54a50370c1fabc527d1e2243605","size":{"x":32,"y":1,"z":32}},{"blockCount":102,"bytes":2670,"file":"chunks/y046-z160-x032.json","offset":{"x":32,"y":46,"z":160},"requirements":{"minecraft:bricks":15,"minecraft:glass":13,"minecraft:polished_diorite":46,"minecraft:sandstone":7,"minecraft:stone_bricks":21},"sha256":"f5566c7dcdd4047673ebc8803250282683316f0c0e46817c74bc1815eeaae60b","size":{"x":32,"y":1,"z":32}},{"blockCount":113,"bytes":3160,"file":"chunks/y046-z160-x064.json","offset":{"x":64,"y":46,"z":160},"requirements":{"minecraft:bricks":24,"minecraft:glass":11,"minecraft:oak_planks":4,"minecraft:polished_diorite":43,"minecraft:sandstone":11,"minecraft:stone_bricks":20},"sha256":"61be44afe3de469d8069bed24d43165e1f578fd4a3d3cff61ffbd103aed31f13","size":{"x":32,"y":1,"z":32}},{"blockCount":18,"bytes":1158,"file":"chunks/y046-z160-x096.json","offset":{"x":96,"y":46,"z":160},"requirements":{"minecraft:bricks":8,"minecraft:glass":10},"sha256":"71ded574cda800e284060fb18daa5c5e313d00fea86989700b42b5ccf19ed5f3","size":{"x":32,"y":1,"z":32}},{"blockCount":77,"bytes":2729,"file":"chunks/y046-z160-x128.json","offset":{"x":128,"y":46,"z":160},"requirements":{"minecraft:bricks":23,"minecraft:glass":14,"minecraft:oak_planks":3,"minecraft:polished_diorite":18,"minecraft:sandstone":10,"minecraft:stone_bricks":9},"sha256":"6aba19d30fd908407cb6c5b61eaf7952b2e25107ec84e1e19fb72dfc2c4572be","size":{"x":32,"y":1,"z":32}},{"blockCount":105,"bytes":2545,"file":"chunks/y046-z160-x160.json","offset":{"x":160,"y":46,"z":160},"requirements":{"minecraft:bricks":19,"minecraft:glass":14,"minecraft:oak_planks":1,"minecraft:polished_diorite":43,"minecraft:sandstone":7,"minecraft:stone_bricks":21},"sha256":"7d478ae100da83ee3527249424c16ecce0a03816fc2cf51e627bf433bf601672","size":{"x":32,"y":1,"z":32}},{"blockCount":238,"bytes":4600,"file":"chunks/y046-z160-x192.json","offset":{"x":192,"y":46,"z":160},"requirements":{"minecraft:bricks":133,"minecraft:cobbled_deepslate":5,"minecraft:glass":16,"minecraft:polished_diorite":50,"minecraft:sandstone":9,"minecraft:stone_bricks":25},"sha256":"87175e536aed071f147e4c228206e4077f141861b3ff8a11176debd0229f47d2","size":{"x":32,"y":1,"z":32}},{"blockCount":109,"bytes":3338,"file":"chunks/y046-z160-x224.json","offset":{"x":224,"y":46,"z":160},"requirements":{"minecraft:bricks":56,"minecraft:glass":8,"minecraft:polished_diorite":43,"minecraft:stone_bricks":2},"sha256":"c6afda1674870607f422b79e159fd8e844feed2b14b9098170059cd7e84111b4","size":{"x":32,"y":1,"z":32}},{"blockCount":10,"bytes":890,"file":"chunks/y046-z160-x256.json","offset":{"x":256,"y":46,"z":160},"requirements":{"minecraft:oak_planks":2,"minecraft:spruce_planks":1,"minecraft:stone_bricks":7},"sha256":"2e7a6bb828357e09abd2f876cde79d44dcf472a922a3ebe565b954db695dfbe3","size":{"x":32,"y":1,"z":32}},{"blockCount":5,"bytes":785,"file":"chunks/y046-z160-x288.json","offset":{"x":288,"y":46,"z":160},"requirements":{"minecraft:oak_planks":1,"minecraft:stone_bricks":4},"sha256":"463395eb9b164ce109ca90b0139dccbed371f75ec90642e488ce36215068fb2b","size":{"x":32,"y":1,"z":32}},{"blockCount":2,"bytes":629,"file":"chunks/y046-z160-x320.json","offset":{"x":320,"y":46,"z":160},"requirements":{"minecraft:cobbled_deepslate":2},"sha256":"8ef47a5c0b5d168d0b5e1868dd567a0a9c219883b57499ca2183fc454391d31f","size":{"x":32,"y":1,"z":32}},{"blockCount":43,"bytes":1613,"file":"chunks/y046-z160-x352.json","offset":{"x":352,"y":46,"z":160},"requirements":{"minecraft:cobbled_deepslate":22,"minecraft:polished_diorite":21},"sha256":"9591788e22970953c42b5b38f72b02ebd1916911bb3084309ce4a68a949d0cbb","size":{"x":32,"y":1,"z":32}},{"blockCount":99,"bytes":2911,"file":"chunks/y046-z192-x064.json","offset":{"x":64,"y":46,"z":192},"requirements":{"minecraft:bricks":26,"minecraft:glass":9,"minecraft:polished_diorite":41,"minecraft:sandstone":5,"minecraft:stone_bricks":18},"sha256":"28c93f5b7f1be635cd5f6218f468f4c4783a48fef99839d772664d43506ced1c","size":{"x":32,"y":1,"z":32}},{"blockCount":156,"bytes":2829,"file":"chunks/y046-z192-x096.json","offset":{"x":96,"y":46,"z":192},"requirements":{"minecraft:bricks":66,"minecraft:cobbled_deepslate":1,"minecraft:glass":5,"minecraft:oak_planks":3,"minecraft:polished_diorite":55,"minecraft:sandstone":11,"minecraft:stone_bricks":15},"sha256":"a441f67ff9091e4f5e7f92fd912c9c5e716a95ac185dc0f71ba98f46895e6299","size":{"x":32,"y":1,"z":32}},{"blockCount":195,"bytes":4131,"file":"chunks/y046-z192-x128.json","offset":{"x":128,"y":46,"z":192},"requirements":{"minecraft:bricks":62,"minecraft:cobbled_deepslate":1,"minecraft:glass":14,"minecraft:oak_planks":3,"minecraft:polished_diorite":74,"minecraft:sandstone":15,"minecraft:stone_bricks":26},"sha256":"19387b1ea3949c12fb4f5afede92533f93557b154a09742642a101c8ee8cf3a7","size":{"x":32,"y":1,"z":32}},{"blockCount":6,"bytes":844,"file":"chunks/y046-z192-x160.json","offset":{"x":160,"y":46,"z":192},"requirements":{"minecraft:polished_diorite":6},"sha256":"3c900583eb940f25d4f4729070a4589bdaf7144ceb38c596fe9153b7c0749752","size":{"x":32,"y":1,"z":32}},{"blockCount":2,"bytes":647,"file":"chunks/y046-z192-x320.json","offset":{"x":320,"y":46,"z":192},"requirements":{"minecraft:polished_diorite":2},"sha256":"9ac6c8ae23fe04b44d562823956ff55e7e608d4c25c395ce0e4b3915e2dbed81","size":{"x":32,"y":1,"z":32}},{"blockCount":1,"bytes":628,"file":"chunks/y046-z192-x352.json","offset":{"x":352,"y":46,"z":192},"requirements":{"minecraft:polished_diorite":1},"sha256":"b24cb50b6111230413c99805271d6a000f3b58f1627f3bcf7b61f8d62bd8f913","size":{"x":32,"y":1,"z":32}},{"blockCount":248,"bytes":4727,"file":"chunks/y047-z000-x352.json","offset":{"x":352,"y":47,"z":0},"requirements":{"minecraft:bricks":28,"minecraft:cobbled_deepslate":15,"minecraft:glass":20,"minecraft:polished_diorite":56,"minecraft:sandstone":26,"minecraft:spruce_planks":59,"minecraft:stone_bricks":44},"sha256":"1f34b1434738299e086ec98333bf0f2752ec4abc13b7dd757c261ba80e49ef04","size":{"x":32,"y":1,"z":32}},{"blockCount":334,"bytes":6800,"file":"chunks/y047-z000-x384.json","offset":{"x":384,"y":47,"z":0},"requirements":{"minecraft:glass":5,"minecraft:oak_planks":48,"minecraft:polished_diorite":126,"minecraft:sandstone":14,"minecraft:spruce_planks":14,"minecraft:stone_bricks":127},"sha256":"869511affccd31c691811750eab1bb059c690c880403f6f3aaa465578d523f9b","size":{"x":32,"y":1,"z":32}},{"blockCount":76,"bytes":2946,"file":"chunks/y047-z032-x352.json","offset":{"x":352,"y":47,"z":32},"requirements":{"minecraft:cobbled_deepslate":10,"minecraft:glass":44,"minecraft:spruce_planks":6,"minecraft:stone_bricks":16},"sha256":"32361687e865a9c11f6e9a4bb777bdce00771f3e13f53a13aa3fd9966171e0d5","size":{"x":32,"y":1,"z":32}},{"blockCount":51,"bytes":1241,"file":"chunks/y047-z032-x384.json","offset":{"x":384,"y":47,"z":32},"requirements":{"minecraft:oak_planks":17,"minecraft:polished_diorite":20,"minecraft:stone_bricks":14},"sha256":"345066ae737fbd17c3386dce51ab659b0b2054010f2cf030bfbec5f550b81d2d","size":{"x":32,"y":1,"z":32}},{"blockCount":135,"bytes":3753,"file":"chunks/y047-z064-x064.json","offset":{"x":64,"y":47,"z":64},"requirements":{"minecraft:bricks":26,"minecraft:glass":12,"minecraft:polished_diorite":52,"minecraft:sandstone":8,"minecraft:stone_bricks":37},"sha256":"9501272114e0624af55942e4c3d382209649316797c880ae052375a78da0aa85","size":{"x":32,"y":1,"z":32}},{"blockCount":168,"bytes":2818,"file":"chunks/y047-z064-x096.json","offset":{"x":96,"y":47,"z":64},"requirements":{"minecraft:bricks":68,"minecraft:glass":8,"minecraft:oak_planks":3,"minecraft:polished_diorite":60,"minecraft:sandstone":11,"minecraft:stone_bricks":18},"sha256":"d5fdc0f10270b31840fb01351798fe0752329699c0c6fc073b3fe3b13db756b8","size":{"x":32,"y":1,"z":32}},{"blockCount":223,"bytes":4692,"file":"chunks/y047-z064-x128.json","offset":{"x":128,"y":47,"z":64},"requirements":{"minecraft:bricks":63,"minecraft:glass":20,"minecraft:oak_planks":3,"minecraft:polished_diorite":86,"minecraft:sandstone":18,"minecraft:stone_bricks":33},"sha256":"06ca7d3571129eddc0720ac2ca3d2de74ef47185c6ceee3bc855c4dfec45a4de","size":{"x":32,"y":1,"z":32}},{"blockCount":19,"bytes":1237,"file":"chunks/y047-z064-x160.json","offset":{"x":160,"y":47,"z":64},"requirements":{"minecraft:polished_diorite":7,"minecraft:stone_bricks":12},"sha256":"e24d975107b5e8ab1fc564f7ab18dea1df0f5edaf252c4709dda23cdc404e0c3","size":{"x":32,"y":1,"z":32}},{"blockCount":17,"bytes":1055,"file":"chunks/y047-z064-x192.json","offset":{"x":192,"y":47,"z":64},"requirements":{"minecraft:polished_diorite":9,"minecraft:stone_bricks":8},"sha256":"d7077d3f04f120aabd9eeb0e82a32f34ac6c9ba31a0bfff67b00c4b924c0838d","size":{"x":32,"y":1,"z":32}},{"blockCount":23,"bytes":1115,"file":"chunks/y047-z064-x224.json","offset":{"x":224,"y":47,"z":64},"requirements":{"minecraft:polished_diorite":12,"minecraft:stone_bricks":11},"sha256":"fc171921bff2668d8a981e39cccc18beb58baacef2d951213545826cae949cff","size":{"x":32,"y":1,"z":32}},{"blockCount":2,"bytes":718,"file":"chunks/y047-z064-x320.json","offset":{"x":320,"y":47,"z":64},"requirements":{"minecraft:cobbled_deepslate":1,"minecraft:polished_diorite":1},"sha256":"441ac7af1e89c79786f35a651f5ee2b0d2e72ac8aee17225785f4222ee7e63da","size":{"x":32,"y":1,"z":32}},{"blockCount":10,"bytes":1026,"file":"chunks/y047-z064-x352.json","offset":{"x":352,"y":47,"z":64},"requirements":{"minecraft:cobbled_deepslate":3,"minecraft:polished_diorite":7},"sha256":"cb400a49211291651bf69b1f8a31fe3076075da7257217837235e7de7988892e","size":{"x":32,"y":1,"z":32}},{"blockCount":82,"bytes":2794,"file":"chunks/y047-z096-x000.json","offset":{"x":0,"y":47,"z":96},"requirements":{"minecraft:bricks":5,"minecraft:glass":13,"minecraft:polished_diorite":28,"minecraft:sandstone":2,"minecraft:stone_bricks":34},"sha256":"7eac09cbf937edb3496a0c155caa9f43d509e4f13b471ec034f732f5ffdef45e","size":{"x":32,"y":1,"z":32}},{"blockCount":152,"bytes":3964,"file":"chunks/y047-z096-x032.json","offset":{"x":32,"y":47,"z":96},"requirements":{"minecraft:bricks":30,"minecraft:glass":22,"minecraft:oak_planks":2,"minecraft:polished_diorite":47,"minecraft:sandstone":6,"minecraft:spruce_planks":7,"minecraft:stone_bricks":38},"sha256":"29f8508a0a3d540d53d82b545cacf4ddc18ff0b414f1558f76ed423c46dc24ee","size":{"x":32,"y":1,"z":32}},{"blockCount":118,"bytes":3385,"file":"chunks/y047-z096-x064.json","offset":{"x":64,"y":47,"z":96},"requirements":{"minecraft:bricks":29,"minecraft:glass":14,"minecraft:oak_planks":4,"minecraft:polished_diorite":37,"minecraft:sandstone":9,"minecraft:stone_bricks":25},"sha256":"794e9cd4d31241af913d56c05ef5143e10b73d0606205c0315412bd0c0613d5d","size":{"x":32,"y":1,"z":32}},{"blockCount":21,"bytes":1235,"file":"chunks/y047-z096-x096.json","offset":{"x":96,"y":47,"z":96},"requirements":{"minecraft:bricks":11,"minecraft:glass":10},"sha256":"d11a12ea35043ec2d67971f2a0215d50904db8c9aadb7adf6a93ee19fcd40ca2","size":{"x":32,"y":1,"z":32}},{"blockCount":66,"bytes":2514,"file":"chunks/y047-z096-x128.json","offset":{"x":128,"y":47,"z":96},"requirements":{"minecraft:bricks":27,"minecraft:glass":14,"minecraft:oak_planks":3,"minecraft:polished_diorite":12,"minecraft:sandstone":5,"minecraft:stone_bricks":5},"sha256":"f153c6cd74a67f717e60fdf0cfcc79adf8202bde81fb3e18aa6c0b5c69cd14cc","size":{"x":32,"y":1,"z":32}},{"blockCount":135,"bytes":3573,"file":"chunks/y047-z096-x160.json","offset":{"x":160,"y":47,"z":96},"requirements":{"minecraft:bricks":28,"minecraft:glass":22,"minecraft:oak_planks":1,"minecraft:polished_diorite":44,"minecraft:sandstone":7,"minecraft:stone_bricks":33},"sha256":"747c4a47c8360de41dea6d541c360ec754576215d2f01c768f985c8ede43275f","size":{"x":32,"y":1,"z":32}},{"blockCount":261,"bytes":4992,"file":"chunks/y047-z096-x192.json","offset":{"x":192,"y":47,"z":96},"requirements":{"minecraft:bricks":154,"minecraft:glass":18,"minecraft:oak_planks":2,"minecraft:polished_diorite":40,"minecraft:sandstone":11,"minecraft:stone_bricks":36},"sha256":"d9a0e8af2f794ef5c405bafdb816321f957b1ccb2e79eb1be663f640949e5b2c","size":{"x":32,"y":1,"z":32}},{"blockCount":173,"bytes":4410,"file":"chunks/y047-z096-x224.json","offset":{"x":224,"y":47,"z":96},"requirements":{"minecraft:bricks":72,"minecraft:cobbled_deepslate":4,"minecraft:glass":9,"minecraft:oak_planks":1,"minecraft:polished_diorite":61,"minecraft:sandstone":5,"minecraft:stone_bricks":21},"sha256":"da12e283766d61b297000f74d4b120927295a446717465d52c2b2fbf160354a2","size":{"x":32,"y":1,"z":32}},{"blockCount":6,"bytes":784,"file":"chunks/y047-z096-x256.json","offset":{"x":256,"y":47,"z":96},"requirements":{"minecraft:oak_planks":1,"minecraft:stone_bricks":5},"sha256":"416b13fc90adf36cae5e3b24852e5930ecc0f0e4be2b478cf959fc1d68e41327","size":{"x":32,"y":1,"z":32}},{"blockCount":12,"bytes":1111,"file":"chunks/y047-z096-x352.json","offset":{"x":352,"y":47,"z":96},"requirements":{"minecraft:cobbled_deepslate":4,"minecraft:polished_diorite":8},"sha256":"b108ead88693052fa690f560dfde36d803f4220b0c39b067dff66e79c8a3b0c3","size":{"x":32,"y":1,"z":32}},{"blockCount":102,"bytes":3279,"file":"chunks/y047-z128-x000.json","offset":{"x":0,"y":47,"z":128},"requirements":{"minecraft:bricks":18,"minecraft:glass":18,"minecraft:polished_diorite":31,"minecraft:sandstone":6,"minecraft:stone_bricks":29},"sha256":"749625a0400ee661d5ff61a619cb596e03bb6961016cbe3bdec2fde211ba2835","size":{"x":32,"y":1,"z":32}},{"blockCount":200,"bytes":5131,"file":"chunks/y047-z128-x032.json","offset":{"x":32,"y":47,"z":128},"requirements":{"minecraft:bricks":99,"minecraft:cobbled_deepslate":20,"minecraft:glass":16,"minecraft:oak_planks":26,"minecraft:polished_diorite":14,"minecraft:spruce_planks":7,"minecraft:stone_bricks":18},"sha256":"337c2e4d87b7730d1f4fe94b13b84a01bb2c7f3daf4932e483cbc8b2e5ec7fa3","size":{"x":32,"y":1,"z":32}},{"blockCount":16,"bytes":1078,"file":"chunks/y047-z128-x064.json","offset":{"x":64,"y":47,"z":128},"requirements":{"minecraft:bricks":8,"minecraft:glass":8},"sha256":"92443e3793e8223d52396f1e4bee53fcd7e992a52fad2ca672c3a3dcbd4202a3","size":{"x":32,"y":1,"z":32}},{"blockCount":9,"bytes":915,"file":"chunks/y047-z128-x096.json","offset":{"x":96,"y":47,"z":128},"requirements":{"minecraft:bricks":4,"minecraft:glass":4,"minecraft:spruce_planks":1},"sha256":"a45a834049181fa352c793316523c756b999f58a64eec6cdc8deeb437046e991","size":{"x":32,"y":1,"z":32}},{"blockCount":16,"bytes":1076,"file":"chunks/y047-z128-x128.json","offset":{"x":128,"y":47,"z":128},"requirements":{"minecraft:bricks":8,"minecraft:glass":8},"sha256":"bed5a2e3ee970d914624aa6ed7774fbf24f18745d75a8277ff66910a8873a5b7","size":{"x":32,"y":1,"z":32}},{"blockCount":19,"bytes":1176,"file":"chunks/y047-z128-x160.json","offset":{"x":160,"y":47,"z":128},"requirements":{"minecraft:bricks":9,"minecraft:glass":10},"sha256":"c9aa1b0883141c46b829f2a6da1aa2467d01ee05d6b07be33033d7dcbac6d7e6","size":{"x":32,"y":1,"z":32}},{"blockCount":66,"bytes":2124,"file":"chunks/y047-z128-x192.json","offset":{"x":192,"y":47,"z":128},"requirements":{"minecraft:bricks":46,"minecraft:glass":7,"minecraft:oak_planks":2,"minecraft:sandstone":3,"minecraft:stone_bricks":8},"sha256":"fbe74122ac28dfd72874e77126be2a09aadcd2b6013b65551c78ba59411aa50e","size":{"x":32,"y":1,"z":32}},{"blockCount":155,"bytes":3831,"file":"chunks/y047-z128-x224.json","offset":{"x":224,"y":47,"z":128},"requirements":{"minecraft:bricks":43,"minecraft:cobbled_deepslate":4,"minecraft:glass":1,"minecraft:oak_planks":3,"minecraft:polished_diorite":74,"minecraft:sandstone":13,"minecraft:stone_bricks":17},"sha256":"f708526b75739dd219da66cbd09cfda8913d47576e4eac55d250dccb33f79255","size":{"x":32,"y":1,"z":32}},{"blockCount":5,"bytes":791,"file":"chunks/y047-z128-x320.json","offset":{"x":320,"y":47,"z":128},"requirements":{"minecraft:polished_diorite":4,"minecraft:stone_bricks":1},"sha256":"da570ac724aa1d2f70e33711d9afea9a14a0386549c7523700afae0951c8fed6","size":{"x":32,"y":1,"z":32}},{"blockCount":55,"bytes":2141,"file":"chunks/y047-z160-x000.json","offset":{"x":0,"y":47,"z":160},"requirements":{"minecraft:bricks":5,"minecraft:glass":7,"minecraft:polished_diorite":20,"minecraft:sandstone":1,"minecraft:stone_bricks":22},"sha256":"e557f87a9c05154f7f4260fc180d88985577e4f731f227d9de8b594e1a8cf9ac","size":{"x":32,"y":1,"z":32}},{"blockCount":112,"bytes":3088,"file":"chunks/y047-z160-x032.json","offset":{"x":32,"y":47,"z":160},"requirements":{"minecraft:bricks":15,"minecraft:glass":14,"minecraft:polished_diorite":47,"minecraft:sandstone":6,"minecraft:stone_bricks":30},"sha256":"be45c4c392da7c849938d6f09b4b6a1acbb813629dc2e3d9d29726a8657c6652","size":{"x":32,"y":1,"z":32}},{"blockCount":124,"bytes":3461,"file":"chunks/y047-z160-x064.json","offset":{"x":64,"y":47,"z":160},"requirements":{"minecraft:bricks":24,"minecraft:glass":9,"minecraft:oak_planks":4,"minecraft:polished_diorite":45,"minecraft:sandstone":11,"minecraft:stone_bricks":31},"sha256":"1a037941575ee68029e55e4795095a66869bdd7d029ae0d32b4d520b5cb4b50b","size":{"x":32,"y":1,"z":32}},{"blockCount":16,"bytes":1081,"file":"chunks/y047-z160-x096.json","offset":{"x":96,"y":47,"z":160},"requirements":{"minecraft:bricks":8,"minecraft:glass":8},"sha256":"1b7f2dc7272989233dc12795e1f20858dfde86ae577c98261d28eab6ad0a0f8f","size":{"x":32,"y":1,"z":32}},{"blockCount":74,"bytes":2632,"file":"chunks/y047-z160-x128.json","offset":{"x":128,"y":47,"z":160},"requirements":{"minecraft:bricks":23,"minecraft:glass":11,"minecraft:oak_planks":3,"minecraft:polished_diorite":19,"minecraft:sandstone":9,"minecraft:stone_bricks":9},"sha256":"4032995f9d485da69fb88873b60022fab6fcd9e45524f40a076c923749a60268","size":{"x":32,"y":1,"z":32}},{"blockCount":119,"bytes":3133,"file":"chunks/y047-z160-x160.json","offset":{"x":160,"y":47,"z":160},"requirements":{"minecraft:bricks":19,"minecraft:glass":12,"minecraft:oak_planks":1,"minecraft:polished_diorite":45,"minecraft:sandstone":7,"minecraft:stone_bricks":35},"sha256":"e2429e3965aac88141dc65958e30279e306b1641c7dbe9ec236d822ab23d476c","size":{"x":32,"y":1,"z":32}},{"blockCount":240,"bytes":4720,"file":"chunks/y047-z160-x192.json","offset":{"x":192,"y":47,"z":160},"requirements":{"minecraft:bricks":130,"minecraft:glass":11,"minecraft:polished_diorite":49,"minecraft:sandstone":8,"minecraft:stone_bricks":42},"sha256":"78bd7eb6f39cd72b6441a2b5c181e7b7dec74d994aedd2d3c30aed93aafd4f30","size":{"x":32,"y":1,"z":32}},{"blockCount":132,"bytes":3720,"file":"chunks/y047-z160-x224.json","offset":{"x":224,"y":47,"z":160},"requirements":{"minecraft:bricks":60,"minecraft:glass":8,"minecraft:polished_diorite":42,"minecraft:stone_bricks":22},"sha256":"c2c821a72fea147d7382354d8ac54ab1f4fff49090e16b0a1ce16a549ecba757","size":{"x":32,"y":1,"z":32}},{"blockCount":6,"bytes":785,"file":"chunks/y047-z160-x256.json","offset":{"x":256,"y":47,"z":160},"requirements":{"minecraft:oak_planks":1,"minecraft:stone_bricks":5},"sha256":"07410628bcc03bfbd4919c79f0c612604bd4d88d746ba43472ecf9b0e03503a5","size":{"x":32,"y":1,"z":32}},{"blockCount":4,"bytes":766,"file":"chunks/y047-z160-x288.json","offset":{"x":288,"y":47,"z":160},"requirements":{"minecraft:oak_planks":1,"minecraft:stone_bricks":3},"sha256":"3b39fdcb25c07bb46f6c17769a713e1f2316894dc935c24b5cc35d7e10397c51","size":{"x":32,"y":1,"z":32}},{"blockCount":1,"bytes":629,"file":"chunks/y047-z160-x320.json","offset":{"x":320,"y":47,"z":160},"requirements":{"minecraft:cobbled_deepslate":1},"sha256":"19acaf8edf4375157f688aa52649b06f3132cfd92584285b0469d1e4768b4c13","size":{"x":32,"y":1,"z":32}},{"blockCount":21,"bytes":1460,"file":"chunks/y047-z160-x352.json","offset":{"x":352,"y":47,"z":160},"requirements":{"minecraft:cobbled_deepslate":7,"minecraft:polished_diorite":14},"sha256":"4e148f163c2cc16471acf5a353720ca6f9dbef4f9bd17c8bb13322c79d5ac518","size":{"x":32,"y":1,"z":32}},{"blockCount":113,"bytes":3216,"file":"chunks/y047-z192-x064.json","offset":{"x":64,"y":47,"z":192},"requirements":{"minecraft:bricks":23,"minecraft:glass":9,"minecraft:polished_diorite":44,"minecraft:sandstone":6,"minecraft:stone_bricks":31},"sha256":"b19c2512bf3e660f10e26aa0b3ae747588324a80019a9afb7ad06e7998d637b4","size":{"x":32,"y":1,"z":32}},{"blockCount":165,"bytes":2742,"file":"chunks/y047-z192-x096.json","offset":{"x":96,"y":47,"z":192},"requirements":{"minecraft:bricks":67,"minecraft:glass":6,"minecraft:oak_planks":3,"minecraft:polished_diorite":60,"minecraft:sandstone":11,"minecraft:stone_bricks":18},"sha256":"5ddb5855daa889dd2858347ca2776b10f0d6613d1284685bfae0f52503241fbc","size":{"x":32,"y":1,"z":32}},{"blockCount":201,"bytes":4195,"file":"chunks/y047-z192-x128.json","offset":{"x":128,"y":47,"z":192},"requirements":{"minecraft:bricks":59,"minecraft:glass":15,"minecraft:oak_planks":3,"minecraft:polished_diorite":79,"minecraft:sandstone":16,"minecraft:stone_bricks":29},"sha256":"e40eb324d00d5d9210d8c836d0883c47dd202172bc3fa8880d7d043be1a47e9d","size":{"x":32,"y":1,"z":32}},{"blockCount":16,"bytes":1142,"file":"chunks/y047-z192-x160.json","offset":{"x":160,"y":47,"z":192},"requirements":{"minecraft:polished_diorite":6,"minecraft:stone_bricks":10},"sha256":"e16f90e9edef00f4deff1a22cd4eeef84e89776011d9ad7b099528710121a2b6","size":{"x":32,"y":1,"z":32}},{"blockCount":1,"bytes":647,"file":"chunks/y047-z192-x320.json","offset":{"x":320,"y":47,"z":192},"requirements":{"minecraft:polished_diorite":1},"sha256":"f462cd68539c1829fa06731940c64fcef194712dfe70f24394587de5f8e7103c","size":{"x":32,"y":1,"z":32}},{"blockCount":1,"bytes":628,"file":"chunks/y047-z192-x352.json","offset":{"x":352,"y":47,"z":192},"requirements":{"minecraft:polished_diorite":1},"sha256":"cfd021ff7841da2882b36f694f260d4dd5bcb137cc2f14495dc2aab495d6fa83","size":{"x":32,"y":1,"z":32}},{"blockCount":256,"bytes":3914,"file":"chunks/y048-z000-x352.json","offset":{"x":352,"y":48,"z":0},"requirements":{"minecraft:bricks":8,"minecraft:cobbled_deepslate":25,"minecraft:glass":24,"minecraft:oak_planks":7,"minecraft:polished_diorite":17,"minecraft:sandstone":52,"minecraft:spruce_planks":84,"minecraft:stone_bricks":39},"sha256":"bc93a4d93b210af404406dbc953a5b9eea4e6a4f3b6707803fdd150be542e729","size":{"x":32,"y":1,"z":32}},{"blockCount":310,"bytes":3761,"file":"chunks/y048-z000-x384.json","offset":{"x":384,"y":48,"z":0},"requirements":{"minecraft:glass":4,"minecraft:oak_planks":46,"minecraft:polished_diorite":24,"minecraft:sandstone":20,"minecraft:spruce_planks":9,"minecraft:stone_bricks":207},"sha256":"cc6ef47cc559d29edae40fccce8bdbfa393172ed15e7cf3cc97893323456ac5f","size":{"x":32,"y":1,"z":32}},{"blockCount":76,"bytes":2950,"file":"chunks/y048-z032-x352.json","offset":{"x":352,"y":48,"z":32},"requirements":{"minecraft:cobbled_deepslate":10,"minecraft:glass":44,"minecraft:polished_diorite":16,"minecraft:spruce_planks":6},"sha256":"aa18c9964be8627942082babee00c11ed3576a4a2e3923efec02a7180baa53ef","size":{"x":32,"y":1,"z":32}},{"blockCount":60,"bytes":1088,"file":"chunks/y048-z032-x384.json","offset":{"x":384,"y":48,"z":32},"requirements":{"minecraft:oak_planks":12,"minecraft:polished_diorite":6,"minecraft:stone_bricks":42},"sha256":"fd0f58722983a88e9b5c4269de6fdba5005ff0eaaa60c43d75086089fdb9b56e","size":{"x":32,"y":1,"z":32}},{"blockCount":112,"bytes":3334,"file":"chunks/y048-z064-x064.json","offset":{"x":64,"y":48,"z":64},"requirements":{"minecraft:bricks":29,"minecraft:glass":12,"minecraft:polished_diorite":50,"minecraft:sandstone":8,"minecraft:stone_bricks":13},"sha256":"d2ca87b817f1f0300c42850080735bc4e36fd48dddaa0e6ee567b7e1c8b7051b","size":{"x":32,"y":1,"z":32}},{"blockCount":158,"bytes":2721,"file":"chunks/y048-z064-x096.json","offset":{"x":96,"y":48,"z":64},"requirements":{"minecraft:bricks":61,"minecraft:glass":8,"minecraft:oak_planks":5,"minecraft:polished_diorite":49,"minecraft:sandstone":14,"minecraft:stone_bricks":21},"sha256":"e76c8d08e961d639165a5930679040e3d6f6cff35115a0ebc42997c18fadfcae","size":{"x":32,"y":1,"z":32}},{"blockCount":212,"bytes":4425,"file":"chunks/y048-z064-x128.json","offset":{"x":128,"y":48,"z":64},"requirements":{"minecraft:bricks":66,"minecraft:glass":20,"minecraft:oak_planks":3,"minecraft:polished_diorite":85,"minecraft:sandstone":19,"minecraft:stone_bricks":19},"sha256":"28b6008939474036948030dca8b5fc5e6bc623036b357a95966982c498d1689c","size":{"x":32,"y":1,"z":32}},{"blockCount":7,"bytes":881,"file":"chunks/y048-z064-x160.json","offset":{"x":160,"y":48,"z":64},"requirements":{"minecraft:polished_diorite":7},"sha256":"6e92ad266972bffdb455ee154c4158b49f5d82bd6b59ff9117f8a351452c7969","size":{"x":32,"y":1,"z":32}},{"blockCount":9,"bytes":875,"file":"chunks/y048-z064-x192.json","offset":{"x":192,"y":48,"z":64},"requirements":{"minecraft:polished_diorite":9},"sha256":"6cca792bbd8256c45759cecc5f3f78c58567c017c236395c3055ace93107e40a","size":{"x":32,"y":1,"z":32}},{"blockCount":12,"bytes":915,"file":"chunks/y048-z064-x224.json","offset":{"x":224,"y":48,"z":64},"requirements":{"minecraft:polished_diorite":12},"sha256":"61af80e9a7f2e110779ba7fe6a58d2aa4902257aebd31a35e655a24fc45ce80d","size":{"x":32,"y":1,"z":32}},{"blockCount":57,"bytes":2336,"file":"chunks/y048-z096-x000.json","offset":{"x":0,"y":48,"z":96},"requirements":{"minecraft:bricks":5,"minecraft:glass":13,"minecraft:polished_diorite":28,"minecraft:sandstone":2,"minecraft:stone_bricks":9},"sha256":"2920bf01a4bc0f0f31360d1f109f1ade78b66cec8ab5f282bd1741f52e72ce5c","size":{"x":32,"y":1,"z":32}},{"blockCount":123,"bytes":3660,"file":"chunks/y048-z096-x032.json","offset":{"x":32,"y":48,"z":96},"requirements":{"minecraft:bricks":23,"minecraft:glass":22,"minecraft:oak_planks":2,"minecraft:polished_diorite":47,"minecraft:sandstone":6,"minecraft:spruce_planks":8,"minecraft:stone_bricks":15},"sha256":"f61e78c6a9c5976e87ed4647fe6e754c41ce8c6b32c742af7f6e4e3c02a35131","size":{"x":32,"y":1,"z":32}},{"blockCount":114,"bytes":3538,"file":"chunks/y048-z096-x064.json","offset":{"x":64,"y":48,"z":96},"requirements":{"minecraft:bricks":29,"minecraft:cobbled_deepslate":2,"minecraft:glass":22,"minecraft:oak_planks":4,"minecraft:polished_diorite":37,"minecraft:sandstone":9,"minecraft:stone_bricks":11},"sha256":"7a0f66b2924ff737882c50e3641add8d57b4863b798f8dfaff0b3f311db4036d","size":{"x":32,"y":1,"z":32}},{"blockCount":30,"bytes":1533,"file":"chunks/y048-z096-x096.json","offset":{"x":96,"y":48,"z":96},"requirements":{"minecraft:bricks":11,"minecraft:cobbled_deepslate":2,"minecraft:glass":17},"sha256":"cd05ef8da6c20c31bb033199b0e385330ad3112dc4086e3846a835973e0eb092","size":{"x":32,"y":1,"z":32}},{"blockCount":80,"bytes":2985,"file":"chunks/y048-z096-x128.json","offset":{"x":128,"y":48,"z":96},"requirements":{"minecraft:bricks":27,"minecraft:cobbled_deepslate":3,"minecraft:glass":25,"minecraft:oak_planks":3,"minecraft:polished_diorite":12,"minecraft:sandstone":5,"minecraft:stone_bricks":5},"sha256":"7493bb0f224abe41dce70200a74d89d26d8e6488d335d3a1aed1cfb157667196","size":{"x":32,"y":1,"z":32}},{"blockCount":124,"bytes":3591,"file":"chunks/y048-z096-x160.json","offset":{"x":160,"y":48,"z":96},"requirements":{"minecraft:bricks":28,"minecraft:cobbled_deepslate":2,"minecraft:glass":31,"minecraft:oak_planks":1,"minecraft:polished_diorite":44,"minecraft:sandstone":7,"minecraft:stone_bricks":11},"sha256":"7b62d93aad3b89c9ec98cade8202635c1323da5e5a410477bd262e6cfaf62ba8","size":{"x":32,"y":1,"z":32}},{"blockCount":255,"bytes":4934,"file":"chunks/y048-z096-x192.json","offset":{"x":192,"y":48,"z":96},"requirements":{"minecraft:bricks":159,"minecraft:cobbled_deepslate":1,"minecraft:glass":21,"minecraft:oak_planks":2,"minecraft:polished_diorite":39,"minecraft:sandstone":10,"minecraft:stone_bricks":23},"sha256":"d4ae612271e8a5366df13c1636024aa18bd8efe5bbf726035203ff296aec9eef","size":{"x":32,"y":1,"z":32}},{"blockCount":157,"bytes":4029,"file":"chunks/y048-z096-x224.json","offset":{"x":224,"y":48,"z":96},"requirements":{"minecraft:bricks":72,"minecraft:cobbled_deepslate":1,"minecraft:glass":9,"minecraft:oak_planks":1,"minecraft:polished_diorite":63,"minecraft:sandstone":5,"minecraft:stone_bricks":6},"sha256":"7ec932db041b797d24b762883b59b0d3f218ad62751adb4526a2006c1dce4e82","size":{"x":32,"y":1,"z":32}},{"blockCount":6,"bytes":851,"file":"chunks/y048-z096-x256.json","offset":{"x":256,"y":48,"z":96},"requirements":{"minecraft:oak_planks":1,"minecraft:spruce_planks":1,"minecraft:stone_bricks":4},"sha256":"84bda51df4b5991617f1eb3129bd3fd393895d6e6789d49b766b8934657d7e75","size":{"x":32,"y":1,"z":32}},{"blockCount":86,"bytes":3013,"file":"chunks/y048-z128-x000.json","offset":{"x":0,"y":48,"z":128},"requirements":{"minecraft:bricks":18,"minecraft:glass":18,"minecraft:polished_diorite":31,"minecraft:sandstone":6,"minecraft:stone_bricks":13},"sha256":"3e9b74c8e2ce6535fbcbcf29a1acb8ae5ef78e19ad22031752d7f836d6ddd401","size":{"x":32,"y":1,"z":32}},{"blockCount":180,"bytes":5358,"file":"chunks/y048-z128-x032.json","offset":{"x":32,"y":48,"z":128},"requirements":{"minecraft:bricks":71,"minecraft:cobbled_deepslate":28,"minecraft:glass":16,"minecraft:oak_planks":19,"minecraft:polished_diorite":4,"minecraft:spruce_planks":26,"minecraft:stone_bricks":16},"sha256":"ea5efbc735070dc5e91734c4114bcd91757d16156fb4bf3ebaa0957dc50e8da5","size":{"x":32,"y":1,"z":32}},{"blockCount":16,"bytes":1078,"file":"chunks/y048-z128-x064.json","offset":{"x":64,"y":48,"z":128},"requirements":{"minecraft:bricks":8,"minecraft:glass":8},"sha256":"272835f27265db2578cbb26d7382c2d3ceb6b479e7f7b5ef758463ff49f0f19e","size":{"x":32,"y":1,"z":32}},{"blockCount":15,"bytes":991,"file":"chunks/y048-z128-x096.json","offset":{"x":96,"y":48,"z":128},"requirements":{"minecraft:bricks":4,"minecraft:glass":4,"minecraft:stone_bricks":7},"sha256":"2bc2d77587d5661e5f7f202f15949a634f4d65bb23010978d947978a547942dc","size":{"x":32,"y":1,"z":32}},{"blockCount":16,"bytes":1076,"file":"chunks/y048-z128-x128.json","offset":{"x":128,"y":48,"z":128},"requirements":{"minecraft:bricks":8,"minecraft:glass":8},"sha256":"6516e12d63e75e389dbe3a4d55cbd36d229d32f0ff55a80afc818ff26d15ed09","size":{"x":32,"y":1,"z":32}},{"blockCount":19,"bytes":1176,"file":"chunks/y048-z128-x160.json","offset":{"x":160,"y":48,"z":128},"requirements":{"minecraft:bricks":9,"minecraft:glass":10},"sha256":"68b1d8ef339ffc4851fa4fe0411c4368d6a6cb58f56e2a303d57e1547f28a8de","size":{"x":32,"y":1,"z":32}},{"blockCount":58,"bytes":2046,"file":"chunks/y048-z128-x192.json","offset":{"x":192,"y":48,"z":128},"requirements":{"minecraft:bricks":42,"minecraft:glass":7,"minecraft:oak_planks":2,"minecraft:sandstone":2,"minecraft:stone_bricks":5},"sha256":"f431c98e3970061c4d3e5fcb9302a6a0266a5c39fe49b41e76042a8c93a69196","size":{"x":32,"y":1,"z":32}},{"blockCount":156,"bytes":3964,"file":"chunks/y048-z128-x224.json","offset":{"x":224,"y":48,"z":128},"requirements":{"minecraft:bricks":41,"minecraft:cobbled_deepslate":1,"minecraft:glass":1,"minecraft:oak_planks":5,"minecraft:polished_diorite":68,"minecraft:sandstone":15,"minecraft:stone_bricks":25},"sha256":"f3239920addc3d9237e877ae6d34f65c5d0ca1b783ba177c669dd24daf040e75","size":{"x":32,"y":1,"z":32}},{"blockCount":4,"bytes":764,"file":"chunks/y048-z128-x320.json","offset":{"x":320,"y":48,"z":128},"requirements":{"minecraft:polished_diorite":4},"sha256":"9d6faab2c0838a682172aab0e1f09b817569b360f2e2db566b7ac47815d392ec","size":{"x":32,"y":1,"z":32}},{"blockCount":38,"bytes":1797,"file":"chunks/y048-z160-x000.json","offset":{"x":0,"y":48,"z":160},"requirements":{"minecraft:bricks":5,"minecraft:glass":7,"minecraft:polished_diorite":20,"minecraft:sandstone":1,"minecraft:stone_bricks":5},"sha256":"3d4731d4316ec8164053bfbac32b838c9264bcef7f1d4234eb739bff44e66a52","size":{"x":32,"y":1,"z":32}},{"blockCount":93,"bytes":2784,"file":"chunks/y048-z160-x032.json","offset":{"x":32,"y":48,"z":160},"requirements":{"minecraft:bricks":15,"minecraft:glass":14,"minecraft:polished_diorite":47,"minecraft:sandstone":6,"minecraft:stone_bricks":11},"sha256":"bf9cb07554291ef137daa1493c14afd8a25cbfaf39796dacea415cb6b5a9c822","size":{"x":32,"y":1,"z":32}},{"blockCount":117,"bytes":3557,"file":"chunks/y048-z160-x064.json","offset":{"x":64,"y":48,"z":160},"requirements":{"minecraft:bricks":24,"minecraft:cobbled_deepslate":2,"minecraft:glass":17,"minecraft:oak_planks":4,"minecraft:polished_diorite":45,"minecraft:sandstone":11,"minecraft:stone_bricks":14},"sha256":"de34fc68be2390482d33d027552d41c97d0cebc567cb863616a246f67f15669d","size":{"x":32,"y":1,"z":32}},{"blockCount":26,"bytes":1418,"file":"chunks/y048-z160-x096.json","offset":{"x":96,"y":48,"z":160},"requirements":{"minecraft:bricks":8,"minecraft:cobbled_deepslate":2,"minecraft:glass":16},"sha256":"9e4345c9e511c7df9cf574b5ea1877127dacf24e23d3a71a4e4a7d188b6f6082","size":{"x":32,"y":1,"z":32}},{"blockCount":88,"bytes":3122,"file":"chunks/y048-z160-x128.json","offset":{"x":128,"y":48,"z":160},"requirements":{"minecraft:bricks":23,"minecraft:cobbled_deepslate":3,"minecraft:glass":23,"minecraft:oak_planks":3,"minecraft:polished_diorite":19,"minecraft:sandstone":9,"minecraft:stone_bricks":8},"sha256":"2041afaf2ef325ac41e744742916b4cf12bfd1007f46a8045f5bd02a058a6293","size":{"x":32,"y":1,"z":32}},{"blockCount":105,"bytes":3038,"file":"chunks/y048-z160-x160.json","offset":{"x":160,"y":48,"z":160},"requirements":{"minecraft:bricks":19,"minecraft:cobbled_deepslate":2,"minecraft:glass":21,"minecraft:oak_planks":1,"minecraft:polished_diorite":44,"minecraft:sandstone":7,"minecraft:stone_bricks":11},"sha256":"ad3a5a458f24607a7fe5281e11c3e1edcba0a101f0062984ee638f595fdb2a9f","size":{"x":32,"y":1,"z":32}},{"blockCount":225,"bytes":4450,"file":"chunks/y048-z160-x192.json","offset":{"x":192,"y":48,"z":160},"requirements":{"minecraft:bricks":134,"minecraft:cobbled_deepslate":1,"minecraft:glass":14,"minecraft:polished_diorite":48,"minecraft:sandstone":8,"minecraft:stone_bricks":20},"sha256":"650b8437289f4b737ed7fe6cbfc90bfbf54d1a4325d588938d0a32216a2fdd5c","size":{"x":32,"y":1,"z":32}},{"blockCount":110,"bytes":3376,"file":"chunks/y048-z160-x224.json","offset":{"x":224,"y":48,"z":160},"requirements":{"minecraft:bricks":60,"minecraft:glass":8,"minecraft:polished_diorite":40,"minecraft:stone_bricks":2},"sha256":"d3054ca144d8d85f6c78b49387577006647e8311d0f49baaaadad0474e801a35","size":{"x":32,"y":1,"z":32}},{"blockCount":6,"bytes":852,"file":"chunks/y048-z160-x256.json","offset":{"x":256,"y":48,"z":160},"requirements":{"minecraft:oak_planks":1,"minecraft:spruce_planks":1,"minecraft:stone_bricks":4},"sha256":"2a86d2b844561de0439851e7cb48f72f579ca3a20e3709ca96c3843306078254","size":{"x":32,"y":1,"z":32}},{"blockCount":93,"bytes":2854,"file":"chunks/y048-z192-x064.json","offset":{"x":64,"y":48,"z":192},"requirements":{"minecraft:bricks":26,"minecraft:glass":9,"minecraft:polished_diorite":42,"minecraft:sandstone":6,"minecraft:stone_bricks":10},"sha256":"f14c831da94b0d67c278b438f008bbe3c6e993c628fef9fbf6758155413b04b6","size":{"x":32,"y":1,"z":32}},{"blockCount":153,"bytes":2569,"file":"chunks/y048-z192-x096.json","offset":{"x":96,"y":48,"z":192},"requirements":{"minecraft:bricks":60,"minecraft:glass":5,"minecraft:oak_planks":5,"minecraft:polished_diorite":49,"minecraft:sandstone":13,"minecraft:stone_bricks":21},"sha256":"17c4c29581f6490771a4be80ce00e70c8d5c549e2dd8d2d11ec335002bc9d01d","size":{"x":32,"y":1,"z":32}},{"blockCount":190,"bytes":3909,"file":"chunks/y048-z192-x128.json","offset":{"x":128,"y":48,"z":192},"requirements":{"minecraft:bricks":62,"minecraft:glass":14,"minecraft:oak_planks":3,"minecraft:polished_diorite":78,"minecraft:sandstone":17,"minecraft:stone_bricks":16},"sha256":"87c948666d853f7b49f760460fed170923663843ee7013f2c4bedb59285d61ea","size":{"x":32,"y":1,"z":32}},{"blockCount":6,"bytes":844,"file":"chunks/y048-z192-x160.json","offset":{"x":160,"y":48,"z":192},"requirements":{"minecraft:polished_diorite":6},"sha256":"ffdd265cfdb3a21eec33482b3a3b63b83165d21b28720b7cdca6d37c7628e228","size":{"x":32,"y":1,"z":32}},{"blockCount":187,"bytes":3797,"file":"chunks/y049-z000-x352.json","offset":{"x":352,"y":49,"z":0},"requirements":{"minecraft:bricks":8,"minecraft:cobbled_deepslate":28,"minecraft:glass":43,"minecraft:oak_planks":24,"minecraft:polished_diorite":11,"minecraft:sandstone":59,"minecraft:spruce_planks":6,"minecraft:stone_bricks":8},"sha256":"6815c959747ec79061be71d37a6f924c9a34f795ad641765ab7c2bb9045eaf6e","size":{"x":32,"y":1,"z":32}},{"blockCount":214,"bytes":4300,"file":"chunks/y049-z000-x384.json","offset":{"x":384,"y":49,"z":0},"requirements":{"minecraft:glass":15,"minecraft:oak_planks":31,"minecraft:polished_diorite":28,"minecraft:sandstone":44,"minecraft:spruce_planks":2,"minecraft:stone_bricks":94},"sha256":"ccc8fdce88ca4819ab44b5b04a6182050726936c19924d2e5e32256ca1337b6b","size":{"x":32,"y":1,"z":32}},{"blockCount":99,"bytes":3105,"file":"chunks/y049-z032-x352.json","offset":{"x":352,"y":49,"z":32},"requirements":{"minecraft:cobbled_deepslate":10,"minecraft:glass":55,"minecraft:polished_diorite":16,"minecraft:spruce_planks":18},"sha256":"bc3488df232aa1470adb6786a6376d484cd84ad5f63822731a9de2eb5370d1cc","size":{"x":32,"y":1,"z":32}},{"blockCount":40,"bytes":1164,"file":"chunks/y049-z032-x384.json","offset":{"x":384,"y":49,"z":32},"requirements":{"minecraft:polished_diorite":14,"minecraft:sandstone":14,"minecraft:stone_bricks":12},"sha256":"04508c5138f214f3a4568a6cdcc117b909103b5a8ac58921ae080775a200832f","size":{"x":32,"y":1,"z":32}},{"blockCount":117,"bytes":3378,"file":"chunks/y049-z064-x064.json","offset":{"x":64,"y":49,"z":64},"requirements":{"minecraft:bricks":33,"minecraft:glass":12,"minecraft:oak_planks":1,"minecraft:polished_diorite":51,"minecraft:sandstone":8,"minecraft:stone_bricks":12},"sha256":"75c81109d04dce931ea0e4cdc9f32dff5af7ee7f31011bc0e6c28c245ce6382f","size":{"x":32,"y":1,"z":32}},{"blockCount":152,"bytes":2875,"file":"chunks/y049-z064-x096.json","offset":{"x":96,"y":49,"z":64},"requirements":{"minecraft:bricks":60,"minecraft:glass":10,"minecraft:oak_planks":5,"minecraft:polished_diorite":51,"minecraft:sandstone":14,"minecraft:stone_bricks":12},"sha256":"35279d763071162f69e1a8762ae8e562d90ead86890ff0195e0f63e5c09adf8b","size":{"x":32,"y":1,"z":32}},{"blockCount":215,"bytes":4407,"file":"chunks/y049-z064-x128.json","offset":{"x":128,"y":49,"z":64},"requirements":{"minecraft:bricks":67,"minecraft:glass":22,"minecraft:oak_planks":4,"minecraft:polished_diorite":87,"minecraft:sandstone":19,"minecraft:stone_bricks":16},"sha256":"8f04dd9e164fa17ffa0b8dd870cedf8b7f5b4aac15e0b746afdef327cfd6faa2","size":{"x":32,"y":1,"z":32}},{"blockCount":7,"bytes":881,"file":"chunks/y049-z064-x160.json","offset":{"x":160,"y":49,"z":64},"requirements":{"minecraft:polished_diorite":7},"sha256":"82aa03f44183d5906d515b096abb27445eb1c04f636f0f5007adcb8a9b64e8dd","size":{"x":32,"y":1,"z":32}}],"schema":1}
