{"entries":[{"blockCount":11,"bytes":940,"file":"chunks/y049-z064-x192.json","offset":{"x":192,"y":49,"z":64},"requirements":{"minecraft:polished_diorite":9,"minecraft:stone_bricks":2},"sha256":"2f9ba1247608ea1a4aaeffc1c4849704c83b06de03e6851aa3747dac08a6cccd","size":{"x":32,"y":1,"z":32}},{"blockCount":14,"bytes":980,"file":"chunks/y049-z064-x224.json","offset":{"x":224,"y":49,"z":64},"requirements":{"minecraft:polished_diorite":12,"minecraft:stone_bricks":2},"sha256":"90e9a746f4b1832d427256a87c53fc20a77f8593b87dc3aaa34c114effb21ab3","size":{"x":32,"y":1,"z":32}},{"blockCount":57,"bytes":2336,"file":"chunks/y049-z096-x000.json","offset":{"x":0,"y":49,"z":96},"requirements":{"minecraft:bricks":5,"minecraft:glass":13,"minecraft:polished_diorite":28,"minecraft:sandstone":2,"minecraft:stone_bricks":9},"sha256":"1f958c06a5b830cbdfef1606d5e329304f15dd7f4189981e651541e6437a0629","size":{"x":32,"y":1,"z":32}},{"blockCount":124,"bytes":3483,"file":"chunks/y049-z096-x032.json","offset":{"x":32,"y":49,"z":96},"requirements":{"minecraft:bricks":23,"minecraft:glass":22,"minecraft:polished_diorite":47,"minecraft:sandstone":6,"minecraft:spruce_planks":9,"minecraft:stone_bricks":17},"sha256":"1c7b0b4610fc49008486f79efadb55b2fa51ea9c57142f98b29445f083bedbf5","size":{"x":32,"y":1,"z":32}},{"blockCount":120,"bytes":3506,"file":"chunks/y049-z096-x064.json","offset":{"x":64,"y":49,"z":96},"requirements":{"minecraft:bricks":29,"minecraft:glass":30,"minecraft:oak_planks":4,"minecraft:polished_diorite":37,"minecraft:sandstone":9,"minecraft:stone_bricks":11},"sha256":"360e8c77de6c4e533ddb6715f1ce6820ea79b3744c368225998a2a2ac68e564f","size":{"x":32,"y":1,"z":32}},{"blockCount":34,"bytes":1501,"file":"chunks/y049-z096-x096.json","offset":{"x":96,"y":49,"z":96},"requirements":{"minecraft:bricks":11,"minecraft:glass":23},"sha256":"ed0629bdb123915bdd26b807b01ac66b23222e337297ba7d47bf7b04745c76b3","size":{"x":32,"y":1,"z":32}},{"blockCount":87,"bytes":2953,"file":"chunks/y049-z096-x128.json","offset":{"x":128,"y":49,"z":96},"requirements":{"minecraft:bricks":27,"minecraft:glass":35,"minecraft:oak_planks":3,"minecraft:polished_diorite":12,"minecraft:sandstone":5,"minecraft:stone_bricks":5},"sha256":"80f1344eaa241357d24af7dd8fbc8f836e6d4d1d1b73e0b14b01dea5a7c2a480","size":{"x":32,"y":1,"z":32}},{"blockCount":132,"bytes":3636,"file":"chunks/y049-z096-x160.json","offset":{"x":160,"y":49,"z":96},"requirements":{"minecraft:bricks":28,"minecraft:glass":41,"minecraft:oak_planks":1,"minecraft:polished_diorite":44,"minecraft:sandstone":7,"minecraft:stone_bricks":11},"sha256":"241d258da0e25aaa5d2720e2d092ebd8b9cb72c081d6abc58ad32761d6f6f390","size":{"x":32,"y":1,"z":32}},{"blockCount":260,"bytes":4921,"file":"chunks/y049-z096-x192.json","offset":{"x":192,"y":49,"z":96},"requirements":{"minecraft:bricks":159,"minecraft:glass":23,"minecraft:oak_planks":2,"minecraft:polished_diorite":39,"minecraft:sandstone":11,"minecraft:stone_bricks":26},"sha256":"8356ed558916406c4caf7e1e6fff0c0bee0e4b34b5f0239de6c57396049555a3","size":{"x":32,"y":1,"z":32}},{"blockCount":152,"bytes":3979,"file":"chunks/y049-z096-x224.json","offset":{"x":224,"y":49,"z":96},"requirements":{"minecraft:bricks":74,"minecraft:glass":10,"minecraft:oak_planks":1,"minecraft:polished_diorite":58,"minecraft:sandstone":5,"minecraft:stone_bricks":4},"sha256":"f0f16b6b6dd9acb91ed56fd0ea0b6aba40647b9aa6a996a1046c4c3bfd12ac15","size":{"x":32,"y":1,"z":32}},{"blockCount":2,"bytes":707,"file":"chunks/y049-z096-x256.json","offset":{"x":256,"y":49,"z":96},"requirements":{"minecraft:oak_planks":1,"minecraft:stone_bricks":1},"sha256":"94e1cf0258951e35eb53e4b1ed5c8c3cc767928c61c065cb345235261244b639","size":{"x":32,"y":1,"z":32}},{"blockCount":86,"bytes":3013,"file":"chunks/y049-z128-x000.json","offset":{"x":0,"y":49,"z":128},"requirements":{"minecraft:bricks":18,"minecraft:glass":18,"minecraft:polished_diorite":31,"minecraft:sandstone":6,"minecraft:stone_bricks":13},"sha256":"ad58a1fd4235e5fa781c4292f997ea10734684e45e3fe05c58acea6ca31b4240","size":{"x":32,"y":1,"z":32}},{"blockCount":183,"bytes":5016,"file":"chunks/y049-z128-x032.json","offset":{"x":32,"y":49,"z":128},"requirements":{"minecraft:bricks":48,"minecraft:cobbled_deepslate":28,"minecraft:glass":16,"minecraft:oak_planks":18,"minecraft:polished_diorite":8,"minecraft:spruce_planks":47,"minecraft:stone_bricks":18},"sha256":"0414c53e4a2c5da49a240cdf856aeec17d475dfba0290b28f3877db9e260504f","size":{"x":32,"y":1,"z":32}},{"blockCount":16,"bytes":1078,"file":"chunks/y049-z128-x064.json","offset":{"x":64,"y":49,"z":128},"requirements":{"minecraft:bricks":8,"minecraft:glass":8},"sha256":"3b5d4a5e3e9679298ef582b48decc61ea444e040a3f7d893e4eb9cf9f66571bc","size":{"x":32,"y":1,"z":32}},{"blockCount":15,"bytes":995,"file":"chunks/y049-z128-x096.json","offset":{"x":96,"y":49,"z":128},"requirements":{"minecraft:bricks":4,"minecraft:glass":1,"minecraft:sandstone":3,"minecraft:stone_bricks":7},"sha256":"137bebc19a1b418027d692d4b0ce8d5d7fe7909ba2abcda08f04e2a5a1ff2601","size":{"x":32,"y":1,"z":32}},{"blockCount":16,"bytes":1076,"file":"chunks/y049-z128-x128.json","offset":{"x":128,"y":49,"z":128},"requirements":{"minecraft:bricks":8,"minecraft:glass":8},"sha256":"0baddb4bfbce3024fbb69bcbb7787578c961475438bf9afd45e11bf732cfa368","size":{"x":32,"y":1,"z":32}},{"blockCount":19,"bytes":1176,"file":"chunks/y049-z128-x160.json","offset":{"x":160,"y":49,"z":128},"requirements":{"minecraft:bricks":9,"minecraft:glass":10},"sha256":"d95bc7df7f8298c92eae81bd1fbd3c7524be42ab4a515b5992485655d320c5fa","size":{"x":32,"y":1,"z":32}},{"blockCount":61,"bytes":2045,"file":"chunks/y049-z128-x192.json","offset":{"x":192,"y":49,"z":128},"requirements":{"minecraft:bricks":40,"minecraft:glass":7,"minecraft:oak_planks":2,"minecraft:sandstone":3,"minecraft:stone_bricks":9},"sha256":"3958722fb7419d833c4e440c9eca2411fab91f153585b391b9a3871c0d34ca39","size":{"x":32,"y":1,"z":32}},{"blockCount":139,"bytes":3703,"file":"chunks/y049-z128-x224.json","offset":{"x":224,"y":49,"z":128},"requirements":{"minecraft:bricks":41,"minecraft:glass":2,"minecraft:oak_planks":5,"minecraft:polished_diorite":68,"minecraft:sandstone":15,"minecraft:stone_bricks":8},"sha256":"5f1fcdd45354ed78e7bb07c35b6bcc3c5504a636ee39615cc9e55d881b9b207a","size":{"x":32,"y":1,"z":32}},{"blockCount":5,"bytes":791,"file":"chunks/y049-z128-x320.json","offset":{"x":320,"y":49,"z":128},"requirements":{"minecraft:polished_diorite":4,"minecraft:stone_bricks":1},"sha256":"27d49f0ec52bc7b9eb2ba13d1c9a6dee906cf645672bc8ef9e22cd509a448e38","size":{"x":32,"y":1,"z":32}},{"blockCount":38,"bytes":1797,"file":"chunks/y049-z160-x000.json","offset":{"x":0,"y":49,"z":160},"requirements":{"minecraft:bricks":5,"minecraft:glass":7,"minecraft:polished_diorite":20,"minecraft:sandstone":1,"minecraft:stone_bricks":5},"sha256":"a7fdee4c11ef0ab45dc74050431567617247f04c5cc37dd0667ca5de4ebcc767","size":{"x":32,"y":1,"z":32}},{"blockCount":93,"bytes":2784,"file":"chunks/y049-z160-x032.json","offset":{"x":32,"y":49,"z":160},"requirements":{"minecraft:bricks":15,"minecraft:glass":14,"minecraft:polished_diorite":47,"minecraft:sandstone":6,"minecraft:stone_bricks":11},"sha256":"5e26c63c442fb77ffc83446772f8ee86184a00de6437fc8907101934dc6d1e8d","size":{"x":32,"y":1,"z":32}},{"blockCount":123,"bytes":3525,"file":"chunks/y049-z160-x064.json","offset":{"x":64,"y":49,"z":160},"requirements":{"minecraft:bricks":24,"minecraft:glass":25,"minecraft:oak_planks":4,"minecraft:polished_diorite":45,"minecraft:sandstone":11,"minecraft:stone_bricks":14},"sha256":"77c4bc2707b3a98636d280dddb4003509da98bcda1ddd3570aa2aafca9589138","size":{"x":32,"y":1,"z":32}},{"blockCount":32,"bytes":1386,"file":"chunks/y049-z160-x096.json","offset":{"x":96,"y":49,"z":160},"requirements":{"minecraft:bricks":8,"minecraft:glass":24},"sha256":"baf6e89d131d402fdb19959dc8d679631203c9f74e8f0b559be96873264883f5","size":{"x":32,"y":1,"z":32}},{"blockCount":97,"bytes":3090,"file":"chunks/y049-z160-x128.json","offset":{"x":128,"y":49,"z":160},"requirements":{"minecraft:bricks":23,"minecraft:glass":35,"minecraft:oak_planks":3,"minecraft:polished_diorite":19,"minecraft:sandstone":9,"minecraft:stone_bricks":8},"sha256":"a1e591b6eec01d582dfadc77fb6af142776997fb698dbefe2632c55845b93e69","size":{"x":32,"y":1,"z":32}},{"blockCount":114,"bytes":3120,"file":"chunks/y049-z160-x160.json","offset":{"x":160,"y":49,"z":160},"requirements":{"minecraft:bricks":19,"minecraft:glass":31,"minecraft:oak_planks":1,"minecraft:polished_diorite":45,"minecraft:sandstone":7,"minecraft:stone_bricks":11},"sha256":"6aeb74aff3a08fef6367bc40815f9aa8e43bc39f38e9611599d8213048700b45","size":{"x":32,"y":1,"z":32}},{"blockCount":232,"bytes":4476,"file":"chunks/y049-z160-x192.json","offset":{"x":192,"y":49,"z":160},"requirements":{"minecraft:bricks":135,"minecraft:glass":16,"minecraft:polished_diorite":48,"minecraft:sandstone":8,"minecraft:stone_bricks":25},"sha256":"6c82dbf15a23c32ccd2a946d2bc27fc3f9fda9f529dcf1f4dccd8045f58460f0","size":{"x":32,"y":1,"z":32}},{"blockCount":114,"bytes":3300,"file":"chunks/y049-z160-x224.json","offset":{"x":224,"y":49,"z":160},"requirements":{"minecraft:bricks":62,"minecraft:glass":8,"minecraft:polished_diorite":40,"minecraft:stone_bricks":4},"sha256":"b6dd7cd063b837b7d3a399bcefd9df03c3780820dd45d7ac505f9a9ef3af93b6","size":{"x":32,"y":1,"z":32}},{"blockCount":2,"bytes":708,"file":"chunks/y049-z160-x256.json","offset":{"x":256,"y":49,"z":160},"requirements":{"minecraft:oak_planks":1,"minecraft:stone_bricks":1},"sha256":"3ef56663bc69049891143efe132bed14203d42d7956450bc3b78808b1e3ec304","size":{"x":32,"y":1,"z":32}},{"blockCount":98,"bytes":2897,"file":"chunks/y049-z192-x064.json","offset":{"x":64,"y":49,"z":192},"requirements":{"minecraft:bricks":30,"minecraft:glass":9,"minecraft:oak_planks":1,"minecraft:polished_diorite":43,"minecraft:sandstone":6,"minecraft:stone_bricks":9},"sha256":"b75159ebad441ab5365a373b45ef764e71321ba89ed0aaddad6331beaa148f0a","size":{"x":32,"y":1,"z":32}},{"blockCount":145,"bytes":2722,"file":"chunks/y049-z192-x096.json","offset":{"x":96,"y":49,"z":192},"requirements":{"minecraft:bricks":59,"minecraft:glass":5,"minecraft:oak_planks":5,"minecraft:polished_diorite":51,"minecraft:sandstone":13,"minecraft:stone_bricks":12},"sha256":"5ac68a7abc96e691b44bae3bc4eda733257cbba573ba1e5537bfc70d627c16d8","size":{"x":32,"y":1,"z":32}},{"blockCount":191,"bytes":3891,"file":"chunks/y049-z192-x128.json","offset":{"x":128,"y":49,"z":192},"requirements":{"minecraft:bricks":63,"minecraft:glass":14,"minecraft:oak_planks":4,"minecraft:polished_diorite":80,"minecraft:sandstone":17,"minecraft:stone_bricks":13},"sha256":"a75b22d2070cd913225a2b7b0360d890d5859a56fb41f20011c284dc585e84a1","size":{"x":32,"y":1,"z":32}},{"blockCount":6,"bytes":844,"file":"chunks/y049-z192-x160.json","offset":{"x":160,"y":49,"z":192},"requirements":{"minecraft:polished_diorite":6},"sha256":"984118668b6d2119150b6a70be4d09c5f97e25dc9b37a2193b940f5f3cfb6b39","size":{"x":32,"y":1,"z":32}},{"blockCount":199,"bytes":3307,"file":"chunks/y050-z000-x352.json","offset":{"x":352,"y":50,"z":0},"requirements":{"minecraft:bricks":8,"minecraft:cobbled_deepslate":41,"minecraft:glass":11,"minecraft:oak_planks":1,"minecraft:polished_diorite":35,"minecraft:sandstone":57,"minecraft:spruce_planks":39,"minecraft:stone_bricks":7},"sha256":"7301f4dc219ec8e1214976398874b1cc1d4fcb191c85543ab3cd7e0782c0bfba","size":{"x":32,"y":1,"z":32}},{"blockCount":216,"bytes":3805,"file":"chunks/y050-z000-x384.json","offset":{"x":384,"y":50,"z":0},"requirements":{"minecraft:glass":3,"minecraft:oak_planks":12,"minecraft:polished_diorite":42,"minecraft:sandstone":44,"minecraft:spruce_planks":15,"minecraft:stone_bricks":100},"sha256":"ce2d3d1f7439cfb56c649d894205dd0e6eba4a15b4ecf24d8789595496bcf7b9","size":{"x":32,"y":1,"z":32}},{"blockCount":70,"bytes":2391,"file":"chunks/y050-z032-x352.json","offset":{"x":352,"y":50,"z":32},"requirements":{"minecraft:cobbled_deepslate":48,"minecraft:glass":6,"minecraft:polished_diorite":16},"sha256":"2126957096e3d8f06f0e6ee8cf2b8fac9be889fbd3576f75cf96519a8be483f4","size":{"x":32,"y":1,"z":32}},{"blockCount":40,"bytes":1164,"file":"chunks/y050-z032-x384.json","offset":{"x":384,"y":50,"z":32},"requirements":{"minecraft:polished_diorite":14,"minecraft:sandstone":14,"minecraft:stone_bricks":12},"sha256":"62db9143e439e0e69f6c0453c216f024394e8be5224eef87aabac9a2a4efb210","size":{"x":32,"y":1,"z":32}},{"blockCount":118,"bytes":3360,"file":"chunks/y050-z064-x064.json","offset":{"x":64,"y":50,"z":64},"requirements":{"minecraft:bricks":32,"minecraft:glass":12,"minecraft:oak_planks":1,"minecraft:polished_diorite":51,"minecraft:sandstone":8,"minecraft:stone_bricks":14},"sha256":"3ac1704040b2972f0e223944a7f5636409f8bfc5c719259dbf9fae55bc762375","size":{"x":32,"y":1,"z":32}},{"blockCount":155,"bytes":2885,"file":"chunks/y050-z064-x096.json","offset":{"x":96,"y":50,"z":64},"requirements":{"minecraft:bricks":59,"minecraft:cobbled_deepslate":1,"minecraft:glass":7,"minecraft:oak_planks":5,"minecraft:polished_diorite":58,"minecraft:sandstone":15,"minecraft:stone_bricks":10},"sha256":"6c04b8b5ef3cfbf7032c3abae039d0227ba77d47fdfc8e94593e83b30dc726fa","size":{"x":32,"y":1,"z":32}},{"blockCount":218,"bytes":4440,"file":"chunks/y050-z064-x128.json","offset":{"x":128,"y":50,"z":64},"requirements":{"minecraft:bricks":70,"minecraft:cobbled_deepslate":1,"minecraft:glass":19,"minecraft:oak_planks":4,"minecraft:polished_diorite":87,"minecraft:sandstone":19,"minecraft:stone_bricks":18},"sha256":"da2eee7e7833929a998147b4e5cfa20ff6b5e1e836227b78d253f6414e19415a","size":{"x":32,"y":1,"z":32}},{"blockCount":7,"bytes":881,"file":"chunks/y050-z064-x160.json","offset":{"x":160,"y":50,"z":64},"requirements":{"minecraft:polished_diorite":7},"sha256":"922f5c524dddcf4011afcd45b077f45c740a9aada9db00db4ef8189fc081ed0b","size":{"x":32,"y":1,"z":32}},{"blockCount":11,"bytes":940,"file":"chunks/y050-z064-x192.json","offset":{"x":192,"y":50,"z":64},"requirements":{"minecraft:polished_diorite":9,"minecraft:stone_bricks":2},"sha256":"53752da75c02a0a8ba6e505f0fb8c3e428e71f1026b94fcbfa964a31c26bc3e8","size":{"x":32,"y":1,"z":32}},{"blockCount":14,"bytes":980,"file":"chunks/y050-z064-x224.json","offset":{"x":224,"y":50,"z":64},"requirements":{"minecraft:polished_diorite":12,"minecraft:stone_bricks":2},"sha256":"7300628cca3ca831cbea01b98c265e7a590aacb7174fcfd86a1194e53de5be8f","size":{"x":32,"y":1,"z":32}},{"blockCount":57,"bytes":2336,"file":"chunks/y050-z096-x000.json","offset":{"x":0,"y":50,"z":96},"requirements":{"minecraft:bricks":5,"minecraft:glass":13,"minecraft:polished_diorite":28,"minecraft:sandstone":2,"minecraft:stone_bricks":9},"sha256":"0e32908153ce146a6ee3b1e49fb07e5c565655f3ca0e902ab4a6d58a9a944f3b","size":{"x":32,"y":1,"z":32}},{"blockCount":114,"bytes":3483,"file":"chunks/y050-z096-x032.json","offset":{"x":32,"y":50,"z":96},"requirements":{"minecraft:bricks":23,"minecraft:glass":22,"minecraft:polished_diorite":47,"minecraft:sandstone":6,"minecraft:spruce_planks":3,"minecraft:stone_bricks":13},"sha256":"9537bdf9b7035e0da7464c478566227f410f2ad50dd34c2e1371d164453fa744","size":{"x":32,"y":1,"z":32}},{"blockCount":114,"bytes":3463,"file":"chunks/y050-z096-x064.json","offset":{"x":64,"y":50,"z":96},"requirements":{"minecraft:bricks":29,"minecraft:cobbled_deepslate":10,"minecraft:glass":14,"minecraft:oak_planks":4,"minecraft:polished_diorite":37,"minecraft:sandstone":9,"minecraft:stone_bricks":11},"sha256":"ed27715787ca883aded601513c7fafacfa101ba81b7d6a1460536f10569e0fb4","size":{"x":32,"y":1,"z":32}},{"blockCount":30,"bytes":1457,"file":"chunks/y050-z096-x096.json","offset":{"x":96,"y":50,"z":96},"requirements":{"minecraft:bricks":11,"minecraft:cobbled_deepslate":9,"minecraft:glass":10},"sha256":"ed15d801bb66fcacf76121a3bf33406cc57998d4ef3718b889e36ea8b8105360","size":{"x":32,"y":1,"z":32}},{"blockCount":80,"bytes":2872,"file":"chunks/y050-z096-x128.json","offset":{"x":128,"y":50,"z":96},"requirements":{"minecraft:bricks":27,"minecraft:cobbled_deepslate":14,"minecraft:glass":14,"minecraft:oak_planks":3,"minecraft:polished_diorite":12,"minecraft:sandstone":5,"minecraft:stone_bricks":5},"sha256":"ef0cebc770cac4918eb0be28d8c35ee09e983c919ef730104d03c58f54f13275","size":{"x":32,"y":1,"z":32}},{"blockCount":124,"bytes":3516,"file":"chunks/y050-z096-x160.json","offset":{"x":160,"y":50,"z":96},"requirements":{"minecraft:bricks":28,"minecraft:cobbled_deepslate":11,"minecraft:glass":22,"minecraft:oak_planks":1,"minecraft:polished_diorite":44,"minecraft:sandstone":7,"minecraft:stone_bricks":11},"sha256":"49db53a099aa780c3e7102d2b8005e1d0f78f97f4d696b244fcf327c6c7ed839","size":{"x":32,"y":1,"z":32}},{"blockCount":251,"bytes":5029,"file":"chunks/y050-z096-x192.json","offset":{"x":192,"y":50,"z":96},"requirements":{"minecraft:bricks":159,"minecraft:cobbled_deepslate":4,"minecraft:glass":16,"minecraft:oak_planks":2,"minecraft:polished_diorite":41,"minecraft:sandstone":10,"minecraft:stone_bricks":19},"sha256":"f685d5c3eb86372bf63b018d5a7ce4e36f90e47b707c446db05fe03096a71057","size":{"x":32,"y":1,"z":32}},{"blockCount":160,"bytes":4035,"file":"chunks/y050-z096-x224.json","offset":{"x":224,"y":50,"z":96},"requirements":{"minecraft:bricks":80,"minecraft:glass":5,"minecraft:oak_planks":1,"minecraft:polished_diorite":61,"minecraft:sandstone":5,"minecraft:stone_bricks":8},"sha256":"960454ba976cd30a3040eea7a79b1d837969fa4a57819585610b6ce024967008","size":{"x":32,"y":1,"z":32}},{"blockCount":4,"bytes":768,"file":"chunks/y050-z096-x256.json","offset":{"x":256,"y":50,"z":96},"requirements":{"minecraft:spruce_planks":1,"minecraft:stone_bricks":3},"sha256":"a6ae497167a363cba36cbad015c0e572df8a77f2b8000ae947c7acdc040b6668","size":{"x":32,"y":1,"z":32}},{"blockCount":86,"bytes":3013,"file":"chunks/y050-z128-x000.json","offset":{"x":0,"y":50,"z":128},"requirements":{"minecraft:bricks":18,"minecraft:glass":18,"minecraft:polished_diorite":31,"minecraft:sandstone":6,"minecraft:stone_bricks":13},"sha256":"b516b800f304f12b029fcb20f22d401cb1af3cb9df30bd43c78708d0edd32351","size":{"x":32,"y":1,"z":32}},{"blockCount":167,"bytes":4979,"file":"chunks/y050-z128-x032.json","offset":{"x":32,"y":50,"z":128},"requirements":{"minecraft:bricks":52,"minecraft:cobbled_deepslate":28,"minecraft:glass":16,"minecraft:oak_planks":18,"minecraft:polished_diorite":10,"minecraft:spruce_planks":33,"minecraft:stone_bricks":10},"sha256":"5114d99840503d54b6ebc23cc955830a25512b74cf522703506d140d3f0e8536","size":{"x":32,"y":1,"z":32}},{"blockCount":16,"bytes":1078,"file":"chunks/y050-z128-x064.json","offset":{"x":64,"y":50,"z":128},"requirements":{"minecraft:bricks":8,"minecraft:glass":8},"sha256":"6af45745a83b772a5169712e03d68d3eb8bb2cce244fdd55b18abf574f29d985","size":{"x":32,"y":1,"z":32}},{"blockCount":9,"bytes":918,"file":"chunks/y050-z128-x096.json","offset":{"x":96,"y":50,"z":128},"requirements":{"minecraft:bricks":4,"minecraft:glass":4,"minecraft:polished_diorite":1},"sha256":"51058b6aded7bbe9cc2d3547b9e325f728851d15960c69d61ec8a1b6f1c991f7","size":{"x":32,"y":1,"z":32}},{"blockCount":16,"bytes":1076,"file":"chunks/y050-z128-x128.json","offset":{"x":128,"y":50,"z":128},"requirements":{"minecraft:bricks":8,"minecraft:glass":8},"sha256":"198441040407ffb0f909d547e477be8781fbe8f3248bca2f3c9177c813485e64","size":{"x":32,"y":1,"z":32}},{"blockCount":19,"bytes":1176,"file":"chunks/y050-z128-x160.json","offset":{"x":160,"y":50,"z":128},"requirements":{"minecraft:bricks":9,"minecraft:glass":10},"sha256":"2e5340c3f417fbd5578ab6505b79187b2304e60587bb42f02c152a8fd329ef90","size":{"x":32,"y":1,"z":32}},{"blockCount":53,"bytes":1854,"file":"chunks/y050-z128-x192.json","offset":{"x":192,"y":50,"z":128},"requirements":{"minecraft:bricks":37,"minecraft:glass":7,"minecraft:oak_planks":2,"minecraft:sandstone":2,"minecraft:stone_bricks":5},"sha256":"be1d5be9a71a69ecca71a2dbc75d32b6143a8aa4f08452c56e34f500ffa4e3e8","size":{"x":32,"y":1,"z":32}},{"blockCount":148,"bytes":3665,"file":"chunks/y050-z128-x224.json","offset":{"x":224,"y":50,"z":128},"requirements":{"minecraft:bricks":45,"minecraft:glass":1,"minecraft:oak_planks":5,"minecraft:polished_diorite":74,"minecraft:sandstone":17,"minecraft:stone_bricks":6},"sha256":"1ebfd11b0a0db4d2b5ec5a5b37faf499aa80a2f6c333fbf02c6228d6d51e5549","size":{"x":32,"y":1,"z":32}},{"blockCount":4,"bytes":764,"file":"chunks/y050-z128-x320.json","offset":{"x":320,"y":50,"z":128},"requirements":{"minecraft:polished_diorite":4},"sha256":"6287582e576f4ffe677d6899bf8661c5e39b113e36c3774ec7509bc793d5f073","size":{"x":32,"y":1,"z":32}},{"blockCount":38,"bytes":1797,"file":"chunks/y050-z160-x000.json","offset":{"x":0,"y":50,"z":160},"requirements":{"minecraft:bricks":5,"minecraft:glass":7,"minecraft:polished_diorite":20,"minecraft:sandstone":1,"minecraft:stone_bricks":5},"sha256":"1fbba3221e9daf1d89bfc1d00f4adf34e2fd4a54498c7fa326e46116e5ea14d2","size":{"x":32,"y":1,"z":32}},{"blockCount":93,"bytes":2784,"file":"chunks/y050-z160-x032.json","offset":{"x":32,"y":50,"z":160},"requirements":{"minecraft:bricks":15,"minecraft:glass":14,"minecraft:polished_diorite":47,"minecraft:sandstone":6,"minecraft:stone_bricks":11},"sha256":"2d1f4cc778827fa181ef75d69defac6484d3e11a82cc2c7068d0e29073ee9a59","size":{"x":32,"y":1,"z":32}},{"blockCount":117,"bytes":3481,"file":"chunks/y050-z160-x064.json","offset":{"x":64,"y":50,"z":160},"requirements":{"minecraft:bricks":24,"minecraft:cobbled_deepslate":10,"minecraft:glass":9,"minecraft:oak_planks":4,"minecraft:polished_diorite":45,"minecraft:sandstone":11,"minecraft:stone_bricks":14},"sha256":"79f3432d5463e21cc3cdcb901b6e57f76cfe23c4bed590f1819341f2b9ad72a8","size":{"x":32,"y":1,"z":32}},{"blockCount":26,"bytes":1342,"file":"chunks/y050-z160-x096.json","offset":{"x":96,"y":50,"z":160},"requirements":{"minecraft:bricks":8,"minecraft:cobbled_deepslate":10,"minecraft:glass":8},"sha256":"cce9c50b859f4eda7d07cddb91a26f54175b2c82079bf986cad76a3c6b17cc59","size":{"x":32,"y":1,"z":32}},{"blockCount":89,"bytes":3009,"file":"chunks/y050-z160-x128.json","offset":{"x":128,"y":50,"z":160},"requirements":{"minecraft:bricks":24,"minecraft:cobbled_deepslate":15,"minecraft:glass":11,"minecraft:oak_planks":3,"minecraft:polished_diorite":19,"minecraft:sandstone":9,"minecraft:stone_bricks":8},"sha256":"18fb9a1bf17273326d35447c5dab284b4dd1f4f657fcf946913fbf4691001271","size":{"x":32,"y":1,"z":32}},{"blockCount":106,"bytes":3000,"file":"chunks/y050-z160-x160.json","offset":{"x":160,"y":50,"z":160},"requirements":{"minecraft:bricks":19,"minecraft:cobbled_deepslate":11,"minecraft:glass":12,"minecraft:oak_planks":1,"minecraft:polished_diorite":45,"minecraft:sandstone":7,"minecraft:stone_bricks":11},"sha256":"be6fe201e3afa1f2a2fdcd4d8c2dc88c62132d86097972e5241d74a27892d144","size":{"x":32,"y":1,"z":32}},{"blockCount":223,"bytes":4582,"file":"chunks/y050-z160-x192.json","offset":{"x":192,"y":50,"z":160},"requirements":{"minecraft:bricks":134,"minecraft:cobbled_deepslate":4,"minecraft:glass":9,"minecraft:polished_diorite":50,"minecraft:sandstone":8,"minecraft:stone_bricks":18},"sha256":"48b781568b32d0a058081e5cd2819aad234c651c75c68872ba0f2ef53736f06f","size":{"x":32,"y":1,"z":32}},{"blockCount":123,"bytes":3395,"file":"chunks/y050-z160-x224.json","offset":{"x":224,"y":50,"z":160},"requirements":{"minecraft:bricks":68,"minecraft:glass":4,"minecraft:polished_diorite":43,"minecraft:stone_bricks":8},"sha256":"89b9f50ce76db8f4325b611e851ce019236ccbc1eebefd2c10211e8ee695e3e8","size":{"x":32,"y":1,"z":32}},{"blockCount":4,"bytes":769,"file":"chunks/y050-z160-x256.json","offset":{"x":256,"y":50,"z":160},"requirements":{"minecraft:spruce_planks":1,"minecraft:stone_bricks":3},"sha256":"56e26f9ef4a8b1b78ffef8cf12be8435a455f43db8dd42e67d18bc5b7d58fac3","size":{"x":32,"y":1,"z":32}},{"blockCount":99,"bytes":2880,"file":"chunks/y050-z192-x064.json","offset":{"x":64,"y":50,"z":192},"requirements":{"minecraft:bricks":29,"minecraft:glass":9,"minecraft:oak_planks":1,"minecraft:polished_diorite":43,"minecraft:sandstone":6,"minecraft:stone_bricks":11},"sha256":"06f86e4694024a329414fbce1f1619a882f2c79f0b0d81f33502a1170bfa6a9c","size":{"x":32,"y":1,"z":32}},{"blockCount":151,"bytes":2702,"file":"chunks/y050-z192-x096.json","offset":{"x":96,"y":50,"z":192},"requirements":{"minecraft:bricks":58,"minecraft:glass":5,"minecraft:oak_planks":5,"minecraft:polished_diorite":58,"minecraft:sandstone":15,"minecraft:stone_bricks":10},"sha256":"49d0104e744770495009b0351ae671584dd662301149671cafea506cd26d92c8","size":{"x":32,"y":1,"z":32}},{"blockCount":196,"bytes":3891,"file":"chunks/y050-z192-x128.json","offset":{"x":128,"y":50,"z":192},"requirements":{"minecraft:bricks":66,"minecraft:glass":14,"minecraft:oak_planks":4,"minecraft:polished_diorite":80,"minecraft:sandstone":17,"minecraft:stone_bricks":15},"sha256":"22054cabe26b2097bd8fc64294b7621b2f9ec88e6fb35f311b693f50afc0dd0e","size":{"x":32,"y":1,"z":32}},{"blockCount":6,"bytes":844,"file":"chunks/y050-z192-x160.json","offset":{"x":160,"y":50,"z":192},"requirements":{"minecraft:polished_diorite":6},"sha256":"540cf0d83b4d8db06145541589eb2747cf2dbaeeefe0d18d63d9de71937fabbf","size":{"x":32,"y":1,"z":32}},{"blockCount":212,"bytes":3119,"file":"chunks/y051-z000-x352.json","offset":{"x":352,"y":51,"z":0},"requirements":{"minecraft:glass":6,"minecraft:oak_planks":15,"minecraft:polished_diorite":76,"minecraft:sandstone":56,"minecraft:spruce_planks":1,"minecraft:stone_bricks":58},"sha256":"5707fc369d8a8e28171b71194a180904f4ecd3b8b64489ae98c23b36ff28ece9","size":{"x":32,"y":1,"z":32}},{"blockCount":195,"bytes":3903,"file":"chunks/y051-z000-x384.json","offset":{"x":384,"y":51,"z":0},"requirements":{"minecraft:glass":4,"minecraft:oak_planks":8,"minecraft:polished_diorite":39,"minecraft:sandstone":34,"minecraft:stone_bricks":110},"sha256":"f76aad9f036a14d9a249af2d3c19fd6a26c22c2a8b98f4fb327d35a3a9dfed00","size":{"x":32,"y":1,"z":32}},{"blockCount":8,"bytes":907,"file":"chunks/y051-z032-x352.json","offset":{"x":352,"y":51,"z":32},"requirements":{"minecraft:glass":8},"sha256":"ccbd8535bdc55df4eff4aeee22c15d10eb936a21552c62526fd969642691dd64","size":{"x":32,"y":1,"z":32}},{"blockCount":40,"bytes":1351,"file":"chunks/y051-z032-x384.json","offset":{"x":384,"y":51,"z":32},"requirements":{"minecraft:polished_diorite":14,"minecraft:sandstone":8,"minecraft:stone_bricks":18},"sha256":"164596e5c9de9366588ce4f3f0279e9bbe398e1ae43d14ef30b3acf50f95ba71","size":{"x":32,"y":1,"z":32}},{"blockCount":147,"bytes":3931,"file":"chunks/y051-z064-x064.json","offset":{"x":64,"y":51,"z":64},"requirements":{"minecraft:bricks":30,"minecraft:glass":12,"minecraft:oak_planks":1,"minecraft:polished_diorite":48,"minecraft:sandstone":8,"minecraft:stone_bricks":48},"sha256":"d626a54de96b4747d58e957b3e5302a6c3f143dbe6211944ad029bd62048bd44","size":{"x":32,"y":1,"z":32}},{"blockCount":174,"bytes":3119,"file":"chunks/y051-z064-x096.json","offset":{"x":96,"y":51,"z":64},"requirements":{"minecraft:bricks":61,"minecraft:glass":7,"minecraft:oak_planks":5,"minecraft:polished_diorite":53,"minecraft:sandstone":15,"minecraft:stone_bricks":33},"sha256":"e7cd77773a2944468803f4d8611bf2c27b19ef384b21cf599a4a56e12fe096ad","size":{"x":32,"y":1,"z":32}},{"blockCount":241,"bytes":4847,"file":"chunks/y051-z064-x128.json","offset":{"x":128,"y":51,"z":64},"requirements":{"minecraft:bricks":68,"minecraft:glass":19,"minecraft:oak_planks":4,"minecraft:polished_diorite":87,"minecraft:sandstone":19,"minecraft:stone_bricks":44},"sha256":"0c1cd44903f6d4a1e1ef11a03c1e4cd684c383ae27dc3dbcd7b9bc99b9f3f6c7","size":{"x":32,"y":1,"z":32}},{"blockCount":22,"bytes":1199,"file":"chunks/y051-z064-x160.json","offset":{"x":160,"y":51,"z":64},"requirements":{"minecraft:polished_diorite":7,"minecraft:stone_bricks":15},"sha256":"3cc3cd8703b6982a1fec234302c23d974925b1b18cf349131deed836c8e130e6","size":{"x":32,"y":1,"z":32}},{"blockCount":22,"bytes":1170,"file":"chunks/y051-z064-x192.json","offset":{"x":192,"y":51,"z":64},"requirements":{"minecraft:polished_diorite":9,"minecraft:stone_bricks":13},"sha256":"bab269a77a993566982c4f3f62b456f96d41280e7b4c5563a55daefeae2085ea","size":{"x":32,"y":1,"z":32}},{"blockCount":27,"bytes":1229,"file":"chunks/y051-z064-x224.json","offset":{"x":224,"y":51,"z":64},"requirements":{"minecraft:polished_diorite":12,"minecraft:stone_bricks":15},"sha256":"0ed24267b17bce730f3fb79c20e79da4d63f5eaa726dac700b64da640bc978fd","size":{"x":32,"y":1,"z":32}},{"blockCount":92,"bytes":2908,"file":"chunks/y051-z096-x000.json","offset":{"x":0,"y":51,"z":96},"requirements":{"minecraft:bricks":5,"minecraft:glass":12,"minecraft:polished_diorite":27,"minecraft:sandstone":3,"minecraft:stone_bricks":45},"sha256":"eec1b1d5778c776d314e5f26b7a531182d098957e0cdeff408af38a791e9d878","size":{"x":32,"y":1,"z":32}},{"blockCount":139,"bytes":3547,"file":"chunks/y051-z096-x032.json","offset":{"x":32,"y":51,"z":96},"requirements":{"minecraft:bricks":23,"minecraft:glass":21,"minecraft:polished_diorite":46,"minecraft:sandstone":7,"minecraft:stone_bricks":42},"sha256":"7de37cf5fdf25fa5d77ac00026c292ac894394a9f3b529ebd15c87e8e4ac67fa","size":{"x":32,"y":1,"z":32}},{"blockCount":131,"bytes":3649,"file":"chunks/y051-z096-x064.json","offset":{"x":64,"y":51,"z":96},"requirements":{"minecraft:bricks":29,"minecraft:cobbled_deepslate":4,"minecraft:glass":14,"minecraft:oak_planks":4,"minecraft:polished_diorite":38,"minecraft:sandstone":9,"minecraft:stone_bricks":33},"sha256":"21b658b5b09bf9e57a9222088a430f3c2aa8656faad44727b0cd50c275e00d14","size":{"x":32,"y":1,"z":32}},{"blockCount":25,"bytes":1381,"file":"chunks/y051-z096-x096.json","offset":{"x":96,"y":51,"z":96},"requirements":{"minecraft:bricks":11,"minecraft:cobbled_deepslate":4,"minecraft:glass":10},"sha256":"62803a16f8927d0d225c85cb94ee1241527c2ce5b02d0a58d5aff30130657835","size":{"x":32,"y":1,"z":32}},{"blockCount":76,"bytes":2871,"file":"chunks/y051-z096-x128.json","offset":{"x":128,"y":51,"z":96},"requirements":{"minecraft:bricks":27,"minecraft:cobbled_deepslate":6,"minecraft:glass":14,"minecraft:oak_planks":3,"minecraft:polished_diorite":14,"minecraft:sandstone":5,"minecraft:stone_bricks":7},"sha256":"e64e78a1e179c15e814e128be6a7036087d108b43426d46e1297d936b1d497ef","size":{"x":32,"y":1,"z":32}},{"blockCount":149,"bytes":3588,"file":"chunks/y051-z096-x160.json","offset":{"x":160,"y":51,"z":96},"requirements":{"minecraft:bricks":28,"minecraft:cobbled_deepslate":4,"minecraft:glass":22,"minecraft:oak_planks":1,"minecraft:polished_diorite":42,"minecraft:sandstone":7,"minecraft:stone_bricks":45},"sha256":"ba7efd100ff3ab384ff536d6d95d4761ef15926e0fd4431f5a756cf1940e1766","size":{"x":32,"y":1,"z":32}},{"blockCount":275,"bytes":5252,"file":"chunks/y051-z096-x192.json","offset":{"x":192,"y":51,"z":96},"requirements":{"minecraft:bricks":157,"minecraft:cobbled_deepslate":2,"minecraft:glass":17,"minecraft:oak_planks":2,"minecraft:polished_diorite":40,"minecraft:sandstone":11,"minecraft:stone_bricks":46},"sha256":"4eddea6740adb7ad8a7d2323e3f08f293f0b034eaf44bd6eed8ee11a0c837fc4","size":{"x":32,"y":1,"z":32}},{"blockCount":182,"bytes":4321,"file":"chunks/y051-z096-x224.json","offset":{"x":224,"y":51,"z":96},"requirements":{"minecraft:bricks":79,"minecraft:glass":7,"minecraft:oak_planks":1,"minecraft:polished_diorite":63,"minecraft:sandstone":5,"minecraft:stone_bricks":27},"sha256":"b9eefa04fea8cd1192a3d501d7d48fd8e973774006834cf9e090aecfbbdde583","size":{"x":32,"y":1,"z":32}},{"blockCount":5,"bytes":787,"file":"chunks/y051-z096-x256.json","offset":{"x":256,"y":51,"z":96},"requirements":{"minecraft:spruce_planks":1,"minecraft:stone_bricks":4},"sha256":"f3fa2c2fe65cc04e101d33ab823fcddd2207f2cf885b07b04e5ac963d4ea9e74","size":{"x":32,"y":1,"z":32}},{"blockCount":113,"bytes":3450,"file":"chunks/y051-z128-x000.json","offset":{"x":0,"y":51,"z":128},"requirements":{"minecraft:bricks":18,"minecraft:glass":18,"minecraft:polished_diorite":36,"minecraft:sandstone":6,"minecraft:stone_bricks":35},"sha256":"314b375717b6adcc38bc419fe01d9254c8da85df0814167483220fcd4ebaa62a","size":{"x":32,"y":1,"z":32}},{"blockCount":159,"bytes":4805,"file":"chunks/y051-z128-x032.json","offset":{"x":32,"y":51,"z":128},"requirements":{"minecraft:bricks":42,"minecraft:cobbled_deepslate":28,"minecraft:glass":16,"minecraft:oak_planks":18,"minecraft:polished_diorite":16,"minecraft:spruce_planks":32,"minecraft:stone_bricks":7},"sha256":"c73df464fbdad4b408a3d6edcc6ef6154e91cb4b81bbff7e2dfaadc0ac527368","size":{"x":32,"y":1,"z":32}},{"blockCount":16,"bytes":1078,"file":"chunks/y051-z128-x064.json","offset":{"x":64,"y":51,"z":128},"requirements":{"minecraft:bricks":8,"minecraft:glass":8},"sha256":"aa8c4e271fa6444941439160f1560b45099ed9c7d37897cee37b1d51f73cf769","size":{"x":32,"y":1,"z":32}},{"blockCount":8,"bytes":848,"file":"chunks/y051-z128-x096.json","offset":{"x":96,"y":51,"z":128},"requirements":{"minecraft:bricks":4,"minecraft:glass":4},"sha256":"bbda1180806fe37e472b914a4db642c54e7486137dd46ff412a291668f8dc29c","size":{"x":32,"y":1,"z":32}},{"blockCount":16,"bytes":1076,"file":"chunks/y051-z128-x128.json","offset":{"x":128,"y":51,"z":128},"requirements":{"minecraft:bricks":8,"minecraft:glass":8},"sha256":"aafe9d035a4c858b623abcf4cf331362982a844216c0041e3dc4bd3546b751be","size":{"x":32,"y":1,"z":32}},{"blockCount":19,"bytes":1176,"file":"chunks/y051-z128-x160.json","offset":{"x":160,"y":51,"z":128},"requirements":{"minecraft:bricks":9,"minecraft:glass":10},"sha256":"e4189f5c8cd64d9275f2b66e96f64cfd10389d4db449f49a7fc04f23103aa99f","size":{"x":32,"y":1,"z":32}},{"blockCount":59,"bytes":1969,"file":"chunks/y051-z128-x192.json","offset":{"x":192,"y":51,"z":128},"requirements":{"minecraft:bricks":38,"minecraft:glass":7,"minecraft:oak_planks":2,"minecraft:sandstone":3,"minecraft:stone_bricks":9},"sha256":"effedb73969ec102d43d91b0007d532d9aa590d387624b24ea46b2ecd446ffee","size":{"x":32,"y":1,"z":32}},{"blockCount":169,"bytes":4141,"file":"chunks/y051-z128-x224.json","offset":{"x":224,"y":51,"z":128},"requirements":{"minecraft:bricks":45,"minecraft:glass":1,"minecraft:oak_planks":5,"minecraft:polished_diorite":71,"minecraft:sandstone":17,"minecraft:stone_bricks":30},"sha256":"35e7e59074a7e83aae064105b2fc9504f050f8f829aa96fdea39dbb276aaf25c","size":{"x":32,"y":1,"z":32}},{"blockCount":5,"bytes":791,"file":"chunks/y051-z128-x320.json","offset":{"x":320,"y":51,"z":128},"requirements":{"minecraft:polished_diorite":4,"minecraft:stone_bricks":1},"sha256":"9ca8149b70e5374de0289d5d26f154ad3790eeb828e510a994e26323c8cd8af6","size":{"x":32,"y":1,"z":32}},{"blockCount":62,"bytes":2198,"file":"chunks/y051-z160-x000.json","offset":{"x":0,"y":51,"z":160},"requirements":{"minecraft:bricks":5,"minecraft:glass":6,"minecraft:polished_diorite":20,"minecraft:sandstone":2,"minecraft:stone_bricks":29},"sha256":"638ee60349c4d606eafb44c0ad9f9174657ee898c7fdcca9c049c1a78389f94d","size":{"x":32,"y":1,"z":32}},{"blockCount":123,"bytes":3087,"file":"chunks/y051-z160-x032.json","offset":{"x":32,"y":51,"z":160},"requirements":{"minecraft:bricks":15,"minecraft:glass":13,"minecraft:polished_diorite":46,"minecraft:sandstone":7,"minecraft:stone_bricks":42},"sha256":"2850aaf18147d2e0b3bb7f1a5971b5ef388cf49b3ae6a04bb384b0f0e12d332b","size":{"x":32,"y":1,"z":32}},{"blockCount":140,"bytes":3762,"file":"chunks/y051-z160-x064.json","offset":{"x":64,"y":51,"z":160},"requirements":{"minecraft:bricks":24,"minecraft:cobbled_deepslate":4,"minecraft:glass":9,"minecraft:oak_planks":4,"minecraft:polished_diorite":45,"minecraft:sandstone":11,"minecraft:stone_bricks":43},"sha256":"18b73e215e3c20f8c29bb244393fda91c7cb88f62fad44eed0c0a8f35eb8e3df","size":{"x":32,"y":1,"z":32}},{"blockCount":20,"bytes":1227,"file":"chunks/y051-z160-x096.json","offset":{"x":96,"y":51,"z":160},"requirements":{"minecraft:bricks":8,"minecraft:cobbled_deepslate":4,"minecraft:glass":8},"sha256":"9c7feeb5baae856d5a4f45c921ec5c0c30ee127ca0e8468feeb19f17e7091180","size":{"x":32,"y":1,"z":32}},{"blockCount":86,"bytes":3028,"file":"chunks/y051-z160-x128.json","offset":{"x":128,"y":51,"z":160},"requirements":{"minecraft:bricks":23,"minecraft:cobbled_deepslate":6,"minecraft:glass":11,"minecraft:oak_planks":3,"minecraft:polished_diorite":20,"minecraft:sandstone":9,"minecraft:stone_bricks":14},"sha256":"26c42f0037ed171f0e90a6720d4b085c4c8f0ad8cfc8097c597fbb91559994f7","size":{"x":32,"y":1,"z":32}},{"blockCount":134,"bytes":3109,"file":"chunks/y051-z160-x160.json","offset":{"x":160,"y":51,"z":160},"requirements":{"minecraft:bricks":19,"minecraft:cobbled_deepslate":4,"minecraft:glass":12,"minecraft:oak_planks":1,"minecraft:polished_diorite":43,"minecraft:sandstone":7,"minecraft:stone_bricks":48},"sha256":"d635d97615006aa79d0adb5d18d02941c7800caedb82d81585fdbafd9a6ca6fb","size":{"x":32,"y":1,"z":32}},{"blockCount":258,"bytes":5035,"file":"chunks/y051-z160-x192.json","offset":{"x":192,"y":51,"z":160},"requirements":{"minecraft:bricks":133,"minecraft:cobbled_deepslate":2,"minecraft:glass":10,"minecraft:polished_diorite":49,"minecraft:sandstone":8,"minecraft:stone_bricks":56},"sha256":"8b3eaa09c53c16ba8c512f2fc78378e81843fe2e977361b93e1faea1b5844000","size":{"x":32,"y":1,"z":32}},{"blockCount":145,"bytes":3777,"file":"chunks/y051-z160-x224.json","offset":{"x":224,"y":51,"z":160},"requirements":{"minecraft:bricks":67,"minecraft:glass":6,"minecraft:polished_diorite":41,"minecraft:stone_bricks":31},"sha256":"c02a32eab0a3bd9471fc50bcc843ff0c814bd6c68dc8e0135e1bbbf885c8e6d0","size":{"x":32,"y":1,"z":32}},{"blockCount":5,"bytes":788,"file":"chunks/y051-z160-x256.json","offset":{"x":256,"y":51,"z":160},"requirements":{"minecraft:spruce_planks":1,"minecraft:stone_bricks":4},"sha256":"fb88293370db4fbeb1f544991f582a56b99c86fcd14c502745b56b32b4011c8d","size":{"x":32,"y":1,"z":32}},{"blockCount":122,"bytes":3356,"file":"chunks/y051-z192-x064.json","offset":{"x":64,"y":51,"z":192},"requirements":{"minecraft:bricks":27,"minecraft:glass":9,"minecraft:oak_planks":1,"minecraft:polished_diorite":41,"minecraft:sandstone":6,"minecraft:stone_bricks":38},"sha256":"bf3668cebe45d9a57577f1117e6d41e8625e7b92c3fed9d577ef357f7cb831a0","size":{"x":32,"y":1,"z":32}},{"blockCount":171,"bytes":2988,"file":"chunks/y051-z192-x096.json","offset":{"x":96,"y":51,"z":192},"requirements":{"minecraft:bricks":60,"minecraft:glass":5,"minecraft:oak_planks":5,"minecraft:polished_diorite":53,"minecraft:sandstone":15,"minecraft:stone_bricks":33},"sha256":"b452437efbe285e967b1edb404d7b912a79f22d9f3c482cda296792165d9abf1","size":{"x":32,"y":1,"z":32}},{"blockCount":217,"bytes":4273,"file":"chunks/y051-z192-x128.json","offset":{"x":128,"y":51,"z":192},"requirements":{"minecraft:bricks":64,"minecraft:glass":14,"minecraft:oak_planks":4,"minecraft:polished_diorite":81,"minecraft:sandstone":17,"minecraft:stone_bricks":37},"sha256":"53b383b7f7901152fc988727008c7d8815b9ad04bdf9277e11eb5a0ce03e60fb","size":{"x":32,"y":1,"z":32}},{"blockCount":18,"bytes":1104,"file":"chunks/y051-z192-x160.json","offset":{"x":160,"y":51,"z":192},"requirements":{"minecraft:polished_diorite":6,"minecraft:stone_bricks":12},"sha256":"9d499f0f20480e31bb2a729c3c01e70a9dc74406a5f4c5e48ac38887dbd08201","size":{"x":32,"y":1,"z":32}},{"blockCount":234,"bytes":3991,"file":"chunks/y052-z000-x352.json","offset":{"x":352,"y":52,"z":0},"requirements":{"minecraft:oak_planks":10,"minecraft:polished_diorite":61,"minecraft:sandstone":33,"minecraft:spruce_planks":27,"minecraft:stone_bricks":103},"sha256":"70dff4af14270f1c1c888bbccdc882c6885817cdbceb50699ecb025f101f9907","size":{"x":32,"y":1,"z":32}},{"blockCount":178,"bytes":3893,"file":"chunks/y052-z000-x384.json","offset":{"x":384,"y":52,"z":0},"requirements":{"minecraft:glass":4,"minecraft:oak_planks":27,"minecraft:polished_diorite":42,"minecraft:sandstone":1,"minecraft:spruce_planks":16,"minecraft:stone_bricks":88},"sha256":"f36d79d5c697ac85dc528c9fbd39a34d928c062bbf9a4c8dd6a436d160a0845c","size":{"x":32,"y":1,"z":32}},{"blockCount":40,"bytes":1276,"file":"chunks/y052-z032-x384.json","offset":{"x":384,"y":52,"z":32},"requirements":{"minecraft:oak_planks":8,"minecraft:polished_diorite":10,"minecraft:stone_bricks":22},"sha256":"a67602f9195a7021ad30be7bf4fefd7160e245a16b1831c6af0a0e50a4e3b6e4","size":{"x":32,"y":1,"z":32}},{"blockCount":141,"bytes":3551,"file":"chunks/y052-z064-x064.json","offset":{"x":64,"y":52,"z":64},"requirements":{"minecraft:bricks":33,"minecraft:glass":12,"minecraft:oak_planks":1,"minecraft:polished_diorite":72,"minecraft:sandstone":8,"minecraft:stone_bricks":15},"sha256":"b2938048926f9e4cf4467b618e9aa9fbbfc4d1b522c9964cd8a3579a41c0db7e","size":{"x":32,"y":1,"z":32}},{"blockCount":157,"bytes":3023,"file":"chunks/y052-z064-x096.json","offset":{"x":96,"y":52,"z":64},"requirements":{"minecraft:bricks":62,"minecraft:glass":7,"minecraft:oak_planks":5,"minecraft:polished_diorite":55,"minecraft:sandstone":15,"minecraft:stone_bricks":13},"sha256":"fa52f0a6c88110509a48f28717d1572d22c794af77f701a05f3f6f771f5b670e","size":{"x":32,"y":1,"z":32}},{"blockCount":235,"bytes":4715,"file":"chunks/y052-z064-x128.json","offset":{"x":128,"y":52,"z":64},"requirements":{"minecraft:bricks":71,"minecraft:glass":19,"minecraft:oak_planks":4,"minecraft:polished_diorite":100,"minecraft:sandstone":19,"minecraft:stone_bricks":22},"sha256":"1b75fa4e301f1f3cbdc6c7232e2b3a263e0605dc1fe77150d0495ce0c3914ef5","size":{"x":32,"y":1,"z":32}},{"blockCount":19,"bytes":1142,"file":"chunks/y052-z064-x160.json","offset":{"x":160,"y":52,"z":64},"requirements":{"minecraft:polished_diorite":17,"minecraft:stone_bricks":2},"sha256":"7654e78fa14c6a8d6baf2de631745321251442cf632ad209c08597f96edef6b8","size":{"x":32,"y":1,"z":32}},{"blockCount":20,"bytes":1094,"file":"chunks/y052-z064-x192.json","offset":{"x":192,"y":52,"z":64},"requirements":{"minecraft:polished_diorite":19,"minecraft:stone_bricks":1},"sha256":"8f33e08c38663470ace5440a714e8e57ce0a2460d9f1dd3fc9826b2829c41e89","size":{"x":32,"y":1,"z":32}},{"blockCount":24,"bytes":1133,"file":"chunks/y052-z064-x224.json","offset":{"x":224,"y":52,"z":64},"requirements":{"minecraft:polished_diorite":22,"minecraft:stone_bricks":2},"sha256":"ae210d15df990ad4bf68c1103628711c13ed5302552cedeb536d57d7ae0c0b2b","size":{"x":32,"y":1,"z":32}},{"blockCount":82,"bytes":2623,"file":"chunks/y052-z096-x000.json","offset":{"x":0,"y":52,"z":96},"requirements":{"minecraft:bricks":5,"minecraft:glass":13,"minecraft:polished_diorite":50,"minecraft:sandstone":3,"minecraft:stone_bricks":11},"sha256":"307ffa056a4c3c0aa202290ed1f12629aa167d4456571898223d81d0307c1eb7","size":{"x":32,"y":1,"z":32}},{"blockCount":131,"bytes":3471,"file":"chunks/y052-z096-x032.json","offset":{"x":32,"y":52,"z":96},"requirements":{"minecraft:bricks":26,"minecraft:glass":22,"minecraft:polished_diorite":63,"minecraft:sandstone":6,"minecraft:stone_bricks":14},"sha256":"757707feec0663341fdf62bea32c6a7e3ccb744724dcf69b519864eb3c4f625c","size":{"x":32,"y":1,"z":32}},{"blockCount":130,"bytes":3709,"file":"chunks/y052-z096-x064.json","offset":{"x":64,"y":52,"z":96},"requirements":{"minecraft:bricks":31,"minecraft:cobbled_deepslate":6,"minecraft:glass":14,"minecraft:oak_planks":4,"minecraft:polished_diorite":51,"minecraft:sandstone":9,"minecraft:stone_bricks":15},"sha256":"cf421925c5cd8c575d60e2efb53aa6057d89f7ca35145f205c6ca1df207b4abc","size":{"x":32,"y":1,"z":32}},{"blockCount":29,"bytes":1370,"file":"chunks/y052-z096-x096.json","offset":{"x":96,"y":52,"z":96},"requirements":{"minecraft:bricks":11,"minecraft:cobbled_deepslate":6,"minecraft:glass":10,"minecraft:stone_bricks":2},"sha256":"d7587b734d9dd8324639b6b62a899323763d67d8d76601cdec28d2916921bbab","size":{"x":32,"y":1,"z":32}}],"schema":1}
