{"entries":[{"blockCount":80,"bytes":2796,"file":"chunks/y052-z096-x128.json","offset":{"x":128,"y":52,"z":96},"requirements":{"minecraft:bricks":27,"minecraft:cobbled_deepslate":9,"minecraft:glass":14,"minecraft:oak_planks":3,"minecraft:polished_diorite":14,"minecraft:sandstone":5,"minecraft:stone_bricks":8},"sha256":"4dc39885f62d3267257cfcd68a655139386b46b5c58cb0f173ee8cbdfd21d140","size":{"x":32,"y":1,"z":32}},{"blockCount":146,"bytes":3763,"file":"chunks/y052-z096-x160.json","offset":{"x":160,"y":52,"z":96},"requirements":{"minecraft:bricks":32,"minecraft:cobbled_deepslate":6,"minecraft:glass":22,"minecraft:oak_planks":1,"minecraft:polished_diorite":62,"minecraft:sandstone":7,"minecraft:stone_bricks":16},"sha256":"55999bb6463fc679da7825144de0760707475751ce004911f99ea561a6835e0e","size":{"x":32,"y":1,"z":32}},{"blockCount":277,"bytes":5330,"file":"chunks/y052-z096-x192.json","offset":{"x":192,"y":52,"z":96},"requirements":{"minecraft:bricks":156,"minecraft:cobbled_deepslate":3,"minecraft:glass":17,"minecraft:oak_planks":2,"minecraft:polished_diorite":56,"minecraft:sandstone":14,"minecraft:stone_bricks":29},"sha256":"19fca4961d116dbb75007441120b0c313060520849dc4c59846046db5a757f3a","size":{"x":32,"y":1,"z":32}},{"blockCount":175,"bytes":4130,"file":"chunks/y052-z096-x224.json","offset":{"x":224,"y":52,"z":96},"requirements":{"minecraft:bricks":78,"minecraft:glass":7,"minecraft:oak_planks":1,"minecraft:polished_diorite":76,"minecraft:sandstone":5,"minecraft:stone_bricks":8},"sha256":"395fc4a4947a777423ba506a0d8e69039ca61bba38e8380e6f1fba2741519b25","size":{"x":32,"y":1,"z":32}},{"blockCount":1,"bytes":643,"file":"chunks/y052-z096-x256.json","offset":{"x":256,"y":52,"z":96},"requirements":{"minecraft:stone_bricks":1},"sha256":"aedb0a8be9baab3b8111d1a56e38981390e9751c6f448fae545baf5057d602ae","size":{"x":32,"y":1,"z":32}},{"blockCount":100,"bytes":3089,"file":"chunks/y052-z128-x000.json","offset":{"x":0,"y":52,"z":128},"requirements":{"minecraft:bricks":18,"minecraft:glass":18,"minecraft:polished_diorite":45,"minecraft:sandstone":6,"minecraft:stone_bricks":13},"sha256":"194f1f852ae614660fc908c8a3b2e7e705f11700daf5a14fdd64cbb24933d2b5","size":{"x":32,"y":1,"z":32}},{"blockCount":165,"bytes":4389,"file":"chunks/y052-z128-x032.json","offset":{"x":32,"y":52,"z":128},"requirements":{"minecraft:bricks":46,"minecraft:cobbled_deepslate":26,"minecraft:glass":16,"minecraft:oak_planks":13,"minecraft:polished_diorite":17,"minecraft:spruce_planks":42,"minecraft:stone_bricks":5},"sha256":"9354b2f55e7c5233586a7460172ae9992d8793b004c0d2a4ed7b1625d9f1d23f","size":{"x":32,"y":1,"z":32}},{"blockCount":16,"bytes":1078,"file":"chunks/y052-z128-x064.json","offset":{"x":64,"y":52,"z":128},"requirements":{"minecraft:bricks":8,"minecraft:glass":8},"sha256":"c932376eb76f1f24fa74c678155ea41caa7f62c07ca01228e2eee45d2dc648e7","size":{"x":32,"y":1,"z":32}},{"blockCount":8,"bytes":848,"file":"chunks/y052-z128-x096.json","offset":{"x":96,"y":52,"z":128},"requirements":{"minecraft:bricks":4,"minecraft:glass":4},"sha256":"9d45e96ed64a3a7611beb1fee06d3ba04b2b001993102a1de0bf865f48827d9b","size":{"x":32,"y":1,"z":32}},{"blockCount":16,"bytes":1076,"file":"chunks/y052-z128-x128.json","offset":{"x":128,"y":52,"z":128},"requirements":{"minecraft:bricks":8,"minecraft:glass":8},"sha256":"9a8bcb0a59390deae407b20c09fb286710a9dd349ae3434809bdafdea48b7cd0","size":{"x":32,"y":1,"z":32}},{"blockCount":19,"bytes":1176,"file":"chunks/y052-z128-x160.json","offset":{"x":160,"y":52,"z":128},"requirements":{"minecraft:bricks":9,"minecraft:glass":10},"sha256":"3907a5aec7a05a7c779d5240eeba8d45813943dc7b7ae338dd8f1e3d11f45cc4","size":{"x":32,"y":1,"z":32}},{"blockCount":58,"bytes":2084,"file":"chunks/y052-z128-x192.json","offset":{"x":192,"y":52,"z":128},"requirements":{"minecraft:bricks":39,"minecraft:glass":7,"minecraft:oak_planks":2,"minecraft:sandstone":5,"minecraft:stone_bricks":5},"sha256":"92792cbc2193d0aaba33c681a2768ea805bea3ed44614f5d09f8a65abebbae4d","size":{"x":32,"y":1,"z":32}},{"blockCount":155,"bytes":4027,"file":"chunks/y052-z128-x224.json","offset":{"x":224,"y":52,"z":128},"requirements":{"minecraft:bricks":45,"minecraft:glass":1,"minecraft:oak_planks":5,"minecraft:polished_diorite":74,"minecraft:sandstone":17,"minecraft:stone_bricks":13},"sha256":"c52da96b6224e9ad5767dc9069071a1ad5a627b5e6b0eff32900a6409a0b7e82","size":{"x":32,"y":1,"z":32}},{"blockCount":4,"bytes":764,"file":"chunks/y052-z128-x320.json","offset":{"x":320,"y":52,"z":128},"requirements":{"minecraft:polished_diorite":4},"sha256":"91d91a8e9db8d6b4f375836327961ed3240a61e6b58c77db9ee4010956f01434","size":{"x":32,"y":1,"z":32}},{"blockCount":55,"bytes":2007,"file":"chunks/y052-z160-x000.json","offset":{"x":0,"y":52,"z":160},"requirements":{"minecraft:bricks":5,"minecraft:glass":7,"minecraft:polished_diorite":34,"minecraft:sandstone":2,"minecraft:stone_bricks":7},"sha256":"918d6004b2250dc4a82b7a83c32e0933292760273cd3f783a844f34b64f0ac56","size":{"x":32,"y":1,"z":32}},{"blockCount":115,"bytes":3030,"file":"chunks/y052-z160-x032.json","offset":{"x":32,"y":52,"z":160},"requirements":{"minecraft:bricks":18,"minecraft:glass":14,"minecraft:polished_diorite":63,"minecraft:sandstone":6,"minecraft:stone_bricks":14},"sha256":"db14195a311db8c759a00decf04bc20a9b865247fdcfd2af3dac222897795ac4","size":{"x":32,"y":1,"z":32}},{"blockCount":137,"bytes":3727,"file":"chunks/y052-z160-x064.json","offset":{"x":64,"y":52,"z":160},"requirements":{"minecraft:bricks":27,"minecraft:cobbled_deepslate":6,"minecraft:glass":9,"minecraft:oak_planks":4,"minecraft:polished_diorite":62,"minecraft:sandstone":11,"minecraft:stone_bricks":18},"sha256":"6bc920147b7b46e0153ac1bde48d0200ac478e374afff384ebac5fd8fc55236c","size":{"x":32,"y":1,"z":32}},{"blockCount":24,"bytes":1216,"file":"chunks/y052-z160-x096.json","offset":{"x":96,"y":52,"z":160},"requirements":{"minecraft:bricks":8,"minecraft:cobbled_deepslate":6,"minecraft:glass":8,"minecraft:stone_bricks":2},"sha256":"9eae6c0c3b13e2a33ddb6bed685ab95e49738a0f35f9900c254084f2166cfe8d","size":{"x":32,"y":1,"z":32}},{"blockCount":89,"bytes":2896,"file":"chunks/y052-z160-x128.json","offset":{"x":128,"y":52,"z":160},"requirements":{"minecraft:bricks":24,"minecraft:cobbled_deepslate":9,"minecraft:glass":11,"minecraft:oak_planks":3,"minecraft:polished_diorite":22,"minecraft:sandstone":9,"minecraft:stone_bricks":11},"sha256":"6f70b1bf4373bcaeba8ed16dc9c3e49e4ebcc9e5085fabe0225bf33c24e78039","size":{"x":32,"y":1,"z":32}},{"blockCount":130,"bytes":3322,"file":"chunks/y052-z160-x160.json","offset":{"x":160,"y":52,"z":160},"requirements":{"minecraft:bricks":23,"minecraft:cobbled_deepslate":6,"minecraft:glass":12,"minecraft:oak_planks":1,"minecraft:polished_diorite":65,"minecraft:sandstone":7,"minecraft:stone_bricks":16},"sha256":"8e60dfc956470cf090cdbd9b4131d75e55968d401084fc53bd448b91bc1e3779","size":{"x":32,"y":1,"z":32}},{"blockCount":256,"bytes":4903,"file":"chunks/y052-z160-x192.json","offset":{"x":192,"y":52,"z":160},"requirements":{"minecraft:bricks":132,"minecraft:cobbled_deepslate":3,"minecraft:glass":10,"minecraft:polished_diorite":75,"minecraft:sandstone":9,"minecraft:stone_bricks":27},"sha256":"1168881c65ac89ce04a98dbd66d1a22687137e831c918dcfc4d72d705deca028","size":{"x":32,"y":1,"z":32}},{"blockCount":142,"bytes":3548,"file":"chunks/y052-z160-x224.json","offset":{"x":224,"y":52,"z":160},"requirements":{"minecraft:bricks":66,"minecraft:glass":6,"minecraft:polished_diorite":63,"minecraft:stone_bricks":7},"sha256":"05193389f873e3d81c378a33ccd71a3d8bc679569aa116547a52c524029886c1","size":{"x":32,"y":1,"z":32}},{"blockCount":1,"bytes":644,"file":"chunks/y052-z160-x256.json","offset":{"x":256,"y":52,"z":160},"requirements":{"minecraft:stone_bricks":1},"sha256":"56150c71d349b91b29876f0f71ca7d6db890f8da0794b84a191f61278969b4db","size":{"x":32,"y":1,"z":32}},{"blockCount":118,"bytes":3071,"file":"chunks/y052-z192-x064.json","offset":{"x":64,"y":52,"z":192},"requirements":{"minecraft:bricks":29,"minecraft:glass":9,"minecraft:oak_planks":1,"minecraft:polished_diorite":61,"minecraft:sandstone":6,"minecraft:stone_bricks":12},"sha256":"17dcf855462f0127dadb49c2cb806f15a52cedaea3ee9677eb9d14277b01861e","size":{"x":32,"y":1,"z":32}},{"blockCount":154,"bytes":2911,"file":"chunks/y052-z192-x096.json","offset":{"x":96,"y":52,"z":192},"requirements":{"minecraft:bricks":61,"minecraft:glass":5,"minecraft:oak_planks":5,"minecraft:polished_diorite":55,"minecraft:sandstone":15,"minecraft:stone_bricks":13},"sha256":"848c93d3b0facf1d616c2ac150e7eff3064c57989095d6424bf58bed83e48ed8","size":{"x":32,"y":1,"z":32}},{"blockCount":212,"bytes":4178,"file":"chunks/y052-z192-x128.json","offset":{"x":128,"y":52,"z":192},"requirements":{"minecraft:bricks":66,"minecraft:glass":14,"minecraft:oak_planks":4,"minecraft:polished_diorite":92,"minecraft:sandstone":17,"minecraft:stone_bricks":19},"sha256":"67e312d7626a4524b608a239080546dd8e20dd89c6ec0c7ca46f9d54d0071f2f","size":{"x":32,"y":1,"z":32}},{"blockCount":16,"bytes":1066,"file":"chunks/y052-z192-x160.json","offset":{"x":160,"y":52,"z":192},"requirements":{"minecraft:polished_diorite":14,"minecraft:stone_bricks":2},"sha256":"1a9b6212c1f9df998db5863656cd43e13722f9f217ec52187d64288138f2be04","size":{"x":32,"y":1,"z":32}},{"blockCount":148,"bytes":3020,"file":"chunks/y053-z000-x352.json","offset":{"x":352,"y":53,"z":0},"requirements":{"minecraft:glass":5,"minecraft:oak_planks":28,"minecraft:polished_diorite":18,"minecraft:sandstone":27,"minecraft:spruce_planks":7,"minecraft:stone_bricks":63},"sha256":"b2e4fd47c14f82a91f16c70657b48ebf64b442ba33c410e250b47849367d335f","size":{"x":32,"y":1,"z":32}},{"blockCount":158,"bytes":3181,"file":"chunks/y053-z000-x384.json","offset":{"x":384,"y":53,"z":0},"requirements":{"minecraft:glass":2,"minecraft:oak_planks":48,"minecraft:polished_diorite":29,"minecraft:sandstone":1,"minecraft:stone_bricks":78},"sha256":"3e9f102ebbaaad85dc3ebdf069051166e1214d6bb51233fdefcc2bd0611dd44b","size":{"x":32,"y":1,"z":32}},{"blockCount":26,"bytes":1007,"file":"chunks/y053-z032-x384.json","offset":{"x":384,"y":53,"z":32},"requirements":{"minecraft:oak_planks":6,"minecraft:polished_diorite":12,"minecraft:stone_bricks":8},"sha256":"a871bd28dd7ee4e6a1a475628c2c1da5b8d495732e6d4a8ec903d8e78da8dd47","size":{"x":32,"y":1,"z":32}},{"blockCount":137,"bytes":3817,"file":"chunks/y053-z064-x064.json","offset":{"x":64,"y":53,"z":64},"requirements":{"minecraft:bricks":29,"minecraft:glass":12,"minecraft:oak_planks":1,"minecraft:polished_diorite":62,"minecraft:sandstone":8,"minecraft:stone_bricks":25},"sha256":"59eb4503374a5d5de1890336f41767ae8a017d9e1c3d37b35be4da6017f8296f","size":{"x":32,"y":1,"z":32}},{"blockCount":172,"bytes":2987,"file":"chunks/y053-z064-x096.json","offset":{"x":96,"y":53,"z":64},"requirements":{"minecraft:bricks":63,"minecraft:glass":7,"minecraft:oak_planks":5,"minecraft:polished_diorite":62,"minecraft:sandstone":15,"minecraft:stone_bricks":20},"sha256":"d3974ca3203f914d41aa19b872427b04024343e1d802659b71d01ac63dd30313","size":{"x":32,"y":1,"z":32}},{"blockCount":233,"bytes":4619,"file":"chunks/y053-z064-x128.json","offset":{"x":128,"y":53,"z":64},"requirements":{"minecraft:bricks":68,"minecraft:glass":19,"minecraft:oak_planks":4,"minecraft:polished_diorite":95,"minecraft:sandstone":20,"minecraft:stone_bricks":27},"sha256":"9e80e564336a7c53ecb46ba7d3db31b3afc2e7e3aecb0bb31c278358c0697a88","size":{"x":32,"y":1,"z":32}},{"blockCount":17,"bytes":1199,"file":"chunks/y053-z064-x160.json","offset":{"x":160,"y":53,"z":64},"requirements":{"minecraft:polished_diorite":12,"minecraft:stone_bricks":5},"sha256":"000e2a2809136b4d9f0d6e3007307c3a603520c3d1823a5b35145fbe14cb08ea","size":{"x":32,"y":1,"z":32}},{"blockCount":20,"bytes":1189,"file":"chunks/y053-z064-x192.json","offset":{"x":192,"y":53,"z":64},"requirements":{"minecraft:polished_diorite":13,"minecraft:stone_bricks":7},"sha256":"5421cc60097648ace6040ee40c84c2fe0ad683543d1ecea11c4d990c0faa0ee6","size":{"x":32,"y":1,"z":32}},{"blockCount":25,"bytes":1285,"file":"chunks/y053-z064-x224.json","offset":{"x":224,"y":53,"z":64},"requirements":{"minecraft:polished_diorite":16,"minecraft:stone_bricks":9},"sha256":"ae46dd92be21fd5b7b8755bed13e8de12f9477de9c47a01283e0bc54674b5ff7","size":{"x":32,"y":1,"z":32}},{"blockCount":75,"bytes":2832,"file":"chunks/y053-z096-x000.json","offset":{"x":0,"y":53,"z":96},"requirements":{"minecraft:bricks":4,"minecraft:glass":13,"minecraft:polished_diorite":39,"minecraft:sandstone":1,"minecraft:stone_bricks":18},"sha256":"7991501cbdf11a755dc03870b6d4a497835bac9b529b86ee165d94ae6b912ed8","size":{"x":32,"y":1,"z":32}},{"blockCount":124,"bytes":3491,"file":"chunks/y053-z096-x032.json","offset":{"x":32,"y":53,"z":96},"requirements":{"minecraft:bricks":22,"minecraft:glass":22,"minecraft:polished_diorite":53,"minecraft:sandstone":6,"minecraft:stone_bricks":21},"sha256":"754cf3aa00b70390bb51476ea9a2e96c24c12ff8163169af0baac6af0f1143ca","size":{"x":32,"y":1,"z":32}},{"blockCount":123,"bytes":3434,"file":"chunks/y053-z096-x064.json","offset":{"x":64,"y":53,"z":96},"requirements":{"minecraft:bricks":29,"minecraft:cobbled_deepslate":4,"minecraft:glass":14,"minecraft:polished_diorite":43,"minecraft:sandstone":13,"minecraft:stone_bricks":20},"sha256":"8494aa6fa6c86310ed82cc55f8a2908d706c5b3b69f57e14c82cf47e123b9dc9","size":{"x":32,"y":1,"z":32}},{"blockCount":25,"bytes":1381,"file":"chunks/y053-z096-x096.json","offset":{"x":96,"y":53,"z":96},"requirements":{"minecraft:bricks":11,"minecraft:cobbled_deepslate":4,"minecraft:glass":10},"sha256":"29350bc538e530072b2adda39ddd577c410e8fce5f11c280c0a6a0ea41801097","size":{"x":32,"y":1,"z":32}},{"blockCount":76,"bytes":2694,"file":"chunks/y053-z096-x128.json","offset":{"x":128,"y":53,"z":96},"requirements":{"minecraft:bricks":27,"minecraft:cobbled_deepslate":6,"minecraft:glass":14,"minecraft:polished_diorite":13,"minecraft:sandstone":8,"minecraft:stone_bricks":8},"sha256":"063f869b07c627fe850e41e61d1ba71f671544267a62280d260141b978b01729","size":{"x":32,"y":1,"z":32}},{"blockCount":135,"bytes":3603,"file":"chunks/y053-z096-x160.json","offset":{"x":160,"y":53,"z":96},"requirements":{"minecraft:bricks":28,"minecraft:cobbled_deepslate":4,"minecraft:glass":22,"minecraft:polished_diorite":51,"minecraft:sandstone":8,"minecraft:stone_bricks":22},"sha256":"c1c9215f6bd1fc461e28c64e16bbbc2fcb3bdc9627c9accad4e39a52a0ece830","size":{"x":32,"y":1,"z":32}},{"blockCount":262,"bytes":5057,"file":"chunks/y053-z096-x192.json","offset":{"x":192,"y":53,"z":96},"requirements":{"minecraft:bricks":158,"minecraft:cobbled_deepslate":2,"minecraft:glass":16,"minecraft:polished_diorite":45,"minecraft:sandstone":10,"minecraft:stone_bricks":31},"sha256":"1faf708416a28c86a0e563adf0f669cca28e3bd20a612cc2e06ab756a85eefe9","size":{"x":32,"y":1,"z":32}},{"blockCount":176,"bytes":4397,"file":"chunks/y053-z096-x224.json","offset":{"x":224,"y":53,"z":96},"requirements":{"minecraft:bricks":75,"minecraft:glass":5,"minecraft:oak_planks":1,"minecraft:polished_diorite":73,"minecraft:sandstone":5,"minecraft:stone_bricks":17},"sha256":"efec00af38e6d7f71e48c3219f366480655dcda6771f01e20fc3d8f24e6b546f","size":{"x":32,"y":1,"z":32}},{"blockCount":94,"bytes":3241,"file":"chunks/y053-z128-x000.json","offset":{"x":0,"y":53,"z":128},"requirements":{"minecraft:bricks":18,"minecraft:glass":18,"minecraft:polished_diorite":37,"minecraft:sandstone":5,"minecraft:stone_bricks":16},"sha256":"dae04932a791d81837450b56988d8fb9f3494a0d18884a2e67d0834077942d1b","size":{"x":32,"y":1,"z":32}},{"blockCount":153,"bytes":4196,"file":"chunks/y053-z128-x032.json","offset":{"x":32,"y":53,"z":128},"requirements":{"minecraft:bricks":44,"minecraft:cobbled_deepslate":24,"minecraft:glass":16,"minecraft:oak_planks":9,"minecraft:polished_diorite":19,"minecraft:spruce_planks":36,"minecraft:stone_bricks":5},"sha256":"db33878207664f0d655238dcbb733f746fb9d2d1a6379f0b8d3811262892c2b7","size":{"x":32,"y":1,"z":32}},{"blockCount":16,"bytes":1078,"file":"chunks/y053-z128-x064.json","offset":{"x":64,"y":53,"z":128},"requirements":{"minecraft:bricks":8,"minecraft:glass":8},"sha256":"e40a280136815aaa3844cc60a06accfc3285c13ca0becb792cf547b289a7b0f9","size":{"x":32,"y":1,"z":32}},{"blockCount":8,"bytes":848,"file":"chunks/y053-z128-x096.json","offset":{"x":96,"y":53,"z":128},"requirements":{"minecraft:bricks":4,"minecraft:glass":4},"sha256":"86ec60ed59980af224d99b9d1ee9bc7d2c021b1a3427a8037fd83cb2860e520b","size":{"x":32,"y":1,"z":32}},{"blockCount":16,"bytes":1076,"file":"chunks/y053-z128-x128.json","offset":{"x":128,"y":53,"z":128},"requirements":{"minecraft:bricks":8,"minecraft:glass":8},"sha256":"4fca8895ee075fb6ec75228594ec2e1d939803821bb1eb3b3a7f98f45ba89d77","size":{"x":32,"y":1,"z":32}},{"blockCount":19,"bytes":1176,"file":"chunks/y053-z128-x160.json","offset":{"x":160,"y":53,"z":128},"requirements":{"minecraft:bricks":9,"minecraft:glass":10},"sha256":"e15ba7b83d6fdb7dad9fffba98723bbd6108c4becba7c88372c193134f571706","size":{"x":32,"y":1,"z":32}},{"blockCount":64,"bytes":1946,"file":"chunks/y053-z128-x192.json","offset":{"x":192,"y":53,"z":128},"requirements":{"minecraft:bricks":40,"minecraft:glass":7,"minecraft:sandstone":4,"minecraft:stone_bricks":13},"sha256":"88ed76673d56c10598e02e861318ddb52ad7a2b53fd5b1189c29f91b8dbaba19","size":{"x":32,"y":1,"z":32}},{"blockCount":169,"bytes":4084,"file":"chunks/y053-z128-x224.json","offset":{"x":224,"y":53,"z":128},"requirements":{"minecraft:bricks":47,"minecraft:glass":1,"minecraft:oak_planks":5,"minecraft:polished_diorite":84,"minecraft:sandstone":17,"minecraft:stone_bricks":15},"sha256":"e2fe36add371840c0da90b9e0678ee3b9b97af38bd68ef9b0b978a675b750d56","size":{"x":32,"y":1,"z":32}},{"blockCount":5,"bytes":791,"file":"chunks/y053-z128-x320.json","offset":{"x":320,"y":53,"z":128},"requirements":{"minecraft:polished_diorite":4,"minecraft:stone_bricks":1},"sha256":"d4b2b704fe257f8478142ff023e319578aa1e6b4bba809ef70abbf5d57281f9b","size":{"x":32,"y":1,"z":32}},{"blockCount":50,"bytes":2141,"file":"chunks/y053-z160-x000.json","offset":{"x":0,"y":53,"z":160},"requirements":{"minecraft:bricks":4,"minecraft:glass":7,"minecraft:polished_diorite":27,"minecraft:sandstone":1,"minecraft:stone_bricks":11},"sha256":"be0072b31880c9c1b8c9aee4d0ed21f262070548f605a337e8443b035f9219bb","size":{"x":32,"y":1,"z":32}},{"blockCount":108,"bytes":3050,"file":"chunks/y053-z160-x032.json","offset":{"x":32,"y":53,"z":160},"requirements":{"minecraft:bricks":14,"minecraft:glass":14,"minecraft:polished_diorite":53,"minecraft:sandstone":6,"minecraft:stone_bricks":21},"sha256":"9a3be118e8a213120883ca132fabe6c81a54160735fde7d5876c8db4692eb753","size":{"x":32,"y":1,"z":32}},{"blockCount":129,"bytes":3526,"file":"chunks/y053-z160-x064.json","offset":{"x":64,"y":53,"z":160},"requirements":{"minecraft:bricks":24,"minecraft:cobbled_deepslate":4,"minecraft:glass":9,"minecraft:polished_diorite":52,"minecraft:sandstone":15,"minecraft:stone_bricks":25},"sha256":"96ecd44dce289a1c5353dae362cafaf28f8d07acebe26d6fb43f08f20e0dd5eb","size":{"x":32,"y":1,"z":32}},{"blockCount":20,"bytes":1227,"file":"chunks/y053-z160-x096.json","offset":{"x":96,"y":53,"z":160},"requirements":{"minecraft:bricks":8,"minecraft:cobbled_deepslate":4,"minecraft:glass":8},"sha256":"3a27e96a59e3b876984282d8a536ac2dfb7fb11385afd7f2e289353bd560a3f5","size":{"x":32,"y":1,"z":32}},{"blockCount":84,"bytes":2776,"file":"chunks/y053-z160-x128.json","offset":{"x":128,"y":53,"z":160},"requirements":{"minecraft:bricks":23,"minecraft:cobbled_deepslate":6,"minecraft:glass":11,"minecraft:polished_diorite":20,"minecraft:sandstone":12,"minecraft:stone_bricks":12},"sha256":"b83897ec0064dcdab348965d4b65b6bc5d4d440057957529bf5c7542468c5398","size":{"x":32,"y":1,"z":32}},{"blockCount":119,"bytes":3200,"file":"chunks/y053-z160-x160.json","offset":{"x":160,"y":53,"z":160},"requirements":{"minecraft:bricks":19,"minecraft:cobbled_deepslate":4,"minecraft:glass":12,"minecraft:polished_diorite":53,"minecraft:sandstone":8,"minecraft:stone_bricks":23},"sha256":"8ff6317164c891c15ff79c41cc9f7e491731e63b9c7fb65ba1e8ed003db71bd4","size":{"x":32,"y":1,"z":32}},{"blockCount":239,"bytes":4922,"file":"chunks/y053-z160-x192.json","offset":{"x":192,"y":53,"z":160},"requirements":{"minecraft:bricks":133,"minecraft:cobbled_deepslate":2,"minecraft:glass":9,"minecraft:polished_diorite":58,"minecraft:sandstone":6,"minecraft:stone_bricks":31},"sha256":"aaf9d847744d17c31216aaf7c1ff0146b0b2564b8b9776642df74317038aa959","size":{"x":32,"y":1,"z":32}},{"blockCount":139,"bytes":3986,"file":"chunks/y053-z160-x224.json","offset":{"x":224,"y":53,"z":160},"requirements":{"minecraft:bricks":63,"minecraft:glass":4,"minecraft:polished_diorite":51,"minecraft:stone_bricks":21},"sha256":"32c8b1c79473e685ebd7a562e682f807d70ad8777d71bb689cac80059601341a","size":{"x":32,"y":1,"z":32}},{"blockCount":115,"bytes":3261,"file":"chunks/y053-z192-x064.json","offset":{"x":64,"y":53,"z":192},"requirements":{"minecraft:bricks":26,"minecraft:glass":9,"minecraft:oak_planks":1,"minecraft:polished_diorite":53,"minecraft:sandstone":6,"minecraft:stone_bricks":20},"sha256":"71308c5b625ab656e4825db1f527c1ed8222c5fa4e1e247b86c1998b06d77eef","size":{"x":32,"y":1,"z":32}},{"blockCount":169,"bytes":2875,"file":"chunks/y053-z192-x096.json","offset":{"x":96,"y":53,"z":192},"requirements":{"minecraft:bricks":62,"minecraft:glass":5,"minecraft:oak_planks":5,"minecraft:polished_diorite":62,"minecraft:sandstone":15,"minecraft:stone_bricks":20},"sha256":"4b1eb5f408b661f8cc10617f3e4a5940af8120111517ec71e8e93c658534bcba","size":{"x":32,"y":1,"z":32}},{"blockCount":211,"bytes":4102,"file":"chunks/y053-z192-x128.json","offset":{"x":128,"y":53,"z":192},"requirements":{"minecraft:bricks":64,"minecraft:glass":14,"minecraft:oak_planks":4,"minecraft:polished_diorite":88,"minecraft:sandstone":18,"minecraft:stone_bricks":23},"sha256":"2b14ab15bb4fbf165967618f3ff70397e89448a99c87e85581d923e67ab94bc3","size":{"x":32,"y":1,"z":32}},{"blockCount":14,"bytes":1104,"file":"chunks/y053-z192-x160.json","offset":{"x":160,"y":53,"z":192},"requirements":{"minecraft:polished_diorite":10,"minecraft:stone_bricks":4},"sha256":"33259426df5f3f02cc23dbde4b862ab157733382498df8c55a845f7a7d5ac912","size":{"x":32,"y":1,"z":32}},{"blockCount":146,"bytes":3115,"file":"chunks/y054-z000-x352.json","offset":{"x":352,"y":54,"z":0},"requirements":{"minecraft:glass":8,"minecraft:oak_planks":25,"minecraft:polished_diorite":22,"minecraft:sandstone":29,"minecraft:spruce_planks":2,"minecraft:stone_bricks":60},"sha256":"487cbf5ca2d57c6469b79ec85784f36e95f65fd11bda73ad0e4840de820f6e90","size":{"x":32,"y":1,"z":32}},{"blockCount":145,"bytes":3591,"file":"chunks/y054-z000-x384.json","offset":{"x":384,"y":54,"z":0},"requirements":{"minecraft:glass":16,"minecraft:oak_planks":26,"minecraft:polished_diorite":13,"minecraft:sandstone":4,"minecraft:spruce_planks":16,"minecraft:stone_bricks":70},"sha256":"e2c64a3fef1dfb14e2b1c1d8e1ddd5a67e0e657aa378b48f0be794cd5dd34bf5","size":{"x":32,"y":1,"z":32}},{"blockCount":18,"bytes":1058,"file":"chunks/y054-z032-x384.json","offset":{"x":384,"y":54,"z":32},"requirements":{"minecraft:polished_diorite":10,"minecraft:stone_bricks":8},"sha256":"fb2ff0e840ecbb6c3108eb9fd6245d45e0e95534b95e052837ce5284e137c2a6","size":{"x":32,"y":1,"z":32}},{"blockCount":140,"bytes":3704,"file":"chunks/y054-z064-x064.json","offset":{"x":64,"y":54,"z":64},"requirements":{"minecraft:bricks":29,"minecraft:glass":12,"minecraft:oak_planks":1,"minecraft:polished_diorite":63,"minecraft:sandstone":8,"minecraft:stone_bricks":27},"sha256":"597499ec9191f23f36fe3e906bbd65520c79008c60956e13acf8328a03d84b98","size":{"x":32,"y":1,"z":32}},{"blockCount":162,"bytes":3042,"file":"chunks/y054-z064-x096.json","offset":{"x":96,"y":54,"z":64},"requirements":{"minecraft:bricks":63,"minecraft:glass":7,"minecraft:oak_planks":5,"minecraft:polished_diorite":52,"minecraft:sandstone":15,"minecraft:stone_bricks":20},"sha256":"ba296097f419760137c269e695d814706bda65ba02d3612a748f945ca90308a9","size":{"x":32,"y":1,"z":32}},{"blockCount":225,"bytes":4657,"file":"chunks/y054-z064-x128.json","offset":{"x":128,"y":54,"z":64},"requirements":{"minecraft:bricks":68,"minecraft:glass":19,"minecraft:oak_planks":4,"minecraft:polished_diorite":90,"minecraft:sandstone":19,"minecraft:stone_bricks":25},"sha256":"dc7acb2e875d9850addac72166f608ad23e7f03a025049fa09433d9cb2399b9a","size":{"x":32,"y":1,"z":32}},{"blockCount":19,"bytes":1142,"file":"chunks/y054-z064-x160.json","offset":{"x":160,"y":54,"z":64},"requirements":{"minecraft:polished_diorite":12,"minecraft:stone_bricks":7},"sha256":"6355b4b8e543bd969dc06d2264e6f82f8f717e966255b73441b7dd88c3bdf7d3","size":{"x":32,"y":1,"z":32}},{"blockCount":23,"bytes":1170,"file":"chunks/y054-z064-x192.json","offset":{"x":192,"y":54,"z":64},"requirements":{"minecraft:polished_diorite":16,"minecraft:stone_bricks":7},"sha256":"4507cd6a9e68ca144438e8c68bb26119bd498f78d121d0d6229a6cd4e11d413b","size":{"x":32,"y":1,"z":32}},{"blockCount":29,"bytes":1266,"file":"chunks/y054-z064-x224.json","offset":{"x":224,"y":54,"z":64},"requirements":{"minecraft:polished_diorite":21,"minecraft:stone_bricks":8},"sha256":"8163771ca109e8a1ccee9a4b6b09cfb5c143e0bf47e4e44d894008af628f5e24","size":{"x":32,"y":1,"z":32}},{"blockCount":79,"bytes":2775,"file":"chunks/y054-z096-x000.json","offset":{"x":0,"y":54,"z":96},"requirements":{"minecraft:bricks":4,"minecraft:glass":13,"minecraft:polished_diorite":39,"minecraft:sandstone":1,"minecraft:stone_bricks":22},"sha256":"7d89c56636691cae0f3b08df406fc20ea89570329ca954dd306397af6338dc57","size":{"x":32,"y":1,"z":32}},{"blockCount":127,"bytes":3529,"file":"chunks/y054-z096-x032.json","offset":{"x":32,"y":54,"z":96},"requirements":{"minecraft:bricks":23,"minecraft:glass":22,"minecraft:polished_diorite":53,"minecraft:sandstone":6,"minecraft:stone_bricks":23},"sha256":"978f804979339c6e5b72159282560a3a77450d6c3afa2cf1f7c275a9e9b8d8f8","size":{"x":32,"y":1,"z":32}},{"blockCount":123,"bytes":3437,"file":"chunks/y054-z096-x064.json","offset":{"x":64,"y":54,"z":96},"requirements":{"minecraft:bricks":33,"minecraft:glass":16,"minecraft:polished_diorite":40,"minecraft:sandstone":9,"minecraft:stone_bricks":25},"sha256":"6a37ca4addbe8f0ea72f6dead06ad024f7a3eadfb8916aa3f191ea5f1eacde6f","size":{"x":32,"y":1,"z":32}},{"blockCount":23,"bytes":1311,"file":"chunks/y054-z096-x096.json","offset":{"x":96,"y":54,"z":96},"requirements":{"minecraft:bricks":11,"minecraft:glass":12},"sha256":"2fcf8321f2f291b9affff6fc4e0c19e04dd080b4f4ae1176533a166e0745d2bb","size":{"x":32,"y":1,"z":32}},{"blockCount":73,"bytes":2642,"file":"chunks/y054-z096-x128.json","offset":{"x":128,"y":54,"z":96},"requirements":{"minecraft:bricks":30,"minecraft:glass":17,"minecraft:polished_diorite":12,"minecraft:sandstone":5,"minecraft:stone_bricks":9},"sha256":"bd355a3d762128d24b7a4f9c2ddd4ed5b75382f7a5a0470ecca86eebbafff58f","size":{"x":32,"y":1,"z":32}},{"blockCount":136,"bytes":3531,"file":"chunks/y054-z096-x160.json","offset":{"x":160,"y":54,"z":96},"requirements":{"minecraft:bricks":29,"minecraft:glass":24,"minecraft:polished_diorite":50,"minecraft:sandstone":7,"minecraft:stone_bricks":26},"sha256":"d9cd066e2678ef54862b3595e15582abd515cd1f7fe7b6ef54c6132565055a6e","size":{"x":32,"y":1,"z":32}},{"blockCount":269,"bytes":4835,"file":"chunks/y054-z096-x192.json","offset":{"x":192,"y":54,"z":96},"requirements":{"minecraft:bricks":161,"minecraft:glass":17,"minecraft:polished_diorite":43,"minecraft:sandstone":7,"minecraft:stone_bricks":41},"sha256":"955700145e79fb3b84382c467220a28292d22d1a3fc6e524b14f8af1922d9838","size":{"x":32,"y":1,"z":32}},{"blockCount":176,"bytes":4378,"file":"chunks/y054-z096-x224.json","offset":{"x":224,"y":54,"z":96},"requirements":{"minecraft:bricks":75,"minecraft:glass":5,"minecraft:oak_planks":1,"minecraft:polished_diorite":71,"minecraft:sandstone":5,"minecraft:stone_bricks":19},"sha256":"623281fbf521916828ace31acb71f3fe16b38512f39585ccf595ac71a48214f7","size":{"x":32,"y":1,"z":32}},{"blockCount":101,"bytes":3298,"file":"chunks/y054-z128-x000.json","offset":{"x":0,"y":54,"z":128},"requirements":{"minecraft:bricks":18,"minecraft:glass":18,"minecraft:polished_diorite":41,"minecraft:sandstone":5,"minecraft:stone_bricks":19},"sha256":"09c52b57d7320079889895da30bdc3391f3973cfbec21566a936dc27290fc76b","size":{"x":32,"y":1,"z":32}},{"blockCount":147,"bytes":4234,"file":"chunks/y054-z128-x032.json","offset":{"x":32,"y":54,"z":128},"requirements":{"minecraft:bricks":33,"minecraft:cobbled_deepslate":24,"minecraft:glass":16,"minecraft:oak_planks":9,"minecraft:polished_diorite":17,"minecraft:spruce_planks":44,"minecraft:stone_bricks":4},"sha256":"f8189066d52043f2d41f813c557fabeb5d7b31ff9e2320e903112ba66d2279a5","size":{"x":32,"y":1,"z":32}},{"blockCount":16,"bytes":1078,"file":"chunks/y054-z128-x064.json","offset":{"x":64,"y":54,"z":128},"requirements":{"minecraft:bricks":8,"minecraft:glass":8},"sha256":"971e781bd397a833a3d4372756f91939c96b899692a7df277c7e8adc28d862cf","size":{"x":32,"y":1,"z":32}},{"blockCount":8,"bytes":848,"file":"chunks/y054-z128-x096.json","offset":{"x":96,"y":54,"z":128},"requirements":{"minecraft:bricks":4,"minecraft:glass":4},"sha256":"e5411c4b839b3c0eba96520002316fca17f8b22d0450e978269630acca3d8f3f","size":{"x":32,"y":1,"z":32}},{"blockCount":16,"bytes":1076,"file":"chunks/y054-z128-x128.json","offset":{"x":128,"y":54,"z":128},"requirements":{"minecraft:bricks":8,"minecraft:glass":8},"sha256":"3f97c6e285b275492b8e71735e3ef3ca082e3a266dbf4727ace2ae727c70c26d","size":{"x":32,"y":1,"z":32}},{"blockCount":19,"bytes":1176,"file":"chunks/y054-z128-x160.json","offset":{"x":160,"y":54,"z":128},"requirements":{"minecraft:bricks":9,"minecraft:glass":10},"sha256":"82710e24370ab1b46f9406e272fd7199ff4ecbfefdb46b1a41d6da7ce7360f22","size":{"x":32,"y":1,"z":32}},{"blockCount":62,"bytes":1832,"file":"chunks/y054-z128-x192.json","offset":{"x":192,"y":54,"z":128},"requirements":{"minecraft:bricks":42,"minecraft:glass":7,"minecraft:sandstone":2,"minecraft:stone_bricks":11},"sha256":"3a69336a2efb9961699511e75e98fce6e3b3deae4480db1b60c1865c78a2a0f1","size":{"x":32,"y":1,"z":32}},{"blockCount":163,"bytes":4293,"file":"chunks/y054-z128-x224.json","offset":{"x":224,"y":54,"z":128},"requirements":{"minecraft:bricks":47,"minecraft:glass":1,"minecraft:oak_planks":5,"minecraft:polished_diorite":73,"minecraft:sandstone":17,"minecraft:stone_bricks":20},"sha256":"e3952df4ae770724c890a80ee88406b905a9293a18db1d499e186e1e8e84fabe","size":{"x":32,"y":1,"z":32}},{"blockCount":4,"bytes":764,"file":"chunks/y054-z128-x320.json","offset":{"x":320,"y":54,"z":128},"requirements":{"minecraft:polished_diorite":4},"sha256":"8fa9e437dcdf98972c415fd1980a21ee3dd7e4537930625566ddb9d7894d075f","size":{"x":32,"y":1,"z":32}},{"blockCount":53,"bytes":2103,"file":"chunks/y054-z160-x000.json","offset":{"x":0,"y":54,"z":160},"requirements":{"minecraft:bricks":4,"minecraft:glass":7,"minecraft:polished_diorite":27,"minecraft:sandstone":1,"minecraft:stone_bricks":14},"sha256":"4375149b35870a37ce57a5c341f554346fa64c6aba82d7b341f036df88fe86f9","size":{"x":32,"y":1,"z":32}},{"blockCount":111,"bytes":3069,"file":"chunks/y054-z160-x032.json","offset":{"x":32,"y":54,"z":160},"requirements":{"minecraft:bricks":15,"minecraft:glass":14,"minecraft:polished_diorite":53,"minecraft:sandstone":6,"minecraft:stone_bricks":23},"sha256":"5062d2a25e79fbf89a965ce0bd1660dea40df30d0b2261da05166064ff02a6c3","size":{"x":32,"y":1,"z":32}},{"blockCount":129,"bytes":3512,"file":"chunks/y054-z160-x064.json","offset":{"x":64,"y":54,"z":160},"requirements":{"minecraft:bricks":28,"minecraft:glass":11,"minecraft:polished_diorite":49,"minecraft:sandstone":11,"minecraft:stone_bricks":30},"sha256":"d17a6a476e96015b88a91b2fd0da270f21c58d1608bed7c59142295f7bf0b8ff","size":{"x":32,"y":1,"z":32}},{"blockCount":18,"bytes":1158,"file":"chunks/y054-z160-x096.json","offset":{"x":96,"y":54,"z":160},"requirements":{"minecraft:bricks":8,"minecraft:glass":10},"sha256":"fc66f388adae3db8bb7b95530048a224642719f9af59d9c470b1c95abd67a526","size":{"x":32,"y":1,"z":32}},{"blockCount":81,"bytes":2761,"file":"chunks/y054-z160-x128.json","offset":{"x":128,"y":54,"z":160},"requirements":{"minecraft:bricks":26,"minecraft:glass":14,"minecraft:polished_diorite":19,"minecraft:sandstone":9,"minecraft:stone_bricks":13},"sha256":"724e86de78ccce5a96c6cc001263818cc9efcc5652bb3d47e9552bf171c4d31a","size":{"x":32,"y":1,"z":32}},{"blockCount":120,"bytes":3072,"file":"chunks/y054-z160-x160.json","offset":{"x":160,"y":54,"z":160},"requirements":{"minecraft:bricks":20,"minecraft:glass":14,"minecraft:polished_diorite":52,"minecraft:sandstone":7,"minecraft:stone_bricks":27},"sha256":"9681a7909126f32f34994339fbb0480c021014117bb58728b462f2f10d750f2a","size":{"x":32,"y":1,"z":32}},{"blockCount":247,"bytes":4778,"file":"chunks/y054-z160-x192.json","offset":{"x":192,"y":54,"z":160},"requirements":{"minecraft:bricks":134,"minecraft:glass":10,"minecraft:polished_diorite":59,"minecraft:sandstone":5,"minecraft:stone_bricks":39},"sha256":"3c0fc9ac4c3b4dfaa7006d3abc2bd73c2816037fd48630bf6c2d060a0f70602e","size":{"x":32,"y":1,"z":32}},{"blockCount":149,"bytes":3891,"file":"chunks/y054-z160-x224.json","offset":{"x":224,"y":54,"z":160},"requirements":{"minecraft:bricks":63,"minecraft:glass":4,"minecraft:polished_diorite":61,"minecraft:stone_bricks":21},"sha256":"a3c2bf1cc78d0dc484d3355b73463ea32dd2f76a11e195637ba16f3faad30c5d","size":{"x":32,"y":1,"z":32}},{"blockCount":118,"bytes":3167,"file":"chunks/y054-z192-x064.json","offset":{"x":64,"y":54,"z":192},"requirements":{"minecraft:bricks":26,"minecraft:glass":9,"minecraft:oak_planks":1,"minecraft:polished_diorite":54,"minecraft:sandstone":6,"minecraft:stone_bricks":22},"sha256":"d97bf717eb2615e4b20b10f6ae98c7e2f1b716cfb7838553930f252e8ce91dde","size":{"x":32,"y":1,"z":32}},{"blockCount":159,"bytes":2930,"file":"chunks/y054-z192-x096.json","offset":{"x":96,"y":54,"z":192},"requirements":{"minecraft:bricks":62,"minecraft:glass":5,"minecraft:oak_planks":5,"minecraft:polished_diorite":52,"minecraft:sandstone":15,"minecraft:stone_bricks":20},"sha256":"095b0620b15808fb392453c97c8d98cbc27c4328d24851233bfdd19d9ca0b471","size":{"x":32,"y":1,"z":32}},{"blockCount":203,"bytes":4140,"file":"chunks/y054-z192-x128.json","offset":{"x":128,"y":54,"z":192},"requirements":{"minecraft:bricks":64,"minecraft:glass":14,"minecraft:oak_planks":4,"minecraft:polished_diorite":83,"minecraft:sandstone":17,"minecraft:stone_bricks":21},"sha256":"af6a5350f4a28aa1447339999a59e9637b6fda0a95ab4ea9547736c1635c4dae","size":{"x":32,"y":1,"z":32}},{"blockCount":16,"bytes":1066,"file":"chunks/y054-z192-x160.json","offset":{"x":160,"y":54,"z":192},"requirements":{"minecraft:polished_diorite":10,"minecraft:stone_bricks":6},"sha256":"c746eb6005c73e3666938f0f4feb0bcee341df444261cd0610e15e9265928cbe","size":{"x":32,"y":1,"z":32}},{"blockCount":145,"bytes":2904,"file":"chunks/y055-z000-x352.json","offset":{"x":352,"y":55,"z":0},"requirements":{"minecraft:glass":10,"minecraft:oak_planks":4,"minecraft:polished_diorite":41,"minecraft:sandstone":35,"minecraft:spruce_planks":3,"minecraft:stone_bricks":52},"sha256":"5af84693db994d8e608771b156f1ef79041049c13098b65b9c7d46de9bd1854d","size":{"x":32,"y":1,"z":32}},{"blockCount":113,"bytes":2994,"file":"chunks/y055-z000-x384.json","offset":{"x":384,"y":55,"z":0},"requirements":{"minecraft:glass":13,"minecraft:oak_planks":16,"minecraft:polished_diorite":15,"minecraft:sandstone":4,"minecraft:stone_bricks":65},"sha256":"dfba6d721bce304573ca487b426511ad8238b2b906bc3246f60e1e631e4f765a","size":{"x":32,"y":1,"z":32}},{"blockCount":20,"bytes":982,"file":"chunks/y055-z032-x384.json","offset":{"x":384,"y":55,"z":32},"requirements":{"minecraft:polished_diorite":14,"minecraft:stone_bricks":6},"sha256":"d840d73b70bff1d8d4bc65c109a6859ad5c01ea8b84a780ad7e18740bf96b49d","size":{"x":32,"y":1,"z":32}},{"blockCount":131,"bytes":3363,"file":"chunks/y055-z064-x064.json","offset":{"x":64,"y":55,"z":64},"requirements":{"minecraft:bricks":29,"minecraft:glass":12,"minecraft:oak_planks":1,"minecraft:polished_diorite":61,"minecraft:sandstone":12,"minecraft:stone_bricks":16},"sha256":"d711e2703fc7713e4a8a71b9bbd12e6a374fd5afd433d63a92111507a92104da","size":{"x":32,"y":1,"z":32}},{"blockCount":160,"bytes":3119,"file":"chunks/y055-z064-x096.json","offset":{"x":96,"y":55,"z":64},"requirements":{"minecraft:bricks":60,"minecraft:glass":7,"minecraft:oak_planks":5,"minecraft:polished_diorite":51,"minecraft:sandstone":15,"minecraft:stone_bricks":22},"sha256":"e94105e88699133221ff703ade551f4eb3a6acb33be577b919d9bcab50fc6b9e","size":{"x":32,"y":1,"z":32}},{"blockCount":220,"bytes":4505,"file":"chunks/y055-z064-x128.json","offset":{"x":128,"y":55,"z":64},"requirements":{"minecraft:bricks":68,"minecraft:glass":19,"minecraft:oak_planks":4,"minecraft:polished_diorite":87,"minecraft:sandstone":24,"minecraft:stone_bricks":18},"sha256":"22d859af56cd79772088b986390a51b874908cfb1e89bd7ccae0122a82e487a6","size":{"x":32,"y":1,"z":32}},{"blockCount":14,"bytes":947,"file":"chunks/y055-z064-x160.json","offset":{"x":160,"y":55,"z":64},"requirements":{"minecraft:polished_diorite":12,"minecraft:stone_bricks":2},"sha256":"dd39992926d34840ccb3a3408726424328ad0e01dd3f52ff4a6a0ef3b14e4ba6","size":{"x":32,"y":1,"z":32}},{"blockCount":21,"bytes":1056,"file":"chunks/y055-z064-x192.json","offset":{"x":192,"y":55,"z":64},"requirements":{"minecraft:polished_diorite":16,"minecraft:stone_bricks":5},"sha256":"30d13156a68512944a33d04f260e510e0a775fb4c60e65d595af43c59a1cbcd2","size":{"x":32,"y":1,"z":32}},{"blockCount":27,"bytes":1171,"file":"chunks/y055-z064-x224.json","offset":{"x":224,"y":55,"z":64},"requirements":{"minecraft:polished_diorite":21,"minecraft:stone_bricks":6},"sha256":"246578336410001cc375d939d7eb2186d53e2325e1eef81e63c2564f8fad2c86","size":{"x":32,"y":1,"z":32}},{"blockCount":79,"bytes":2564,"file":"chunks/y055-z096-x000.json","offset":{"x":0,"y":55,"z":96},"requirements":{"minecraft:bricks":4,"minecraft:glass":11,"minecraft:polished_diorite":51,"minecraft:sandstone":4,"minecraft:stone_bricks":9},"sha256":"c998aade3b3eb8cbb3eb8782b7d93213b56b2a4b062b4b187765bee369391f24","size":{"x":32,"y":1,"z":32}},{"blockCount":123,"bytes":3512,"file":"chunks/y055-z096-x032.json","offset":{"x":32,"y":55,"z":96},"requirements":{"minecraft:bricks":23,"minecraft:glass":22,"minecraft:polished_diorite":55,"minecraft:sandstone":9,"minecraft:stone_bricks":14},"sha256":"5af81d4d66a13ad3fe4c9abd609a8d5bf630e041275ca30d928eb3420f9e127f","size":{"x":32,"y":1,"z":32}},{"blockCount":115,"bytes":3170,"file":"chunks/y055-z096-x064.json","offset":{"x":64,"y":55,"z":96},"requirements":{"minecraft:bricks":29,"minecraft:glass":14,"minecraft:polished_diorite":40,"minecraft:sandstone":15,"minecraft:stone_bricks":17},"sha256":"f9cba3045c27dac18195b5b62060505611f46c7b1f76e9a3562d245b0f0b8b13","size":{"x":32,"y":1,"z":32}},{"blockCount":21,"bytes":1235,"file":"chunks/y055-z096-x096.json","offset":{"x":96,"y":55,"z":96},"requirements":{"minecraft:bricks":11,"minecraft:glass":10},"sha256":"d5c08e5c8cd268c719fb7d6193aea3381bd75bfefe93f2495c91610057cad062","size":{"x":32,"y":1,"z":32}},{"blockCount":69,"bytes":2470,"file":"chunks/y055-z096-x128.json","offset":{"x":128,"y":55,"z":96},"requirements":{"minecraft:bricks":27,"minecraft:glass":14,"minecraft:polished_diorite":12,"minecraft:sandstone":8,"minecraft:stone_bricks":8},"sha256":"5ab9c0578538cd2481cd20de133ad87902a44c3863e0ee939d413af8d8831fd0","size":{"x":32,"y":1,"z":32}},{"blockCount":127,"bytes":3360,"file":"chunks/y055-z096-x160.json","offset":{"x":160,"y":55,"z":96},"requirements":{"minecraft:bricks":28,"minecraft:glass":22,"minecraft:polished_diorite":50,"minecraft:sandstone":12,"minecraft:stone_bricks":15},"sha256":"da27f395061a8a4b11563d65fa3990a6b7601ca8541580bd83a37d0b1566ace5","size":{"x":32,"y":1,"z":32}},{"blockCount":265,"bytes":4797,"file":"chunks/y055-z096-x192.json","offset":{"x":192,"y":55,"z":96},"requirements":{"minecraft:bricks":165,"minecraft:glass":15,"minecraft:polished_diorite":43,"minecraft:sandstone":10,"minecraft:stone_bricks":32},"sha256":"af6c8b58feed8fce4f3d9beb1e103d490ac7d4c1f5eed1fa8f0316715dab67aa","size":{"x":32,"y":1,"z":32}},{"blockCount":163,"bytes":4150,"file":"chunks/y055-z096-x224.json","offset":{"x":224,"y":55,"z":96},"requirements":{"minecraft:bricks":77,"minecraft:glass":3,"minecraft:oak_planks":1,"minecraft:polished_diorite":64,"minecraft:sandstone":5,"minecraft:stone_bricks":13},"sha256":"6eaf09c9ad52ff31285360f103d03c8dbe02daedb975e949cbcb31050c137dd1","size":{"x":32,"y":1,"z":32}},{"blockCount":102,"bytes":3203,"file":"chunks/y055-z128-x000.json","offset":{"x":0,"y":55,"z":128},"requirements":{"minecraft:bricks":18,"minecraft:glass":17,"minecraft:polished_diorite":49,"minecraft:sandstone":6,"minecraft:stone_bricks":12},"sha256":"7fcecb7b0f13255b4316819042a583db3a1ef79e78aeaed11ac91e989578d9cc","size":{"x":32,"y":1,"z":32}},{"blockCount":139,"bytes":4270,"file":"chunks/y055-z128-x032.json","offset":{"x":32,"y":55,"z":128},"requirements":{"minecraft:bricks":24,"minecraft:cobbled_deepslate":20,"minecraft:glass":16,"minecraft:oak_planks":7,"minecraft:polished_diorite":20,"minecraft:spruce_planks":44,"minecraft:stone_bricks":8},"sha256":"3e4897a79598b8856e9b3548e013fadb63a99884fd3601f470889f2df48ee50e","size":{"x":32,"y":1,"z":32}},{"blockCount":16,"bytes":1078,"file":"chunks/y055-z128-x064.json","offset":{"x":64,"y":55,"z":128},"requirements":{"minecraft:bricks":8,"minecraft:glass":8},"sha256":"be86a9de96a8d0d5d41431c70e2715ac6b529b00d0655d1b3343da09a3af22f2","size":{"x":32,"y":1,"z":32}},{"blockCount":8,"bytes":848,"file":"chunks/y055-z128-x096.json","offset":{"x":96,"y":55,"z":128},"requirements":{"minecraft:bricks":4,"minecraft:glass":4},"sha256":"0e1a63ccb99d9bed845b2165ca28ac029203667070939e49f4731a6c5611f422","size":{"x":32,"y":1,"z":32}},{"blockCount":16,"bytes":1076,"file":"chunks/y055-z128-x128.json","offset":{"x":128,"y":55,"z":128},"requirements":{"minecraft:bricks":8,"minecraft:glass":8},"sha256":"fa515d80917829be5f7a7e37720216bac5cbd17dd8319262afa1878ed9eda7db","size":{"x":32,"y":1,"z":32}},{"blockCount":19,"bytes":1176,"file":"chunks/y055-z128-x160.json","offset":{"x":160,"y":55,"z":128},"requirements":{"minecraft:bricks":9,"minecraft:glass":10},"sha256":"7eb42da22681bd414d1bebc04144dfb81dac60d00f4c9699a67255cf716bc7a8","size":{"x":32,"y":1,"z":32}},{"blockCount":63,"bytes":1927,"file":"chunks/y055-z128-x192.json","offset":{"x":192,"y":55,"z":128},"requirements":{"minecraft:bricks":40,"minecraft:glass":7,"minecraft:sandstone":4,"minecraft:stone_bricks":12},"sha256":"901fae3743ceb5f4bdfeb1a7128ca4b342c679269787c5131a5a2e29ad49077c","size":{"x":32,"y":1,"z":32}},{"blockCount":157,"bytes":4236,"file":"chunks/y055-z128-x224.json","offset":{"x":224,"y":55,"z":128},"requirements":{"minecraft:bricks":44,"minecraft:glass":1,"minecraft:oak_planks":5,"minecraft:polished_diorite":71,"minecraft:sandstone":17,"minecraft:stone_bricks":19},"sha256":"482d28c4c799929d380be1d6d647663876f425ab6544dd6f98841abe739ff852","size":{"x":32,"y":1,"z":32}}],"schema":1}
