{"entries":[{"blockCount":5,"bytes":791,"file":"chunks/y055-z128-x320.json","offset":{"x":320,"y":55,"z":128},"requirements":{"minecraft:polished_diorite":4,"minecraft:stone_bricks":1},"sha256":"399c334058093a9dc6fcd0b41512c38e1a67cff953168f61ae1a9fed6479c5a7","size":{"x":32,"y":1,"z":32}},{"blockCount":52,"bytes":1949,"file":"chunks/y055-z160-x000.json","offset":{"x":0,"y":55,"z":160},"requirements":{"minecraft:bricks":4,"minecraft:glass":6,"minecraft:polished_diorite":33,"minecraft:sandstone":3,"minecraft:stone_bricks":6},"sha256":"43b242df1087c861b0b3a0e4a8895b488d9703db2fd6f76c2eacb00148a2e724","size":{"x":32,"y":1,"z":32}},{"blockCount":107,"bytes":3033,"file":"chunks/y055-z160-x032.json","offset":{"x":32,"y":55,"z":160},"requirements":{"minecraft:bricks":15,"minecraft:glass":14,"minecraft:polished_diorite":55,"minecraft:sandstone":9,"minecraft:stone_bricks":14},"sha256":"40a9c21a4ebaef1e77544daf2c604253960e26d8f4d932aeeecf770ceefacba0","size":{"x":32,"y":1,"z":32}},{"blockCount":120,"bytes":3187,"file":"chunks/y055-z160-x064.json","offset":{"x":64,"y":55,"z":160},"requirements":{"minecraft:bricks":24,"minecraft:glass":9,"minecraft:polished_diorite":49,"minecraft:sandstone":18,"minecraft:stone_bricks":20},"sha256":"6af1434269ee21a1156bcc10c0d63f869eb34e3d57fcfc91bce10244e2c46570","size":{"x":32,"y":1,"z":32}},{"blockCount":16,"bytes":1081,"file":"chunks/y055-z160-x096.json","offset":{"x":96,"y":55,"z":160},"requirements":{"minecraft:bricks":8,"minecraft:glass":8},"sha256":"7fb63133044f5a346da8db85e42c8502f7ea10ff9d844cee74c1f1236226edac","size":{"x":32,"y":1,"z":32}},{"blockCount":77,"bytes":2533,"file":"chunks/y055-z160-x128.json","offset":{"x":128,"y":55,"z":160},"requirements":{"minecraft:bricks":23,"minecraft:glass":11,"minecraft:polished_diorite":19,"minecraft:sandstone":13,"minecraft:stone_bricks":11},"sha256":"256f755cc2eb407fb0953079e547ad7d4bb5498e101853f7e414e38d4678b0ca","size":{"x":32,"y":1,"z":32}},{"blockCount":110,"bytes":2863,"file":"chunks/y055-z160-x160.json","offset":{"x":160,"y":55,"z":160},"requirements":{"minecraft:bricks":19,"minecraft:glass":12,"minecraft:polished_diorite":52,"minecraft:sandstone":12,"minecraft:stone_bricks":15},"sha256":"480e0f01f684e952ecd88f56f8b9fd91b30b3951ce0b82a3eb667ba1abfeea26","size":{"x":32,"y":1,"z":32}},{"blockCount":243,"bytes":4550,"file":"chunks/y055-z160-x192.json","offset":{"x":192,"y":55,"z":160},"requirements":{"minecraft:bricks":140,"minecraft:glass":8,"minecraft:polished_diorite":59,"minecraft:sandstone":6,"minecraft:stone_bricks":30},"sha256":"c4d4ef2dd27d2200d422e061e4aed282e2d2aa45a2065f3d48cff3c8786b7a4b","size":{"x":32,"y":1,"z":32}},{"blockCount":141,"bytes":3663,"file":"chunks/y055-z160-x224.json","offset":{"x":224,"y":55,"z":160},"requirements":{"minecraft:bricks":65,"minecraft:glass":2,"minecraft:polished_diorite":57,"minecraft:stone_bricks":17},"sha256":"59603a34ce0f2fc6905dab8236085388ec17ca9dd02c8e41cb322f3bc3bd211a","size":{"x":32,"y":1,"z":32}},{"blockCount":110,"bytes":2901,"file":"chunks/y055-z192-x064.json","offset":{"x":64,"y":55,"z":192},"requirements":{"minecraft:bricks":26,"minecraft:glass":9,"minecraft:oak_planks":2,"minecraft:polished_diorite":52,"minecraft:sandstone":8,"minecraft:stone_bricks":13},"sha256":"551804ba2d5d3192aa73f86a92473043afef8d25253fd9fa14753fdedeb75dcc","size":{"x":32,"y":1,"z":32}},{"blockCount":157,"bytes":3026,"file":"chunks/y055-z192-x096.json","offset":{"x":96,"y":55,"z":192},"requirements":{"minecraft:bricks":59,"minecraft:glass":5,"minecraft:oak_planks":5,"minecraft:polished_diorite":51,"minecraft:sandstone":15,"minecraft:stone_bricks":22},"sha256":"24466ea5ed0c61eae67c4a42965b1bb5aa1ef221fe00b706d410a6f01755e792","size":{"x":32,"y":1,"z":32}},{"blockCount":198,"bytes":3969,"file":"chunks/y055-z192-x128.json","offset":{"x":128,"y":55,"z":192},"requirements":{"minecraft:bricks":64,"minecraft:glass":14,"minecraft:oak_planks":4,"minecraft:polished_diorite":80,"minecraft:sandstone":21,"minecraft:stone_bricks":15},"sha256":"9452d78707df958ba0541f269e1207a8e239243945bad7321c29f069bac670d9","size":{"x":32,"y":1,"z":32}},{"blockCount":12,"bytes":910,"file":"chunks/y055-z192-x160.json","offset":{"x":160,"y":55,"z":192},"requirements":{"minecraft:polished_diorite":10,"minecraft:stone_bricks":2},"sha256":"d59c31da935e591006aa2f51ceb04c7b02aed22e63cb5b5aa36e00cd5c2d5b42","size":{"x":32,"y":1,"z":32}},{"blockCount":161,"bytes":3037,"file":"chunks/y056-z000-x352.json","offset":{"x":352,"y":56,"z":0},"requirements":{"minecraft:glass":7,"minecraft:oak_planks":12,"minecraft:polished_diorite":45,"minecraft:sandstone":40,"minecraft:spruce_planks":8,"minecraft:stone_bricks":49},"sha256":"b62ddf709453a6abd3027ae6ab4638b72ac0a52323fd576252fb20709aefa364","size":{"x":32,"y":1,"z":32}},{"blockCount":97,"bytes":2846,"file":"chunks/y056-z000-x384.json","offset":{"x":384,"y":56,"z":0},"requirements":{"minecraft:glass":12,"minecraft:oak_planks":12,"minecraft:polished_diorite":6,"minecraft:sandstone":4,"minecraft:spruce_planks":16,"minecraft:stone_bricks":47},"sha256":"6225edc66d9372ac58eb932a745a4cb4be1594cfbbb7f37782f77b1f3b5b93ab","size":{"x":32,"y":1,"z":32}},{"blockCount":12,"bytes":828,"file":"chunks/y056-z032-x384.json","offset":{"x":384,"y":56,"z":32},"requirements":{"minecraft:polished_diorite":6,"minecraft:stone_bricks":6},"sha256":"7549040faa8f77b5d4893d7e5e081c09ce544ce16ecdd5b77428feeff2ef16db","size":{"x":32,"y":1,"z":32}},{"blockCount":143,"bytes":3722,"file":"chunks/y056-z064-x064.json","offset":{"x":64,"y":56,"z":64},"requirements":{"minecraft:bricks":29,"minecraft:glass":12,"minecraft:oak_planks":1,"minecraft:polished_diorite":70,"minecraft:sandstone":8,"minecraft:stone_bricks":23},"sha256":"ecb16910ecc89dbb18f768a7a2317d63de982753f4dec7e4bc2ec3ebb530913d","size":{"x":32,"y":1,"z":32}},{"blockCount":158,"bytes":3023,"file":"chunks/y056-z064-x096.json","offset":{"x":96,"y":56,"z":64},"requirements":{"minecraft:bricks":63,"minecraft:glass":7,"minecraft:oak_planks":5,"minecraft:polished_diorite":54,"minecraft:sandstone":15,"minecraft:stone_bricks":14},"sha256":"05f67df65e030c9890922e229310f48f70468e417966cf6d35ac5e28bc6573d9","size":{"x":32,"y":1,"z":32}},{"blockCount":234,"bytes":4753,"file":"chunks/y056-z064-x128.json","offset":{"x":128,"y":56,"z":64},"requirements":{"minecraft:bricks":68,"minecraft:glass":19,"minecraft:oak_planks":4,"minecraft:polished_diorite":101,"minecraft:sandstone":19,"minecraft:stone_bricks":23},"sha256":"3e1ff5f4b55d03f9801d7bc9cc6efe76acfdada32e0ec56c0f7060194e66331f","size":{"x":32,"y":1,"z":32}},{"blockCount":14,"bytes":1003,"file":"chunks/y056-z064-x160.json","offset":{"x":160,"y":56,"z":64},"requirements":{"minecraft:polished_diorite":9,"minecraft:stone_bricks":5},"sha256":"1fc21df64dc91503101c981632171ee469793fd21db7ef0f0986762370c8f258","size":{"x":32,"y":1,"z":32}},{"blockCount":22,"bytes":1113,"file":"chunks/y056-z064-x192.json","offset":{"x":192,"y":56,"z":64},"requirements":{"minecraft:polished_diorite":16,"minecraft:stone_bricks":6},"sha256":"f695769b96b6c53f813c00bcb5328ae2272f98aae938436029b155dcb8077114","size":{"x":32,"y":1,"z":32}},{"blockCount":28,"bytes":1228,"file":"chunks/y056-z064-x224.json","offset":{"x":224,"y":56,"z":64},"requirements":{"minecraft:polished_diorite":20,"minecraft:stone_bricks":8},"sha256":"4beb2215c4d371fd02c0b96b86d8c907a8e8aaa6e44cf684e169b2cacb242405","size":{"x":32,"y":1,"z":32}},{"blockCount":71,"bytes":2450,"file":"chunks/y056-z096-x000.json","offset":{"x":0,"y":56,"z":96},"requirements":{"minecraft:bricks":6,"minecraft:glass":10,"minecraft:polished_diorite":38,"minecraft:sandstone":2,"minecraft:stone_bricks":15},"sha256":"61fd40cc4d58ce664d62d94c41a2e55351a047ef093c92cf9228b9f47bde6f29","size":{"x":32,"y":1,"z":32}},{"blockCount":131,"bytes":3171,"file":"chunks/y056-z096-x032.json","offset":{"x":32,"y":56,"z":96},"requirements":{"minecraft:bricks":23,"minecraft:glass":21,"minecraft:polished_diorite":65,"minecraft:sandstone":6,"minecraft:stone_bricks":16},"sha256":"0ca0b9043077e91adc558d852b6231b1bd3e84d4d7c427ea9661ac02f8c7723e","size":{"x":32,"y":1,"z":32}},{"blockCount":119,"bytes":3081,"file":"chunks/y056-z096-x064.json","offset":{"x":64,"y":56,"z":96},"requirements":{"minecraft:bricks":33,"minecraft:glass":14,"minecraft:oak_planks":4,"minecraft:polished_diorite":45,"minecraft:sandstone":9,"minecraft:stone_bricks":14},"sha256":"0ce7898c3a6c68f44c94efffd11f460f688a2a407d75ff7da9502f0e40e3b24f","size":{"x":32,"y":1,"z":32}},{"blockCount":21,"bytes":1235,"file":"chunks/y056-z096-x096.json","offset":{"x":96,"y":56,"z":96},"requirements":{"minecraft:bricks":11,"minecraft:glass":10},"sha256":"f8bff465820c46bce7e21d1b652e989959e027d5d66eadb420f4f43f3f410ff6","size":{"x":32,"y":1,"z":32}},{"blockCount":69,"bytes":2514,"file":"chunks/y056-z096-x128.json","offset":{"x":128,"y":56,"z":96},"requirements":{"minecraft:bricks":30,"minecraft:glass":14,"minecraft:oak_planks":3,"minecraft:polished_diorite":12,"minecraft:sandstone":5,"minecraft:stone_bricks":5},"sha256":"da6d3019b34abd650b9200c0979e96426c029d2013a4aed63e3540e0e3c724c8","size":{"x":32,"y":1,"z":32}},{"blockCount":135,"bytes":3024,"file":"chunks/y056-z096-x160.json","offset":{"x":160,"y":56,"z":96},"requirements":{"minecraft:bricks":29,"minecraft:glass":22,"minecraft:oak_planks":1,"minecraft:polished_diorite":59,"minecraft:sandstone":7,"minecraft:stone_bricks":17},"sha256":"17eedea30a8b41109794c68f8387f21bff70348fe8500c8677ef038e16fe5f90","size":{"x":32,"y":1,"z":32}},{"blockCount":265,"bytes":4630,"file":"chunks/y056-z096-x192.json","offset":{"x":192,"y":56,"z":96},"requirements":{"minecraft:bricks":166,"minecraft:glass":14,"minecraft:polished_diorite":48,"minecraft:sandstone":11,"minecraft:stone_bricks":26},"sha256":"d7ee9e669ad4d1d67b28fd9c2ef4cea2a6984303bba7753ba9700fa014f602ea","size":{"x":32,"y":1,"z":32}},{"blockCount":170,"bytes":4113,"file":"chunks/y056-z096-x224.json","offset":{"x":224,"y":56,"z":96},"requirements":{"minecraft:bricks":77,"minecraft:glass":1,"minecraft:oak_planks":1,"minecraft:polished_diorite":69,"minecraft:sandstone":5,"minecraft:stone_bricks":17},"sha256":"dfca8e7aeed74267fd3a2fe0df0754264d1e3768b3be42ea37c3f7e34f1fafb6","size":{"x":32,"y":1,"z":32}},{"blockCount":102,"bytes":3165,"file":"chunks/y056-z128-x000.json","offset":{"x":0,"y":56,"z":128},"requirements":{"minecraft:bricks":19,"minecraft:glass":17,"minecraft:polished_diorite":46,"minecraft:sandstone":9,"minecraft:stone_bricks":11},"sha256":"9e230f48bb3348e11eb5826c10c43317dfe8a515584aca1023406c69770665c4","size":{"x":32,"y":1,"z":32}},{"blockCount":144,"bytes":3577,"file":"chunks/y056-z128-x032.json","offset":{"x":32,"y":56,"z":128},"requirements":{"minecraft:bricks":21,"minecraft:cobbled_deepslate":18,"minecraft:glass":16,"minecraft:polished_diorite":3,"minecraft:spruce_planks":78,"minecraft:stone_bricks":8},"sha256":"2bd107789ee8f53f4b84e1e29dee6ea0192840d9ee7691447d7d06697ee357fd","size":{"x":32,"y":1,"z":32}},{"blockCount":16,"bytes":1078,"file":"chunks/y056-z128-x064.json","offset":{"x":64,"y":56,"z":128},"requirements":{"minecraft:bricks":8,"minecraft:glass":8},"sha256":"59414bad82c56b2f064bacaaa1f1af2857feadb32c989f9f1ded3bc3ab1f966d","size":{"x":32,"y":1,"z":32}},{"blockCount":8,"bytes":848,"file":"chunks/y056-z128-x096.json","offset":{"x":96,"y":56,"z":128},"requirements":{"minecraft:bricks":4,"minecraft:glass":4},"sha256":"0472dbb7a78d8671df7ffd37ae33f293cbd897c0e56c7aac7358008bae233f6a","size":{"x":32,"y":1,"z":32}},{"blockCount":16,"bytes":1076,"file":"chunks/y056-z128-x128.json","offset":{"x":128,"y":56,"z":128},"requirements":{"minecraft:bricks":8,"minecraft:glass":8},"sha256":"aa748079048f62a40596a422a210de0344d3f1622e3d5619720ea66985340289","size":{"x":32,"y":1,"z":32}},{"blockCount":19,"bytes":1176,"file":"chunks/y056-z128-x160.json","offset":{"x":160,"y":56,"z":128},"requirements":{"minecraft:bricks":9,"minecraft:glass":10},"sha256":"3b3483fb04291ddb7260647c282e2875bbc06ae5e7c00598299520e956ba8c29","size":{"x":32,"y":1,"z":32}},{"blockCount":57,"bytes":1810,"file":"chunks/y056-z128-x192.json","offset":{"x":192,"y":56,"z":128},"requirements":{"minecraft:bricks":38,"minecraft:glass":7,"minecraft:sandstone":4,"minecraft:stone_bricks":8},"sha256":"f1193ab622f2350a6d5df7094a52b327e163066da60568be675f1a5963a85a01","size":{"x":32,"y":1,"z":32}},{"blockCount":164,"bytes":4407,"file":"chunks/y056-z128-x224.json","offset":{"x":224,"y":56,"z":128},"requirements":{"minecraft:bricks":49,"minecraft:glass":1,"minecraft:oak_planks":5,"minecraft:polished_diorite":75,"minecraft:sandstone":17,"minecraft:stone_bricks":17},"sha256":"07cc077331448f6578ef7ea3fcb148d8c5bf6aa9bd85f4de01d484ee4b7a81eb","size":{"x":32,"y":1,"z":32}},{"blockCount":4,"bytes":764,"file":"chunks/y056-z128-x320.json","offset":{"x":320,"y":56,"z":128},"requirements":{"minecraft:polished_diorite":4},"sha256":"6571798f2fa3e78df16f8fcba3fc20c18b3fd6f8f1338c445ca64998dcae87d0","size":{"x":32,"y":1,"z":32}},{"blockCount":48,"bytes":1872,"file":"chunks/y056-z160-x000.json","offset":{"x":0,"y":56,"z":160},"requirements":{"minecraft:bricks":5,"minecraft:glass":5,"minecraft:polished_diorite":27,"minecraft:sandstone":2,"minecraft:stone_bricks":9},"sha256":"5191c7744bfd877118ae6d784e0f67a5c6b682fd78382999dd8d93ad4ede9369","size":{"x":32,"y":1,"z":32}},{"blockCount":115,"bytes":2692,"file":"chunks/y056-z160-x032.json","offset":{"x":32,"y":56,"z":160},"requirements":{"minecraft:bricks":15,"minecraft:glass":13,"minecraft:polished_diorite":65,"minecraft:sandstone":6,"minecraft:stone_bricks":16},"sha256":"0a99eb132b9d6244eaacd3604fd473ba912b41f858b355cde6264fdb8a171525","size":{"x":32,"y":1,"z":32}},{"blockCount":126,"bytes":3176,"file":"chunks/y056-z160-x064.json","offset":{"x":64,"y":56,"z":160},"requirements":{"minecraft:bricks":28,"minecraft:glass":9,"minecraft:oak_planks":4,"minecraft:polished_diorite":56,"minecraft:sandstone":11,"minecraft:stone_bricks":18},"sha256":"eb88fbe558b2c2c874a46e50c082a5427a53c6d3d92cb99f4364753023410b36","size":{"x":32,"y":1,"z":32}},{"blockCount":16,"bytes":1081,"file":"chunks/y056-z160-x096.json","offset":{"x":96,"y":56,"z":160},"requirements":{"minecraft:bricks":8,"minecraft:glass":8},"sha256":"c07a79065e98c0613b0551c314164a08f9675925cf14eb80c5c1b6e22532e702","size":{"x":32,"y":1,"z":32}},{"blockCount":79,"bytes":2670,"file":"chunks/y056-z160-x128.json","offset":{"x":128,"y":56,"z":160},"requirements":{"minecraft:bricks":26,"minecraft:glass":11,"minecraft:oak_planks":3,"minecraft:polished_diorite":22,"minecraft:sandstone":9,"minecraft:stone_bricks":8},"sha256":"1e68987bce616fb4f2b04048e75f8f1cd789dff7655c729b852a0cc226f5b939","size":{"x":32,"y":1,"z":32}},{"blockCount":118,"bytes":2527,"file":"chunks/y056-z160-x160.json","offset":{"x":160,"y":56,"z":160},"requirements":{"minecraft:bricks":20,"minecraft:glass":12,"minecraft:oak_planks":1,"minecraft:polished_diorite":60,"minecraft:sandstone":7,"minecraft:stone_bricks":18},"sha256":"37cc430ef3f512ce2f310fb85e76798c2e6173c53bb9a5c6b0dda2d0c07d0c55","size":{"x":32,"y":1,"z":32}},{"blockCount":244,"bytes":4440,"file":"chunks/y056-z160-x192.json","offset":{"x":192,"y":56,"z":160},"requirements":{"minecraft:bricks":141,"minecraft:glass":7,"minecraft:polished_diorite":64,"minecraft:sandstone":7,"minecraft:stone_bricks":25},"sha256":"e86a0b8efb60052ea58430de2ed3f869aec49ab6475c4f262dfac0590fcfb3b2","size":{"x":32,"y":1,"z":32}},{"blockCount":145,"bytes":3644,"file":"chunks/y056-z160-x224.json","offset":{"x":224,"y":56,"z":160},"requirements":{"minecraft:bricks":65,"minecraft:polished_diorite":59,"minecraft:stone_bricks":21},"sha256":"d070e29a7523e9ca8125716dfe35b349e2324f4b4a7da2877187db6eb56c7784","size":{"x":32,"y":1,"z":32}},{"blockCount":120,"bytes":3166,"file":"chunks/y056-z192-x064.json","offset":{"x":64,"y":56,"z":192},"requirements":{"minecraft:bricks":26,"minecraft:glass":9,"minecraft:oak_planks":1,"minecraft:polished_diorite":59,"minecraft:sandstone":6,"minecraft:stone_bricks":19},"sha256":"1559e6e2bb62bcc8d230defff66d7f0e98c36a7ce765e24ae17e153720bbf431","size":{"x":32,"y":1,"z":32}},{"blockCount":155,"bytes":2930,"file":"chunks/y056-z192-x096.json","offset":{"x":96,"y":56,"z":192},"requirements":{"minecraft:bricks":62,"minecraft:glass":5,"minecraft:oak_planks":5,"minecraft:polished_diorite":54,"minecraft:sandstone":15,"minecraft:stone_bricks":14},"sha256":"f4707c64e075e75db34b7760533858cd1649b39fa4478bd397ac335a0cb1c3d8","size":{"x":32,"y":1,"z":32}},{"blockCount":210,"bytes":4159,"file":"chunks/y056-z192-x128.json","offset":{"x":128,"y":56,"z":192},"requirements":{"minecraft:bricks":64,"minecraft:glass":14,"minecraft:oak_planks":4,"minecraft:polished_diorite":91,"minecraft:sandstone":17,"minecraft:stone_bricks":20},"sha256":"168d52de18332aa68e605e2180bcbaf1236ae9679666daba6c092f018fcb70e1","size":{"x":32,"y":1,"z":32}},{"blockCount":12,"bytes":947,"file":"chunks/y056-z192-x160.json","offset":{"x":160,"y":56,"z":192},"requirements":{"minecraft:polished_diorite":8,"minecraft:stone_bricks":4},"sha256":"1cea41440ec6f4cf5ef7ae99173dc3237168bb5a67e9c2d81a94c3305faad0a7","size":{"x":32,"y":1,"z":32}},{"blockCount":119,"bytes":2413,"file":"chunks/y057-z000-x352.json","offset":{"x":352,"y":57,"z":0},"requirements":{"minecraft:glass":12,"minecraft:polished_diorite":43,"minecraft:sandstone":48,"minecraft:stone_bricks":16},"sha256":"28cc5a9309789cf43b5f44d1799f03e3b0f8d098a11b1e0fe736cbc43da53d54","size":{"x":32,"y":1,"z":32}},{"blockCount":68,"bytes":2512,"file":"chunks/y057-z000-x384.json","offset":{"x":384,"y":57,"z":0},"requirements":{"minecraft:glass":12,"minecraft:oak_planks":14,"minecraft:polished_diorite":6,"minecraft:sandstone":4,"minecraft:stone_bricks":32},"sha256":"652185f526642b24aa473fc155823a236583477f8fb72a3ee1240dc93df81c10","size":{"x":32,"y":1,"z":32}},{"blockCount":12,"bytes":853,"file":"chunks/y057-z032-x384.json","offset":{"x":384,"y":57,"z":32},"requirements":{"minecraft:oak_planks":2,"minecraft:polished_diorite":6,"minecraft:stone_bricks":4},"sha256":"af8370fab12cda7aa36cebb1e489a89e930bf37cc785a96179e7e712045e0a51","size":{"x":32,"y":1,"z":32}},{"blockCount":125,"bytes":3399,"file":"chunks/y057-z064-x064.json","offset":{"x":64,"y":57,"z":64},"requirements":{"minecraft:bricks":33,"minecraft:glass":8,"minecraft:oak_planks":1,"minecraft:polished_diorite":61,"minecraft:sandstone":12,"minecraft:stone_bricks":10},"sha256":"4d2070067af963afbff33de8b9d67402fd744df3542c56dac313af77a5ca8309","size":{"x":32,"y":1,"z":32}},{"blockCount":155,"bytes":3004,"file":"chunks/y057-z064-x096.json","offset":{"x":96,"y":57,"z":64},"requirements":{"minecraft:bricks":65,"minecraft:glass":7,"minecraft:oak_planks":5,"minecraft:polished_diorite":52,"minecraft:sandstone":15,"minecraft:stone_bricks":11},"sha256":"4e64fc3c61632c4b0bd2c95a74bcaef92b9b954fcd0c05498eae33b2f7dbbf81","size":{"x":32,"y":1,"z":32}},{"blockCount":219,"bytes":4543,"file":"chunks/y057-z064-x128.json","offset":{"x":128,"y":57,"z":64},"requirements":{"minecraft:bricks":72,"minecraft:glass":15,"minecraft:oak_planks":4,"minecraft:polished_diorite":90,"minecraft:sandstone":24,"minecraft:stone_bricks":14},"sha256":"e66c513292e7ca68313819f6c143389cf233bb4c32805abddc2f56e6452ac8d8","size":{"x":32,"y":1,"z":32}},{"blockCount":9,"bytes":881,"file":"chunks/y057-z064-x160.json","offset":{"x":160,"y":57,"z":64},"requirements":{"minecraft:polished_diorite":9},"sha256":"049f662988cd04789c0faf4b3d56c18d8552d03eb2093f23b694caa154c6a48c","size":{"x":32,"y":1,"z":32}},{"blockCount":19,"bytes":1018,"file":"chunks/y057-z064-x192.json","offset":{"x":192,"y":57,"z":64},"requirements":{"minecraft:polished_diorite":17,"minecraft:stone_bricks":2},"sha256":"20da6d69c5ed3fc0975199b37c4e6262f4747318b34e687abfb4349447327a98","size":{"x":32,"y":1,"z":32}},{"blockCount":23,"bytes":1096,"file":"chunks/y057-z064-x224.json","offset":{"x":224,"y":57,"z":64},"requirements":{"minecraft:polished_diorite":21,"minecraft:stone_bricks":2},"sha256":"77203e18b0437e930c1da24535a84432f582132b090c27e71dc0dc24bb729628","size":{"x":32,"y":1,"z":32}},{"blockCount":66,"bytes":2372,"file":"chunks/y057-z096-x000.json","offset":{"x":0,"y":57,"z":96},"requirements":{"minecraft:bricks":7,"minecraft:glass":8,"minecraft:polished_diorite":41,"minecraft:sandstone":3,"minecraft:stone_bricks":7},"sha256":"7145dabff6ed4ed2bb1756a6be883b5ac8a344dba4346fd5b63ea34645a0790a","size":{"x":32,"y":1,"z":32}},{"blockCount":117,"bytes":3264,"file":"chunks/y057-z096-x032.json","offset":{"x":32,"y":57,"z":96},"requirements":{"minecraft:bricks":27,"minecraft:glass":17,"minecraft:polished_diorite":58,"minecraft:sandstone":8,"minecraft:stone_bricks":7},"sha256":"c796c64af492ab11da1c3653b3ee4a391df615b71584e2e20ffb6e87912cf1bb","size":{"x":32,"y":1,"z":32}},{"blockCount":112,"bytes":3158,"file":"chunks/y057-z096-x064.json","offset":{"x":64,"y":57,"z":96},"requirements":{"minecraft:bricks":31,"minecraft:glass":12,"minecraft:oak_planks":2,"minecraft:polished_diorite":41,"minecraft:sandstone":13,"minecraft:stone_bricks":13},"sha256":"9902026946c95c278e8b1dbdcdaa5d391b92c848f146b5173c03a9fd06f61e31","size":{"x":32,"y":1,"z":32}},{"blockCount":21,"bytes":1235,"file":"chunks/y057-z096-x096.json","offset":{"x":96,"y":57,"z":96},"requirements":{"minecraft:bricks":11,"minecraft:glass":10},"sha256":"f328611c521a845b8c6efbc9abb88f406ae738bb71907b117d4a8e2ce17cb2b2","size":{"x":32,"y":1,"z":32}},{"blockCount":69,"bytes":2533,"file":"chunks/y057-z096-x128.json","offset":{"x":128,"y":57,"z":96},"requirements":{"minecraft:bricks":27,"minecraft:glass":14,"minecraft:oak_planks":2,"minecraft:polished_diorite":12,"minecraft:sandstone":6,"minecraft:stone_bricks":8},"sha256":"0bf25e6f0861529aa51ca98125dbf670c0b406d644c2d18c190a78928b25f202","size":{"x":32,"y":1,"z":32}},{"blockCount":121,"bytes":3150,"file":"chunks/y057-z096-x160.json","offset":{"x":160,"y":57,"z":96},"requirements":{"minecraft:bricks":32,"minecraft:glass":18,"minecraft:polished_diorite":51,"minecraft:sandstone":12,"minecraft:stone_bricks":8},"sha256":"a2a257d9800d04e90aa91a93cd336c8728236c100c9e6961b0bd3899ace4dd17","size":{"x":32,"y":1,"z":32}},{"blockCount":257,"bytes":4889,"file":"chunks/y057-z096-x192.json","offset":{"x":192,"y":57,"z":96},"requirements":{"minecraft:bricks":154,"minecraft:glass":13,"minecraft:oak_planks":4,"minecraft:polished_diorite":44,"minecraft:sandstone":16,"minecraft:spruce_planks":1,"minecraft:stone_bricks":25},"sha256":"6fe694af4867a5adea6d4bb1ca8ba7894edd356a627b7be0290070a64db0e079","size":{"x":32,"y":1,"z":32}},{"blockCount":152,"bytes":3961,"file":"chunks/y057-z096-x224.json","offset":{"x":224,"y":57,"z":96},"requirements":{"minecraft:bricks":75,"minecraft:glass":1,"minecraft:oak_planks":1,"minecraft:polished_diorite":64,"minecraft:sandstone":5,"minecraft:stone_bricks":6},"sha256":"1d3398c940b7f8b7b7a0e19d4627df8199e6a0da481ddc41329796a3ba0c7c04","size":{"x":32,"y":1,"z":32}},{"blockCount":94,"bytes":3051,"file":"chunks/y057-z128-x000.json","offset":{"x":0,"y":57,"z":128},"requirements":{"minecraft:bricks":19,"minecraft:glass":13,"minecraft:polished_diorite":41,"minecraft:sandstone":11,"minecraft:stone_bricks":10},"sha256":"0f274d32cf9fc7a9ddfc29a2051e38b56477e56a4889c04481a594646c15dcfa","size":{"x":32,"y":1,"z":32}},{"blockCount":122,"bytes":3109,"file":"chunks/y057-z128-x032.json","offset":{"x":32,"y":57,"z":128},"requirements":{"minecraft:bricks":16,"minecraft:cobbled_deepslate":18,"minecraft:glass":16,"minecraft:spruce_planks":70,"minecraft:stone_bricks":2},"sha256":"ed7e26569c5ec786b1d77ac66c4a1b4784f027a6bf106f32efdfd0f3fe93f4f0","size":{"x":32,"y":1,"z":32}},{"blockCount":16,"bytes":1078,"file":"chunks/y057-z128-x064.json","offset":{"x":64,"y":57,"z":128},"requirements":{"minecraft:bricks":8,"minecraft:glass":8},"sha256":"a72990d1ed2db87aa0f6ba57029dd8c8bfaa878620f6403f6b274c62f03dd960","size":{"x":32,"y":1,"z":32}},{"blockCount":8,"bytes":848,"file":"chunks/y057-z128-x096.json","offset":{"x":96,"y":57,"z":128},"requirements":{"minecraft:bricks":4,"minecraft:glass":4},"sha256":"e42c435fc72af6ef2206fd4473e75bd3258f9f596a4dceae1fb0961221240e69","size":{"x":32,"y":1,"z":32}},{"blockCount":16,"bytes":1076,"file":"chunks/y057-z128-x128.json","offset":{"x":128,"y":57,"z":128},"requirements":{"minecraft:bricks":8,"minecraft:glass":8},"sha256":"149ed25f9d75d1f69e1637ee73217f563d06d6a7c09c3944da3d635e5be82299","size":{"x":32,"y":1,"z":32}},{"blockCount":19,"bytes":1176,"file":"chunks/y057-z128-x160.json","offset":{"x":160,"y":57,"z":128},"requirements":{"minecraft:bricks":9,"minecraft:glass":10},"sha256":"6d09246336e448572e891532e719d0a067262735a177e1208ae7c8ad127e2d93","size":{"x":32,"y":1,"z":32}},{"blockCount":56,"bytes":1835,"file":"chunks/y057-z128-x192.json","offset":{"x":192,"y":57,"z":128},"requirements":{"minecraft:bricks":37,"minecraft:glass":7,"minecraft:oak_planks":1,"minecraft:sandstone":4,"minecraft:stone_bricks":7},"sha256":"819c94525e297b63b854f2269eb305063d40232f5cff5b34968f3711328c025c","size":{"x":32,"y":1,"z":32}},{"blockCount":160,"bytes":4350,"file":"chunks/y057-z128-x224.json","offset":{"x":224,"y":57,"z":128},"requirements":{"minecraft:bricks":51,"minecraft:glass":1,"minecraft:oak_planks":5,"minecraft:polished_diorite":73,"minecraft:sandstone":17,"minecraft:stone_bricks":13},"sha256":"903297cd15ed88d2836a841ce31187d3140dfc4706b17a387dac9ce973a48a89","size":{"x":32,"y":1,"z":32}},{"blockCount":5,"bytes":791,"file":"chunks/y057-z128-x320.json","offset":{"x":320,"y":57,"z":128},"requirements":{"minecraft:polished_diorite":4,"minecraft:stone_bricks":1},"sha256":"9f774fad0c27483b7e3409f64fa3491b76de744df864c4962b5f0742f56c44ed","size":{"x":32,"y":1,"z":32}},{"blockCount":43,"bytes":1796,"file":"chunks/y057-z160-x000.json","offset":{"x":0,"y":57,"z":160},"requirements":{"minecraft:bricks":6,"minecraft:glass":5,"minecraft:polished_diorite":27,"minecraft:sandstone":1,"minecraft:stone_bricks":4},"sha256":"e6938f2e29721d5c2361964779276b6eecef92372ab7fb265cce1a6f9f52c5d2","size":{"x":32,"y":1,"z":32}},{"blockCount":101,"bytes":2784,"file":"chunks/y057-z160-x032.json","offset":{"x":32,"y":57,"z":160},"requirements":{"minecraft:bricks":19,"minecraft:glass":9,"minecraft:polished_diorite":58,"minecraft:sandstone":8,"minecraft:stone_bricks":7},"sha256":"e2128ee62419b1091b6c56c65d0682e8ae2ba63b306d05b686e85a11d1e94542","size":{"x":32,"y":1,"z":32}},{"blockCount":116,"bytes":3176,"file":"chunks/y057-z160-x064.json","offset":{"x":64,"y":57,"z":160},"requirements":{"minecraft:bricks":27,"minecraft:glass":6,"minecraft:oak_planks":2,"minecraft:polished_diorite":50,"minecraft:sandstone":16,"minecraft:stone_bricks":15},"sha256":"da45591c5d66b6c26b93b5ab6bb03d5d590e82999631154990627a0f6b26e406","size":{"x":32,"y":1,"z":32}},{"blockCount":16,"bytes":1081,"file":"chunks/y057-z160-x096.json","offset":{"x":96,"y":57,"z":160},"requirements":{"minecraft:bricks":8,"minecraft:glass":8},"sha256":"7b99a8a1d91b7e3344ffe04f8765235a3ab2f938e503e0c992fd65bf2bd3197e","size":{"x":32,"y":1,"z":32}},{"blockCount":77,"bytes":2596,"file":"chunks/y057-z160-x128.json","offset":{"x":128,"y":57,"z":160},"requirements":{"minecraft:bricks":24,"minecraft:glass":10,"minecraft:oak_planks":2,"minecraft:polished_diorite":20,"minecraft:sandstone":11,"minecraft:stone_bricks":10},"sha256":"34ae0ef87444e4ce74fc29b2757cb0cdcf68828112148f0672ec9228a5921221","size":{"x":32,"y":1,"z":32}},{"blockCount":103,"bytes":2632,"file":"chunks/y057-z160-x160.json","offset":{"x":160,"y":57,"z":160},"requirements":{"minecraft:bricks":23,"minecraft:glass":8,"minecraft:polished_diorite":52,"minecraft:sandstone":12,"minecraft:stone_bricks":8},"sha256":"6c4796fb22bae42f9043908015261f2138c958fc24ca0591ada5995c0baf7923","size":{"x":32,"y":1,"z":32}},{"blockCount":235,"bytes":4586,"file":"chunks/y057-z160-x192.json","offset":{"x":192,"y":57,"z":160},"requirements":{"minecraft:bricks":130,"minecraft:glass":6,"minecraft:oak_planks":3,"minecraft:polished_diorite":61,"minecraft:sandstone":12,"minecraft:spruce_planks":1,"minecraft:stone_bricks":22},"sha256":"bf5c6e65c30108a0a282ded949c481f7f80106e7f5603fd510a9f5e067a5a2c3","size":{"x":32,"y":1,"z":32}},{"blockCount":129,"bytes":3436,"file":"chunks/y057-z160-x224.json","offset":{"x":224,"y":57,"z":160},"requirements":{"minecraft:bricks":63,"minecraft:polished_diorite":58,"minecraft:stone_bricks":8},"sha256":"95b2d2b61630f4bb7255ab90d7d32ef50c6bb76f2042357ea8189ea393d79921","size":{"x":32,"y":1,"z":32}},{"blockCount":105,"bytes":2918,"file":"chunks/y057-z192-x064.json","offset":{"x":64,"y":57,"z":192},"requirements":{"minecraft:bricks":29,"minecraft:glass":6,"minecraft:oak_planks":1,"minecraft:polished_diorite":52,"minecraft:sandstone":9,"minecraft:stone_bricks":8},"sha256":"0437bdce395de96faafbd66ada7c25bf33e84992677a1b7f6fe66d1bbc4b1a43","size":{"x":32,"y":1,"z":32}},{"blockCount":152,"bytes":2911,"file":"chunks/y057-z192-x096.json","offset":{"x":96,"y":57,"z":192},"requirements":{"minecraft:bricks":64,"minecraft:glass":5,"minecraft:oak_planks":5,"minecraft:polished_diorite":52,"minecraft:sandstone":15,"minecraft:stone_bricks":11},"sha256":"fddabf266cdff64ccd65e9b9c668f96963e774b1c8918e9af4d77a82b361e1fc","size":{"x":32,"y":1,"z":32}},{"blockCount":197,"bytes":4007,"file":"chunks/y057-z192-x128.json","offset":{"x":128,"y":57,"z":192},"requirements":{"minecraft:bricks":67,"minecraft:glass":11,"minecraft:oak_planks":4,"minecraft:polished_diorite":82,"minecraft:sandstone":21,"minecraft:stone_bricks":12},"sha256":"5c8990a8c1c74ae34a0ac2cdcccd953e03faa2fbe4268068b33be12e2fe74514","size":{"x":32,"y":1,"z":32}},{"blockCount":8,"bytes":844,"file":"chunks/y057-z192-x160.json","offset":{"x":160,"y":57,"z":192},"requirements":{"minecraft:polished_diorite":8},"sha256":"e39b4fb5d6aa49b3c38de3537a38b15342d5bf93e473c54d7f99556511ef78f7","size":{"x":32,"y":1,"z":32}},{"blockCount":96,"bytes":2384,"file":"chunks/y058-z000-x352.json","offset":{"x":352,"y":58,"z":0},"requirements":{"minecraft:glass":1,"minecraft:polished_diorite":47,"minecraft:sandstone":48},"sha256":"18b6f6e7a18e66d3f412a27d1bd9c3c2e87f486f3f672ef2e93fe32e8d9c1a1a","size":{"x":32,"y":1,"z":32}},{"blockCount":70,"bytes":2588,"file":"chunks/y058-z000-x384.json","offset":{"x":384,"y":58,"z":0},"requirements":{"minecraft:glass":12,"minecraft:oak_planks":12,"minecraft:polished_diorite":4,"minecraft:sandstone":4,"minecraft:stone_bricks":38},"sha256":"b60a8caf90be35f0fb16c3a551a32d03d8ebf338971d875a00358a9e40c10bf2","size":{"x":32,"y":1,"z":32}},{"blockCount":10,"bytes":828,"file":"chunks/y058-z032-x384.json","offset":{"x":384,"y":58,"z":32},"requirements":{"minecraft:polished_diorite":4,"minecraft:stone_bricks":6},"sha256":"622824917b521e0affc06fe6ab5b57d9d0cb0af11ceca93cde9e646bd3ddf068","size":{"x":32,"y":1,"z":32}},{"blockCount":129,"bytes":3589,"file":"chunks/y058-z064-x064.json","offset":{"x":64,"y":58,"z":64},"requirements":{"minecraft:bricks":33,"minecraft:glass":10,"minecraft:oak_planks":1,"minecraft:polished_diorite":60,"minecraft:sandstone":6,"minecraft:stone_bricks":19},"sha256":"70da3b02162e70c099a0a8407829789bfd65cc3aec983e9b241bee8c3652cd6a","size":{"x":32,"y":1,"z":32}},{"blockCount":156,"bytes":2832,"file":"chunks/y058-z064-x096.json","offset":{"x":96,"y":58,"z":64},"requirements":{"minecraft:bricks":64,"minecraft:glass":7,"minecraft:oak_planks":5,"minecraft:polished_diorite":55,"minecraft:sandstone":15,"minecraft:stone_bricks":10},"sha256":"ea78fefd4e266fc37300adbf14aa96de8b02b1e8492b9dd77d6b1c5b3bdd71ca","size":{"x":32,"y":1,"z":32}},{"blockCount":225,"bytes":4638,"file":"chunks/y058-z064-x128.json","offset":{"x":128,"y":58,"z":64},"requirements":{"minecraft:bricks":72,"minecraft:glass":17,"minecraft:oak_planks":4,"minecraft:polished_diorite":94,"minecraft:sandstone":17,"minecraft:stone_bricks":21},"sha256":"ade31777b22e581e396c3b939216e11be50ab55fd2bb8235efed87852650c5bf","size":{"x":32,"y":1,"z":32}},{"blockCount":9,"bytes":946,"file":"chunks/y058-z064-x160.json","offset":{"x":160,"y":58,"z":64},"requirements":{"minecraft:polished_diorite":7,"minecraft:stone_bricks":2},"sha256":"e9bf0e8612b9a2d361b462243232af635a85323e7d29b26eb0e0af48fe732428","size":{"x":32,"y":1,"z":32}},{"blockCount":18,"bytes":1018,"file":"chunks/y058-z064-x192.json","offset":{"x":192,"y":58,"z":64},"requirements":{"minecraft:polished_diorite":13,"minecraft:stone_bricks":5},"sha256":"3722aa2e032347dc52be938e24b00f6ed608cdfe608b0b1208243ddb0eee808c","size":{"x":32,"y":1,"z":32}},{"blockCount":22,"bytes":1096,"file":"chunks/y058-z064-x224.json","offset":{"x":224,"y":58,"z":64},"requirements":{"minecraft:polished_diorite":16,"minecraft:stone_bricks":6},"sha256":"d205be2db0fce183239b868473b2c5801d9cf2c3dc80a976721930c850b57164","size":{"x":32,"y":1,"z":32}},{"blockCount":66,"bytes":2393,"file":"chunks/y058-z096-x000.json","offset":{"x":0,"y":58,"z":96},"requirements":{"minecraft:bricks":8,"minecraft:glass":7,"minecraft:polished_diorite":38,"minecraft:sandstone":1,"minecraft:stone_bricks":12},"sha256":"d0d27a9014f89c2ef23cecfbff7ebd800197c1cab4b75ffaecafa8951a1a37e5","size":{"x":32,"y":1,"z":32}},{"blockCount":122,"bytes":3303,"file":"chunks/y058-z096-x032.json","offset":{"x":32,"y":58,"z":96},"requirements":{"minecraft:bricks":28,"minecraft:glass":18,"minecraft:polished_diorite":57,"minecraft:sandstone":3,"minecraft:stone_bricks":16},"sha256":"9fd6171ce6a8f848b2f7652345203599c65fcd7b385e534eae39a02b1a3ab75e","size":{"x":32,"y":1,"z":32}},{"blockCount":115,"bytes":3195,"file":"chunks/y058-z096-x064.json","offset":{"x":64,"y":58,"z":96},"requirements":{"minecraft:bricks":32,"minecraft:glass":13,"minecraft:oak_planks":8,"minecraft:polished_diorite":42,"minecraft:sandstone":2,"minecraft:stone_bricks":18},"sha256":"3e92948ded150ed688fcb66b71c209fe3d04870a3370647f47b6d6d8a861be18","size":{"x":32,"y":1,"z":32}},{"blockCount":21,"bytes":1235,"file":"chunks/y058-z096-x096.json","offset":{"x":96,"y":58,"z":96},"requirements":{"minecraft:bricks":11,"minecraft:glass":10},"sha256":"cd023c6426c619e8870693c3622f1278656145d214d75e7a85556ca0cd14642b","size":{"x":32,"y":1,"z":32}},{"blockCount":69,"bytes":2528,"file":"chunks/y058-z096-x128.json","offset":{"x":128,"y":58,"z":96},"requirements":{"minecraft:bricks":27,"minecraft:glass":14,"minecraft:oak_planks":6,"minecraft:polished_diorite":14,"minecraft:stone_bricks":8},"sha256":"16673b7fa0dfe5f193b0e2dbf14b058086605fe9ee7eab5c28d4a3531987ac00","size":{"x":32,"y":1,"z":32}},{"blockCount":125,"bytes":3194,"file":"chunks/y058-z096-x160.json","offset":{"x":160,"y":58,"z":96},"requirements":{"minecraft:bricks":32,"minecraft:glass":20,"minecraft:oak_planks":2,"minecraft:polished_diorite":50,"minecraft:sandstone":4,"minecraft:stone_bricks":17},"sha256":"711cec50081939bc73dffe2ec7b157a6ff7747826b5ff68b816c2d52343035fb","size":{"x":32,"y":1,"z":32}},{"blockCount":253,"bytes":4984,"file":"chunks/y058-z096-x192.json","offset":{"x":192,"y":58,"z":96},"requirements":{"minecraft:bricks":146,"minecraft:glass":16,"minecraft:oak_planks":5,"minecraft:polished_diorite":43,"minecraft:sandstone":14,"minecraft:spruce_planks":2,"minecraft:stone_bricks":27},"sha256":"c57a6dd6007ef42a74e388221aeca56a696ac87c7feb7abc85b6df4865e3b08e","size":{"x":32,"y":1,"z":32}},{"blockCount":157,"bytes":3962,"file":"chunks/y058-z096-x224.json","offset":{"x":224,"y":58,"z":96},"requirements":{"minecraft:bricks":75,"minecraft:glass":1,"minecraft:oak_planks":1,"minecraft:polished_diorite":63,"minecraft:sandstone":5,"minecraft:stone_bricks":12},"sha256":"709cad7f112830ac5b9c178564d54a96bd37a9b391f11c37f057677e0d47d71d","size":{"x":32,"y":1,"z":32}},{"blockCount":102,"bytes":3260,"file":"chunks/y058-z128-x000.json","offset":{"x":0,"y":58,"z":128},"requirements":{"minecraft:bricks":20,"minecraft:glass":14,"minecraft:polished_diorite":42,"minecraft:sandstone":10,"minecraft:stone_bricks":16},"sha256":"e19f95dc315656c3109d99ff4ba09d61334ed39fdade0ce4c598f0ef1084e659","size":{"x":32,"y":1,"z":32}},{"blockCount":85,"bytes":2452,"file":"chunks/y058-z128-x032.json","offset":{"x":32,"y":58,"z":128},"requirements":{"minecraft:bricks":16,"minecraft:cobbled_deepslate":14,"minecraft:glass":16,"minecraft:spruce_planks":39},"sha256":"9f4d6864b6563318b4df61e0bc3fb64fef93f061be50c27b55d74f5e643ca37a","size":{"x":32,"y":1,"z":32}},{"blockCount":16,"bytes":1078,"file":"chunks/y058-z128-x064.json","offset":{"x":64,"y":58,"z":128},"requirements":{"minecraft:bricks":8,"minecraft:glass":8},"sha256":"e79e7ec93014ea071a89c304b3bd46cca4c2c7726023d6446388ecb3fb682cf3","size":{"x":32,"y":1,"z":32}},{"blockCount":8,"bytes":848,"file":"chunks/y058-z128-x096.json","offset":{"x":96,"y":58,"z":128},"requirements":{"minecraft:bricks":4,"minecraft:glass":4},"sha256":"bf2b0a96764c6cb09fa30b897978f4a0e7be8f774c6d3dceb878476b4c616f6e","size":{"x":32,"y":1,"z":32}},{"blockCount":16,"bytes":1076,"file":"chunks/y058-z128-x128.json","offset":{"x":128,"y":58,"z":128},"requirements":{"minecraft:bricks":8,"minecraft:glass":8},"sha256":"bb7dfbecc9f6ac4a48fa5c03a40779ba87fac5579bfaa206d571b4cb2258ec11","size":{"x":32,"y":1,"z":32}},{"blockCount":19,"bytes":1176,"file":"chunks/y058-z128-x160.json","offset":{"x":160,"y":58,"z":128},"requirements":{"minecraft:bricks":9,"minecraft:glass":10},"sha256":"87c3258bf8d4f63ce808d6189406545b0e2c74b98da5de83b94d9ad22a448d1e","size":{"x":32,"y":1,"z":32}},{"blockCount":50,"bytes":1676,"file":"chunks/y058-z128-x192.json","offset":{"x":192,"y":58,"z":128},"requirements":{"minecraft:bricks":34,"minecraft:glass":7,"minecraft:oak_planks":4,"minecraft:stone_bricks":5},"sha256":"4e86578ee237a82176357dacef43c7645a7ca2de03b0ac805a22b2793049eff0","size":{"x":32,"y":1,"z":32}},{"blockCount":169,"bytes":4274,"file":"chunks/y058-z128-x224.json","offset":{"x":224,"y":58,"z":128},"requirements":{"minecraft:bricks":53,"minecraft:glass":1,"minecraft:oak_planks":5,"minecraft:polished_diorite":80,"minecraft:sandstone":17,"minecraft:stone_bricks":13},"sha256":"62e96de04b2a2e9334da5a986f2099c397bd447d1dfef48c563f6f3a68e064b0","size":{"x":32,"y":1,"z":32}},{"blockCount":4,"bytes":764,"file":"chunks/y058-z128-x320.json","offset":{"x":320,"y":58,"z":128},"requirements":{"minecraft:polished_diorite":4},"sha256":"ed33b85b9bc03a3b175710a2e38c1dbb1fc73f01d2ce9669505b1d2594567435","size":{"x":32,"y":1,"z":32}},{"blockCount":45,"bytes":1873,"file":"chunks/y058-z160-x000.json","offset":{"x":0,"y":58,"z":160},"requirements":{"minecraft:bricks":6,"minecraft:glass":4,"minecraft:polished_diorite":26,"minecraft:sandstone":1,"minecraft:stone_bricks":8},"sha256":"d1f5baaf7e8e7af6b193c1a9f4576b30efc76872cd71140a1a491531a6b51a4f","size":{"x":32,"y":1,"z":32}},{"blockCount":106,"bytes":2824,"file":"chunks/y058-z160-x032.json","offset":{"x":32,"y":58,"z":160},"requirements":{"minecraft:bricks":20,"minecraft:glass":10,"minecraft:polished_diorite":57,"minecraft:sandstone":3,"minecraft:stone_bricks":16},"sha256":"1c94ddd89e1391be2a39153d64d563a4ccd1b8f497a9c35f3db8df5782ca96de","size":{"x":32,"y":1,"z":32}},{"blockCount":122,"bytes":3195,"file":"chunks/y058-z160-x064.json","offset":{"x":64,"y":58,"z":160},"requirements":{"minecraft:bricks":27,"minecraft:glass":8,"minecraft:oak_planks":8,"minecraft:polished_diorite":55,"minecraft:sandstone":3,"minecraft:stone_bricks":21},"sha256":"bb1f6e4669867cd93eec7ff6f53e325fd15dde742b53fc3dee0883b1e4c4df5f","size":{"x":32,"y":1,"z":32}},{"blockCount":16,"bytes":1081,"file":"chunks/y058-z160-x096.json","offset":{"x":96,"y":58,"z":160},"requirements":{"minecraft:bricks":8,"minecraft:glass":8},"sha256":"4687aa2987339d385892807e78ebe08253074b9cbb3601da029aca462cbb5a54","size":{"x":32,"y":1,"z":32}},{"blockCount":77,"bytes":2671,"file":"chunks/y058-z160-x128.json","offset":{"x":128,"y":58,"z":160},"requirements":{"minecraft:bricks":24,"minecraft:glass":11,"minecraft:oak_planks":6,"minecraft:polished_diorite":22,"minecraft:sandstone":3,"minecraft:stone_bricks":11},"sha256":"95902f4be66dfa470bad496d5eeb4b390b0b09048c5fecc3f1aa7e5be2853526","size":{"x":32,"y":1,"z":32}},{"blockCount":107,"bytes":2677,"file":"chunks/y058-z160-x160.json","offset":{"x":160,"y":58,"z":160},"requirements":{"minecraft:bricks":23,"minecraft:glass":10,"minecraft:oak_planks":2,"minecraft:polished_diorite":51,"minecraft:sandstone":4,"minecraft:stone_bricks":17},"sha256":"8691206fa884872922d929c4265ec1bf86e5dab21930183af90d7ad84ff67e59","size":{"x":32,"y":1,"z":32}},{"blockCount":231,"bytes":4720,"file":"chunks/y058-z160-x192.json","offset":{"x":192,"y":58,"z":160},"requirements":{"minecraft:bricks":122,"minecraft:glass":9,"minecraft:oak_planks":1,"minecraft:polished_diorite":56,"minecraft:sandstone":14,"minecraft:spruce_planks":2,"minecraft:stone_bricks":27},"sha256":"a812983d3e5eb71ba07c573ab1b1ad322da6392bb8b2dba54ec2ec740f35c3c7","size":{"x":32,"y":1,"z":32}},{"blockCount":128,"bytes":3513,"file":"chunks/y058-z160-x224.json","offset":{"x":224,"y":58,"z":160},"requirements":{"minecraft:bricks":63,"minecraft:polished_diorite":48,"minecraft:stone_bricks":17},"sha256":"e8f8609895db611fc41a1118049053d7c32111c96f2d26f88e5cb4c6dbd69ac9","size":{"x":32,"y":1,"z":32}},{"blockCount":109,"bytes":3090,"file":"chunks/y058-z192-x064.json","offset":{"x":64,"y":58,"z":192},"requirements":{"minecraft:bricks":29,"minecraft:glass":7,"minecraft:oak_planks":1,"minecraft:polished_diorite":51,"minecraft:sandstone":5,"minecraft:stone_bricks":16},"sha256":"bcbb943dbcebd8a515fc2403b876082a7f837a69fd8e58052c45a6ce64c77756","size":{"x":32,"y":1,"z":32}},{"blockCount":153,"bytes":2739,"file":"chunks/y058-z192-x096.json","offset":{"x":96,"y":58,"z":192},"requirements":{"minecraft:bricks":63,"minecraft:glass":5,"minecraft:oak_planks":5,"minecraft:polished_diorite":55,"minecraft:sandstone":15,"minecraft:stone_bricks":10},"sha256":"5646d3fa3b38a382895eb880ef05aaa2823aebd6aecca7b4dacc2a2c6a2ae8cd","size":{"x":32,"y":1,"z":32}},{"blockCount":203,"bytes":4083,"file":"chunks/y058-z192-x128.json","offset":{"x":128,"y":58,"z":192},"requirements":{"minecraft:bricks":67,"minecraft:glass":12,"minecraft:oak_planks":4,"minecraft:polished_diorite":86,"minecraft:sandstone":16,"minecraft:stone_bricks":18},"sha256":"1252ab0cb96bd2b31cfb4fb7b036ea58af0806d02c064051b787bbeb1c414b47","size":{"x":32,"y":1,"z":32}},{"blockCount":8,"bytes":909,"file":"chunks/y058-z192-x160.json","offset":{"x":160,"y":58,"z":192},"requirements":{"minecraft:polished_diorite":6,"minecraft:stone_bricks":2},"sha256":"fa9f492b28d59383fcf7cea0a01c419c8c013009d52a03e42334f12c78fe82da","size":{"x":32,"y":1,"z":32}},{"blockCount":167,"bytes":2602,"file":"chunks/y059-z000-x352.json","offset":{"x":352,"y":59,"z":0},"requirements":{"minecraft:glass":12,"minecraft:polished_diorite":67,"minecraft:sandstone":1,"minecraft:stone_bricks":87},"sha256":"7916e61759a7ba32bcc5fa09abaf5433e980caec80a3721756a0dfdffb118275","size":{"x":32,"y":1,"z":32}}],"schema":1}
