{"entries":[{"blockCount":72,"bytes":2527,"file":"chunks/y059-z000-x384.json","offset":{"x":384,"y":59,"z":0},"requirements":{"minecraft:glass":13,"minecraft:oak_planks":16,"minecraft:polished_diorite":12,"minecraft:stone_bricks":31},"sha256":"6024efe678361d6c1f67bd16ded742eb2da1ae342efb8b68ef54dc574ceaad03","size":{"x":32,"y":1,"z":32}},{"blockCount":8,"bytes":828,"file":"chunks/y059-z032-x384.json","offset":{"x":384,"y":59,"z":32},"requirements":{"minecraft:polished_diorite":4,"minecraft:stone_bricks":4},"sha256":"50b44be4fa99c90d66e2d7227d8508bb3d79cd356569812ed86ae31ec5181b01","size":{"x":32,"y":1,"z":32}},{"blockCount":127,"bytes":3436,"file":"chunks/y059-z064-x064.json","offset":{"x":64,"y":59,"z":64},"requirements":{"minecraft:bricks":37,"minecraft:glass":6,"minecraft:oak_planks":1,"minecraft:polished_diorite":60,"minecraft:sandstone":10,"minecraft:stone_bricks":13},"sha256":"701d2b2a639941cca2c87421cf67c60c4347b721a0746047c86ced8086010c2a","size":{"x":32,"y":1,"z":32}},{"blockCount":163,"bytes":2831,"file":"chunks/y059-z064-x096.json","offset":{"x":96,"y":59,"z":64},"requirements":{"minecraft:bricks":66,"minecraft:glass":7,"minecraft:oak_planks":5,"minecraft:polished_diorite":58,"minecraft:sandstone":15,"minecraft:stone_bricks":12},"sha256":"c28a06549808922d07e4e698423d15fb111bc00cacb543508669c6bf173eb5ce","size":{"x":32,"y":1,"z":32}},{"blockCount":226,"bytes":4446,"file":"chunks/y059-z064-x128.json","offset":{"x":128,"y":59,"z":64},"requirements":{"minecraft:bricks":76,"minecraft:glass":13,"minecraft:oak_planks":4,"minecraft:polished_diorite":94,"minecraft:sandstone":22,"minecraft:stone_bricks":17},"sha256":"d9f87729b9a7ff5c55bf574dabeabea0292ea99f10290180019eee4d617532d9","size":{"x":32,"y":1,"z":32}},{"blockCount":7,"bytes":881,"file":"chunks/y059-z064-x160.json","offset":{"x":160,"y":59,"z":64},"requirements":{"minecraft:polished_diorite":7},"sha256":"aa657146907a84aac7943e1a2b7e9f2577c9044ec14017f4e941fdd0f4234dd5","size":{"x":32,"y":1,"z":32}},{"blockCount":17,"bytes":979,"file":"chunks/y059-z064-x192.json","offset":{"x":192,"y":59,"z":64},"requirements":{"minecraft:polished_diorite":14,"minecraft:stone_bricks":3},"sha256":"55def645b477a9e1311e4d3c383a2391dd85145103450deb92023187995cfee0","size":{"x":32,"y":1,"z":32}},{"blockCount":20,"bytes":1018,"file":"chunks/y059-z064-x224.json","offset":{"x":224,"y":59,"z":64},"requirements":{"minecraft:polished_diorite":17,"minecraft:stone_bricks":3},"sha256":"48852f8f12867532f3f930c6babd3469e53e29eaf3e0d52c31c9e8ad399d9e64","size":{"x":32,"y":1,"z":32}},{"blockCount":63,"bytes":2279,"file":"chunks/y059-z096-x000.json","offset":{"x":0,"y":59,"z":96},"requirements":{"minecraft:bricks":11,"minecraft:glass":7,"minecraft:polished_diorite":39,"minecraft:sandstone":2,"minecraft:stone_bricks":4},"sha256":"0d2678cd54bb917b9d6c0a7d60e41b0af339e4fb958c8e404c4762b6ac9d1251","size":{"x":32,"y":1,"z":32}},{"blockCount":118,"bytes":3093,"file":"chunks/y059-z096-x032.json","offset":{"x":32,"y":59,"z":96},"requirements":{"minecraft:bricks":31,"minecraft:glass":14,"minecraft:polished_diorite":56,"minecraft:sandstone":7,"minecraft:stone_bricks":10},"sha256":"4028d57862a3f225bc5483b3c58cb4b6a944319416142a47fe0e7562d031ebc6","size":{"x":32,"y":1,"z":32}},{"blockCount":114,"bytes":3100,"file":"chunks/y059-z096-x064.json","offset":{"x":64,"y":59,"z":96},"requirements":{"minecraft:bricks":37,"minecraft:glass":11,"minecraft:oak_planks":2,"minecraft:polished_diorite":40,"minecraft:sandstone":12,"minecraft:stone_bricks":12},"sha256":"f4d3825afdeea6ff4655a4c8b4e9a865d30fdb798c3ad2728760de958e6b0995","size":{"x":32,"y":1,"z":32}},{"blockCount":21,"bytes":1235,"file":"chunks/y059-z096-x096.json","offset":{"x":96,"y":59,"z":96},"requirements":{"minecraft:bricks":11,"minecraft:glass":10},"sha256":"b131552774cb86dcd4d4998bb92e853fbc9db19fa150b2c9b706b1c4fe067c14","size":{"x":32,"y":1,"z":32}},{"blockCount":70,"bytes":2552,"file":"chunks/y059-z096-x128.json","offset":{"x":128,"y":59,"z":96},"requirements":{"minecraft:bricks":30,"minecraft:glass":14,"minecraft:oak_planks":2,"minecraft:polished_diorite":12,"minecraft:sandstone":6,"minecraft:stone_bricks":6},"sha256":"2f7811cbdfc77aec0e13eb56ced6c7736e0044ab72c0327c76f1d02b520b6dad","size":{"x":32,"y":1,"z":32}},{"blockCount":123,"bytes":2941,"file":"chunks/y059-z096-x160.json","offset":{"x":160,"y":59,"z":96},"requirements":{"minecraft:bricks":37,"minecraft:glass":16,"minecraft:polished_diorite":50,"minecraft:sandstone":10,"minecraft:stone_bricks":10},"sha256":"4b611111bd63995a813cd36f22dd7dce73cf65ac278e727acd0087066ab7f3c1","size":{"x":32,"y":1,"z":32}},{"blockCount":252,"bytes":4929,"file":"chunks/y059-z096-x192.json","offset":{"x":192,"y":59,"z":96},"requirements":{"minecraft:bricks":150,"minecraft:glass":14,"minecraft:oak_planks":2,"minecraft:polished_diorite":42,"minecraft:sandstone":21,"minecraft:spruce_planks":2,"minecraft:stone_bricks":21},"sha256":"44011ba38ce1de18a86326b1a0f0d5e8e42d9a9321afa245290fc9f335b4d1e9","size":{"x":32,"y":1,"z":32}},{"blockCount":153,"bytes":3942,"file":"chunks/y059-z096-x224.json","offset":{"x":224,"y":59,"z":96},"requirements":{"minecraft:bricks":75,"minecraft:glass":1,"minecraft:oak_planks":1,"minecraft:polished_diorite":62,"minecraft:sandstone":5,"minecraft:stone_bricks":9},"sha256":"910fe3b489fb21d9640723587b1ebbe3e38a2f8e6c920ea22f36c3e04804b514","size":{"x":32,"y":1,"z":32}},{"blockCount":105,"bytes":3202,"file":"chunks/y059-z128-x000.json","offset":{"x":0,"y":59,"z":128},"requirements":{"minecraft:bricks":27,"minecraft:glass":6,"minecraft:polished_diorite":44,"minecraft:sandstone":14,"minecraft:stone_bricks":14},"sha256":"5f6c2a5dca52d7657e71656040b87933d5af378e93bb48a39e27e9041aede927","size":{"x":32,"y":1,"z":32}},{"blockCount":50,"bytes":2030,"file":"chunks/y059-z128-x032.json","offset":{"x":32,"y":59,"z":128},"requirements":{"minecraft:bricks":16,"minecraft:cobbled_deepslate":10,"minecraft:glass":16,"minecraft:spruce_planks":8},"sha256":"435f298da1455d59e17b1012b5e15d451efdffedf63b81382c184755a6021ba5","size":{"x":32,"y":1,"z":32}},{"blockCount":16,"bytes":1078,"file":"chunks/y059-z128-x064.json","offset":{"x":64,"y":59,"z":128},"requirements":{"minecraft:bricks":8,"minecraft:glass":8},"sha256":"e2a70ad0e2d5d020273741d620c54ae9fa24788195c04166a5b2075f5eebe132","size":{"x":32,"y":1,"z":32}},{"blockCount":8,"bytes":848,"file":"chunks/y059-z128-x096.json","offset":{"x":96,"y":59,"z":128},"requirements":{"minecraft:bricks":4,"minecraft:glass":4},"sha256":"995327d951ba55ceaaafa4790cdd82df4f34116b88b0ccd97c2a6d8386708043","size":{"x":32,"y":1,"z":32}},{"blockCount":16,"bytes":1076,"file":"chunks/y059-z128-x128.json","offset":{"x":128,"y":59,"z":128},"requirements":{"minecraft:bricks":8,"minecraft:glass":8},"sha256":"2886e2a7e209b9b889d3cdc8c8315a43678e42ca24dbb88c66de33194498b5bb","size":{"x":32,"y":1,"z":32}},{"blockCount":19,"bytes":1176,"file":"chunks/y059-z128-x160.json","offset":{"x":160,"y":59,"z":128},"requirements":{"minecraft:bricks":9,"minecraft:glass":10},"sha256":"485c331be98149ed54015354808bd7d4d772ff0b9ed1f365d1b0db3c66b87105","size":{"x":32,"y":1,"z":32}},{"blockCount":52,"bytes":1776,"file":"chunks/y059-z128-x192.json","offset":{"x":192,"y":59,"z":128},"requirements":{"minecraft:bricks":36,"minecraft:glass":7,"minecraft:oak_planks":1,"minecraft:sandstone":4,"minecraft:stone_bricks":4},"sha256":"210692b5e4a4bcdaeca737bcb4e4d85614952e5a3c68f4297bbdb2e80f13e14b","size":{"x":32,"y":1,"z":32}},{"blockCount":177,"bytes":4350,"file":"chunks/y059-z128-x224.json","offset":{"x":224,"y":59,"z":128},"requirements":{"minecraft:bricks":55,"minecraft:glass":1,"minecraft:oak_planks":5,"minecraft:polished_diorite":83,"minecraft:sandstone":17,"minecraft:stone_bricks":16},"sha256":"a62fc8afa0a638d7fb3395ca3ab552f83091ba4b2ce9f33c796525f2fa7f9d57","size":{"x":32,"y":1,"z":32}},{"blockCount":5,"bytes":791,"file":"chunks/y059-z128-x320.json","offset":{"x":320,"y":59,"z":128},"requirements":{"minecraft:polished_diorite":4,"minecraft:stone_bricks":1},"sha256":"da17659447c51b211566edd65e25e0e5bdebf076b014984d2c74f07824ce838a","size":{"x":32,"y":1,"z":32}},{"blockCount":41,"bytes":1754,"file":"chunks/y059-z160-x000.json","offset":{"x":0,"y":59,"z":160},"requirements":{"minecraft:bricks":8,"minecraft:glass":4,"minecraft:polished_diorite":27,"minecraft:stone_bricks":2},"sha256":"4b97f899a4f5017fa619104a3fadddc7a6450c13e7480330c4ab856e864d5fe1","size":{"x":32,"y":1,"z":32}},{"blockCount":102,"bytes":2613,"file":"chunks/y059-z160-x032.json","offset":{"x":32,"y":59,"z":160},"requirements":{"minecraft:bricks":23,"minecraft:glass":6,"minecraft:polished_diorite":56,"minecraft:sandstone":7,"minecraft:stone_bricks":10},"sha256":"8358c5a9cbf6cbcd03c7f974a960e77a935efe1d1a4bdf8495064456e8218ccc","size":{"x":32,"y":1,"z":32}},{"blockCount":117,"bytes":3100,"file":"chunks/y059-z160-x064.json","offset":{"x":64,"y":59,"z":160},"requirements":{"minecraft:bricks":34,"minecraft:glass":5,"minecraft:oak_planks":2,"minecraft:polished_diorite":49,"minecraft:sandstone":14,"minecraft:stone_bricks":13},"sha256":"58b1ce5825d80fc28a508de0d9a24f6cedce14cbea73313bcf2fb24f7eec4dbd","size":{"x":32,"y":1,"z":32}},{"blockCount":16,"bytes":1081,"file":"chunks/y059-z160-x096.json","offset":{"x":96,"y":59,"z":160},"requirements":{"minecraft:bricks":8,"minecraft:glass":8},"sha256":"5a82b7bd36a18c6cecc73b78ddccf10fcb61588fd453c693dfb7c8a60b39d7af","size":{"x":32,"y":1,"z":32}},{"blockCount":77,"bytes":2595,"file":"chunks/y059-z160-x128.json","offset":{"x":128,"y":59,"z":160},"requirements":{"minecraft:bricks":28,"minecraft:glass":10,"minecraft:oak_planks":2,"minecraft:polished_diorite":20,"minecraft:sandstone":10,"minecraft:stone_bricks":7},"sha256":"91299b60d578ae307f7cb6952815018b0381ea6d53f4941db97b6ef4428307fa","size":{"x":32,"y":1,"z":32}},{"blockCount":105,"bytes":2443,"file":"chunks/y059-z160-x160.json","offset":{"x":160,"y":59,"z":160},"requirements":{"minecraft:bricks":28,"minecraft:glass":6,"minecraft:polished_diorite":51,"minecraft:sandstone":10,"minecraft:stone_bricks":10},"sha256":"491b8f415c69134843cbd1a19b20fa4e1ea9451903e382efe95be489b80d45f2","size":{"x":32,"y":1,"z":32}},{"blockCount":227,"bytes":4550,"file":"chunks/y059-z160-x192.json","offset":{"x":192,"y":59,"z":160},"requirements":{"minecraft:bricks":124,"minecraft:glass":7,"minecraft:oak_planks":1,"minecraft:polished_diorite":56,"minecraft:sandstone":17,"minecraft:spruce_planks":2,"minecraft:stone_bricks":20},"sha256":"4e02584135954dd5f16d4c24f6b8ceac68eb59d424212f96104d0a8e1b686158","size":{"x":32,"y":1,"z":32}},{"blockCount":125,"bytes":3416,"file":"chunks/y059-z160-x224.json","offset":{"x":224,"y":59,"z":160},"requirements":{"minecraft:bricks":64,"minecraft:polished_diorite":49,"minecraft:stone_bricks":12},"sha256":"461cef7d1fce3906a7bda996f30ad77b33fdebe494e62f4c5e3a4648122cb648","size":{"x":32,"y":1,"z":32}},{"blockCount":108,"bytes":2975,"file":"chunks/y059-z192-x064.json","offset":{"x":64,"y":59,"z":192},"requirements":{"minecraft:bricks":32,"minecraft:glass":4,"minecraft:oak_planks":1,"minecraft:polished_diorite":51,"minecraft:sandstone":8,"minecraft:stone_bricks":12},"sha256":"1d9c806c977839a823d2e533f0017dc48831e4c96034c5d1e101dd1caeaf72dd","size":{"x":32,"y":1,"z":32}},{"blockCount":160,"bytes":2699,"file":"chunks/y059-z192-x096.json","offset":{"x":96,"y":59,"z":192},"requirements":{"minecraft:bricks":65,"minecraft:glass":5,"minecraft:oak_planks":5,"minecraft:polished_diorite":58,"minecraft:sandstone":15,"minecraft:stone_bricks":12},"sha256":"fe31f576edad4d61671a131c6c2efd90d1a72eecb26c8b5b030b45726c1e5b66","size":{"x":32,"y":1,"z":32}},{"blockCount":205,"bytes":3928,"file":"chunks/y059-z192-x128.json","offset":{"x":128,"y":59,"z":192},"requirements":{"minecraft:bricks":70,"minecraft:glass":9,"minecraft:oak_planks":4,"minecraft:polished_diorite":86,"minecraft:sandstone":20,"minecraft:stone_bricks":16},"sha256":"626fa5b1f581c1a3696b887f6a36e82a8d2ffa6fcb8d77c34223f32cb7a67e17","size":{"x":32,"y":1,"z":32}},{"blockCount":6,"bytes":844,"file":"chunks/y059-z192-x160.json","offset":{"x":160,"y":59,"z":192},"requirements":{"minecraft:polished_diorite":6},"sha256":"16ac0820dce94ff44369ea8c426698cb7ee6a3e239d6680447b125b53957732f","size":{"x":32,"y":1,"z":32}},{"blockCount":189,"bytes":2054,"file":"chunks/y060-z000-x352.json","offset":{"x":352,"y":60,"z":0},"requirements":{"minecraft:glass":20,"minecraft:polished_diorite":2,"minecraft:sandstone":40,"minecraft:stone_bricks":127},"sha256":"80d223391269648d4b4c09ec42fd0c578d4ec439d18bcaf49b6faa62e68f4d77","size":{"x":32,"y":1,"z":32}},{"blockCount":97,"bytes":2784,"file":"chunks/y060-z000-x384.json","offset":{"x":384,"y":60,"z":0},"requirements":{"minecraft:glass":8,"minecraft:oak_planks":26,"minecraft:polished_diorite":12,"minecraft:spruce_planks":12,"minecraft:stone_bricks":39},"sha256":"6af1c57a6970c44bac1b47cbcd23e80fb2d38f5cf49e90e36bc2720069964224","size":{"x":32,"y":1,"z":32}},{"blockCount":10,"bytes":853,"file":"chunks/y060-z032-x384.json","offset":{"x":384,"y":60,"z":32},"requirements":{"minecraft:oak_planks":2,"minecraft:polished_diorite":4,"minecraft:stone_bricks":4},"sha256":"5ad571ccb7fe764e198bfb05e69a94f1ed9d6ca0f936e264e07fb23cc425db46","size":{"x":32,"y":1,"z":32}},{"blockCount":139,"bytes":3777,"file":"chunks/y060-z064-x064.json","offset":{"x":64,"y":60,"z":64},"requirements":{"minecraft:bricks":37,"minecraft:glass":6,"minecraft:oak_planks":1,"minecraft:polished_diorite":60,"minecraft:sandstone":6,"minecraft:stone_bricks":29},"sha256":"59e4ffa62e36ed10627a8e708763264484a0af0850439b830e1b5d2c8d7734ef","size":{"x":32,"y":1,"z":32}},{"blockCount":166,"bytes":2718,"file":"chunks/y060-z064-x096.json","offset":{"x":96,"y":60,"z":64},"requirements":{"minecraft:bricks":66,"minecraft:glass":4,"minecraft:oak_planks":5,"minecraft:polished_diorite":62,"minecraft:sandstone":15,"minecraft:stone_bricks":14},"sha256":"d2999352844646987f9e4fe4190aa0dd2d37a6463af6eb14f92cb010dba9aecf","size":{"x":32,"y":1,"z":32}},{"blockCount":236,"bytes":4693,"file":"chunks/y060-z064-x128.json","offset":{"x":128,"y":60,"z":64},"requirements":{"minecraft:bricks":76,"minecraft:glass":10,"minecraft:oak_planks":4,"minecraft:polished_diorite":96,"minecraft:sandstone":17,"minecraft:stone_bricks":33},"sha256":"6cc30d27170603458cf80cecdc6526d13ab0ceaeb1b3cbc8e8ca6ef336a4c923","size":{"x":32,"y":1,"z":32}},{"blockCount":12,"bytes":1103,"file":"chunks/y060-z064-x160.json","offset":{"x":160,"y":60,"z":64},"requirements":{"minecraft:polished_diorite":7,"minecraft:stone_bricks":5},"sha256":"339ea5e39b75f00e0e83c1d90007c6c73b49cac0a78dda07ef98ea674dc8cb34","size":{"x":32,"y":1,"z":32}},{"blockCount":19,"bytes":1074,"file":"chunks/y060-z064-x192.json","offset":{"x":192,"y":60,"z":64},"requirements":{"minecraft:polished_diorite":12,"minecraft:stone_bricks":7},"sha256":"fcea5ab47a2aee272f0c8caf6ee7dba72d3beacec4e95aadfdfe8487426631fa","size":{"x":32,"y":1,"z":32}},{"blockCount":22,"bytes":1094,"file":"chunks/y060-z064-x224.json","offset":{"x":224,"y":60,"z":64},"requirements":{"minecraft:polished_diorite":15,"minecraft:stone_bricks":7},"sha256":"483b6863b8c1f228936cb5136847d5a6068ab4666c19bdb70d36f211821ca70f","size":{"x":32,"y":1,"z":32}},{"blockCount":84,"bytes":2719,"file":"chunks/y060-z096-x000.json","offset":{"x":0,"y":60,"z":96},"requirements":{"minecraft:bricks":13,"minecraft:glass":3,"minecraft:polished_diorite":43,"minecraft:sandstone":4,"minecraft:stone_bricks":21},"sha256":"3e68f46c721f6f519ef8661f67451487cba55d166b3aa7f2183e903bd9381e20","size":{"x":32,"y":1,"z":32}},{"blockCount":136,"bytes":3303,"file":"chunks/y060-z096-x032.json","offset":{"x":32,"y":60,"z":96},"requirements":{"minecraft:bricks":34,"minecraft:glass":10,"minecraft:polished_diorite":58,"minecraft:sandstone":3,"minecraft:stone_bricks":31},"sha256":"f3fbf05754fa3850ff98ed9212e4d20986f26a98e0429ead4e95c22f78287e96","size":{"x":32,"y":1,"z":32}},{"blockCount":123,"bytes":3252,"file":"chunks/y060-z096-x064.json","offset":{"x":64,"y":60,"z":96},"requirements":{"minecraft:bricks":37,"minecraft:glass":7,"minecraft:oak_planks":2,"minecraft:polished_diorite":42,"minecraft:sandstone":6,"minecraft:stone_bricks":29},"sha256":"72ef0706ab515bc2a5ec98128a0f40c6431ad57bd0b1bdbeb8215196bb872b9d","size":{"x":32,"y":1,"z":32}},{"blockCount":24,"bytes":1376,"file":"chunks/y060-z096-x096.json","offset":{"x":96,"y":60,"z":96},"requirements":{"minecraft:bricks":11,"minecraft:glass":10,"minecraft:stone_bricks":3},"sha256":"dd21f7fcb24bd182a5200b88f24eed9e543288e545cbf2709d29d65bfb05bb71","size":{"x":32,"y":1,"z":32}},{"blockCount":72,"bytes":2629,"file":"chunks/y060-z096-x128.json","offset":{"x":128,"y":60,"z":96},"requirements":{"minecraft:bricks":30,"minecraft:glass":12,"minecraft:oak_planks":2,"minecraft:polished_diorite":12,"minecraft:sandstone":3,"minecraft:stone_bricks":13},"sha256":"021c6bf020eebfde7fba33518a98faaebed343ee6cf43108f0178cc49e3bb4cb","size":{"x":32,"y":1,"z":32}},{"blockCount":142,"bytes":3266,"file":"chunks/y060-z096-x160.json","offset":{"x":160,"y":60,"z":96},"requirements":{"minecraft:bricks":37,"minecraft:glass":11,"minecraft:polished_diorite":54,"minecraft:sandstone":5,"minecraft:stone_bricks":35},"sha256":"e73147c7e170baecc93bf8233c6768236ee267ef45e52608aa9a9db2c8adf733","size":{"x":32,"y":1,"z":32}},{"blockCount":383,"bytes":7095,"file":"chunks/y060-z096-x192.json","offset":{"x":192,"y":60,"z":96},"requirements":{"minecraft:bricks":159,"minecraft:glass":67,"minecraft:oak_planks":62,"minecraft:polished_diorite":43,"minecraft:sandstone":11,"minecraft:spruce_planks":2,"minecraft:stone_bricks":39},"sha256":"e9694e7536d149fae9daee9589eeb2741c02c9aefdacc8f8d31c75d71135842a","size":{"x":32,"y":1,"z":32}},{"blockCount":428,"bytes":8971,"file":"chunks/y060-z096-x224.json","offset":{"x":224,"y":60,"z":96},"requirements":{"minecraft:bricks":69,"minecraft:glass":141,"minecraft:oak_planks":139,"minecraft:polished_diorite":58,"minecraft:sandstone":5,"minecraft:stone_bricks":16},"sha256":"884dd2ca9d1965e28a2b3878dfc673898bef162b615191e5528190dfe84f572c","size":{"x":32,"y":1,"z":32}},{"blockCount":124,"bytes":3448,"file":"chunks/y060-z128-x000.json","offset":{"x":0,"y":60,"z":128},"requirements":{"minecraft:bricks":34,"minecraft:glass":4,"minecraft:polished_diorite":51,"minecraft:sandstone":6,"minecraft:stone_bricks":29},"sha256":"626595d428e68d0f6e4f5a1ef27e28018332efd66d22e80225473b2d77b3e5b3","size":{"x":32,"y":1,"z":32}},{"blockCount":40,"bytes":1892,"file":"chunks/y060-z128-x032.json","offset":{"x":32,"y":60,"z":128},"requirements":{"minecraft:bricks":16,"minecraft:cobbled_deepslate":8,"minecraft:glass":8,"minecraft:stone_bricks":8},"sha256":"70f3a751dd2cab77f5b12d7a67d94595aa9ed5678db81195866c24937f332775","size":{"x":32,"y":1,"z":32}},{"blockCount":19,"bytes":1244,"file":"chunks/y060-z128-x064.json","offset":{"x":64,"y":60,"z":128},"requirements":{"minecraft:bricks":8,"minecraft:glass":8,"minecraft:stone_bricks":3},"sha256":"80c72eed11e59f44a509f349d3a4343ba6b591a009ce1bb8441ae3398ca0e753","size":{"x":32,"y":1,"z":32}},{"blockCount":11,"bytes":966,"file":"chunks/y060-z128-x096.json","offset":{"x":96,"y":60,"z":128},"requirements":{"minecraft:bricks":4,"minecraft:glass":7},"sha256":"d49ee129c927178ecba4279f468b0c0d53c02809dc337763e30113e4a62c0be9","size":{"x":32,"y":1,"z":32}},{"blockCount":20,"bytes":1281,"file":"chunks/y060-z128-x128.json","offset":{"x":128,"y":60,"z":128},"requirements":{"minecraft:bricks":8,"minecraft:glass":11,"minecraft:stone_bricks":1},"sha256":"bce9421d78d722acfc01c56a3566ecbdc5c6b228e642ead2543198452c9f4241","size":{"x":32,"y":1,"z":32}},{"blockCount":23,"bytes":1360,"file":"chunks/y060-z128-x160.json","offset":{"x":160,"y":60,"z":128},"requirements":{"minecraft:bricks":9,"minecraft:glass":9,"minecraft:stone_bricks":5},"sha256":"270794f580db7bcea990e351cb2ce4e8b43ef196cd0aafebe56d13d0209af04b","size":{"x":32,"y":1,"z":32}},{"blockCount":51,"bytes":1738,"file":"chunks/y060-z128-x192.json","offset":{"x":192,"y":60,"z":128},"requirements":{"minecraft:bricks":34,"minecraft:glass":7,"minecraft:oak_planks":1,"minecraft:sandstone":2,"minecraft:stone_bricks":7},"sha256":"c3085a5b12ba77b025deea27679f5ee203f717b44abfa3c9441c1f7da2b3cc76","size":{"x":32,"y":1,"z":32}},{"blockCount":178,"bytes":4350,"file":"chunks/y060-z128-x224.json","offset":{"x":224,"y":60,"z":128},"requirements":{"minecraft:bricks":57,"minecraft:glass":1,"minecraft:oak_planks":5,"minecraft:polished_diorite":84,"minecraft:sandstone":17,"minecraft:stone_bricks":14},"sha256":"4730048362724eb38f6a02455036317de94c3a7d6cb01e153b337b2c8c851160","size":{"x":32,"y":1,"z":32}},{"blockCount":12,"bytes":839,"file":"chunks/y060-z128-x320.json","offset":{"x":320,"y":60,"z":128},"requirements":{"minecraft:stone_bricks":12},"sha256":"a8c9ea0b9f3cd6ee04159cb737a2a8a6fad036581aac8d10bbd9c6f748764e90","size":{"x":32,"y":1,"z":32}},{"blockCount":55,"bytes":2085,"file":"chunks/y060-z160-x000.json","offset":{"x":0,"y":60,"z":160},"requirements":{"minecraft:bricks":9,"minecraft:glass":2,"minecraft:polished_diorite":30,"minecraft:sandstone":2,"minecraft:stone_bricks":12},"sha256":"0cf1af2bf8ed6f1115454d35553243c1cc77506da14802a4a5030098a9c5a64d","size":{"x":32,"y":1,"z":32}},{"blockCount":120,"bytes":2861,"file":"chunks/y060-z160-x032.json","offset":{"x":32,"y":60,"z":160},"requirements":{"minecraft:bricks":26,"minecraft:glass":6,"minecraft:polished_diorite":58,"minecraft:sandstone":3,"minecraft:stone_bricks":27},"sha256":"56065a2a13d9ecd4dd539c9d451c51926e20fc6b08f01fc2eac5ee7e8cad6db1","size":{"x":32,"y":1,"z":32}},{"blockCount":131,"bytes":3348,"file":"chunks/y060-z160-x064.json","offset":{"x":64,"y":60,"z":160},"requirements":{"minecraft:bricks":34,"minecraft:glass":5,"minecraft:oak_planks":2,"minecraft:polished_diorite":52,"minecraft:sandstone":7,"minecraft:stone_bricks":31},"sha256":"7ca58565b9de53a5dbe80dfff8db0f5b7e8246e85019ca0a1dbcec077b68df86","size":{"x":32,"y":1,"z":32}},{"blockCount":19,"bytes":1203,"file":"chunks/y060-z160-x096.json","offset":{"x":96,"y":60,"z":160},"requirements":{"minecraft:bricks":8,"minecraft:glass":7,"minecraft:stone_bricks":4},"sha256":"9878db14b3487f4630d9701146c8eb8ece5879d3cb7684a2bcbed5701f93a0ed","size":{"x":32,"y":1,"z":32}},{"blockCount":82,"bytes":2726,"file":"chunks/y060-z160-x128.json","offset":{"x":128,"y":60,"z":160},"requirements":{"minecraft:bricks":28,"minecraft:glass":8,"minecraft:oak_planks":2,"minecraft:polished_diorite":21,"minecraft:sandstone":6,"minecraft:stone_bricks":17},"sha256":"0a7884b1489f8380a1b70230906ae5892dbfa4fcab4061a46923ab66262b63ad","size":{"x":32,"y":1,"z":32}},{"blockCount":125,"bytes":2768,"file":"chunks/y060-z160-x160.json","offset":{"x":160,"y":60,"z":160},"requirements":{"minecraft:bricks":28,"minecraft:glass":6,"minecraft:polished_diorite":55,"minecraft:sandstone":5,"minecraft:stone_bricks":31},"sha256":"2aa4366316eba3b40eafea8cbc8b8f9923e47b5f1610efa766871bbc8fa49d67","size":{"x":32,"y":1,"z":32}},{"blockCount":363,"bytes":6867,"file":"chunks/y060-z160-x192.json","offset":{"x":192,"y":60,"z":160},"requirements":{"minecraft:bricks":133,"minecraft:glass":64,"minecraft:oak_planks":61,"minecraft:polished_diorite":55,"minecraft:sandstone":9,"minecraft:spruce_planks":2,"minecraft:stone_bricks":39},"sha256":"f651e245bb7adc2033999d85fbc5803e0ddfb0aa8ee578ea94f466a1d8003f67","size":{"x":32,"y":1,"z":32}},{"blockCount":395,"bytes":8489,"file":"chunks/y060-z160-x224.json","offset":{"x":224,"y":60,"z":160},"requirements":{"minecraft:bricks":57,"minecraft:glass":138,"minecraft:oak_planks":138,"minecraft:polished_diorite":42,"minecraft:stone_bricks":20},"sha256":"15d4d0827313cf003539e51f7579d40bd2e2dde7874fd7810b0853031819aa07","size":{"x":32,"y":1,"z":32}},{"blockCount":116,"bytes":3241,"file":"chunks/y060-z192-x064.json","offset":{"x":64,"y":60,"z":192},"requirements":{"minecraft:bricks":32,"minecraft:glass":4,"minecraft:oak_planks":1,"minecraft:polished_diorite":50,"minecraft:sandstone":5,"minecraft:stone_bricks":24},"sha256":"f45f6ae97aea2557c09fb88f9cda645be7570c7c0fd1692ed210b6b229edf4f6","size":{"x":32,"y":1,"z":32}},{"blockCount":163,"bytes":2587,"file":"chunks/y060-z192-x096.json","offset":{"x":96,"y":60,"z":192},"requirements":{"minecraft:bricks":65,"minecraft:glass":3,"minecraft:oak_planks":5,"minecraft:polished_diorite":62,"minecraft:sandstone":15,"minecraft:stone_bricks":13},"sha256":"741222bc10ee07cc2025e6353b2d156e47546e6e20fb7fe5fb77d78421d8b3cb","size":{"x":32,"y":1,"z":32}},{"blockCount":212,"bytes":4099,"file":"chunks/y060-z192-x128.json","offset":{"x":128,"y":60,"z":192},"requirements":{"minecraft:bricks":70,"minecraft:glass":7,"minecraft:oak_planks":4,"minecraft:polished_diorite":87,"minecraft:sandstone":16,"minecraft:stone_bricks":28},"sha256":"890a355706a59eb394839dddebaf8c05b4899413169def20c8c24e60d5c3b390","size":{"x":32,"y":1,"z":32}},{"blockCount":10,"bytes":1027,"file":"chunks/y060-z192-x160.json","offset":{"x":160,"y":60,"z":192},"requirements":{"minecraft:polished_diorite":6,"minecraft:stone_bricks":4},"sha256":"d5d5872c4ccd5b97c8a72a8d1d413118f7d59872b0209ea7f01cfdb17ae0b913","size":{"x":32,"y":1,"z":32}},{"blockCount":74,"bytes":2709,"file":"chunks/y061-z000-x352.json","offset":{"x":352,"y":61,"z":0},"requirements":{"minecraft:glass":3,"minecraft:oak_planks":40,"minecraft:polished_diorite":23,"minecraft:sandstone":8},"sha256":"9667914aaca706f6a185a113eef9886b6f235ee6bec260389349d3f3fa7a18d7","size":{"x":32,"y":1,"z":32}},{"blockCount":108,"bytes":2670,"file":"chunks/y061-z000-x384.json","offset":{"x":384,"y":61,"z":0},"requirements":{"minecraft:glass":22,"minecraft:oak_planks":29,"minecraft:polished_diorite":8,"minecraft:spruce_planks":12,"minecraft:stone_bricks":37},"sha256":"6e6e83104eaad0dde43c24e5363b55c19626f524fa34dbeeec75c0973ac63713","size":{"x":32,"y":1,"z":32}},{"blockCount":8,"bytes":810,"file":"chunks/y061-z032-x384.json","offset":{"x":384,"y":61,"z":32},"requirements":{"minecraft:glass":2,"minecraft:polished_diorite":4,"minecraft:stone_bricks":2},"sha256":"8fb85eda62fc86866dd2728dc9bab157d2f76400c6215c6134560d179bd22060","size":{"x":32,"y":1,"z":32}},{"blockCount":146,"bytes":3607,"file":"chunks/y061-z064-x064.json","offset":{"x":64,"y":61,"z":64},"requirements":{"minecraft:bricks":41,"minecraft:glass":2,"minecraft:oak_planks":1,"minecraft:polished_diorite":74,"minecraft:sandstone":10,"minecraft:stone_bricks":18},"sha256":"7909642e0d60e519dc5633bd16b107c47b4ae9d3e0b5bd8da64db757c6909855","size":{"x":32,"y":1,"z":32}},{"blockCount":163,"bytes":2886,"file":"chunks/y061-z064-x096.json","offset":{"x":96,"y":61,"z":64},"requirements":{"minecraft:bricks":68,"minecraft:glass":4,"minecraft:oak_planks":5,"minecraft:polished_diorite":56,"minecraft:sandstone":15,"minecraft:stone_bricks":15},"sha256":"fd89a22a914f5921bbac2bed61c27409a5d18396332ebd62a17d31397dbdae7b","size":{"x":32,"y":1,"z":32}},{"blockCount":241,"bytes":4693,"file":"chunks/y061-z064-x128.json","offset":{"x":128,"y":61,"z":64},"requirements":{"minecraft:bricks":80,"minecraft:glass":6,"minecraft:oak_planks":4,"minecraft:polished_diorite":101,"minecraft:sandstone":22,"minecraft:stone_bricks":28},"sha256":"355bcb55525239706c11fd78f2e29ddcdb0fec1527dce61d87a1487fa1c1cb9e","size":{"x":32,"y":1,"z":32}},{"blockCount":12,"bytes":1077,"file":"chunks/y061-z064-x160.json","offset":{"x":160,"y":61,"z":64},"requirements":{"minecraft:polished_diorite":12},"sha256":"def193f05325666b82209710d98ef62a65894091e1c230a1a29b9ba2c1d1b066","size":{"x":32,"y":1,"z":32}},{"blockCount":21,"bytes":1017,"file":"chunks/y061-z064-x192.json","offset":{"x":192,"y":61,"z":64},"requirements":{"minecraft:polished_diorite":19,"minecraft:stone_bricks":2},"sha256":"d8c0c331056325c16f365180c06120521c545e8ec235d52943db8f540f43edd3","size":{"x":32,"y":1,"z":32}},{"blockCount":24,"bytes":1075,"file":"chunks/y061-z064-x224.json","offset":{"x":224,"y":61,"z":64},"requirements":{"minecraft:polished_diorite":20,"minecraft:stone_bricks":4},"sha256":"e3bd7b7d9cfebd76b717708008865dff8e5d7773bb109793b314b68d097a339c","size":{"x":32,"y":1,"z":32}},{"blockCount":95,"bytes":2605,"file":"chunks/y061-z096-x000.json","offset":{"x":0,"y":61,"z":96},"requirements":{"minecraft:bricks":14,"minecraft:polished_diorite":61,"minecraft:sandstone":3,"minecraft:stone_bricks":17},"sha256":"430c031eec61f8a99af9e5e9d3a017c3bf23afaa5cdfbddce83134fdbf0347d5","size":{"x":32,"y":1,"z":32}},{"blockCount":145,"bytes":3321,"file":"chunks/y061-z096-x032.json","offset":{"x":32,"y":61,"z":96},"requirements":{"minecraft:bricks":37,"minecraft:glass":6,"minecraft:polished_diorite":74,"minecraft:sandstone":7,"minecraft:stone_bricks":21},"sha256":"181d9571f9c592178fdf2af6e271ebf22a53fd77c2edeb293ec4f7c6265171d2","size":{"x":32,"y":1,"z":32}},{"blockCount":130,"bytes":3255,"file":"chunks/y061-z096-x064.json","offset":{"x":64,"y":61,"z":96},"requirements":{"minecraft:bricks":43,"minecraft:glass":5,"minecraft:oak_planks":2,"minecraft:polished_diorite":52,"minecraft:sandstone":8,"minecraft:stone_bricks":20},"sha256":"0f76f8afdde4cb47684d426fd990f7feec40e5a12d3cbc2e7c8d41c29eed0033","size":{"x":32,"y":1,"z":32}},{"blockCount":22,"bytes":1280,"file":"chunks/y061-z096-x096.json","offset":{"x":96,"y":61,"z":96},"requirements":{"minecraft:bricks":11,"minecraft:glass":7,"minecraft:stone_bricks":4},"sha256":"317ac029aeb9d29624684f8c8ae478b93bf950788508cdc7441aefec95ee500c","size":{"x":32,"y":1,"z":32}},{"blockCount":73,"bytes":2611,"file":"chunks/y061-z096-x128.json","offset":{"x":128,"y":61,"z":96},"requirements":{"minecraft:bricks":33,"minecraft:glass":9,"minecraft:oak_planks":2,"minecraft:polished_diorite":13,"minecraft:sandstone":3,"minecraft:stone_bricks":13},"sha256":"e5bee5aead40b36fc20f5cdea88494c1579027762751262ab992046871f2cdf4","size":{"x":32,"y":1,"z":32}},{"blockCount":150,"bytes":3230,"file":"chunks/y061-z096-x160.json","offset":{"x":160,"y":61,"z":96},"requirements":{"minecraft:bricks":42,"minecraft:glass":7,"minecraft:polished_diorite":69,"minecraft:sandstone":9,"minecraft:stone_bricks":23},"sha256":"b0c3f5f65a809720ec889c84274f16c62ddb666f2af0dce2e0a7557caa9f4605","size":{"x":32,"y":1,"z":32}},{"blockCount":336,"bytes":4877,"file":"chunks/y061-z096-x192.json","offset":{"x":192,"y":61,"z":96},"requirements":{"minecraft:bricks":166,"minecraft:glass":9,"minecraft:oak_planks":2,"minecraft:polished_diorite":54,"minecraft:sandstone":9,"minecraft:spruce_planks":62,"minecraft:stone_bricks":34},"sha256":"244de1341e50ddb4f532b16de18b4f9f1efb1586badd0d2ca358e17c4e7848db","size":{"x":32,"y":1,"z":32}},{"blockCount":292,"bytes":4017,"file":"chunks/y061-z096-x224.json","offset":{"x":224,"y":61,"z":96},"requirements":{"minecraft:bricks":69,"minecraft:glass":1,"minecraft:oak_planks":1,"minecraft:polished_diorite":59,"minecraft:sandstone":5,"minecraft:spruce_planks":145,"minecraft:stone_bricks":12},"sha256":"fe5e6c3433d0f4b956dd8013ebb0aecde6a8d6924663d5b67b9421fb7d67c4b5","size":{"x":32,"y":1,"z":32}},{"blockCount":125,"bytes":3240,"file":"chunks/y061-z128-x000.json","offset":{"x":0,"y":61,"z":128},"requirements":{"minecraft:bricks":37,"minecraft:glass":1,"minecraft:polished_diorite":64,"minecraft:sandstone":5,"minecraft:stone_bricks":18},"sha256":"c0e53f6c24128db89fae819d727d0531cb7ed31767ee8db0bdbfe73696312be1","size":{"x":32,"y":1,"z":32}},{"blockCount":38,"bytes":1816,"file":"chunks/y061-z128-x032.json","offset":{"x":32,"y":61,"z":128},"requirements":{"minecraft:bricks":16,"minecraft:cobbled_deepslate":6,"minecraft:glass":8,"minecraft:stone_bricks":8},"sha256":"1e78f86a6ab2a063405ff44d5c27c11b2695c92a8ee1004d635870bf0c34a9d3","size":{"x":32,"y":1,"z":32}},{"blockCount":15,"bytes":1086,"file":"chunks/y061-z128-x064.json","offset":{"x":64,"y":61,"z":128},"requirements":{"minecraft:bricks":8,"minecraft:glass":4,"minecraft:stone_bricks":3},"sha256":"d4e6aa68d78a94fd0adab1030793fac43f26793539740443cc28d4ca49762e95","size":{"x":32,"y":1,"z":32}},{"blockCount":8,"bytes":848,"file":"chunks/y061-z128-x096.json","offset":{"x":96,"y":61,"z":128},"requirements":{"minecraft:bricks":4,"minecraft:glass":4},"sha256":"71e37a5260576bd910396fd724e0733f190d4ed6aae9c72b062059157d178bd9","size":{"x":32,"y":1,"z":32}},{"blockCount":15,"bytes":1085,"file":"chunks/y061-z128-x128.json","offset":{"x":128,"y":61,"z":128},"requirements":{"minecraft:bricks":8,"minecraft:glass":6,"minecraft:stone_bricks":1},"sha256":"c2efb02e304d18f840705c62f01a73cf748c6929fc4652690dbb6123ad71d8be","size":{"x":32,"y":1,"z":32}},{"blockCount":19,"bytes":1202,"file":"chunks/y061-z128-x160.json","offset":{"x":160,"y":61,"z":128},"requirements":{"minecraft:bricks":9,"minecraft:glass":5,"minecraft:stone_bricks":5},"sha256":"8260d087c06d38126c6231e8dcca540ed6043736edd05165cfd00992a05ee51a","size":{"x":32,"y":1,"z":32}},{"blockCount":50,"bytes":1663,"file":"chunks/y061-z128-x192.json","offset":{"x":192,"y":61,"z":128},"requirements":{"minecraft:bricks":36,"minecraft:glass":5,"minecraft:oak_planks":1,"minecraft:sandstone":2,"minecraft:stone_bricks":6},"sha256":"893d8088ffaf622a4a25ea513b275eeed0d1047a063b31eea97501002c3e3a75","size":{"x":32,"y":1,"z":32}},{"blockCount":172,"bytes":4559,"file":"chunks/y061-z128-x224.json","offset":{"x":224,"y":61,"z":128},"requirements":{"minecraft:bricks":57,"minecraft:glass":1,"minecraft:oak_planks":5,"minecraft:polished_diorite":77,"minecraft:sandstone":17,"minecraft:stone_bricks":15},"sha256":"c7fe2cb77b9416ca01ad6fe0ef14a3f5c4444369e9de473612068489276780f9","size":{"x":32,"y":1,"z":32}},{"blockCount":12,"bytes":839,"file":"chunks/y061-z128-x320.json","offset":{"x":320,"y":61,"z":128},"requirements":{"minecraft:stone_bricks":12},"sha256":"81019469408479f97ac903df5d0b6d44dd5def36a7e398487b24696f76361363","size":{"x":32,"y":1,"z":32}},{"blockCount":65,"bytes":2066,"file":"chunks/y061-z160-x000.json","offset":{"x":0,"y":61,"z":160},"requirements":{"minecraft:bricks":9,"minecraft:polished_diorite":41,"minecraft:sandstone":2,"minecraft:stone_bricks":13},"sha256":"c2175e8e87cce7bbce914a604afc200d6376489096bd750caf73ec4801637846","size":{"x":32,"y":1,"z":32}},{"blockCount":129,"bytes":2861,"file":"chunks/y061-z160-x032.json","offset":{"x":32,"y":61,"z":160},"requirements":{"minecraft:bricks":29,"minecraft:glass":2,"minecraft:polished_diorite":74,"minecraft:sandstone":7,"minecraft:stone_bricks":17},"sha256":"8ecad774ebffff8724d3e9589cdffe08c800645ed6676ecdde76f9c2d930c32b","size":{"x":32,"y":1,"z":32}},{"blockCount":140,"bytes":3332,"file":"chunks/y061-z160-x064.json","offset":{"x":64,"y":61,"z":160},"requirements":{"minecraft:bricks":41,"minecraft:glass":2,"minecraft:oak_planks":2,"minecraft:polished_diorite":65,"minecraft:sandstone":10,"minecraft:stone_bricks":20},"sha256":"f732ff9380e88db98dc0a19f33285f3ca34dc97db5265a7121294ff3e9b3788b","size":{"x":32,"y":1,"z":32}},{"blockCount":18,"bytes":1146,"file":"chunks/y061-z160-x096.json","offset":{"x":96,"y":61,"z":160},"requirements":{"minecraft:bricks":8,"minecraft:glass":5,"minecraft:stone_bricks":5},"sha256":"ae446e78cb20dad40d582f605b3acd066e8d87ea606ef883af6c2f3f1a218fb2","size":{"x":32,"y":1,"z":32}},{"blockCount":86,"bytes":2766,"file":"chunks/y061-z160-x128.json","offset":{"x":128,"y":61,"z":160},"requirements":{"minecraft:bricks":32,"minecraft:glass":5,"minecraft:oak_planks":2,"minecraft:polished_diorite":24,"minecraft:sandstone":7,"minecraft:stone_bricks":16},"sha256":"f5f811da539d1e436f9522be153e62e13c7bb9d87afd388bdbda7c4bb008118d","size":{"x":32,"y":1,"z":32}},{"blockCount":133,"bytes":2733,"file":"chunks/y061-z160-x160.json","offset":{"x":160,"y":61,"z":160},"requirements":{"minecraft:bricks":33,"minecraft:glass":2,"minecraft:polished_diorite":71,"minecraft:sandstone":9,"minecraft:stone_bricks":18},"sha256":"c982bbc14a1dc604849726268fc83222a8a60bae36edb71d259bd0852ef36c68","size":{"x":32,"y":1,"z":32}},{"blockCount":315,"bytes":4612,"file":"chunks/y061-z160-x192.json","offset":{"x":192,"y":61,"z":160},"requirements":{"minecraft:bricks":138,"minecraft:glass":4,"minecraft:oak_planks":1,"minecraft:polished_diorite":73,"minecraft:sandstone":7,"minecraft:spruce_planks":62,"minecraft:stone_bricks":30},"sha256":"29d5143aff597dba88a255bf6a11f4eb8a831ad8f45d9c8133d18125420c113d","size":{"x":32,"y":1,"z":32}},{"blockCount":269,"bytes":3509,"file":"chunks/y061-z160-x224.json","offset":{"x":224,"y":61,"z":160},"requirements":{"minecraft:bricks":57,"minecraft:polished_diorite":53,"minecraft:spruce_planks":145,"minecraft:stone_bricks":14},"sha256":"b7409d98f7c00fa5a3c3f0ea9b1b81e0c573a303a2caba49d60bf2f91937e06a","size":{"x":32,"y":1,"z":32}},{"blockCount":121,"bytes":3089,"file":"chunks/y061-z192-x064.json","offset":{"x":64,"y":61,"z":192},"requirements":{"minecraft:bricks":35,"minecraft:glass":1,"minecraft:oak_planks":1,"minecraft:polished_diorite":61,"minecraft:sandstone":8,"minecraft:stone_bricks":15},"sha256":"a2fe5a9981cf0b5a6c6130a5505185ecae71d2b2cd5d161e036dfaa560531d1a","size":{"x":32,"y":1,"z":32}},{"blockCount":160,"bytes":2774,"file":"chunks/y061-z192-x096.json","offset":{"x":96,"y":61,"z":192},"requirements":{"minecraft:bricks":67,"minecraft:glass":3,"minecraft:oak_planks":5,"minecraft:polished_diorite":56,"minecraft:sandstone":15,"minecraft:stone_bricks":14},"sha256":"17eabf61b214705e2b31b2e2ec119ca1371beec4057585d9289cad525ca81e95","size":{"x":32,"y":1,"z":32}},{"blockCount":215,"bytes":4118,"file":"chunks/y061-z192-x128.json","offset":{"x":128,"y":61,"z":192},"requirements":{"minecraft:bricks":73,"minecraft:glass":4,"minecraft:oak_planks":4,"minecraft:polished_diorite":90,"minecraft:sandstone":20,"minecraft:stone_bricks":24},"sha256":"bb5d167f135f1ad6dddd66ed4160104bb4ad6a205c51d16851dc766a753d8399","size":{"x":32,"y":1,"z":32}},{"blockCount":10,"bytes":1001,"file":"chunks/y061-z192-x160.json","offset":{"x":160,"y":61,"z":192},"requirements":{"minecraft:polished_diorite":10},"sha256":"47be99038cbd2b82bf3fbf12af53a94ef0dd859ec9af4932fbd9d5784da4d5e5","size":{"x":32,"y":1,"z":32}},{"blockCount":71,"bytes":2864,"file":"chunks/y062-z000-x352.json","offset":{"x":352,"y":62,"z":0},"requirements":{"minecraft:glass":3,"minecraft:polished_diorite":20,"minecraft:sandstone":32,"minecraft:stone_bricks":16},"sha256":"768ffe9f810f417409b857ca3512cd64fe413ad405cba7d9df58c43e6109401b","size":{"x":32,"y":1,"z":32}},{"blockCount":77,"bytes":1389,"file":"chunks/y062-z000-x384.json","offset":{"x":384,"y":62,"z":0},"requirements":{"minecraft:glass":2,"minecraft:polished_diorite":8,"minecraft:stone_bricks":67},"sha256":"31297f5387daa8c44967b1a570ebb0bb87af370bbbddba56ca892f8cdfb69775","size":{"x":32,"y":1,"z":32}},{"blockCount":6,"bytes":781,"file":"chunks/y062-z032-x384.json","offset":{"x":384,"y":62,"z":32},"requirements":{"minecraft:glass":2,"minecraft:polished_diorite":4},"sha256":"3d99d1786488bdddc418713190b0378c7e4f81dbadf40db721debb8db4dc6a7a","size":{"x":32,"y":1,"z":32}},{"blockCount":177,"bytes":4081,"file":"chunks/y062-z064-x064.json","offset":{"x":64,"y":62,"z":64},"requirements":{"minecraft:bricks":42,"minecraft:oak_planks":1,"minecraft:polished_diorite":93,"minecraft:sandstone":6,"minecraft:stone_bricks":35},"sha256":"6e87a0d0ec73d543636a965a150980d99ebbd526e0f9fe76a02ec08fb85577f4","size":{"x":32,"y":1,"z":32}},{"blockCount":173,"bytes":3041,"file":"chunks/y062-z064-x096.json","offset":{"x":96,"y":62,"z":64},"requirements":{"minecraft:bricks":70,"minecraft:glass":5,"minecraft:oak_planks":5,"minecraft:polished_diorite":60,"minecraft:sandstone":15,"minecraft:stone_bricks":18},"sha256":"c509fa9e6557dfb1604e00c5fb670f02300b28011e982ea648f9d08725f7c340","size":{"x":32,"y":1,"z":32}},{"blockCount":276,"bytes":5419,"file":"chunks/y062-z064-x128.json","offset":{"x":128,"y":62,"z":64},"requirements":{"minecraft:bricks":81,"minecraft:glass":5,"minecraft:oak_planks":4,"minecraft:polished_diorite":118,"minecraft:sandstone":17,"minecraft:stone_bricks":51},"sha256":"6dbee1c90793fb32858b532e3e90ca8321b71981eee516880beba32e4bce13aa","size":{"x":32,"y":1,"z":32}},{"blockCount":17,"bytes":1077,"file":"chunks/y062-z064-x160.json","offset":{"x":160,"y":62,"z":64},"requirements":{"minecraft:polished_diorite":17},"sha256":"369e47cc1bf89996754668d9758ef48d9dde8f60c45cccb49bbde9f19ba5455d","size":{"x":32,"y":1,"z":32}},{"blockCount":26,"bytes":1132,"file":"chunks/y062-z064-x192.json","offset":{"x":192,"y":62,"z":64},"requirements":{"minecraft:polished_diorite":22,"minecraft:stone_bricks":4},"sha256":"ccdf9f924306c9990b57a8d0e081596d3202eacc2a913792d7573c5d0a89de19","size":{"x":32,"y":1,"z":32}},{"blockCount":29,"bytes":1133,"file":"chunks/y062-z064-x224.json","offset":{"x":224,"y":62,"z":64},"requirements":{"minecraft:polished_diorite":25,"minecraft:stone_bricks":4},"sha256":"59ff869eafb97c2666b87a89d3475390ae4ba8b66d4864846198802cc220fdb8","size":{"x":32,"y":1,"z":32}},{"blockCount":100,"bytes":2756,"file":"chunks/y062-z096-x000.json","offset":{"x":0,"y":62,"z":96},"requirements":{"minecraft:bricks":17,"minecraft:polished_diorite":68,"minecraft:sandstone":1,"minecraft:stone_bricks":14},"sha256":"13a9d572256535a7ef9b9e43da8d7ab51b24aee44d995628dc0608adff95ce3f","size":{"x":32,"y":1,"z":32}},{"blockCount":175,"bytes":3531,"file":"chunks/y062-z096-x032.json","offset":{"x":32,"y":62,"z":96},"requirements":{"minecraft:bricks":37,"minecraft:glass":4,"minecraft:polished_diorite":92,"minecraft:sandstone":3,"minecraft:stone_bricks":39},"sha256":"cdb81c60d6cbe4a4f18b0c324478ae3e66c7e58497a451e57c6c491bcb2ef78b","size":{"x":32,"y":1,"z":32}},{"blockCount":153,"bytes":3497,"file":"chunks/y062-z096-x064.json","offset":{"x":64,"y":62,"z":96},"requirements":{"minecraft:bricks":45,"minecraft:glass":4,"minecraft:polished_diorite":63,"minecraft:sandstone":4,"minecraft:stone_bricks":37},"sha256":"d3fd828a86c1f6817ef67cb01b6ac035d8701bb1cf122970fc6f4dd134f9af4a","size":{"x":32,"y":1,"z":32}},{"blockCount":44,"bytes":1981,"file":"chunks/y062-z096-x096.json","offset":{"x":96,"y":62,"z":96},"requirements":{"minecraft:bricks":11,"minecraft:cobbled_deepslate":3,"minecraft:glass":20,"minecraft:stone_bricks":10},"sha256":"4d842d64c8b8d1272e75fb340b008efff1e531470c9e5d171dfc04f8a8c8ed65","size":{"x":32,"y":1,"z":32}},{"blockCount":93,"bytes":3129,"file":"chunks/y062-z096-x128.json","offset":{"x":128,"y":62,"z":96},"requirements":{"minecraft:bricks":35,"minecraft:cobbled_deepslate":3,"minecraft:glass":16,"minecraft:polished_diorite":14,"minecraft:sandstone":2,"minecraft:stone_bricks":23},"sha256":"9a045972dee7fc73ae56ac356333f7834c032a347458e35888a6bf888fbfd7aa","size":{"x":32,"y":1,"z":32}},{"blockCount":182,"bytes":3666,"file":"chunks/y062-z096-x160.json","offset":{"x":160,"y":62,"z":96},"requirements":{"minecraft:bricks":41,"minecraft:glass":5,"minecraft:polished_diorite":84,"minecraft:sandstone":4,"minecraft:stone_bricks":48},"sha256":"98a5aba1db9022aa92e00b99266e42e67201c53c67a8c418144a1eea3ce158f6","size":{"x":32,"y":1,"z":32}}],"schema":1}
