{"entries":[{"blockCount":386,"bytes":4975,"file":"chunks/y062-z096-x192.json","offset":{"x":192,"y":62,"z":96},"requirements":{"minecraft:bricks":151,"minecraft:glass":8,"minecraft:oak_planks":1,"minecraft:polished_diorite":64,"minecraft:sandstone":3,"minecraft:spruce_planks":121,"minecraft:stone_bricks":38},"sha256":"53108040b118ed98b0d32f3d0d38efe7afc8d47cdaba61ce20622f6da9793c6b","size":{"x":32,"y":1,"z":32}},{"blockCount":445,"bytes":4327,"file":"chunks/y062-z096-x224.json","offset":{"x":224,"y":62,"z":96},"requirements":{"minecraft:bricks":70,"minecraft:glass":1,"minecraft:oak_planks":1,"minecraft:polished_diorite":67,"minecraft:sandstone":5,"minecraft:spruce_planks":278,"minecraft:stone_bricks":23},"sha256":"95c582570258095a6c53a24504a1c3e02797c0718449150a1a677b4d81d89235","size":{"x":32,"y":1,"z":32}},{"blockCount":140,"bytes":3448,"file":"chunks/y062-z128-x000.json","offset":{"x":0,"y":62,"z":128},"requirements":{"minecraft:bricks":42,"minecraft:polished_diorite":75,"minecraft:sandstone":2,"minecraft:stone_bricks":21},"sha256":"816697b60f5057911f9f06a7015fffeef090600700a3e1537290799437de1454","size":{"x":32,"y":1,"z":32}},{"blockCount":42,"bytes":1951,"file":"chunks/y062-z128-x032.json","offset":{"x":32,"y":62,"z":128},"requirements":{"minecraft:bricks":14,"minecraft:cobbled_deepslate":5,"minecraft:glass":6,"minecraft:stone_bricks":17},"sha256":"70cc4a9109bccccd363b7659f1664d0f9d22d6857db4bbad1c11f99e9eb41131","size":{"x":32,"y":1,"z":32}},{"blockCount":38,"bytes":1834,"file":"chunks/y062-z128-x064.json","offset":{"x":64,"y":62,"z":128},"requirements":{"minecraft:bricks":8,"minecraft:cobbled_deepslate":4,"minecraft:glass":20,"minecraft:stone_bricks":6},"sha256":"e6c36e294d1b346e4763b35a5e9815ba23cac5cd21d18b5660f95249100593bd","size":{"x":32,"y":1,"z":32}},{"blockCount":24,"bytes":1410,"file":"chunks/y062-z128-x096.json","offset":{"x":96,"y":62,"z":128},"requirements":{"minecraft:bricks":4,"minecraft:cobbled_deepslate":3,"minecraft:glass":16,"minecraft:stone_bricks":1},"sha256":"6992c12ac42eac3f3d6916417b297439ed5df19276d5e6ae4dc6ca60acefe85c","size":{"x":32,"y":1,"z":32}},{"blockCount":41,"bytes":1887,"file":"chunks/y062-z128-x128.json","offset":{"x":128,"y":62,"z":128},"requirements":{"minecraft:bricks":8,"minecraft:cobbled_deepslate":5,"minecraft:glass":24,"minecraft:stone_bricks":4},"sha256":"643c823fec688c9b5cfba16cc0b3001230bb8220da098118c3f7c5620c045b95","size":{"x":32,"y":1,"z":32}},{"blockCount":41,"bytes":2026,"file":"chunks/y062-z128-x160.json","offset":{"x":160,"y":62,"z":128},"requirements":{"minecraft:bricks":9,"minecraft:cobbled_deepslate":4,"minecraft:glass":23,"minecraft:stone_bricks":5},"sha256":"f7e51daa431088808f9d188654e366e7641cc350b0f5edb80348cac8b9a899d9","size":{"x":32,"y":1,"z":32}},{"blockCount":55,"bytes":1918,"file":"chunks/y062-z128-x192.json","offset":{"x":192,"y":62,"z":128},"requirements":{"minecraft:bricks":35,"minecraft:cobbled_deepslate":2,"minecraft:glass":11,"minecraft:sandstone":1,"minecraft:stone_bricks":6},"sha256":"4c00520c543f8a5d5db192fc433e89d73616cf4885aaa2e163d360fa526c1c54","size":{"x":32,"y":1,"z":32}},{"blockCount":182,"bytes":4730,"file":"chunks/y062-z128-x224.json","offset":{"x":224,"y":62,"z":128},"requirements":{"minecraft:bricks":59,"minecraft:glass":1,"minecraft:oak_planks":5,"minecraft:polished_diorite":81,"minecraft:sandstone":17,"minecraft:stone_bricks":19},"sha256":"dbe9774e8e472f08dc076be98a57f19d14b7e3daf18a0c81cd04bddef4608807","size":{"x":32,"y":1,"z":32}},{"blockCount":12,"bytes":839,"file":"chunks/y062-z128-x320.json","offset":{"x":320,"y":62,"z":128},"requirements":{"minecraft:stone_bricks":12},"sha256":"5eea0ae00ea0467175f68f5d3cfd3b37d90876ee5bb8b2bb52a120d501baec37","size":{"x":32,"y":1,"z":32}},{"blockCount":67,"bytes":2161,"file":"chunks/y062-z160-x000.json","offset":{"x":0,"y":62,"z":160},"requirements":{"minecraft:bricks":11,"minecraft:polished_diorite":44,"minecraft:sandstone":1,"minecraft:stone_bricks":11},"sha256":"44ade1bed93bd16c0d89417de2466c1ee891b5ac06d6b35fc605fe1a1a6cc7f3","size":{"x":32,"y":1,"z":32}},{"blockCount":158,"bytes":3071,"file":"chunks/y062-z160-x032.json","offset":{"x":32,"y":62,"z":160},"requirements":{"minecraft:bricks":27,"minecraft:polished_diorite":92,"minecraft:sandstone":3,"minecraft:stone_bricks":36},"sha256":"29bd3b1fcf08801a562e0161afe1797d38b9df3d59ca669c914b30d4232d457e","size":{"x":32,"y":1,"z":32}},{"blockCount":167,"bytes":3610,"file":"chunks/y062-z160-x064.json","offset":{"x":64,"y":62,"z":160},"requirements":{"minecraft:bricks":43,"minecraft:polished_diorite":80,"minecraft:sandstone":6,"minecraft:stone_bricks":38},"sha256":"0caaf897ef4b0688ef5a5b23fff6618298bfdfe11d65dd5f7c54261934ec8565","size":{"x":32,"y":1,"z":32}},{"blockCount":35,"bytes":1734,"file":"chunks/y062-z160-x096.json","offset":{"x":96,"y":62,"z":160},"requirements":{"minecraft:bricks":8,"minecraft:cobbled_deepslate":2,"minecraft:glass":14,"minecraft:stone_bricks":11},"sha256":"c21bdb928243970601c3d25df7cc195264cc9c1443441e2773d4ca4dd772e981","size":{"x":32,"y":1,"z":32}},{"blockCount":108,"bytes":3383,"file":"chunks/y062-z160-x128.json","offset":{"x":128,"y":62,"z":160},"requirements":{"minecraft:bricks":34,"minecraft:cobbled_deepslate":2,"minecraft:glass":10,"minecraft:polished_diorite":28,"minecraft:sandstone":6,"minecraft:stone_bricks":28},"sha256":"5b07d3f2c072797546524a0c0d1f82b0d2bd78b64bc3bbea6daba1c49896c99a","size":{"x":32,"y":1,"z":32}},{"blockCount":165,"bytes":3188,"file":"chunks/y062-z160-x160.json","offset":{"x":160,"y":62,"z":160},"requirements":{"minecraft:bricks":32,"minecraft:polished_diorite":86,"minecraft:sandstone":4,"minecraft:stone_bricks":43},"sha256":"6162a9d1ce085407f5305fd2f6c4334f8f14938d8de74e2df036e40021f978b3","size":{"x":32,"y":1,"z":32}},{"blockCount":373,"bytes":4768,"file":"chunks/y062-z160-x192.json","offset":{"x":192,"y":62,"z":160},"requirements":{"minecraft:bricks":124,"minecraft:glass":3,"minecraft:oak_planks":1,"minecraft:polished_diorite":86,"minecraft:sandstone":2,"minecraft:spruce_planks":121,"minecraft:stone_bricks":36},"sha256":"ba634c0510c628627bb9910701a1a59efc93c1c9afa346f3de3a653d141318cc","size":{"x":32,"y":1,"z":32}},{"blockCount":417,"bytes":3763,"file":"chunks/y062-z160-x224.json","offset":{"x":224,"y":62,"z":160},"requirements":{"minecraft:bricks":58,"minecraft:polished_diorite":63,"minecraft:spruce_planks":278,"minecraft:stone_bricks":18},"sha256":"f7da1b6534618454211956bb325ecae7d03c6174bb58ef7453e1bfcdbca27326","size":{"x":32,"y":1,"z":32}},{"blockCount":145,"bytes":3412,"file":"chunks/y062-z192-x064.json","offset":{"x":64,"y":62,"z":192},"requirements":{"minecraft:bricks":36,"minecraft:oak_planks":1,"minecraft:polished_diorite":76,"minecraft:sandstone":4,"minecraft:stone_bricks":28},"sha256":"cc6a837d64ad682b587c64827cae3461044049d09bd644ea2be970746e91054b","size":{"x":32,"y":1,"z":32}},{"blockCount":168,"bytes":2853,"file":"chunks/y062-z192-x096.json","offset":{"x":96,"y":62,"z":192},"requirements":{"minecraft:bricks":69,"minecraft:glass":3,"minecraft:oak_planks":5,"minecraft:polished_diorite":60,"minecraft:sandstone":15,"minecraft:stone_bricks":16},"sha256":"be9c3d97abbda4f49528ad2e1c615077ea067f776fcb2e113f20e99be536e647","size":{"x":32,"y":1,"z":32}},{"blockCount":242,"bytes":4597,"file":"chunks/y062-z192-x128.json","offset":{"x":128,"y":62,"z":192},"requirements":{"minecraft:bricks":74,"minecraft:glass":3,"minecraft:oak_planks":4,"minecraft:polished_diorite":104,"minecraft:sandstone":15,"minecraft:stone_bricks":42},"sha256":"65dc9037c68eb745314d9f3b7122a4b7cc6c7520217bc43121e7e2ab9e0b4705","size":{"x":32,"y":1,"z":32}},{"blockCount":14,"bytes":1001,"file":"chunks/y062-z192-x160.json","offset":{"x":160,"y":62,"z":192},"requirements":{"minecraft:polished_diorite":14},"sha256":"55c77e86ee61f4e89b519230dc3cfe32bf403c7f65bcf18b427bc1a23991e58b","size":{"x":32,"y":1,"z":32}},{"blockCount":55,"bytes":2445,"file":"chunks/y063-z000-x352.json","offset":{"x":352,"y":63,"z":0},"requirements":{"minecraft:glass":3,"minecraft:polished_diorite":20,"minecraft:sandstone":8,"minecraft:stone_bricks":24},"sha256":"b384516d0bc9bb91b06ad707614888d13db61c1dcabe8151f4f6be8dea8233d6","size":{"x":32,"y":1,"z":32}},{"blockCount":53,"bytes":1558,"file":"chunks/y063-z000-x384.json","offset":{"x":384,"y":63,"z":0},"requirements":{"minecraft:polished_diorite":6,"minecraft:stone_bricks":47},"sha256":"3c92ba115f08ddb8bb996a4b86ad68e922c3352cbd43926f2ccf7b52a4b548d6","size":{"x":32,"y":1,"z":32}},{"blockCount":2,"bytes":646,"file":"chunks/y063-z032-x384.json","offset":{"x":384,"y":63,"z":32},"requirements":{"minecraft:polished_diorite":2},"sha256":"4482a8a0115268ee1e12c5f9a76cd6ca1c8636539f85a4e03de938d1fba7ad9a","size":{"x":32,"y":1,"z":32}},{"blockCount":177,"bytes":4613,"file":"chunks/y063-z064-x064.json","offset":{"x":64,"y":63,"z":64},"requirements":{"minecraft:bricks":44,"minecraft:oak_planks":1,"minecraft:polished_diorite":74,"minecraft:sandstone":4,"minecraft:stone_bricks":54},"sha256":"8b0fa55fdf9249eda396b5ca4e940015c65c4250617746f705090c0029a1ebf4","size":{"x":32,"y":1,"z":32}},{"blockCount":181,"bytes":3269,"file":"chunks/y063-z064-x096.json","offset":{"x":96,"y":63,"z":64},"requirements":{"minecraft:bricks":70,"minecraft:glass":8,"minecraft:oak_planks":5,"minecraft:polished_diorite":58,"minecraft:sandstone":15,"minecraft:stone_bricks":25},"sha256":"7e731e68f96577a85cc7905d13fbeb768df83fca5ac8da23c375f4e6c60fdc45","size":{"x":32,"y":1,"z":32}},{"blockCount":273,"bytes":5893,"file":"chunks/y063-z064-x128.json","offset":{"x":128,"y":63,"z":64},"requirements":{"minecraft:bricks":82,"minecraft:glass":6,"minecraft:oak_planks":4,"minecraft:polished_diorite":103,"minecraft:sandstone":16,"minecraft:stone_bricks":62},"sha256":"97664f53ad2dd1d5a219afff37b499716396e997a97ab0270a875f5e4364bbc7","size":{"x":32,"y":1,"z":32}},{"blockCount":22,"bytes":1295,"file":"chunks/y063-z064-x160.json","offset":{"x":160,"y":63,"z":64},"requirements":{"minecraft:polished_diorite":10,"minecraft:stone_bricks":12},"sha256":"be3e9d2389c6241ea21e235f695591abb1d62c96a62315f742bf144f7d820970","size":{"x":32,"y":1,"z":32}},{"blockCount":31,"bytes":1209,"file":"chunks/y063-z064-x192.json","offset":{"x":192,"y":63,"z":64},"requirements":{"minecraft:polished_diorite":17,"minecraft:stone_bricks":14},"sha256":"9e97cb85c89aeb5654480cc560e1a63745fb2a690f9616dfce4d362505b9daa7","size":{"x":32,"y":1,"z":32}},{"blockCount":36,"bytes":1286,"file":"chunks/y063-z064-x224.json","offset":{"x":224,"y":63,"z":64},"requirements":{"minecraft:polished_diorite":19,"minecraft:stone_bricks":17},"sha256":"ae3c08823714e3ff284a86d031815f5c13330d78490fa76338fabdba5076aa1d","size":{"x":32,"y":1,"z":32}},{"blockCount":112,"bytes":3017,"file":"chunks/y063-z096-x000.json","offset":{"x":0,"y":63,"z":96},"requirements":{"minecraft:bricks":20,"minecraft:polished_diorite":54,"minecraft:stone_bricks":38},"sha256":"5f3a530f631e1dbc9fb205ff7ec6479ddcbaef021d510fc493ed90018de1e88f","size":{"x":32,"y":1,"z":32}},{"blockCount":177,"bytes":3876,"file":"chunks/y063-z096-x032.json","offset":{"x":32,"y":63,"z":96},"requirements":{"minecraft:bricks":40,"minecraft:glass":4,"minecraft:polished_diorite":78,"minecraft:sandstone":2,"minecraft:stone_bricks":53},"sha256":"817b16e6a5d7885efa72e584ed7a293c957657f13e95242459d89fe95fcefffd","size":{"x":32,"y":1,"z":32}},{"blockCount":151,"bytes":3801,"file":"chunks/y063-z096-x064.json","offset":{"x":64,"y":63,"z":96},"requirements":{"minecraft:bricks":44,"minecraft:glass":4,"minecraft:polished_diorite":51,"minecraft:sandstone":3,"minecraft:stone_bricks":49},"sha256":"51d31d525216aaa4644b3e938a946940b03d9c86e503055381ba1b15a66098a2","size":{"x":32,"y":1,"z":32}},{"blockCount":56,"bytes":2141,"file":"chunks/y063-z096-x096.json","offset":{"x":96,"y":63,"z":96},"requirements":{"minecraft:bricks":11,"minecraft:glass":35,"minecraft:stone_bricks":10},"sha256":"ad0e73c39d79ed00cbbcca6f24ec927bba4c0cb420d7f2a0e233c51ff44cfd1e","size":{"x":32,"y":1,"z":32}},{"blockCount":93,"bytes":3135,"file":"chunks/y063-z096-x128.json","offset":{"x":128,"y":63,"z":96},"requirements":{"minecraft:bricks":33,"minecraft:glass":21,"minecraft:polished_diorite":13,"minecraft:sandstone":2,"minecraft:stone_bricks":24},"sha256":"bafecdd823fb4157761ee260412d501a656094b63ea6bab7c13d4fa2e7626af5","size":{"x":32,"y":1,"z":32}},{"blockCount":182,"bytes":3969,"file":"chunks/y063-z096-x160.json","offset":{"x":160,"y":63,"z":96},"requirements":{"minecraft:bricks":43,"minecraft:glass":5,"minecraft:polished_diorite":68,"minecraft:sandstone":2,"minecraft:stone_bricks":64},"sha256":"cf99f8b3e3f7709c7bf3199548ad2ce6703ba555976c3716172dfc2f328ebe45","size":{"x":32,"y":1,"z":32}},{"blockCount":269,"bytes":5219,"file":"chunks/y063-z096-x192.json","offset":{"x":192,"y":63,"z":96},"requirements":{"minecraft:bricks":152,"minecraft:glass":7,"minecraft:oak_planks":4,"minecraft:polished_diorite":49,"minecraft:sandstone":2,"minecraft:stone_bricks":55},"sha256":"49ba582a5ebeaff24e27af48e724b7def928d7934c118a3c92108ec66eab471c","size":{"x":32,"y":1,"z":32}},{"blockCount":203,"bytes":5041,"file":"chunks/y063-z096-x224.json","offset":{"x":224,"y":63,"z":96},"requirements":{"minecraft:bricks":93,"minecraft:glass":1,"minecraft:oak_planks":7,"minecraft:polished_diorite":55,"minecraft:sandstone":5,"minecraft:stone_bricks":42},"sha256":"379b0dbb087d317fdf15a83a238dfd16720a9580f097dae599fd9e7e44c801d1","size":{"x":32,"y":1,"z":32}},{"blockCount":138,"bytes":3733,"file":"chunks/y063-z128-x000.json","offset":{"x":0,"y":63,"z":128},"requirements":{"minecraft:bricks":42,"minecraft:polished_diorite":61,"minecraft:sandstone":1,"minecraft:stone_bricks":34},"sha256":"a1e22c401477247152992659c320366b0945a257b55bdcbe9be13e18801b616a","size":{"x":32,"y":1,"z":32}},{"blockCount":38,"bytes":1911,"file":"chunks/y063-z128-x032.json","offset":{"x":32,"y":63,"z":128},"requirements":{"minecraft:bricks":14,"minecraft:cobbled_deepslate":3,"minecraft:glass":6,"minecraft:stone_bricks":15},"sha256":"45f67f821f0790532fe37c1facef78b4152d0c274e09a790c43e4efa49caa806","size":{"x":32,"y":1,"z":32}},{"blockCount":49,"bytes":1821,"file":"chunks/y063-z128-x064.json","offset":{"x":64,"y":63,"z":128},"requirements":{"minecraft:bricks":8,"minecraft:glass":36,"minecraft:stone_bricks":5},"sha256":"bca1f305e1c07b68e399dbd6e15376febc683c5209d2f2ff6d52e8cb1701615c","size":{"x":32,"y":1,"z":32}},{"blockCount":35,"bytes":1435,"file":"chunks/y063-z128-x096.json","offset":{"x":96,"y":63,"z":128},"requirements":{"minecraft:bricks":4,"minecraft:glass":30,"minecraft:stone_bricks":1},"sha256":"f2053bf1ba9de92010b20143b3f97a90be832234f17e12aa3e6d1e1b40dd412f","size":{"x":32,"y":1,"z":32}},{"blockCount":53,"bytes":1851,"file":"chunks/y063-z128-x128.json","offset":{"x":128,"y":63,"z":128},"requirements":{"minecraft:bricks":8,"minecraft:glass":42,"minecraft:stone_bricks":3},"sha256":"10e873d1f044a5b357b40ad7fcbb9cf79a4253d81ba91724e06f366f2a3a1bd6","size":{"x":32,"y":1,"z":32}},{"blockCount":57,"bytes":2147,"file":"chunks/y063-z128-x160.json","offset":{"x":160,"y":63,"z":128},"requirements":{"minecraft:bricks":9,"minecraft:glass":43,"minecraft:stone_bricks":5},"sha256":"6b70fb9c43fd5f7a21bd472ce9ccae346517d9729e1e660bda8abfc635afa6f2","size":{"x":32,"y":1,"z":32}},{"blockCount":57,"bytes":1848,"file":"chunks/y063-z128-x192.json","offset":{"x":192,"y":63,"z":128},"requirements":{"minecraft:bricks":35,"minecraft:glass":15,"minecraft:sandstone":1,"minecraft:stone_bricks":6},"sha256":"b6607088cb0446848505596653434429410600d8ad61b2d2eaf2434aee1dba63","size":{"x":32,"y":1,"z":32}},{"blockCount":183,"bytes":4806,"file":"chunks/y063-z128-x224.json","offset":{"x":224,"y":63,"z":128},"requirements":{"minecraft:bricks":59,"minecraft:glass":1,"minecraft:oak_planks":5,"minecraft:polished_diorite":74,"minecraft:sandstone":17,"minecraft:stone_bricks":27},"sha256":"69ad56226cbeed50ac9ba4a0bff0e4a2e8842fcc85f9e4f5e89a5e345b30782d","size":{"x":32,"y":1,"z":32}},{"blockCount":6,"bytes":836,"file":"chunks/y063-z128-x320.json","offset":{"x":320,"y":63,"z":128},"requirements":{"minecraft:cobbled_deepslate":4,"minecraft:polished_diorite":2},"sha256":"a62b7db1653c923dcedfa5584cf9386ffd99b6e48863f0b2c466f0a1a1e82827","size":{"x":32,"y":1,"z":32}},{"blockCount":76,"bytes":2289,"file":"chunks/y063-z160-x000.json","offset":{"x":0,"y":63,"z":160},"requirements":{"minecraft:bricks":13,"minecraft:polished_diorite":36,"minecraft:stone_bricks":27},"sha256":"b3fae32f07d2b2e2b38a61e04473df2421904baeb61ecff63f4c585ac5d0bf1a","size":{"x":32,"y":1,"z":32}},{"blockCount":162,"bytes":3359,"file":"chunks/y063-z160-x032.json","offset":{"x":32,"y":63,"z":160},"requirements":{"minecraft:bricks":32,"minecraft:polished_diorite":78,"minecraft:sandstone":2,"minecraft:stone_bricks":50},"sha256":"176c3d828d358e8b619ed93c5b268add0e9e5ea747d0d8eaebb41930ca4b231b","size":{"x":32,"y":1,"z":32}},{"blockCount":167,"bytes":4009,"file":"chunks/y063-z160-x064.json","offset":{"x":64,"y":63,"z":160},"requirements":{"minecraft:bricks":43,"minecraft:polished_diorite":65,"minecraft:sandstone":4,"minecraft:stone_bricks":55},"sha256":"e285cfe932a550aaf3c9f45a6d358d8861c45d63be83f73defd822243c8ea63a","size":{"x":32,"y":1,"z":32}},{"blockCount":45,"bytes":1854,"file":"chunks/y063-z160-x096.json","offset":{"x":96,"y":63,"z":160},"requirements":{"minecraft:bricks":8,"minecraft:glass":26,"minecraft:stone_bricks":11},"sha256":"c4a5a64486cd752404788086fea6967a7ee66301e839a7b7eade7e2fc50d8361","size":{"x":32,"y":1,"z":32}},{"blockCount":107,"bytes":3408,"file":"chunks/y063-z160-x128.json","offset":{"x":128,"y":63,"z":160},"requirements":{"minecraft:bricks":33,"minecraft:glass":14,"minecraft:polished_diorite":25,"minecraft:sandstone":3,"minecraft:stone_bricks":32},"sha256":"f9f380dd7f4cb2e39d11ee1ce49fc83c743b8047e9c5e0cc8872d1a0410d1a4f","size":{"x":32,"y":1,"z":32}},{"blockCount":167,"bytes":3453,"file":"chunks/y063-z160-x160.json","offset":{"x":160,"y":63,"z":160},"requirements":{"minecraft:bricks":34,"minecraft:polished_diorite":70,"minecraft:sandstone":2,"minecraft:stone_bricks":61},"sha256":"8e5ff54de5019810ae74bfd5b74b341a5e30ea1d299f7583828a0b1967edaaf2","size":{"x":32,"y":1,"z":32}},{"blockCount":261,"bytes":5089,"file":"chunks/y063-z160-x192.json","offset":{"x":192,"y":63,"z":160},"requirements":{"minecraft:bricks":125,"minecraft:glass":2,"minecraft:oak_planks":4,"minecraft:polished_diorite":66,"minecraft:sandstone":1,"minecraft:stone_bricks":63},"sha256":"d9c831b5ddb16702506ae5923b24a80eb1c64da0cdb25e326875f175b506762e","size":{"x":32,"y":1,"z":32}},{"blockCount":187,"bytes":4738,"file":"chunks/y063-z160-x224.json","offset":{"x":224,"y":63,"z":160},"requirements":{"minecraft:bricks":82,"minecraft:oak_planks":6,"minecraft:polished_diorite":49,"minecraft:spruce_planks":6,"minecraft:stone_bricks":44},"sha256":"63d141d32c1796728194c8399e2737b6d90dcd5257e169961edae62aa75c9f0e","size":{"x":32,"y":1,"z":32}},{"blockCount":144,"bytes":3830,"file":"chunks/y063-z192-x064.json","offset":{"x":64,"y":63,"z":192},"requirements":{"minecraft:bricks":37,"minecraft:oak_planks":1,"minecraft:polished_diorite":60,"minecraft:sandstone":3,"minecraft:stone_bricks":43},"sha256":"709e7f9bc2408d97527b0ceaac022ef679a48c6c4d4fd50bcda27047b9fbec07","size":{"x":32,"y":1,"z":32}},{"blockCount":174,"bytes":3080,"file":"chunks/y063-z192-x096.json","offset":{"x":96,"y":63,"z":192},"requirements":{"minecraft:bricks":69,"minecraft:glass":3,"minecraft:oak_planks":5,"minecraft:polished_diorite":58,"minecraft:sandstone":16,"minecraft:stone_bricks":23},"sha256":"09edfa1b5d25455199b14577d14e939601a488838c2b710820bc563e2c7f696e","size":{"x":32,"y":1,"z":32}},{"blockCount":241,"bytes":5031,"file":"chunks/y063-z192-x128.json","offset":{"x":128,"y":63,"z":192},"requirements":{"minecraft:bricks":74,"minecraft:glass":3,"minecraft:oak_planks":4,"minecraft:polished_diorite":91,"minecraft:sandstone":18,"minecraft:stone_bricks":51},"sha256":"8e051f7dd0af3ce89d4d2fd4a6406bd1e5a049cda06a62c851930ead9986dff0","size":{"x":32,"y":1,"z":32}},{"blockCount":18,"bytes":1180,"file":"chunks/y063-z192-x160.json","offset":{"x":160,"y":63,"z":192},"requirements":{"minecraft:polished_diorite":8,"minecraft:stone_bricks":10},"sha256":"4962b986320932bcc72b152c5e2509833a70667e6176ec935f1374d3e458b7d6","size":{"x":32,"y":1,"z":32}},{"blockCount":32,"bytes":1649,"file":"chunks/y064-z000-x352.json","offset":{"x":352,"y":64,"z":0},"requirements":{"minecraft:glass":4,"minecraft:polished_diorite":20,"minecraft:sandstone":8},"sha256":"f130b238e68131c5b464db78c6d928e5cec1a8fc5cf1ec93deaad18e70a9ac80","size":{"x":32,"y":1,"z":32}},{"blockCount":32,"bytes":1098,"file":"chunks/y064-z000-x384.json","offset":{"x":384,"y":64,"z":0},"requirements":{"minecraft:polished_diorite":4,"minecraft:stone_bricks":28},"sha256":"5df7970f512884f0594f3cfff08b726f1ab7474418697cc7dde6447d6ae18aeb","size":{"x":32,"y":1,"z":32}},{"blockCount":184,"bytes":4233,"file":"chunks/y064-z064-x064.json","offset":{"x":64,"y":64,"z":64},"requirements":{"minecraft:bricks":44,"minecraft:oak_planks":1,"minecraft:polished_diorite":89,"minecraft:sandstone":4,"minecraft:stone_bricks":46},"sha256":"5e54039b78a9c8536400042f5e7f6fde0f1772334553bd21028cfb4feef574f0","size":{"x":32,"y":1,"z":32}},{"blockCount":192,"bytes":3722,"file":"chunks/y064-z064-x096.json","offset":{"x":96,"y":64,"z":64},"requirements":{"minecraft:bricks":73,"minecraft:cobbled_deepslate":1,"minecraft:glass":8,"minecraft:oak_planks":5,"minecraft:polished_diorite":65,"minecraft:sandstone":18,"minecraft:stone_bricks":22},"sha256":"9f101d5ba04e18ddbbc198898022e5fc26bd29193f75bd5ab1d558a4be843997","size":{"x":32,"y":1,"z":32}},{"blockCount":289,"bytes":5961,"file":"chunks/y064-z064-x128.json","offset":{"x":128,"y":64,"z":64},"requirements":{"minecraft:bricks":85,"minecraft:cobbled_deepslate":1,"minecraft:glass":6,"minecraft:oak_planks":4,"minecraft:polished_diorite":114,"minecraft:sandstone":19,"minecraft:stone_bricks":60},"sha256":"4f32435a39465bb772e02f17c1fc6f921d1f33ca06ae9618a46380e80d5f437b","size":{"x":32,"y":1,"z":32}},{"blockCount":22,"bytes":1199,"file":"chunks/y064-z064-x160.json","offset":{"x":160,"y":64,"z":64},"requirements":{"minecraft:polished_diorite":17,"minecraft:stone_bricks":5},"sha256":"7f9f25136ef0419ea9f437c5124c651852090202e89280014f0250ff554500f7","size":{"x":32,"y":1,"z":32}},{"blockCount":32,"bytes":1113,"file":"chunks/y064-z064-x192.json","offset":{"x":192,"y":64,"z":64},"requirements":{"minecraft:polished_diorite":24,"minecraft:stone_bricks":8},"sha256":"0c977187651c32a3d0e159b3bd3cbcce76e4c35ae545bb1cb8294e96dce41ccb","size":{"x":32,"y":1,"z":32}},{"blockCount":37,"bytes":1171,"file":"chunks/y064-z064-x224.json","offset":{"x":224,"y":64,"z":64},"requirements":{"minecraft:polished_diorite":29,"minecraft:stone_bricks":8},"sha256":"08ec99269c82e5e8a46802697304e52abad9c9af53c7eff7fb1b6e3dc501b41c","size":{"x":32,"y":1,"z":32}},{"blockCount":107,"bytes":2902,"file":"chunks/y064-z096-x000.json","offset":{"x":0,"y":64,"z":96},"requirements":{"minecraft:bricks":20,"minecraft:polished_diorite":63,"minecraft:stone_bricks":24},"sha256":"b9e747639b1da179ffe636a30abbceb02187106a478fb0a111c60c09a4a86cf8","size":{"x":32,"y":1,"z":32}},{"blockCount":194,"bytes":4273,"file":"chunks/y064-z096-x032.json","offset":{"x":32,"y":64,"z":96},"requirements":{"minecraft:bricks":44,"minecraft:glass":4,"minecraft:polished_diorite":95,"minecraft:sandstone":1,"minecraft:stone_bricks":50},"sha256":"f21bac34eb71780ad0b17c0f840d9ced3fab8cbc078b0bf549c01f38e3eca151","size":{"x":32,"y":1,"z":32}},{"blockCount":176,"bytes":4254,"file":"chunks/y064-z096-x064.json","offset":{"x":64,"y":64,"z":96},"requirements":{"minecraft:bricks":50,"minecraft:glass":4,"minecraft:polished_diorite":57,"minecraft:sandstone":3,"minecraft:stone_bricks":62},"sha256":"d6a014163358ba41f1dda48847692872edce022368cc0fbf36d6cff2ab8152fe","size":{"x":32,"y":1,"z":32}},{"blockCount":69,"bytes":2538,"file":"chunks/y064-z096-x096.json","offset":{"x":96,"y":64,"z":96},"requirements":{"minecraft:bricks":13,"minecraft:cobbled_deepslate":17,"minecraft:glass":21,"minecraft:stone_bricks":18},"sha256":"d37f1a394afa683f7ce80eaa2da68867a15683973def2c2c8df9235e7394281b","size":{"x":32,"y":1,"z":32}},{"blockCount":113,"bytes":3627,"file":"chunks/y064-z096-x128.json","offset":{"x":128,"y":64,"z":96},"requirements":{"minecraft:bricks":36,"minecraft:cobbled_deepslate":11,"minecraft:glass":13,"minecraft:polished_diorite":13,"minecraft:sandstone":2,"minecraft:stone_bricks":38},"sha256":"cdda76678ad981691e9098ddc64fb50d779ba4aa0d074c01d4a609b3cbf961da","size":{"x":32,"y":1,"z":32}},{"blockCount":214,"bytes":4557,"file":"chunks/y064-z096-x160.json","offset":{"x":160,"y":64,"z":96},"requirements":{"minecraft:bricks":54,"minecraft:glass":5,"minecraft:polished_diorite":79,"minecraft:sandstone":2,"minecraft:stone_bricks":74},"sha256":"fab2f4aad773c3167f058f3175dd80982590b21dae1614fbe292fb3d7e1d9a90","size":{"x":32,"y":1,"z":32}},{"blockCount":289,"bytes":5371,"file":"chunks/y064-z096-x192.json","offset":{"x":192,"y":64,"z":96},"requirements":{"minecraft:bricks":159,"minecraft:glass":5,"minecraft:oak_planks":4,"minecraft:polished_diorite":59,"minecraft:sandstone":2,"minecraft:stone_bricks":60},"sha256":"a6fbb234f58f87855a57a4f05a22a0ce97b94600c256d032bfa905162a517e14","size":{"x":32,"y":1,"z":32}},{"blockCount":202,"bytes":4794,"file":"chunks/y064-z096-x224.json","offset":{"x":224,"y":64,"z":96},"requirements":{"minecraft:bricks":90,"minecraft:glass":2,"minecraft:oak_planks":7,"minecraft:polished_diorite":73,"minecraft:sandstone":8,"minecraft:stone_bricks":22},"sha256":"4eefa86f7aebce1d54e0c35ba695e892400fe880c70f992bd6e3b1934839de0b","size":{"x":32,"y":1,"z":32}},{"blockCount":147,"bytes":3671,"file":"chunks/y064-z128-x000.json","offset":{"x":0,"y":64,"z":128},"requirements":{"minecraft:bricks":44,"minecraft:polished_diorite":70,"minecraft:stone_bricks":33},"sha256":"419be1c5438f3e906dca1eb26d5dd658e4992b85b9f04536e9a349d70a958e54","size":{"x":32,"y":1,"z":32}},{"blockCount":58,"bytes":2170,"file":"chunks/y064-z128-x032.json","offset":{"x":32,"y":64,"z":128},"requirements":{"minecraft:bricks":18,"minecraft:cobbled_deepslate":1,"minecraft:glass":6,"minecraft:polished_diorite":1,"minecraft:stone_bricks":32},"sha256":"02ef0fad2c77da4802a824268b8386c9c0e0ec7b5ee0b844c08cf6bd1bc69a10","size":{"x":32,"y":1,"z":32}},{"blockCount":62,"bytes":2177,"file":"chunks/y064-z128-x064.json","offset":{"x":64,"y":64,"z":128},"requirements":{"minecraft:bricks":12,"minecraft:cobbled_deepslate":20,"minecraft:glass":20,"minecraft:stone_bricks":10},"sha256":"f8995b4ec13a1d1a511f57ea11e39892f3222b5ff6cde1836aaecde20e53a54c","size":{"x":32,"y":1,"z":32}},{"blockCount":38,"bytes":1601,"file":"chunks/y064-z128-x096.json","offset":{"x":96,"y":64,"z":128},"requirements":{"minecraft:bricks":4,"minecraft:cobbled_deepslate":16,"minecraft:glass":17,"minecraft:stone_bricks":1},"sha256":"02709f179690b020b2329fe84c6d41add7e11fa8e10a7f290a809ee946f43d37","size":{"x":32,"y":1,"z":32}},{"blockCount":61,"bytes":2131,"file":"chunks/y064-z128-x128.json","offset":{"x":128,"y":64,"z":128},"requirements":{"minecraft:bricks":9,"minecraft:cobbled_deepslate":24,"minecraft:glass":23,"minecraft:stone_bricks":5},"sha256":"ad6c4c1bcb7219fdaf62cba0e6f694d5b35b83d17a681aa7bcbc55424916ab28","size":{"x":32,"y":1,"z":32}},{"blockCount":71,"bytes":2522,"file":"chunks/y064-z128-x160.json","offset":{"x":160,"y":64,"z":128},"requirements":{"minecraft:bricks":14,"minecraft:cobbled_deepslate":22,"minecraft:glass":25,"minecraft:stone_bricks":10},"sha256":"421acfbb9f76bb589622058a555ec9f3b382d73415c85de548ed266e45df16d9","size":{"x":32,"y":1,"z":32}},{"blockCount":63,"bytes":2025,"file":"chunks/y064-z128-x192.json","offset":{"x":192,"y":64,"z":128},"requirements":{"minecraft:bricks":37,"minecraft:cobbled_deepslate":8,"minecraft:glass":9,"minecraft:stone_bricks":9},"sha256":"f29e9fea10bed365f1b58f3f1ef55574161009de7aa23b0827d4a0d61bd42396","size":{"x":32,"y":1,"z":32}},{"blockCount":180,"bytes":4654,"file":"chunks/y064-z128-x224.json","offset":{"x":224,"y":64,"z":128},"requirements":{"minecraft:bricks":57,"minecraft:glass":2,"minecraft:oak_planks":5,"minecraft:polished_diorite":80,"minecraft:sandstone":20,"minecraft:stone_bricks":16},"sha256":"0b4fd1e3cbb41bf7df44ba353e2d4fa2545398531c6470b2c158bde8f7942c37","size":{"x":32,"y":1,"z":32}},{"blockCount":9,"bytes":875,"file":"chunks/y064-z128-x320.json","offset":{"x":320,"y":64,"z":128},"requirements":{"minecraft:cobbled_deepslate":4,"minecraft:glass":1,"minecraft:polished_diorite":4},"sha256":"569c1d258755e1a55d8c43295802e8b66ff808133f5a73706aa2c06b48f0e0e1","size":{"x":32,"y":1,"z":32}},{"blockCount":72,"bytes":2155,"file":"chunks/y064-z160-x000.json","offset":{"x":0,"y":64,"z":160},"requirements":{"minecraft:bricks":13,"minecraft:polished_diorite":43,"minecraft:stone_bricks":16},"sha256":"94313711d62c2c845369e70eb970fdf45849b26a2c666897d4947da7fdc5dcc5","size":{"x":32,"y":1,"z":32}},{"blockCount":174,"bytes":3605,"file":"chunks/y064-z160-x032.json","offset":{"x":32,"y":64,"z":160},"requirements":{"minecraft:bricks":34,"minecraft:polished_diorite":94,"minecraft:sandstone":1,"minecraft:stone_bricks":45},"sha256":"780ecc3b398715d6bf1075b24cc02ecd5733e85c261a76d0a4027acfdf1c5d46","size":{"x":32,"y":1,"z":32}},{"blockCount":185,"bytes":4201,"file":"chunks/y064-z160-x064.json","offset":{"x":64,"y":64,"z":160},"requirements":{"minecraft:bricks":46,"minecraft:polished_diorite":73,"minecraft:sandstone":4,"minecraft:stone_bricks":62},"sha256":"e144b1f9921065f435f5a3652903398c25e7e5032c4efe5185a4aa013b81ad3f","size":{"x":32,"y":1,"z":32}},{"blockCount":60,"bytes":2310,"file":"chunks/y064-z160-x096.json","offset":{"x":96,"y":64,"z":160},"requirements":{"minecraft:bricks":11,"minecraft:cobbled_deepslate":12,"minecraft:glass":16,"minecraft:stone_bricks":21},"sha256":"3c7337828a6670f988e1ef9bc88cc07c44d0d2f7a09681e32f09a009f3727522","size":{"x":32,"y":1,"z":32}},{"blockCount":128,"bytes":3860,"file":"chunks/y064-z160-x128.json","offset":{"x":128,"y":64,"z":160},"requirements":{"minecraft:bricks":37,"minecraft:cobbled_deepslate":8,"minecraft:glass":8,"minecraft:polished_diorite":26,"minecraft:sandstone":3,"minecraft:stone_bricks":46},"sha256":"c24590bf21b3fc5b2fb800d94a1b300a1452b54576a9fe8d5189816eb878c446","size":{"x":32,"y":1,"z":32}},{"blockCount":189,"bytes":3777,"file":"chunks/y064-z160-x160.json","offset":{"x":160,"y":64,"z":160},"requirements":{"minecraft:bricks":40,"minecraft:polished_diorite":82,"minecraft:sandstone":2,"minecraft:stone_bricks":65},"sha256":"7109f073089065df78583247b0b4ea5d857c16665597aaf59c047da471de96cb","size":{"x":32,"y":1,"z":32}},{"blockCount":278,"bytes":5030,"file":"chunks/y064-z160-x192.json","offset":{"x":192,"y":64,"z":160},"requirements":{"minecraft:bricks":129,"minecraft:oak_planks":4,"minecraft:polished_diorite":83,"minecraft:sandstone":2,"minecraft:stone_bricks":60},"sha256":"3ab3e5e9561966b31161f6c444d7f602139ef99c085774578fe339bdebbc90b0","size":{"x":32,"y":1,"z":32}},{"blockCount":188,"bytes":4435,"file":"chunks/y064-z160-x224.json","offset":{"x":224,"y":64,"z":160},"requirements":{"minecraft:bricks":81,"minecraft:oak_planks":6,"minecraft:polished_diorite":72,"minecraft:spruce_planks":4,"minecraft:stone_bricks":25},"sha256":"bbac5fff6dc4ffed28b029071ac4bcd2caf51af8b100b1fe0ab6bf99b6234f2c","size":{"x":32,"y":1,"z":32}},{"blockCount":150,"bytes":3545,"file":"chunks/y064-z192-x064.json","offset":{"x":64,"y":64,"z":192},"requirements":{"minecraft:bricks":37,"minecraft:oak_planks":1,"minecraft:polished_diorite":73,"minecraft:sandstone":3,"minecraft:stone_bricks":36},"sha256":"f473c6b197ad639b45c9e334910b548f192f95d3adb89ad9507b8dd37b9c90be","size":{"x":32,"y":1,"z":32}},{"blockCount":180,"bytes":3329,"file":"chunks/y064-z192-x096.json","offset":{"x":96,"y":64,"z":192},"requirements":{"minecraft:bricks":70,"minecraft:glass":4,"minecraft:oak_planks":5,"minecraft:polished_diorite":65,"minecraft:sandstone":18,"minecraft:stone_bricks":18},"sha256":"960677e5653dde27908741ce8e4f40a5a2e736f4ffeda9169a7c77adf2d53a72","size":{"x":32,"y":1,"z":32}},{"blockCount":249,"bytes":4994,"file":"chunks/y064-z192-x128.json","offset":{"x":128,"y":64,"z":192},"requirements":{"minecraft:bricks":75,"minecraft:glass":4,"minecraft:oak_planks":4,"minecraft:polished_diorite":101,"minecraft:sandstone":18,"minecraft:stone_bricks":47},"sha256":"333d4407809903ee7b660006656377319a378b55b364c54200b9a6daa382a30c","size":{"x":32,"y":1,"z":32}},{"blockCount":18,"bytes":1104,"file":"chunks/y064-z192-x160.json","offset":{"x":160,"y":64,"z":192},"requirements":{"minecraft:polished_diorite":14,"minecraft:stone_bricks":4},"sha256":"adf011a7922f309ef735ee5cba637d69f1c85d1c00eec4c19986716eb3308f5f","size":{"x":32,"y":1,"z":32}},{"blockCount":36,"bytes":1649,"file":"chunks/y065-z000-x352.json","offset":{"x":352,"y":65,"z":0},"requirements":{"minecraft:glass":8,"minecraft:polished_diorite":20,"minecraft:sandstone":8},"sha256":"4987f573f9e1e0a9703bb637f1fef0394d202655b1391752a5f1043c0c83827a","size":{"x":32,"y":1,"z":32}},{"blockCount":24,"bytes":1022,"file":"chunks/y065-z000-x384.json","offset":{"x":384,"y":65,"z":0},"requirements":{"minecraft:polished_diorite":4,"minecraft:stone_bricks":20},"sha256":"6b0496d68e182c0c09e43f2a24cebff0cfafee1cac422b0d6092701d7766b761","size":{"x":32,"y":1,"z":32}},{"blockCount":176,"bytes":4404,"file":"chunks/y065-z064-x064.json","offset":{"x":64,"y":65,"z":64},"requirements":{"minecraft:bricks":46,"minecraft:oak_planks":1,"minecraft:polished_diorite":62,"minecraft:sandstone":2,"minecraft:stone_bricks":65},"sha256":"cce6d64e6cbf6986c2a9d10846f959969075b0ff4ca332d12243f79554737459","size":{"x":32,"y":1,"z":32}},{"blockCount":188,"bytes":3633,"file":"chunks/y065-z064-x096.json","offset":{"x":96,"y":65,"z":64},"requirements":{"minecraft:bricks":71,"minecraft:glass":7,"minecraft:oak_planks":5,"minecraft:polished_diorite":60,"minecraft:sandstone":17,"minecraft:stone_bricks":28},"sha256":"f2d45936574d34099519177d3e96eacbb411b8b09dd63c30fb182023b2d39a0a","size":{"x":32,"y":1,"z":32}},{"blockCount":275,"bytes":6004,"file":"chunks/y065-z064-x128.json","offset":{"x":128,"y":65,"z":64},"requirements":{"minecraft:bricks":85,"minecraft:glass":7,"minecraft:oak_planks":4,"minecraft:polished_diorite":92,"minecraft:sandstone":15,"minecraft:stone_bricks":72},"sha256":"bb7b9d45008a2a129629d2da7ad1094ea35b34f28b2d359f9bb2ede5d2ec0fed","size":{"x":32,"y":1,"z":32}},{"blockCount":24,"bytes":1237,"file":"chunks/y065-z064-x160.json","offset":{"x":160,"y":65,"z":64},"requirements":{"minecraft:polished_diorite":7,"minecraft:stone_bricks":17},"sha256":"7c599697a76010cfd9e4ceb88861892f9ae6564a0fcfb756eaf9561347b79c49","size":{"x":32,"y":1,"z":32}},{"blockCount":31,"bytes":1133,"file":"chunks/y065-z064-x192.json","offset":{"x":192,"y":65,"z":64},"requirements":{"minecraft:polished_diorite":18,"minecraft:stone_bricks":13},"sha256":"670b825ecd6aedbd1336ab192e96584c815eda875dadfb0a4925c99392679cdb","size":{"x":32,"y":1,"z":32}},{"blockCount":37,"bytes":1153,"file":"chunks/y065-z064-x224.json","offset":{"x":224,"y":65,"z":64},"requirements":{"minecraft:polished_diorite":21,"minecraft:stone_bricks":16},"sha256":"837bc82643eafa2d5d1db4db0ee56fc851a6e052e5036083b7a80f5819ed88a9","size":{"x":32,"y":1,"z":32}},{"blockCount":110,"bytes":2997,"file":"chunks/y065-z096-x000.json","offset":{"x":0,"y":65,"z":96},"requirements":{"minecraft:bricks":21,"minecraft:polished_diorite":43,"minecraft:stone_bricks":46},"sha256":"e0c91b49cb1e87afd1259cdcb744896017f24ccad2f9fe5bda797945c26e3d60","size":{"x":32,"y":1,"z":32}},{"blockCount":180,"bytes":4213,"file":"chunks/y065-z096-x032.json","offset":{"x":32,"y":65,"z":96},"requirements":{"minecraft:bricks":45,"minecraft:glass":4,"minecraft:polished_diorite":72,"minecraft:stone_bricks":59},"sha256":"f6bddb630ea4841b5ebd3984ae843616f8be835898e53f6bc61e955d06aa05af","size":{"x":32,"y":1,"z":32}},{"blockCount":162,"bytes":4135,"file":"chunks/y065-z096-x064.json","offset":{"x":64,"y":65,"z":96},"requirements":{"minecraft:bricks":53,"minecraft:glass":4,"minecraft:polished_diorite":44,"minecraft:stone_bricks":61},"sha256":"48ecfc494bfb5c5a1f518b0729179f0791deda684c7702fc660160fda88758fa","size":{"x":32,"y":1,"z":32}},{"blockCount":34,"bytes":1724,"file":"chunks/y065-z096-x096.json","offset":{"x":96,"y":65,"z":96},"requirements":{"minecraft:bricks":13,"minecraft:glass":6,"minecraft:stone_bricks":15},"sha256":"480a3ceed1a3916e23b10899f41e3532c88813c46eb21239a9c617b26e2cc97f","size":{"x":32,"y":1,"z":32}},{"blockCount":88,"bytes":3174,"file":"chunks/y065-z096-x128.json","offset":{"x":128,"y":65,"z":96},"requirements":{"minecraft:bricks":38,"minecraft:glass":8,"minecraft:polished_diorite":12,"minecraft:stone_bricks":30},"sha256":"7ae64978cc1b922c36cb3468e3294af4ec121eee4a301b4010fc491f47c57537","size":{"x":32,"y":1,"z":32}},{"blockCount":198,"bytes":4437,"file":"chunks/y065-z096-x160.json","offset":{"x":160,"y":65,"z":96},"requirements":{"minecraft:bricks":56,"minecraft:glass":5,"minecraft:polished_diorite":58,"minecraft:stone_bricks":79},"sha256":"b90210804bf1bb11b9fa4208e636c06ae892b056ebc35b7ac8fd6dd78265647e","size":{"x":32,"y":1,"z":32}},{"blockCount":277,"bytes":5295,"file":"chunks/y065-z096-x192.json","offset":{"x":192,"y":65,"z":96},"requirements":{"minecraft:bricks":160,"minecraft:glass":5,"minecraft:oak_planks":4,"minecraft:polished_diorite":44,"minecraft:sandstone":1,"minecraft:stone_bricks":63},"sha256":"ece9d9308b1c6fee08c7db7077f9277de30ef02a822be1415acb7cf95f9e74e2","size":{"x":32,"y":1,"z":32}},{"blockCount":196,"bytes":5079,"file":"chunks/y065-z096-x224.json","offset":{"x":224,"y":65,"z":96},"requirements":{"minecraft:bricks":82,"minecraft:glass":4,"minecraft:oak_planks":7,"minecraft:polished_diorite":54,"minecraft:sandstone":7,"minecraft:stone_bricks":42},"sha256":"655d85619d4417d374888e3609d0adba821548e50d87ec0fb7c125ec2bd55959","size":{"x":32,"y":1,"z":32}},{"blockCount":141,"bytes":3803,"file":"chunks/y065-z128-x000.json","offset":{"x":0,"y":65,"z":128},"requirements":{"minecraft:bricks":42,"minecraft:polished_diorite":59,"minecraft:stone_bricks":40},"sha256":"a1b280518866cb8acfe91deeff88524717942f641d198edf32ccba1ae7f1f92a","size":{"x":32,"y":1,"z":32}},{"blockCount":56,"bytes":2360,"file":"chunks/y065-z128-x032.json","offset":{"x":32,"y":65,"z":128},"requirements":{"minecraft:bricks":20,"minecraft:cobbled_deepslate":1,"minecraft:glass":6,"minecraft:polished_diorite":5,"minecraft:stone_bricks":24},"sha256":"47c25c1a0e647da1c0a6b36a7497307addf5531ba49781fd44477fd71b51b8bd","size":{"x":32,"y":1,"z":32}},{"blockCount":25,"bytes":1387,"file":"chunks/y065-z128-x064.json","offset":{"x":64,"y":65,"z":128},"requirements":{"minecraft:bricks":12,"minecraft:glass":4,"minecraft:stone_bricks":9},"sha256":"49fcd854a9c2b977828969bba9f96ec7b90bd951022239a1b52c2ef88cb09b36","size":{"x":32,"y":1,"z":32}},{"blockCount":8,"bytes":894,"file":"chunks/y065-z128-x096.json","offset":{"x":96,"y":65,"z":128},"requirements":{"minecraft:bricks":4,"minecraft:glass":3,"minecraft:stone_bricks":1},"sha256":"a87c298a0ed8ac83e3d897247dd6f0cf218b8eed3f0431cee8a359c0daefcb52","size":{"x":32,"y":1,"z":32}},{"blockCount":18,"bytes":1198,"file":"chunks/y065-z128-x128.json","offset":{"x":128,"y":65,"z":128},"requirements":{"minecraft:bricks":9,"minecraft:glass":5,"minecraft:stone_bricks":4},"sha256":"094dcb47b7e08b0818d6069b51387497df2163bad6a46944f7a4be6c32e25f2e","size":{"x":32,"y":1,"z":32}},{"blockCount":29,"bytes":1485,"file":"chunks/y065-z128-x160.json","offset":{"x":160,"y":65,"z":128},"requirements":{"minecraft:bricks":14,"minecraft:glass":5,"minecraft:stone_bricks":10},"sha256":"9b23b618240b275269bf513496e099762451fc7d8482aa2a5d1d559f942fbf2c","size":{"x":32,"y":1,"z":32}},{"blockCount":50,"bytes":1687,"file":"chunks/y065-z128-x192.json","offset":{"x":192,"y":65,"z":128},"requirements":{"minecraft:bricks":37,"minecraft:glass":5,"minecraft:stone_bricks":8},"sha256":"41dd631732c84d7216126ffd07585557181c2efecdcc190f2bf0f9e01eb4b289","size":{"x":32,"y":1,"z":32}},{"blockCount":180,"bytes":4749,"file":"chunks/y065-z128-x224.json","offset":{"x":224,"y":65,"z":128},"requirements":{"minecraft:bricks":54,"minecraft:glass":4,"minecraft:oak_planks":5,"minecraft:polished_diorite":74,"minecraft:sandstone":19,"minecraft:stone_bricks":24},"sha256":"ad92250a6078b470910a14f9fb4a4377d36687acdbbc578fd5b1db7407257c39","size":{"x":32,"y":1,"z":32}},{"blockCount":7,"bytes":914,"file":"chunks/y065-z128-x320.json","offset":{"x":320,"y":65,"z":128},"requirements":{"minecraft:cobbled_deepslate":2,"minecraft:glass":1,"minecraft:polished_diorite":4},"sha256":"adc36b15039d9f7aa414235d40108ea37ba6d8d4bdd350be2f54b51817fb312c","size":{"x":32,"y":1,"z":32}},{"blockCount":75,"bytes":2193,"file":"chunks/y065-z160-x000.json","offset":{"x":0,"y":65,"z":160},"requirements":{"minecraft:bricks":14,"minecraft:polished_diorite":30,"minecraft:stone_bricks":31},"sha256":"e761ffe784d5101f86becd7d515e6913e86852d72a9a46dd532d6485d3633115","size":{"x":32,"y":1,"z":32}},{"blockCount":159,"bytes":3545,"file":"chunks/y065-z160-x032.json","offset":{"x":32,"y":65,"z":160},"requirements":{"minecraft:bricks":35,"minecraft:polished_diorite":71,"minecraft:stone_bricks":53},"sha256":"59f0f3bd2f686792ba98f371611fd318830f5cca5b10bc7e2c85f24e5d044cbb","size":{"x":32,"y":1,"z":32}},{"blockCount":169,"bytes":4122,"file":"chunks/y065-z160-x064.json","offset":{"x":64,"y":65,"z":160},"requirements":{"minecraft:bricks":50,"minecraft:polished_diorite":56,"minecraft:stone_bricks":63},"sha256":"540f646886313d8f5c0516568fb8357b138439794aa0ec5999bd97f3f5ec19fa","size":{"x":32,"y":1,"z":32}},{"blockCount":33,"bytes":1687,"file":"chunks/y065-z160-x096.json","offset":{"x":96,"y":65,"z":160},"requirements":{"minecraft:bricks":11,"minecraft:glass":4,"minecraft:stone_bricks":18},"sha256":"b88e74f30423b05c89d31fcc4e30292e242d1d62bde7f47ce4185468d91139ac","size":{"x":32,"y":1,"z":32}},{"blockCount":105,"bytes":3521,"file":"chunks/y065-z160-x128.json","offset":{"x":128,"y":65,"z":160},"requirements":{"minecraft:bricks":40,"minecraft:glass":4,"minecraft:polished_diorite":23,"minecraft:stone_bricks":38},"sha256":"92f1098c5620b46953d93713d34fcd5f3fbe067909b650364f74176f82fd0c29","size":{"x":32,"y":1,"z":32}}],"schema":1}
