{"entries":[{"blockCount":173,"bytes":3657,"file":"chunks/y065-z160-x160.json","offset":{"x":160,"y":65,"z":160},"requirements":{"minecraft:bricks":42,"minecraft:polished_diorite":59,"minecraft:stone_bricks":72},"sha256":"3087f761218658c4aec28a1eda057024533dbb583bf23336948235f4473ceb23","size":{"x":32,"y":1,"z":32}},{"blockCount":265,"bytes":5030,"file":"chunks/y065-z160-x192.json","offset":{"x":192,"y":65,"z":160},"requirements":{"minecraft:bricks":130,"minecraft:oak_planks":4,"minecraft:polished_diorite":62,"minecraft:sandstone":1,"minecraft:stone_bricks":68},"sha256":"86b2b0b2caf7bb371d5d1b978b7c77a32b271290dbbd7fa0e874d5e13ba8d64e","size":{"x":32,"y":1,"z":32}},{"blockCount":178,"bytes":4540,"file":"chunks/y065-z160-x224.json","offset":{"x":224,"y":65,"z":160},"requirements":{"minecraft:bricks":74,"minecraft:oak_planks":6,"minecraft:polished_diorite":53,"minecraft:stone_bricks":45},"sha256":"e49df282f7b7024e4799475c49e8c629b3521cd85f441a606576069c33419c96","size":{"x":32,"y":1,"z":32}},{"blockCount":145,"bytes":3659,"file":"chunks/y065-z192-x064.json","offset":{"x":64,"y":65,"z":192},"requirements":{"minecraft:bricks":38,"minecraft:oak_planks":1,"minecraft:polished_diorite":50,"minecraft:sandstone":2,"minecraft:stone_bricks":54},"sha256":"d33a8862013a2838baabe3bb6939f5cfb17406a50c06468e9a3074784bce5c0d","size":{"x":32,"y":1,"z":32}},{"blockCount":180,"bytes":3367,"file":"chunks/y065-z192-x096.json","offset":{"x":96,"y":65,"z":192},"requirements":{"minecraft:bricks":68,"minecraft:glass":6,"minecraft:oak_planks":5,"minecraft:polished_diorite":60,"minecraft:sandstone":17,"minecraft:stone_bricks":24},"sha256":"4debece426225c2e952a0fc0b2bfa730d10a876cef432556e9c16950add0be84","size":{"x":32,"y":1,"z":32}},{"blockCount":240,"bytes":5087,"file":"chunks/y065-z192-x128.json","offset":{"x":128,"y":65,"z":192},"requirements":{"minecraft:bricks":74,"minecraft:glass":6,"minecraft:oak_planks":4,"minecraft:polished_diorite":81,"minecraft:sandstone":15,"minecraft:stone_bricks":60},"sha256":"c223e27e459bed121dcab6ecd9a92fe6462c0a53af0f0fbc468561c1b4019c88","size":{"x":32,"y":1,"z":32}},{"blockCount":20,"bytes":1142,"file":"chunks/y065-z192-x160.json","offset":{"x":160,"y":65,"z":192},"requirements":{"minecraft:polished_diorite":6,"minecraft:stone_bricks":14},"sha256":"10e37cbfc37099f214b78d469375721e401ff0ac86684867b5457426979177ea","size":{"x":32,"y":1,"z":32}},{"blockCount":36,"bytes":1611,"file":"chunks/y066-z000-x352.json","offset":{"x":352,"y":66,"z":0},"requirements":{"minecraft:glass":4,"minecraft:polished_diorite":24,"minecraft:sandstone":8},"sha256":"0bc42b60a45d7b06cb965ded04e3b879aaf3457fff3284294b4b744a60f57bb4","size":{"x":32,"y":1,"z":32}},{"blockCount":24,"bytes":991,"file":"chunks/y066-z000-x384.json","offset":{"x":384,"y":66,"z":0},"requirements":{"minecraft:stone_bricks":24},"sha256":"b5aae3a3e645fcd3677c02921915444c80117081c9cfcc2fbd234a2ad5931706","size":{"x":32,"y":1,"z":32}},{"blockCount":163,"bytes":3903,"file":"chunks/y066-z064-x064.json","offset":{"x":64,"y":66,"z":64},"requirements":{"minecraft:bricks":32,"minecraft:polished_diorite":93,"minecraft:sandstone":3,"minecraft:stone_bricks":35},"sha256":"e58d2e4216bd1aecbc54f65c3d8c54b56f2182ef0d0a1e5b5901c0ee7ac4049e","size":{"x":32,"y":1,"z":32}},{"blockCount":195,"bytes":3515,"file":"chunks/y066-z064-x096.json","offset":{"x":96,"y":66,"z":64},"requirements":{"minecraft:bricks":81,"minecraft:glass":4,"minecraft:polished_diorite":58,"minecraft:sandstone":23,"minecraft:stone_bricks":29},"sha256":"8cb03e9a073a43c82883834be1777189f02622a1662e7171128c6a3dc0614b59","size":{"x":32,"y":1,"z":32}},{"blockCount":283,"bytes":5582,"file":"chunks/y066-z064-x128.json","offset":{"x":128,"y":66,"z":64},"requirements":{"minecraft:bricks":81,"minecraft:glass":4,"minecraft:polished_diorite":124,"minecraft:sandstone":18,"minecraft:stone_bricks":56},"sha256":"cecc082a76315d7b5b71e2d3adb8ff500728c695461b25ecbe7e8cc0c3bcd39f","size":{"x":32,"y":1,"z":32}},{"blockCount":14,"bytes":1003,"file":"chunks/y066-z064-x160.json","offset":{"x":160,"y":66,"z":64},"requirements":{"minecraft:polished_diorite":9,"minecraft:stone_bricks":5},"sha256":"124857b755b26c97fb4c7c54250ae103d5fa7125149987aa47a80e09982a5018","size":{"x":32,"y":1,"z":32}},{"blockCount":19,"bytes":1037,"file":"chunks/y066-z064-x192.json","offset":{"x":192,"y":66,"z":64},"requirements":{"minecraft:polished_diorite":12,"minecraft:stone_bricks":7},"sha256":"9dc9e05f782b2db35fc4810ffbaea3483bb7d735242ddd624e26965688f54ff1","size":{"x":32,"y":1,"z":32}},{"blockCount":25,"bytes":1152,"file":"chunks/y066-z064-x224.json","offset":{"x":224,"y":66,"z":64},"requirements":{"minecraft:polished_diorite":16,"minecraft:stone_bricks":9},"sha256":"cc1075c1f83806980bd3dd457973fb770b10bf068f6ec0c42580ce0faac34c6a","size":{"x":32,"y":1,"z":32}},{"blockCount":92,"bytes":2768,"file":"chunks/y066-z096-x000.json","offset":{"x":0,"y":66,"z":96},"requirements":{"minecraft:bricks":26,"minecraft:polished_diorite":48,"minecraft:stone_bricks":18},"sha256":"1c1ac602fca2ddc315096d94496e9d3fc964ef612fe7dad237d6feb05be2a954","size":{"x":32,"y":1,"z":32}},{"blockCount":190,"bytes":4333,"file":"chunks/y066-z096-x032.json","offset":{"x":32,"y":66,"z":96},"requirements":{"minecraft:bricks":57,"minecraft:glass":4,"minecraft:polished_diorite":81,"minecraft:stone_bricks":48},"sha256":"48ba18cd9a4cce31cbb6b40d8a6b2918c6a7e273d8012ec1dea3504c582d19e7","size":{"x":32,"y":1,"z":32}},{"blockCount":179,"bytes":4290,"file":"chunks/y066-z096-x064.json","offset":{"x":64,"y":66,"z":96},"requirements":{"minecraft:bricks":68,"minecraft:glass":4,"minecraft:polished_diorite":53,"minecraft:stone_bricks":54},"sha256":"3d7c36fb5ca4a5e538d3888c00bd80e8c80d4acabdf360007edb8819d6430a4c","size":{"x":32,"y":1,"z":32}},{"blockCount":52,"bytes":2108,"file":"chunks/y066-z096-x096.json","offset":{"x":96,"y":66,"z":96},"requirements":{"minecraft:bricks":23,"minecraft:glass":6,"minecraft:stone_bricks":23},"sha256":"d55aa8e768fb752c6becaf5cbefd1499101349908f5279f480e48548b655de8e","size":{"x":32,"y":1,"z":32}},{"blockCount":116,"bytes":3595,"file":"chunks/y066-z096-x128.json","offset":{"x":128,"y":66,"z":96},"requirements":{"minecraft:bricks":49,"minecraft:glass":8,"minecraft:polished_diorite":18,"minecraft:stone_bricks":41},"sha256":"e45419154aa74f1e68a929783ef80bb491d40c194b42b4b9eb0c22b3a57717ba","size":{"x":32,"y":1,"z":32}},{"blockCount":214,"bytes":4687,"file":"chunks/y066-z096-x160.json","offset":{"x":160,"y":66,"z":96},"requirements":{"minecraft:bricks":80,"minecraft:glass":5,"minecraft:polished_diorite":63,"minecraft:stone_bricks":66},"sha256":"2a814f3d0a6eae86724ab9e75d5d7316ee57a441977e6d0b12208e1dff01547c","size":{"x":32,"y":1,"z":32}},{"blockCount":307,"bytes":5626,"file":"chunks/y066-z096-x192.json","offset":{"x":192,"y":66,"z":96},"requirements":{"minecraft:bricks":175,"minecraft:glass":5,"minecraft:oak_planks":4,"minecraft:polished_diorite":48,"minecraft:sandstone":1,"minecraft:spruce_planks":21,"minecraft:stone_bricks":53},"sha256":"ad8a44f320c90cdd7e2db6c41847b118613461ecd5f8ae0945fbe061f6039856","size":{"x":32,"y":1,"z":32}},{"blockCount":219,"bytes":5235,"file":"chunks/y066-z096-x224.json","offset":{"x":224,"y":66,"z":96},"requirements":{"minecraft:bricks":89,"minecraft:glass":1,"minecraft:oak_planks":6,"minecraft:polished_diorite":54,"minecraft:sandstone":9,"minecraft:spruce_planks":39,"minecraft:stone_bricks":21},"sha256":"2d5dc5dab3dd0d89dd0f10b2b23e8f03874680edf4df1caafdb8832cf8910c5b","size":{"x":32,"y":1,"z":32}},{"blockCount":146,"bytes":3841,"file":"chunks/y066-z128-x000.json","offset":{"x":0,"y":66,"z":128},"requirements":{"minecraft:bricks":45,"minecraft:polished_diorite":73,"minecraft:stone_bricks":28},"sha256":"aee531bfe77e1149a2287670ac41cdba426cbda0f141bb69f1d828684b93c386","size":{"x":32,"y":1,"z":32}},{"blockCount":80,"bytes":2519,"file":"chunks/y066-z128-x032.json","offset":{"x":32,"y":66,"z":128},"requirements":{"minecraft:bricks":31,"minecraft:glass":6,"minecraft:polished_diorite":8,"minecraft:stone_bricks":35},"sha256":"c3924018521c1a24ca339fd6286aff43c392e0982a51c3e9be2aae75cd102106","size":{"x":32,"y":1,"z":32}},{"blockCount":35,"bytes":1426,"file":"chunks/y066-z128-x064.json","offset":{"x":64,"y":66,"z":128},"requirements":{"minecraft:bricks":17,"minecraft:glass":4,"minecraft:stone_bricks":14},"sha256":"4b3f058d2bb63d0e0a9279ac916edaf98e959c1891ce4c6a71013cc2d325e546","size":{"x":32,"y":1,"z":32}},{"blockCount":10,"bytes":932,"file":"chunks/y066-z128-x096.json","offset":{"x":96,"y":66,"z":128},"requirements":{"minecraft:bricks":5,"minecraft:glass":3,"minecraft:stone_bricks":2},"sha256":"f30d777d162de71290ce700aef2ff22a195109654da7169799f123dbea51df89","size":{"x":32,"y":1,"z":32}},{"blockCount":24,"bytes":1275,"file":"chunks/y066-z128-x128.json","offset":{"x":128,"y":66,"z":128},"requirements":{"minecraft:bricks":12,"minecraft:glass":5,"minecraft:stone_bricks":7},"sha256":"bbf961b99dcea6fcfdce77420c116ae97d128ea41421c7d2462e1b91ab477cab","size":{"x":32,"y":1,"z":32}},{"blockCount":39,"bytes":1466,"file":"chunks/y066-z128-x160.json","offset":{"x":160,"y":66,"z":128},"requirements":{"minecraft:bricks":19,"minecraft:glass":5,"minecraft:stone_bricks":15},"sha256":"335bf77dc7ea0f3e7a6f1349ffcdff4fcdbd36b064228cb845c3533e8d13da0a","size":{"x":32,"y":1,"z":32}},{"blockCount":56,"bytes":1688,"file":"chunks/y066-z128-x192.json","offset":{"x":192,"y":66,"z":128},"requirements":{"minecraft:bricks":39,"minecraft:glass":5,"minecraft:stone_bricks":12},"sha256":"db1965ddc7fb6e339015e2a9974b180cca3bfa425279128e2c7f4102bbc303e1","size":{"x":32,"y":1,"z":32}},{"blockCount":176,"bytes":4515,"file":"chunks/y066-z128-x224.json","offset":{"x":224,"y":66,"z":128},"requirements":{"minecraft:bricks":59,"minecraft:glass":1,"minecraft:polished_diorite":72,"minecraft:sandstone":23,"minecraft:stone_bricks":21},"sha256":"d58846354cef21fb1f3f04f985c88db5f41b79179f64d0e97a9c8f199f9b27a1","size":{"x":32,"y":1,"z":32}},{"blockCount":10,"bytes":953,"file":"chunks/y066-z128-x320.json","offset":{"x":320,"y":66,"z":128},"requirements":{"minecraft:cobbled_deepslate":1,"minecraft:glass":1,"minecraft:polished_diorite":8},"sha256":"c68e4381813882f544d477d015dce69cf1cf6f743175417fab40406377b703dd","size":{"x":32,"y":1,"z":32}},{"blockCount":62,"bytes":2002,"file":"chunks/y066-z160-x000.json","offset":{"x":0,"y":66,"z":160},"requirements":{"minecraft:bricks":19,"minecraft:polished_diorite":32,"minecraft:stone_bricks":11},"sha256":"af5c49fa4a5ba0da67c8f515118d44da2faf2db1a8dca8e0ff44fea405d9e96e","size":{"x":32,"y":1,"z":32}},{"blockCount":162,"bytes":3625,"file":"chunks/y066-z160-x032.json","offset":{"x":32,"y":66,"z":160},"requirements":{"minecraft:bricks":44,"minecraft:polished_diorite":81,"minecraft:stone_bricks":37},"sha256":"d7ab5bf13e9aba50e08ca7130aaefd416b5fc820f79d40532c50e95dfa41e48a","size":{"x":32,"y":1,"z":32}},{"blockCount":173,"bytes":4086,"file":"chunks/y066-z160-x064.json","offset":{"x":64,"y":66,"z":160},"requirements":{"minecraft:bricks":57,"minecraft:polished_diorite":69,"minecraft:stone_bricks":47},"sha256":"5fbbac91d21d4cfb1091d7794c88a9181fa5d537c3196deebbd158e334131e86","size":{"x":32,"y":1,"z":32}},{"blockCount":53,"bytes":2091,"file":"chunks/y066-z160-x096.json","offset":{"x":96,"y":66,"z":160},"requirements":{"minecraft:bricks":23,"minecraft:glass":4,"minecraft:stone_bricks":26},"sha256":"490c61c59537dedb2cf85eba559a95e298953f742bce84dd1ceb3befe8c026f1","size":{"x":32,"y":1,"z":32}},{"blockCount":131,"bytes":3828,"file":"chunks/y066-z160-x128.json","offset":{"x":128,"y":66,"z":160},"requirements":{"minecraft:bricks":48,"minecraft:glass":4,"minecraft:polished_diorite":34,"minecraft:stone_bricks":45},"sha256":"5b7d76b185f1b6ba3069f6a55856ad12e2e22a823a642c8340bd02c3e929a2d2","size":{"x":32,"y":1,"z":32}},{"blockCount":177,"bytes":3907,"file":"chunks/y066-z160-x160.json","offset":{"x":160,"y":66,"z":160},"requirements":{"minecraft:bricks":61,"minecraft:polished_diorite":64,"minecraft:stone_bricks":52},"sha256":"30095bb228001ba22490bb8d1d161ff1c2455dec04f01276f26a100d8afb4eeb","size":{"x":32,"y":1,"z":32}},{"blockCount":277,"bytes":5248,"file":"chunks/y066-z160-x192.json","offset":{"x":192,"y":66,"z":160},"requirements":{"minecraft:bricks":143,"minecraft:oak_planks":4,"minecraft:polished_diorite":60,"minecraft:sandstone":1,"minecraft:spruce_planks":21,"minecraft:stone_bricks":48},"sha256":"4bc9c6181c6b3ca1a51b4a69dfa495c04db62ddfe57c9490122baf0a838bceec","size":{"x":32,"y":1,"z":32}},{"blockCount":191,"bytes":4848,"file":"chunks/y066-z160-x224.json","offset":{"x":224,"y":66,"z":160},"requirements":{"minecraft:bricks":80,"minecraft:oak_planks":6,"minecraft:polished_diorite":45,"minecraft:spruce_planks":39,"minecraft:stone_bricks":21},"sha256":"486bf6b4998b7c5ab1fa5931039816994ba2141151eec37eb6a4b307b234239a","size":{"x":32,"y":1,"z":32}},{"blockCount":134,"bytes":3291,"file":"chunks/y066-z192-x064.json","offset":{"x":64,"y":66,"z":192},"requirements":{"minecraft:bricks":27,"minecraft:polished_diorite":76,"minecraft:sandstone":3,"minecraft:stone_bricks":28},"sha256":"a10e0c95b1cdf051b3ce672aba98a3d0e6fc46c859e1db10250e934ff32a9a5c","size":{"x":32,"y":1,"z":32}},{"blockCount":183,"bytes":3171,"file":"chunks/y066-z192-x096.json","offset":{"x":96,"y":66,"z":192},"requirements":{"minecraft:bricks":75,"minecraft:glass":3,"minecraft:polished_diorite":58,"minecraft:sandstone":23,"minecraft:stone_bricks":24},"sha256":"6435c39848a9b8955b69b47bf072e1e7b44f789d209b850cf7c54834ab3b771f","size":{"x":32,"y":1,"z":32}},{"blockCount":244,"bytes":4741,"file":"chunks/y066-z192-x128.json","offset":{"x":128,"y":66,"z":192},"requirements":{"minecraft:bricks":70,"minecraft:glass":3,"minecraft:polished_diorite":108,"minecraft:sandstone":18,"minecraft:stone_bricks":45},"sha256":"5bec4f15294d17669b09e6eeb26227f01fff7bdb628d2fe74ce8c253b1cec6b0","size":{"x":32,"y":1,"z":32}},{"blockCount":12,"bytes":947,"file":"chunks/y066-z192-x160.json","offset":{"x":160,"y":66,"z":192},"requirements":{"minecraft:polished_diorite":8,"minecraft:stone_bricks":4},"sha256":"49bf6aa87311d956e0ce8a5fb42ecfcad6e3117d5ec7e98eac6f130d843aa17c","size":{"x":32,"y":1,"z":32}},{"blockCount":52,"bytes":2040,"file":"chunks/y067-z000-x352.json","offset":{"x":352,"y":67,"z":0},"requirements":{"minecraft:oak_planks":28,"minecraft:polished_diorite":12,"minecraft:sandstone":12},"sha256":"ee0915e22f0058f828876adf998ed21237998b713c038344a1565abd17bc69a8","size":{"x":32,"y":1,"z":32}},{"blockCount":16,"bytes":991,"file":"chunks/y067-z000-x384.json","offset":{"x":384,"y":67,"z":0},"requirements":{"minecraft:stone_bricks":16},"sha256":"cf64c4656a7a151fe30a0f7e550365acdee3bf8dec6c258ce1d384c671f1ce89","size":{"x":32,"y":1,"z":32}},{"blockCount":159,"bytes":3789,"file":"chunks/y067-z064-x064.json","offset":{"x":64,"y":67,"z":64},"requirements":{"minecraft:bricks":36,"minecraft:polished_diorite":85,"minecraft:sandstone":1,"minecraft:stone_bricks":37},"sha256":"0333c663542b99745824a9bb4798e9df1210d16992b143146c877fd0c30133f5","size":{"x":32,"y":1,"z":32}},{"blockCount":199,"bytes":3478,"file":"chunks/y067-z064-x096.json","offset":{"x":96,"y":67,"z":64},"requirements":{"minecraft:bricks":95,"minecraft:glass":3,"minecraft:polished_diorite":56,"minecraft:sandstone":18,"minecraft:stone_bricks":27},"sha256":"2cbfa62a950220d1b90b2d1b3ab7b00231dbc2c758a808d40b3f57de615555f8","size":{"x":32,"y":1,"z":32}},{"blockCount":277,"bytes":5320,"file":"chunks/y067-z064-x128.json","offset":{"x":128,"y":67,"z":64},"requirements":{"minecraft:bricks":93,"minecraft:glass":3,"minecraft:polished_diorite":118,"minecraft:sandstone":11,"minecraft:stone_bricks":52},"sha256":"0df9ac2680ce5fafc8672ba59c0ed58ea04c2a82073ef17263678ea2b492b0aa","size":{"x":32,"y":1,"z":32}},{"blockCount":14,"bytes":1041,"file":"chunks/y067-z064-x160.json","offset":{"x":160,"y":67,"z":64},"requirements":{"minecraft:polished_diorite":7,"minecraft:stone_bricks":7},"sha256":"23510c04e20a879abe276ce37ea643e3193f827276f112fb289e1e091c11ee99","size":{"x":32,"y":1,"z":32}},{"blockCount":18,"bytes":999,"file":"chunks/y067-z064-x192.json","offset":{"x":192,"y":67,"z":64},"requirements":{"minecraft:polished_diorite":10,"minecraft:stone_bricks":8},"sha256":"0917df418ab5a211fffaece0a38ef8afdb39f71aef2d06f128bd5c0c3579b3ff","size":{"x":32,"y":1,"z":32}},{"blockCount":24,"bytes":1077,"file":"chunks/y067-z064-x224.json","offset":{"x":224,"y":67,"z":64},"requirements":{"minecraft:polished_diorite":13,"minecraft:stone_bricks":11},"sha256":"ba23b7800d83b92ede8c3c4324b36a19fcdb3c07c48185522265a718ac1345fe","size":{"x":32,"y":1,"z":32}},{"blockCount":101,"bytes":2825,"file":"chunks/y067-z096-x000.json","offset":{"x":0,"y":67,"z":96},"requirements":{"minecraft:bricks":24,"minecraft:polished_diorite":56,"minecraft:stone_bricks":21},"sha256":"3343049e90c7cc24f67b785f933725c0e787ebc3592d02708d2e40a2b603f170","size":{"x":32,"y":1,"z":32}},{"blockCount":176,"bytes":4429,"file":"chunks/y067-z096-x032.json","offset":{"x":32,"y":67,"z":96},"requirements":{"minecraft:bricks":54,"minecraft:glass":4,"minecraft:polished_diorite":79,"minecraft:stone_bricks":39},"sha256":"dc65cafc12b1c1128b5ab7cde8afc61c9a2f382d8a8cc65da04219acb9c31969","size":{"x":32,"y":1,"z":32}},{"blockCount":161,"bytes":4368,"file":"chunks/y067-z096-x064.json","offset":{"x":64,"y":67,"z":96},"requirements":{"minecraft:bricks":61,"minecraft:glass":4,"minecraft:polished_diorite":52,"minecraft:stone_bricks":44},"sha256":"b3fbd4bc4c1df3b302f65793ceb740ac0be66722fbbc19377a6c87851dad0167","size":{"x":32,"y":1,"z":32}},{"blockCount":46,"bytes":2089,"file":"chunks/y067-z096-x096.json","offset":{"x":96,"y":67,"z":96},"requirements":{"minecraft:bricks":21,"minecraft:glass":6,"minecraft:stone_bricks":19},"sha256":"d164ab60172bf418cfee36fc843846363139d598bf5f1732b540ea8647635df9","size":{"x":32,"y":1,"z":32}},{"blockCount":105,"bytes":3614,"file":"chunks/y067-z096-x128.json","offset":{"x":128,"y":67,"z":96},"requirements":{"minecraft:bricks":45,"minecraft:glass":8,"minecraft:polished_diorite":18,"minecraft:stone_bricks":34},"sha256":"3a1835c101d96be410ee3b3cd3fe1679de707ab4bf1cadd181db3d4bec999e49","size":{"x":32,"y":1,"z":32}},{"blockCount":191,"bytes":4839,"file":"chunks/y067-z096-x160.json","offset":{"x":160,"y":67,"z":96},"requirements":{"minecraft:bricks":71,"minecraft:glass":5,"minecraft:polished_diorite":62,"minecraft:stone_bricks":53},"sha256":"62c21c69c361b8ffda5232e0f49c5eee66df815dbe595abbbd21bc47bdef071b","size":{"x":32,"y":1,"z":32}},{"blockCount":283,"bytes":5680,"file":"chunks/y067-z096-x192.json","offset":{"x":192,"y":67,"z":96},"requirements":{"minecraft:bricks":175,"minecraft:glass":5,"minecraft:oak_planks":4,"minecraft:polished_diorite":49,"minecraft:spruce_planks":2,"minecraft:stone_bricks":48},"sha256":"2de25f1cbfed9f08029600a50fe1841d50353c4913b6fd5292dfe2c886679f0d","size":{"x":32,"y":1,"z":32}},{"blockCount":183,"bytes":5124,"file":"chunks/y067-z096-x224.json","offset":{"x":224,"y":67,"z":96},"requirements":{"minecraft:bricks":91,"minecraft:oak_planks":6,"minecraft:polished_diorite":50,"minecraft:sandstone":6,"minecraft:spruce_planks":2,"minecraft:stone_bricks":28},"sha256":"6882bcdd754309f3393a6d189ead12ffb54c1936c210c1239fe799aaa5678550","size":{"x":32,"y":1,"z":32}},{"blockCount":153,"bytes":3936,"file":"chunks/y067-z128-x000.json","offset":{"x":0,"y":67,"z":128},"requirements":{"minecraft:bricks":47,"minecraft:polished_diorite":78,"minecraft:stone_bricks":28},"sha256":"df0405646c3aad840850f218b3d82c59e309e1ffcca60d853a9ecbf315975ad6","size":{"x":32,"y":1,"z":32}},{"blockCount":81,"bytes":2672,"file":"chunks/y067-z128-x032.json","offset":{"x":32,"y":67,"z":128},"requirements":{"minecraft:bricks":36,"minecraft:glass":6,"minecraft:polished_diorite":12,"minecraft:stone_bricks":27},"sha256":"ea26a60e812068e6e43e1300ed9009190f529a303f03c86bbb59d56d622f3e09","size":{"x":32,"y":1,"z":32}},{"blockCount":31,"bytes":1483,"file":"chunks/y067-z128-x064.json","offset":{"x":64,"y":67,"z":128},"requirements":{"minecraft:bricks":17,"minecraft:glass":4,"minecraft:stone_bricks":10},"sha256":"003c321551279c7cbfeb154842056e0466b3499507618bba0e2e42a1a8bc9895","size":{"x":32,"y":1,"z":32}},{"blockCount":10,"bytes":932,"file":"chunks/y067-z128-x096.json","offset":{"x":96,"y":67,"z":128},"requirements":{"minecraft:bricks":5,"minecraft:glass":3,"minecraft:stone_bricks":2},"sha256":"d60607ce8a0225c5799f4944ab3292e5dd26bf291e083483e2b2c35c477a9738","size":{"x":32,"y":1,"z":32}},{"blockCount":23,"bytes":1294,"file":"chunks/y067-z128-x128.json","offset":{"x":128,"y":67,"z":128},"requirements":{"minecraft:bricks":12,"minecraft:glass":5,"minecraft:stone_bricks":6},"sha256":"605270962c90ecc916b8c40d4a7f1621673834a7eaaebd09309830f2290b43c8","size":{"x":32,"y":1,"z":32}},{"blockCount":34,"bytes":1561,"file":"chunks/y067-z128-x160.json","offset":{"x":160,"y":67,"z":128},"requirements":{"minecraft:bricks":19,"minecraft:glass":5,"minecraft:stone_bricks":10},"sha256":"f52cd6df1bdf0aa1fa65db320608b72cb82cdc5c4c5d81c07dfd9e40eef703c0","size":{"x":32,"y":1,"z":32}},{"blockCount":64,"bytes":2226,"file":"chunks/y067-z128-x192.json","offset":{"x":192,"y":67,"z":128},"requirements":{"minecraft:bricks":51,"minecraft:glass":5,"minecraft:stone_bricks":8},"sha256":"f913b7ed0b1052bc9e5e6e522f7ac62e14a488c29cf69920ec1be62eb2bc7237","size":{"x":32,"y":1,"z":32}},{"blockCount":171,"bytes":4476,"file":"chunks/y067-z128-x224.json","offset":{"x":224,"y":67,"z":128},"requirements":{"minecraft:bricks":61,"minecraft:polished_diorite":73,"minecraft:sandstone":20,"minecraft:stone_bricks":17},"sha256":"ea8588b540f57facfa75ee6cad29bd4da2612a7a7b7f5aa99ddaa3aca1aa6258","size":{"x":32,"y":1,"z":32}},{"blockCount":15,"bytes":1029,"file":"chunks/y067-z128-x320.json","offset":{"x":320,"y":67,"z":128},"requirements":{"minecraft:cobbled_deepslate":5,"minecraft:glass":1,"minecraft:polished_diorite":9},"sha256":"262a9793000b15e944c05dddeff666ce5e6d6a38828cae7bca98723d3e67fed8","size":{"x":32,"y":1,"z":32}},{"blockCount":65,"bytes":2021,"file":"chunks/y067-z160-x000.json","offset":{"x":0,"y":67,"z":160},"requirements":{"minecraft:bricks":16,"minecraft:polished_diorite":38,"minecraft:stone_bricks":11},"sha256":"5eb3986947781abd824d8268d7be8495e7d118c10a2870b99f89bbb36413c0a9","size":{"x":32,"y":1,"z":32}},{"blockCount":151,"bytes":3626,"file":"chunks/y067-z160-x032.json","offset":{"x":32,"y":67,"z":160},"requirements":{"minecraft:bricks":40,"minecraft:polished_diorite":79,"minecraft:stone_bricks":32},"sha256":"30e037dfaac225173a0af66bd8d49fbd2df10bd95455ed2bfcf5514a88d1851b","size":{"x":32,"y":1,"z":32}},{"blockCount":158,"bytes":4162,"file":"chunks/y067-z160-x064.json","offset":{"x":64,"y":67,"z":160},"requirements":{"minecraft:bricks":50,"minecraft:polished_diorite":69,"minecraft:stone_bricks":39},"sha256":"2c0b8aa51f6067283f2e314e0da934a6ef5cfe7cc510d29c7bc1e2db5bbec7f4","size":{"x":32,"y":1,"z":32}},{"blockCount":45,"bytes":2091,"file":"chunks/y067-z160-x096.json","offset":{"x":96,"y":67,"z":160},"requirements":{"minecraft:bricks":20,"minecraft:glass":4,"minecraft:stone_bricks":21},"sha256":"52b85e5f592d25dfc441782cfa815947ba58972d21a02462c1a0149c0a393634","size":{"x":32,"y":1,"z":32}},{"blockCount":117,"bytes":3847,"file":"chunks/y067-z160-x128.json","offset":{"x":128,"y":67,"z":160},"requirements":{"minecraft:bricks":43,"minecraft:glass":4,"minecraft:polished_diorite":34,"minecraft:stone_bricks":36},"sha256":"da3daa7b0f320b6d6b5b3e7f65fcf5a5c72272f18db5055138e719edab6638c4","size":{"x":32,"y":1,"z":32}},{"blockCount":159,"bytes":3964,"file":"chunks/y067-z160-x160.json","offset":{"x":160,"y":67,"z":160},"requirements":{"minecraft:bricks":52,"minecraft:polished_diorite":63,"minecraft:stone_bricks":44},"sha256":"80779884cfac040a19c60fface6f8034bbf565d2c7ce8b0c89f17d79754ecbc2","size":{"x":32,"y":1,"z":32}},{"blockCount":254,"bytes":5148,"file":"chunks/y067-z160-x192.json","offset":{"x":192,"y":67,"z":160},"requirements":{"minecraft:bricks":141,"minecraft:oak_planks":4,"minecraft:polished_diorite":59,"minecraft:spruce_planks":2,"minecraft:stone_bricks":48},"sha256":"9c6204a75b123ff57059f97f541ca159f0ddac949579c134976dfe64c068e4f7","size":{"x":32,"y":1,"z":32}},{"blockCount":155,"bytes":4586,"file":"chunks/y067-z160-x224.json","offset":{"x":224,"y":67,"z":160},"requirements":{"minecraft:bricks":80,"minecraft:oak_planks":6,"minecraft:polished_diorite":35,"minecraft:spruce_planks":2,"minecraft:stone_bricks":32},"sha256":"bbd2e38fe59e812fcdbe596dcfb6e307292e180f2f8d7b354c7269e5ce54b7fa","size":{"x":32,"y":1,"z":32}},{"blockCount":132,"bytes":3177,"file":"chunks/y067-z192-x064.json","offset":{"x":64,"y":67,"z":192},"requirements":{"minecraft:bricks":31,"minecraft:polished_diorite":68,"minecraft:sandstone":1,"minecraft:stone_bricks":32},"sha256":"dadd8cce86ac65b905ee8340816864e0bc251798e96ee169aad0ed776bba02cc","size":{"x":32,"y":1,"z":32}},{"blockCount":191,"bytes":3171,"file":"chunks/y067-z192-x096.json","offset":{"x":96,"y":67,"z":192},"requirements":{"minecraft:bricks":90,"minecraft:glass":2,"minecraft:polished_diorite":56,"minecraft:sandstone":20,"minecraft:stone_bricks":23},"sha256":"4c21902c7afa39f88f28ec9d5437605bab48e38b114293aee5db8ed9b1eef221","size":{"x":32,"y":1,"z":32}},{"blockCount":244,"bytes":4497,"file":"chunks/y067-z192-x128.json","offset":{"x":128,"y":67,"z":192},"requirements":{"minecraft:bricks":83,"minecraft:glass":2,"minecraft:polished_diorite":102,"minecraft:sandstone":13,"minecraft:stone_bricks":44},"sha256":"75ac212b64206f6a839d874a353f22c1ff7ee8716efb5c9501f07de1d1f9091c","size":{"x":32,"y":1,"z":32}},{"blockCount":12,"bytes":985,"file":"chunks/y067-z192-x160.json","offset":{"x":160,"y":67,"z":192},"requirements":{"minecraft:polished_diorite":6,"minecraft:stone_bricks":6},"sha256":"8464d0e2930d4916a5938125920179029db47d75b792d9504b57693f791b1745","size":{"x":32,"y":1,"z":32}},{"blockCount":173,"bytes":2368,"file":"chunks/y068-z000-x352.json","offset":{"x":352,"y":68,"z":0},"requirements":{"minecraft:glass":5,"minecraft:oak_planks":92,"minecraft:polished_diorite":40,"minecraft:sandstone":36},"sha256":"3d192ddc17ce0ef66feb98ef99f9baa0a952833c9a0ca7105a3bcb7113888ccd","size":{"x":32,"y":1,"z":32}},{"blockCount":16,"bytes":991,"file":"chunks/y068-z000-x384.json","offset":{"x":384,"y":68,"z":0},"requirements":{"minecraft:stone_bricks":16},"sha256":"3081388bc530022fbeac8a432f096d5e1f0334e809167d1653314120fc07f6ed","size":{"x":32,"y":1,"z":32}},{"blockCount":161,"bytes":3651,"file":"chunks/y068-z064-x064.json","offset":{"x":64,"y":68,"z":64},"requirements":{"minecraft:bricks":39,"minecraft:polished_diorite":93,"minecraft:stone_bricks":29},"sha256":"e80a41c6fb9c6f57713bb9f499c48d66a064bb4d17eb8b5085da5813f7d0f33e","size":{"x":32,"y":1,"z":32}},{"blockCount":226,"bytes":3233,"file":"chunks/y068-z064-x096.json","offset":{"x":96,"y":68,"z":64},"requirements":{"minecraft:bricks":131,"minecraft:glass":3,"minecraft:polished_diorite":57,"minecraft:stone_bricks":35},"sha256":"1e99dbc96d86204ea1a3d105f1287a13ed62644a1f2ad456897636bc6fd52554","size":{"x":32,"y":1,"z":32}},{"blockCount":305,"bytes":5487,"file":"chunks/y068-z064-x128.json","offset":{"x":128,"y":68,"z":64},"requirements":{"minecraft:bricks":123,"minecraft:glass":3,"minecraft:polished_diorite":125,"minecraft:stone_bricks":54},"sha256":"4cf24df03fbe015cceb55bed13b0347b842856dbde90b8f502bce35b6c6a9479","size":{"x":32,"y":1,"z":32}},{"blockCount":9,"bytes":946,"file":"chunks/y068-z064-x160.json","offset":{"x":160,"y":68,"z":64},"requirements":{"minecraft:polished_diorite":7,"minecraft:stone_bricks":2},"sha256":"907b55c7cf85168d7c666988575420ffd28b2a129812409da2088bbfc72debd3","size":{"x":32,"y":1,"z":32}},{"blockCount":19,"bytes":1056,"file":"chunks/y068-z064-x192.json","offset":{"x":192,"y":68,"z":64},"requirements":{"minecraft:polished_diorite":9,"minecraft:stone_bricks":10},"sha256":"70c6afd647e201b0a461e4a2b31a3d5099569fa719f948a107579599cbd2c004","size":{"x":32,"y":1,"z":32}},{"blockCount":23,"bytes":1135,"file":"chunks/y068-z064-x224.json","offset":{"x":224,"y":68,"z":64},"requirements":{"minecraft:polished_diorite":12,"minecraft:stone_bricks":11},"sha256":"48e3b2eadd92c0321fefffa00f513181fbd9ec3771ac4c4ab91ab84f7f8055fc","size":{"x":32,"y":1,"z":32}},{"blockCount":93,"bytes":2786,"file":"chunks/y068-z096-x000.json","offset":{"x":0,"y":68,"z":96},"requirements":{"minecraft:bricks":21,"minecraft:polished_diorite":59,"minecraft:stone_bricks":13},"sha256":"b377fcd5eac953fc8c6cd6a628e89a475ce1e316a8be42b1bf732f3d7bea76d2","size":{"x":32,"y":1,"z":32}},{"blockCount":211,"bytes":4731,"file":"chunks/y068-z096-x032.json","offset":{"x":32,"y":68,"z":96},"requirements":{"minecraft:bricks":68,"minecraft:glass":4,"minecraft:polished_diorite":93,"minecraft:stone_bricks":46},"sha256":"9cdacd59391e343ba57864a2332562d62c0d6029f7c4ea5005ac88a353016d09","size":{"x":32,"y":1,"z":32}},{"blockCount":198,"bytes":4653,"file":"chunks/y068-z096-x064.json","offset":{"x":64,"y":68,"z":96},"requirements":{"minecraft:bricks":88,"minecraft:glass":4,"minecraft:polished_diorite":53,"minecraft:stone_bricks":53},"sha256":"0eb0d4f5aa7583745a8a4dc48cf114c7f425400d9a78c10f4cb40d7928a9e800","size":{"x":32,"y":1,"z":32}},{"blockCount":68,"bytes":2416,"file":"chunks/y068-z096-x096.json","offset":{"x":96,"y":68,"z":96},"requirements":{"minecraft:bricks":35,"minecraft:glass":6,"minecraft:stone_bricks":27},"sha256":"ce48e86607d58f9d448e19faac7fd88b5517c328e544259f90aeaef908d04c01","size":{"x":32,"y":1,"z":32}},{"blockCount":143,"bytes":4147,"file":"chunks/y068-z096-x128.json","offset":{"x":128,"y":68,"z":96},"requirements":{"minecraft:bricks":68,"minecraft:glass":8,"minecraft:polished_diorite":19,"minecraft:stone_bricks":48},"sha256":"c3f6196d7c4c59b1a6e68172a60b8cf0e38a0af2aa7ed45f84b08b10ca512070","size":{"x":32,"y":1,"z":32}},{"blockCount":227,"bytes":5030,"file":"chunks/y068-z096-x160.json","offset":{"x":160,"y":68,"z":96},"requirements":{"minecraft:bricks":101,"minecraft:glass":5,"minecraft:polished_diorite":62,"minecraft:stone_bricks":59},"sha256":"7e24ac1c7b4cadd64d4905973eb14510b1c1961b58051d710f193049a8ac377b","size":{"x":32,"y":1,"z":32}},{"blockCount":298,"bytes":5990,"file":"chunks/y068-z096-x192.json","offset":{"x":192,"y":68,"z":96},"requirements":{"minecraft:bricks":188,"minecraft:glass":5,"minecraft:oak_planks":4,"minecraft:polished_diorite":50,"minecraft:sandstone":1,"minecraft:spruce_planks":2,"minecraft:stone_bricks":48},"sha256":"1e447a55d14f90687e14f72e45631599c77ad22150ba195604356fef4dd887e1","size":{"x":32,"y":1,"z":32}},{"blockCount":184,"bytes":5120,"file":"chunks/y068-z096-x224.json","offset":{"x":224,"y":68,"z":96},"requirements":{"minecraft:bricks":100,"minecraft:oak_planks":6,"minecraft:polished_diorite":47,"minecraft:spruce_planks":2,"minecraft:stone_bricks":29},"sha256":"f7b668bb47ebd519123274e8915951d0ceeeff55bd59468514839f8883edcda5","size":{"x":32,"y":1,"z":32}},{"blockCount":160,"bytes":4145,"file":"chunks/y068-z128-x000.json","offset":{"x":0,"y":68,"z":128},"requirements":{"minecraft:bricks":50,"minecraft:polished_diorite":80,"minecraft:stone_bricks":30},"sha256":"3309e2a27b84512c6223aceaa10a06f057e7d7c308845c9bbf1dc376fa2c2134","size":{"x":32,"y":1,"z":32}},{"blockCount":98,"bytes":2789,"file":"chunks/y068-z128-x032.json","offset":{"x":32,"y":68,"z":128},"requirements":{"minecraft:bricks":40,"minecraft:glass":6,"minecraft:polished_diorite":18,"minecraft:stone_bricks":34},"sha256":"686b2d1b2cbc104456d369d425037dc7e050574a4eeb4d7c968f83e8f40dca35","size":{"x":32,"y":1,"z":32}},{"blockCount":41,"bytes":1483,"file":"chunks/y068-z128-x064.json","offset":{"x":64,"y":68,"z":128},"requirements":{"minecraft:bricks":22,"minecraft:glass":4,"minecraft:stone_bricks":15},"sha256":"811b584371f8b6403986a2c270a6ebb32dd6d6d2c5d208d0a6896fc805a828cb","size":{"x":32,"y":1,"z":32}},{"blockCount":12,"bytes":932,"file":"chunks/y068-z128-x096.json","offset":{"x":96,"y":68,"z":128},"requirements":{"minecraft:bricks":6,"minecraft:glass":3,"minecraft:stone_bricks":3},"sha256":"00b75b2634317f856fa221f0c20f1d89f50a82c4a2b752e63f9a186058f2129a","size":{"x":32,"y":1,"z":32}},{"blockCount":30,"bytes":1314,"file":"chunks/y068-z128-x128.json","offset":{"x":128,"y":68,"z":128},"requirements":{"minecraft:bricks":15,"minecraft:glass":5,"minecraft:stone_bricks":10},"sha256":"ee9d06ffaa7f75e57b23c2b7086e9cf8e1d59bec123bcee458b685898236f854","size":{"x":32,"y":1,"z":32}},{"blockCount":43,"bytes":1504,"file":"chunks/y068-z128-x160.json","offset":{"x":160,"y":68,"z":128},"requirements":{"minecraft:bricks":24,"minecraft:glass":5,"minecraft:stone_bricks":14},"sha256":"516007996dfa524cb1c864bce44ca2a85f7e53006530d4d6590a83e296df9ca3","size":{"x":32,"y":1,"z":32}},{"blockCount":78,"bytes":2538,"file":"chunks/y068-z128-x192.json","offset":{"x":192,"y":68,"z":128},"requirements":{"minecraft:bricks":61,"minecraft:glass":5,"minecraft:stone_bricks":12},"sha256":"82f55601d19c6752e371033922b05c6adee8d1a78f4577e80bb7bbcf6d2d5a78","size":{"x":32,"y":1,"z":32}},{"blockCount":177,"bytes":4280,"file":"chunks/y068-z128-x224.json","offset":{"x":224,"y":68,"z":128},"requirements":{"minecraft:bricks":80,"minecraft:polished_diorite":71,"minecraft:stone_bricks":26},"sha256":"50e1a3d0a380b1339556fd3e95b65b9aa35bbc32ad90d93204b434bf6bab32e0","size":{"x":32,"y":1,"z":32}},{"blockCount":9,"bytes":972,"file":"chunks/y068-z128-x320.json","offset":{"x":320,"y":68,"z":128},"requirements":{"minecraft:cobbled_deepslate":2,"minecraft:glass":1,"minecraft:polished_diorite":6},"sha256":"f49e0c080cfe687d0d66ebc2187d8f00951ee536ea8cbc01d9fa084a77d7db19","size":{"x":32,"y":1,"z":32}},{"blockCount":58,"bytes":1925,"file":"chunks/y068-z160-x000.json","offset":{"x":0,"y":68,"z":160},"requirements":{"minecraft:bricks":12,"minecraft:polished_diorite":41,"minecraft:stone_bricks":5},"sha256":"dfc97eb86c94d51331ccd12e46152dd8a7c17e4db1a5cfa24584501504863a8d","size":{"x":32,"y":1,"z":32}},{"blockCount":175,"bytes":3967,"file":"chunks/y068-z160-x032.json","offset":{"x":32,"y":68,"z":160},"requirements":{"minecraft:bricks":50,"minecraft:polished_diorite":93,"minecraft:stone_bricks":32},"sha256":"cdb6124a2817ad4333fc66dfd464902230c347888f45a9d4198a1bb2f10d7859","size":{"x":32,"y":1,"z":32}},{"blockCount":186,"bytes":4448,"file":"chunks/y068-z160-x064.json","offset":{"x":64,"y":68,"z":160},"requirements":{"minecraft:bricks":71,"minecraft:polished_diorite":72,"minecraft:stone_bricks":43},"sha256":"5ac32d31d6151813e74895b508ff9ddfc7e6f6acc7367494b89d464a0f8d543a","size":{"x":32,"y":1,"z":32}},{"blockCount":70,"bytes":2513,"file":"chunks/y068-z160-x096.json","offset":{"x":96,"y":68,"z":160},"requirements":{"minecraft:bricks":37,"minecraft:glass":4,"minecraft:stone_bricks":29},"sha256":"3e616788e5df7a0714a6cbcd81ae4cba322f82d7330213711c502bcf0ab037e1","size":{"x":32,"y":1,"z":32}},{"blockCount":155,"bytes":4419,"file":"chunks/y068-z160-x128.json","offset":{"x":128,"y":68,"z":160},"requirements":{"minecraft:bricks":67,"minecraft:glass":4,"minecraft:polished_diorite":36,"minecraft:stone_bricks":48},"sha256":"41acef5b80485aa5f4cdfca5bf6b76b04838637185df24889cdad16ac0003c53","size":{"x":32,"y":1,"z":32}},{"blockCount":185,"bytes":4134,"file":"chunks/y068-z160-x160.json","offset":{"x":160,"y":68,"z":160},"requirements":{"minecraft:bricks":77,"minecraft:polished_diorite":63,"minecraft:stone_bricks":45},"sha256":"d9d84773e2bee0fc5628e372f551055524577c34e2d77e85baf62d88792e9192","size":{"x":32,"y":1,"z":32}},{"blockCount":265,"bytes":5514,"file":"chunks/y068-z160-x192.json","offset":{"x":192,"y":68,"z":160},"requirements":{"minecraft:bricks":153,"minecraft:oak_planks":4,"minecraft:polished_diorite":59,"minecraft:sandstone":1,"minecraft:spruce_planks":2,"minecraft:stone_bricks":46},"sha256":"109f6dfafb1b1ce44a555cf4dfdaa63eacaf020a896176535c9d4f2a500dd085","size":{"x":32,"y":1,"z":32}},{"blockCount":156,"bytes":4720,"file":"chunks/y068-z160-x224.json","offset":{"x":224,"y":68,"z":160},"requirements":{"minecraft:bricks":82,"minecraft:oak_planks":6,"minecraft:polished_diorite":34,"minecraft:spruce_planks":2,"minecraft:stone_bricks":32},"sha256":"31e38749047c137d55038759e9cd5491c35425588384d3bc05f9435813009617","size":{"x":32,"y":1,"z":32}},{"blockCount":132,"bytes":3077,"file":"chunks/y068-z192-x064.json","offset":{"x":64,"y":68,"z":192},"requirements":{"minecraft:bricks":33,"minecraft:polished_diorite":75,"minecraft:stone_bricks":24},"sha256":"01fcd07a0a8fa79d1dbcf91b393779633dc2369123ca28de066c59ced7591ad7","size":{"x":32,"y":1,"z":32}},{"blockCount":212,"bytes":2774,"file":"chunks/y068-z192-x096.json","offset":{"x":96,"y":68,"z":192},"requirements":{"minecraft:bricks":123,"minecraft:glass":2,"minecraft:polished_diorite":57,"minecraft:stone_bricks":30},"sha256":"b7f2680bd8be79b7070f725125861c3f0052c7ad8c2b8dc4d2c1080168dd598c","size":{"x":32,"y":1,"z":32}},{"blockCount":264,"bytes":4537,"file":"chunks/y068-z192-x128.json","offset":{"x":128,"y":68,"z":192},"requirements":{"minecraft:bricks":109,"minecraft:glass":2,"minecraft:polished_diorite":108,"minecraft:sandstone":1,"minecraft:stone_bricks":44},"sha256":"e2fe030cf9143ded26d08baf17a18ad6eb6414f3f480c7a9a976df36366e4baf","size":{"x":32,"y":1,"z":32}},{"blockCount":8,"bytes":909,"file":"chunks/y068-z192-x160.json","offset":{"x":160,"y":68,"z":192},"requirements":{"minecraft:polished_diorite":6,"minecraft:stone_bricks":2},"sha256":"b3bf027d45f3e6ce232fa76c9dc09bb59783bee4e902abbebdc432a193ae7746","size":{"x":32,"y":1,"z":32}},{"blockCount":78,"bytes":2176,"file":"chunks/y069-z000-x352.json","offset":{"x":352,"y":69,"z":0},"requirements":{"minecraft:cobbled_deepslate":58,"minecraft:polished_diorite":20},"sha256":"42751d4b38dfc3fb2ccead653a298808f982bf6517014e3cc145c3fc429cfa85","size":{"x":32,"y":1,"z":32}},{"blockCount":13,"bytes":894,"file":"chunks/y069-z000-x384.json","offset":{"x":384,"y":69,"z":0},"requirements":{"minecraft:glass":4,"minecraft:stone_bricks":9},"sha256":"8319e2ff765f1966c7743bd042e116ae5bc0c92f308bac7c31b5d807b366e72a","size":{"x":32,"y":1,"z":32}},{"blockCount":174,"bytes":3633,"file":"chunks/y069-z064-x064.json","offset":{"x":64,"y":69,"z":64},"requirements":{"minecraft:bricks":39,"minecraft:polished_diorite":101,"minecraft:stone_bricks":34},"sha256":"c3f11ab83d4e159790d184f39a9a1d63960f5036c4073b0eb8c74d803b82b9af","size":{"x":32,"y":1,"z":32}},{"blockCount":224,"bytes":3599,"file":"chunks/y069-z064-x096.json","offset":{"x":96,"y":69,"z":64},"requirements":{"minecraft:bricks":105,"minecraft:glass":3,"minecraft:polished_diorite":59,"minecraft:sandstone":3,"minecraft:stone_bricks":54},"sha256":"069800306b81666bea9e68527c58a37eaaa5cc1aa790d816db62cfcf0794f193","size":{"x":32,"y":1,"z":32}},{"blockCount":324,"bytes":5832,"file":"chunks/y069-z064-x128.json","offset":{"x":128,"y":69,"z":64},"requirements":{"minecraft:bricks":111,"minecraft:glass":3,"minecraft:polished_diorite":138,"minecraft:sandstone":3,"minecraft:stone_bricks":69},"sha256":"e7c5ae2e575952d518f5330d15be2d4ce78006de04cf8140119df27751ad1290","size":{"x":32,"y":1,"z":32}},{"blockCount":9,"bytes":946,"file":"chunks/y069-z064-x160.json","offset":{"x":160,"y":69,"z":64},"requirements":{"minecraft:polished_diorite":7,"minecraft:stone_bricks":2},"sha256":"cdafd0c9dda0a715153ef75c4ed2e5635f068ca72f5dc60718bea33eb2edb85a","size":{"x":32,"y":1,"z":32}},{"blockCount":21,"bytes":1094,"file":"chunks/y069-z064-x192.json","offset":{"x":192,"y":69,"z":64},"requirements":{"minecraft:polished_diorite":13,"minecraft:stone_bricks":8},"sha256":"3bc07f032617565e7a98d940b1a8f7b2a48707aaf25fe856200b68008649835c","size":{"x":32,"y":1,"z":32}},{"blockCount":25,"bytes":1172,"file":"chunks/y069-z064-x224.json","offset":{"x":224,"y":69,"z":64},"requirements":{"minecraft:polished_diorite":16,"minecraft:stone_bricks":9},"sha256":"95733e036f3fe1b36da1165a27b70027a552a5da0b7f07fb4741ab2beffeef83","size":{"x":32,"y":1,"z":32}},{"blockCount":111,"bytes":2844,"file":"chunks/y069-z096-x000.json","offset":{"x":0,"y":69,"z":96},"requirements":{"minecraft:bricks":24,"minecraft:polished_diorite":73,"minecraft:stone_bricks":14},"sha256":"7ad8b180531e7efa6097cef9b55b8c3b29527732cacdad04df2564315f924a16","size":{"x":32,"y":1,"z":32}},{"blockCount":247,"bytes":5081,"file":"chunks/y069-z096-x032.json","offset":{"x":32,"y":69,"z":96},"requirements":{"minecraft:bricks":86,"minecraft:glass":4,"minecraft:polished_diorite":104,"minecraft:sandstone":3,"minecraft:stone_bricks":50},"sha256":"5d40098ae3fba3f8192dac228b7e07430095568e42e739c63314fc8316b21002","size":{"x":32,"y":1,"z":32}}],"schema":1}
