{"entries":[{"blockCount":233,"bytes":5057,"file":"chunks/y069-z096-x064.json","offset":{"x":64,"y":69,"z":96},"requirements":{"minecraft:bricks":107,"minecraft:glass":4,"minecraft:polished_diorite":60,"minecraft:sandstone":4,"minecraft:stone_bricks":58},"sha256":"fd94f0d0516ff3b28e1cbc46b2e97fc21e259da20a469fa1b6698be10fb4b8ee","size":{"x":32,"y":1,"z":32}},{"blockCount":81,"bytes":2727,"file":"chunks/y069-z096-x096.json","offset":{"x":96,"y":69,"z":96},"requirements":{"minecraft:bricks":48,"minecraft:glass":6,"minecraft:sandstone":2,"minecraft:stone_bricks":25},"sha256":"4bb3a655a113f086bb806f50284cf5e8bfa6ea5f7e9e8aabbe0f2ffb1aae957a","size":{"x":32,"y":1,"z":32}},{"blockCount":172,"bytes":4799,"file":"chunks/y069-z096-x128.json","offset":{"x":128,"y":69,"z":96},"requirements":{"minecraft:bricks":88,"minecraft:glass":8,"minecraft:polished_diorite":21,"minecraft:sandstone":3,"minecraft:stone_bricks":52},"sha256":"5eafb293de1fd987b4f79bb962c7ff6fe7fd3f1169badb2636d4789b56f6eaf6","size":{"x":32,"y":1,"z":32}},{"blockCount":264,"bytes":5148,"file":"chunks/y069-z096-x160.json","offset":{"x":160,"y":69,"z":96},"requirements":{"minecraft:bricks":124,"minecraft:glass":5,"minecraft:polished_diorite":71,"minecraft:sandstone":5,"minecraft:stone_bricks":59},"sha256":"24a75fdfaae92c35b46f85499c7b90c00332f9a1ba0a1cf107557a72739580b1","size":{"x":32,"y":1,"z":32}},{"blockCount":324,"bytes":5931,"file":"chunks/y069-z096-x192.json","offset":{"x":192,"y":69,"z":96},"requirements":{"minecraft:bricks":200,"minecraft:glass":5,"minecraft:oak_planks":4,"minecraft:polished_diorite":55,"minecraft:sandstone":4,"minecraft:spruce_planks":2,"minecraft:stone_bricks":54},"sha256":"3f0eb998d06307c84a9b39878ec27ad7ce234ae8b0f840027c89add16017c7ed","size":{"x":32,"y":1,"z":32}},{"blockCount":187,"bytes":5157,"file":"chunks/y069-z096-x224.json","offset":{"x":224,"y":69,"z":96},"requirements":{"minecraft:bricks":94,"minecraft:oak_planks":6,"minecraft:polished_diorite":54,"minecraft:spruce_planks":2,"minecraft:stone_bricks":31},"sha256":"f3b8df9cf46db5aa99c3263dbab8072cbe940399ee4adae62adcbbc3caec73db","size":{"x":32,"y":1,"z":32}},{"blockCount":188,"bytes":4394,"file":"chunks/y069-z128-x000.json","offset":{"x":0,"y":69,"z":128},"requirements":{"minecraft:bricks":53,"minecraft:polished_diorite":101,"minecraft:stone_bricks":34},"sha256":"94a93c4dcdb3415ed95f1ec77b973d38e7408b9f9255cf32ed5a473d1a875b28","size":{"x":32,"y":1,"z":32}},{"blockCount":103,"bytes":2946,"file":"chunks/y069-z128-x032.json","offset":{"x":32,"y":69,"z":128},"requirements":{"minecraft:bricks":46,"minecraft:glass":6,"minecraft:polished_diorite":22,"minecraft:sandstone":5,"minecraft:stone_bricks":24},"sha256":"0b81c7d1a0c7f19c026631e3b54403a3967a15f1e2db973523cb824a5d4baed4","size":{"x":32,"y":1,"z":32}},{"blockCount":48,"bytes":1545,"file":"chunks/y069-z128-x064.json","offset":{"x":64,"y":69,"z":128},"requirements":{"minecraft:bricks":25,"minecraft:glass":4,"minecraft:sandstone":4,"minecraft:stone_bricks":15},"sha256":"212b4580dc9e9363d3a936492d49ac4abe5d7dfa8f67fa039b5e397cefb2dfb5","size":{"x":32,"y":1,"z":32}},{"blockCount":13,"bytes":951,"file":"chunks/y069-z128-x096.json","offset":{"x":96,"y":69,"z":128},"requirements":{"minecraft:bricks":7,"minecraft:glass":3,"minecraft:stone_bricks":3},"sha256":"525414199d98cef0d83a6ffa6b0161c142e82ac74d6007c0f21c083917c54601","size":{"x":32,"y":1,"z":32}},{"blockCount":35,"bytes":1451,"file":"chunks/y069-z128-x128.json","offset":{"x":128,"y":69,"z":128},"requirements":{"minecraft:bricks":18,"minecraft:glass":5,"minecraft:sandstone":1,"minecraft:stone_bricks":11},"sha256":"d07f11c2735ef7246d9827775e59042b44ca8d96844826828a630769922e4b40","size":{"x":32,"y":1,"z":32}},{"blockCount":49,"bytes":1585,"file":"chunks/y069-z128-x160.json","offset":{"x":160,"y":69,"z":128},"requirements":{"minecraft:bricks":26,"minecraft:glass":5,"minecraft:sandstone":5,"minecraft:stone_bricks":13},"sha256":"1df81140c255f4ecd6dbebef6ea19968a711874fa28fa4dbb5d4e9f0edf8f96c","size":{"x":32,"y":1,"z":32}},{"blockCount":66,"bytes":2058,"file":"chunks/y069-z128-x192.json","offset":{"x":192,"y":69,"z":128},"requirements":{"minecraft:bricks":45,"minecraft:glass":5,"minecraft:sandstone":4,"minecraft:stone_bricks":12},"sha256":"e5cc566b97d70376169d0093bc22ffcf7a7ad623d36419b3819bece04b863345","size":{"x":32,"y":1,"z":32}},{"blockCount":178,"bytes":4584,"file":"chunks/y069-z128-x224.json","offset":{"x":224,"y":69,"z":128},"requirements":{"minecraft:bricks":60,"minecraft:polished_diorite":75,"minecraft:stone_bricks":43},"sha256":"f68c00c83dae3b7205142dd62cbbbb312b748588075cdba39dff265e77c5599e","size":{"x":32,"y":1,"z":32}},{"blockCount":4,"bytes":797,"file":"chunks/y069-z128-x320.json","offset":{"x":320,"y":69,"z":128},"requirements":{"minecraft:cobbled_deepslate":1,"minecraft:glass":1,"minecraft:polished_diorite":2},"sha256":"2cd08e1395a897535d448857aa0a81b852e3c29e5175560b8e1de96395939aa8","size":{"x":32,"y":1,"z":32}},{"blockCount":64,"bytes":1925,"file":"chunks/y069-z160-x000.json","offset":{"x":0,"y":69,"z":160},"requirements":{"minecraft:bricks":14,"minecraft:polished_diorite":46,"minecraft:stone_bricks":4},"sha256":"ffc102ef339a360b1741508fcd82c04a9e7ab6a5ae101de3131df44c94439ec7","size":{"x":32,"y":1,"z":32}},{"blockCount":200,"bytes":4176,"file":"chunks/y069-z160-x032.json","offset":{"x":32,"y":69,"z":160},"requirements":{"minecraft:bricks":62,"minecraft:polished_diorite":104,"minecraft:stone_bricks":34},"sha256":"30ca7a4858092e2dab0a58cf620fa27a62440cd8465a2e0fbf262f596854f14e","size":{"x":32,"y":1,"z":32}},{"blockCount":219,"bytes":4789,"file":"chunks/y069-z160-x064.json","offset":{"x":64,"y":69,"z":160},"requirements":{"minecraft:bricks":89,"minecraft:polished_diorite":82,"minecraft:stone_bricks":48},"sha256":"72c1906cc25144de8e8dd76400317ab396f1a4e51795e455ad50107031b1fbf9","size":{"x":32,"y":1,"z":32}},{"blockCount":85,"bytes":2920,"file":"chunks/y069-z160-x096.json","offset":{"x":96,"y":69,"z":160},"requirements":{"minecraft:bricks":51,"minecraft:glass":4,"minecraft:sandstone":3,"minecraft:stone_bricks":27},"sha256":"2b17ddec25abd00c676c54fda1c09d64c7f2a935bb34bb87ec1f99cd64527c0a","size":{"x":32,"y":1,"z":32}},{"blockCount":189,"bytes":4998,"file":"chunks/y069-z160-x128.json","offset":{"x":128,"y":69,"z":160},"requirements":{"minecraft:bricks":89,"minecraft:glass":4,"minecraft:polished_diorite":41,"minecraft:sandstone":3,"minecraft:stone_bricks":52},"sha256":"015e49f6c46bce827cc307722fbd6877bc8b387e1576bafa65b360877e98b7c5","size":{"x":32,"y":1,"z":32}},{"blockCount":216,"bytes":4190,"file":"chunks/y069-z160-x160.json","offset":{"x":160,"y":69,"z":160},"requirements":{"minecraft:bricks":98,"minecraft:polished_diorite":72,"minecraft:stone_bricks":46},"sha256":"dfa5ada035eb7903b758fcd3de2cd644dddaaf0f0e37cb3924149aa0719eb355","size":{"x":32,"y":1,"z":32}},{"blockCount":291,"bytes":5470,"file":"chunks/y069-z160-x192.json","offset":{"x":192,"y":69,"z":160},"requirements":{"minecraft:bricks":167,"minecraft:oak_planks":4,"minecraft:polished_diorite":68,"minecraft:spruce_planks":2,"minecraft:stone_bricks":50},"sha256":"be64e2c13a1806397d3ee5463af0cdbc03967a3876e794fd927508be4e0621d8","size":{"x":32,"y":1,"z":32}},{"blockCount":161,"bytes":4720,"file":"chunks/y069-z160-x224.json","offset":{"x":224,"y":69,"z":160},"requirements":{"minecraft:bricks":80,"minecraft:oak_planks":6,"minecraft:polished_diorite":43,"minecraft:spruce_planks":2,"minecraft:stone_bricks":30},"sha256":"3e8334f08c4dc74518bd609ecee5cc9891edcad64909232ae26283a90928c699","size":{"x":32,"y":1,"z":32}},{"blockCount":139,"bytes":3001,"file":"chunks/y069-z192-x064.json","offset":{"x":64,"y":69,"z":192},"requirements":{"minecraft:bricks":32,"minecraft:polished_diorite":79,"minecraft:stone_bricks":28},"sha256":"da1acfacde15443acea5cfa06a4f156b52961be1e7661bc2879139c1db2fe5c7","size":{"x":32,"y":1,"z":32}},{"blockCount":205,"bytes":3138,"file":"chunks/y069-z192-x096.json","offset":{"x":96,"y":69,"z":192},"requirements":{"minecraft:bricks":93,"minecraft:glass":2,"minecraft:polished_diorite":59,"minecraft:sandstone":2,"minecraft:stone_bricks":49},"sha256":"4512b1b516ea32b85ca3457293380103d0c8b730af4258533daa59613c7bc769","size":{"x":32,"y":1,"z":32}},{"blockCount":271,"bytes":4800,"file":"chunks/y069-z192-x128.json","offset":{"x":128,"y":69,"z":192},"requirements":{"minecraft:bricks":92,"minecraft:glass":2,"minecraft:polished_diorite":117,"minecraft:sandstone":2,"minecraft:stone_bricks":58},"sha256":"615545a3d99b826bd0aa21011c3c633bfc3b276fbebceabac4401c13e83d4f2b","size":{"x":32,"y":1,"z":32}},{"blockCount":8,"bytes":909,"file":"chunks/y069-z192-x160.json","offset":{"x":160,"y":69,"z":192},"requirements":{"minecraft:polished_diorite":6,"minecraft:stone_bricks":2},"sha256":"baf45cb0bfdd8753b41909f6dd8619f0a3f854de53327c48d471d91954f89139","size":{"x":32,"y":1,"z":32}},{"blockCount":70,"bytes":1686,"file":"chunks/y070-z000-x352.json","offset":{"x":352,"y":70,"z":0},"requirements":{"minecraft:cobbled_deepslate":70},"sha256":"911c5fda888cb97642d0891b30bd59d596acbf6bb93635e53da7fa755df45396","size":{"x":32,"y":1,"z":32}},{"blockCount":9,"bytes":894,"file":"chunks/y070-z000-x384.json","offset":{"x":384,"y":70,"z":0},"requirements":{"minecraft:glass":4,"minecraft:stone_bricks":5},"sha256":"646aef60008ea6176bf8da7f3e13766eb8d338532412647fdeaf853ba9e34c56","size":{"x":32,"y":1,"z":32}},{"blockCount":158,"bytes":3769,"file":"chunks/y070-z064-x064.json","offset":{"x":64,"y":70,"z":64},"requirements":{"minecraft:bricks":37,"minecraft:polished_diorite":78,"minecraft:sandstone":1,"minecraft:stone_bricks":42},"sha256":"77add9291b799749a7009658ea252490fe7967dc71be934532f5150e57451c0a","size":{"x":32,"y":1,"z":32}},{"blockCount":217,"bytes":3826,"file":"chunks/y070-z064-x096.json","offset":{"x":96,"y":70,"z":64},"requirements":{"minecraft:bricks":95,"minecraft:glass":3,"minecraft:polished_diorite":58,"minecraft:sandstone":20,"minecraft:stone_bricks":41},"sha256":"2b279e6a84b92bd7493c3cac3c0c17639da251583707471fac59ba05a03a4786","size":{"x":32,"y":1,"z":32}},{"blockCount":310,"bytes":6018,"file":"chunks/y070-z064-x128.json","offset":{"x":128,"y":70,"z":64},"requirements":{"minecraft:bricks":108,"minecraft:glass":3,"minecraft:polished_diorite":116,"minecraft:sandstone":13,"minecraft:stone_bricks":70},"sha256":"896e3a5a367276996b4dda848840eab764d4405989ee0447286c59f320918c5c","size":{"x":32,"y":1,"z":32}},{"blockCount":7,"bytes":881,"file":"chunks/y070-z064-x160.json","offset":{"x":160,"y":70,"z":64},"requirements":{"minecraft:polished_diorite":7},"sha256":"00e07536fcc99b1a3967ad8898ce28b0eebc9a75e6b6a9f9bf3332799bbd8346","size":{"x":32,"y":1,"z":32}},{"blockCount":22,"bytes":1017,"file":"chunks/y070-z064-x192.json","offset":{"x":192,"y":70,"z":64},"requirements":{"minecraft:polished_diorite":13,"minecraft:stone_bricks":9},"sha256":"522d5397f708633bc902263dad7cb9c02d1a9af54a7d9cc7466421a6bfa353e7","size":{"x":32,"y":1,"z":32}},{"blockCount":25,"bytes":1056,"file":"chunks/y070-z064-x224.json","offset":{"x":224,"y":70,"z":64},"requirements":{"minecraft:polished_diorite":16,"minecraft:stone_bricks":9},"sha256":"a46996da6b8330871f67a7ad22bb97b4fdd145efbb3ea81af2002520d9bdc03f","size":{"x":32,"y":1,"z":32}},{"blockCount":98,"bytes":3014,"file":"chunks/y070-z096-x000.json","offset":{"x":0,"y":70,"z":96},"requirements":{"minecraft:bricks":21,"minecraft:polished_diorite":56,"minecraft:stone_bricks":21},"sha256":"a8feb10f0075fea23423ae380eaedf9b53eea2c40917c0ee6d9511738c47125b","size":{"x":32,"y":1,"z":32}},{"blockCount":273,"bytes":5716,"file":"chunks/y070-z096-x032.json","offset":{"x":32,"y":70,"z":96},"requirements":{"minecraft:bricks":108,"minecraft:glass":4,"minecraft:polished_diorite":89,"minecraft:sandstone":5,"minecraft:stone_bricks":67},"sha256":"04cd6bf9f5a847494efe970318f4ce3beb67541895ce2a2c76de4de281a1968c","size":{"x":32,"y":1,"z":32}},{"blockCount":265,"bytes":5680,"file":"chunks/y070-z096-x064.json","offset":{"x":64,"y":70,"z":96},"requirements":{"minecraft:bricks":127,"minecraft:glass":4,"minecraft:polished_diorite":39,"minecraft:sandstone":8,"minecraft:stone_bricks":87},"sha256":"d0944d34920e2f475dcc975f3ae839cb5fb2e33e33bd3ebf44eb532c81032897","size":{"x":32,"y":1,"z":32}},{"blockCount":88,"bytes":2862,"file":"chunks/y070-z096-x096.json","offset":{"x":96,"y":70,"z":96},"requirements":{"minecraft:bricks":61,"minecraft:glass":6,"minecraft:sandstone":3,"minecraft:stone_bricks":18},"sha256":"b3fa8b3426544b225f7ce4f968911dd54ffecc88580dc5f4d96fb94d26304dc2","size":{"x":32,"y":1,"z":32}},{"blockCount":213,"bytes":5386,"file":"chunks/y070-z096-x128.json","offset":{"x":128,"y":70,"z":96},"requirements":{"minecraft:bricks":109,"minecraft:glass":8,"minecraft:polished_diorite":16,"minecraft:sandstone":7,"minecraft:stone_bricks":73},"sha256":"cded2fc4d58e63b0974d773711348faf6d7e17eaa155a8a435b4a5db8fc6656a","size":{"x":32,"y":1,"z":32}},{"blockCount":263,"bytes":5411,"file":"chunks/y070-z096-x160.json","offset":{"x":160,"y":70,"z":96},"requirements":{"minecraft:bricks":146,"minecraft:glass":5,"minecraft:polished_diorite":41,"minecraft:sandstone":7,"minecraft:stone_bricks":64},"sha256":"d82567d317897b914d17ef48267c322e8d5f154484196d66a0003d8c3750ce7a","size":{"x":32,"y":1,"z":32}},{"blockCount":327,"bytes":5986,"file":"chunks/y070-z096-x192.json","offset":{"x":192,"y":70,"z":96},"requirements":{"minecraft:bricks":216,"minecraft:glass":15,"minecraft:oak_planks":4,"minecraft:polished_diorite":35,"minecraft:sandstone":5,"minecraft:spruce_planks":1,"minecraft:stone_bricks":51},"sha256":"05e33c9031f86cfbbfa363ddcb2c523e448087c71f4ec5877ff2bcd9383d6bfc","size":{"x":32,"y":1,"z":32}},{"blockCount":195,"bytes":5182,"file":"chunks/y070-z096-x224.json","offset":{"x":224,"y":70,"z":96},"requirements":{"minecraft:bricks":89,"minecraft:glass":13,"minecraft:oak_planks":6,"minecraft:polished_diorite":50,"minecraft:sandstone":4,"minecraft:spruce_planks":3,"minecraft:stone_bricks":30},"sha256":"cd83ed53d0ca460ad1fac95ae8c356a9d5b31cd1e185cb80e7a6658a525815b4","size":{"x":32,"y":1,"z":32}},{"blockCount":189,"bytes":4772,"file":"chunks/y070-z128-x000.json","offset":{"x":0,"y":70,"z":128},"requirements":{"minecraft:bricks":57,"minecraft:polished_diorite":74,"minecraft:stone_bricks":58},"sha256":"fa99003f3f08a48605b9d3aab89e6ce47c212cab643364f4dd64a46cce5cc814","size":{"x":32,"y":1,"z":32}},{"blockCount":125,"bytes":3213,"file":"chunks/y070-z128-x032.json","offset":{"x":32,"y":70,"z":128},"requirements":{"minecraft:bricks":49,"minecraft:glass":6,"minecraft:polished_diorite":31,"minecraft:sandstone":9,"minecraft:stone_bricks":30},"sha256":"2682ada1446fc7bbd4470f8a6d08b02ed833ce28b9f056a996653c3dbb3bae8d","size":{"x":32,"y":1,"z":32}},{"blockCount":50,"bytes":1431,"file":"chunks/y070-z128-x064.json","offset":{"x":64,"y":70,"z":128},"requirements":{"minecraft:bricks":30,"minecraft:glass":4,"minecraft:sandstone":4,"minecraft:stone_bricks":12},"sha256":"030d63329de6023b8ba6205f4552c2de25a6a46f4afe5721a0a8dc1291390814","size":{"x":32,"y":1,"z":32}},{"blockCount":15,"bytes":975,"file":"chunks/y070-z128-x096.json","offset":{"x":96,"y":70,"z":128},"requirements":{"minecraft:bricks":8,"minecraft:glass":3,"minecraft:sandstone":1,"minecraft:stone_bricks":3},"sha256":"be57186f4b207ca1d3fdf0936d4f8cf3ee7cbe5bb15d6d29641f6189d46bddbb","size":{"x":32,"y":1,"z":32}},{"blockCount":39,"bytes":1375,"file":"chunks/y070-z128-x128.json","offset":{"x":128,"y":70,"z":128},"requirements":{"minecraft:bricks":22,"minecraft:glass":5,"minecraft:sandstone":2,"minecraft:stone_bricks":10},"sha256":"d4da6b8d8c52e5447ce299eab207015e8af6db06cba669f76fc7ab191fb008ba","size":{"x":32,"y":1,"z":32}},{"blockCount":50,"bytes":1490,"file":"chunks/y070-z128-x160.json","offset":{"x":160,"y":70,"z":128},"requirements":{"minecraft:bricks":30,"minecraft:glass":5,"minecraft:sandstone":5,"minecraft:stone_bricks":10},"sha256":"825e89daddce58e537adf70a1a45e9536ca6893d2289dc83bacaa6d78a7740e9","size":{"x":32,"y":1,"z":32}},{"blockCount":65,"bytes":1904,"file":"chunks/y070-z128-x192.json","offset":{"x":192,"y":70,"z":128},"requirements":{"minecraft:bricks":46,"minecraft:glass":5,"minecraft:sandstone":4,"minecraft:stone_bricks":10},"sha256":"1d239a0ffe5d6c930ee9445f9e6a2fe1424bbc1bdf39109cb679bb5d43d151da","size":{"x":32,"y":1,"z":32}},{"blockCount":168,"bytes":4343,"file":"chunks/y070-z128-x224.json","offset":{"x":224,"y":70,"z":128},"requirements":{"minecraft:bricks":37,"minecraft:polished_diorite":74,"minecraft:sandstone":22,"minecraft:stone_bricks":35},"sha256":"5c8e8726a00e02e15d2cb125e0caa26063105b36b4ce74ab43813444e9766fa9","size":{"x":32,"y":1,"z":32}},{"blockCount":1,"bytes":637,"file":"chunks/y070-z128-x320.json","offset":{"x":320,"y":70,"z":128},"requirements":{"minecraft:glass":1},"sha256":"fdbc69d0e88ca59de69146b7734b5f388ef3bacc82651f181747ab464aa19b21","size":{"x":32,"y":1,"z":32}},{"blockCount":52,"bytes":1982,"file":"chunks/y070-z160-x000.json","offset":{"x":0,"y":70,"z":160},"requirements":{"minecraft:bricks":12,"minecraft:polished_diorite":32,"minecraft:stone_bricks":8},"sha256":"88ef80f713b4f9a2c22b544d2f73bc9e31e124d6cd0089b0f2d95ef573fc81ef","size":{"x":32,"y":1,"z":32}},{"blockCount":208,"bytes":4533,"file":"chunks/y070-z160-x032.json","offset":{"x":32,"y":70,"z":160},"requirements":{"minecraft:bricks":75,"minecraft:polished_diorite":86,"minecraft:sandstone":2,"minecraft:stone_bricks":45},"sha256":"fb5c42e55964fc02b41187970881e581607499d74d0c974c8a59aab8a017962b","size":{"x":32,"y":1,"z":32}},{"blockCount":250,"bytes":5550,"file":"chunks/y070-z160-x064.json","offset":{"x":64,"y":70,"z":160},"requirements":{"minecraft:bricks":106,"minecraft:polished_diorite":54,"minecraft:sandstone":4,"minecraft:stone_bricks":86},"sha256":"46249edbeb9b2630721b430039a76cce0d8468fb4a844d9536512136c3154dca","size":{"x":32,"y":1,"z":32}},{"blockCount":92,"bytes":3094,"file":"chunks/y070-z160-x096.json","offset":{"x":96,"y":70,"z":160},"requirements":{"minecraft:bricks":66,"minecraft:glass":4,"minecraft:sandstone":3,"minecraft:stone_bricks":19},"sha256":"1b3e44e24b63a76bf82f9dccd6f7767c04c16d52a656e875ac5aaab812fd8513","size":{"x":32,"y":1,"z":32}},{"blockCount":227,"bytes":5756,"file":"chunks/y070-z160-x128.json","offset":{"x":128,"y":70,"z":160},"requirements":{"minecraft:bricks":110,"minecraft:glass":4,"minecraft:polished_diorite":29,"minecraft:sandstone":6,"minecraft:stone_bricks":78},"sha256":"c1a00df4465c561b72a6e3650fabd204741d123c95214f49aee8fd6604d3aaff","size":{"x":32,"y":1,"z":32}},{"blockCount":214,"bytes":4555,"file":"chunks/y070-z160-x160.json","offset":{"x":160,"y":70,"z":160},"requirements":{"minecraft:bricks":116,"minecraft:polished_diorite":42,"minecraft:sandstone":2,"minecraft:stone_bricks":54},"sha256":"db4bb93f0e3a0f598b0bfc33da7889b6c98d2949efd298976d0c6f88ce1ad53d","size":{"x":32,"y":1,"z":32}},{"blockCount":294,"bytes":5550,"file":"chunks/y070-z160-x192.json","offset":{"x":192,"y":70,"z":160},"requirements":{"minecraft:bricks":180,"minecraft:glass":10,"minecraft:oak_planks":4,"minecraft:polished_diorite":48,"minecraft:sandstone":1,"minecraft:spruce_planks":1,"minecraft:stone_bricks":50},"sha256":"b70aaf9dcb0f8f4b70fd6c2f1c823520fc424165a137b850ef9ea07d2288535d","size":{"x":32,"y":1,"z":32}},{"blockCount":171,"bytes":4738,"file":"chunks/y070-z160-x224.json","offset":{"x":224,"y":70,"z":160},"requirements":{"minecraft:bricks":80,"minecraft:glass":13,"minecraft:oak_planks":6,"minecraft:polished_diorite":40,"minecraft:spruce_planks":3,"minecraft:stone_bricks":29},"sha256":"d066ee95c9ec9c9f3a504f47918cf00d58b548b30437d39491061d385515ca0b","size":{"x":32,"y":1,"z":32}},{"blockCount":124,"bytes":3100,"file":"chunks/y070-z192-x064.json","offset":{"x":64,"y":70,"z":192},"requirements":{"minecraft:bricks":29,"minecraft:polished_diorite":63,"minecraft:sandstone":1,"minecraft:stone_bricks":31},"sha256":"d94584ffebc87d50b4f4364064e0b9edd5ac7b3b4ef18f76380ea229caf7fcd1","size":{"x":32,"y":1,"z":32}},{"blockCount":196,"bytes":3345,"file":"chunks/y070-z192-x096.json","offset":{"x":96,"y":70,"z":192},"requirements":{"minecraft:bricks":80,"minecraft:glass":2,"minecraft:polished_diorite":58,"minecraft:sandstone":19,"minecraft:stone_bricks":37},"sha256":"f8c811e7b6dde76d0c6cb9aaae8d1f0c3ffb7c90deec279955bc1914257fc8c4","size":{"x":32,"y":1,"z":32}},{"blockCount":256,"bytes":4891,"file":"chunks/y070-z192-x128.json","offset":{"x":128,"y":70,"z":192},"requirements":{"minecraft:bricks":85,"minecraft:glass":2,"minecraft:polished_diorite":102,"minecraft:sandstone":12,"minecraft:stone_bricks":55},"sha256":"d4ada80806f44eb5eabab4278c5e6b710158637c75bc7cd927121515db419523","size":{"x":32,"y":1,"z":32}},{"blockCount":6,"bytes":844,"file":"chunks/y070-z192-x160.json","offset":{"x":160,"y":70,"z":192},"requirements":{"minecraft:polished_diorite":6},"sha256":"af914bc5d34029c5f3470fe91f639173243612d52f4310ee3191fdaab8654c1e","size":{"x":32,"y":1,"z":32}},{"blockCount":60,"bytes":1440,"file":"chunks/y071-z000-x352.json","offset":{"x":352,"y":71,"z":0},"requirements":{"minecraft:cobbled_deepslate":56,"minecraft:glass":4},"sha256":"18b5c69f5d314b8109a8e2a9a769a065edcd579601c155479267315d091fe40b","size":{"x":32,"y":1,"z":32}},{"blockCount":5,"bytes":720,"file":"chunks/y071-z000-x384.json","offset":{"x":384,"y":71,"z":0},"requirements":{"minecraft:stone_bricks":5},"sha256":"9f44ece650a7515fe4fa0c3fbf20baaf290db6ed899e48013cf866b9af4e3534","size":{"x":32,"y":1,"z":32}},{"blockCount":185,"bytes":4412,"file":"chunks/y071-z064-x064.json","offset":{"x":64,"y":71,"z":64},"requirements":{"minecraft:bricks":35,"minecraft:polished_diorite":119,"minecraft:stone_bricks":31},"sha256":"2dbbaa44e0f2201073fdedcb1e4aeff384d7da764dec14515606709854930f0e","size":{"x":32,"y":1,"z":32}},{"blockCount":223,"bytes":4224,"file":"chunks/y071-z064-x096.json","offset":{"x":96,"y":71,"z":64},"requirements":{"minecraft:bricks":107,"minecraft:polished_diorite":65,"minecraft:sandstone":15,"minecraft:stone_bricks":36},"sha256":"06e8622eb6a0cd9f9c63cc5cdc24f781743f1cb37176d5a4a1f86f78b339ad95","size":{"x":32,"y":1,"z":32}},{"blockCount":331,"bytes":7039,"file":"chunks/y071-z064-x128.json","offset":{"x":128,"y":71,"z":64},"requirements":{"minecraft:bricks":89,"minecraft:polished_diorite":177,"minecraft:sandstone":13,"minecraft:stone_bricks":52},"sha256":"818b9e8902cd0527230b9f344335304bec3247c599ddc9b71ffa0a68b6855641","size":{"x":32,"y":1,"z":32}},{"blockCount":17,"bytes":1104,"file":"chunks/y071-z064-x160.json","offset":{"x":160,"y":71,"z":64},"requirements":{"minecraft:polished_diorite":15,"minecraft:stone_bricks":2},"sha256":"c83e0fb3606c4f9c0b73175dd0dd570e95e5b6071e064b4a70550423b0630ae2","size":{"x":32,"y":1,"z":32}},{"blockCount":31,"bytes":1132,"file":"chunks/y071-z064-x192.json","offset":{"x":192,"y":71,"z":64},"requirements":{"minecraft:polished_diorite":24,"minecraft:stone_bricks":7},"sha256":"268524fb4ae637a5eac74a1f934962e27bb351b73425e4e3eac35e4599000ad3","size":{"x":32,"y":1,"z":32}},{"blockCount":36,"bytes":1247,"file":"chunks/y071-z064-x224.json","offset":{"x":224,"y":71,"z":64},"requirements":{"minecraft:polished_diorite":28,"minecraft:stone_bricks":8},"sha256":"5c6e79e10d073b8047807e5dad5f437a1a23bfd4d31103d9d2a427fb8cc1ac5d","size":{"x":32,"y":1,"z":32}},{"blockCount":144,"bytes":3097,"file":"chunks/y071-z096-x000.json","offset":{"x":0,"y":71,"z":96},"requirements":{"minecraft:bricks":26,"minecraft:polished_diorite":109,"minecraft:sandstone":1,"minecraft:stone_bricks":8},"sha256":"6ce6417102680335cbaa2ba9722e0ffa980d64b26a50ba5c32a6e0e58dc333e9","size":{"x":32,"y":1,"z":32}},{"blockCount":325,"bytes":6059,"file":"chunks/y071-z096-x032.json","offset":{"x":32,"y":71,"z":96},"requirements":{"minecraft:bricks":119,"minecraft:polished_diorite":134,"minecraft:sandstone":15,"minecraft:stone_bricks":57},"sha256":"9275bd17e48773a38ae6ecc7f052194e9509bc95277dcce4feda486c88015022","size":{"x":32,"y":1,"z":32}},{"blockCount":306,"bytes":6096,"file":"chunks/y071-z096-x064.json","offset":{"x":64,"y":71,"z":96},"requirements":{"minecraft:bricks":134,"minecraft:polished_diorite":74,"minecraft:sandstone":16,"minecraft:stone_bricks":82},"sha256":"c7d1d6596f67b485a889992e9ebd3e927118de3cf603c54b9dc8414f33c1848d","size":{"x":32,"y":1,"z":32}},{"blockCount":93,"bytes":2882,"file":"chunks/y071-z096-x096.json","offset":{"x":96,"y":71,"z":96},"requirements":{"minecraft:bricks":60,"minecraft:sandstone":20,"minecraft:stone_bricks":13},"sha256":"37d116d64e50a2bd33e716058eb69a3e67941d08624d2374d6b322ecf292c345","size":{"x":32,"y":1,"z":32}},{"blockCount":241,"bytes":5748,"file":"chunks/y071-z096-x128.json","offset":{"x":128,"y":71,"z":96},"requirements":{"minecraft:bricks":116,"minecraft:polished_diorite":31,"minecraft:sandstone":27,"minecraft:stone_bricks":67},"sha256":"cf1234b14a5fa8de45ddd69ab1d245aa04b0fe3e3eae07d6454ac7efe57b4402","size":{"x":32,"y":1,"z":32}},{"blockCount":289,"bytes":5791,"file":"chunks/y071-z096-x160.json","offset":{"x":160,"y":71,"z":96},"requirements":{"minecraft:bricks":145,"minecraft:polished_diorite":76,"minecraft:sandstone":17,"minecraft:stone_bricks":51},"sha256":"7ebe31b97313c4115ac1d9943b8422f7d90854762d5405921bd79f55e13a4e3d","size":{"x":32,"y":1,"z":32}},{"blockCount":357,"bytes":5999,"file":"chunks/y071-z096-x192.json","offset":{"x":192,"y":71,"z":96},"requirements":{"minecraft:bricks":188,"minecraft:oak_planks":32,"minecraft:polished_diorite":75,"minecraft:sandstone":18,"minecraft:stone_bricks":44},"sha256":"6440728a2c414a72de470ee96fa446142558c5297954f1fc0e9261565525d164","size":{"x":32,"y":1,"z":32}},{"blockCount":246,"bytes":5292,"file":"chunks/y071-z096-x224.json","offset":{"x":224,"y":71,"z":96},"requirements":{"minecraft:bricks":95,"minecraft:oak_planks":53,"minecraft:polished_diorite":72,"minecraft:sandstone":1,"minecraft:spruce_planks":1,"minecraft:stone_bricks":24},"sha256":"0e416631674a8c30cea5e41469dcda9ad00a52d8ea227a03ce36e1578e8335f4","size":{"x":32,"y":1,"z":32}},{"blockCount":244,"bytes":4778,"file":"chunks/y071-z128-x000.json","offset":{"x":0,"y":71,"z":128},"requirements":{"minecraft:bricks":67,"minecraft:polished_diorite":145,"minecraft:sandstone":3,"minecraft:stone_bricks":29},"sha256":"8730e536ef54ca05a4ed40249a9bee5d80e7eacc6e5a7bf44afe701831d47b5d","size":{"x":32,"y":1,"z":32}},{"blockCount":144,"bytes":3537,"file":"chunks/y071-z128-x032.json","offset":{"x":32,"y":71,"z":128},"requirements":{"minecraft:bricks":56,"minecraft:glass":4,"minecraft:polished_diorite":25,"minecraft:sandstone":31,"minecraft:stone_bricks":28},"sha256":"46abedaf2215f6ef6e1ab3a98b690ad01ca13db21239f55c7a72dabdfa847440","size":{"x":32,"y":1,"z":32}},{"blockCount":52,"bytes":1584,"file":"chunks/y071-z128-x064.json","offset":{"x":64,"y":71,"z":128},"requirements":{"minecraft:bricks":29,"minecraft:sandstone":16,"minecraft:stone_bricks":7},"sha256":"deda3b5ccdb346fb1015fd66dbe2dd882b825897b09268baa30bf0427bc63f82","size":{"x":32,"y":1,"z":32}},{"blockCount":18,"bytes":1013,"file":"chunks/y071-z128-x096.json","offset":{"x":96,"y":71,"z":128},"requirements":{"minecraft:bricks":8,"minecraft:sandstone":8,"minecraft:stone_bricks":2},"sha256":"7c98274d046b0aeda186e354a6f457dc57ee76daf86e6c3e353321169088f716","size":{"x":32,"y":1,"z":32}},{"blockCount":42,"bytes":1415,"file":"chunks/y071-z128-x128.json","offset":{"x":128,"y":71,"z":128},"requirements":{"minecraft:bricks":22,"minecraft:sandstone":14,"minecraft:stone_bricks":6},"sha256":"3db7cc55d33f63385b22dbd8578d5c029c642d51ea963998b94257c3316d3248","size":{"x":32,"y":1,"z":32}},{"blockCount":52,"bytes":1624,"file":"chunks/y071-z128-x160.json","offset":{"x":160,"y":71,"z":128},"requirements":{"minecraft:bricks":29,"minecraft:sandstone":17,"minecraft:stone_bricks":6},"sha256":"05abc578da694ed608c6ba7a5cfa41d4737c6115bb7501b7b4462e8e90e0f31d","size":{"x":32,"y":1,"z":32}},{"blockCount":67,"bytes":1940,"file":"chunks/y071-z128-x192.json","offset":{"x":192,"y":71,"z":128},"requirements":{"minecraft:bricks":44,"minecraft:sandstone":17,"minecraft:stone_bricks":6},"sha256":"53591dcd6aac3ffe9117459ec6e88eb40debac7ba00ccd2391261cc1722f8272","size":{"x":32,"y":1,"z":32}},{"blockCount":177,"bytes":3734,"file":"chunks/y071-z128-x224.json","offset":{"x":224,"y":71,"z":128},"requirements":{"minecraft:bricks":58,"minecraft:polished_diorite":82,"minecraft:sandstone":7,"minecraft:stone_bricks":30},"sha256":"2c0c0bad512295552e53be5f74a7a6c113d2badfcf805202911f7cff80874d7f","size":{"x":32,"y":1,"z":32}},{"blockCount":1,"bytes":637,"file":"chunks/y071-z128-x320.json","offset":{"x":320,"y":71,"z":128},"requirements":{"minecraft:glass":1},"sha256":"5f4172aab2d7fee8609e6ff426f78c3479f96452b31b225a549c84aa93791b42","size":{"x":32,"y":1,"z":32}},{"blockCount":77,"bytes":2041,"file":"chunks/y071-z160-x000.json","offset":{"x":0,"y":71,"z":160},"requirements":{"minecraft:bricks":10,"minecraft:polished_diorite":64,"minecraft:stone_bricks":3},"sha256":"5c31013a4e59b8a058e315266e2413267feda2c5ca8793a2d43b6681aa2e05de","size":{"x":32,"y":1,"z":32}},{"blockCount":249,"bytes":4799,"file":"chunks/y071-z160-x032.json","offset":{"x":32,"y":71,"z":160},"requirements":{"minecraft:bricks":79,"minecraft:polished_diorite":129,"minecraft:sandstone":2,"minecraft:stone_bricks":39},"sha256":"4020c8dac00107b5c341a9959f7696eb74bb3b3e90cd0553440d5bda9b7ef050","size":{"x":32,"y":1,"z":32}},{"blockCount":294,"bytes":6071,"file":"chunks/y071-z160-x064.json","offset":{"x":64,"y":71,"z":160},"requirements":{"minecraft:bricks":113,"minecraft:polished_diorite":98,"minecraft:stone_bricks":83},"sha256":"70fd9b237e23c7f386adcfac4eb616924157535f05fcf7d6dc197ff9d91d9dd4","size":{"x":32,"y":1,"z":32}},{"blockCount":96,"bytes":3037,"file":"chunks/y071-z160-x096.json","offset":{"x":96,"y":71,"z":160},"requirements":{"minecraft:bricks":65,"minecraft:sandstone":16,"minecraft:stone_bricks":15},"sha256":"e04660c1e1d4a1bcf764e1426105750946e1d52e6c94f8b9baaa90b163377fdd","size":{"x":32,"y":1,"z":32}},{"blockCount":258,"bytes":6682,"file":"chunks/y071-z160-x128.json","offset":{"x":128,"y":71,"z":160},"requirements":{"minecraft:bricks":80,"minecraft:polished_diorite":89,"minecraft:sandstone":16,"minecraft:stone_bricks":73},"sha256":"28a286e8134e572dfef74f9be0a9a4d017be6e92f73281ffd56adf07c51d03f5","size":{"x":32,"y":1,"z":32}},{"blockCount":240,"bytes":5289,"file":"chunks/y071-z160-x160.json","offset":{"x":160,"y":71,"z":160},"requirements":{"minecraft:bricks":37,"minecraft:polished_diorite":158,"minecraft:stone_bricks":45},"sha256":"ee4b860995434d1455f2f47416101f266f2f128606671cfb503f441ca1c79bc1","size":{"x":32,"y":1,"z":32}},{"blockCount":330,"bytes":5715,"file":"chunks/y071-z160-x192.json","offset":{"x":192,"y":71,"z":160},"requirements":{"minecraft:bricks":127,"minecraft:oak_planks":32,"minecraft:polished_diorite":124,"minecraft:sandstone":1,"minecraft:stone_bricks":46},"sha256":"aeef3d9de18afe4904e5d6abd0d1c06b425f87f30f846261ceb011a3a8234b1d","size":{"x":32,"y":1,"z":32}},{"blockCount":229,"bytes":5058,"file":"chunks/y071-z160-x224.json","offset":{"x":224,"y":71,"z":160},"requirements":{"minecraft:bricks":82,"minecraft:oak_planks":53,"minecraft:polished_diorite":68,"minecraft:spruce_planks":1,"minecraft:stone_bricks":25},"sha256":"9011f435d19e41231e12d0b24b1516d368ed9ca588c482a9fa5cbd8420e49ef9","size":{"x":32,"y":1,"z":32}},{"blockCount":146,"bytes":3629,"file":"chunks/y071-z192-x064.json","offset":{"x":64,"y":71,"z":192},"requirements":{"minecraft:bricks":16,"minecraft:polished_diorite":107,"minecraft:stone_bricks":23},"sha256":"65cdc26a2a0febe0bbf466395c74ac470593e778538fd6bff19efdc98dcf03b6","size":{"x":32,"y":1,"z":32}},{"blockCount":201,"bytes":3724,"file":"chunks/y071-z192-x096.json","offset":{"x":96,"y":71,"z":192},"requirements":{"minecraft:bricks":83,"minecraft:polished_diorite":74,"minecraft:sandstone":12,"minecraft:stone_bricks":32},"sha256":"51ce6a14df65ca62f12d5b0f5ea8b270923029a105c3ca749e447b3238cb208f","size":{"x":32,"y":1,"z":32}},{"blockCount":271,"bytes":5781,"file":"chunks/y071-z192-x128.json","offset":{"x":128,"y":71,"z":192},"requirements":{"minecraft:bricks":58,"minecraft:polished_diorite":163,"minecraft:sandstone":10,"minecraft:stone_bricks":40},"sha256":"af5ddb20f0b3300c83315e2411e91442463c9bae57a475e8f2e5c040ab6c3b78","size":{"x":32,"y":1,"z":32}},{"blockCount":14,"bytes":1028,"file":"chunks/y071-z192-x160.json","offset":{"x":160,"y":71,"z":192},"requirements":{"minecraft:polished_diorite":12,"minecraft:stone_bricks":2},"sha256":"7dc2d199ffa4803e484434e7d715a2f2714763cbc6e9639c64a7d7c7c3b10022","size":{"x":32,"y":1,"z":32}},{"blockCount":65,"bytes":1342,"file":"chunks/y072-z000-x352.json","offset":{"x":352,"y":72,"z":0},"requirements":{"minecraft:cobbled_deepslate":65},"sha256":"ca9b39d0d7e02ce6e30f6126fa7ddf1d35604862e51bfe0a5172d262fb8e62e4","size":{"x":32,"y":1,"z":32}},{"blockCount":5,"bytes":720,"file":"chunks/y072-z000-x384.json","offset":{"x":384,"y":72,"z":0},"requirements":{"minecraft:stone_bricks":5},"sha256":"736b534d40b8906daeaec02875e139a5d02079476c6244631708d0f59439ee5c","size":{"x":32,"y":1,"z":32}},{"blockCount":311,"bytes":4817,"file":"chunks/y072-z064-x064.json","offset":{"x":64,"y":72,"z":64},"requirements":{"minecraft:bricks":77,"minecraft:polished_diorite":106,"minecraft:sandstone":1,"minecraft:stone_bricks":127},"sha256":"48b9dc4eaeafe16f042d2fb2c573da727102b87d226bd548a9f2a03a55b6a10f","size":{"x":32,"y":1,"z":32}},{"blockCount":268,"bytes":4300,"file":"chunks/y072-z064-x096.json","offset":{"x":96,"y":72,"z":64},"requirements":{"minecraft:bricks":114,"minecraft:polished_diorite":72,"minecraft:sandstone":25,"minecraft:stone_bricks":57},"sha256":"f0f5c197749942e8a8eeb111582cf82be7ae2d1c8f42cca12ab9e50372207058","size":{"x":32,"y":1,"z":32}},{"blockCount":483,"bytes":6735,"file":"chunks/y072-z064-x128.json","offset":{"x":128,"y":72,"z":64},"requirements":{"minecraft:bricks":141,"minecraft:polished_diorite":170,"minecraft:sandstone":24,"minecraft:stone_bricks":148},"sha256":"7161c91b481c0c937609c8d44a2670194bc4698f98ac06f726faebe288d9b105","size":{"x":32,"y":1,"z":32}},{"blockCount":29,"bytes":1432,"file":"chunks/y072-z064-x160.json","offset":{"x":160,"y":72,"z":64},"requirements":{"minecraft:polished_diorite":7,"minecraft:stone_bricks":22},"sha256":"fe30f373c1640eec0437925944752ca975f7e2f79647aff771a8614481210499","size":{"x":32,"y":1,"z":32}},{"blockCount":39,"bytes":1095,"file":"chunks/y072-z064-x192.json","offset":{"x":192,"y":72,"z":64},"requirements":{"minecraft:polished_diorite":14,"minecraft:stone_bricks":25},"sha256":"a7d91f5a4797f9e193ff2c3fb7704333d4a6dba5162c710b36095c2dab4ba591","size":{"x":32,"y":1,"z":32}},{"blockCount":45,"bytes":1115,"file":"chunks/y072-z064-x224.json","offset":{"x":224,"y":72,"z":64},"requirements":{"minecraft:polished_diorite":17,"minecraft:stone_bricks":28},"sha256":"3065772bca1e3b21c026ce1a2c249cc1254c8eeac71c1b76aaf806b36ce75e60","size":{"x":32,"y":1,"z":32}},{"blockCount":231,"bytes":3076,"file":"chunks/y072-z096-x000.json","offset":{"x":0,"y":72,"z":96},"requirements":{"minecraft:bricks":37,"minecraft:polished_diorite":111,"minecraft:stone_bricks":83},"sha256":"f47d1355fbf5429fbbd0309576b5854312a4dac6fdfd17adcef3c5303bd07275","size":{"x":32,"y":1,"z":32}},{"blockCount":599,"bytes":5921,"file":"chunks/y072-z096-x032.json","offset":{"x":32,"y":72,"z":96},"requirements":{"minecraft:bricks":243,"minecraft:polished_diorite":200,"minecraft:sandstone":23,"minecraft:stone_bricks":133},"sha256":"2a887b12b922e15bef2ce0fdc7eff588e5cd749d3a3b9b16c3a2ae708d5c68f0","size":{"x":32,"y":1,"z":32}},{"blockCount":519,"bytes":6565,"file":"chunks/y072-z096-x064.json","offset":{"x":64,"y":72,"z":96},"requirements":{"minecraft:bricks":296,"minecraft:polished_diorite":56,"minecraft:sandstone":29,"minecraft:stone_bricks":138},"sha256":"0be6610cb582ae1f8df0a429625e16c871ce82feffc20e0b0e8eb1c26f974d0a","size":{"x":32,"y":1,"z":32}},{"blockCount":146,"bytes":2913,"file":"chunks/y072-z096-x096.json","offset":{"x":96,"y":72,"z":96},"requirements":{"minecraft:bricks":90,"minecraft:polished_diorite":2,"minecraft:sandstone":37,"minecraft:stone_bricks":17},"sha256":"1ef08512d126cc513b82a09c644ff67882cb6716b5a4cc526b4549a60ed52ce2","size":{"x":32,"y":1,"z":32}},{"blockCount":396,"bytes":5386,"file":"chunks/y072-z096-x128.json","offset":{"x":128,"y":72,"z":96},"requirements":{"minecraft:bricks":238,"minecraft:polished_diorite":40,"minecraft:sandstone":51,"minecraft:stone_bricks":67},"sha256":"4e00676bd510be73310427400ddc2a1f7691db96cc42b6e251f729076b4b12a3","size":{"x":32,"y":1,"z":32}},{"blockCount":495,"bytes":6697,"file":"chunks/y072-z096-x160.json","offset":{"x":160,"y":72,"z":96},"requirements":{"minecraft:bricks":281,"minecraft:polished_diorite":29,"minecraft:sandstone":30,"minecraft:stone_bricks":155},"sha256":"ad5a8f1f867dc50d4fda0292bf5d8352e5f3cb29cf34d2a339d00c5571e0d514","size":{"x":32,"y":1,"z":32}},{"blockCount":462,"bytes":6562,"file":"chunks/y072-z096-x192.json","offset":{"x":192,"y":72,"z":96},"requirements":{"minecraft:bricks":230,"minecraft:oak_planks":4,"minecraft:polished_diorite":84,"minecraft:sandstone":32,"minecraft:stone_bricks":112},"sha256":"894ae2406360b4c280fcf2eab66a659106b0c3db6b5f6d06805ed0952feb36f3","size":{"x":32,"y":1,"z":32}},{"blockCount":228,"bytes":5099,"file":"chunks/y072-z096-x224.json","offset":{"x":224,"y":72,"z":96},"requirements":{"minecraft:bricks":96,"minecraft:glass":3,"minecraft:oak_planks":6,"minecraft:polished_diorite":51,"minecraft:sandstone":1,"minecraft:stone_bricks":71},"sha256":"4592801909e393911f14fb0707c31142e00b40c8ea96f8672048a841467ee9e7","size":{"x":32,"y":1,"z":32}},{"blockCount":393,"bytes":4757,"file":"chunks/y072-z128-x000.json","offset":{"x":0,"y":72,"z":128},"requirements":{"minecraft:bricks":94,"minecraft:polished_diorite":193,"minecraft:stone_bricks":106},"sha256":"97f47a4d679ff1afe655020c2d16e4a9862fe63576d583f0f04688a708c38849","size":{"x":32,"y":1,"z":32}},{"blockCount":218,"bytes":3253,"file":"chunks/y072-z128-x032.json","offset":{"x":32,"y":72,"z":128},"requirements":{"minecraft:bricks":63,"minecraft:polished_diorite":89,"minecraft:sandstone":45,"minecraft:stone_bricks":21},"sha256":"bf5a615454f1a61294d22b959da242391a0c0c9e3e386eb6186fbecae168e79a","size":{"x":32,"y":1,"z":32}},{"blockCount":49,"bytes":1527,"file":"chunks/y072-z128-x064.json","offset":{"x":64,"y":72,"z":128},"requirements":{"minecraft:bricks":18,"minecraft:sandstone":29,"minecraft:stone_bricks":2},"sha256":"b3a507b161ffdc77fcee4812a9c3f507c213d43eb4289f8cf7e0cf51e064903e","size":{"x":32,"y":1,"z":32}},{"blockCount":18,"bytes":938,"file":"chunks/y072-z128-x096.json","offset":{"x":96,"y":72,"z":128},"requirements":{"minecraft:bricks":3,"minecraft:sandstone":14,"minecraft:stone_bricks":1},"sha256":"c026839fb413ec48c0092c25114f189ca35709b95aac0ccd48a5f1437fc1fdeb","size":{"x":32,"y":1,"z":32}},{"blockCount":40,"bytes":1358,"file":"chunks/y072-z128-x128.json","offset":{"x":128,"y":72,"z":128},"requirements":{"minecraft:bricks":10,"minecraft:sandstone":28,"minecraft:stone_bricks":2},"sha256":"edfa121f3ffc6572dd4ec79b7c4635055bfb89081524fc3033aca13aaabd81fd","size":{"x":32,"y":1,"z":32}},{"blockCount":50,"bytes":1510,"file":"chunks/y072-z128-x160.json","offset":{"x":160,"y":72,"z":128},"requirements":{"minecraft:bricks":18,"minecraft:sandstone":30,"minecraft:stone_bricks":2},"sha256":"f1eb2ef89546fb20c25a4ed8b2e2b5ed45f494e27076db69b07bbee5796231da","size":{"x":32,"y":1,"z":32}},{"blockCount":65,"bytes":1883,"file":"chunks/y072-z128-x192.json","offset":{"x":192,"y":72,"z":128},"requirements":{"minecraft:bricks":31,"minecraft:sandstone":32,"minecraft:stone_bricks":2},"sha256":"c3df52ec7d73622ce3c6940666b8a37fbaea5521234483a92337a32bb8b6b484","size":{"x":32,"y":1,"z":32}},{"blockCount":179,"bytes":3791,"file":"chunks/y072-z128-x224.json","offset":{"x":224,"y":72,"z":128},"requirements":{"minecraft:bricks":43,"minecraft:polished_diorite":79,"minecraft:sandstone":7,"minecraft:stone_bricks":50},"sha256":"f03ee2121a656290474cc2affb02ab8f90ef84254ea89dde143d6cc1c5b727bc","size":{"x":32,"y":1,"z":32}},{"blockCount":1,"bytes":649,"file":"chunks/y072-z128-x320.json","offset":{"x":320,"y":72,"z":128},"requirements":{"minecraft:cobbled_deepslate":1},"sha256":"226e4dad35a59ddaa3ee2e128b04325c50fec3d34a6a1318a2830cc914ab78fd","size":{"x":32,"y":1,"z":32}},{"blockCount":115,"bytes":2195,"file":"chunks/y072-z160-x000.json","offset":{"x":0,"y":72,"z":160},"requirements":{"minecraft:bricks":1,"minecraft:polished_diorite":57,"minecraft:stone_bricks":57},"sha256":"e55f5f98c2dd905ecc4217affa38276f3083caf65d825d9fd3602a016883ad83","size":{"x":32,"y":1,"z":32}},{"blockCount":498,"bytes":4828,"file":"chunks/y072-z160-x032.json","offset":{"x":32,"y":72,"z":160},"requirements":{"minecraft:bricks":195,"minecraft:polished_diorite":177,"minecraft:stone_bricks":126},"sha256":"a59dd5a945c8490ac6fb1421993f3924ef2764db9e7fef4d84af9313d5d7a945","size":{"x":32,"y":1,"z":32}}],"schema":1}
