{"entries":[{"blockCount":535,"bytes":6675,"file":"chunks/y072-z160-x064.json","offset":{"x":64,"y":72,"z":160},"requirements":{"minecraft:bricks":297,"minecraft:polished_diorite":75,"minecraft:stone_bricks":163},"sha256":"940d8caa091b44fbec6d4088766f7fe7a82773846b09bd7310c4320e76da16ce","size":{"x":32,"y":1,"z":32}},{"blockCount":162,"bytes":3202,"file":"chunks/y072-z160-x096.json","offset":{"x":96,"y":72,"z":160},"requirements":{"minecraft:bricks":107,"minecraft:polished_diorite":4,"minecraft:sandstone":29,"minecraft:stone_bricks":22},"sha256":"47a88e1e6f8cbe132cabed51ec1c2f1dda6b9f132d5f3bddf82deececa3cb1cc","size":{"x":32,"y":1,"z":32}},{"blockCount":453,"bytes":6509,"file":"chunks/y072-z160-x128.json","offset":{"x":128,"y":72,"z":160},"requirements":{"minecraft:bricks":125,"minecraft:polished_diorite":205,"minecraft:sandstone":29,"minecraft:stone_bricks":94},"sha256":"5086fd4a5fcc8b27bd665f59506710bdb981c5dc57270b7ba8ba468b1533f8f5","size":{"x":32,"y":1,"z":32}},{"blockCount":452,"bytes":6101,"file":"chunks/y072-z160-x160.json","offset":{"x":160,"y":72,"z":160},"requirements":{"minecraft:bricks":58,"minecraft:polished_diorite":237,"minecraft:stone_bricks":157},"sha256":"664b72f5c3317d0520fe633a39e8c669f967ee233462067055e3568e718547af","size":{"x":32,"y":1,"z":32}},{"blockCount":446,"bytes":6121,"file":"chunks/y072-z160-x192.json","offset":{"x":192,"y":72,"z":160},"requirements":{"minecraft:bricks":149,"minecraft:oak_planks":4,"minecraft:polished_diorite":158,"minecraft:stone_bricks":135},"sha256":"5e13e97ddc332c5b42eb3ba8ab4b2e48625b8b4db3eca79b2b0199d63fad24c6","size":{"x":32,"y":1,"z":32}},{"blockCount":211,"bytes":4751,"file":"chunks/y072-z160-x224.json","offset":{"x":224,"y":72,"z":160},"requirements":{"minecraft:bricks":86,"minecraft:glass":3,"minecraft:oak_planks":6,"minecraft:polished_diorite":40,"minecraft:stone_bricks":76},"sha256":"7063700cadedfa3d808d89f51dbdae6c0e26c1b86397b8317b92c0386d421436","size":{"x":32,"y":1,"z":32}},{"blockCount":244,"bytes":3767,"file":"chunks/y072-z192-x064.json","offset":{"x":64,"y":72,"z":192},"requirements":{"minecraft:bricks":14,"minecraft:polished_diorite":130,"minecraft:sandstone":1,"minecraft:stone_bricks":99},"sha256":"c9caebf69c19fb9ab75ced04df1e830659e37569096f4c24e089c4d4a79f0470","size":{"x":32,"y":1,"z":32}},{"blockCount":234,"bytes":3800,"file":"chunks/y072-z192-x096.json","offset":{"x":96,"y":72,"z":192},"requirements":{"minecraft:bricks":74,"minecraft:polished_diorite":89,"minecraft:sandstone":20,"minecraft:stone_bricks":51},"sha256":"7501380fd706449df8dd5c3de6a52c18523db34f30adc8a3091d6e03d622a01c","size":{"x":32,"y":1,"z":32}},{"blockCount":385,"bytes":5459,"file":"chunks/y072-z192-x128.json","offset":{"x":128,"y":72,"z":192},"requirements":{"minecraft:bricks":56,"minecraft:polished_diorite":191,"minecraft:sandstone":19,"minecraft:stone_bricks":119},"sha256":"43152d0720b33d0eac355e333af81c295add56187575c251215fb780d9b44c44","size":{"x":32,"y":1,"z":32}},{"blockCount":24,"bytes":1297,"file":"chunks/y072-z192-x160.json","offset":{"x":160,"y":72,"z":192},"requirements":{"minecraft:polished_diorite":6,"minecraft:stone_bricks":18},"sha256":"2327bf2e1945fe43643d9cf8e7c81d6b0191eb74d4494d3e994da25ece560ebc","size":{"x":32,"y":1,"z":32}},{"blockCount":48,"bytes":1056,"file":"chunks/y073-z000-x352.json","offset":{"x":352,"y":73,"z":0},"requirements":{"minecraft:cobbled_deepslate":44,"minecraft:glass":4},"sha256":"bf4fa5202c8a6ca1a62d5d6fad13f111321f062c4e56916eb16c767b20718cbf","size":{"x":32,"y":1,"z":32}},{"blockCount":1,"bytes":642,"file":"chunks/y073-z000-x384.json","offset":{"x":384,"y":73,"z":0},"requirements":{"minecraft:stone_bricks":1},"sha256":"0e5db766843a250b879d1a1aec100115e3aed400330bf6427102c04c1855b2af","size":{"x":32,"y":1,"z":32}},{"blockCount":328,"bytes":5226,"file":"chunks/y073-z064-x064.json","offset":{"x":64,"y":73,"z":64},"requirements":{"minecraft:bricks":30,"minecraft:cobbled_deepslate":96,"minecraft:glass":19,"minecraft:polished_diorite":130,"minecraft:stone_bricks":53},"sha256":"adf698fe3cc7cddf5103a62ad2906653ce456358972677b488627e9471f3fba0","size":{"x":32,"y":1,"z":32}},{"blockCount":265,"bytes":5337,"file":"chunks/y073-z064-x096.json","offset":{"x":96,"y":73,"z":64},"requirements":{"minecraft:bricks":89,"minecraft:cobbled_deepslate":14,"minecraft:glass":27,"minecraft:polished_diorite":63,"minecraft:sandstone":19,"minecraft:stone_bricks":53},"sha256":"fa4ff346e898f759d075f843a6ff977da4c038b31ef34205a74b97fc0ffe1cc2","size":{"x":32,"y":1,"z":32}},{"blockCount":501,"bytes":7924,"file":"chunks/y073-z064-x128.json","offset":{"x":128,"y":73,"z":64},"requirements":{"minecraft:bricks":79,"minecraft:cobbled_deepslate":123,"minecraft:glass":40,"minecraft:polished_diorite":167,"minecraft:sandstone":16,"minecraft:stone_bricks":76},"sha256":"fe322b172c176c1021d4d9ebc68772928cb16198d83da264a0b27aff65ccf3fa","size":{"x":32,"y":1,"z":32}},{"blockCount":24,"bytes":1077,"file":"chunks/y073-z064-x160.json","offset":{"x":160,"y":73,"z":64},"requirements":{"minecraft:polished_diorite":24},"sha256":"4138345680257cbc2dc4a276d55b7615bcf40416e555488233757434e5bf1332","size":{"x":32,"y":1,"z":32}},{"blockCount":35,"bytes":1208,"file":"chunks/y073-z064-x192.json","offset":{"x":192,"y":73,"z":64},"requirements":{"minecraft:polished_diorite":27,"minecraft:stone_bricks":8},"sha256":"83e94eab0198a6e88d2f5a0dc58b43d1a9f78bebc775bfc5780fc05f35590e7f","size":{"x":32,"y":1,"z":32}},{"blockCount":41,"bytes":1209,"file":"chunks/y073-z064-x224.json","offset":{"x":224,"y":73,"z":64},"requirements":{"minecraft:polished_diorite":33,"minecraft:stone_bricks":8},"sha256":"e30ee78bb09f44e74f87a9a9d1d54c79d6d9e0439e018d15ebb863b980735380","size":{"x":32,"y":1,"z":32}},{"blockCount":130,"bytes":2613,"file":"chunks/y073-z096-x000.json","offset":{"x":0,"y":73,"z":96},"requirements":{"minecraft:cobbled_deepslate":20,"minecraft:glass":16,"minecraft:polished_diorite":83,"minecraft:stone_bricks":11},"sha256":"34db085007919e185929e999a550cf4308a033f7467498c414246b68712d27dd","size":{"x":32,"y":1,"z":32}},{"blockCount":478,"bytes":6957,"file":"chunks/y073-z096-x032.json","offset":{"x":32,"y":73,"z":96},"requirements":{"minecraft:bricks":32,"minecraft:cobbled_deepslate":154,"minecraft:glass":19,"minecraft:polished_diorite":180,"minecraft:sandstone":15,"minecraft:stone_bricks":78},"sha256":"f94c0a3079f3b6b6d6cd9e9333adfa57193e888be2bb8cb1360b2883f4afca5b","size":{"x":32,"y":1,"z":32}},{"blockCount":583,"bytes":7964,"file":"chunks/y073-z096-x064.json","offset":{"x":64,"y":73,"z":96},"requirements":{"minecraft:bricks":122,"minecraft:cobbled_deepslate":200,"minecraft:glass":12,"minecraft:polished_diorite":151,"minecraft:sandstone":15,"minecraft:stone_bricks":83},"sha256":"a4a2dd70491c3376845df81980f69690ad1cef3af0dd8055144770abfb3c6842","size":{"x":32,"y":1,"z":32}},{"blockCount":141,"bytes":3496,"file":"chunks/y073-z096-x096.json","offset":{"x":96,"y":73,"z":96},"requirements":{"minecraft:bricks":70,"minecraft:cobbled_deepslate":8,"minecraft:glass":8,"minecraft:polished_diorite":6,"minecraft:sandstone":20,"minecraft:stone_bricks":29},"sha256":"ef9e41e14b25a042e09a6f4bc4324b8ab86ae5dc059d058aa3cfa54d8979de40","size":{"x":32,"y":1,"z":32}},{"blockCount":430,"bytes":6841,"file":"chunks/y073-z096-x128.json","offset":{"x":128,"y":73,"z":96},"requirements":{"minecraft:bricks":98,"minecraft:cobbled_deepslate":120,"minecraft:glass":11,"minecraft:polished_diorite":101,"minecraft:sandstone":28,"minecraft:stone_bricks":72},"sha256":"52eee27b3e3e88cfe094e6fc478ae859d497eb5ad528372ace050bfae24999bb","size":{"x":32,"y":1,"z":32}},{"blockCount":534,"bytes":7451,"file":"chunks/y073-z096-x160.json","offset":{"x":160,"y":73,"z":96},"requirements":{"minecraft:bricks":58,"minecraft:cobbled_deepslate":155,"minecraft:glass":17,"minecraft:polished_diorite":208,"minecraft:sandstone":15,"minecraft:stone_bricks":81},"sha256":"acf4dd7096e4782a52fac4acdce20b9b8dbbeedd0455d6fc66ec93f9a7085d33","size":{"x":32,"y":1,"z":32}},{"blockCount":491,"bytes":6844,"file":"chunks/y073-z096-x192.json","offset":{"x":192,"y":73,"z":96},"requirements":{"minecraft:bricks":142,"minecraft:cobbled_deepslate":96,"minecraft:glass":12,"minecraft:oak_planks":4,"minecraft:polished_diorite":147,"minecraft:sandstone":17,"minecraft:stone_bricks":73},"sha256":"1f8e5bbaa4ee8ae3680be7d552c60fa0b591a4f23557cb696cb344e64670bdc8","size":{"x":32,"y":1,"z":32}},{"blockCount":207,"bytes":5025,"file":"chunks/y073-z096-x224.json","offset":{"x":224,"y":73,"z":96},"requirements":{"minecraft:bricks":87,"minecraft:glass":17,"minecraft:oak_planks":6,"minecraft:polished_diorite":73,"minecraft:sandstone":1,"minecraft:stone_bricks":23},"sha256":"286ec1e0b97460a2d223ecf7379d5947ab5c383535f95a9b4adaccbcc68a32d6","size":{"x":32,"y":1,"z":32}},{"blockCount":312,"bytes":4758,"file":"chunks/y073-z128-x000.json","offset":{"x":0,"y":73,"z":128},"requirements":{"minecraft:bricks":37,"minecraft:cobbled_deepslate":127,"minecraft:glass":22,"minecraft:polished_diorite":101,"minecraft:stone_bricks":25},"sha256":"13028513fd05b6dc697f95edcce54eb0cbd50a5c8af86343632c8f1a43ef9e74","size":{"x":32,"y":1,"z":32}},{"blockCount":206,"bytes":4068,"file":"chunks/y073-z128-x032.json","offset":{"x":32,"y":73,"z":128},"requirements":{"minecraft:bricks":36,"minecraft:cobbled_deepslate":12,"minecraft:glass":8,"minecraft:polished_diorite":65,"minecraft:sandstone":23,"minecraft:stone_bricks":62},"sha256":"76761ce32e64b388950b478817b1f67a118fa60c724f5b61daf38da1035f37c9","size":{"x":32,"y":1,"z":32}},{"blockCount":69,"bytes":1547,"file":"chunks/y073-z128-x064.json","offset":{"x":64,"y":73,"z":128},"requirements":{"minecraft:bricks":21,"minecraft:glass":7,"minecraft:sandstone":15,"minecraft:stone_bricks":26},"sha256":"81254d0bee1d154f8bd0f81f9d8a390e57c5fabdd0271352251f4848c2aab326","size":{"x":32,"y":1,"z":32}},{"blockCount":17,"bytes":975,"file":"chunks/y073-z128-x096.json","offset":{"x":96,"y":73,"z":128},"requirements":{"minecraft:bricks":3,"minecraft:glass":2,"minecraft:sandstone":7,"minecraft:stone_bricks":5},"sha256":"a6bc82ebaf830a3238bca4b62eca0f000bdd68f9c8ce184ef4358223055f0231","size":{"x":32,"y":1,"z":32}},{"blockCount":49,"bytes":1377,"file":"chunks/y073-z128-x128.json","offset":{"x":128,"y":73,"z":128},"requirements":{"minecraft:bricks":11,"minecraft:glass":5,"minecraft:sandstone":16,"minecraft:stone_bricks":17},"sha256":"a5a4fc1d10f857b46a6658b609f45af0fdda165d37804424d9023a376711abc4","size":{"x":32,"y":1,"z":32}},{"blockCount":68,"bytes":1548,"file":"chunks/y073-z128-x160.json","offset":{"x":160,"y":73,"z":128},"requirements":{"minecraft:bricks":21,"minecraft:glass":7,"minecraft:sandstone":15,"minecraft:stone_bricks":25},"sha256":"9cb91f59fdb653c66122eb4fc51b36b6b0b6f16be2edd1e7155628bd33ef8e69","size":{"x":32,"y":1,"z":32}},{"blockCount":83,"bytes":1962,"file":"chunks/y073-z128-x192.json","offset":{"x":192,"y":73,"z":128},"requirements":{"minecraft:bricks":35,"minecraft:glass":7,"minecraft:sandstone":17,"minecraft:stone_bricks":24},"sha256":"7d9edd0c5ea9bbb7a5f51cb36a2f64b05a4703f01de9c31002667bd234bdc78f","size":{"x":32,"y":1,"z":32}},{"blockCount":160,"bytes":4231,"file":"chunks/y073-z128-x224.json","offset":{"x":224,"y":73,"z":128},"requirements":{"minecraft:bricks":21,"minecraft:glass":36,"minecraft:polished_diorite":59,"minecraft:sandstone":13,"minecraft:stone_bricks":31},"sha256":"fa4379e5cc70399f493f2abed1253625d77de7559b7edb634737830935ff5dd1","size":{"x":32,"y":1,"z":32}},{"blockCount":78,"bytes":1862,"file":"chunks/y073-z160-x000.json","offset":{"x":0,"y":73,"z":160},"requirements":{"minecraft:cobbled_deepslate":7,"minecraft:glass":9,"minecraft:polished_diorite":56,"minecraft:stone_bricks":6},"sha256":"577b297d6e89187b9bc0e3942c94bb440e81a324b8da62574bf647a27343bea0","size":{"x":32,"y":1,"z":32}},{"blockCount":388,"bytes":5580,"file":"chunks/y073-z160-x032.json","offset":{"x":32,"y":73,"z":160},"requirements":{"minecraft:bricks":18,"minecraft:cobbled_deepslate":146,"minecraft:glass":13,"minecraft:polished_diorite":163,"minecraft:stone_bricks":48},"sha256":"44387e39ba2c3bf7eb7139f8b174d4d389e5b0af3df61f7a525e0780f1166566","size":{"x":32,"y":1,"z":32}},{"blockCount":588,"bytes":8074,"file":"chunks/y073-z160-x064.json","offset":{"x":64,"y":73,"z":160},"requirements":{"minecraft:bricks":67,"minecraft:cobbled_deepslate":219,"minecraft:glass":8,"minecraft:polished_diorite":218,"minecraft:stone_bricks":76},"sha256":"24c664a67ac9d1cf8b4b59dcecb6acdbd3a9a884f6f5aea0b5c6c1a5d79ba070","size":{"x":32,"y":1,"z":32}},{"blockCount":160,"bytes":4015,"file":"chunks/y073-z160-x096.json","offset":{"x":96,"y":73,"z":160},"requirements":{"minecraft:bricks":65,"minecraft:cobbled_deepslate":10,"minecraft:glass":8,"minecraft:polished_diorite":27,"minecraft:sandstone":16,"minecraft:stone_bricks":34},"sha256":"c3b99c74259e7200656848658778a7e0d468cdc2694644ac795cfb84b579a29b","size":{"x":32,"y":1,"z":32}},{"blockCount":488,"bytes":7376,"file":"chunks/y073-z160-x128.json","offset":{"x":128,"y":73,"z":160},"requirements":{"minecraft:bricks":85,"minecraft:cobbled_deepslate":156,"minecraft:glass":11,"minecraft:polished_diorite":150,"minecraft:sandstone":17,"minecraft:stone_bricks":69},"sha256":"63e341b7ec8c0cfce23e897886eda2354b091de06c6d243a5d495e852e7c3566","size":{"x":32,"y":1,"z":32}},{"blockCount":470,"bytes":6875,"file":"chunks/y073-z160-x160.json","offset":{"x":160,"y":73,"z":160},"requirements":{"minecraft:bricks":38,"minecraft:cobbled_deepslate":151,"minecraft:glass":10,"minecraft:polished_diorite":211,"minecraft:stone_bricks":60},"sha256":"45b2d094be4cb51a4d96ca3d45da943e328d13f05750fe394c101e3541920354","size":{"x":32,"y":1,"z":32}},{"blockCount":451,"bytes":6648,"file":"chunks/y073-z160-x192.json","offset":{"x":192,"y":73,"z":160},"requirements":{"minecraft:bricks":117,"minecraft:cobbled_deepslate":93,"minecraft:glass":5,"minecraft:oak_planks":4,"minecraft:polished_diorite":172,"minecraft:stone_bricks":60},"sha256":"592582f7611676f2d3427f966ec287d86b7b0c9d1ebe798b48f4c1da048687ad","size":{"x":32,"y":1,"z":32}},{"blockCount":193,"bytes":4714,"file":"chunks/y073-z160-x224.json","offset":{"x":224,"y":73,"z":160},"requirements":{"minecraft:bricks":81,"minecraft:glass":3,"minecraft:oak_planks":6,"minecraft:polished_diorite":79,"minecraft:stone_bricks":24},"sha256":"0ca0ba38d995edb204f8178a28915826afd2aede100ac2dcef843b357a6cdb68","size":{"x":32,"y":1,"z":32}},{"blockCount":253,"bytes":4062,"file":"chunks/y073-z192-x064.json","offset":{"x":64,"y":73,"z":192},"requirements":{"minecraft:bricks":8,"minecraft:cobbled_deepslate":74,"minecraft:glass":16,"minecraft:polished_diorite":118,"minecraft:stone_bricks":37},"sha256":"695884ae14ec0342703a18150a5860eacbca5e6da3999a0f0cd39abc69d574f8","size":{"x":32,"y":1,"z":32}},{"blockCount":229,"bytes":4704,"file":"chunks/y073-z192-x096.json","offset":{"x":96,"y":73,"z":192},"requirements":{"minecraft:bricks":59,"minecraft:cobbled_deepslate":9,"minecraft:glass":25,"minecraft:polished_diorite":74,"minecraft:sandstone":17,"minecraft:stone_bricks":45},"sha256":"13090901c80998f0f66c11525f1f918b5635d978496adc2be78484da04b9b8db","size":{"x":32,"y":1,"z":32}},{"blockCount":392,"bytes":6324,"file":"chunks/y073-z192-x128.json","offset":{"x":128,"y":73,"z":192},"requirements":{"minecraft:bricks":39,"minecraft:cobbled_deepslate":90,"minecraft:glass":35,"minecraft:polished_diorite":156,"minecraft:sandstone":13,"minecraft:stone_bricks":59},"sha256":"51c22922c0370d1ad4c2b2c6ec595a0c62c4607b6b139c79304909d081c66d81","size":{"x":32,"y":1,"z":32}},{"blockCount":20,"bytes":1001,"file":"chunks/y073-z192-x160.json","offset":{"x":160,"y":73,"z":192},"requirements":{"minecraft:polished_diorite":20},"sha256":"77933566444dcc44553479d0a76a43526ff64763267a192a112b1b9e57217575","size":{"x":32,"y":1,"z":32}},{"blockCount":17,"bytes":1046,"file":"chunks/y074-z000-x352.json","offset":{"x":352,"y":74,"z":0},"requirements":{"minecraft:cobbled_deepslate":9,"minecraft:glass":4,"minecraft:polished_diorite":4},"sha256":"9bcd6478ddf7a16b490a46eed4edf9f6327c5a43b06bdac4a71a3d36846c79af","size":{"x":32,"y":1,"z":32}},{"blockCount":1,"bytes":642,"file":"chunks/y074-z000-x384.json","offset":{"x":384,"y":74,"z":0},"requirements":{"minecraft:stone_bricks":1},"sha256":"94eb2bb9d3d070b8cd50f46c9164a25b4433a9b260c4d476187fb5f856ef413f","size":{"x":32,"y":1,"z":32}},{"blockCount":220,"bytes":5396,"file":"chunks/y074-z064-x064.json","offset":{"x":64,"y":74,"z":64},"requirements":{"minecraft:cobbled_deepslate":50,"minecraft:glass":10,"minecraft:polished_diorite":126,"minecraft:stone_bricks":34},"sha256":"dbf2d46eb08c6f409cdc60a6b4e4047e6bf3c5ddd5511fc771fe48989e57c1b0","size":{"x":32,"y":1,"z":32}},{"blockCount":272,"bytes":5282,"file":"chunks/y074-z064-x096.json","offset":{"x":96,"y":74,"z":64},"requirements":{"minecraft:bricks":43,"minecraft:cobbled_deepslate":15,"minecraft:glass":38,"minecraft:polished_diorite":95,"minecraft:sandstone":25,"minecraft:stone_bricks":56},"sha256":"297806104af3cb78044efe3328b5f4ef30e31faaefcf07cb476c4a28a74816de","size":{"x":32,"y":1,"z":32}},{"blockCount":405,"bytes":8343,"file":"chunks/y074-z064-x128.json","offset":{"x":128,"y":74,"z":64},"requirements":{"minecraft:bricks":39,"minecraft:cobbled_deepslate":65,"minecraft:glass":42,"minecraft:polished_diorite":184,"minecraft:sandstone":12,"minecraft:stone_bricks":63},"sha256":"71276741e2fc01dec94b5a707d9f084737b4d5f8a2d2473c7d2549c36c37a5c0","size":{"x":32,"y":1,"z":32}},{"blockCount":14,"bytes":1077,"file":"chunks/y074-z064-x160.json","offset":{"x":160,"y":74,"z":64},"requirements":{"minecraft:polished_diorite":14},"sha256":"9361adc5d5bc052c812cc7c2065e0dfb89de1e35c523ca7c6aa0ec26dfc1c81f","size":{"x":32,"y":1,"z":32}},{"blockCount":25,"bytes":1170,"file":"chunks/y074-z064-x192.json","offset":{"x":192,"y":74,"z":64},"requirements":{"minecraft:polished_diorite":17,"minecraft:stone_bricks":8},"sha256":"73d26b6a54b40ce91f1029bb18e3b22fc7c4bbee256b48e11ed4f8e6b295e640","size":{"x":32,"y":1,"z":32}},{"blockCount":29,"bytes":1247,"file":"chunks/y074-z064-x224.json","offset":{"x":224,"y":74,"z":64},"requirements":{"minecraft:polished_diorite":21,"minecraft:stone_bricks":8},"sha256":"4b55c7f0baf740155b55b92b7d8c1c26e0995ffc866e351ae4fdf97d3b6dd6ee","size":{"x":32,"y":1,"z":32}},{"blockCount":102,"bytes":2895,"file":"chunks/y074-z096-x000.json","offset":{"x":0,"y":74,"z":96},"requirements":{"minecraft:cobbled_deepslate":32,"minecraft:glass":16,"minecraft:polished_diorite":51,"minecraft:stone_bricks":3},"sha256":"5f32da92962f01c0b692155927ab38ad6167296cf8d8fd94bebe38dedd53ff74","size":{"x":32,"y":1,"z":32}},{"blockCount":358,"bytes":8553,"file":"chunks/y074-z096-x032.json","offset":{"x":32,"y":74,"z":96},"requirements":{"minecraft:bricks":23,"minecraft:cobbled_deepslate":94,"minecraft:glass":38,"minecraft:polished_diorite":137,"minecraft:sandstone":20,"minecraft:stone_bricks":46},"sha256":"3e83f7e60a1d87556ee62f5b9c2ef3ded2cd315ae1fcd739dfeb759d2a20aa5b","size":{"x":32,"y":1,"z":32}},{"blockCount":434,"bytes":8572,"file":"chunks/y074-z096-x064.json","offset":{"x":64,"y":74,"z":96},"requirements":{"minecraft:bricks":77,"minecraft:cobbled_deepslate":102,"minecraft:glass":39,"minecraft:polished_diorite":124,"minecraft:sandstone":17,"minecraft:stone_bricks":75},"sha256":"6f694d38094ea45f77fe6d20521a8c79eca3f66479e1c8e8d563ae93caee48c3","size":{"x":32,"y":1,"z":32}},{"blockCount":154,"bytes":3765,"file":"chunks/y074-z096-x096.json","offset":{"x":96,"y":74,"z":96},"requirements":{"minecraft:bricks":30,"minecraft:cobbled_deepslate":10,"minecraft:glass":36,"minecraft:polished_diorite":18,"minecraft:sandstone":22,"minecraft:stone_bricks":38},"sha256":"a842ae656638b6b660c31d5f7f3b1c757597aab36fc0de9e0e2afe334d1082f0","size":{"x":32,"y":1,"z":32}},{"blockCount":357,"bytes":6914,"file":"chunks/y074-z096-x128.json","offset":{"x":128,"y":74,"z":96},"requirements":{"minecraft:bricks":50,"minecraft:cobbled_deepslate":64,"minecraft:glass":54,"minecraft:polished_diorite":106,"minecraft:sandstone":24,"minecraft:stone_bricks":59},"sha256":"2b17158e5fd6f205dc51df07335ef6978204255b1ae8e0c03f08c9a494a486ab","size":{"x":32,"y":1,"z":32}},{"blockCount":401,"bytes":8668,"file":"chunks/y074-z096-x160.json","offset":{"x":160,"y":74,"z":96},"requirements":{"minecraft:bricks":33,"minecraft:cobbled_deepslate":81,"minecraft:glass":41,"minecraft:polished_diorite":172,"minecraft:sandstone":14,"minecraft:stone_bricks":60},"sha256":"c19b28bde077d9a533892ef6a8a7a948feb69b0513353f89e8277f577c848690","size":{"x":32,"y":1,"z":32}},{"blockCount":399,"bytes":7723,"file":"chunks/y074-z096-x192.json","offset":{"x":192,"y":74,"z":96},"requirements":{"minecraft:bricks":122,"minecraft:cobbled_deepslate":31,"minecraft:glass":36,"minecraft:oak_planks":4,"minecraft:polished_diorite":112,"minecraft:sandstone":26,"minecraft:stone_bricks":68},"sha256":"a88f3a1f2be252ae994ca516cfa12060757740d1705e8b1602892594bd264668","size":{"x":32,"y":1,"z":32}},{"blockCount":189,"bytes":5272,"file":"chunks/y074-z096-x224.json","offset":{"x":224,"y":74,"z":96},"requirements":{"minecraft:bricks":87,"minecraft:glass":10,"minecraft:oak_planks":6,"minecraft:polished_diorite":53,"minecraft:sandstone":2,"minecraft:stone_bricks":31},"sha256":"8c873292eeda078ad3af8483fcf5cd6523f8634db9b9b6b01285e87e43db7ede","size":{"x":32,"y":1,"z":32}},{"blockCount":250,"bytes":5417,"file":"chunks/y074-z128-x000.json","offset":{"x":0,"y":74,"z":128},"requirements":{"minecraft:bricks":47,"minecraft:cobbled_deepslate":85,"minecraft:glass":22,"minecraft:polished_diorite":68,"minecraft:stone_bricks":28},"sha256":"669dddc3b72db688ee071b5472d17bc8d03c3eb0bd825a3019cb96d168cc350d","size":{"x":32,"y":1,"z":32}},{"blockCount":214,"bytes":4431,"file":"chunks/y074-z128-x032.json","offset":{"x":32,"y":74,"z":128},"requirements":{"minecraft:bricks":12,"minecraft:cobbled_deepslate":20,"minecraft:glass":37,"minecraft:polished_diorite":55,"minecraft:sandstone":20,"minecraft:stone_bricks":70},"sha256":"21f9b639e332992bedd3d2850ba1df21ed7d375a2b733f71dc8d5e2842ab6bc1","size":{"x":32,"y":1,"z":32}},{"blockCount":88,"bytes":1523,"file":"chunks/y074-z128-x064.json","offset":{"x":64,"y":74,"z":128},"requirements":{"minecraft:bricks":15,"minecraft:cobbled_deepslate":4,"minecraft:glass":34,"minecraft:sandstone":24,"minecraft:stone_bricks":11},"sha256":"840afcf7fb83be2852e31744e01bb73f2b59d649c2846600c07b94474272df88","size":{"x":32,"y":1,"z":32}},{"blockCount":20,"bytes":956,"file":"chunks/y074-z128-x096.json","offset":{"x":96,"y":74,"z":128},"requirements":{"minecraft:bricks":5,"minecraft:glass":8,"minecraft:sandstone":6,"minecraft:stone_bricks":1},"sha256":"64b086c232da286aace5f3d4e581f6be7a2d46d796876f256fcf4d8ea8be66a4","size":{"x":32,"y":1,"z":32}},{"blockCount":60,"bytes":1298,"file":"chunks/y074-z128-x128.json","offset":{"x":128,"y":74,"z":128},"requirements":{"minecraft:glass":26,"minecraft:sandstone":13,"minecraft:stone_bricks":21},"sha256":"3f0c6887beba7c432a3f5762cfdb1f3c4da0708217b94652484d00e34899133d","size":{"x":32,"y":1,"z":32}},{"blockCount":81,"bytes":1568,"file":"chunks/y074-z128-x160.json","offset":{"x":160,"y":74,"z":128},"requirements":{"minecraft:bricks":13,"minecraft:glass":32,"minecraft:sandstone":25,"minecraft:stone_bricks":11},"sha256":"4ca1074c9eb3447c47c47e3cbb16ca278b58643dcb3d56184ad5d3c14c2d1a8f","size":{"x":32,"y":1,"z":32}},{"blockCount":109,"bytes":2540,"file":"chunks/y074-z128-x192.json","offset":{"x":192,"y":74,"z":128},"requirements":{"minecraft:bricks":33,"minecraft:glass":31,"minecraft:sandstone":26,"minecraft:stone_bricks":19},"sha256":"706a072d4901144f6243164915dd9b68c79cbdc20829ce63d00f4993e05b3dce","size":{"x":32,"y":1,"z":32}},{"blockCount":152,"bytes":4154,"file":"chunks/y074-z128-x224.json","offset":{"x":224,"y":74,"z":128},"requirements":{"minecraft:bricks":27,"minecraft:glass":19,"minecraft:polished_diorite":50,"minecraft:sandstone":8,"minecraft:stone_bricks":48},"sha256":"d699fd3bbe3b4e17bbb80f2bc3d29d6fade31d25ed664c1c2dd78646a3c21d9f","size":{"x":32,"y":1,"z":32}},{"blockCount":58,"bytes":2071,"file":"chunks/y074-z160-x000.json","offset":{"x":0,"y":74,"z":160},"requirements":{"minecraft:cobbled_deepslate":14,"minecraft:glass":9,"minecraft:polished_diorite":34,"minecraft:stone_bricks":1},"sha256":"94b099d5e8ad79b6f9870ba8f8c4e1ac17d152cb645e24113f2a61bdf98939b2","size":{"x":32,"y":1,"z":32}},{"blockCount":262,"bytes":7024,"file":"chunks/y074-z160-x032.json","offset":{"x":32,"y":74,"z":160},"requirements":{"minecraft:bricks":11,"minecraft:cobbled_deepslate":85,"minecraft:glass":13,"minecraft:polished_diorite":126,"minecraft:stone_bricks":27},"sha256":"bf4876edcde4fb6c226a18c6f10ab8a16ed1a96566c6c929ee531e09a96eb55e","size":{"x":32,"y":1,"z":32}},{"blockCount":394,"bytes":8765,"file":"chunks/y074-z160-x064.json","offset":{"x":64,"y":74,"z":160},"requirements":{"minecraft:bricks":33,"minecraft:cobbled_deepslate":110,"minecraft:glass":8,"minecraft:polished_diorite":193,"minecraft:sandstone":1,"minecraft:stone_bricks":49},"sha256":"7f37c1996f8ec59370f46833343e2a75b926ecceb563a29107f2e4e1934245e7","size":{"x":32,"y":1,"z":32}},{"blockCount":168,"bytes":4187,"file":"chunks/y074-z160-x096.json","offset":{"x":96,"y":74,"z":160},"requirements":{"minecraft:bricks":27,"minecraft:cobbled_deepslate":16,"minecraft:glass":36,"minecraft:polished_diorite":47,"minecraft:sandstone":13,"minecraft:stone_bricks":29},"sha256":"6eeba86daf92e7ba2cef56e3b3b21fd0fa911a38bd78cc12188478acaa292c3f","size":{"x":32,"y":1,"z":32}},{"blockCount":380,"bytes":7810,"file":"chunks/y074-z160-x128.json","offset":{"x":128,"y":74,"z":160},"requirements":{"minecraft:bricks":30,"minecraft:cobbled_deepslate":82,"minecraft:glass":39,"minecraft:polished_diorite":145,"minecraft:sandstone":25,"minecraft:stone_bricks":59},"sha256":"0bb2d0afb2a4b8f707afb1355ec5ebfb356712476caf29adb039079749d2695b","size":{"x":32,"y":1,"z":32}},{"blockCount":321,"bytes":7883,"file":"chunks/y074-z160-x160.json","offset":{"x":160,"y":74,"z":160},"requirements":{"minecraft:bricks":27,"minecraft:cobbled_deepslate":79,"minecraft:glass":10,"minecraft:polished_diorite":174,"minecraft:stone_bricks":31},"sha256":"067f374fa0720c8ca3cd91fdbbcd4d0f15f57c04435c7c60f11027232a39611f","size":{"x":32,"y":1,"z":32}},{"blockCount":335,"bytes":7239,"file":"chunks/y074-z160-x192.json","offset":{"x":192,"y":74,"z":160},"requirements":{"minecraft:bricks":112,"minecraft:cobbled_deepslate":33,"minecraft:glass":5,"minecraft:oak_planks":4,"minecraft:polished_diorite":127,"minecraft:stone_bricks":54},"sha256":"5eed9fc09d602558152cd0309274bca6cadc661f76fbebc63ca9eb469e386f18","size":{"x":32,"y":1,"z":32}},{"blockCount":167,"bytes":4866,"file":"chunks/y074-z160-x224.json","offset":{"x":224,"y":74,"z":160},"requirements":{"minecraft:bricks":81,"minecraft:glass":3,"minecraft:oak_planks":6,"minecraft:polished_diorite":53,"minecraft:stone_bricks":24},"sha256":"843f7438fd298698c2e2b7a274da4defb2f0fc03ddd8d29e82dd5ce574c3ffb8","size":{"x":32,"y":1,"z":32}},{"blockCount":171,"bytes":4324,"file":"chunks/y074-z192-x064.json","offset":{"x":64,"y":74,"z":192},"requirements":{"minecraft:cobbled_deepslate":37,"minecraft:glass":7,"minecraft:polished_diorite":99,"minecraft:stone_bricks":28},"sha256":"5825f1e68ff5f9045545c367f57c17543328d9db42aea5601922e323874ffcbd","size":{"x":32,"y":1,"z":32}},{"blockCount":231,"bytes":4460,"file":"chunks/y074-z192-x096.json","offset":{"x":96,"y":74,"z":192},"requirements":{"minecraft:bricks":45,"minecraft:cobbled_deepslate":12,"minecraft:glass":30,"minecraft:polished_diorite":81,"minecraft:sandstone":12,"minecraft:stone_bricks":51},"sha256":"22b93f7efdca93efd983f191ce6c0c4c5f7e73256de769e0d76422fb5bc5f4de","size":{"x":32,"y":1,"z":32}},{"blockCount":321,"bytes":6572,"file":"chunks/y074-z192-x128.json","offset":{"x":128,"y":74,"z":192},"requirements":{"minecraft:bricks":28,"minecraft:cobbled_deepslate":51,"minecraft:glass":31,"minecraft:polished_diorite":146,"minecraft:sandstone":10,"minecraft:stone_bricks":55},"sha256":"8b211cea6f2ce4b3a61e394bf4f27635e1247ba7b154c381951ab8fbd9a541d4","size":{"x":32,"y":1,"z":32}},{"blockCount":12,"bytes":1001,"file":"chunks/y074-z192-x160.json","offset":{"x":160,"y":74,"z":192},"requirements":{"minecraft:polished_diorite":12},"sha256":"9922287a3d77faebd92e39c1c5c01f4e5f2148d7c5be5deb8b3e682d39b84345","size":{"x":32,"y":1,"z":32}},{"blockCount":4,"bytes":761,"file":"chunks/y075-z000-x352.json","offset":{"x":352,"y":75,"z":0},"requirements":{"minecraft:polished_diorite":4},"sha256":"c92716fd310b82ffbe718701af10c9b6b33a47b1e9b83250d5e5d52a8d3576d5","size":{"x":32,"y":1,"z":32}},{"blockCount":1,"bytes":642,"file":"chunks/y075-z000-x384.json","offset":{"x":384,"y":75,"z":0},"requirements":{"minecraft:stone_bricks":1},"sha256":"2b44502d944aaa76bb8d64d9601b9e248065bde96c72f17dc6fe184576ffd4e2","size":{"x":32,"y":1,"z":32}},{"blockCount":181,"bytes":5031,"file":"chunks/y075-z064-x064.json","offset":{"x":64,"y":75,"z":64},"requirements":{"minecraft:cobbled_deepslate":41,"minecraft:glass":6,"minecraft:polished_diorite":93,"minecraft:stone_bricks":41},"sha256":"923b31167b1a774dd919bf98a5a5be9c4cd7cf90a5bc54eb491a36c0e44c77fa","size":{"x":32,"y":1,"z":32}},{"blockCount":233,"bytes":5281,"file":"chunks/y075-z064-x096.json","offset":{"x":96,"y":75,"z":64},"requirements":{"minecraft:bricks":32,"minecraft:cobbled_deepslate":14,"minecraft:glass":21,"minecraft:polished_diorite":90,"minecraft:sandstone":21,"minecraft:stone_bricks":55},"sha256":"20a83073c5b96e8aabaa5d9d3d44a6695e071b097fef46bf0a78dc196c4a86e6","size":{"x":32,"y":1,"z":32}},{"blockCount":335,"bytes":7985,"file":"chunks/y075-z064-x128.json","offset":{"x":128,"y":75,"z":64},"requirements":{"minecraft:bricks":33,"minecraft:cobbled_deepslate":56,"minecraft:glass":21,"minecraft:polished_diorite":152,"minecraft:sandstone":8,"minecraft:stone_bricks":65},"sha256":"6835727dd0c6f164baac269a31a80714f08a2b355eca324b65ad32a41b5bf9be","size":{"x":32,"y":1,"z":32}},{"blockCount":14,"bytes":1103,"file":"chunks/y075-z064-x160.json","offset":{"x":160,"y":75,"z":64},"requirements":{"minecraft:polished_diorite":9,"minecraft:stone_bricks":5},"sha256":"6bc400b06b715594068fc1ab737a71b2611f3ff4e472876d378f56d8b4a57df5","size":{"x":32,"y":1,"z":32}},{"blockCount":25,"bytes":1247,"file":"chunks/y075-z064-x192.json","offset":{"x":192,"y":75,"z":64},"requirements":{"minecraft:polished_diorite":14,"minecraft:stone_bricks":11},"sha256":"33c2729e469fd697ef26c2b25f575e5b550f2145c0f4eae62adb1ce634185c8b","size":{"x":32,"y":1,"z":32}},{"blockCount":29,"bytes":1362,"file":"chunks/y075-z064-x224.json","offset":{"x":224,"y":75,"z":64},"requirements":{"minecraft:polished_diorite":16,"minecraft:stone_bricks":13},"sha256":"222c6b4469d5160c99d00985d143c9a25486dae45e893da1766cdb1cab0817f7","size":{"x":32,"y":1,"z":32}},{"blockCount":76,"bytes":3027,"file":"chunks/y075-z096-x000.json","offset":{"x":0,"y":75,"z":96},"requirements":{"minecraft:cobbled_deepslate":17,"minecraft:glass":7,"minecraft:polished_diorite":35,"minecraft:stone_bricks":17},"sha256":"ce23f5261fe3cf2c6b47318fa625026f578dc1d91bc9f06c6c2b5cfc0806c68b","size":{"x":32,"y":1,"z":32}},{"blockCount":311,"bytes":8745,"file":"chunks/y075-z096-x032.json","offset":{"x":32,"y":75,"z":96},"requirements":{"minecraft:bricks":26,"minecraft:cobbled_deepslate":81,"minecraft:glass":14,"minecraft:polished_diorite":101,"minecraft:sandstone":16,"minecraft:stone_bricks":73},"sha256":"4437c3816cbc45c8a1801d39daac5bf4c4371b5c9887e5f334a373c700053a0c","size":{"x":32,"y":1,"z":32}},{"blockCount":378,"bytes":8727,"file":"chunks/y075-z096-x064.json","offset":{"x":64,"y":75,"z":96},"requirements":{"minecraft:bricks":68,"minecraft:cobbled_deepslate":99,"minecraft:glass":15,"minecraft:polished_diorite":93,"minecraft:sandstone":12,"minecraft:stone_bricks":91},"sha256":"e9af080e0a15e90de416042aa2880e06803a60e9a792405bc6ba8119d3cc1a4d","size":{"x":32,"y":1,"z":32}},{"blockCount":133,"bytes":3651,"file":"chunks/y075-z096-x096.json","offset":{"x":96,"y":75,"z":96},"requirements":{"minecraft:bricks":29,"minecraft:cobbled_deepslate":13,"minecraft:glass":13,"minecraft:polished_diorite":15,"minecraft:sandstone":17,"minecraft:stone_bricks":46},"sha256":"2607a3f30f4a63748f91aecafdd5e5462f7bdebc119b1e86ba0e2802e60f90ba","size":{"x":32,"y":1,"z":32}},{"blockCount":317,"bytes":6989,"file":"chunks/y075-z096-x128.json","offset":{"x":128,"y":75,"z":96},"requirements":{"minecraft:bricks":50,"minecraft:cobbled_deepslate":62,"minecraft:glass":19,"minecraft:polished_diorite":92,"minecraft:sandstone":16,"minecraft:stone_bricks":78},"sha256":"fdb685f6e0541cb378f7ce46678d1edec1298e529ce130ef3a14e3cb7e0c085c","size":{"x":32,"y":1,"z":32}},{"blockCount":339,"bytes":9184,"file":"chunks/y075-z096-x160.json","offset":{"x":160,"y":75,"z":96},"requirements":{"minecraft:bricks":40,"minecraft:cobbled_deepslate":63,"minecraft:glass":17,"minecraft:polished_diorite":115,"minecraft:sandstone":9,"minecraft:stone_bricks":95},"sha256":"6f652818393eb7d04324d67d67bcaafd2dada55f4518a05308adc625b96fafef","size":{"x":32,"y":1,"z":32}},{"blockCount":358,"bytes":8271,"file":"chunks/y075-z096-x192.json","offset":{"x":192,"y":75,"z":96},"requirements":{"minecraft:bricks":119,"minecraft:cobbled_deepslate":26,"minecraft:glass":14,"minecraft:oak_planks":4,"minecraft:polished_diorite":86,"minecraft:sandstone":22,"minecraft:stone_bricks":87},"sha256":"a936ca40a738ea322996cdf00e65b40d81592ba36ff91afe5609adc1d7620767","size":{"x":32,"y":1,"z":32}},{"blockCount":178,"bytes":5345,"file":"chunks/y075-z096-x224.json","offset":{"x":224,"y":75,"z":96},"requirements":{"minecraft:bricks":83,"minecraft:glass":7,"minecraft:oak_planks":6,"minecraft:polished_diorite":52,"minecraft:sandstone":1,"minecraft:stone_bricks":29},"sha256":"b980a03f22a40b215a00aa4d23368bcb4cfb6912b958109b3c7c1b26a997a790","size":{"x":32,"y":1,"z":32}},{"blockCount":198,"bytes":4795,"file":"chunks/y075-z128-x000.json","offset":{"x":0,"y":75,"z":128},"requirements":{"minecraft:bricks":30,"minecraft:cobbled_deepslate":72,"minecraft:glass":10,"minecraft:polished_diorite":57,"minecraft:sandstone":1,"minecraft:stone_bricks":28},"sha256":"acf06da2620635a790e6a4aef8eb3c90d227feaada11d7af2bc8d9a5f2feab1b","size":{"x":32,"y":1,"z":32}},{"blockCount":197,"bytes":4622,"file":"chunks/y075-z128-x032.json","offset":{"x":32,"y":75,"z":128},"requirements":{"minecraft:bricks":14,"minecraft:cobbled_deepslate":12,"minecraft:glass":14,"minecraft:polished_diorite":52,"minecraft:sandstone":17,"minecraft:stone_bricks":88},"sha256":"13002b5bf28b1a21b309ae961e68f0d6d004553218df799a3d838773214f4aab","size":{"x":32,"y":1,"z":32}},{"blockCount":66,"bytes":1884,"file":"chunks/y075-z128-x064.json","offset":{"x":64,"y":75,"z":128},"requirements":{"minecraft:bricks":15,"minecraft:cobbled_deepslate":4,"minecraft:glass":12,"minecraft:sandstone":19,"minecraft:stone_bricks":16},"sha256":"823be031c41ff135ee03f6e1c35ada4abb1ee8e769a445d8074ddf9202bc9b84","size":{"x":32,"y":1,"z":32}},{"blockCount":15,"bytes":1013,"file":"chunks/y075-z128-x096.json","offset":{"x":96,"y":75,"z":128},"requirements":{"minecraft:bricks":5,"minecraft:glass":3,"minecraft:sandstone":5,"minecraft:stone_bricks":2},"sha256":"92119263cd636bacb2a6bf4a8cabfdce5770487359be40df47659df68df9a9e4","size":{"x":32,"y":1,"z":32}},{"blockCount":44,"bytes":1563,"file":"chunks/y075-z128-x128.json","offset":{"x":128,"y":75,"z":128},"requirements":{"minecraft:glass":9,"minecraft:sandstone":10,"minecraft:stone_bricks":25},"sha256":"b79ea60bf984c7a7da1612fab36a87b754e054503f5db5a2decad66a9f76beec","size":{"x":32,"y":1,"z":32}},{"blockCount":61,"bytes":1891,"file":"chunks/y075-z128-x160.json","offset":{"x":160,"y":75,"z":128},"requirements":{"minecraft:bricks":13,"minecraft:glass":11,"minecraft:sandstone":20,"minecraft:stone_bricks":17},"sha256":"819255b0329325a26001ff227b199b375aa72615549194bf935dbb367e0f3518","size":{"x":32,"y":1,"z":32}},{"blockCount":75,"bytes":2304,"file":"chunks/y075-z128-x192.json","offset":{"x":192,"y":75,"z":128},"requirements":{"minecraft:bricks":19,"minecraft:glass":11,"minecraft:sandstone":22,"minecraft:stone_bricks":23},"sha256":"201196adc0f53acb1eb029ea6d1cc31adfbc590dab3c64a83e4cfb36f70453ac","size":{"x":32,"y":1,"z":32}},{"blockCount":126,"bytes":3774,"file":"chunks/y075-z128-x224.json","offset":{"x":224,"y":75,"z":128},"requirements":{"minecraft:bricks":27,"minecraft:glass":16,"minecraft:polished_diorite":46,"minecraft:sandstone":7,"minecraft:stone_bricks":30},"sha256":"5b2bb551cb37ad205a5f9cb162609d2057f9c159b4bbd9bdcd882821436d5312","size":{"x":32,"y":1,"z":32}},{"blockCount":47,"bytes":2185,"file":"chunks/y075-z160-x000.json","offset":{"x":0,"y":75,"z":160},"requirements":{"minecraft:cobbled_deepslate":7,"minecraft:glass":4,"minecraft:polished_diorite":24,"minecraft:stone_bricks":12},"sha256":"5a8a3c9ac4cc1d84166233e84fd7f5ce03a8862a71744a2ba29a4d19aecc8f30","size":{"x":32,"y":1,"z":32}},{"blockCount":231,"bytes":6910,"file":"chunks/y075-z160-x032.json","offset":{"x":32,"y":75,"z":160},"requirements":{"minecraft:bricks":15,"minecraft:cobbled_deepslate":74,"minecraft:glass":6,"minecraft:polished_diorite":93,"minecraft:stone_bricks":43},"sha256":"9f83ca552544fc8ebe436f126aaae015d8606b63cc8fcc53a80d3c4fa0d76590","size":{"x":32,"y":1,"z":32}},{"blockCount":353,"bytes":8459,"file":"chunks/y075-z160-x064.json","offset":{"x":64,"y":75,"z":160},"requirements":{"minecraft:bricks":40,"minecraft:cobbled_deepslate":103,"minecraft:glass":5,"minecraft:polished_diorite":140,"minecraft:stone_bricks":65},"sha256":"4b1d4dabc2d17f82a141bafc4e626f2aec29109d735ab1db7830f5f5cf27d099","size":{"x":32,"y":1,"z":32}},{"blockCount":147,"bytes":4034,"file":"chunks/y075-z160-x096.json","offset":{"x":96,"y":75,"z":160},"requirements":{"minecraft:bricks":30,"minecraft:cobbled_deepslate":15,"minecraft:glass":13,"minecraft:polished_diorite":39,"minecraft:sandstone":8,"minecraft:stone_bricks":42},"sha256":"ea05982bfafc2261bc72c573fcdf9e8b56484d6762dcfe42a4805a09d8f45fd6","size":{"x":32,"y":1,"z":32}},{"blockCount":346,"bytes":7715,"file":"chunks/y075-z160-x128.json","offset":{"x":128,"y":75,"z":160},"requirements":{"minecraft:bricks":32,"minecraft:cobbled_deepslate":76,"minecraft:glass":17,"minecraft:polished_diorite":122,"minecraft:sandstone":19,"minecraft:stone_bricks":80},"sha256":"5b207ef437116f3131d512522e781621f99a8828649fc0bdd325a697022b65e9","size":{"x":32,"y":1,"z":32}},{"blockCount":280,"bytes":7943,"file":"chunks/y075-z160-x160.json","offset":{"x":160,"y":75,"z":160},"requirements":{"minecraft:bricks":35,"minecraft:cobbled_deepslate":65,"minecraft:glass":6,"minecraft:polished_diorite":116,"minecraft:stone_bricks":58},"sha256":"3e801a4253bb26683653a6a81fe21933368a31d9168dd3fe52b9d216c84304d2","size":{"x":32,"y":1,"z":32}},{"blockCount":316,"bytes":7637,"file":"chunks/y075-z160-x192.json","offset":{"x":192,"y":75,"z":160},"requirements":{"minecraft:bricks":111,"minecraft:cobbled_deepslate":26,"minecraft:glass":3,"minecraft:oak_planks":4,"minecraft:polished_diorite":98,"minecraft:stone_bricks":74},"sha256":"3c35783863f8dd72278ed750363f79e4fe6bafbfb8513d0272037ff7d593fa37","size":{"x":32,"y":1,"z":32}},{"blockCount":169,"bytes":5130,"file":"chunks/y075-z160-x224.json","offset":{"x":224,"y":75,"z":160},"requirements":{"minecraft:bricks":77,"minecraft:glass":3,"minecraft:oak_planks":6,"minecraft:polished_diorite":50,"minecraft:stone_bricks":33},"sha256":"64f634f574847e576e7a1eb0476f2b87f0819adb5a6670379be9655461ede890","size":{"x":32,"y":1,"z":32}},{"blockCount":140,"bytes":4077,"file":"chunks/y075-z192-x064.json","offset":{"x":64,"y":75,"z":192},"requirements":{"minecraft:cobbled_deepslate":31,"minecraft:glass":4,"minecraft:polished_diorite":74,"minecraft:stone_bricks":31},"sha256":"4e3fd6cf6edd3046345e771f08cd1d8920f87610c5538bae2d27e837842057ab","size":{"x":32,"y":1,"z":32}},{"blockCount":198,"bytes":4571,"file":"chunks/y075-z192-x096.json","offset":{"x":96,"y":75,"z":192},"requirements":{"minecraft:bricks":34,"minecraft:cobbled_deepslate":8,"minecraft:glass":18,"minecraft:polished_diorite":78,"minecraft:sandstone":9,"minecraft:stone_bricks":51},"sha256":"1954ab1ab23c021bc6d2633bb68adae9a6f3e8b7ece2be87c3751fc0ff7d81ac","size":{"x":32,"y":1,"z":32}},{"blockCount":265,"bytes":6554,"file":"chunks/y075-z192-x128.json","offset":{"x":128,"y":75,"z":192},"requirements":{"minecraft:bricks":22,"minecraft:cobbled_deepslate":39,"minecraft:glass":17,"minecraft:polished_diorite":122,"minecraft:sandstone":7,"minecraft:stone_bricks":58},"sha256":"d71cd106ba40224b03ae89c5d7fae009f446874d7902e1384c440fc046ae203b","size":{"x":32,"y":1,"z":32}},{"blockCount":12,"bytes":1027,"file":"chunks/y075-z192-x160.json","offset":{"x":160,"y":75,"z":192},"requirements":{"minecraft:polished_diorite":8,"minecraft:stone_bricks":4},"sha256":"6535adfc0b27900da596c169e87dee78a02ee42c2a685562ef2e776389f0feea","size":{"x":32,"y":1,"z":32}},{"blockCount":8,"bytes":865,"file":"chunks/y076-z000-x352.json","offset":{"x":352,"y":76,"z":0},"requirements":{"minecraft:polished_diorite":4,"minecraft:stone_bricks":4},"sha256":"7a41a00bc1f2f3d1c5132bbe8e3559ec2f70a382d88fd2eec3e6a22f7c928666","size":{"x":32,"y":1,"z":32}},{"blockCount":1,"bytes":642,"file":"chunks/y076-z000-x384.json","offset":{"x":384,"y":76,"z":0},"requirements":{"minecraft:stone_bricks":1},"sha256":"efbdc0cb02d2f618e4aaa5bfddbd8354cd3f43bfa2851713308010ba4e472648","size":{"x":32,"y":1,"z":32}},{"blockCount":172,"bytes":4289,"file":"chunks/y076-z064-x064.json","offset":{"x":64,"y":76,"z":64},"requirements":{"minecraft:cobbled_deepslate":39,"minecraft:polished_diorite":93,"minecraft:stone_bricks":40},"sha256":"4bfd628dd25827380e1146eacee2cd4513c2852169c3f2629c440868cf69d855","size":{"x":32,"y":1,"z":32}},{"blockCount":232,"bytes":4409,"file":"chunks/y076-z064-x096.json","offset":{"x":96,"y":76,"z":64},"requirements":{"minecraft:bricks":40,"minecraft:cobbled_deepslate":14,"minecraft:glass":12,"minecraft:polished_diorite":105,"minecraft:sandstone":21,"minecraft:stone_bricks":40},"sha256":"df45ec84f6fe56e4be5ea80e05aeddb742bca713a759b6a254e99e2a90303123","size":{"x":32,"y":1,"z":32}},{"blockCount":316,"bytes":6643,"file":"chunks/y076-z064-x128.json","offset":{"x":128,"y":76,"z":64},"requirements":{"minecraft:bricks":33,"minecraft:cobbled_deepslate":51,"minecraft:glass":6,"minecraft:polished_diorite":163,"minecraft:sandstone":8,"minecraft:stone_bricks":55},"sha256":"93df120615ee0737d15415e8e7057b8c6847080317a96a1ef1a798e76da57731","size":{"x":32,"y":1,"z":32}},{"blockCount":14,"bytes":1103,"file":"chunks/y076-z064-x160.json","offset":{"x":160,"y":76,"z":64},"requirements":{"minecraft:polished_diorite":9,"minecraft:stone_bricks":5},"sha256":"ec20bb5f1cf032dcb55e7cf433ee358881ba267c263625c61ad8a2d12cb2a6a7","size":{"x":32,"y":1,"z":32}},{"blockCount":19,"bytes":1208,"file":"chunks/y076-z064-x192.json","offset":{"x":192,"y":76,"z":64},"requirements":{"minecraft:polished_diorite":11,"minecraft:stone_bricks":8},"sha256":"1f258c49b53a8261ff73c74f743072d41ed8fc30ecfb0f6f4dd226132c0f547d","size":{"x":32,"y":1,"z":32}},{"blockCount":23,"bytes":1285,"file":"chunks/y076-z064-x224.json","offset":{"x":224,"y":76,"z":64},"requirements":{"minecraft:polished_diorite":15,"minecraft:stone_bricks":8},"sha256":"4187dc07f09a3b5fd39b658fcf7ea8ec713a30b8cc5657229a46cf15377e7681","size":{"x":32,"y":1,"z":32}},{"blockCount":70,"bytes":2664,"file":"chunks/y076-z096-x000.json","offset":{"x":0,"y":76,"z":96},"requirements":{"minecraft:cobbled_deepslate":17,"minecraft:polished_diorite":36,"minecraft:stone_bricks":17},"sha256":"f3db2bc75ef9e9f47068696a98ecc7341e172ddfff0d63a03751d5c860e2f69c","size":{"x":32,"y":1,"z":32}},{"blockCount":288,"bytes":7889,"file":"chunks/y076-z096-x032.json","offset":{"x":32,"y":76,"z":96},"requirements":{"minecraft:bricks":26,"minecraft:cobbled_deepslate":76,"minecraft:polished_diorite":110,"minecraft:sandstone":17,"minecraft:stone_bricks":59},"sha256":"804c2a7878c8b9591aeb30808c5e9764f7187ef9741946734f5ee44e7bd917b6","size":{"x":32,"y":1,"z":32}}],"schema":1}
