{"entries":[{"blockCount":349,"bytes":7835,"file":"chunks/y076-z096-x064.json","offset":{"x":64,"y":76,"z":96},"requirements":{"minecraft:bricks":72,"minecraft:cobbled_deepslate":85,"minecraft:polished_diorite":95,"minecraft:sandstone":12,"minecraft:stone_bricks":85},"sha256":"cb246c672a4d3b7893179fc4e2b105fc8f70f2d9e6fb518a8958709143a4689f","size":{"x":32,"y":1,"z":32}},{"blockCount":113,"bytes":3041,"file":"chunks/y076-z096-x096.json","offset":{"x":96,"y":76,"z":96},"requirements":{"minecraft:bricks":28,"minecraft:cobbled_deepslate":10,"minecraft:polished_diorite":21,"minecraft:sandstone":17,"minecraft:stone_bricks":37},"sha256":"fb7b48287732b263680e3e8943bca077bd53e25d0d2b2267f17749797271b1c1","size":{"x":32,"y":1,"z":32}},{"blockCount":284,"bytes":6030,"file":"chunks/y076-z096-x128.json","offset":{"x":128,"y":76,"z":96},"requirements":{"minecraft:bricks":48,"minecraft:cobbled_deepslate":54,"minecraft:polished_diorite":103,"minecraft:sandstone":16,"minecraft:stone_bricks":63},"sha256":"c1019e5db57c80a6efa92cf148b1cf1e7ae94b53231f2ac8da980a2e0bec317f","size":{"x":32,"y":1,"z":32}},{"blockCount":310,"bytes":8005,"file":"chunks/y076-z096-x160.json","offset":{"x":160,"y":76,"z":96},"requirements":{"minecraft:bricks":40,"minecraft:cobbled_deepslate":64,"minecraft:polished_diorite":124,"minecraft:sandstone":9,"minecraft:stone_bricks":73},"sha256":"5a2801b5623aa19667ac3cf7a6d38f645c69686c9a5d60e4c6070dddbd84ae0d","size":{"x":32,"y":1,"z":32}},{"blockCount":334,"bytes":7208,"file":"chunks/y076-z096-x192.json","offset":{"x":192,"y":76,"z":96},"requirements":{"minecraft:bricks":121,"minecraft:cobbled_deepslate":27,"minecraft:oak_planks":4,"minecraft:polished_diorite":93,"minecraft:sandstone":22,"minecraft:stone_bricks":67},"sha256":"4d9199ffc5f644d898e53a23e9917db4d2ae95dd855ab7cba8fcbd1aa5bdd558","size":{"x":32,"y":1,"z":32}},{"blockCount":169,"bytes":5079,"file":"chunks/y076-z096-x224.json","offset":{"x":224,"y":76,"z":96},"requirements":{"minecraft:bricks":83,"minecraft:glass":6,"minecraft:oak_planks":6,"minecraft:polished_diorite":52,"minecraft:sandstone":1,"minecraft:stone_bricks":21},"sha256":"f08ba28a8e1b9e93caf7cb7a51ca5e3d8054c8a21a11450845c966bdd15a21a3","size":{"x":32,"y":1,"z":32}},{"blockCount":188,"bytes":4197,"file":"chunks/y076-z128-x000.json","offset":{"x":0,"y":76,"z":128},"requirements":{"minecraft:bricks":26,"minecraft:cobbled_deepslate":80,"minecraft:polished_diorite":58,"minecraft:stone_bricks":24},"sha256":"3e20a7cb0eb1c7201e8c8b5ff92ecf352122034268bbda236871760850202d20","size":{"x":32,"y":1,"z":32}},{"blockCount":187,"bytes":4318,"file":"chunks/y076-z128-x032.json","offset":{"x":32,"y":76,"z":128},"requirements":{"minecraft:bricks":13,"minecraft:cobbled_deepslate":20,"minecraft:glass":6,"minecraft:polished_diorite":60,"minecraft:sandstone":19,"minecraft:stone_bricks":69},"sha256":"3d1c1341d3a802e412e3453c8b54d2ba8fce65989ef3a363a7d886f0ed91a2b9","size":{"x":32,"y":1,"z":32}},{"blockCount":50,"bytes":1351,"file":"chunks/y076-z128-x064.json","offset":{"x":64,"y":76,"z":128},"requirements":{"minecraft:bricks":15,"minecraft:cobbled_deepslate":4,"minecraft:sandstone":19,"minecraft:stone_bricks":12},"sha256":"104ff1b96143cbbee88456382d60921a9c71de53701568292eefd7a1e0ce4abb","size":{"x":32,"y":1,"z":32}},{"blockCount":12,"bytes":879,"file":"chunks/y076-z128-x096.json","offset":{"x":96,"y":76,"z":128},"requirements":{"minecraft:bricks":5,"minecraft:sandstone":5,"minecraft:stone_bricks":2},"sha256":"c68b89c47f73edb2125d3a2d4f6fa9cfd21d486a86e66b970d33c66ca9228c09","size":{"x":32,"y":1,"z":32}},{"blockCount":34,"bytes":1184,"file":"chunks/y076-z128-x128.json","offset":{"x":128,"y":76,"z":128},"requirements":{"minecraft:sandstone":10,"minecraft:stone_bricks":24},"sha256":"331dd3d9be4e76711d90a43b2cae614bb51a7fe03d50dd4762177a4d6bda4c57","size":{"x":32,"y":1,"z":32}},{"blockCount":45,"bytes":1359,"file":"chunks/y076-z128-x160.json","offset":{"x":160,"y":76,"z":128},"requirements":{"minecraft:bricks":13,"minecraft:sandstone":20,"minecraft:stone_bricks":12},"sha256":"7fd6e3137470ce248c4c8dd382e3cac82c4e278f3a534cf8dcc6404dae78efa2","size":{"x":32,"y":1,"z":32}},{"blockCount":63,"bytes":1926,"file":"chunks/y076-z128-x192.json","offset":{"x":192,"y":76,"z":128},"requirements":{"minecraft:bricks":22,"minecraft:sandstone":22,"minecraft:stone_bricks":19},"sha256":"a172681f2a53b362dc14d71d17278c77ac26b5dfead2def514331c5c95b5e0d8","size":{"x":32,"y":1,"z":32}},{"blockCount":137,"bytes":3850,"file":"chunks/y076-z128-x224.json","offset":{"x":224,"y":76,"z":128},"requirements":{"minecraft:bricks":32,"minecraft:glass":15,"minecraft:polished_diorite":56,"minecraft:sandstone":7,"minecraft:stone_bricks":27},"sha256":"d7570e70125fd54cc5d0928c7ada1155ab0c1d0c5f47f8aa3d6da1b16335e900","size":{"x":32,"y":1,"z":32}},{"blockCount":44,"bytes":1898,"file":"chunks/y076-z160-x000.json","offset":{"x":0,"y":76,"z":160},"requirements":{"minecraft:cobbled_deepslate":9,"minecraft:polished_diorite":24,"minecraft:stone_bricks":11},"sha256":"c069d4806b475b3ac1cd78d046693c7878397f52b666b31317df85d887dcd725","size":{"x":32,"y":1,"z":32}},{"blockCount":220,"bytes":6416,"file":"chunks/y076-z160-x032.json","offset":{"x":32,"y":76,"z":160},"requirements":{"minecraft:bricks":15,"minecraft:cobbled_deepslate":68,"minecraft:polished_diorite":101,"minecraft:stone_bricks":36},"sha256":"e151a6c7b54e6c27842918547cb822f894738eedfb3db0cd1dd3de0483a2ca08","size":{"x":32,"y":1,"z":32}},{"blockCount":338,"bytes":7717,"file":"chunks/y076-z160-x064.json","offset":{"x":64,"y":76,"z":160},"requirements":{"minecraft:bricks":41,"minecraft:cobbled_deepslate":94,"minecraft:polished_diorite":145,"minecraft:stone_bricks":58},"sha256":"a82d3b1df812682514336ce3aedb4c5b9949e96c72efd1e16e270dcf5152491c","size":{"x":32,"y":1,"z":32}},{"blockCount":125,"bytes":3310,"file":"chunks/y076-z160-x096.json","offset":{"x":96,"y":76,"z":160},"requirements":{"minecraft:bricks":30,"minecraft:cobbled_deepslate":15,"minecraft:polished_diorite":46,"minecraft:sandstone":8,"minecraft:stone_bricks":26},"sha256":"1337e3f07de4bfaa5dfe484d5ef8bb14e412ad3471b8e2b2d6e11acf984d2603","size":{"x":32,"y":1,"z":32}},{"blockCount":313,"bytes":6700,"file":"chunks/y076-z160-x128.json","offset":{"x":128,"y":76,"z":160},"requirements":{"minecraft:bricks":30,"minecraft:cobbled_deepslate":66,"minecraft:polished_diorite":135,"minecraft:sandstone":19,"minecraft:stone_bricks":63},"sha256":"1953abdb89bf1bc3a2ff9a0d0f57747cb217f4c2b206f3b1d833d512ce944e74","size":{"x":32,"y":1,"z":32}},{"blockCount":267,"bytes":7353,"file":"chunks/y076-z160-x160.json","offset":{"x":160,"y":76,"z":160},"requirements":{"minecraft:bricks":35,"minecraft:cobbled_deepslate":58,"minecraft:polished_diorite":125,"minecraft:stone_bricks":49},"sha256":"8f825204ff576d50eec2ea51cc102efb9a907bd94251b29dcff123ac2a1d8556","size":{"x":32,"y":1,"z":32}},{"blockCount":303,"bytes":7049,"file":"chunks/y076-z160-x192.json","offset":{"x":192,"y":76,"z":160},"requirements":{"minecraft:bricks":113,"minecraft:cobbled_deepslate":26,"minecraft:oak_planks":4,"minecraft:polished_diorite":104,"minecraft:stone_bricks":56},"sha256":"af1c0b0507c107d8496ba7dfe1e0a8b2ee6e5b9fbb50599db22401f29bbb2e04","size":{"x":32,"y":1,"z":32}},{"blockCount":153,"bytes":4826,"file":"chunks/y076-z160-x224.json","offset":{"x":224,"y":76,"z":160},"requirements":{"minecraft:bricks":77,"minecraft:glass":3,"minecraft:oak_planks":6,"minecraft:polished_diorite":47,"minecraft:stone_bricks":20},"sha256":"bf38d50e96ff436acd8db5e3b10dd2bccffe06e9ebc2d9fd100348e00a1667d8","size":{"x":32,"y":1,"z":32}},{"blockCount":132,"bytes":3506,"file":"chunks/y076-z192-x064.json","offset":{"x":64,"y":76,"z":192},"requirements":{"minecraft:cobbled_deepslate":28,"minecraft:polished_diorite":74,"minecraft:stone_bricks":30},"sha256":"bab14da45910a06073c888094d11bfe68d48c8920a2891f7437fae01e4723f78","size":{"x":32,"y":1,"z":32}},{"blockCount":202,"bytes":3851,"file":"chunks/y076-z192-x096.json","offset":{"x":96,"y":76,"z":192},"requirements":{"minecraft:bricks":42,"minecraft:cobbled_deepslate":10,"minecraft:glass":12,"minecraft:polished_diorite":91,"minecraft:sandstone":9,"minecraft:stone_bricks":38},"sha256":"2ed36c966b20144a74e9818fad2be144ba46ef4bff67cdd709e852cfb797955c","size":{"x":32,"y":1,"z":32}},{"blockCount":252,"bytes":5384,"file":"chunks/y076-z192-x128.json","offset":{"x":128,"y":76,"z":192},"requirements":{"minecraft:bricks":22,"minecraft:cobbled_deepslate":39,"minecraft:glass":6,"minecraft:polished_diorite":131,"minecraft:sandstone":7,"minecraft:stone_bricks":47},"sha256":"af3e970db3d5aa373d626f171be37eed152ddf092281515927c1501203876756","size":{"x":32,"y":1,"z":32}},{"blockCount":12,"bytes":1027,"file":"chunks/y076-z192-x160.json","offset":{"x":160,"y":76,"z":192},"requirements":{"minecraft:polished_diorite":8,"minecraft:stone_bricks":4},"sha256":"5ac9a6fca6ea2525f49962080a5778d1c5ec2cccf92f58820f1e0fd118ffaa95","size":{"x":32,"y":1,"z":32}},{"blockCount":12,"bytes":837,"file":"chunks/y077-z000-x352.json","offset":{"x":352,"y":77,"z":0},"requirements":{"minecraft:stone_bricks":12},"sha256":"d22fd53514a7c146a264d31a1e22edabe3d2f3dc96e30264409fd62cbd957edb","size":{"x":32,"y":1,"z":32}},{"blockCount":1,"bytes":642,"file":"chunks/y077-z000-x384.json","offset":{"x":384,"y":77,"z":0},"requirements":{"minecraft:stone_bricks":1},"sha256":"cf45380a43907dbf8678dc973d3b7832ab661a724b247628375490359609b0cf","size":{"x":32,"y":1,"z":32}},{"blockCount":128,"bytes":3173,"file":"chunks/y077-z064-x064.json","offset":{"x":64,"y":77,"z":64},"requirements":{"minecraft:cobbled_deepslate":32,"minecraft:polished_diorite":66,"minecraft:sandstone":2,"minecraft:stone_bricks":28},"sha256":"3dcb656125864aaca4d5d6e21ab19be7fd52ec12809d3da9a9a9d3fe75b53bda","size":{"x":32,"y":1,"z":32}},{"blockCount":242,"bytes":4638,"file":"chunks/y077-z064-x096.json","offset":{"x":96,"y":77,"z":64},"requirements":{"minecraft:bricks":40,"minecraft:cobbled_deepslate":15,"minecraft:glass":12,"minecraft:polished_diorite":102,"minecraft:sandstone":21,"minecraft:stone_bricks":52},"sha256":"c807d4acf030ae09ac3aba5317cd48dbd6656d96c7a83ffa4ddbdbe497b766e5","size":{"x":32,"y":1,"z":32}},{"blockCount":285,"bytes":5891,"file":"chunks/y077-z064-x128.json","offset":{"x":128,"y":77,"z":64},"requirements":{"minecraft:bricks":33,"minecraft:cobbled_deepslate":47,"minecraft:glass":6,"minecraft:polished_diorite":136,"minecraft:sandstone":10,"minecraft:stone_bricks":53},"sha256":"ee78d2a4c899199eb4a04d979ccc18bc35a4e0b8909315b57980b50e8ee45be2","size":{"x":32,"y":1,"z":32}},{"blockCount":9,"bytes":908,"file":"chunks/y077-z064-x160.json","offset":{"x":160,"y":77,"z":64},"requirements":{"minecraft:polished_diorite":4,"minecraft:stone_bricks":5},"sha256":"a159755bd2d7a46740624b384ad597726b18aa6b3b853204d51008c9bf11eb87","size":{"x":32,"y":1,"z":32}},{"blockCount":17,"bytes":1056,"file":"chunks/y077-z064-x192.json","offset":{"x":192,"y":77,"z":64},"requirements":{"minecraft:polished_diorite":7,"minecraft:stone_bricks":10},"sha256":"46145eeceebb73d92eae999b8a82dc50fb58465b8906a191263663b500e41cf7","size":{"x":32,"y":1,"z":32}},{"blockCount":21,"bytes":1172,"file":"chunks/y077-z064-x224.json","offset":{"x":224,"y":77,"z":64},"requirements":{"minecraft:polished_diorite":9,"minecraft:stone_bricks":12},"sha256":"78aef41fb53d7a7275599dc97e83217c73f5bc2abaab349ebbddb953915126b7","size":{"x":32,"y":1,"z":32}},{"blockCount":64,"bytes":2358,"file":"chunks/y077-z096-x000.json","offset":{"x":0,"y":77,"z":96},"requirements":{"minecraft:cobbled_deepslate":25,"minecraft:polished_diorite":20,"minecraft:stone_bricks":19},"sha256":"b80a4579cb4a28dd00384924e0953e3a0d55e97f07886cde9911a5c06cf22765","size":{"x":32,"y":1,"z":32}},{"blockCount":251,"bytes":6658,"file":"chunks/y077-z096-x032.json","offset":{"x":32,"y":77,"z":96},"requirements":{"minecraft:bricks":30,"minecraft:cobbled_deepslate":62,"minecraft:polished_diorite":74,"minecraft:sandstone":16,"minecraft:stone_bricks":69},"sha256":"c1b86661b68e5d7979514cc81f472dbf4340e1fe51fbd6effff1323834e7f98e","size":{"x":32,"y":1,"z":32}},{"blockCount":295,"bytes":6264,"file":"chunks/y077-z096-x064.json","offset":{"x":64,"y":77,"z":96},"requirements":{"minecraft:bricks":65,"minecraft:cobbled_deepslate":79,"minecraft:polished_diorite":70,"minecraft:sandstone":15,"minecraft:stone_bricks":66},"sha256":"9f263e138bf3f644ead6cfacf009faa0405997ddd66ee0b348ba9850ac46ad0e","size":{"x":32,"y":1,"z":32}},{"blockCount":119,"bytes":3097,"file":"chunks/y077-z096-x096.json","offset":{"x":96,"y":77,"z":96},"requirements":{"minecraft:bricks":24,"minecraft:cobbled_deepslate":8,"minecraft:polished_diorite":22,"minecraft:sandstone":17,"minecraft:stone_bricks":48},"sha256":"12fac0113c60d77a237cac2a0f2006724eb0824e48204ec4c5caf4b332e676fb","size":{"x":32,"y":1,"z":32}},{"blockCount":267,"bytes":5598,"file":"chunks/y077-z096-x128.json","offset":{"x":128,"y":77,"z":96},"requirements":{"minecraft:bricks":51,"minecraft:cobbled_deepslate":54,"minecraft:polished_diorite":82,"minecraft:sandstone":18,"minecraft:stone_bricks":62},"sha256":"09a147b697e30c271315bc8c12783f98622afd809d4cbaa158718e4171597222","size":{"x":32,"y":1,"z":32}},{"blockCount":264,"bytes":6190,"file":"chunks/y077-z096-x160.json","offset":{"x":160,"y":77,"z":96},"requirements":{"minecraft:bricks":49,"minecraft:cobbled_deepslate":51,"minecraft:polished_diorite":81,"minecraft:sandstone":11,"minecraft:stone_bricks":72},"sha256":"6cad760bec58329104aebfab7ee88c7af4c9f2b9fab2bb09c0507c0794b95923","size":{"x":32,"y":1,"z":32}},{"blockCount":308,"bytes":6320,"file":"chunks/y077-z096-x192.json","offset":{"x":192,"y":77,"z":96},"requirements":{"minecraft:bricks":123,"minecraft:cobbled_deepslate":24,"minecraft:oak_planks":4,"minecraft:polished_diorite":64,"minecraft:sandstone":23,"minecraft:stone_bricks":70},"sha256":"c23a5e76ad6b5b73353978b3c8cf9690edfa39649be082060e128ae6f8cd16bb","size":{"x":32,"y":1,"z":32}},{"blockCount":164,"bytes":4946,"file":"chunks/y077-z096-x224.json","offset":{"x":224,"y":77,"z":96},"requirements":{"minecraft:bricks":83,"minecraft:glass":6,"minecraft:oak_planks":6,"minecraft:polished_diorite":41,"minecraft:sandstone":1,"minecraft:stone_bricks":27},"sha256":"f937c1b2a6df395e3a067c8b6fc6d656db73c4a9099f2064eee7d5c8e72b92f3","size":{"x":32,"y":1,"z":32}},{"blockCount":159,"bytes":3568,"file":"chunks/y077-z128-x000.json","offset":{"x":0,"y":77,"z":128},"requirements":{"minecraft:bricks":23,"minecraft:cobbled_deepslate":78,"minecraft:polished_diorite":34,"minecraft:stone_bricks":24},"sha256":"5944fa928b5dfb29cec0dbdf9b01ac2a66befe43814bfad3799455f129eb7059","size":{"x":32,"y":1,"z":32}},{"blockCount":195,"bytes":4152,"file":"chunks/y077-z128-x032.json","offset":{"x":32,"y":77,"z":128},"requirements":{"minecraft:bricks":17,"minecraft:cobbled_deepslate":14,"minecraft:oak_planks":2,"minecraft:polished_diorite":58,"minecraft:sandstone":19,"minecraft:stone_bricks":85},"sha256":"0e33139fd80c4f781fddc1b954456afac81b2278cadb7e25fc79ebd7936ef6d5","size":{"x":32,"y":1,"z":32}},{"blockCount":52,"bytes":1275,"file":"chunks/y077-z128-x064.json","offset":{"x":64,"y":77,"z":128},"requirements":{"minecraft:bricks":15,"minecraft:cobbled_deepslate":4,"minecraft:sandstone":19,"minecraft:stone_bricks":14},"sha256":"5f1376c647b8054a6d03a421133dfe0bb46828928f0cebe8b7f294072dface96","size":{"x":32,"y":1,"z":32}},{"blockCount":13,"bytes":879,"file":"chunks/y077-z128-x096.json","offset":{"x":96,"y":77,"z":128},"requirements":{"minecraft:bricks":5,"minecraft:sandstone":5,"minecraft:stone_bricks":3},"sha256":"0bcf805650bfd2f402ec99a1bb968ae6f95ec1c211f56ce034eb0986990effbd","size":{"x":32,"y":1,"z":32}},{"blockCount":36,"bytes":1108,"file":"chunks/y077-z128-x128.json","offset":{"x":128,"y":77,"z":128},"requirements":{"minecraft:sandstone":10,"minecraft:stone_bricks":26},"sha256":"b0725eec6f00a3344e727d49133012bff8b9c98cc185ccab51098258ff640e75","size":{"x":32,"y":1,"z":32}},{"blockCount":47,"bytes":1283,"file":"chunks/y077-z128-x160.json","offset":{"x":160,"y":77,"z":128},"requirements":{"minecraft:bricks":13,"minecraft:sandstone":20,"minecraft:stone_bricks":14},"sha256":"cae8c30136d062c16d9e917655dd9a4a20fe4892871c896362d06a7f7cfc847d","size":{"x":32,"y":1,"z":32}},{"blockCount":66,"bytes":1831,"file":"chunks/y077-z128-x192.json","offset":{"x":192,"y":77,"z":128},"requirements":{"minecraft:bricks":22,"minecraft:sandstone":22,"minecraft:stone_bricks":22},"sha256":"0a5919f3191fdbeeed9175bfc34dd923657ad1d6123b4d1850595f5d1e033415","size":{"x":32,"y":1,"z":32}},{"blockCount":133,"bytes":3679,"file":"chunks/y077-z128-x224.json","offset":{"x":224,"y":77,"z":128},"requirements":{"minecraft:bricks":32,"minecraft:glass":15,"minecraft:polished_diorite":52,"minecraft:sandstone":7,"minecraft:stone_bricks":27},"sha256":"8218ddc6eb526ff4a92f65ffc1adf83563533731297e2e739c84c3d928ce9e94","size":{"x":32,"y":1,"z":32}},{"blockCount":33,"bytes":1611,"file":"chunks/y077-z160-x000.json","offset":{"x":0,"y":77,"z":160},"requirements":{"minecraft:cobbled_deepslate":8,"minecraft:polished_diorite":14,"minecraft:stone_bricks":11},"sha256":"27b7cc2841654b451d803fedbc53596a54ce6bd858b8a99e6add76fd297fd6eb","size":{"x":32,"y":1,"z":32}},{"blockCount":185,"bytes":5456,"file":"chunks/y077-z160-x032.json","offset":{"x":32,"y":77,"z":160},"requirements":{"minecraft:bricks":19,"minecraft:cobbled_deepslate":57,"minecraft:polished_diorite":68,"minecraft:sandstone":1,"minecraft:stone_bricks":40},"sha256":"a1de3420d1d2d832d775c93c5cfc0b2029ecca5ef89c8c9155d29a0e2b5b6ae2","size":{"x":32,"y":1,"z":32}},{"blockCount":270,"bytes":6074,"file":"chunks/y077-z160-x064.json","offset":{"x":64,"y":77,"z":160},"requirements":{"minecraft:bricks":41,"minecraft:cobbled_deepslate":76,"minecraft:polished_diorite":106,"minecraft:sandstone":4,"minecraft:stone_bricks":43},"sha256":"4965e829d539416a5af6b14bd69c07c656cb4bf4e40946ad895f37a4c78c02a8","size":{"x":32,"y":1,"z":32}},{"blockCount":133,"bytes":3367,"file":"chunks/y077-z160-x096.json","offset":{"x":96,"y":77,"z":160},"requirements":{"minecraft:bricks":27,"minecraft:cobbled_deepslate":14,"minecraft:polished_diorite":45,"minecraft:sandstone":8,"minecraft:stone_bricks":39},"sha256":"f973d05971190211052110b646e6a0930ab6c86b3f384beb1ed8b869cfeb5dc6","size":{"x":32,"y":1,"z":32}},{"blockCount":287,"bytes":6045,"file":"chunks/y077-z160-x128.json","offset":{"x":128,"y":77,"z":160},"requirements":{"minecraft:bricks":33,"minecraft:cobbled_deepslate":69,"minecraft:polished_diorite":107,"minecraft:sandstone":22,"minecraft:stone_bricks":56},"sha256":"92eb3a17a9b302213114489295f789ad6e0ba12a9dd2ea753edb08bed7ea521b","size":{"x":32,"y":1,"z":32}},{"blockCount":218,"bytes":5580,"file":"chunks/y077-z160-x160.json","offset":{"x":160,"y":77,"z":160},"requirements":{"minecraft:bricks":44,"minecraft:cobbled_deepslate":51,"minecraft:polished_diorite":81,"minecraft:sandstone":2,"minecraft:stone_bricks":40},"sha256":"f123df527c8aa7021d4743ccb24e474c20f0ce96fe4487b8b52d0b1654122dc9","size":{"x":32,"y":1,"z":32}},{"blockCount":271,"bytes":6166,"file":"chunks/y077-z160-x192.json","offset":{"x":192,"y":77,"z":160},"requirements":{"minecraft:bricks":115,"minecraft:cobbled_deepslate":24,"minecraft:oak_planks":4,"minecraft:polished_diorite":70,"minecraft:sandstone":1,"minecraft:stone_bricks":57},"sha256":"bfb2da5c8835749472998d5315ca29b8f44902eac5112729859fc820b4438b3d","size":{"x":32,"y":1,"z":32}},{"blockCount":150,"bytes":4675,"file":"chunks/y077-z160-x224.json","offset":{"x":224,"y":77,"z":160},"requirements":{"minecraft:bricks":77,"minecraft:glass":3,"minecraft:oak_planks":6,"minecraft:polished_diorite":34,"minecraft:stone_bricks":30},"sha256":"4f6f4f71968cca740085937fe0e1058cfbcd9fb34f8c7c38a444153885622e47","size":{"x":32,"y":1,"z":32}},{"blockCount":101,"bytes":2542,"file":"chunks/y077-z192-x064.json","offset":{"x":64,"y":77,"z":192},"requirements":{"minecraft:cobbled_deepslate":28,"minecraft:polished_diorite":54,"minecraft:sandstone":1,"minecraft:stone_bricks":18},"sha256":"76947ecd8e02bdce9f5dd99dbbc7f9ab7403dd391c1b93a376eeedfb0349cc89","size":{"x":32,"y":1,"z":32}},{"blockCount":209,"bytes":3947,"file":"chunks/y077-z192-x096.json","offset":{"x":96,"y":77,"z":192},"requirements":{"minecraft:bricks":42,"minecraft:cobbled_deepslate":12,"minecraft:glass":12,"minecraft:polished_diorite":89,"minecraft:sandstone":9,"minecraft:stone_bricks":45},"sha256":"9fe8ab76a990b193a197bf16bf6953448f37f312a8979178e3f5f435f08f49ac","size":{"x":32,"y":1,"z":32}},{"blockCount":229,"bytes":4875,"file":"chunks/y077-z192-x128.json","offset":{"x":128,"y":77,"z":192},"requirements":{"minecraft:bricks":22,"minecraft:cobbled_deepslate":36,"minecraft:glass":6,"minecraft:polished_diorite":111,"minecraft:sandstone":8,"minecraft:stone_bricks":46},"sha256":"0ec8aff904dc07718fc3abcbc0a56fa7dd29304e19cba6b1219a4196663f127c","size":{"x":32,"y":1,"z":32}},{"blockCount":8,"bytes":871,"file":"chunks/y077-z192-x160.json","offset":{"x":160,"y":77,"z":192},"requirements":{"minecraft:polished_diorite":4,"minecraft:stone_bricks":4},"sha256":"2a1b58852cb13e7aed21cd4ea0092b83334b415193ff0d4454809909205234a8","size":{"x":32,"y":1,"z":32}},{"blockCount":21,"bytes":868,"file":"chunks/y078-z000-x352.json","offset":{"x":352,"y":78,"z":0},"requirements":{"minecraft:polished_diorite":20,"minecraft:stone_bricks":1},"sha256":"998b9d468a5ec3be73006da4cdf61f95978dc1b3f13ecb8e1a9e32f12300015a","size":{"x":32,"y":1,"z":32}},{"blockCount":1,"bytes":642,"file":"chunks/y078-z000-x384.json","offset":{"x":384,"y":78,"z":0},"requirements":{"minecraft:stone_bricks":1},"sha256":"316dc0d8a6d315a895a93f38251f2a2ebd1f1fc6d14bdeead9846d98070423e6","size":{"x":32,"y":1,"z":32}},{"blockCount":122,"bytes":2807,"file":"chunks/y078-z064-x064.json","offset":{"x":64,"y":78,"z":64},"requirements":{"minecraft:cobbled_deepslate":31,"minecraft:polished_diorite":76,"minecraft:stone_bricks":15},"sha256":"f930547f451b1cfc4aedf22cc5137220389b17d1054923dd2a0fa7d449c8f3b3","size":{"x":32,"y":1,"z":32}},{"blockCount":244,"bytes":4903,"file":"chunks/y078-z064-x096.json","offset":{"x":96,"y":78,"z":64},"requirements":{"minecraft:bricks":46,"minecraft:cobbled_deepslate":13,"minecraft:glass":12,"minecraft:polished_diorite":105,"minecraft:sandstone":21,"minecraft:stone_bricks":47},"sha256":"077516fb19883b35eeda3f5e9c079919dc914dc3210eac6b1f02ec8b51f5ccfc","size":{"x":32,"y":1,"z":32}},{"blockCount":280,"bytes":5532,"file":"chunks/y078-z064-x128.json","offset":{"x":128,"y":78,"z":64},"requirements":{"minecraft:bricks":34,"minecraft:cobbled_deepslate":46,"minecraft:glass":6,"minecraft:polished_diorite":150,"minecraft:sandstone":8,"minecraft:stone_bricks":36},"sha256":"bf57bc8794b1c47a11886a7a3cb158fb081f460d8c6e15d6883f76f1f57f05aa","size":{"x":32,"y":1,"z":32}},{"blockCount":9,"bytes":946,"file":"chunks/y078-z064-x160.json","offset":{"x":160,"y":78,"z":64},"requirements":{"minecraft:polished_diorite":7,"minecraft:stone_bricks":2},"sha256":"8752ce2c73ceb97d7eb49b41258a04a7b452252d9c2783fcd4a3b516a39fd673","size":{"x":32,"y":1,"z":32}},{"blockCount":19,"bytes":1132,"file":"chunks/y078-z064-x192.json","offset":{"x":192,"y":78,"z":64},"requirements":{"minecraft:polished_diorite":10,"minecraft:stone_bricks":9},"sha256":"e68c2f995cd01db09fe391e88fff8672659fd80ad87a65309d06260be4820a00","size":{"x":32,"y":1,"z":32}},{"blockCount":23,"bytes":1211,"file":"chunks/y078-z064-x224.json","offset":{"x":224,"y":78,"z":64},"requirements":{"minecraft:polished_diorite":13,"minecraft:stone_bricks":10},"sha256":"9250b49a888c035a94fe3270a2196103589fe10587b4359d5e61e9632a85e176","size":{"x":32,"y":1,"z":32}},{"blockCount":67,"bytes":2282,"file":"chunks/y078-z096-x000.json","offset":{"x":0,"y":78,"z":96},"requirements":{"minecraft:cobbled_deepslate":30,"minecraft:polished_diorite":29,"minecraft:stone_bricks":8},"sha256":"147862b55ad6501f29c903e375bc8c0e63cea16345d5bd2a9f4b1b570f91a734","size":{"x":32,"y":1,"z":32}},{"blockCount":243,"bytes":6412,"file":"chunks/y078-z096-x032.json","offset":{"x":32,"y":78,"z":96},"requirements":{"minecraft:bricks":30,"minecraft:cobbled_deepslate":64,"minecraft:polished_diorite":91,"minecraft:sandstone":13,"minecraft:stone_bricks":45},"sha256":"13ac8387c81d996cfaa6a5062322607f61c866709bf201c64afdb1113e5a513b","size":{"x":32,"y":1,"z":32}},{"blockCount":286,"bytes":6248,"file":"chunks/y078-z096-x064.json","offset":{"x":64,"y":78,"z":96},"requirements":{"minecraft:bricks":64,"minecraft:cobbled_deepslate":67,"minecraft:polished_diorite":82,"minecraft:sandstone":12,"minecraft:stone_bricks":61},"sha256":"7c4017eb0565d20542b98ca825a30a156cdf11f387a7581eaf31790a4e2dee87","size":{"x":32,"y":1,"z":32}},{"blockCount":119,"bytes":3059,"file":"chunks/y078-z096-x096.json","offset":{"x":96,"y":78,"z":96},"requirements":{"minecraft:bricks":24,"minecraft:cobbled_deepslate":8,"minecraft:polished_diorite":28,"minecraft:sandstone":17,"minecraft:stone_bricks":42},"sha256":"295053f9072631d8ae6ee1fdf4ce56ad056b77ab6116722b38513563f559559e","size":{"x":32,"y":1,"z":32}},{"blockCount":261,"bytes":5411,"file":"chunks/y078-z096-x128.json","offset":{"x":128,"y":78,"z":96},"requirements":{"minecraft:bricks":51,"minecraft:cobbled_deepslate":53,"minecraft:polished_diorite":90,"minecraft:sandstone":16,"minecraft:stone_bricks":51},"sha256":"091f869e9e61b275932c114e5478c3ae477884b28767e7f29329bfe6d61dbcaf","size":{"x":32,"y":1,"z":32}},{"blockCount":258,"bytes":6172,"file":"chunks/y078-z096-x160.json","offset":{"x":160,"y":78,"z":96},"requirements":{"minecraft:bricks":49,"minecraft:cobbled_deepslate":44,"minecraft:polished_diorite":100,"minecraft:sandstone":9,"minecraft:stone_bricks":56},"sha256":"248d070ef77c8fa0b48fa13172b07621fe79e156887417a9f3d03c8f0bf7acc3","size":{"x":32,"y":1,"z":32}},{"blockCount":431,"bytes":6287,"file":"chunks/y078-z096-x192.json","offset":{"x":192,"y":78,"z":96},"requirements":{"minecraft:bricks":120,"minecraft:cobbled_deepslate":23,"minecraft:polished_diorite":73,"minecraft:sandstone":22,"minecraft:spruce_planks":122,"minecraft:stone_bricks":71},"sha256":"551f845432c8c322bbffa576dc969847e8f0c3e80df70ef085a64267623c1f04","size":{"x":32,"y":1,"z":32}},{"blockCount":420,"bytes":3901,"file":"chunks/y078-z096-x224.json","offset":{"x":224,"y":78,"z":96},"requirements":{"minecraft:bricks":59,"minecraft:glass":6,"minecraft:polished_diorite":40,"minecraft:sandstone":1,"minecraft:spruce_planks":288,"minecraft:stone_bricks":26},"sha256":"3170c2fcb2e63ddd108ca6ec1c13cd6134ab553a4087b138acbb075c4516b1c6","size":{"x":32,"y":1,"z":32}},{"blockCount":134,"bytes":3549,"file":"chunks/y078-z128-x000.json","offset":{"x":0,"y":78,"z":128},"requirements":{"minecraft:bricks":17,"minecraft:cobbled_deepslate":50,"minecraft:polished_diorite":47,"minecraft:stone_bricks":20},"sha256":"2e742cd65a95bac852ec237b7585b915ed8ab7205a2a4e7838bb13d5a17ca77f","size":{"x":32,"y":1,"z":32}},{"blockCount":185,"bytes":4084,"file":"chunks/y078-z128-x032.json","offset":{"x":32,"y":78,"z":128},"requirements":{"minecraft:bricks":9,"minecraft:cobbled_deepslate":13,"minecraft:oak_planks":1,"minecraft:polished_diorite":64,"minecraft:sandstone":18,"minecraft:spruce_planks":1,"minecraft:stone_bricks":79},"sha256":"f98e83648de36e791193871a586befa573df2a7a7f87f3f1098c16f938fbf929","size":{"x":32,"y":1,"z":32}},{"blockCount":52,"bytes":1218,"file":"chunks/y078-z128-x064.json","offset":{"x":64,"y":78,"z":128},"requirements":{"minecraft:bricks":15,"minecraft:cobbled_deepslate":5,"minecraft:sandstone":19,"minecraft:stone_bricks":13},"sha256":"d0c2e3ebab5b055079d746cfb8fc4347a879253fc8a6bac250231b38ffd48484","size":{"x":32,"y":1,"z":32}},{"blockCount":13,"bytes":879,"file":"chunks/y078-z128-x096.json","offset":{"x":96,"y":78,"z":128},"requirements":{"minecraft:bricks":5,"minecraft:sandstone":5,"minecraft:stone_bricks":3},"sha256":"18702dfd0ddf95370e4dcd5baeef7c4fa93f8765b23e5461e3639a3f89146b78","size":{"x":32,"y":1,"z":32}},{"blockCount":36,"bytes":1146,"file":"chunks/y078-z128-x128.json","offset":{"x":128,"y":78,"z":128},"requirements":{"minecraft:sandstone":10,"minecraft:stone_bricks":26},"sha256":"e4b80b92bffa6bc47fb4b372091c3d69917626b72aa860760c221964d8e6ce67","size":{"x":32,"y":1,"z":32}},{"blockCount":47,"bytes":1283,"file":"chunks/y078-z128-x160.json","offset":{"x":160,"y":78,"z":128},"requirements":{"minecraft:bricks":13,"minecraft:sandstone":20,"minecraft:stone_bricks":14},"sha256":"b700144dc662ec507ed3dd1b5431bbd96b23096b729c7bbd3d6214df35c95c0d","size":{"x":32,"y":1,"z":32}},{"blockCount":71,"bytes":2079,"file":"chunks/y078-z128-x192.json","offset":{"x":192,"y":78,"z":128},"requirements":{"minecraft:bricks":21,"minecraft:sandstone":22,"minecraft:stone_bricks":28},"sha256":"4a86e2482cf5888baece254e2168db790a78cb2f865c9e8466081022a283d088","size":{"x":32,"y":1,"z":32}},{"blockCount":134,"bytes":3546,"file":"chunks/y078-z128-x224.json","offset":{"x":224,"y":78,"z":128},"requirements":{"minecraft:bricks":39,"minecraft:glass":15,"minecraft:polished_diorite":50,"minecraft:sandstone":7,"minecraft:stone_bricks":23},"sha256":"0c15e4953f40a16cf0861aa761030a3449ba8a1b7930c6ee941d3aeef057fedb","size":{"x":32,"y":1,"z":32}},{"blockCount":36,"bytes":1630,"file":"chunks/y078-z160-x000.json","offset":{"x":0,"y":78,"z":160},"requirements":{"minecraft:cobbled_deepslate":11,"minecraft:polished_diorite":19,"minecraft:stone_bricks":6},"sha256":"dc8e4a215bf8ff1d7a505d3f22e6db69575cead34dd1acb98533b09e417aa262","size":{"x":32,"y":1,"z":32}},{"blockCount":182,"bytes":5243,"file":"chunks/y078-z160-x032.json","offset":{"x":32,"y":78,"z":160},"requirements":{"minecraft:bricks":19,"minecraft:cobbled_deepslate":53,"minecraft:polished_diorite":83,"minecraft:stone_bricks":27},"sha256":"e211c3f378565fd9b813160dc3c09617d780fcfd3c9f2adcfacb17ae749072f2","size":{"x":32,"y":1,"z":32}},{"blockCount":260,"bytes":5882,"file":"chunks/y078-z160-x064.json","offset":{"x":64,"y":78,"z":160},"requirements":{"minecraft:bricks":41,"minecraft:cobbled_deepslate":70,"minecraft:polished_diorite":120,"minecraft:stone_bricks":29},"sha256":"2ce03869344f1df5005f3d5887463126e02936b996f59511b6fa07d15334e92b","size":{"x":32,"y":1,"z":32}},{"blockCount":133,"bytes":3329,"file":"chunks/y078-z160-x096.json","offset":{"x":96,"y":78,"z":160},"requirements":{"minecraft:bricks":27,"minecraft:cobbled_deepslate":14,"minecraft:polished_diorite":53,"minecraft:sandstone":8,"minecraft:stone_bricks":31},"sha256":"605dbfb1d0175d9914deb9b1fed0651bbf7b2c14e6c8f45f94f026706815e39e","size":{"x":32,"y":1,"z":32}},{"blockCount":279,"bytes":5858,"file":"chunks/y078-z160-x128.json","offset":{"x":128,"y":78,"z":160},"requirements":{"minecraft:bricks":33,"minecraft:cobbled_deepslate":62,"minecraft:polished_diorite":119,"minecraft:sandstone":19,"minecraft:stone_bricks":46},"sha256":"c4ddfcd7ff04c0c13098c7d4fe0d7a6269a90c61cf4613ff6510b6e77f13ca6f","size":{"x":32,"y":1,"z":32}},{"blockCount":213,"bytes":5539,"file":"chunks/y078-z160-x160.json","offset":{"x":160,"y":78,"z":160},"requirements":{"minecraft:bricks":44,"minecraft:cobbled_deepslate":46,"minecraft:polished_diorite":101,"minecraft:stone_bricks":22},"sha256":"4e13f06a486c06de7b24c392495b4e1de7de5ae2429058097f5e8bc5908e7685","size":{"x":32,"y":1,"z":32}},{"blockCount":395,"bytes":6110,"file":"chunks/y078-z160-x192.json","offset":{"x":192,"y":78,"z":160},"requirements":{"minecraft:bricks":111,"minecraft:cobbled_deepslate":23,"minecraft:polished_diorite":82,"minecraft:spruce_planks":122,"minecraft:stone_bricks":57},"sha256":"42ad5d0933708a83ee266cad690bc426ba04d0567b7b7a6fc938abcae7592cd9","size":{"x":32,"y":1,"z":32}},{"blockCount":408,"bytes":3725,"file":"chunks/y078-z160-x224.json","offset":{"x":224,"y":78,"z":160},"requirements":{"minecraft:bricks":53,"minecraft:glass":3,"minecraft:polished_diorite":35,"minecraft:spruce_planks":288,"minecraft:stone_bricks":29},"sha256":"7b4d826cc6bd18f21184f70b57be7e06994651698077def8d139ceae8a51204c","size":{"x":32,"y":1,"z":32}},{"blockCount":97,"bytes":2442,"file":"chunks/y078-z192-x064.json","offset":{"x":64,"y":78,"z":192},"requirements":{"minecraft:cobbled_deepslate":21,"minecraft:polished_diorite":61,"minecraft:stone_bricks":15},"sha256":"e6ce1c1f33e3a36635e1aa50c5d83210570357c9a0219bc86b31a1a36a28d723","size":{"x":32,"y":1,"z":32}},{"blockCount":211,"bytes":4250,"file":"chunks/y078-z192-x096.json","offset":{"x":96,"y":78,"z":192},"requirements":{"minecraft:bricks":48,"minecraft:cobbled_deepslate":10,"minecraft:glass":12,"minecraft:polished_diorite":90,"minecraft:sandstone":9,"minecraft:stone_bricks":42},"sha256":"4b5104a01c8172397079b7e73ff169c8feb4bfb9eea41d774e8a23434e40b681","size":{"x":32,"y":1,"z":32}},{"blockCount":226,"bytes":4592,"file":"chunks/y078-z192-x128.json","offset":{"x":128,"y":78,"z":192},"requirements":{"minecraft:bricks":23,"minecraft:cobbled_deepslate":34,"minecraft:glass":6,"minecraft:polished_diorite":121,"minecraft:sandstone":7,"minecraft:stone_bricks":35},"sha256":"e138299637c4c6a74f34bd009946e9829269c7f32fde9103357fb61f699c48ed","size":{"x":32,"y":1,"z":32}},{"blockCount":8,"bytes":909,"file":"chunks/y078-z192-x160.json","offset":{"x":160,"y":78,"z":192},"requirements":{"minecraft:polished_diorite":6,"minecraft:stone_bricks":2},"sha256":"2abd952da38f6c98d82ca34d41b70598133316a33d5d0e59a56d074db94814c4","size":{"x":32,"y":1,"z":32}},{"blockCount":28,"bytes":1060,"file":"chunks/y079-z000-x352.json","offset":{"x":352,"y":79,"z":0},"requirements":{"minecraft:polished_diorite":8,"minecraft:stone_bricks":20},"sha256":"20bce274ed5c99f6582fe70fa6b85dff221117d7be33adea060684c855eeafa6","size":{"x":32,"y":1,"z":32}},{"blockCount":1,"bytes":642,"file":"chunks/y079-z000-x384.json","offset":{"x":384,"y":79,"z":0},"requirements":{"minecraft:stone_bricks":1},"sha256":"1a5ab019609fe39db4093124a0fa7276a7641aae6f0314025f7d01dcf3f3d363","size":{"x":32,"y":1,"z":32}},{"blockCount":99,"bytes":2193,"file":"chunks/y079-z064-x064.json","offset":{"x":64,"y":79,"z":64},"requirements":{"minecraft:cobbled_deepslate":27,"minecraft:polished_diorite":60,"minecraft:stone_bricks":12},"sha256":"a675103eec6df037fe5ed10fcfc2d860e251b29369239e41b731fc1ee446a7d3","size":{"x":32,"y":1,"z":32}},{"blockCount":302,"bytes":4581,"file":"chunks/y079-z064-x096.json","offset":{"x":96,"y":79,"z":64},"requirements":{"minecraft:bricks":75,"minecraft:cobbled_deepslate":16,"minecraft:polished_diorite":105,"minecraft:sandstone":28,"minecraft:stone_bricks":78},"sha256":"5150445f973257e141dfb7010fd5e9a746e5f41a74308f1061f8bff69f6b3a2c","size":{"x":32,"y":1,"z":32}},{"blockCount":287,"bytes":4882,"file":"chunks/y079-z064-x128.json","offset":{"x":128,"y":79,"z":64},"requirements":{"minecraft:bricks":47,"minecraft:cobbled_deepslate":42,"minecraft:polished_diorite":134,"minecraft:sandstone":11,"minecraft:stone_bricks":53},"sha256":"1c794812d26a127f913e59706ba28fde60391e23f7d56a5afb344acc739576ca","size":{"x":32,"y":1,"z":32}},{"blockCount":7,"bytes":881,"file":"chunks/y079-z064-x160.json","offset":{"x":160,"y":79,"z":64},"requirements":{"minecraft:polished_diorite":7},"sha256":"6724356bdad0df3c99c812502803f7328c74a880a18cb4122db962bbf8428484","size":{"x":32,"y":1,"z":32}},{"blockCount":21,"bytes":979,"file":"chunks/y079-z064-x192.json","offset":{"x":192,"y":79,"z":64},"requirements":{"minecraft:polished_diorite":17,"minecraft:stone_bricks":4},"sha256":"96eb8e1e08f7b33ff4b785adc1e2fff590ff92460e33f8e03e8dabacab744a31","size":{"x":32,"y":1,"z":32}},{"blockCount":24,"bytes":1018,"file":"chunks/y079-z064-x224.json","offset":{"x":224,"y":79,"z":64},"requirements":{"minecraft:polished_diorite":20,"minecraft:stone_bricks":4},"sha256":"7fe216fab744be873900f1a23698af3a937337f4f2cb805da2494c7a0b8e383c","size":{"x":32,"y":1,"z":32}},{"blockCount":54,"bytes":1977,"file":"chunks/y079-z096-x000.json","offset":{"x":0,"y":79,"z":96},"requirements":{"minecraft:cobbled_deepslate":24,"minecraft:polished_diorite":29,"minecraft:stone_bricks":1},"sha256":"86bc95ddf85b6154b3e4076ee70e068c043a82276688e85c0393e4b7152098be","size":{"x":32,"y":1,"z":32}},{"blockCount":225,"bytes":5241,"file":"chunks/y079-z096-x032.json","offset":{"x":32,"y":79,"z":96},"requirements":{"minecraft:bricks":11,"minecraft:cobbled_deepslate":60,"minecraft:polished_diorite":100,"minecraft:sandstone":17,"minecraft:stone_bricks":37},"sha256":"d1cfa54992466eaff310cadca5bd39306f89721ed8c394be5c2d6e74b51ba3f9","size":{"x":32,"y":1,"z":32}},{"blockCount":246,"bytes":4541,"file":"chunks/y079-z096-x064.json","offset":{"x":64,"y":79,"z":96},"requirements":{"minecraft:cobbled_deepslate":66,"minecraft:polished_diorite":117,"minecraft:sandstone":12,"minecraft:stone_bricks":51},"sha256":"357ab69ebe1a6009ada8e9580695032b3ab54961e66d531019b8db52f2d789cb","size":{"x":32,"y":1,"z":32}},{"blockCount":125,"bytes":3018,"file":"chunks/y079-z096-x096.json","offset":{"x":96,"y":79,"z":96},"requirements":{"minecraft:cobbled_deepslate":8,"minecraft:polished_diorite":51,"minecraft:sandstone":17,"minecraft:stone_bricks":49},"sha256":"dd759d6beca7a8cacd4b877369fcc1cfcd587ed69ad26c53486d6c9e4bad0b4a","size":{"x":32,"y":1,"z":32}},{"blockCount":242,"bytes":4613,"file":"chunks/y079-z096-x128.json","offset":{"x":128,"y":79,"z":96},"requirements":{"minecraft:bricks":20,"minecraft:cobbled_deepslate":49,"minecraft:polished_diorite":101,"minecraft:sandstone":16,"minecraft:stone_bricks":56},"sha256":"c5a20639ac50abc9f41e6b80b0efce88b2baef4fc92857a4834deb51342bd535","size":{"x":32,"y":1,"z":32}},{"blockCount":230,"bytes":4710,"file":"chunks/y079-z096-x160.json","offset":{"x":160,"y":79,"z":96},"requirements":{"minecraft:bricks":5,"minecraft:cobbled_deepslate":42,"minecraft:polished_diorite":124,"minecraft:sandstone":9,"minecraft:stone_bricks":50},"sha256":"9d36b0bcd6bd7e69225f2ab7bcfe7ad3162419b29837d370203f8af67e4663e4","size":{"x":32,"y":1,"z":32}},{"blockCount":297,"bytes":5370,"file":"chunks/y079-z096-x192.json","offset":{"x":192,"y":79,"z":96},"requirements":{"minecraft:bricks":104,"minecraft:cobbled_deepslate":22,"minecraft:polished_diorite":101,"minecraft:sandstone":22,"minecraft:stone_bricks":48},"sha256":"842dcaf9bdfb9246bafa596bdb460ef72b47776469ab950e1d0eb3ed6ae51ba8","size":{"x":32,"y":1,"z":32}},{"blockCount":188,"bytes":3836,"file":"chunks/y079-z096-x224.json","offset":{"x":224,"y":79,"z":96},"requirements":{"minecraft:bricks":92,"minecraft:polished_diorite":54,"minecraft:sandstone":2,"minecraft:stone_bricks":40},"sha256":"0bb4d42141c69c4421c7bd2245e1881c1f42cedc6b0bdc9e99e8e5bd490e8dab","size":{"x":32,"y":1,"z":32}},{"blockCount":107,"bytes":2879,"file":"chunks/y079-z128-x000.json","offset":{"x":0,"y":79,"z":128},"requirements":{"minecraft:bricks":13,"minecraft:cobbled_deepslate":47,"minecraft:polished_diorite":38,"minecraft:stone_bricks":9},"sha256":"897ae8793ea1cfccd081f2f43c73a80c3ec9e6ccf4b69adc82dbdfb1093842b4","size":{"x":32,"y":1,"z":32}},{"blockCount":201,"bytes":3809,"file":"chunks/y079-z128-x032.json","offset":{"x":32,"y":79,"z":128},"requirements":{"minecraft:bricks":7,"minecraft:cobbled_deepslate":15,"minecraft:oak_planks":4,"minecraft:polished_diorite":61,"minecraft:sandstone":17,"minecraft:stone_bricks":97},"sha256":"c297461676574f3ce679c668627d2c6278726b07700f8f1fc740b42ad97e3c1f","size":{"x":32,"y":1,"z":32}},{"blockCount":57,"bytes":1028,"file":"chunks/y079-z128-x064.json","offset":{"x":64,"y":79,"z":128},"requirements":{"minecraft:bricks":15,"minecraft:cobbled_deepslate":6,"minecraft:sandstone":19,"minecraft:stone_bricks":17},"sha256":"13409f1ce217eb081716d6b1ea77b8568c64ba09e1b5444d61c7e83d34282e01","size":{"x":32,"y":1,"z":32}},{"blockCount":14,"bytes":841,"file":"chunks/y079-z128-x096.json","offset":{"x":96,"y":79,"z":128},"requirements":{"minecraft:bricks":5,"minecraft:sandstone":5,"minecraft:stone_bricks":4},"sha256":"da7a66871b460acbed8d0143f1cb51d5f4639fc25f4a36cac99ec3c3eed78cd1","size":{"x":32,"y":1,"z":32}},{"blockCount":40,"bytes":994,"file":"chunks/y079-z128-x128.json","offset":{"x":128,"y":79,"z":128},"requirements":{"minecraft:sandstone":10,"minecraft:stone_bricks":30},"sha256":"f8c40725e0b050395d5283bdad3c3724d0626a098ac903caf1c1378b181cc3e8","size":{"x":32,"y":1,"z":32}},{"blockCount":51,"bytes":1131,"file":"chunks/y079-z128-x160.json","offset":{"x":160,"y":79,"z":128},"requirements":{"minecraft:bricks":13,"minecraft:sandstone":20,"minecraft:stone_bricks":18},"sha256":"282e71a734abd97295dda190d01e795b5a14cbd988041bff802686b6fc53d812","size":{"x":32,"y":1,"z":32}},{"blockCount":78,"bytes":1987,"file":"chunks/y079-z128-x192.json","offset":{"x":192,"y":79,"z":128},"requirements":{"minecraft:bricks":14,"minecraft:sandstone":22,"minecraft:stone_bricks":42},"sha256":"61ea3eb66de1a8a3af9d4301a7aeab76db35bddfed22b00c9c0199fcd855da8b","size":{"x":32,"y":1,"z":32}},{"blockCount":224,"bytes":4267,"file":"chunks/y079-z128-x224.json","offset":{"x":224,"y":79,"z":128},"requirements":{"minecraft:bricks":64,"minecraft:polished_diorite":59,"minecraft:sandstone":10,"minecraft:stone_bricks":91},"sha256":"03623aa9bdc0dd533ed237b2dcec920eea2d49fff5a71c4d9cca4f389ee6f59e","size":{"x":32,"y":1,"z":32}},{"blockCount":29,"bytes":1495,"file":"chunks/y079-z160-x000.json","offset":{"x":0,"y":79,"z":160},"requirements":{"minecraft:cobbled_deepslate":9,"minecraft:polished_diorite":19,"minecraft:stone_bricks":1},"sha256":"2f8479fde76ef3ad9433ef877bed4b5d11c04747769d8e4e74215a09e5fd91ee","size":{"x":32,"y":1,"z":32}},{"blockCount":154,"bytes":4107,"file":"chunks/y079-z160-x032.json","offset":{"x":32,"y":79,"z":160},"requirements":{"minecraft:cobbled_deepslate":49,"minecraft:polished_diorite":92,"minecraft:stone_bricks":13},"sha256":"deb87d6f250c1e78c4cf52f572c5c7db951fe56a62ea557c4871c5ff27ac39bf","size":{"x":32,"y":1,"z":32}},{"blockCount":210,"bytes":4325,"file":"chunks/y079-z160-x064.json","offset":{"x":64,"y":79,"z":160},"requirements":{"minecraft:cobbled_deepslate":65,"minecraft:polished_diorite":130,"minecraft:stone_bricks":15},"sha256":"50df581adf7d64eeeb12b5059f1a906ebd61a09c7c013c0e348c187b787c862e","size":{"x":32,"y":1,"z":32}},{"blockCount":142,"bytes":3538,"file":"chunks/y079-z160-x096.json","offset":{"x":96,"y":79,"z":160},"requirements":{"minecraft:bricks":13,"minecraft:cobbled_deepslate":12,"minecraft:polished_diorite":68,"minecraft:sandstone":8,"minecraft:stone_bricks":41},"sha256":"bec90dd457a5dbdc162bdb92b84c6a5cf77d092047f9afd06a9510530bc7018c","size":{"x":32,"y":1,"z":32}},{"blockCount":256,"bytes":5114,"file":"chunks/y079-z160-x128.json","offset":{"x":128,"y":79,"z":160},"requirements":{"minecraft:bricks":2,"minecraft:cobbled_deepslate":59,"minecraft:polished_diorite":130,"minecraft:sandstone":19,"minecraft:stone_bricks":46},"sha256":"657db18b2bd4c150048839f7ce4e6722da96fe10a0a8f5b960c780031cd44eb5","size":{"x":32,"y":1,"z":32}},{"blockCount":180,"bytes":4190,"file":"chunks/y079-z160-x160.json","offset":{"x":160,"y":79,"z":160},"requirements":{"minecraft:cobbled_deepslate":42,"minecraft:polished_diorite":125,"minecraft:stone_bricks":13},"sha256":"3fe6e49b34687f2f1fdae870121dac568a74a04dcf79c702c98e36be0b3fe3f7","size":{"x":32,"y":1,"z":32}}],"schema":1}
