{"entries":[{"blockCount":258,"bytes":5074,"file":"chunks/y079-z160-x192.json","offset":{"x":192,"y":79,"z":160},"requirements":{"minecraft:bricks":95,"minecraft:cobbled_deepslate":20,"minecraft:polished_diorite":118,"minecraft:stone_bricks":25},"sha256":"339deed60e40437422204e7913de64132ce64dc33c864e74c87542dd3859c1de","size":{"x":32,"y":1,"z":32}},{"blockCount":148,"bytes":3278,"file":"chunks/y079-z160-x224.json","offset":{"x":224,"y":79,"z":160},"requirements":{"minecraft:bricks":81,"minecraft:polished_diorite":55,"minecraft:stone_bricks":12},"sha256":"5d154f2389b50012adb2b1d482057d068b5b6d9a849631c4e23cc98e5ff73638","size":{"x":32,"y":1,"z":32}},{"blockCount":78,"bytes":1790,"file":"chunks/y079-z192-x064.json","offset":{"x":64,"y":79,"z":192},"requirements":{"minecraft:cobbled_deepslate":22,"minecraft:polished_diorite":47,"minecraft:stone_bricks":9},"sha256":"f6eb107b858a57ef5850fc4ae059f919b4931d1cbb85a848f6d54ae9049b16a7","size":{"x":32,"y":1,"z":32}},{"blockCount":265,"bytes":3871,"file":"chunks/y079-z192-x096.json","offset":{"x":96,"y":79,"z":192},"requirements":{"minecraft:bricks":77,"minecraft:cobbled_deepslate":12,"minecraft:polished_diorite":88,"minecraft:sandstone":16,"minecraft:stone_bricks":72},"sha256":"3211f5b6b6e71440c217304053689c8d754a99c3cd0343b6149c8ec452277847","size":{"x":32,"y":1,"z":32}},{"blockCount":233,"bytes":3963,"file":"chunks/y079-z192-x128.json","offset":{"x":128,"y":79,"z":192},"requirements":{"minecraft:bricks":36,"minecraft:cobbled_deepslate":34,"minecraft:polished_diorite":105,"minecraft:sandstone":10,"minecraft:stone_bricks":48},"sha256":"06e83fb589b0daaec17c267808b79d11e814d655bfc0e23056e7357440d9fb7b","size":{"x":32,"y":1,"z":32}},{"blockCount":6,"bytes":844,"file":"chunks/y079-z192-x160.json","offset":{"x":160,"y":79,"z":192},"requirements":{"minecraft:polished_diorite":6},"sha256":"668537da76bde51a07c685e76b2188be192cbec8a7c0e29398128313d1d58d0d","size":{"x":32,"y":1,"z":32}},{"blockCount":20,"bytes":837,"file":"chunks/y080-z000-x352.json","offset":{"x":352,"y":80,"z":0},"requirements":{"minecraft:stone_bricks":20},"sha256":"4bcf961be76859cde60f7ac177a5da364133832b1ae556fb5982b139fbd68805","size":{"x":32,"y":1,"z":32}},{"blockCount":1,"bytes":635,"file":"chunks/y080-z000-x384.json","offset":{"x":384,"y":80,"z":0},"requirements":{"minecraft:glass":1},"sha256":"8eaff63b46e6af1ad74b3acdbc65196b7995df84acced27ca8c40eba8e3a3d64","size":{"x":32,"y":1,"z":32}},{"blockCount":76,"bytes":2070,"file":"chunks/y080-z064-x064.json","offset":{"x":64,"y":80,"z":64},"requirements":{"minecraft:cobbled_deepslate":26,"minecraft:glass":9,"minecraft:polished_diorite":41},"sha256":"b1d35708577d71ee689cea0bf82f9f792641162953dd72e0e93455e0cb057951","size":{"x":32,"y":1,"z":32}},{"blockCount":280,"bytes":4563,"file":"chunks/y080-z064-x096.json","offset":{"x":96,"y":80,"z":64},"requirements":{"minecraft:bricks":47,"minecraft:cobbled_deepslate":16,"minecraft:glass":32,"minecraft:polished_diorite":85,"minecraft:sandstone":25,"minecraft:stone_bricks":75},"sha256":"4b83bd8626c5db1e55d763d5463a4266c87a3786ab7521fe16da04dbd14d794c","size":{"x":32,"y":1,"z":32}},{"blockCount":248,"bytes":4880,"file":"chunks/y080-z064-x128.json","offset":{"x":128,"y":80,"z":64},"requirements":{"minecraft:bricks":39,"minecraft:cobbled_deepslate":42,"minecraft:glass":23,"minecraft:polished_diorite":100,"minecraft:sandstone":9,"minecraft:stone_bricks":35},"sha256":"6219d1d323c0aeed23e6b5996446b8a852676c048fa8af9509e76d698e022585","size":{"x":32,"y":1,"z":32}},{"blockCount":7,"bytes":881,"file":"chunks/y080-z064-x160.json","offset":{"x":160,"y":80,"z":64},"requirements":{"minecraft:polished_diorite":7},"sha256":"09138112a5cb9a91cd51877ba3b4d49d00663ed9179e015cf1259cf978778316","size":{"x":32,"y":1,"z":32}},{"blockCount":16,"bytes":895,"file":"chunks/y080-z064-x192.json","offset":{"x":192,"y":80,"z":64},"requirements":{"minecraft:glass":7,"minecraft:polished_diorite":9},"sha256":"03fb8b845808e4b910dd2ecf2a4c15779efb29b7df31f25d19232ec88c5e8f39","size":{"x":32,"y":1,"z":32}},{"blockCount":19,"bytes":935,"file":"chunks/y080-z064-x224.json","offset":{"x":224,"y":80,"z":64},"requirements":{"minecraft:glass":7,"minecraft:polished_diorite":12},"sha256":"61f095c6cee8d9789017a63f4f401d682125afa9aefac796686fdeacc1f47c66","size":{"x":32,"y":1,"z":32}},{"blockCount":57,"bytes":1949,"file":"chunks/y080-z096-x000.json","offset":{"x":0,"y":80,"z":96},"requirements":{"minecraft:cobbled_deepslate":28,"minecraft:polished_diorite":29},"sha256":"af5410bb6aeb673b5670b7782cb6f9cfb08d6b223029376d6a56676da8c95696","size":{"x":32,"y":1,"z":32}},{"blockCount":198,"bytes":5374,"file":"chunks/y080-z096-x032.json","offset":{"x":32,"y":80,"z":96},"requirements":{"minecraft:bricks":11,"minecraft:cobbled_deepslate":60,"minecraft:polished_diorite":89,"minecraft:sandstone":16,"minecraft:stone_bricks":22},"sha256":"9c0df01b776d286df6e4463a18baf5aaddad2f8ae8fbe9e27e5f0624982b3098","size":{"x":32,"y":1,"z":32}},{"blockCount":208,"bytes":4770,"file":"chunks/y080-z096-x064.json","offset":{"x":64,"y":80,"z":96},"requirements":{"minecraft:cobbled_deepslate":64,"minecraft:polished_diorite":90,"minecraft:sandstone":12,"minecraft:stone_bricks":42},"sha256":"d6c06f6059b053dc0e37680e9e919297015e20d86e4aecf5405fdbd5003a59e9","size":{"x":32,"y":1,"z":32}},{"blockCount":114,"bytes":3019,"file":"chunks/y080-z096-x096.json","offset":{"x":96,"y":80,"z":96},"requirements":{"minecraft:cobbled_deepslate":10,"minecraft:polished_diorite":45,"minecraft:sandstone":17,"minecraft:stone_bricks":42},"sha256":"a13ac02b2d36cfebf4027481bb46d2d7265905245f4e4d5868ea95c07117e503","size":{"x":32,"y":1,"z":32}},{"blockCount":208,"bytes":4745,"file":"chunks/y080-z096-x128.json","offset":{"x":128,"y":80,"z":96},"requirements":{"minecraft:bricks":20,"minecraft:cobbled_deepslate":47,"minecraft:polished_diorite":79,"minecraft:sandstone":16,"minecraft:stone_bricks":46},"sha256":"25a9ba35c7d3797052a2075203d476515b4d77afad5596e9d0ecea557c1a2e61","size":{"x":32,"y":1,"z":32}},{"blockCount":200,"bytes":5014,"file":"chunks/y080-z096-x160.json","offset":{"x":160,"y":80,"z":96},"requirements":{"minecraft:bricks":5,"minecraft:cobbled_deepslate":42,"minecraft:polished_diorite":102,"minecraft:sandstone":9,"minecraft:stone_bricks":42},"sha256":"29b5f4937e1ad3156fe18816eadd901efaffd4289d7ac1e77b0569b0ff36fa7a","size":{"x":32,"y":1,"z":32}},{"blockCount":256,"bytes":5882,"file":"chunks/y080-z096-x192.json","offset":{"x":192,"y":80,"z":96},"requirements":{"minecraft:bricks":75,"minecraft:cobbled_deepslate":21,"minecraft:glass":26,"minecraft:polished_diorite":77,"minecraft:sandstone":22,"minecraft:stone_bricks":35},"sha256":"2fec80c2afdf169cc94eb5e4cead6ab25fe5ae89482e8abdf47fd56ab568ee38","size":{"x":32,"y":1,"z":32}},{"blockCount":162,"bytes":4122,"file":"chunks/y080-z096-x224.json","offset":{"x":224,"y":80,"z":96},"requirements":{"minecraft:bricks":62,"minecraft:glass":39,"minecraft:polished_diorite":40,"minecraft:sandstone":2,"minecraft:stone_bricks":19},"sha256":"4e508c1534513ffda79b6b1d331dc8d21728936ee23d9c7a1a95a92808809ade","size":{"x":32,"y":1,"z":32}},{"blockCount":98,"bytes":2731,"file":"chunks/y080-z128-x000.json","offset":{"x":0,"y":80,"z":128},"requirements":{"minecraft:bricks":6,"minecraft:cobbled_deepslate":49,"minecraft:polished_diorite":38,"minecraft:sandstone":1,"minecraft:stone_bricks":4},"sha256":"f4518b552478583bd8855b67bd1c132ee9cb71911e803f680ac54dd036c662e7","size":{"x":32,"y":1,"z":32}},{"blockCount":181,"bytes":4085,"file":"chunks/y080-z128-x032.json","offset":{"x":32,"y":80,"z":128},"requirements":{"minecraft:bricks":10,"minecraft:cobbled_deepslate":17,"minecraft:oak_planks":4,"minecraft:polished_diorite":59,"minecraft:sandstone":19,"minecraft:spruce_planks":1,"minecraft:stone_bricks":71},"sha256":"2fa33f3f550e36545b3ea87a8d8ed29fb328ae48bc78e33c90320c289db9724d","size":{"x":32,"y":1,"z":32}},{"blockCount":52,"bytes":1218,"file":"chunks/y080-z128-x064.json","offset":{"x":64,"y":80,"z":128},"requirements":{"minecraft:bricks":15,"minecraft:cobbled_deepslate":6,"minecraft:sandstone":19,"minecraft:stone_bricks":12},"sha256":"645a665d44ec3174fefe9cd840bcee7f7c7eb560b68bca871d07c59b1ef111c8","size":{"x":32,"y":1,"z":32}},{"blockCount":13,"bytes":879,"file":"chunks/y080-z128-x096.json","offset":{"x":96,"y":80,"z":128},"requirements":{"minecraft:bricks":5,"minecraft:sandstone":5,"minecraft:stone_bricks":3},"sha256":"0f4ee33a37324b4c0a26ebb7d542b396715b035f18112bdc096a84484dee3e55","size":{"x":32,"y":1,"z":32}},{"blockCount":36,"bytes":1108,"file":"chunks/y080-z128-x128.json","offset":{"x":128,"y":80,"z":128},"requirements":{"minecraft:sandstone":10,"minecraft:stone_bricks":26},"sha256":"2f1a6aad21297f7d19359b4cfb890ff1bdcb29d332d89ec2b87c8aa243119ddc","size":{"x":32,"y":1,"z":32}},{"blockCount":47,"bytes":1283,"file":"chunks/y080-z128-x160.json","offset":{"x":160,"y":80,"z":128},"requirements":{"minecraft:bricks":13,"minecraft:sandstone":20,"minecraft:stone_bricks":14},"sha256":"4f2b0a96955af8a38fd2f63ddd631107f106fd3b9391fe6d8592599b4d2565ab","size":{"x":32,"y":1,"z":32}},{"blockCount":66,"bytes":1904,"file":"chunks/y080-z128-x192.json","offset":{"x":192,"y":80,"z":128},"requirements":{"minecraft:bricks":8,"minecraft:sandstone":22,"minecraft:stone_bricks":36},"sha256":"9a679149b6cdd389a5623222a5c1b89c5816a12b5bd64c2f279424a4f1548811","size":{"x":32,"y":1,"z":32}},{"blockCount":247,"bytes":4098,"file":"chunks/y080-z128-x224.json","offset":{"x":224,"y":80,"z":128},"requirements":{"minecraft:bricks":57,"minecraft:glass":66,"minecraft:polished_diorite":32,"minecraft:sandstone":11,"minecraft:stone_bricks":81},"sha256":"d7ef2e95734bb5a85b56757ae2bce93c9b6a52a9774635fa1a5df2d917059588","size":{"x":32,"y":1,"z":32}},{"blockCount":33,"bytes":1450,"file":"chunks/y080-z160-x000.json","offset":{"x":0,"y":80,"z":160},"requirements":{"minecraft:cobbled_deepslate":14,"minecraft:polished_diorite":19},"sha256":"65696331099d15d391c855f79f9de5fbf7a8a1c89ac183e6411617638d45b96e","size":{"x":32,"y":1,"z":32}},{"blockCount":136,"bytes":4164,"file":"chunks/y080-z160-x032.json","offset":{"x":32,"y":80,"z":160},"requirements":{"minecraft:cobbled_deepslate":47,"minecraft:polished_diorite":81,"minecraft:stone_bricks":8},"sha256":"0752f96d7a6eec60c6264125c17a2897c2438ab9e07c9a0384d37feec3127c5f","size":{"x":32,"y":1,"z":32}},{"blockCount":171,"bytes":4420,"file":"chunks/y080-z160-x064.json","offset":{"x":64,"y":80,"z":160},"requirements":{"minecraft:cobbled_deepslate":65,"minecraft:polished_diorite":98,"minecraft:stone_bricks":8},"sha256":"aa49c5ab0fe25c96287704609d003c235de3f3adb6889d70a24b129fdc9feedd","size":{"x":32,"y":1,"z":32}},{"blockCount":126,"bytes":3481,"file":"chunks/y080-z160-x096.json","offset":{"x":96,"y":80,"z":160},"requirements":{"minecraft:bricks":13,"minecraft:cobbled_deepslate":14,"minecraft:polished_diorite":57,"minecraft:sandstone":8,"minecraft:stone_bricks":34},"sha256":"311de500e97c29ad17b5547caa64725d30f3814fcd1a857110c588f192f158bf","size":{"x":32,"y":1,"z":32}},{"blockCount":214,"bytes":5112,"file":"chunks/y080-z160-x128.json","offset":{"x":128,"y":80,"z":160},"requirements":{"minecraft:bricks":2,"minecraft:cobbled_deepslate":58,"minecraft:polished_diorite":98,"minecraft:sandstone":19,"minecraft:stone_bricks":37},"sha256":"5adb0c59303f72be5cf2e079f16b023201fd6351119a811a3b3be7241fa195ad","size":{"x":32,"y":1,"z":32}},{"blockCount":154,"bytes":4341,"file":"chunks/y080-z160-x160.json","offset":{"x":160,"y":80,"z":160},"requirements":{"minecraft:cobbled_deepslate":42,"minecraft:polished_diorite":103,"minecraft:stone_bricks":9},"sha256":"0f1f39bac314e061fcb9a63e59ab89eba8c70f72e1956d3c3489319b478a5f55","size":{"x":32,"y":1,"z":32}},{"blockCount":218,"bytes":5416,"file":"chunks/y080-z160-x192.json","offset":{"x":192,"y":80,"z":160},"requirements":{"minecraft:bricks":68,"minecraft:cobbled_deepslate":21,"minecraft:glass":33,"minecraft:polished_diorite":86,"minecraft:stone_bricks":10},"sha256":"8029692dddb859f23479265a86f01b46fbd666317be74c22973364ddc0016dc1","size":{"x":32,"y":1,"z":32}},{"blockCount":113,"bytes":3460,"file":"chunks/y080-z160-x224.json","offset":{"x":224,"y":80,"z":160},"requirements":{"minecraft:bricks":49,"minecraft:glass":33,"minecraft:polished_diorite":31},"sha256":"dfa3c93bcfc5d741f7c9b918c6eb00da0acf4044bd393df2aeccfc063f481eef","size":{"x":32,"y":1,"z":32}},{"blockCount":61,"bytes":1782,"file":"chunks/y080-z192-x064.json","offset":{"x":64,"y":80,"z":192},"requirements":{"minecraft:cobbled_deepslate":19,"minecraft:glass":9,"minecraft:polished_diorite":33},"sha256":"70577c60b58e7fcc2853f6e3b54519af9b59a8b8ac7c5c76fdd0e4b747de3c25","size":{"x":32,"y":1,"z":32}},{"blockCount":249,"bytes":3759,"file":"chunks/y080-z192-x096.json","offset":{"x":96,"y":80,"z":192},"requirements":{"minecraft:bricks":51,"minecraft:cobbled_deepslate":12,"minecraft:glass":32,"minecraft:polished_diorite":73,"minecraft:sandstone":10,"minecraft:stone_bricks":71},"sha256":"7e127d79c1e453f24450ef8a9a7271429e0d7404c9af93b7ccb9f60498eb56e9","size":{"x":32,"y":1,"z":32}},{"blockCount":206,"bytes":3998,"file":"chunks/y080-z192-x128.json","offset":{"x":128,"y":80,"z":192},"requirements":{"minecraft:bricks":28,"minecraft:cobbled_deepslate":31,"minecraft:glass":23,"minecraft:polished_diorite":81,"minecraft:sandstone":8,"minecraft:stone_bricks":35},"sha256":"2fb198ab89f7b68dd556a46b76ef28700b381c4fdf0907184b4411d455e515b8","size":{"x":32,"y":1,"z":32}},{"blockCount":6,"bytes":844,"file":"chunks/y080-z192-x160.json","offset":{"x":160,"y":80,"z":192},"requirements":{"minecraft:polished_diorite":6},"sha256":"cd87631a9308d58c98190fd98ef36bf69d92c524ec23fb61b9fb0705a9dfc130","size":{"x":32,"y":1,"z":32}},{"blockCount":12,"bytes":837,"file":"chunks/y081-z000-x352.json","offset":{"x":352,"y":81,"z":0},"requirements":{"minecraft:stone_bricks":12},"sha256":"e6ba333a424faa73e7c6399d5ae3dcc7dba039c162cb294476b080b46605de3e","size":{"x":32,"y":1,"z":32}},{"blockCount":1,"bytes":635,"file":"chunks/y081-z000-x384.json","offset":{"x":384,"y":81,"z":0},"requirements":{"minecraft:glass":1},"sha256":"d2c98a8a15de817c8a67de45cdca62d456280951e30daba272f4b1c9d0882797","size":{"x":32,"y":1,"z":32}},{"blockCount":70,"bytes":2191,"file":"chunks/y081-z064-x064.json","offset":{"x":64,"y":81,"z":64},"requirements":{"minecraft:cobbled_deepslate":22,"minecraft:polished_diorite":39,"minecraft:stone_bricks":9},"sha256":"7a1e25f0f7d99c902a4c433c8d234eff9ccdf9e724157355ef107e56df5fb016","size":{"x":32,"y":1,"z":32}},{"blockCount":262,"bytes":4735,"file":"chunks/y081-z064-x096.json","offset":{"x":96,"y":81,"z":64},"requirements":{"minecraft:bricks":69,"minecraft:cobbled_deepslate":12,"minecraft:glass":16,"minecraft:polished_diorite":90,"minecraft:sandstone":23,"minecraft:stone_bricks":52},"sha256":"7f06b3df68805e51955a1769ccde162d44912710706da6f8e5c996df570d5b44","size":{"x":32,"y":1,"z":32}},{"blockCount":246,"bytes":5240,"file":"chunks/y081-z064-x128.json","offset":{"x":128,"y":81,"z":64},"requirements":{"minecraft:bricks":41,"minecraft:cobbled_deepslate":34,"minecraft:glass":6,"minecraft:polished_diorite":106,"minecraft:sandstone":17,"minecraft:stone_bricks":42},"sha256":"0d09cf1e72e23882586ba27fd49b80ed012b7292cdbe68f264e957020389b8e5","size":{"x":32,"y":1,"z":32}},{"blockCount":7,"bytes":881,"file":"chunks/y081-z064-x160.json","offset":{"x":160,"y":81,"z":64},"requirements":{"minecraft:polished_diorite":7},"sha256":"c4c783415a6635004d2867697b79ed6ab59c12010821f5a65e6c890dec9dc619","size":{"x":32,"y":1,"z":32}},{"blockCount":16,"bytes":895,"file":"chunks/y081-z064-x192.json","offset":{"x":192,"y":81,"z":64},"requirements":{"minecraft:glass":7,"minecraft:polished_diorite":9},"sha256":"63c2568e62cde2ec462ff15ef665a8b15db0bfc6e105dbdbc3a43687eee2630c","size":{"x":32,"y":1,"z":32}},{"blockCount":19,"bytes":935,"file":"chunks/y081-z064-x224.json","offset":{"x":224,"y":81,"z":64},"requirements":{"minecraft:glass":7,"minecraft:polished_diorite":12},"sha256":"a7834fadf92c8a5d384b1ea68771e8d99c86ea3d9e94546ae93286026a6eae40","size":{"x":32,"y":1,"z":32}},{"blockCount":96,"bytes":2148,"file":"chunks/y081-z096-x000.json","offset":{"x":0,"y":81,"z":96},"requirements":{"minecraft:cobbled_deepslate":66,"minecraft:polished_diorite":29,"minecraft:stone_bricks":1},"sha256":"71024146d7d20e37e80905a0bd2fadd51b4722a42f9e2b1c76aa09ead8d8db17","size":{"x":32,"y":1,"z":32}},{"blockCount":198,"bytes":4616,"file":"chunks/y081-z096-x032.json","offset":{"x":32,"y":81,"z":96},"requirements":{"minecraft:bricks":12,"minecraft:cobbled_deepslate":37,"minecraft:polished_diorite":95,"minecraft:sandstone":23,"minecraft:stone_bricks":31},"sha256":"15e89cbcb0befc1f549edfba242a13663fead5755140d53f47fab1d79dce917b","size":{"x":32,"y":1,"z":32}},{"blockCount":212,"bytes":4317,"file":"chunks/y081-z096-x064.json","offset":{"x":64,"y":81,"z":96},"requirements":{"minecraft:bricks":23,"minecraft:cobbled_deepslate":46,"minecraft:polished_diorite":95,"minecraft:sandstone":25,"minecraft:stone_bricks":23},"sha256":"3466e409ccd1dbecd5a325f78cf820a202ce05e13406dc788faa277a7ee3297e","size":{"x":32,"y":1,"z":32}},{"blockCount":126,"bytes":3554,"file":"chunks/y081-z096-x096.json","offset":{"x":96,"y":81,"z":96},"requirements":{"minecraft:bricks":22,"minecraft:cobbled_deepslate":8,"minecraft:polished_diorite":49,"minecraft:sandstone":31,"minecraft:stone_bricks":16},"sha256":"e7c8ae7e1e8a85ac5e69a68bd458ffe904975d22c9ce90187e6632566aab8195","size":{"x":32,"y":1,"z":32}},{"blockCount":223,"bytes":5126,"file":"chunks/y081-z096-x128.json","offset":{"x":128,"y":81,"z":96},"requirements":{"minecraft:bricks":32,"minecraft:cobbled_deepslate":37,"minecraft:polished_diorite":85,"minecraft:sandstone":44,"minecraft:stone_bricks":25},"sha256":"8650757a2b45982cd5ef392dfe1ee54eac305f1c0a765bae9c55cc63dbbe547b","size":{"x":32,"y":1,"z":32}},{"blockCount":214,"bytes":4503,"file":"chunks/y081-z096-x160.json","offset":{"x":160,"y":81,"z":96},"requirements":{"minecraft:bricks":23,"minecraft:cobbled_deepslate":34,"minecraft:polished_diorite":108,"minecraft:sandstone":24,"minecraft:stone_bricks":25},"sha256":"e16fb1ef75a0ee842341c2e489dade27a77691a3277269218031f92a5df18e60","size":{"x":32,"y":1,"z":32}},{"blockCount":272,"bytes":5748,"file":"chunks/y081-z096-x192.json","offset":{"x":192,"y":81,"z":96},"requirements":{"minecraft:bricks":96,"minecraft:cobbled_deepslate":17,"minecraft:glass":26,"minecraft:polished_diorite":80,"minecraft:sandstone":26,"minecraft:stone_bricks":27},"sha256":"276af593c0dc08ae523b39e40c50e6303c168984aa6750e1f60a9ca1d22e10a5","size":{"x":32,"y":1,"z":32}},{"blockCount":145,"bytes":4021,"file":"chunks/y081-z096-x224.json","offset":{"x":224,"y":81,"z":96},"requirements":{"minecraft:bricks":65,"minecraft:glass":39,"minecraft:polished_diorite":40,"minecraft:stone_bricks":1},"sha256":"3e1256e696af8403d98eeacd89b93293c0958892b8377405169555c7ed4bfe02","size":{"x":32,"y":1,"z":32}},{"blockCount":152,"bytes":2879,"file":"chunks/y081-z128-x000.json","offset":{"x":0,"y":81,"z":128},"requirements":{"minecraft:cobbled_deepslate":107,"minecraft:polished_diorite":36,"minecraft:stone_bricks":9},"sha256":"a8f815d6f70afe15004141f66aa5ee4c4c7b07dc9223be68437d546ab5b4e716","size":{"x":32,"y":1,"z":32}},{"blockCount":214,"bytes":4406,"file":"chunks/y081-z128-x032.json","offset":{"x":32,"y":81,"z":128},"requirements":{"minecraft:bricks":26,"minecraft:cobbled_deepslate":9,"minecraft:oak_planks":1,"minecraft:polished_diorite":70,"minecraft:sandstone":39,"minecraft:spruce_planks":5,"minecraft:stone_bricks":64},"sha256":"ab88a3376add9ef968eaba41301efab0220309ef5ad5f10bc2deac526372ea93","size":{"x":32,"y":1,"z":32}},{"blockCount":59,"bytes":1661,"file":"chunks/y081-z128-x064.json","offset":{"x":64,"y":81,"z":128},"requirements":{"minecraft:bricks":23,"minecraft:sandstone":25,"minecraft:stone_bricks":11},"sha256":"a117c3c09db858b5e20ae885dc0ec37191cac251e8981496e2cfe142cf11ad86","size":{"x":32,"y":1,"z":32}},{"blockCount":16,"bytes":957,"file":"chunks/y081-z128-x096.json","offset":{"x":96,"y":81,"z":128},"requirements":{"minecraft:bricks":4,"minecraft:sandstone":10,"minecraft:stone_bricks":2},"sha256":"1bd53e840324391d5b0c42e8225c35d7ed70558c8b699158ab12782ee29a78c7","size":{"x":32,"y":1,"z":32}},{"blockCount":43,"bytes":1435,"file":"chunks/y081-z128-x128.json","offset":{"x":128,"y":81,"z":128},"requirements":{"minecraft:bricks":13,"minecraft:sandstone":24,"minecraft:stone_bricks":6},"sha256":"8a79fc5d735697f5e497f2a1593476de33effc883525d7ae7f20c1c78b6da282","size":{"x":32,"y":1,"z":32}},{"blockCount":59,"bytes":1644,"file":"chunks/y081-z128-x160.json","offset":{"x":160,"y":81,"z":128},"requirements":{"minecraft:bricks":23,"minecraft:sandstone":25,"minecraft:stone_bricks":11},"sha256":"21bb22d3bf3ca62b4f23fc677fc389ffeef61889cd433e55a8b6d9e141d78486","size":{"x":32,"y":1,"z":32}},{"blockCount":66,"bytes":1861,"file":"chunks/y081-z128-x192.json","offset":{"x":192,"y":81,"z":128},"requirements":{"minecraft:bricks":25,"minecraft:sandstone":26,"minecraft:stone_bricks":15},"sha256":"cae171b500ae60e4cc9e906cf3c9e5010078ed94dbc7426a91e9bd33a5fd2f54","size":{"x":32,"y":1,"z":32}},{"blockCount":180,"bytes":4191,"file":"chunks/y081-z128-x224.json","offset":{"x":224,"y":81,"z":128},"requirements":{"minecraft:bricks":66,"minecraft:glass":68,"minecraft:polished_diorite":32,"minecraft:sandstone":6,"minecraft:stone_bricks":8},"sha256":"18631bd81b83597a3615531a30b28d8f662f72183bb017da44a485da31ee40e4","size":{"x":32,"y":1,"z":32}},{"blockCount":42,"bytes":1488,"file":"chunks/y081-z160-x000.json","offset":{"x":0,"y":81,"z":160},"requirements":{"minecraft:cobbled_deepslate":23,"minecraft:polished_diorite":19},"sha256":"3cdb841128bc6c38df5a4f43956bf14573f0fc37834d9af4028011a43a2606d6","size":{"x":32,"y":1,"z":32}},{"blockCount":132,"bytes":3216,"file":"chunks/y081-z160-x032.json","offset":{"x":32,"y":81,"z":160},"requirements":{"minecraft:cobbled_deepslate":36,"minecraft:polished_diorite":84,"minecraft:stone_bricks":12},"sha256":"ea20b8336decfa5ed61ff5797f6ac89681a9d2c6d0aa275f463ce3c1fc074200","size":{"x":32,"y":1,"z":32}},{"blockCount":169,"bytes":3510,"file":"chunks/y081-z160-x064.json","offset":{"x":64,"y":81,"z":160},"requirements":{"minecraft:cobbled_deepslate":55,"minecraft:polished_diorite":102,"minecraft:stone_bricks":12},"sha256":"362d1e46283eb045339fab7e0a0b6dca59b4d08faf9822372d98d053b9de8ab5","size":{"x":32,"y":1,"z":32}},{"blockCount":144,"bytes":3976,"file":"chunks/y081-z160-x096.json","offset":{"x":96,"y":81,"z":160},"requirements":{"minecraft:bricks":23,"minecraft:cobbled_deepslate":13,"minecraft:polished_diorite":63,"minecraft:sandstone":25,"minecraft:stone_bricks":20},"sha256":"86d4321b845e942f3939082f257150b922108326686f0b78ae4a46e3f43f90f1","size":{"x":32,"y":1,"z":32}},{"blockCount":229,"bytes":5265,"file":"chunks/y081-z160-x128.json","offset":{"x":128,"y":81,"z":160},"requirements":{"minecraft:bricks":23,"minecraft:cobbled_deepslate":51,"minecraft:polished_diorite":105,"minecraft:sandstone":25,"minecraft:stone_bricks":25},"sha256":"5c835c94611d65a9293ca0d4411d9a51455192217ffbbef988c2eda084f715f5","size":{"x":32,"y":1,"z":32}},{"blockCount":156,"bytes":3430,"file":"chunks/y081-z160-x160.json","offset":{"x":160,"y":81,"z":160},"requirements":{"minecraft:cobbled_deepslate":34,"minecraft:polished_diorite":109,"minecraft:stone_bricks":13},"sha256":"b08e784afa29c04a55e9bf043f7b0212c080fba3595cc77008235e49caeab125","size":{"x":32,"y":1,"z":32}},{"blockCount":226,"bytes":4960,"file":"chunks/y081-z160-x192.json","offset":{"x":192,"y":81,"z":160},"requirements":{"minecraft:bricks":71,"minecraft:cobbled_deepslate":17,"minecraft:glass":33,"minecraft:polished_diorite":89,"minecraft:stone_bricks":16},"sha256":"e1ff24f9d872a51dfd2ae81ad6bc09095abf62671e98ecab1afacf1587472c25","size":{"x":32,"y":1,"z":32}},{"blockCount":113,"bytes":3460,"file":"chunks/y081-z160-x224.json","offset":{"x":224,"y":81,"z":160},"requirements":{"minecraft:bricks":49,"minecraft:glass":33,"minecraft:polished_diorite":31},"sha256":"f1e10179c957470313723fcec91a5ebeca620846282fcd6105d8add7313db57b","size":{"x":32,"y":1,"z":32}},{"blockCount":54,"bytes":1884,"file":"chunks/y081-z192-x064.json","offset":{"x":64,"y":81,"z":192},"requirements":{"minecraft:cobbled_deepslate":13,"minecraft:polished_diorite":32,"minecraft:stone_bricks":9},"sha256":"cdb58fd511869c6382520083c9152fa68aee42b354c751e6262d5b0c852bf08a","size":{"x":32,"y":1,"z":32}},{"blockCount":228,"bytes":3987,"file":"chunks/y081-z192-x096.json","offset":{"x":96,"y":81,"z":192},"requirements":{"minecraft:bricks":65,"minecraft:cobbled_deepslate":7,"minecraft:glass":16,"minecraft:polished_diorite":76,"minecraft:sandstone":18,"minecraft:stone_bricks":46},"sha256":"cc67256139b92f3080af1473affa9ad29c9a6aaf8dd432d6116f971a9634a24c","size":{"x":32,"y":1,"z":32}},{"blockCount":197,"bytes":4281,"file":"chunks/y081-z192-x128.json","offset":{"x":128,"y":81,"z":192},"requirements":{"minecraft:bricks":36,"minecraft:cobbled_deepslate":20,"minecraft:glass":6,"minecraft:polished_diorite":86,"minecraft:sandstone":13,"minecraft:stone_bricks":36},"sha256":"51eda3c77ff59d74541869fd3bf37f8d3321b3fe92bfb334f725991aec4af048","size":{"x":32,"y":1,"z":32}},{"blockCount":6,"bytes":844,"file":"chunks/y081-z192-x160.json","offset":{"x":160,"y":81,"z":192},"requirements":{"minecraft:polished_diorite":6},"sha256":"9c3df457bba6b29f538e4486ca017c9a97a6c3ce13f96cad599c5c523aa06cea","size":{"x":32,"y":1,"z":32}},{"blockCount":8,"bytes":758,"file":"chunks/y082-z000-x352.json","offset":{"x":352,"y":82,"z":0},"requirements":{"minecraft:stone_bricks":8},"sha256":"d5e52337b0f2dcf51469fcdbe7edc390dfe125fc504334dd43a50b9daf6ec751","size":{"x":32,"y":1,"z":32}},{"blockCount":51,"bytes":1967,"file":"chunks/y082-z064-x064.json","offset":{"x":64,"y":82,"z":64},"requirements":{"minecraft:glass":8,"minecraft:polished_diorite":39,"minecraft:stone_bricks":4},"sha256":"de4af1f82e2baf00d9db9999d6479ac1f7bb589dee066f0526f9689a177b6543","size":{"x":32,"y":1,"z":32}},{"blockCount":221,"bytes":4777,"file":"chunks/y082-z064-x096.json","offset":{"x":96,"y":82,"z":64},"requirements":{"minecraft:bricks":45,"minecraft:glass":17,"minecraft:polished_diorite":86,"minecraft:sandstone":38,"minecraft:stone_bricks":35},"sha256":"79e281ec51ddf464edafa39397208a2c6fb929270a9548f87c17a1467a254e40","size":{"x":32,"y":1,"z":32}},{"blockCount":204,"bytes":5072,"file":"chunks/y082-z064-x128.json","offset":{"x":128,"y":82,"z":64},"requirements":{"minecraft:bricks":37,"minecraft:glass":15,"minecraft:polished_diorite":100,"minecraft:sandstone":22,"minecraft:stone_bricks":30},"sha256":"00440e497a24f46d79f2db99d4397585e08ca4e1b277c1efbb4e475860a83177","size":{"x":32,"y":1,"z":32}},{"blockCount":7,"bytes":881,"file":"chunks/y082-z064-x160.json","offset":{"x":160,"y":82,"z":64},"requirements":{"minecraft:polished_diorite":7},"sha256":"b9c8bd2f5caaea4484de14949fa1cff90786e4bbc7629fac0d7e5ef35eecd1b7","size":{"x":32,"y":1,"z":32}},{"blockCount":12,"bytes":1009,"file":"chunks/y082-z064-x192.json","offset":{"x":192,"y":82,"z":64},"requirements":{"minecraft:glass":3,"minecraft:polished_diorite":9},"sha256":"a8c3a87d7702b048c68349b1fdd2ae4edb714398af5ca0a1d015a3f34b393c5d","size":{"x":32,"y":1,"z":32}},{"blockCount":15,"bytes":1049,"file":"chunks/y082-z064-x224.json","offset":{"x":224,"y":82,"z":64},"requirements":{"minecraft:glass":3,"minecraft:polished_diorite":12},"sha256":"bd5058ea2af713c2917b376eb425e45a6b210c8719aa5611aacfba8a184b0389","size":{"x":32,"y":1,"z":32}},{"blockCount":61,"bytes":2289,"file":"chunks/y082-z096-x000.json","offset":{"x":0,"y":82,"z":96},"requirements":{"minecraft:glass":22,"minecraft:polished_diorite":29,"minecraft:stone_bricks":10},"sha256":"182c7943bf8f9eed832bbf034228ec8683f8b3a4d1d4b99f1c9253e3db16fcf9","size":{"x":32,"y":1,"z":32}},{"blockCount":176,"bytes":4737,"file":"chunks/y082-z096-x032.json","offset":{"x":32,"y":82,"z":96},"requirements":{"minecraft:bricks":19,"minecraft:glass":11,"minecraft:polished_diorite":94,"minecraft:sandstone":20,"minecraft:stone_bricks":32},"sha256":"51d2c81dcd47ec8d0797a18ef3987333c023fbc32db0aa8e81db7e22958621ec","size":{"x":32,"y":1,"z":32}},{"blockCount":189,"bytes":4362,"file":"chunks/y082-z096-x064.json","offset":{"x":64,"y":82,"z":96},"requirements":{"minecraft:bricks":32,"minecraft:glass":14,"minecraft:polished_diorite":89,"minecraft:sandstone":22,"minecraft:stone_bricks":32},"sha256":"8814b4c23f1ed2bece4226e5b8f16fe4a38e2a3209318ac31054cc242fdaf5b6","size":{"x":32,"y":1,"z":32}},{"blockCount":124,"bytes":3732,"file":"chunks/y082-z096-x096.json","offset":{"x":96,"y":82,"z":96},"requirements":{"minecraft:bricks":33,"minecraft:glass":1,"minecraft:polished_diorite":46,"minecraft:sandstone":25,"minecraft:stone_bricks":19},"sha256":"154c221a602e31afb3cc0c30499f6267a4803b64b4180f5139d2b3d6c51701b2","size":{"x":32,"y":1,"z":32}},{"blockCount":207,"bytes":5261,"file":"chunks/y082-z096-x128.json","offset":{"x":128,"y":82,"z":96},"requirements":{"minecraft:bricks":48,"minecraft:glass":10,"minecraft:polished_diorite":79,"minecraft:sandstone":35,"minecraft:stone_bricks":35},"sha256":"304f622a5cc5d4058b507a488e7ab4b62cb8e2359290c809e60f9a2c691b26bb","size":{"x":32,"y":1,"z":32}},{"blockCount":197,"bytes":4680,"file":"chunks/y082-z096-x160.json","offset":{"x":160,"y":82,"z":96},"requirements":{"minecraft:bricks":32,"minecraft:glass":10,"minecraft:polished_diorite":102,"minecraft:sandstone":23,"minecraft:stone_bricks":30},"sha256":"c0949edd9826e1df0bde1286034a07b94ffeef3ef5759ce21bc042c8220b07f8","size":{"x":32,"y":1,"z":32}},{"blockCount":252,"bytes":5488,"file":"chunks/y082-z096-x192.json","offset":{"x":192,"y":82,"z":96},"requirements":{"minecraft:bricks":105,"minecraft:glass":23,"minecraft:polished_diorite":77,"minecraft:sandstone":22,"minecraft:stone_bricks":25},"sha256":"c89cd3a5fba9f1f1fd9e71455fcc6984e517d72c1fe1b4df8752ccbe25512738","size":{"x":32,"y":1,"z":32}},{"blockCount":134,"bytes":3912,"file":"chunks/y082-z096-x224.json","offset":{"x":224,"y":82,"z":96},"requirements":{"minecraft:bricks":64,"minecraft:glass":26,"minecraft:polished_diorite":40,"minecraft:sandstone":1,"minecraft:stone_bricks":3},"sha256":"625a8f7a0ec4e0b9bf359528f4a389c25237d744c3fc0922186c06f0aad0769f","size":{"x":32,"y":1,"z":32}},{"blockCount":83,"bytes":2729,"file":"chunks/y082-z128-x000.json","offset":{"x":0,"y":82,"z":128},"requirements":{"minecraft:glass":33,"minecraft:polished_diorite":36,"minecraft:stone_bricks":14},"sha256":"c4fc81f12b7753eec77a75c9d91fa1efaefae1de1551a5ace966a0a18af50854","size":{"x":32,"y":1,"z":32}},{"blockCount":204,"bytes":4718,"file":"chunks/y082-z128-x032.json","offset":{"x":32,"y":82,"z":128},"requirements":{"minecraft:bricks":40,"minecraft:glass":2,"minecraft:oak_planks":2,"minecraft:polished_diorite":72,"minecraft:sandstone":33,"minecraft:spruce_planks":3,"minecraft:stone_bricks":52},"sha256":"608eeca98ca12edf92b6cb45fee6bce8788b117faf73c41dfc5aafe7db55060f","size":{"x":32,"y":1,"z":32}},{"blockCount":64,"bytes":1699,"file":"chunks/y082-z128-x064.json","offset":{"x":64,"y":82,"z":128},"requirements":{"minecraft:bricks":32,"minecraft:sandstone":21,"minecraft:stone_bricks":11},"sha256":"c1f43f8824c49bcdcd69b7003e64a2d7c498f41515b795852edc24a666e35ac4","size":{"x":32,"y":1,"z":32}},{"blockCount":18,"bytes":1051,"file":"chunks/y082-z128-x096.json","offset":{"x":96,"y":82,"z":128},"requirements":{"minecraft:bricks":8,"minecraft:sandstone":8,"minecraft:stone_bricks":2},"sha256":"f062e0826c2e52ffb8e887fd835646ef4d3878b5f572fd1cdf4e6c12d7d4ca50","size":{"x":32,"y":1,"z":32}},{"blockCount":48,"bytes":1585,"file":"chunks/y082-z128-x128.json","offset":{"x":128,"y":82,"z":128},"requirements":{"minecraft:bricks":23,"minecraft:sandstone":18,"minecraft:stone_bricks":7},"sha256":"ac11b24b11a7202b0af32a813a40c34a9d53bec4c4af1eac66eeefedc4c80404","size":{"x":32,"y":1,"z":32}},{"blockCount":64,"bytes":1720,"file":"chunks/y082-z128-x160.json","offset":{"x":160,"y":82,"z":128},"requirements":{"minecraft:bricks":32,"minecraft:sandstone":22,"minecraft:stone_bricks":10},"sha256":"de6943341c8c2a33e6111a7163daa6c35d0bce201a28347caaef21e945f8d1ff","size":{"x":32,"y":1,"z":32}},{"blockCount":67,"bytes":1720,"file":"chunks/y082-z128-x192.json","offset":{"x":192,"y":82,"z":128},"requirements":{"minecraft:bricks":37,"minecraft:sandstone":22,"minecraft:stone_bricks":8},"sha256":"d41d71784d5810326ca5649d63ca3d218cbccc1c8ecb1bf47860d2bb7ee72169","size":{"x":32,"y":1,"z":32}},{"blockCount":133,"bytes":4307,"file":"chunks/y082-z128-x224.json","offset":{"x":224,"y":82,"z":128},"requirements":{"minecraft:bricks":27,"minecraft:glass":35,"minecraft:polished_diorite":32,"minecraft:sandstone":27,"minecraft:stone_bricks":12},"sha256":"9fd32946cdb77d5d1482f3a8a0ae101d6a3323a18daffe17ea5459b7416f16b7","size":{"x":32,"y":1,"z":32}},{"blockCount":33,"bytes":1559,"file":"chunks/y082-z160-x000.json","offset":{"x":0,"y":82,"z":160},"requirements":{"minecraft:glass":9,"minecraft:polished_diorite":19,"minecraft:stone_bricks":5},"sha256":"0dea370287ae8710e0e6acb6cf3bfd851b734f45b924c3aa82d7e2c037419783","size":{"x":32,"y":1,"z":32}},{"blockCount":109,"bytes":3203,"file":"chunks/y082-z160-x032.json","offset":{"x":32,"y":82,"z":160},"requirements":{"minecraft:glass":11,"minecraft:polished_diorite":81,"minecraft:stone_bricks":17},"sha256":"dd5b393e9cba6c167857197f268eda94092b9a20f56418f50347e77d83f6dd20","size":{"x":32,"y":1,"z":32}},{"blockCount":138,"bytes":3420,"file":"chunks/y082-z160-x064.json","offset":{"x":64,"y":82,"z":160},"requirements":{"minecraft:glass":18,"minecraft:polished_diorite":96,"minecraft:stone_bricks":24},"sha256":"c75ac7a6fb02b6c05ea01401fc34f9c2e853ed3843fec8355aaeb48843096c02","size":{"x":32,"y":1,"z":32}},{"blockCount":138,"bytes":4077,"file":"chunks/y082-z160-x096.json","offset":{"x":96,"y":82,"z":160},"requirements":{"minecraft:bricks":31,"minecraft:glass":2,"minecraft:polished_diorite":59,"minecraft:sandstone":22,"minecraft:stone_bricks":24},"sha256":"439887e80efb6e2d27e8edd39d387d0742dd15822266e9b2d3ea94b18c02927a","size":{"x":32,"y":1,"z":32}},{"blockCount":203,"bytes":5267,"file":"chunks/y082-z160-x128.json","offset":{"x":128,"y":82,"z":160},"requirements":{"minecraft:bricks":31,"minecraft:glass":15,"minecraft:polished_diorite":98,"minecraft:sandstone":22,"minecraft:stone_bricks":37},"sha256":"936904f3ab5c2ded685236950377cca9e430ac1c0a5dce46228da0c028d31122","size":{"x":32,"y":1,"z":32}},{"blockCount":134,"bytes":3493,"file":"chunks/y082-z160-x160.json","offset":{"x":160,"y":82,"z":160},"requirements":{"minecraft:glass":10,"minecraft:polished_diorite":103,"minecraft:stone_bricks":21},"sha256":"129a83ff3c4cfb3413e0dc90f3898bee81acb81a3f4bbeb1145943ade73be657","size":{"x":32,"y":1,"z":32}},{"blockCount":197,"bytes":4776,"file":"chunks/y082-z160-x192.json","offset":{"x":192,"y":82,"z":160},"requirements":{"minecraft:bricks":68,"minecraft:glass":26,"minecraft:polished_diorite":86,"minecraft:stone_bricks":17},"sha256":"6bb6f5ba7eac386d9336343f026478a169196c3cec9d170326ef663770c2324b","size":{"x":32,"y":1,"z":32}},{"blockCount":101,"bytes":3346,"file":"chunks/y082-z160-x224.json","offset":{"x":224,"y":82,"z":160},"requirements":{"minecraft:bricks":49,"minecraft:glass":21,"minecraft:polished_diorite":31},"sha256":"59f04546018dbf233ef079b50ee12535078e6c6abfbce90eba4c4887a0b7bd7d","size":{"x":32,"y":1,"z":32}},{"blockCount":38,"bytes":1680,"file":"chunks/y082-z192-x064.json","offset":{"x":64,"y":82,"z":192},"requirements":{"minecraft:glass":4,"minecraft:polished_diorite":32,"minecraft:stone_bricks":2},"sha256":"dde63c56b48cf6193f93f15b28b63374c3afbb3463004f3ec2b66c1e70a499b8","size":{"x":32,"y":1,"z":32}},{"blockCount":189,"bytes":4068,"file":"chunks/y082-z192-x096.json","offset":{"x":96,"y":82,"z":192},"requirements":{"minecraft:bricks":39,"minecraft:glass":16,"minecraft:polished_diorite":73,"minecraft:sandstone":33,"minecraft:stone_bricks":28},"sha256":"2f5ea474fcfb18045e4f29874483b7948f5312d8ef598b01731382d04110a017","size":{"x":32,"y":1,"z":32}},{"blockCount":160,"bytes":4115,"file":"chunks/y082-z192-x128.json","offset":{"x":128,"y":82,"z":192},"requirements":{"minecraft:bricks":31,"minecraft:glass":10,"minecraft:polished_diorite":81,"minecraft:sandstone":17,"minecraft:stone_bricks":21},"sha256":"5545d42f39d96cde9c7f999106eacd12d56605f0f76c9666993bc9666d392742","size":{"x":32,"y":1,"z":32}},{"blockCount":6,"bytes":844,"file":"chunks/y082-z192-x160.json","offset":{"x":160,"y":82,"z":192},"requirements":{"minecraft:polished_diorite":6},"sha256":"e1ef4c59c976763d401087e4c6cf99cf5a2938ff4c00e59d3920a745a67cada0","size":{"x":32,"y":1,"z":32}},{"blockCount":4,"bytes":758,"file":"chunks/y083-z000-x352.json","offset":{"x":352,"y":83,"z":0},"requirements":{"minecraft:stone_bricks":4},"sha256":"0f19c2edba7a63c679a9d17e784a775e528fd8b7fe3837a20ea004e53283e1c7","size":{"x":32,"y":1,"z":32}},{"blockCount":51,"bytes":1834,"file":"chunks/y083-z064-x064.json","offset":{"x":64,"y":83,"z":64},"requirements":{"minecraft:polished_diorite":39,"minecraft:stone_bricks":12},"sha256":"b033d9ec527e9caf12734e29986696ed558346095fc0d8bf68d772402db4912f","size":{"x":32,"y":1,"z":32}},{"blockCount":214,"bytes":4814,"file":"chunks/y083-z064-x096.json","offset":{"x":96,"y":83,"z":64},"requirements":{"minecraft:bricks":46,"minecraft:glass":15,"minecraft:polished_diorite":86,"minecraft:sandstone":13,"minecraft:stone_bricks":54},"sha256":"24cc4bf80700c0b64508e8181918923701d631fb0811b75088f337c9864f0f38","size":{"x":32,"y":1,"z":32}},{"blockCount":207,"bytes":4861,"file":"chunks/y083-z064-x128.json","offset":{"x":128,"y":83,"z":64},"requirements":{"minecraft:bricks":38,"minecraft:glass":5,"minecraft:polished_diorite":100,"minecraft:sandstone":7,"minecraft:stone_bricks":57},"sha256":"ba426edb8723784167e76fdec12b491f26c8946204ba0b88b86f2c00d05814a2","size":{"x":32,"y":1,"z":32}},{"blockCount":7,"bytes":881,"file":"chunks/y083-z064-x160.json","offset":{"x":160,"y":83,"z":64},"requirements":{"minecraft:polished_diorite":7},"sha256":"031e5ec8fb576459752000bc1671075ccd6e2fef973bf89446f6de55d5a826ac","size":{"x":32,"y":1,"z":32}},{"blockCount":9,"bytes":875,"file":"chunks/y083-z064-x192.json","offset":{"x":192,"y":83,"z":64},"requirements":{"minecraft:polished_diorite":9},"sha256":"7456484e094fa33e5abfe33c7a3d2e50b017063b383452e353ab5410314bc023","size":{"x":32,"y":1,"z":32}},{"blockCount":12,"bytes":915,"file":"chunks/y083-z064-x224.json","offset":{"x":224,"y":83,"z":64},"requirements":{"minecraft:polished_diorite":12},"sha256":"f75b5fa42e2ab9729bcf9dc014d0ac2d2f03b73b31850997f6742b663b8d660a","size":{"x":32,"y":1,"z":32}},{"blockCount":61,"bytes":2116,"file":"chunks/y083-z096-x000.json","offset":{"x":0,"y":83,"z":96},"requirements":{"minecraft:polished_diorite":29,"minecraft:stone_bricks":32},"sha256":"98dd29e251e2ee27bd003db2b695417d2c4a0986e4bb815b43082d5ef458d938","size":{"x":32,"y":1,"z":32}},{"blockCount":186,"bytes":4221,"file":"chunks/y083-z096-x032.json","offset":{"x":32,"y":83,"z":96},"requirements":{"minecraft:bricks":27,"minecraft:polished_diorite":90,"minecraft:sandstone":5,"minecraft:stone_bricks":64},"sha256":"0ec08cf4997ce56610c0c6ffec12763129060c7996d41cebdfa5266f1384ac54","size":{"x":32,"y":1,"z":32}},{"blockCount":197,"bytes":3618,"file":"chunks/y083-z096-x064.json","offset":{"x":64,"y":83,"z":96},"requirements":{"minecraft:bricks":34,"minecraft:polished_diorite":89,"minecraft:sandstone":6,"minecraft:stone_bricks":68},"sha256":"ff0017c7c6e17298da65b3230a5b6b5fc09d5be59b3fcb9147219f2e0eee5895","size":{"x":32,"y":1,"z":32}},{"blockCount":127,"bytes":3558,"file":"chunks/y083-z096-x096.json","offset":{"x":96,"y":83,"z":96},"requirements":{"minecraft:bricks":36,"minecraft:polished_diorite":46,"minecraft:sandstone":9,"minecraft:stone_bricks":36},"sha256":"f350cd975595ef893e9c99154d4dcb4411f1784683c00cf4eb6059331376357f","size":{"x":32,"y":1,"z":32}},{"blockCount":213,"bytes":4706,"file":"chunks/y083-z096-x128.json","offset":{"x":128,"y":83,"z":96},"requirements":{"minecraft:bricks":51,"minecraft:polished_diorite":79,"minecraft:sandstone":12,"minecraft:stone_bricks":71},"sha256":"4b0423c6536afae97a4d4081143450aec028b0dc4667cdd3d81f2c12b2acc47d","size":{"x":32,"y":1,"z":32}},{"blockCount":205,"bytes":4013,"file":"chunks/y083-z096-x160.json","offset":{"x":160,"y":83,"z":96},"requirements":{"minecraft:bricks":34,"minecraft:polished_diorite":102,"minecraft:sandstone":7,"minecraft:stone_bricks":62},"sha256":"4a0f78548859ed047b72b1a51fd003ea9e6e31a2a3d8acf07702162a08746534","size":{"x":32,"y":1,"z":32}},{"blockCount":249,"bytes":4727,"file":"chunks/y083-z096-x192.json","offset":{"x":192,"y":83,"z":96},"requirements":{"minecraft:bricks":107,"minecraft:glass":12,"minecraft:polished_diorite":77,"minecraft:sandstone":7,"minecraft:stone_bricks":46},"sha256":"977b65979ab1962409a12f42408d59aa187a126142a484d644e2072f1789318d","size":{"x":32,"y":1,"z":32}},{"blockCount":121,"bytes":3456,"file":"chunks/y083-z096-x224.json","offset":{"x":224,"y":83,"z":96},"requirements":{"minecraft:bricks":64,"minecraft:glass":15,"minecraft:polished_diorite":40,"minecraft:sandstone":1,"minecraft:stone_bricks":1},"sha256":"3ade210f8b52674d0929c34eda3b8b52b74eae2dbf6b6ea736f8bd9d9d6f408a","size":{"x":32,"y":1,"z":32}}],"schema":1}
