{"entries":[{"blockCount":83,"bytes":2311,"file":"chunks/y083-z128-x000.json","offset":{"x":0,"y":83,"z":128},"requirements":{"minecraft:polished_diorite":36,"minecraft:stone_bricks":47},"sha256":"48b8ff7f86064957fe698b2b260bed15e7e13ccfab7c094669d86290478ec573","size":{"x":32,"y":1,"z":32}},{"blockCount":215,"bytes":4160,"file":"chunks/y083-z128-x032.json","offset":{"x":32,"y":83,"z":128},"requirements":{"minecraft:bricks":57,"minecraft:polished_diorite":66,"minecraft:sandstone":11,"minecraft:spruce_planks":5,"minecraft:stone_bricks":76},"sha256":"b51d459aaa07a5d1e8508983a9ef0c662be67cf1f4095ac255c453a38be2d4cb","size":{"x":32,"y":1,"z":32}},{"blockCount":64,"bytes":1223,"file":"chunks/y083-z128-x064.json","offset":{"x":64,"y":83,"z":128},"requirements":{"minecraft:bricks":34,"minecraft:sandstone":6,"minecraft:stone_bricks":24},"sha256":"b3c0c5926b93242234579558cc3fd130e7bc010fa470b9305eb01b67a403ce78","size":{"x":32,"y":1,"z":32}},{"blockCount":17,"bytes":936,"file":"chunks/y083-z128-x096.json","offset":{"x":96,"y":83,"z":128},"requirements":{"minecraft:bricks":9,"minecraft:sandstone":4,"minecraft:stone_bricks":4},"sha256":"8caf4b483e5a9b58dafadfba17b08712fda9a15d033efc8a7996317da48261d0","size":{"x":32,"y":1,"z":32}},{"blockCount":46,"bytes":1222,"file":"chunks/y083-z128-x128.json","offset":{"x":128,"y":83,"z":128},"requirements":{"minecraft:bricks":25,"minecraft:sandstone":7,"minecraft:stone_bricks":14},"sha256":"4093f81457e58f5b27ece6bcfbeddc1f710775152bcb18767571a42fe1f41f94","size":{"x":32,"y":1,"z":32}},{"blockCount":64,"bytes":1263,"file":"chunks/y083-z128-x160.json","offset":{"x":160,"y":83,"z":128},"requirements":{"minecraft:bricks":34,"minecraft:sandstone":7,"minecraft:stone_bricks":23},"sha256":"9c50f367c2576251792ef4b74c5a96832ab8accda8cca8cb6197c2c9d3c2638c","size":{"x":32,"y":1,"z":32}},{"blockCount":66,"bytes":1244,"file":"chunks/y083-z128-x192.json","offset":{"x":192,"y":83,"z":128},"requirements":{"minecraft:bricks":38,"minecraft:sandstone":7,"minecraft:stone_bricks":21},"sha256":"ccbcf3e8a08c45f0c28491787c5728e99e59fc95d388d9ba92fdf121bfd1338c","size":{"x":32,"y":1,"z":32}},{"blockCount":101,"bytes":3147,"file":"chunks/y083-z128-x224.json","offset":{"x":224,"y":83,"z":128},"requirements":{"minecraft:bricks":25,"minecraft:glass":21,"minecraft:polished_diorite":36,"minecraft:sandstone":9,"minecraft:stone_bricks":10},"sha256":"4d39653e0683da195daee9898413e9f560e7e6d58142ecce630a1cecf41c0813","size":{"x":32,"y":1,"z":32}},{"blockCount":33,"bytes":1483,"file":"chunks/y083-z160-x000.json","offset":{"x":0,"y":83,"z":160},"requirements":{"minecraft:polished_diorite":19,"minecraft:stone_bricks":14},"sha256":"6df4c35efbb567c38947e310beda341e40c11212ba0cb8c39b4ac57afbdcf177","size":{"x":32,"y":1,"z":32}},{"blockCount":115,"bytes":3049,"file":"chunks/y083-z160-x032.json","offset":{"x":32,"y":83,"z":160},"requirements":{"minecraft:polished_diorite":81,"minecraft:stone_bricks":34},"sha256":"f5a653b7e8737f356652f10cb1181529f45fe33fb000cb22959d5e16ac1bf541","size":{"x":32,"y":1,"z":32}},{"blockCount":146,"bytes":3133,"file":"chunks/y083-z160-x064.json","offset":{"x":64,"y":83,"z":160},"requirements":{"minecraft:polished_diorite":96,"minecraft:stone_bricks":50},"sha256":"f72a23b356d1f8bf048b77b74b2d4a0fef01ed9dc4a2001b1d8443a5f4da75d7","size":{"x":32,"y":1,"z":32}},{"blockCount":145,"bytes":3999,"file":"chunks/y083-z160-x096.json","offset":{"x":96,"y":83,"z":160},"requirements":{"minecraft:bricks":34,"minecraft:polished_diorite":59,"minecraft:sandstone":7,"minecraft:stone_bricks":45},"sha256":"7f3f8cf4c44c9f5f34b0183c41de3bf6147d00a8314d1afc6b1bd57a1fb800e6","size":{"x":32,"y":1,"z":32}},{"blockCount":214,"bytes":4998,"file":"chunks/y083-z160-x128.json","offset":{"x":128,"y":83,"z":160},"requirements":{"minecraft:bricks":34,"minecraft:polished_diorite":98,"minecraft:sandstone":7,"minecraft:stone_bricks":75},"sha256":"6d3707855837c07440bbd8f7d58b7b3fef5cede525cc8266d69915fb9c7b6135","size":{"x":32,"y":1,"z":32}},{"blockCount":142,"bytes":3320,"file":"chunks/y083-z160-x160.json","offset":{"x":160,"y":83,"z":160},"requirements":{"minecraft:polished_diorite":103,"minecraft:stone_bricks":39},"sha256":"1b24db9ea0765e1e61356be37de1c62987fd9dc2e3aa07a0b8b35922787f4746","size":{"x":32,"y":1,"z":32}},{"blockCount":192,"bytes":4377,"file":"chunks/y083-z160-x192.json","offset":{"x":192,"y":83,"z":160},"requirements":{"minecraft:bricks":69,"minecraft:glass":12,"minecraft:polished_diorite":86,"minecraft:stone_bricks":25},"sha256":"7dfd6873771140d87d12fa5ca09b2689b05d9a61e951bc435b96370e09e6adfc","size":{"x":32,"y":1,"z":32}},{"blockCount":94,"bytes":3004,"file":"chunks/y083-z160-x224.json","offset":{"x":224,"y":83,"z":160},"requirements":{"minecraft:bricks":51,"minecraft:glass":12,"minecraft:polished_diorite":31},"sha256":"17bf5887be0c522b29177fdc9a8563eb7c6b5c4cb3579fc34182d45456433cb8","size":{"x":32,"y":1,"z":32}},{"blockCount":38,"bytes":1603,"file":"chunks/y083-z192-x064.json","offset":{"x":64,"y":83,"z":192},"requirements":{"minecraft:polished_diorite":32,"minecraft:stone_bricks":6},"sha256":"d59e58686bd7231f67bcf1badb739efe18aa6222235b743bd3df15b874f57d62","size":{"x":32,"y":1,"z":32}},{"blockCount":180,"bytes":4149,"file":"chunks/y083-z192-x096.json","offset":{"x":96,"y":83,"z":192},"requirements":{"minecraft:bricks":39,"minecraft:glass":15,"minecraft:oak_planks":1,"minecraft:polished_diorite":73,"minecraft:sandstone":11,"minecraft:stone_bricks":41},"sha256":"5e201cfad3a5ebe09adbfb439d0a99209046c59db5aa988d6ed42e1758a7f86f","size":{"x":32,"y":1,"z":32}},{"blockCount":160,"bytes":4000,"file":"chunks/y083-z192-x128.json","offset":{"x":128,"y":83,"z":192},"requirements":{"minecraft:bricks":31,"minecraft:glass":5,"minecraft:polished_diorite":81,"minecraft:sandstone":5,"minecraft:stone_bricks":38},"sha256":"8724ad4e3ffb258fb7efcb081d43e27122ead3272a70c0c9a72fa8f634f21672","size":{"x":32,"y":1,"z":32}},{"blockCount":6,"bytes":844,"file":"chunks/y083-z192-x160.json","offset":{"x":160,"y":83,"z":192},"requirements":{"minecraft:polished_diorite":6},"sha256":"a302bf0f6acd67cc10563e37202c6569db53ee6004ad09b09ea9d6d7572f3eeb","size":{"x":32,"y":1,"z":32}},{"blockCount":5,"bytes":720,"file":"chunks/y084-z000-x352.json","offset":{"x":352,"y":84,"z":0},"requirements":{"minecraft:stone_bricks":5},"sha256":"452a261b00771ba8d049e63e8266420202faa2e6bffd5d9172f9355c361d8ac1","size":{"x":32,"y":1,"z":32}},{"blockCount":43,"bytes":1909,"file":"chunks/y084-z064-x064.json","offset":{"x":64,"y":84,"z":64},"requirements":{"minecraft:polished_diorite":39,"minecraft:stone_bricks":4},"sha256":"3db1a4826a31ebe02ef057a6a82e24a0b97643e91e38219f8d5d30db1869d011","size":{"x":32,"y":1,"z":32}},{"blockCount":209,"bytes":4625,"file":"chunks/y084-z064-x096.json","offset":{"x":96,"y":84,"z":64},"requirements":{"minecraft:bricks":45,"minecraft:glass":18,"minecraft:polished_diorite":100,"minecraft:sandstone":9,"minecraft:stone_bricks":37},"sha256":"4cb041c62c7fa9f7518b4a00b00ea9fd3032a58d619c29728f019d002b6d96fb","size":{"x":32,"y":1,"z":32}},{"blockCount":186,"bytes":4899,"file":"chunks/y084-z064-x128.json","offset":{"x":128,"y":84,"z":64},"requirements":{"minecraft:bricks":37,"minecraft:glass":8,"minecraft:polished_diorite":104,"minecraft:sandstone":3,"minecraft:stone_bricks":34},"sha256":"b61046d31d39414c3703843a65e918d1a3df02275d70e42c364f137a2cf5b7dd","size":{"x":32,"y":1,"z":32}},{"blockCount":7,"bytes":881,"file":"chunks/y084-z064-x160.json","offset":{"x":160,"y":84,"z":64},"requirements":{"minecraft:polished_diorite":7},"sha256":"b5543125f4c7ad3c5275733c46f3e5c3d57f6843563c457afc39e3893a75a50b","size":{"x":32,"y":1,"z":32}},{"blockCount":9,"bytes":875,"file":"chunks/y084-z064-x192.json","offset":{"x":192,"y":84,"z":64},"requirements":{"minecraft:polished_diorite":9},"sha256":"e78d3f81b40b1bf8d0c975baec17fd0fc54df79cc50a0854c629efc6742c53e7","size":{"x":32,"y":1,"z":32}},{"blockCount":12,"bytes":915,"file":"chunks/y084-z064-x224.json","offset":{"x":224,"y":84,"z":64},"requirements":{"minecraft:polished_diorite":12},"sha256":"48cd8f0d587f3a625dc88de68d2f0c2f0bb8b0efa5adaffa575f83129482d048","size":{"x":32,"y":1,"z":32}},{"blockCount":39,"bytes":1886,"file":"chunks/y084-z096-x000.json","offset":{"x":0,"y":84,"z":96},"requirements":{"minecraft:polished_diorite":29,"minecraft:stone_bricks":10},"sha256":"2f06800d2637cb8f8a809cbae817ce075d6a0cf9114772cca48e7e08b0e25fb7","size":{"x":32,"y":1,"z":32}},{"blockCount":158,"bytes":4177,"file":"chunks/y084-z096-x032.json","offset":{"x":32,"y":84,"z":96},"requirements":{"minecraft:bricks":26,"minecraft:glass":4,"minecraft:polished_diorite":91,"minecraft:stone_bricks":37},"sha256":"8ed2150d5b148cd61333341c19e93d6b554c6cf4bd3e2f7df3e674d0aef9001d","size":{"x":32,"y":1,"z":32}},{"blockCount":165,"bytes":3701,"file":"chunks/y084-z096-x064.json","offset":{"x":64,"y":84,"z":96},"requirements":{"minecraft:bricks":34,"minecraft:glass":4,"minecraft:polished_diorite":89,"minecraft:stone_bricks":38},"sha256":"8e2c62c54560f2d10b4e3e200485b5b47a0a8a3a8e4f895b9aca16c26665af42","size":{"x":32,"y":1,"z":32}},{"blockCount":112,"bytes":3478,"file":"chunks/y084-z096-x096.json","offset":{"x":96,"y":84,"z":96},"requirements":{"minecraft:bricks":36,"minecraft:glass":6,"minecraft:polished_diorite":46,"minecraft:stone_bricks":24},"sha256":"4104f9005f132ed68b3ae2c3851d23b805f438752e96c3e9dbae92439e313024","size":{"x":32,"y":1,"z":32}},{"blockCount":181,"bytes":4622,"file":"chunks/y084-z096-x128.json","offset":{"x":128,"y":84,"z":96},"requirements":{"minecraft:bricks":52,"minecraft:glass":8,"minecraft:polished_diorite":79,"minecraft:stone_bricks":42},"sha256":"4b0bf89fb7dd9117e5cd60a942f6e4f2df0b8e32af8656959d512ffe6b14e216","size":{"x":32,"y":1,"z":32}},{"blockCount":178,"bytes":4040,"file":"chunks/y084-z096-x160.json","offset":{"x":160,"y":84,"z":96},"requirements":{"minecraft:bricks":34,"minecraft:glass":5,"minecraft:polished_diorite":102,"minecraft:stone_bricks":37},"sha256":"268aaacdf38b8fde0f5cda82ef7c3812019ef55b85d538388a419e4a99b7325c","size":{"x":32,"y":1,"z":32}},{"blockCount":236,"bytes":4814,"file":"chunks/y084-z096-x192.json","offset":{"x":192,"y":84,"z":96},"requirements":{"minecraft:bricks":109,"minecraft:glass":17,"minecraft:polished_diorite":77,"minecraft:stone_bricks":33},"sha256":"8e7a291e432796951ab75a8485c95aa9c426558c7c556aa65b65a4ad7895e585","size":{"x":32,"y":1,"z":32}},{"blockCount":128,"bytes":3517,"file":"chunks/y084-z096-x224.json","offset":{"x":224,"y":84,"z":96},"requirements":{"minecraft:bricks":67,"minecraft:glass":13,"minecraft:polished_diorite":43,"minecraft:sandstone":2,"minecraft:stone_bricks":3},"sha256":"50d02dcad7c7abb3d1273da6ef582fc96488d9af826575d3cbb4f8fbb3da5c4b","size":{"x":32,"y":1,"z":32}},{"blockCount":52,"bytes":2325,"file":"chunks/y084-z128-x000.json","offset":{"x":0,"y":84,"z":128},"requirements":{"minecraft:polished_diorite":38,"minecraft:stone_bricks":14},"sha256":"3bd2df3e601e5c1c872970387b09011735d96a9597a7609a6ba41f0247f67ee0","size":{"x":32,"y":1,"z":32}},{"blockCount":178,"bytes":4153,"file":"chunks/y084-z128-x032.json","offset":{"x":32,"y":84,"z":128},"requirements":{"minecraft:bricks":55,"minecraft:glass":8,"minecraft:oak_planks":1,"minecraft:polished_diorite":66,"minecraft:stone_bricks":48},"sha256":"cbd0e769f5f9f6bdf6f245c7e91ea4315ce9494f6686df9905c906854efe41a9","size":{"x":32,"y":1,"z":32}},{"blockCount":54,"bytes":1504,"file":"chunks/y084-z128-x064.json","offset":{"x":64,"y":84,"z":128},"requirements":{"minecraft:bricks":34,"minecraft:glass":4,"minecraft:stone_bricks":16},"sha256":"66924274db516f0eee9eb87eab58ad6b6068335d4745343269287bd59d5fc891","size":{"x":32,"y":1,"z":32}},{"blockCount":15,"bytes":970,"file":"chunks/y084-z128-x096.json","offset":{"x":96,"y":84,"z":128},"requirements":{"minecraft:bricks":9,"minecraft:glass":3,"minecraft:stone_bricks":3},"sha256":"31e6e63ab8de1d1f5fad7ca383418450b68a9f3b928b7c457ac02c73fa3e5dbf","size":{"x":32,"y":1,"z":32}},{"blockCount":40,"bytes":1314,"file":"chunks/y084-z128-x128.json","offset":{"x":128,"y":84,"z":128},"requirements":{"minecraft:bricks":25,"minecraft:glass":5,"minecraft:stone_bricks":10},"sha256":"7e34f4a3229172c4426c26bfbcc1a1a325491552fd6efede6da9b031d824b3f5","size":{"x":32,"y":1,"z":32}},{"blockCount":55,"bytes":1525,"file":"chunks/y084-z128-x160.json","offset":{"x":160,"y":84,"z":128},"requirements":{"minecraft:bricks":34,"minecraft:glass":5,"minecraft:stone_bricks":16},"sha256":"9f53001f4ef2cd6f4bef5d4cfb610602a242771db056bfe9a0d0fa201b981924","size":{"x":32,"y":1,"z":32}},{"blockCount":58,"bytes":1468,"file":"chunks/y084-z128-x192.json","offset":{"x":192,"y":84,"z":128},"requirements":{"minecraft:bricks":38,"minecraft:glass":5,"minecraft:stone_bricks":15},"sha256":"a5e4dde901de1f9dac082c2649291fa323dbbe63f84e988e76d34077a9355632","size":{"x":32,"y":1,"z":32}},{"blockCount":121,"bytes":3281,"file":"chunks/y084-z128-x224.json","offset":{"x":224,"y":84,"z":128},"requirements":{"minecraft:bricks":24,"minecraft:glass":19,"minecraft:polished_diorite":58,"minecraft:sandstone":10,"minecraft:stone_bricks":10},"sha256":"d9b3b327a1513fe87b96f80044fd12e80b4bab80eab5d4953de0890abe30a35d","size":{"x":32,"y":1,"z":32}},{"blockCount":24,"bytes":1406,"file":"chunks/y084-z160-x000.json","offset":{"x":0,"y":84,"z":160},"requirements":{"minecraft:polished_diorite":19,"minecraft:stone_bricks":5},"sha256":"d4b4e4faf58245240ba97a55272591aca86a09f0de6f540ae33b879c59f56dc7","size":{"x":32,"y":1,"z":32}},{"blockCount":99,"bytes":2799,"file":"chunks/y084-z160-x032.json","offset":{"x":32,"y":84,"z":160},"requirements":{"minecraft:polished_diorite":82,"minecraft:stone_bricks":17},"sha256":"bae63cd4254a642c95738ab111ae28801812c409b7bc1671aed233ed52a0b504","size":{"x":32,"y":1,"z":32}},{"blockCount":120,"bytes":2993,"file":"chunks/y084-z160-x064.json","offset":{"x":64,"y":84,"z":160},"requirements":{"minecraft:polished_diorite":96,"minecraft:stone_bricks":24},"sha256":"4da0cbd8b52e5d9ddca48bb915b546ecd94389d228d39dab2293986bca5d9c5c","size":{"x":32,"y":1,"z":32}},{"blockCount":129,"bytes":3982,"file":"chunks/y084-z160-x096.json","offset":{"x":96,"y":84,"z":160},"requirements":{"minecraft:bricks":34,"minecraft:glass":4,"minecraft:oak_planks":2,"minecraft:polished_diorite":59,"minecraft:stone_bricks":30},"sha256":"59a7cac3286d8dec221e299111fd3f43b7a38cade1b29214da9942d379763357","size":{"x":32,"y":1,"z":32}},{"blockCount":179,"bytes":4876,"file":"chunks/y084-z160-x128.json","offset":{"x":128,"y":84,"z":160},"requirements":{"minecraft:bricks":34,"minecraft:glass":4,"minecraft:polished_diorite":98,"minecraft:stone_bricks":43},"sha256":"1f5073f693ee750a0c8c0187e00797e9ff0787863a843a1346c4e11bc05b37d2","size":{"x":32,"y":1,"z":32}},{"blockCount":124,"bytes":3084,"file":"chunks/y084-z160-x160.json","offset":{"x":160,"y":84,"z":160},"requirements":{"minecraft:polished_diorite":103,"minecraft:stone_bricks":21},"sha256":"bd34564f3ac177f2a213225fdb4606295fe0752be905c19e3b6addc206e5fcf7","size":{"x":32,"y":1,"z":32}},{"blockCount":187,"bytes":4241,"file":"chunks/y084-z160-x192.json","offset":{"x":192,"y":84,"z":160},"requirements":{"minecraft:bricks":71,"minecraft:glass":12,"minecraft:polished_diorite":86,"minecraft:stone_bricks":18},"sha256":"c54a1248e62d456898e80df1c1738ececd9f1e5514214beea1e52a9c04e8ed5a","size":{"x":32,"y":1,"z":32}},{"blockCount":98,"bytes":3084,"file":"chunks/y084-z160-x224.json","offset":{"x":224,"y":84,"z":160},"requirements":{"minecraft:bricks":55,"minecraft:glass":12,"minecraft:polished_diorite":31},"sha256":"7f7d1bceead3dea7a9c6bf8fd30f73bc32d8a322303c6fb13f32cb3553093ae6","size":{"x":32,"y":1,"z":32}},{"blockCount":34,"bytes":1641,"file":"chunks/y084-z192-x064.json","offset":{"x":64,"y":84,"z":192},"requirements":{"minecraft:polished_diorite":32,"minecraft:stone_bricks":2},"sha256":"d050f63969c0e4f1503adc52145d8545af72cf52fad1043a1959cbbb714a8af2","size":{"x":32,"y":1,"z":32}},{"blockCount":180,"bytes":3978,"file":"chunks/y084-z192-x096.json","offset":{"x":96,"y":84,"z":192},"requirements":{"minecraft:bricks":38,"minecraft:glass":17,"minecraft:oak_planks":1,"minecraft:polished_diorite":87,"minecraft:sandstone":9,"minecraft:stone_bricks":28},"sha256":"1f7bec533450e8ce26e873e191a0a347d4c188dab44c83d10c9d803377812231","size":{"x":32,"y":1,"z":32}},{"blockCount":148,"bytes":4000,"file":"chunks/y084-z192-x128.json","offset":{"x":128,"y":84,"z":192},"requirements":{"minecraft:bricks":30,"minecraft:glass":7,"minecraft:polished_diorite":85,"minecraft:sandstone":3,"minecraft:stone_bricks":23},"sha256":"7701de7a5f87851bd79e447c604832f0087ec8e964cd95f5f98ab0d0226d6d7f","size":{"x":32,"y":1,"z":32}},{"blockCount":6,"bytes":844,"file":"chunks/y084-z192-x160.json","offset":{"x":160,"y":84,"z":192},"requirements":{"minecraft:polished_diorite":6},"sha256":"51ee6c995883eeacc0afec63a776c9b57e1b6fb2f2a3dda450ae245bd29c04cc","size":{"x":32,"y":1,"z":32}},{"blockCount":1,"bytes":642,"file":"chunks/y085-z000-x352.json","offset":{"x":352,"y":85,"z":0},"requirements":{"minecraft:stone_bricks":1},"sha256":"8de871116880ed5066a6ba733728edba4ae2ccf5bf13ffb6c0ea2d1af318ec77","size":{"x":32,"y":1,"z":32}},{"blockCount":43,"bytes":1902,"file":"chunks/y085-z064-x064.json","offset":{"x":64,"y":85,"z":64},"requirements":{"minecraft:glass":4,"minecraft:polished_diorite":39},"sha256":"ba2117bbf3b9a1b6c72a0e7c65654c046c4283297bed730090e2892f009b9320","size":{"x":32,"y":1,"z":32}},{"blockCount":199,"bytes":4661,"file":"chunks/y085-z064-x096.json","offset":{"x":96,"y":85,"z":64},"requirements":{"minecraft:bricks":44,"minecraft:glass":20,"minecraft:polished_diorite":90,"minecraft:sandstone":9,"minecraft:stone_bricks":36},"sha256":"564de13806b91ef5d5a0ea9b170e78e72463735f0dc0a7606af8c40c6f1bf981","size":{"x":32,"y":1,"z":32}},{"blockCount":190,"bytes":4976,"file":"chunks/y085-z064-x128.json","offset":{"x":128,"y":85,"z":64},"requirements":{"minecraft:bricks":37,"minecraft:glass":14,"minecraft:polished_diorite":108,"minecraft:sandstone":3,"minecraft:stone_bricks":28},"sha256":"172fe4182506cf50848699ebc25bcf2dd909db73352e36a383cb618ce5a58f24","size":{"x":32,"y":1,"z":32}},{"blockCount":7,"bytes":881,"file":"chunks/y085-z064-x160.json","offset":{"x":160,"y":85,"z":64},"requirements":{"minecraft:polished_diorite":7},"sha256":"d697c5feca9ca91a9096cf4961c74f21bdd2b83c348190dd0534699f8dff2d6d","size":{"x":32,"y":1,"z":32}},{"blockCount":9,"bytes":875,"file":"chunks/y085-z064-x192.json","offset":{"x":192,"y":85,"z":64},"requirements":{"minecraft:polished_diorite":9},"sha256":"4a4e2966c94ef965ae9b95ba957cdddd41a49c9f06154c9432ce0a00cff3fbca","size":{"x":32,"y":1,"z":32}},{"blockCount":12,"bytes":915,"file":"chunks/y085-z064-x224.json","offset":{"x":224,"y":85,"z":64},"requirements":{"minecraft:polished_diorite":12},"sha256":"7a791f8936b609f1b9cdc7540133a0e10b5a1924d65a8ecf73b57abd87cd60a4","size":{"x":32,"y":1,"z":32}},{"blockCount":39,"bytes":1879,"file":"chunks/y085-z096-x000.json","offset":{"x":0,"y":85,"z":96},"requirements":{"minecraft:glass":10,"minecraft:polished_diorite":29},"sha256":"e685c8e2a94a0d4f04e530727fc7690214e2e937dbbd23ed36797222f8a79460","size":{"x":32,"y":1,"z":32}},{"blockCount":171,"bytes":3781,"file":"chunks/y085-z096-x032.json","offset":{"x":32,"y":85,"z":96},"requirements":{"minecraft:bricks":28,"minecraft:glass":10,"minecraft:polished_diorite":107,"minecraft:stone_bricks":26},"sha256":"9c637d55c9819bf6f7bd4729690c610f07dfd33bf1ace1d1a36257b755859534","size":{"x":32,"y":1,"z":32}},{"blockCount":174,"bytes":3228,"file":"chunks/y085-z096-x064.json","offset":{"x":64,"y":85,"z":96},"requirements":{"minecraft:bricks":33,"minecraft:glass":12,"minecraft:polished_diorite":97,"minecraft:stone_bricks":32},"sha256":"282f1e2a2d69f15bd92489a6531243e90355371d21350ac9ba436336f0b35710","size":{"x":32,"y":1,"z":32}},{"blockCount":123,"bytes":3497,"file":"chunks/y085-z096-x096.json","offset":{"x":96,"y":85,"z":96},"requirements":{"minecraft:bricks":36,"minecraft:glass":8,"minecraft:polished_diorite":51,"minecraft:stone_bricks":28},"sha256":"79f649f6e168712e0b3a42c839ae5d5ca69a4c8fdd08a960dfe668ba68b94c9c","size":{"x":32,"y":1,"z":32}},{"blockCount":197,"bytes":4451,"file":"chunks/y085-z096-x128.json","offset":{"x":128,"y":85,"z":96},"requirements":{"minecraft:bricks":52,"minecraft:glass":15,"minecraft:polished_diorite":88,"minecraft:stone_bricks":42},"sha256":"3a1a33fedb15f5e69ef3e5c7ea2cf53079fd18817022ab2722f5b0d06d0146f0","size":{"x":32,"y":1,"z":32}},{"blockCount":187,"bytes":3549,"file":"chunks/y085-z096-x160.json","offset":{"x":160,"y":85,"z":96},"requirements":{"minecraft:bricks":34,"minecraft:glass":11,"minecraft:polished_diorite":110,"minecraft:stone_bricks":32},"sha256":"d8edcc7a8888cdd453ddaa474fed12407d322e931ef99c90d8d666fcee2d6df8","size":{"x":32,"y":1,"z":32}},{"blockCount":254,"bytes":4474,"file":"chunks/y085-z096-x192.json","offset":{"x":192,"y":85,"z":96},"requirements":{"minecraft:bricks":116,"minecraft:glass":20,"minecraft:polished_diorite":81,"minecraft:stone_bricks":37},"sha256":"7d6bca00ec3569f6e3208c099ede3d660655727053c73030386b1e7a4a68d31b","size":{"x":32,"y":1,"z":32}},{"blockCount":131,"bytes":3479,"file":"chunks/y085-z096-x224.json","offset":{"x":224,"y":85,"z":96},"requirements":{"minecraft:bricks":67,"minecraft:glass":13,"minecraft:polished_diorite":43,"minecraft:sandstone":2,"minecraft:stone_bricks":6},"sha256":"65047948e8bdb725baf1a23fa7ad795b41878313ce3758b5e08de3221559d279","size":{"x":32,"y":1,"z":32}},{"blockCount":52,"bytes":2318,"file":"chunks/y085-z128-x000.json","offset":{"x":0,"y":85,"z":128},"requirements":{"minecraft:glass":14,"minecraft:polished_diorite":38},"sha256":"1493cb7960cff93562a9751a63adb99cc9c43a52e367a1ed8a2113e3371515d4","size":{"x":32,"y":1,"z":32}},{"blockCount":213,"bytes":4158,"file":"chunks/y085-z128-x032.json","offset":{"x":32,"y":85,"z":128},"requirements":{"minecraft:bricks":54,"minecraft:glass":8,"minecraft:polished_diorite":102,"minecraft:spruce_planks":3,"minecraft:stone_bricks":46},"sha256":"b5ad73cad8c00e4167a8916020f093e43f0a3e9eec972ebc558fb7ba4c7e627f","size":{"x":32,"y":1,"z":32}},{"blockCount":63,"bytes":1182,"file":"chunks/y085-z128-x064.json","offset":{"x":64,"y":85,"z":128},"requirements":{"minecraft:bricks":33,"minecraft:glass":4,"minecraft:stone_bricks":26},"sha256":"ce4c3fbdccc6bb4732087d25545a5d4c727f7738caf717e48d612c520544f896","size":{"x":32,"y":1,"z":32}},{"blockCount":17,"bytes":913,"file":"chunks/y085-z128-x096.json","offset":{"x":96,"y":85,"z":128},"requirements":{"minecraft:bricks":9,"minecraft:glass":3,"minecraft:stone_bricks":5},"sha256":"1b929e9245de9d94107bcec55bcf044dca2bf2e02653382ee7ce06b3ce06004a","size":{"x":32,"y":1,"z":32}},{"blockCount":47,"bytes":1123,"file":"chunks/y085-z128-x128.json","offset":{"x":128,"y":85,"z":128},"requirements":{"minecraft:bricks":25,"minecraft:glass":5,"minecraft:stone_bricks":17},"sha256":"13bd2933636c000888a54a211b714363f2f17c6ee5df81389bed1934abc0f8fc","size":{"x":32,"y":1,"z":32}},{"blockCount":64,"bytes":1185,"file":"chunks/y085-z128-x160.json","offset":{"x":160,"y":85,"z":128},"requirements":{"minecraft:bricks":34,"minecraft:glass":5,"minecraft:stone_bricks":25},"sha256":"d8d725e69dc2a6141ec78978da480598bcaac2d726a79e63d6e770cf0bdfd09e","size":{"x":32,"y":1,"z":32}},{"blockCount":66,"bytes":1166,"file":"chunks/y085-z128-x192.json","offset":{"x":192,"y":85,"z":128},"requirements":{"minecraft:bricks":38,"minecraft:glass":5,"minecraft:stone_bricks":23},"sha256":"5b7dfc48c26787b17b7371b6e5188301cedeec41ce8fd9b20a69211171617dcd","size":{"x":32,"y":1,"z":32}},{"blockCount":107,"bytes":2901,"file":"chunks/y085-z128-x224.json","offset":{"x":224,"y":85,"z":128},"requirements":{"minecraft:bricks":24,"minecraft:glass":19,"minecraft:polished_diorite":40,"minecraft:sandstone":10,"minecraft:stone_bricks":14},"sha256":"e596123dcb2cf3584fc10ae5a0b65a1389768ce486b1aa38ef0b689204ce382c","size":{"x":32,"y":1,"z":32}},{"blockCount":24,"bytes":1399,"file":"chunks/y085-z160-x000.json","offset":{"x":0,"y":85,"z":160},"requirements":{"minecraft:glass":5,"minecraft:polished_diorite":19},"sha256":"ea2b20ed426d61103cfe478d4eab4a5dc4271ef67681a739ed7a8d28a2bef9ce","size":{"x":32,"y":1,"z":32}},{"blockCount":100,"bytes":2704,"file":"chunks/y085-z160-x032.json","offset":{"x":32,"y":85,"z":160},"requirements":{"minecraft:glass":6,"minecraft:polished_diorite":89,"minecraft:stone_bricks":5},"sha256":"d9b17052af5f42556f1f2da5156c24b2b47ada338dc6dab70c8806b7f2755b2b","size":{"x":32,"y":1,"z":32}},{"blockCount":120,"bytes":2862,"file":"chunks/y085-z160-x064.json","offset":{"x":64,"y":85,"z":160},"requirements":{"minecraft:glass":10,"minecraft:polished_diorite":104,"minecraft:stone_bricks":6},"sha256":"1dd6655726cf946e4b502c6afbae761b24393859956246575827c7b4751d6d8f","size":{"x":32,"y":1,"z":32}},{"blockCount":164,"bytes":4781,"file":"chunks/y085-z160-x096.json","offset":{"x":96,"y":85,"z":160},"requirements":{"minecraft:bricks":34,"minecraft:glass":7,"minecraft:oak_planks":26,"minecraft:polished_diorite":66,"minecraft:stone_bricks":31},"sha256":"01b2fcd5ee1a1f607ed77236a45d87ca65d8a2f9674d9cc150586927e8359fb4","size":{"x":32,"y":1,"z":32}},{"blockCount":190,"bytes":4897,"file":"chunks/y085-z160-x128.json","offset":{"x":128,"y":85,"z":160},"requirements":{"minecraft:bricks":34,"minecraft:glass":14,"minecraft:polished_diorite":109,"minecraft:stone_bricks":33},"sha256":"536c5d3eecca209e9efa364b0b804088da603e9ef06e2debc6d2bd307bf80d5f","size":{"x":32,"y":1,"z":32}},{"blockCount":124,"bytes":2951,"file":"chunks/y085-z160-x160.json","offset":{"x":160,"y":85,"z":160},"requirements":{"minecraft:glass":6,"minecraft:polished_diorite":111,"minecraft:stone_bricks":7},"sha256":"df1009bccdc0a92d7c2a28b7849fabd9a1dea51c9f5fe28bf95a76c94dd1b1d4","size":{"x":32,"y":1,"z":32}},{"blockCount":197,"bytes":4221,"file":"chunks/y085-z160-x192.json","offset":{"x":192,"y":85,"z":160},"requirements":{"minecraft:bricks":78,"minecraft:glass":15,"minecraft:polished_diorite":90,"minecraft:stone_bricks":14},"sha256":"7f139f59b814d84a2964d266ae0811e109e2b1fa3dca5c4c3de5985909b4a6bb","size":{"x":32,"y":1,"z":32}},{"blockCount":98,"bytes":3084,"file":"chunks/y085-z160-x224.json","offset":{"x":224,"y":85,"z":160},"requirements":{"minecraft:bricks":55,"minecraft:glass":12,"minecraft:polished_diorite":31},"sha256":"43dd47498b1eecb87d7cd571419d20829d84db0a814ec93732b3b2e4a26dc8a6","size":{"x":32,"y":1,"z":32}},{"blockCount":34,"bytes":1634,"file":"chunks/y085-z192-x064.json","offset":{"x":64,"y":85,"z":192},"requirements":{"minecraft:glass":2,"minecraft:polished_diorite":32},"sha256":"e2ad61ab1c396ea31903c06c42ff937b9ee08e2d5973ef6c2db49b7964f2f8ee","size":{"x":32,"y":1,"z":32}},{"blockCount":178,"bytes":4263,"file":"chunks/y085-z192-x096.json","offset":{"x":96,"y":85,"z":192},"requirements":{"minecraft:bricks":38,"minecraft:glass":18,"minecraft:oak_planks":10,"minecraft:polished_diorite":75,"minecraft:sandstone":9,"minecraft:stone_bricks":28},"sha256":"bcd0cd46690a469b32119e2b5e108cc0ca80a86f3714ec38d627e47ebc674c28","size":{"x":32,"y":1,"z":32}},{"blockCount":150,"bytes":4039,"file":"chunks/y085-z192-x128.json","offset":{"x":128,"y":85,"z":192},"requirements":{"minecraft:bricks":30,"minecraft:glass":10,"minecraft:polished_diorite":87,"minecraft:sandstone":3,"minecraft:stone_bricks":20},"sha256":"4e51e696c01b8c5e002ff2d2d42654d2554aceebce80feb167c6a00e2b4123e3","size":{"x":32,"y":1,"z":32}},{"blockCount":6,"bytes":844,"file":"chunks/y085-z192-x160.json","offset":{"x":160,"y":85,"z":192},"requirements":{"minecraft:polished_diorite":6},"sha256":"62030b5ddfee9821fc4c60dd4e945f6aec1329c429d0e2ea0da709e84d8fb523","size":{"x":32,"y":1,"z":32}},{"blockCount":1,"bytes":642,"file":"chunks/y086-z000-x352.json","offset":{"x":352,"y":86,"z":0},"requirements":{"minecraft:stone_bricks":1},"sha256":"03ce873e8ad0c4d7d5487cbf86ce24e2c57f8191b654f1256805f5aef4af2203","size":{"x":32,"y":1,"z":32}},{"blockCount":39,"bytes":1726,"file":"chunks/y086-z064-x064.json","offset":{"x":64,"y":86,"z":64},"requirements":{"minecraft:polished_diorite":39},"sha256":"b74a2fff1a5d255a9412b4601f2c3c36f0a503f84f79dc04cdd5fc2e4ad4aa5a","size":{"x":32,"y":1,"z":32}},{"blockCount":192,"bytes":4396,"file":"chunks/y086-z064-x096.json","offset":{"x":96,"y":86,"z":64},"requirements":{"minecraft:bricks":28,"minecraft:glass":18,"minecraft:polished_diorite":92,"minecraft:sandstone":27,"minecraft:stone_bricks":27},"sha256":"7ca4793a7bc011bbabd664f067c6cbc1db4df0c386435f7907281542f3c2b32e","size":{"x":32,"y":1,"z":32}},{"blockCount":177,"bytes":4577,"file":"chunks/y086-z064-x128.json","offset":{"x":128,"y":86,"z":64},"requirements":{"minecraft:bricks":19,"minecraft:glass":8,"minecraft:polished_diorite":110,"minecraft:sandstone":21,"minecraft:stone_bricks":19},"sha256":"6df02be3d6c5da66fece370e04d548331cb86138242a80d6545b24c403e0dfe8","size":{"x":32,"y":1,"z":32}},{"blockCount":7,"bytes":881,"file":"chunks/y086-z064-x160.json","offset":{"x":160,"y":86,"z":64},"requirements":{"minecraft:polished_diorite":7},"sha256":"b23889087302a956ea94fba7bf3101f4b7a6cc1aab464f7746ecc7b0f9ca471d","size":{"x":32,"y":1,"z":32}},{"blockCount":9,"bytes":875,"file":"chunks/y086-z064-x192.json","offset":{"x":192,"y":86,"z":64},"requirements":{"minecraft:polished_diorite":9},"sha256":"46b01d09479babefeba039d3d495976e56cd9aba8c5a58e11fcaf5e6d371297c","size":{"x":32,"y":1,"z":32}},{"blockCount":12,"bytes":915,"file":"chunks/y086-z064-x224.json","offset":{"x":224,"y":86,"z":64},"requirements":{"minecraft:polished_diorite":12},"sha256":"411429dcc7c07b492cc3c5fb10c6e0347c6a499cc619b7de6c4ea62929ac7adc","size":{"x":32,"y":1,"z":32}},{"blockCount":29,"bytes":1476,"file":"chunks/y086-z096-x000.json","offset":{"x":0,"y":86,"z":96},"requirements":{"minecraft:polished_diorite":29},"sha256":"bb17bb987eb4b66a87347356a29dc40219cf71cdcc49fbf14fb2440e06bc563f","size":{"x":32,"y":1,"z":32}},{"blockCount":169,"bytes":3536,"file":"chunks/y086-z096-x032.json","offset":{"x":32,"y":86,"z":96},"requirements":{"minecraft:bricks":11,"minecraft:glass":4,"minecraft:polished_diorite":123,"minecraft:sandstone":11,"minecraft:stone_bricks":20},"sha256":"56a2956210e708e913752fd73b18d0ff83d7e94b099a1eb6707b286697e78a2d","size":{"x":32,"y":1,"z":32}},{"blockCount":156,"bytes":3188,"file":"chunks/y086-z096-x064.json","offset":{"x":64,"y":86,"z":96},"requirements":{"minecraft:bricks":15,"minecraft:glass":4,"minecraft:polished_diorite":99,"minecraft:sandstone":19,"minecraft:stone_bricks":19},"sha256":"d4e91037f16f7ab4ab8cbe8e0b10a806b4ed7dcb1d19419f3df4111c10903a55","size":{"x":32,"y":1,"z":32}},{"blockCount":108,"bytes":3370,"file":"chunks/y086-z096-x096.json","offset":{"x":96,"y":86,"z":96},"requirements":{"minecraft:bricks":22,"minecraft:glass":6,"minecraft:polished_diorite":52,"minecraft:sandstone":14,"minecraft:stone_bricks":14},"sha256":"c6084343ef000373537ba4ff2d5c31329778b3e55313fd008e9ed9cae432978d","size":{"x":32,"y":1,"z":32}},{"blockCount":173,"bytes":4302,"file":"chunks/y086-z096-x128.json","offset":{"x":128,"y":86,"z":96},"requirements":{"minecraft:bricks":31,"minecraft:glass":8,"minecraft:polished_diorite":90,"minecraft:sandstone":22,"minecraft:stone_bricks":22},"sha256":"c8b737be50b9a525a2ed6f9884d10619ec8f77f15e1a0b44c0c4ee9235dab179","size":{"x":32,"y":1,"z":32}},{"blockCount":171,"bytes":3604,"file":"chunks/y086-z096-x160.json","offset":{"x":160,"y":86,"z":96},"requirements":{"minecraft:bricks":14,"minecraft:glass":5,"minecraft:polished_diorite":112,"minecraft:sandstone":20,"minecraft:stone_bricks":20},"sha256":"1c9e69499f86b10357b8c483177afbe57b9fc6da2dae687e85b0ed9b6c9dd98d","size":{"x":32,"y":1,"z":32}},{"blockCount":231,"bytes":4778,"file":"chunks/y086-z096-x192.json","offset":{"x":192,"y":86,"z":96},"requirements":{"minecraft:bricks":102,"minecraft:glass":17,"minecraft:polished_diorite":82,"minecraft:sandstone":12,"minecraft:stone_bricks":18},"sha256":"a1986cc996d4d8ae4af5600703e6f24a49f0a129268f70e062108e2828bcb24e","size":{"x":32,"y":1,"z":32}},{"blockCount":130,"bytes":3517,"file":"chunks/y086-z096-x224.json","offset":{"x":224,"y":86,"z":96},"requirements":{"minecraft:bricks":67,"minecraft:glass":13,"minecraft:polished_diorite":43,"minecraft:sandstone":2,"minecraft:stone_bricks":5},"sha256":"9fb0e8bb02a35133dcc070fdfc3921e5a8c84e6a0b078ab4076579154c0f0e0f","size":{"x":32,"y":1,"z":32}},{"blockCount":40,"bytes":1760,"file":"chunks/y086-z128-x000.json","offset":{"x":0,"y":86,"z":128},"requirements":{"minecraft:polished_diorite":40},"sha256":"96bccc78dd5de5a898bf2d0e5787041f2a9f3875844313be72fd508941a4f01f","size":{"x":32,"y":1,"z":32}},{"blockCount":215,"bytes":4129,"file":"chunks/y086-z128-x032.json","offset":{"x":32,"y":86,"z":128},"requirements":{"minecraft:bricks":21,"minecraft:glass":8,"minecraft:oak_planks":4,"minecraft:polished_diorite":133,"minecraft:sandstone":24,"minecraft:spruce_planks":2,"minecraft:stone_bricks":23},"sha256":"32a28e0c1741211b181a9bcb2a67fd74b9da49b3a1be836bd397207c7d7048db","size":{"x":32,"y":1,"z":32}},{"blockCount":45,"bytes":1526,"file":"chunks/y086-z128-x064.json","offset":{"x":64,"y":86,"z":128},"requirements":{"minecraft:bricks":15,"minecraft:glass":4,"minecraft:sandstone":19,"minecraft:stone_bricks":7},"sha256":"e16a635983da870adc52bfbf5043dd74f94f2b5cdeb76f84c284debce555cb47","size":{"x":32,"y":1,"z":32}},{"blockCount":14,"bytes":1051,"file":"chunks/y086-z128-x096.json","offset":{"x":96,"y":86,"z":128},"requirements":{"minecraft:bricks":7,"minecraft:glass":3,"minecraft:sandstone":2,"minecraft:stone_bricks":2},"sha256":"c80a203c340345260ce3cf8edb5063d4ecd518ffb88d111bd5493d50cad70426","size":{"x":32,"y":1,"z":32}},{"blockCount":35,"bytes":1452,"file":"chunks/y086-z128-x128.json","offset":{"x":128,"y":86,"z":128},"requirements":{"minecraft:bricks":15,"minecraft:glass":5,"minecraft:sandstone":10,"minecraft:stone_bricks":5},"sha256":"52da5ae5188162fae2f58d33c0798eebec01af40bd546e9f025ca1808f37c0eb","size":{"x":32,"y":1,"z":32}},{"blockCount":46,"bytes":1585,"file":"chunks/y086-z128-x160.json","offset":{"x":160,"y":86,"z":128},"requirements":{"minecraft:bricks":14,"minecraft:glass":5,"minecraft:sandstone":20,"minecraft:stone_bricks":7},"sha256":"0e1e208eaa37ee8c2da83835a7c2c0e8d7354c9faaabc96dd6d9a628f736747b","size":{"x":32,"y":1,"z":32}},{"blockCount":50,"bytes":1547,"file":"chunks/y086-z128-x192.json","offset":{"x":192,"y":86,"z":128},"requirements":{"minecraft:bricks":27,"minecraft:glass":5,"minecraft:sandstone":12,"minecraft:stone_bricks":6},"sha256":"4a0f29480142aa4b6fc52fa21c6cb3cf7595d20c479fc2c85c99da33f487404b","size":{"x":32,"y":1,"z":32}},{"blockCount":106,"bytes":2939,"file":"chunks/y086-z128-x224.json","offset":{"x":224,"y":86,"z":128},"requirements":{"minecraft:bricks":24,"minecraft:glass":19,"minecraft:polished_diorite":40,"minecraft:sandstone":10,"minecraft:stone_bricks":13},"sha256":"447ccf4d822f975d066e37840ed7441fd5455934f797d8f0d470fe58ace23b2c","size":{"x":32,"y":1,"z":32}},{"blockCount":19,"bytes":1188,"file":"chunks/y086-z160-x000.json","offset":{"x":0,"y":86,"z":160},"requirements":{"minecraft:polished_diorite":19},"sha256":"78a203244573451ecc4a262ea6aa7fa11708094b670524524f68e48d9197fc5e","size":{"x":32,"y":1,"z":32}},{"blockCount":101,"bytes":2399,"file":"chunks/y086-z160-x032.json","offset":{"x":32,"y":86,"z":160},"requirements":{"minecraft:polished_diorite":95,"minecraft:stone_bricks":6},"sha256":"c73dc1c6f9c6bf3b23795210c2ae328841f4bac41d3795b463d83508f89481e4","size":{"x":32,"y":1,"z":32}},{"blockCount":118,"bytes":2383,"file":"chunks/y086-z160-x064.json","offset":{"x":64,"y":86,"z":160},"requirements":{"minecraft:polished_diorite":106,"minecraft:stone_bricks":12},"sha256":"aa3c2bd60f8795660e88542ba7fc1c7894836c12d9966e94e47e01c166000217","size":{"x":32,"y":1,"z":32}},{"blockCount":142,"bytes":4173,"file":"chunks/y086-z160-x096.json","offset":{"x":96,"y":86,"z":160},"requirements":{"minecraft:bricks":19,"minecraft:glass":19,"minecraft:polished_diorite":68,"minecraft:sandstone":17,"minecraft:stone_bricks":19},"sha256":"b851965d6e4531af3febeb33338e20e3ddf5efa39b4a5f083371600ab8e27841","size":{"x":32,"y":1,"z":32}},{"blockCount":172,"bytes":4292,"file":"chunks/y086-z160-x128.json","offset":{"x":128,"y":86,"z":160},"requirements":{"minecraft:bricks":17,"minecraft:glass":4,"minecraft:polished_diorite":112,"minecraft:sandstone":17,"minecraft:stone_bricks":22},"sha256":"c2f8e71b9c349f709b1b9ab0e4864e3d7c5df493076dbaed24f2128662deef73","size":{"x":32,"y":1,"z":32}},{"blockCount":126,"bytes":2625,"file":"chunks/y086-z160-x160.json","offset":{"x":160,"y":86,"z":160},"requirements":{"minecraft:polished_diorite":113,"minecraft:stone_bricks":13},"sha256":"8b6ac2512b16d2a8e7f5c51d095f5fceb5141ff95a7214f2a00e79b1d908622d","size":{"x":32,"y":1,"z":32}},{"blockCount":190,"bytes":4143,"file":"chunks/y086-z160-x192.json","offset":{"x":192,"y":86,"z":160},"requirements":{"minecraft:bricks":75,"minecraft:glass":12,"minecraft:polished_diorite":91,"minecraft:stone_bricks":12},"sha256":"6b9e949a45d1f650460ce760fdda5bddc4ca6c78fe022d444ef462e381587e2f","size":{"x":32,"y":1,"z":32}},{"blockCount":98,"bytes":3084,"file":"chunks/y086-z160-x224.json","offset":{"x":224,"y":86,"z":160},"requirements":{"minecraft:bricks":55,"minecraft:glass":12,"minecraft:polished_diorite":31},"sha256":"63c14b4a3758f5509ec44ab04b668276c206b43ec22f633085e79d3169387918","size":{"x":32,"y":1,"z":32}},{"blockCount":32,"bytes":1536,"file":"chunks/y086-z192-x064.json","offset":{"x":64,"y":86,"z":192},"requirements":{"minecraft:polished_diorite":32},"sha256":"52ce1a85913656d10abc0650945467fc6eea6ea1e0e42c1ca94daae521f237ce","size":{"x":32,"y":1,"z":32}},{"blockCount":169,"bytes":4067,"file":"chunks/y086-z192-x096.json","offset":{"x":96,"y":86,"z":192},"requirements":{"minecraft:bricks":24,"minecraft:glass":23,"minecraft:polished_diorite":76,"minecraft:sandstone":22,"minecraft:stone_bricks":24},"sha256":"a2dd2f1d69615904a073c30c6d9145ad5e4c45314835ac093e01e57f5fed95eb","size":{"x":32,"y":1,"z":32}},{"blockCount":143,"bytes":3792,"file":"chunks/y086-z192-x128.json","offset":{"x":128,"y":86,"z":192},"requirements":{"minecraft:bricks":18,"minecraft:glass":7,"minecraft:polished_diorite":88,"minecraft:sandstone":16,"minecraft:stone_bricks":14},"sha256":"136f656bbfc0013650fd7fe8a878457f2d1fd92df62f48dda1f93c4f78e6289e","size":{"x":32,"y":1,"z":32}},{"blockCount":6,"bytes":844,"file":"chunks/y086-z192-x160.json","offset":{"x":160,"y":86,"z":192},"requirements":{"minecraft:polished_diorite":6},"sha256":"0608d522141a75397fdbe8967382e3ec58ab83d07a707078b9d57a79c61c358a","size":{"x":32,"y":1,"z":32}},{"blockCount":1,"bytes":642,"file":"chunks/y087-z000-x352.json","offset":{"x":352,"y":87,"z":0},"requirements":{"minecraft:stone_bricks":1},"sha256":"3ddf7aa06bf415c85f881a2f4d4bcdccb56f00d650730ae72cc0ea601bd69e8f","size":{"x":32,"y":1,"z":32}},{"blockCount":39,"bytes":1726,"file":"chunks/y087-z064-x064.json","offset":{"x":64,"y":87,"z":64},"requirements":{"minecraft:polished_diorite":39},"sha256":"c742c5e8089245ccb2a38530deb92585eabb832820d30c5d678708a33ad51625","size":{"x":32,"y":1,"z":32}},{"blockCount":168,"bytes":4592,"file":"chunks/y087-z064-x096.json","offset":{"x":96,"y":87,"z":64},"requirements":{"minecraft:bricks":27,"minecraft:glass":44,"minecraft:oak_planks":1,"minecraft:polished_diorite":62,"minecraft:sandstone":15,"minecraft:stone_bricks":19},"sha256":"a6469ac40705a59ff6f84191c7a22942d98e2d3334ce396021d0b69388321bb5","size":{"x":32,"y":1,"z":32}}],"schema":1}
