{"entries":[{"blockCount":155,"bytes":4772,"file":"chunks/y087-z064-x128.json","offset":{"x":128,"y":87,"z":64},"requirements":{"minecraft:bricks":18,"minecraft:glass":34,"minecraft:oak_planks":1,"minecraft:polished_diorite":80,"minecraft:sandstone":9,"minecraft:stone_bricks":13},"sha256":"3a0caeae3446d887fee87b457ad5b4187f5623bff45a69be3e2632d702ccfd82","size":{"x":32,"y":1,"z":32}},{"blockCount":7,"bytes":881,"file":"chunks/y087-z064-x160.json","offset":{"x":160,"y":87,"z":64},"requirements":{"minecraft:polished_diorite":7},"sha256":"fcbe30b892fe1dbbd7244887034319fe2b25697a3c8a65fd35e0476bc07a6473","size":{"x":32,"y":1,"z":32}},{"blockCount":9,"bytes":902,"file":"chunks/y087-z064-x192.json","offset":{"x":192,"y":87,"z":64},"requirements":{"minecraft:polished_diorite":7,"minecraft:stone_bricks":2},"sha256":"3073cfa65112bace9e3857c9ee5ab4ca023d4411abdb1263f67f95c0ebdfec3f","size":{"x":32,"y":1,"z":32}},{"blockCount":12,"bytes":942,"file":"chunks/y087-z064-x224.json","offset":{"x":224,"y":87,"z":64},"requirements":{"minecraft:polished_diorite":10,"minecraft:stone_bricks":2},"sha256":"c479c7fa904bac8339f3e54447953cf8074de26ed6bda0d9456e190a162df885","size":{"x":32,"y":1,"z":32}},{"blockCount":30,"bytes":1476,"file":"chunks/y087-z096-x000.json","offset":{"x":0,"y":87,"z":96},"requirements":{"minecraft:polished_diorite":30},"sha256":"9993fc54175547c4f6cc58080ab75b13e5c410c5a055b5935251f9fb581cbc1d","size":{"x":32,"y":1,"z":32}},{"blockCount":151,"bytes":4143,"file":"chunks/y087-z096-x032.json","offset":{"x":32,"y":87,"z":96},"requirements":{"minecraft:bricks":11,"minecraft:glass":38,"minecraft:polished_diorite":83,"minecraft:sandstone":9,"minecraft:stone_bricks":10},"sha256":"50d67fac15f1e41d6c2c38b41247d1645d510d6259c82d8da2eca82cc3078a19","size":{"x":32,"y":1,"z":32}},{"blockCount":135,"bytes":3644,"file":"chunks/y087-z096-x064.json","offset":{"x":64,"y":87,"z":96},"requirements":{"minecraft:bricks":16,"minecraft:glass":30,"minecraft:polished_diorite":69,"minecraft:sandstone":6,"minecraft:stone_bricks":14},"sha256":"7148c6b5f87af6c0a92bb91bbea0847aca9fbf447f9fe756b43b7180823d87ff","size":{"x":32,"y":1,"z":32}},{"blockCount":100,"bytes":3465,"file":"chunks/y087-z096-x096.json","offset":{"x":96,"y":87,"z":96},"requirements":{"minecraft:bricks":27,"minecraft:glass":19,"minecraft:polished_diorite":37,"minecraft:sandstone":3,"minecraft:stone_bricks":14},"sha256":"1a591e82443a657760119525c5bbc060d784505e7256fbcd9c7f555644bf7a4f","size":{"x":32,"y":1,"z":32}},{"blockCount":157,"bytes":4511,"file":"chunks/y087-z096-x128.json","offset":{"x":128,"y":87,"z":96},"requirements":{"minecraft:bricks":37,"minecraft:glass":32,"minecraft:polished_diorite":62,"minecraft:sandstone":5,"minecraft:stone_bricks":21},"sha256":"0f811dc7f7d31f5937fd307624a1bf084359b0790066d4048420c15d7e0af6ce","size":{"x":32,"y":1,"z":32}},{"blockCount":147,"bytes":4078,"file":"chunks/y087-z096-x160.json","offset":{"x":160,"y":87,"z":96},"requirements":{"minecraft:bricks":14,"minecraft:glass":33,"minecraft:polished_diorite":80,"minecraft:sandstone":7,"minecraft:stone_bricks":13},"sha256":"733ecb525f1cb0fc4b3930452ee87b33bd7ded9126a87a64918742a27adee4ad","size":{"x":32,"y":1,"z":32}},{"blockCount":223,"bytes":4911,"file":"chunks/y087-z096-x192.json","offset":{"x":192,"y":87,"z":96},"requirements":{"minecraft:bricks":106,"minecraft:glass":30,"minecraft:polished_diorite":63,"minecraft:sandstone":3,"minecraft:stone_bricks":21},"sha256":"625d396ab2d5a7dc9a18968c9b069fb1da9e56b0f4e61ec858743f84d425e2fa","size":{"x":32,"y":1,"z":32}},{"blockCount":126,"bytes":3479,"file":"chunks/y087-z096-x224.json","offset":{"x":224,"y":87,"z":96},"requirements":{"minecraft:bricks":67,"minecraft:glass":13,"minecraft:polished_diorite":39,"minecraft:sandstone":2,"minecraft:stone_bricks":5},"sha256":"d939aec247f26ca020f689731ad05a7280662e9a756e7f4b58b90b2a87ebb331","size":{"x":32,"y":1,"z":32}},{"blockCount":47,"bytes":1787,"file":"chunks/y087-z128-x000.json","offset":{"x":0,"y":87,"z":128},"requirements":{"minecraft:polished_diorite":45,"minecraft:stone_bricks":2},"sha256":"43901ae651a1cd7a0f900848083eb551b1028fcd2b744a100e50a93c55a4d23e","size":{"x":32,"y":1,"z":32}},{"blockCount":169,"bytes":5155,"file":"chunks/y087-z128-x032.json","offset":{"x":32,"y":87,"z":128},"requirements":{"minecraft:bricks":21,"minecraft:glass":58,"minecraft:oak_planks":7,"minecraft:polished_diorite":52,"minecraft:sandstone":17,"minecraft:spruce_planks":1,"minecraft:stone_bricks":13},"sha256":"7501821187830c8c7433cd1db671847a6b2c9d1dc9872c87e3ca27a76a123c2e","size":{"x":32,"y":1,"z":32}},{"blockCount":46,"bytes":1659,"file":"chunks/y087-z128-x064.json","offset":{"x":64,"y":87,"z":128},"requirements":{"minecraft:bricks":16,"minecraft:glass":16,"minecraft:sandstone":6,"minecraft:stone_bricks":8},"sha256":"46dc5ec54f736c672581c93e17401d8ccafb2b30f3fbb2718119c0e96bc30b2b","size":{"x":32,"y":1,"z":32}},{"blockCount":15,"bytes":1008,"file":"chunks/y087-z128-x096.json","offset":{"x":96,"y":87,"z":128},"requirements":{"minecraft:bricks":9,"minecraft:glass":3,"minecraft:stone_bricks":3},"sha256":"71d2f24ba3ef275c9019e64a1dc92a338816a4fa217a49d1940dc4dcb5bebdd7","size":{"x":32,"y":1,"z":32}},{"blockCount":37,"bytes":1471,"file":"chunks/y087-z128-x128.json","offset":{"x":128,"y":87,"z":128},"requirements":{"minecraft:bricks":18,"minecraft:glass":10,"minecraft:sandstone":2,"minecraft:stone_bricks":7},"sha256":"5af7efcc7c94a587c87e3ac3204261f10be6aa1e9dac1af1a034ce07379dfced","size":{"x":32,"y":1,"z":32}},{"blockCount":46,"bytes":1756,"file":"chunks/y087-z128-x160.json","offset":{"x":160,"y":87,"z":128},"requirements":{"minecraft:bricks":14,"minecraft:glass":18,"minecraft:sandstone":7,"minecraft:stone_bricks":7},"sha256":"4dde278ee374eda32f685b6e79b6f5f2042cb40f686faea19d4de424da8d8b66","size":{"x":32,"y":1,"z":32}},{"blockCount":50,"bytes":1510,"file":"chunks/y087-z128-x192.json","offset":{"x":192,"y":87,"z":128},"requirements":{"minecraft:bricks":30,"minecraft:glass":11,"minecraft:sandstone":3,"minecraft:stone_bricks":6},"sha256":"e58f123864b9fc6fecfe9a791de2c3e765c4d8f75af06115e9beb149ac5f0f59","size":{"x":32,"y":1,"z":32}},{"blockCount":100,"bytes":2824,"file":"chunks/y087-z128-x224.json","offset":{"x":224,"y":87,"z":128},"requirements":{"minecraft:bricks":24,"minecraft:glass":19,"minecraft:polished_diorite":40,"minecraft:sandstone":10,"minecraft:stone_bricks":7},"sha256":"cd05df7f0da2401dc10b18eaeb165ba937a70301a4cdd93badd9840a33295910","size":{"x":32,"y":1,"z":32}},{"blockCount":19,"bytes":1188,"file":"chunks/y087-z160-x000.json","offset":{"x":0,"y":87,"z":160},"requirements":{"minecraft:polished_diorite":19},"sha256":"16b58f12ced72bd82eef3fe896b1e15e35e1058e3e2dc925621f7f0cbf7306f3","size":{"x":32,"y":1,"z":32}},{"blockCount":92,"bytes":2667,"file":"chunks/y087-z160-x032.json","offset":{"x":32,"y":87,"z":160},"requirements":{"minecraft:glass":12,"minecraft:polished_diorite":76,"minecraft:stone_bricks":4},"sha256":"a1adca2ad77fb5aae05e600b8134bf74db3a04ee736746d0b8a6d7102ba0122c","size":{"x":32,"y":1,"z":32}},{"blockCount":96,"bytes":2706,"file":"chunks/y087-z160-x064.json","offset":{"x":64,"y":87,"z":160},"requirements":{"minecraft:glass":14,"minecraft:polished_diorite":76,"minecraft:stone_bricks":6},"sha256":"f9f2c1afe0194c2f8d5549cb251669d0a3497e9ee9736e846e37badc3e8f6150","size":{"x":32,"y":1,"z":32}},{"blockCount":112,"bytes":3830,"file":"chunks/y087-z160-x096.json","offset":{"x":96,"y":87,"z":160},"requirements":{"minecraft:bricks":22,"minecraft:glass":26,"minecraft:polished_diorite":44,"minecraft:sandstone":5,"minecraft:stone_bricks":15},"sha256":"4033a2ced71ae31dd4a24274c3c52a34828d2e051f8aa296ae2357decba4641b","size":{"x":32,"y":1,"z":32}},{"blockCount":148,"bytes":4538,"file":"chunks/y087-z160-x128.json","offset":{"x":128,"y":87,"z":160},"requirements":{"minecraft:bricks":20,"minecraft:glass":30,"minecraft:polished_diorite":75,"minecraft:sandstone":5,"minecraft:stone_bricks":18},"sha256":"abf5a262973944743a9dbb13ce242f608c8420d719773f6782d5b5b0305d6741","size":{"x":32,"y":1,"z":32}},{"blockCount":102,"bytes":3005,"file":"chunks/y087-z160-x160.json","offset":{"x":160,"y":87,"z":160},"requirements":{"minecraft:glass":15,"minecraft:polished_diorite":81,"minecraft:stone_bricks":6},"sha256":"cc4373fa753c7b813de84f0c02987a61a84f13bd1fcbadaaaa3e1ff8766a1adf","size":{"x":32,"y":1,"z":32}},{"blockCount":182,"bytes":4314,"file":"chunks/y087-z160-x192.json","offset":{"x":192,"y":87,"z":160},"requirements":{"minecraft:bricks":76,"minecraft:glass":19,"minecraft:polished_diorite":70,"minecraft:stone_bricks":17},"sha256":"046f88780832aba72bb9171336cca8d9bf52db05d0996c1443f548df78ac5108","size":{"x":32,"y":1,"z":32}},{"blockCount":98,"bytes":3111,"file":"chunks/y087-z160-x224.json","offset":{"x":224,"y":87,"z":160},"requirements":{"minecraft:bricks":55,"minecraft:glass":12,"minecraft:polished_diorite":25,"minecraft:stone_bricks":6},"sha256":"1fc40f5ebc5df140aaa0e07a4a2b317466f848f0a0f20e7124ee7eb5df0e86fc","size":{"x":32,"y":1,"z":32}},{"blockCount":32,"bytes":1536,"file":"chunks/y087-z192-x064.json","offset":{"x":64,"y":87,"z":192},"requirements":{"minecraft:polished_diorite":32},"sha256":"18e45404e5026d24466b618c86d9ece6490aba647438a8eb2e97e4745ffc6751","size":{"x":32,"y":1,"z":32}},{"blockCount":145,"bytes":4035,"file":"chunks/y087-z192-x096.json","offset":{"x":96,"y":87,"z":192},"requirements":{"minecraft:bricks":23,"minecraft:glass":38,"minecraft:oak_planks":1,"minecraft:polished_diorite":55,"minecraft:sandstone":13,"minecraft:stone_bricks":15},"sha256":"07a1f6b5b4fb7bdd777d155c3d0c645c76b0f56861da7d1bddecff2c39201c82","size":{"x":32,"y":1,"z":32}},{"blockCount":127,"bytes":3930,"file":"chunks/y087-z192-x128.json","offset":{"x":128,"y":87,"z":192},"requirements":{"minecraft:bricks":17,"minecraft:glass":26,"minecraft:oak_planks":1,"minecraft:polished_diorite":67,"minecraft:sandstone":7,"minecraft:stone_bricks":9},"sha256":"2e585673a44f13c25641354d5a493d8142269bc52700aab6018f14421c7ef8dd","size":{"x":32,"y":1,"z":32}},{"blockCount":6,"bytes":844,"file":"chunks/y087-z192-x160.json","offset":{"x":160,"y":87,"z":192},"requirements":{"minecraft:polished_diorite":6},"sha256":"3cc3ee47c5388aa6ae0a338281f39ad9ebb520c5ed71c51be011d59452e06618","size":{"x":32,"y":1,"z":32}},{"blockCount":1,"bytes":642,"file":"chunks/y088-z000-x352.json","offset":{"x":352,"y":88,"z":0},"requirements":{"minecraft:stone_bricks":1},"sha256":"fc5f9d1c62392dd301143dfe5b40dc243f8531ae05fe663de7237f5649884177","size":{"x":32,"y":1,"z":32}},{"blockCount":39,"bytes":1754,"file":"chunks/y088-z064-x064.json","offset":{"x":64,"y":88,"z":64},"requirements":{"minecraft:polished_diorite":29,"minecraft:stone_bricks":10},"sha256":"7c670df3712af5f38bcb87e3a15b5b7812fce14bf9d1832797168bf154d80a86","size":{"x":32,"y":1,"z":32}},{"blockCount":175,"bytes":4555,"file":"chunks/y088-z064-x096.json","offset":{"x":96,"y":88,"z":64},"requirements":{"minecraft:bricks":23,"minecraft:glass":44,"minecraft:oak_planks":1,"minecraft:polished_diorite":65,"minecraft:sandstone":20,"minecraft:stone_bricks":22},"sha256":"c379b18b26a1fc24551bfd6850daaefb46a116e4f59114d85eb62db74559b40f","size":{"x":32,"y":1,"z":32}},{"blockCount":160,"bytes":4754,"file":"chunks/y088-z064-x128.json","offset":{"x":128,"y":88,"z":64},"requirements":{"minecraft:bricks":17,"minecraft:glass":34,"minecraft:oak_planks":1,"minecraft:polished_diorite":69,"minecraft:sandstone":10,"minecraft:stone_bricks":29},"sha256":"68ced6576a8fa4c2183fe32b044d7d8c7598ab3cb446fbf3317d6c2f883a89b8","size":{"x":32,"y":1,"z":32}},{"blockCount":7,"bytes":881,"file":"chunks/y088-z064-x160.json","offset":{"x":160,"y":88,"z":64},"requirements":{"minecraft:polished_diorite":7},"sha256":"e44e9bf6acf4ce1202e3129dfc1ea835a4ea29b3bb495989fd46464b4b352c78","size":{"x":32,"y":1,"z":32}},{"blockCount":9,"bytes":902,"file":"chunks/y088-z064-x192.json","offset":{"x":192,"y":88,"z":64},"requirements":{"minecraft:polished_diorite":6,"minecraft:stone_bricks":3},"sha256":"1e9e9ca92dca9f41a881d39ea5a8575e8b862d1f33817214efbae1bdca5958c9","size":{"x":32,"y":1,"z":32}},{"blockCount":12,"bytes":941,"file":"chunks/y088-z064-x224.json","offset":{"x":224,"y":88,"z":64},"requirements":{"minecraft:polished_diorite":9,"minecraft:stone_bricks":3},"sha256":"bb6b87f3cdcfb4a6008e01c3c8acbeed20dc819d541f48ebf0e42ea9478cca7a","size":{"x":32,"y":1,"z":32}},{"blockCount":30,"bytes":1541,"file":"chunks/y088-z096-x000.json","offset":{"x":0,"y":88,"z":96},"requirements":{"minecraft:polished_diorite":24,"minecraft:stone_bricks":6},"sha256":"0c2ee13c7cd3534369c4c0957fc7f259911dc6552bc7c3117fb42be695a472ca","size":{"x":32,"y":1,"z":32}},{"blockCount":146,"bytes":4047,"file":"chunks/y088-z096-x032.json","offset":{"x":32,"y":88,"z":96},"requirements":{"minecraft:bricks":11,"minecraft:glass":38,"minecraft:polished_diorite":69,"minecraft:sandstone":5,"minecraft:stone_bricks":23},"sha256":"0a93695290b3232ada32544d319d884d8a7a855671311e87977a30a9727708d7","size":{"x":32,"y":1,"z":32}},{"blockCount":138,"bytes":3644,"file":"chunks/y088-z096-x064.json","offset":{"x":64,"y":88,"z":96},"requirements":{"minecraft:bricks":16,"minecraft:glass":30,"minecraft:polished_diorite":60,"minecraft:sandstone":6,"minecraft:stone_bricks":26},"sha256":"b3b5aa861ccf27220e937687083fcfae8e742e028aa587c06dc9bb8aabfd1730","size":{"x":32,"y":1,"z":32}},{"blockCount":104,"bytes":3465,"file":"chunks/y088-z096-x096.json","offset":{"x":96,"y":88,"z":96},"requirements":{"minecraft:bricks":27,"minecraft:glass":19,"minecraft:polished_diorite":38,"minecraft:sandstone":3,"minecraft:stone_bricks":17},"sha256":"39e6aacc9cf75e37081d4de87778444b8d5cff0e6c34b67c3326faaf0351fa2f","size":{"x":32,"y":1,"z":32}},{"blockCount":164,"bytes":4473,"file":"chunks/y088-z096-x128.json","offset":{"x":128,"y":88,"z":96},"requirements":{"minecraft:bricks":37,"minecraft:glass":32,"minecraft:polished_diorite":62,"minecraft:sandstone":5,"minecraft:stone_bricks":28},"sha256":"6b2342d3e87812b281a6be77361fff8c3bc9834227f73459c9838bb47c385380","size":{"x":32,"y":1,"z":32}},{"blockCount":147,"bytes":4078,"file":"chunks/y088-z096-x160.json","offset":{"x":160,"y":88,"z":96},"requirements":{"minecraft:bricks":14,"minecraft:glass":33,"minecraft:polished_diorite":67,"minecraft:sandstone":7,"minecraft:stone_bricks":26},"sha256":"d7f818aa4240d5dc239ec308d711fd6575b80a318650e6d904346d7d253fcd4f","size":{"x":32,"y":1,"z":32}},{"blockCount":232,"bytes":4930,"file":"chunks/y088-z096-x192.json","offset":{"x":192,"y":88,"z":96},"requirements":{"minecraft:bricks":112,"minecraft:glass":30,"minecraft:polished_diorite":51,"minecraft:sandstone":3,"minecraft:stone_bricks":36},"sha256":"ec277a2758277608e869ecde20d460a14c3c0b245a8bf39e1c1fc7ab14d20784","size":{"x":32,"y":1,"z":32}},{"blockCount":131,"bytes":3441,"file":"chunks/y088-z096-x224.json","offset":{"x":224,"y":88,"z":96},"requirements":{"minecraft:bricks":66,"minecraft:glass":13,"minecraft:polished_diorite":42,"minecraft:sandstone":3,"minecraft:stone_bricks":7},"sha256":"8da7252ea51fd632f7af5b015306ebc16944715f82b45639358aa3e293af9459","size":{"x":32,"y":1,"z":32}},{"blockCount":45,"bytes":1977,"file":"chunks/y088-z128-x000.json","offset":{"x":0,"y":88,"z":128},"requirements":{"minecraft:polished_diorite":37,"minecraft:stone_bricks":8},"sha256":"7feb7a712aa5d7d2105fd33c53679351ac33797d0eaf04ba96557ca459d86c13","size":{"x":32,"y":1,"z":32}},{"blockCount":161,"bytes":4918,"file":"chunks/y088-z128-x032.json","offset":{"x":32,"y":88,"z":128},"requirements":{"minecraft:bricks":21,"minecraft:glass":58,"minecraft:oak_planks":2,"minecraft:polished_diorite":48,"minecraft:sandstone":13,"minecraft:stone_bricks":19},"sha256":"08525fa30e3f19895016ed495272af01cae54e43773babc23957614701bdfa86","size":{"x":32,"y":1,"z":32}},{"blockCount":46,"bytes":1640,"file":"chunks/y088-z128-x064.json","offset":{"x":64,"y":88,"z":128},"requirements":{"minecraft:bricks":16,"minecraft:glass":16,"minecraft:sandstone":6,"minecraft:stone_bricks":8},"sha256":"072fff5ba9b1b26da1d17c93da44b9c7e66afd1d327ff36b22fd621ff87e0b43","size":{"x":32,"y":1,"z":32}},{"blockCount":15,"bytes":970,"file":"chunks/y088-z128-x096.json","offset":{"x":96,"y":88,"z":128},"requirements":{"minecraft:bricks":9,"minecraft:glass":3,"minecraft:stone_bricks":3},"sha256":"014f27d0f4c290b30aa7230722677d4258140deb4544051fde50f1542366918d","size":{"x":32,"y":1,"z":32}},{"blockCount":37,"bytes":1395,"file":"chunks/y088-z128-x128.json","offset":{"x":128,"y":88,"z":128},"requirements":{"minecraft:bricks":18,"minecraft:glass":10,"minecraft:sandstone":2,"minecraft:stone_bricks":7},"sha256":"bb9de6e5b9e397b1b1606ff61f417f72cbe75624d9afcde48fa9d3405e9ad3ca","size":{"x":32,"y":1,"z":32}},{"blockCount":46,"bytes":1756,"file":"chunks/y088-z128-x160.json","offset":{"x":160,"y":88,"z":128},"requirements":{"minecraft:bricks":14,"minecraft:glass":18,"minecraft:sandstone":7,"minecraft:stone_bricks":7},"sha256":"2a5bfa8b71583ec3669c5cb84ae15577ff93511b156c0b4a2dd4d0a7f5620ca1","size":{"x":32,"y":1,"z":32}},{"blockCount":54,"bytes":1586,"file":"chunks/y088-z128-x192.json","offset":{"x":192,"y":88,"z":128},"requirements":{"minecraft:bricks":35,"minecraft:glass":11,"minecraft:sandstone":3,"minecraft:stone_bricks":5},"sha256":"e5079201672dbd43074eac7f21f805a097c6fe09506b4d64bdff39b03ef069f6","size":{"x":32,"y":1,"z":32}},{"blockCount":115,"bytes":3033,"file":"chunks/y088-z128-x224.json","offset":{"x":224,"y":88,"z":128},"requirements":{"minecraft:bricks":19,"minecraft:glass":19,"minecraft:polished_diorite":55,"minecraft:sandstone":16,"minecraft:stone_bricks":6},"sha256":"48dd206c52bed110eac8fdd82f6a7e2d08926653a450b80897cdb37b78af5cc6","size":{"x":32,"y":1,"z":32}},{"blockCount":19,"bytes":1215,"file":"chunks/y088-z160-x000.json","offset":{"x":0,"y":88,"z":160},"requirements":{"minecraft:polished_diorite":15,"minecraft:stone_bricks":4},"sha256":"8ab7663f7bf645664e03e9679679d6951e6ad96dfa4e8bbe6c8154027d73e928","size":{"x":32,"y":1,"z":32}},{"blockCount":91,"bytes":2629,"file":"chunks/y088-z160-x032.json","offset":{"x":32,"y":88,"z":160},"requirements":{"minecraft:glass":12,"minecraft:polished_diorite":63,"minecraft:stone_bricks":16},"sha256":"27037173cc2677a4b907678ac5c2266533bb71e75a870f7e676c5cb535d61150","size":{"x":32,"y":1,"z":32}},{"blockCount":99,"bytes":2745,"file":"chunks/y088-z160-x064.json","offset":{"x":64,"y":88,"z":160},"requirements":{"minecraft:glass":14,"minecraft:polished_diorite":62,"minecraft:stone_bricks":23},"sha256":"118db95281c76f2e73acdfe0d6d453358c39e26d3023a44847a7fd0ccddb6d2b","size":{"x":32,"y":1,"z":32}},{"blockCount":116,"bytes":3906,"file":"chunks/y088-z160-x096.json","offset":{"x":96,"y":88,"z":160},"requirements":{"minecraft:bricks":22,"minecraft:glass":26,"minecraft:polished_diorite":41,"minecraft:sandstone":5,"minecraft:stone_bricks":22},"sha256":"915ed184a90238a24cb10e7e1a4ebac3feb67e7acb21a960e4a15939244ba112","size":{"x":32,"y":1,"z":32}},{"blockCount":155,"bytes":4614,"file":"chunks/y088-z160-x128.json","offset":{"x":128,"y":88,"z":160},"requirements":{"minecraft:bricks":20,"minecraft:glass":30,"minecraft:polished_diorite":66,"minecraft:sandstone":5,"minecraft:stone_bricks":34},"sha256":"4b19dc0e27bcff5de8041ed77ca84affe373827bdf97d4942fbdc54e2f4ad653","size":{"x":32,"y":1,"z":32}},{"blockCount":102,"bytes":3006,"file":"chunks/y088-z160-x160.json","offset":{"x":160,"y":88,"z":160},"requirements":{"minecraft:glass":15,"minecraft:polished_diorite":68,"minecraft:stone_bricks":19},"sha256":"10b2aa454bf6f58a4288feef79ab84a71015216eaaaa5882812bd0faa57bc697","size":{"x":32,"y":1,"z":32}},{"blockCount":186,"bytes":4257,"file":"chunks/y088-z160-x192.json","offset":{"x":192,"y":88,"z":160},"requirements":{"minecraft:bricks":77,"minecraft:glass":19,"minecraft:polished_diorite":56,"minecraft:stone_bricks":34},"sha256":"2116b98b877eee9731603d74f285c2981ef7f965a7f03c06965ad95cdb99f060","size":{"x":32,"y":1,"z":32}},{"blockCount":98,"bytes":3111,"file":"chunks/y088-z160-x224.json","offset":{"x":224,"y":88,"z":160},"requirements":{"minecraft:bricks":55,"minecraft:glass":12,"minecraft:polished_diorite":24,"minecraft:stone_bricks":7},"sha256":"2e05cc1a9f477a53c7ab2d047fed4576be4519c72c79c530bda66d46686c12d1","size":{"x":32,"y":1,"z":32}},{"blockCount":32,"bytes":1563,"file":"chunks/y088-z192-x064.json","offset":{"x":64,"y":88,"z":192},"requirements":{"minecraft:polished_diorite":24,"minecraft:stone_bricks":8},"sha256":"fb10fa8e8d977bf53e7e896101713b1aa1e6a60dc8843e69e461a5b904f4cc95","size":{"x":32,"y":1,"z":32}},{"blockCount":149,"bytes":3998,"file":"chunks/y088-z192-x096.json","offset":{"x":96,"y":88,"z":192},"requirements":{"minecraft:bricks":20,"minecraft:glass":38,"minecraft:oak_planks":1,"minecraft:polished_diorite":57,"minecraft:sandstone":16,"minecraft:stone_bricks":17},"sha256":"44d950eb127fc1530ac09fe363564301bbf3e0895f778b103d636d83b3a29e58","size":{"x":32,"y":1,"z":32}},{"blockCount":129,"bytes":3931,"file":"chunks/y088-z192-x128.json","offset":{"x":128,"y":88,"z":192},"requirements":{"minecraft:bricks":15,"minecraft:glass":26,"minecraft:oak_planks":1,"minecraft:polished_diorite":57,"minecraft:sandstone":8,"minecraft:stone_bricks":22},"sha256":"ff88b5dfcdf7f2e0715273073f763a1ee5ff0f8adb846b1ee0451e1584f6f642","size":{"x":32,"y":1,"z":32}},{"blockCount":6,"bytes":844,"file":"chunks/y088-z192-x160.json","offset":{"x":160,"y":88,"z":192},"requirements":{"minecraft:polished_diorite":6},"sha256":"1ae64422308646fbf6c8c0445254a73bea3fad39222f6425b7b050b24beb4a62","size":{"x":32,"y":1,"z":32}},{"blockCount":1,"bytes":642,"file":"chunks/y089-z000-x352.json","offset":{"x":352,"y":89,"z":0},"requirements":{"minecraft:stone_bricks":1},"sha256":"91bf4602c7d8a5785fc5a914751d0912556cf0db70c78b1868bd39d2cd86475f","size":{"x":32,"y":1,"z":32}},{"blockCount":45,"bytes":1726,"file":"chunks/y089-z064-x064.json","offset":{"x":64,"y":89,"z":64},"requirements":{"minecraft:polished_diorite":45},"sha256":"187c47afc426ea80fc54ae5500cf8d433e4770a811991293b1f169b6becf6a66","size":{"x":32,"y":1,"z":32}},{"blockCount":152,"bytes":4364,"file":"chunks/y089-z064-x096.json","offset":{"x":96,"y":89,"z":64},"requirements":{"minecraft:bricks":27,"minecraft:glass":36,"minecraft:oak_planks":1,"minecraft:polished_diorite":57,"minecraft:sandstone":15,"minecraft:stone_bricks":16},"sha256":"f02c5429e8e171cc392470e586fc2b13f8ef83648392f8cae0d19bdb09feeddf","size":{"x":32,"y":1,"z":32}},{"blockCount":149,"bytes":4468,"file":"chunks/y089-z064-x128.json","offset":{"x":128,"y":89,"z":64},"requirements":{"minecraft:bricks":18,"minecraft:glass":26,"minecraft:oak_planks":1,"minecraft:polished_diorite":84,"minecraft:sandstone":9,"minecraft:stone_bricks":11},"sha256":"d639d06b4f7b5003d512e2cf402ea4fce89feeba81229a36e3006bd5f1244d41","size":{"x":32,"y":1,"z":32}},{"blockCount":11,"bytes":882,"file":"chunks/y089-z064-x160.json","offset":{"x":160,"y":89,"z":64},"requirements":{"minecraft:polished_diorite":11},"sha256":"54824caf1c4f5ff0e044f8443b1e9e7b88882e73c719d72a116c2b06580fc805","size":{"x":32,"y":1,"z":32}},{"blockCount":9,"bytes":875,"file":"chunks/y089-z064-x192.json","offset":{"x":192,"y":89,"z":64},"requirements":{"minecraft:polished_diorite":9},"sha256":"186e296d563dbc3cd8223112585283d01f5d8a2cadb0397f65912b81bdb6b3d1","size":{"x":32,"y":1,"z":32}},{"blockCount":12,"bytes":915,"file":"chunks/y089-z064-x224.json","offset":{"x":224,"y":89,"z":64},"requirements":{"minecraft:polished_diorite":12},"sha256":"138f0ca36c342409b7a779b34cc35047c7819ad29da5c0818758625d7ba7bbb1","size":{"x":32,"y":1,"z":32}},{"blockCount":31,"bytes":1514,"file":"chunks/y089-z096-x000.json","offset":{"x":0,"y":89,"z":96},"requirements":{"minecraft:polished_diorite":31},"sha256":"fa0be0f71ea6ab992b20c9309c6a274b3fce0922539982558761de2cf0b95dc4","size":{"x":32,"y":1,"z":32}},{"blockCount":143,"bytes":4430,"file":"chunks/y089-z096-x032.json","offset":{"x":32,"y":89,"z":96},"requirements":{"minecraft:bricks":11,"minecraft:glass":27,"minecraft:polished_diorite":93,"minecraft:sandstone":5,"minecraft:stone_bricks":7},"sha256":"6126adaefeff8e316e6c6f9bc3807d0df79e9e127b90f9b4ad52f2bc39fe487b","size":{"x":32,"y":1,"z":32}},{"blockCount":135,"bytes":3930,"file":"chunks/y089-z096-x064.json","offset":{"x":64,"y":89,"z":96},"requirements":{"minecraft:bricks":17,"minecraft:glass":22,"minecraft:polished_diorite":77,"minecraft:sandstone":6,"minecraft:stone_bricks":13},"sha256":"13916f537dcc8be0b34a37616672d3ad0386c60954a294b97fce39299375c60c","size":{"x":32,"y":1,"z":32}},{"blockCount":102,"bytes":3256,"file":"chunks/y089-z096-x096.json","offset":{"x":96,"y":89,"z":96},"requirements":{"minecraft:bricks":30,"minecraft:glass":15,"minecraft:polished_diorite":38,"minecraft:sandstone":3,"minecraft:stone_bricks":16},"sha256":"7e4de5a017f44468b663ea36e6e2f688117fc87ddc97bd2e6f7a4d3201f21ad4","size":{"x":32,"y":1,"z":32}},{"blockCount":159,"bytes":4302,"file":"chunks/y089-z096-x128.json","offset":{"x":128,"y":89,"z":96},"requirements":{"minecraft:bricks":41,"minecraft:glass":25,"minecraft:polished_diorite":65,"minecraft:sandstone":5,"minecraft:stone_bricks":23},"sha256":"1cb85fb253d818964c3d165a357ce2af2122017ce171a20949b7f9eb0973eb89","size":{"x":32,"y":1,"z":32}},{"blockCount":146,"bytes":4520,"file":"chunks/y089-z096-x160.json","offset":{"x":160,"y":89,"z":96},"requirements":{"minecraft:bricks":14,"minecraft:glass":24,"minecraft:polished_diorite":90,"minecraft:sandstone":7,"minecraft:stone_bricks":11},"sha256":"85a0ca8884df0fe37b154d1309281968b019e093976d97e4714725113dd2c919","size":{"x":32,"y":1,"z":32}},{"blockCount":228,"bytes":5006,"file":"chunks/y089-z096-x192.json","offset":{"x":192,"y":89,"z":96},"requirements":{"minecraft:bricks":114,"minecraft:glass":26,"minecraft:polished_diorite":74,"minecraft:sandstone":3,"minecraft:stone_bricks":11},"sha256":"88445f8d54c25d8b9eef71d9a69c26d4f3f403f4be21c7638e6ee1a01fce0cfc","size":{"x":32,"y":1,"z":32}},{"blockCount":126,"bytes":3479,"file":"chunks/y089-z096-x224.json","offset":{"x":224,"y":89,"z":96},"requirements":{"minecraft:bricks":67,"minecraft:glass":13,"minecraft:polished_diorite":43,"minecraft:sandstone":2,"minecraft:stone_bricks":1},"sha256":"f3d91d491e8a24c9cde6818aaabea1e85f9665b0bcc6bdc80d07ed6c82983e2e","size":{"x":32,"y":1,"z":32}},{"blockCount":52,"bytes":1949,"file":"chunks/y089-z128-x000.json","offset":{"x":0,"y":89,"z":128},"requirements":{"minecraft:polished_diorite":52},"sha256":"d5f05057ed94e13f7e4ed6fedd6f15fe5d9af12845e6b03c3c96c2d732531768","size":{"x":32,"y":1,"z":32}},{"blockCount":132,"bytes":4173,"file":"chunks/y089-z128-x032.json","offset":{"x":32,"y":89,"z":128},"requirements":{"minecraft:bricks":21,"minecraft:glass":43,"minecraft:polished_diorite":44,"minecraft:sandstone":13,"minecraft:stone_bricks":11},"sha256":"bf09beaaa7491ea66bc27f8a559e5d3217efc28d0d347d193b72ae7e9da8c274","size":{"x":32,"y":1,"z":32}},{"blockCount":48,"bytes":1602,"file":"chunks/y089-z128-x064.json","offset":{"x":64,"y":89,"z":128},"requirements":{"minecraft:bricks":17,"minecraft:glass":16,"minecraft:sandstone":6,"minecraft:stone_bricks":9},"sha256":"64cc390f806afdb66136a8968a8d17b1f05dd823bf4f76623cccb431d9ef01ff","size":{"x":32,"y":1,"z":32}},{"blockCount":17,"bytes":914,"file":"chunks/y089-z128-x096.json","offset":{"x":96,"y":89,"z":128},"requirements":{"minecraft:bricks":10,"minecraft:glass":3,"minecraft:stone_bricks":4},"sha256":"f9dfbb750cfcff57545cc02da433325b551a9700c5d65e06804a207a3ddbacc9","size":{"x":32,"y":1,"z":32}},{"blockCount":41,"bytes":1281,"file":"chunks/y089-z128-x128.json","offset":{"x":128,"y":89,"z":128},"requirements":{"minecraft:bricks":20,"minecraft:glass":10,"minecraft:sandstone":2,"minecraft:stone_bricks":9},"sha256":"641a027ee60ee27298a16b881f31774812c37832e450e3cd54a676b268961929","size":{"x":32,"y":1,"z":32}},{"blockCount":46,"bytes":1756,"file":"chunks/y089-z128-x160.json","offset":{"x":160,"y":89,"z":128},"requirements":{"minecraft:bricks":14,"minecraft:glass":18,"minecraft:sandstone":7,"minecraft:stone_bricks":7},"sha256":"4714817c752cedbfdcf3c8360655138860ff08de8a9327e8eaf7b20d5469ffa3","size":{"x":32,"y":1,"z":32}},{"blockCount":56,"bytes":1434,"file":"chunks/y089-z128-x192.json","offset":{"x":192,"y":89,"z":128},"requirements":{"minecraft:bricks":39,"minecraft:glass":11,"minecraft:sandstone":3,"minecraft:stone_bricks":3},"sha256":"7f68612676198eedc939b138c52d298aa061329347a465f4f040544594568a2d","size":{"x":32,"y":1,"z":32}},{"blockCount":92,"bytes":2729,"file":"chunks/y089-z128-x224.json","offset":{"x":224,"y":89,"z":128},"requirements":{"minecraft:bricks":24,"minecraft:glass":19,"minecraft:polished_diorite":33,"minecraft:sandstone":10,"minecraft:stone_bricks":6},"sha256":"5e9b05214865953e71e768264d6fefbcbea0be31a3ce6fc8cfc58ff8c2630cbf","size":{"x":32,"y":1,"z":32}},{"blockCount":19,"bytes":1188,"file":"chunks/y089-z160-x000.json","offset":{"x":0,"y":89,"z":160},"requirements":{"minecraft:polished_diorite":19},"sha256":"2dd93bfaa6492cd981a0c4f9110cff028619818fd7a8ca4f7e41980ae1dfbc83","size":{"x":32,"y":1,"z":32}},{"blockCount":93,"bytes":3050,"file":"chunks/y089-z160-x032.json","offset":{"x":32,"y":89,"z":160},"requirements":{"minecraft:glass":6,"minecraft:polished_diorite":85,"minecraft:stone_bricks":2},"sha256":"44adfb5a75fdc54d2ea9d3d0ab8a67c95afe348750e135a5e1b3e6feaffa430b","size":{"x":32,"y":1,"z":32}},{"blockCount":94,"bytes":3048,"file":"chunks/y089-z160-x064.json","offset":{"x":64,"y":89,"z":160},"requirements":{"minecraft:glass":6,"minecraft:polished_diorite":84,"minecraft:stone_bricks":4},"sha256":"ba0aa6018386825e877861b72802d3c2452ea82ddea96a4b533bac11feb848b1","size":{"x":32,"y":1,"z":32}},{"blockCount":110,"bytes":3640,"file":"chunks/y089-z160-x096.json","offset":{"x":96,"y":89,"z":160},"requirements":{"minecraft:bricks":24,"minecraft:glass":20,"minecraft:polished_diorite":46,"minecraft:sandstone":5,"minecraft:stone_bricks":15},"sha256":"cd9eed344aaec726e69fd4abf3235e3266b77217fcfd7ce5a6518458eac7db6f","size":{"x":32,"y":1,"z":32}},{"blockCount":144,"bytes":4443,"file":"chunks/y089-z160-x128.json","offset":{"x":128,"y":89,"z":160},"requirements":{"minecraft:bricks":22,"minecraft:glass":21,"minecraft:polished_diorite":79,"minecraft:sandstone":5,"minecraft:stone_bricks":17},"sha256":"eaffbd2cbacc1a2231041532176754534bf13d0aeda8cb2390128e08ab5964cd","size":{"x":32,"y":1,"z":32}},{"blockCount":101,"bytes":3446,"file":"chunks/y089-z160-x160.json","offset":{"x":160,"y":89,"z":160},"requirements":{"minecraft:glass":6,"minecraft:polished_diorite":91,"minecraft:stone_bricks":4},"sha256":"fd08f590e1377db67d0511b27a8d5b23d63b91886adfe65f097dc05d60dcefc3","size":{"x":32,"y":1,"z":32}},{"blockCount":181,"bytes":4504,"file":"chunks/y089-z160-x192.json","offset":{"x":192,"y":89,"z":160},"requirements":{"minecraft:bricks":75,"minecraft:glass":15,"minecraft:polished_diorite":83,"minecraft:stone_bricks":8},"sha256":"3fcb78c08fd252d8d89956369c8cabf246d685fef0d08eb03b44bd8d3c8d936d","size":{"x":32,"y":1,"z":32}},{"blockCount":98,"bytes":3084,"file":"chunks/y089-z160-x224.json","offset":{"x":224,"y":89,"z":160},"requirements":{"minecraft:bricks":55,"minecraft:glass":12,"minecraft:polished_diorite":31},"sha256":"545abae70197c839a6480e2d6b8331da94d86d7fbf97ef44b6eab3fd9ea60ca4","size":{"x":32,"y":1,"z":32}},{"blockCount":38,"bytes":1536,"file":"chunks/y089-z192-x064.json","offset":{"x":64,"y":89,"z":192},"requirements":{"minecraft:polished_diorite":38},"sha256":"68e433bba3885c7ae7a5ded70689e1ac242488214c478614c3c48a8ef52dbace","size":{"x":32,"y":1,"z":32}},{"blockCount":130,"bytes":3845,"file":"chunks/y089-z192-x096.json","offset":{"x":96,"y":89,"z":192},"requirements":{"minecraft:bricks":23,"minecraft:glass":31,"minecraft:oak_planks":1,"minecraft:polished_diorite":49,"minecraft:sandstone":13,"minecraft:stone_bricks":13},"sha256":"101265f6c7c49fe9a83398d39f8150b46bdf11ae7ed302bda70f1348d5ecd0b5","size":{"x":32,"y":1,"z":32}},{"blockCount":123,"bytes":3702,"file":"chunks/y089-z192-x128.json","offset":{"x":128,"y":89,"z":192},"requirements":{"minecraft:bricks":17,"minecraft:glass":20,"minecraft:oak_planks":1,"minecraft:polished_diorite":70,"minecraft:sandstone":7,"minecraft:stone_bricks":8},"sha256":"161000ab1f769e2899766c258ead622f51d362428f5767f975cdce3acdd093d4","size":{"x":32,"y":1,"z":32}},{"blockCount":10,"bytes":845,"file":"chunks/y089-z192-x160.json","offset":{"x":160,"y":89,"z":192},"requirements":{"minecraft:polished_diorite":10},"sha256":"a08d0eedd64e222a1fdd771c50daa8ad0d32cd4d5538bff05a3f3e1b480034b8","size":{"x":32,"y":1,"z":32}},{"blockCount":1,"bytes":642,"file":"chunks/y090-z000-x352.json","offset":{"x":352,"y":90,"z":0},"requirements":{"minecraft:stone_bricks":1},"sha256":"3c05a7d515dc7eab3047e6169d039c77441169ff72cec6bba3f08430c2f233ef","size":{"x":32,"y":1,"z":32}},{"blockCount":47,"bytes":1726,"file":"chunks/y090-z064-x064.json","offset":{"x":64,"y":90,"z":64},"requirements":{"minecraft:polished_diorite":47},"sha256":"5c79b021405364edcd75e3e8d99cbe120194f4369ee0321fda6376161a486c01","size":{"x":32,"y":1,"z":32}},{"blockCount":140,"bytes":3910,"file":"chunks/y090-z064-x096.json","offset":{"x":96,"y":90,"z":64},"requirements":{"minecraft:bricks":26,"minecraft:glass":30,"minecraft:oak_planks":1,"minecraft:polished_diorite":56,"minecraft:sandstone":13,"minecraft:stone_bricks":14},"sha256":"a99b73d9126458a8804db82a8f5cda9098f2eac44fcb5205b23cb51b21880e2c","size":{"x":32,"y":1,"z":32}},{"blockCount":142,"bytes":4202,"file":"chunks/y090-z064-x128.json","offset":{"x":128,"y":90,"z":64},"requirements":{"minecraft:bricks":17,"minecraft:glass":20,"minecraft:oak_planks":1,"minecraft:polished_diorite":84,"minecraft:sandstone":9,"minecraft:stone_bricks":11},"sha256":"7974026636986ee0f9c5c47a941403f4a24b5a8ffab972d8d0cbbe715da2b8d8","size":{"x":32,"y":1,"z":32}},{"blockCount":13,"bytes":882,"file":"chunks/y090-z064-x160.json","offset":{"x":160,"y":90,"z":64},"requirements":{"minecraft:polished_diorite":13},"sha256":"a9e5e9a127c6ce031df5ebba2547a19a97918bb78330ebd3198a7f33d907a1ac","size":{"x":32,"y":1,"z":32}},{"blockCount":9,"bytes":875,"file":"chunks/y090-z064-x192.json","offset":{"x":192,"y":90,"z":64},"requirements":{"minecraft:polished_diorite":9},"sha256":"0ebfe640bd7effc5d19a53a3518693fd25c11e1fdc7d304388a9ea3752c0c21b","size":{"x":32,"y":1,"z":32}},{"blockCount":12,"bytes":915,"file":"chunks/y090-z064-x224.json","offset":{"x":224,"y":90,"z":64},"requirements":{"minecraft:polished_diorite":12},"sha256":"5bb0cc5adee3d2f6a94ba4fe139917cc1445b4c2ee55bc19fc3d378f6b243d61","size":{"x":32,"y":1,"z":32}},{"blockCount":31,"bytes":1552,"file":"chunks/y090-z096-x000.json","offset":{"x":0,"y":90,"z":96},"requirements":{"minecraft:polished_diorite":31},"sha256":"21faf0787638d893fef7c78b3868ecee3640c4779ac508193c08ac404383347b","size":{"x":32,"y":1,"z":32}},{"blockCount":136,"bytes":4189,"file":"chunks/y090-z096-x032.json","offset":{"x":32,"y":90,"z":96},"requirements":{"minecraft:bricks":11,"minecraft:glass":17,"minecraft:polished_diorite":96,"minecraft:sandstone":5,"minecraft:stone_bricks":7},"sha256":"6c5817621ff3893273cb1fc3b9e30f411f5a72b7ac1bd4fc67c6e1dd2b47be72","size":{"x":32,"y":1,"z":32}},{"blockCount":129,"bytes":3841,"file":"chunks/y090-z096-x064.json","offset":{"x":64,"y":90,"z":96},"requirements":{"minecraft:bricks":14,"minecraft:glass":16,"minecraft:oak_planks":1,"minecraft:polished_diorite":79,"minecraft:sandstone":8,"minecraft:stone_bricks":11},"sha256":"c4edcce52e9a737eea85b23321f880dbbb90d7ffd0f39b7486e70e6d5a47b45d","size":{"x":32,"y":1,"z":32}},{"blockCount":93,"bytes":3281,"file":"chunks/y090-z096-x096.json","offset":{"x":96,"y":90,"z":96},"requirements":{"minecraft:bricks":21,"minecraft:glass":12,"minecraft:oak_planks":3,"minecraft:polished_diorite":38,"minecraft:sandstone":11,"minecraft:stone_bricks":8},"sha256":"d8c27d0608096dbfdc31f9e92a28cdfb746d5fce8878df7f0b07649878f7d744","size":{"x":32,"y":1,"z":32}},{"blockCount":145,"bytes":4366,"file":"chunks/y090-z096-x128.json","offset":{"x":128,"y":90,"z":96},"requirements":{"minecraft:bricks":29,"minecraft:glass":19,"minecraft:oak_planks":4,"minecraft:polished_diorite":65,"minecraft:sandstone":15,"minecraft:stone_bricks":13},"sha256":"eb816bc925c28466c3d3da01623973f9b218f3e8cf839eded60085146afb5e97","size":{"x":32,"y":1,"z":32}},{"blockCount":143,"bytes":4369,"file":"chunks/y090-z096-x160.json","offset":{"x":160,"y":90,"z":96},"requirements":{"minecraft:bricks":14,"minecraft:glass":18,"minecraft:polished_diorite":93,"minecraft:sandstone":7,"minecraft:stone_bricks":11},"sha256":"391a39ca694a1da41838eb4745467681406761fdb67a83072e5a80256094070d","size":{"x":32,"y":1,"z":32}},{"blockCount":223,"bytes":5044,"file":"chunks/y090-z096-x192.json","offset":{"x":192,"y":90,"z":96},"requirements":{"minecraft:bricks":106,"minecraft:glass":23,"minecraft:polished_diorite":76,"minecraft:sandstone":3,"minecraft:stone_bricks":15},"sha256":"3f27143a8149c20c5afd75699b577f3b08198f92344aa65f2cdda96a7c8400e4","size":{"x":32,"y":1,"z":32}},{"blockCount":126,"bytes":3479,"file":"chunks/y090-z096-x224.json","offset":{"x":224,"y":90,"z":96},"requirements":{"minecraft:bricks":67,"minecraft:glass":13,"minecraft:polished_diorite":43,"minecraft:sandstone":2,"minecraft:stone_bricks":1},"sha256":"3218a5be68ebfeedf8f73964377a50a4030c003681a4f317bb827dfe2c1cb3f5","size":{"x":32,"y":1,"z":32}},{"blockCount":56,"bytes":1987,"file":"chunks/y090-z128-x000.json","offset":{"x":0,"y":90,"z":128},"requirements":{"minecraft:polished_diorite":56},"sha256":"2a574fcfadaf0b7309d7710c3b608732b6d44e34a35e68b48b3aef69abca5685","size":{"x":32,"y":1,"z":32}},{"blockCount":118,"bytes":3673,"file":"chunks/y090-z128-x032.json","offset":{"x":32,"y":90,"z":128},"requirements":{"minecraft:bricks":21,"minecraft:cobbled_deepslate":2,"minecraft:glass":31,"minecraft:polished_diorite":40,"minecraft:sandstone":13,"minecraft:stone_bricks":11},"sha256":"fe335b657d9c535a2c6050174995b8ca7cfa612fa7bec3bcc278796afe03518a","size":{"x":32,"y":1,"z":32}},{"blockCount":45,"bytes":1703,"file":"chunks/y090-z128-x064.json","offset":{"x":64,"y":90,"z":128},"requirements":{"minecraft:bricks":14,"minecraft:glass":16,"minecraft:oak_planks":1,"minecraft:sandstone":7,"minecraft:stone_bricks":7},"sha256":"55dc7a58a15952e15374a9f6ba80aa85860ee1927fe2ca81e68e984647bbb568","size":{"x":32,"y":1,"z":32}},{"blockCount":14,"bytes":1076,"file":"chunks/y090-z128-x096.json","offset":{"x":96,"y":90,"z":128},"requirements":{"minecraft:bricks":7,"minecraft:glass":3,"minecraft:oak_planks":1,"minecraft:sandstone":2,"minecraft:stone_bricks":1},"sha256":"e4fdcc42f48952aedf2323d3a89eaece1ff904deb763518980d943b275c82949","size":{"x":32,"y":1,"z":32}},{"blockCount":35,"bytes":1534,"file":"chunks/y090-z128-x128.json","offset":{"x":128,"y":90,"z":128},"requirements":{"minecraft:bricks":14,"minecraft:glass":10,"minecraft:oak_planks":2,"minecraft:sandstone":5,"minecraft:stone_bricks":4},"sha256":"3a9e61980f93f9cf597344398895b207e2553efb9465a64dcad24eb5ff44137f","size":{"x":32,"y":1,"z":32}},{"blockCount":46,"bytes":1756,"file":"chunks/y090-z128-x160.json","offset":{"x":160,"y":90,"z":128},"requirements":{"minecraft:bricks":14,"minecraft:glass":18,"minecraft:sandstone":7,"minecraft:stone_bricks":7},"sha256":"213f8ca51169e591ad55a61e9f27ce3e76606c345ca45269d4a63c11461d13b1","size":{"x":32,"y":1,"z":32}},{"blockCount":50,"bytes":1510,"file":"chunks/y090-z128-x192.json","offset":{"x":192,"y":90,"z":128},"requirements":{"minecraft:bricks":31,"minecraft:glass":11,"minecraft:sandstone":3,"minecraft:stone_bricks":5},"sha256":"57a3d3319c596378850f2056b6c0d9262a49c2e87d675f28344711c436360246","size":{"x":32,"y":1,"z":32}},{"blockCount":85,"bytes":2671,"file":"chunks/y090-z128-x224.json","offset":{"x":224,"y":90,"z":128},"requirements":{"minecraft:bricks":22,"minecraft:glass":19,"minecraft:polished_diorite":32,"minecraft:sandstone":8,"minecraft:stone_bricks":4},"sha256":"05487c724e1f73428647933c45e48778046e32e676e92fb16a69126a8e67812c","size":{"x":32,"y":1,"z":32}},{"blockCount":19,"bytes":1188,"file":"chunks/y090-z160-x000.json","offset":{"x":0,"y":90,"z":160},"requirements":{"minecraft:polished_diorite":19},"sha256":"eacc7e664f56286dd8c681004020a45b5ee89dbe323b1465e38e9ba81ae8659d","size":{"x":32,"y":1,"z":32}},{"blockCount":90,"bytes":2939,"file":"chunks/y090-z160-x032.json","offset":{"x":32,"y":90,"z":160},"requirements":{"minecraft:polished_diorite":88,"minecraft:stone_bricks":2},"sha256":"424a359c765da41c4f4c293059ea3093a76682c5923b0dda8a489f382be5754f","size":{"x":32,"y":1,"z":32}},{"blockCount":91,"bytes":2900,"file":"chunks/y090-z160-x064.json","offset":{"x":64,"y":90,"z":160},"requirements":{"minecraft:polished_diorite":86,"minecraft:sandstone":1,"minecraft:stone_bricks":4},"sha256":"371768dfc5e2458f5b6d8bfde55943a2806f48a17c4588ce8ff492f2f2829798","size":{"x":32,"y":1,"z":32}}],"schema":1}
