{"entries":[{"blockCount":102,"bytes":3476,"file":"chunks/y090-z160-x096.json","offset":{"x":96,"y":90,"z":160},"requirements":{"minecraft:bricks":18,"minecraft:glass":15,"minecraft:oak_planks":2,"minecraft:polished_diorite":46,"minecraft:sandstone":11,"minecraft:stone_bricks":10},"sha256":"a29d9ca199a19b5f491cf158eb554f3c5fb2c42cbaa5f11e2e0964c88e6d2fdc","size":{"x":32,"y":1,"z":32}},{"blockCount":134,"bytes":4184,"file":"chunks/y090-z160-x128.json","offset":{"x":128,"y":90,"z":160},"requirements":{"minecraft:bricks":15,"minecraft:glass":13,"minecraft:oak_planks":2,"minecraft:polished_diorite":79,"minecraft:sandstone":13,"minecraft:stone_bricks":12},"sha256":"b21919b2a72f0eb13fea2d2f0119d9f98f5772cfc5b875d9cfe33dfc448ef51d","size":{"x":32,"y":1,"z":32}},{"blockCount":98,"bytes":3275,"file":"chunks/y090-z160-x160.json","offset":{"x":160,"y":90,"z":160},"requirements":{"minecraft:polished_diorite":94,"minecraft:stone_bricks":4},"sha256":"a43eb74af68c97b11770f31a6a3aff705cd0598e1170939e38456c382234aaf6","size":{"x":32,"y":1,"z":32}},{"blockCount":182,"bytes":4467,"file":"chunks/y090-z160-x192.json","offset":{"x":192,"y":90,"z":160},"requirements":{"minecraft:bricks":75,"minecraft:glass":12,"minecraft:polished_diorite":85,"minecraft:stone_bricks":10},"sha256":"c7543c26eb0fee9cfa8ea6329fa7dcfd3b55fe58a409587d633eb90eb278d1b6","size":{"x":32,"y":1,"z":32}},{"blockCount":98,"bytes":3084,"file":"chunks/y090-z160-x224.json","offset":{"x":224,"y":90,"z":160},"requirements":{"minecraft:bricks":55,"minecraft:glass":12,"minecraft:polished_diorite":31},"sha256":"93525927ff0ff7d4268e2638c2536cf90fe6d5820bc13b4b10842513640c818d","size":{"x":32,"y":1,"z":32}},{"blockCount":40,"bytes":1536,"file":"chunks/y090-z192-x064.json","offset":{"x":64,"y":90,"z":192},"requirements":{"minecraft:polished_diorite":40},"sha256":"4e79c7c530cf4a01725707822996d4cbc7a8d87799fa708bddf4d2053054385f","size":{"x":32,"y":1,"z":32}},{"blockCount":120,"bytes":3467,"file":"chunks/y090-z192-x096.json","offset":{"x":96,"y":90,"z":192},"requirements":{"minecraft:bricks":22,"minecraft:glass":27,"minecraft:oak_planks":1,"minecraft:polished_diorite":48,"minecraft:sandstone":11,"minecraft:stone_bricks":11},"sha256":"00e31b95d844aea6fc2afbdee55060ee108b9465873fec382d8f185953b14197","size":{"x":32,"y":1,"z":32}},{"blockCount":118,"bytes":3512,"file":"chunks/y090-z192-x128.json","offset":{"x":128,"y":90,"z":192},"requirements":{"minecraft:bricks":16,"minecraft:glass":16,"minecraft:oak_planks":1,"minecraft:polished_diorite":70,"minecraft:sandstone":7,"minecraft:stone_bricks":8},"sha256":"647b9e4ba72fc526f2b5a2a2c29eaf45ca66f30df7d28f58b43850a1381d1dda","size":{"x":32,"y":1,"z":32}},{"blockCount":12,"bytes":845,"file":"chunks/y090-z192-x160.json","offset":{"x":160,"y":90,"z":192},"requirements":{"minecraft:polished_diorite":12},"sha256":"d7d419f72d239046e351dd9e379a1509208e4deb28f1a380ba817feace4b6462","size":{"x":32,"y":1,"z":32}},{"blockCount":1,"bytes":642,"file":"chunks/y091-z000-x352.json","offset":{"x":352,"y":91,"z":0},"requirements":{"minecraft:stone_bricks":1},"sha256":"42b9713a48311518f81208cc612c6e17a4d100ba5cc187c34bd08355d6e8f5b3","size":{"x":32,"y":1,"z":32}},{"blockCount":43,"bytes":1726,"file":"chunks/y091-z064-x064.json","offset":{"x":64,"y":91,"z":64},"requirements":{"minecraft:polished_diorite":43},"sha256":"d3eb704ad095b871d483ff69219bf9e4684e8b49f8bca09973d0325d9391b4d7","size":{"x":32,"y":1,"z":32}},{"blockCount":140,"bytes":3891,"file":"chunks/y091-z064-x096.json","offset":{"x":96,"y":91,"z":64},"requirements":{"minecraft:bricks":26,"minecraft:glass":30,"minecraft:oak_planks":1,"minecraft:polished_diorite":56,"minecraft:sandstone":13,"minecraft:stone_bricks":14},"sha256":"76678fae0a51c6032ff20de6b372191be863bc6e04522dc2541544ace56147c7","size":{"x":32,"y":1,"z":32}},{"blockCount":145,"bytes":4221,"file":"chunks/y091-z064-x128.json","offset":{"x":128,"y":91,"z":64},"requirements":{"minecraft:bricks":17,"minecraft:glass":20,"minecraft:oak_planks":1,"minecraft:polished_diorite":86,"minecraft:sandstone":9,"minecraft:stone_bricks":12},"sha256":"25d810fd5d354c0b83bf3b7318c1b31fbcdda21ca0c71b6dfb0626da5266e8e8","size":{"x":32,"y":1,"z":32}},{"blockCount":7,"bytes":881,"file":"chunks/y091-z064-x160.json","offset":{"x":160,"y":91,"z":64},"requirements":{"minecraft:polished_diorite":7},"sha256":"5a592ddfbcb0041d6160f02c8be1e96c2e9aa7a30840668cd13f6dcc8e3acb4f","size":{"x":32,"y":1,"z":32}},{"blockCount":9,"bytes":875,"file":"chunks/y091-z064-x192.json","offset":{"x":192,"y":91,"z":64},"requirements":{"minecraft:polished_diorite":9},"sha256":"1e85fcba876dd4835b89981433962a6d1a55a28af3db98b59933e54a281bac61","size":{"x":32,"y":1,"z":32}},{"blockCount":12,"bytes":915,"file":"chunks/y091-z064-x224.json","offset":{"x":224,"y":91,"z":64},"requirements":{"minecraft:polished_diorite":12},"sha256":"fb018e3e5e2df463cfe86966e003968a20bf34078aebe6b621e586455ca21440","size":{"x":32,"y":1,"z":32}},{"blockCount":32,"bytes":1590,"file":"chunks/y091-z096-x000.json","offset":{"x":0,"y":91,"z":96},"requirements":{"minecraft:polished_diorite":32},"sha256":"f04dcc0780321e3b03d2862bf04b3d05f9f3453a220ef52351e7578a01f01d16","size":{"x":32,"y":1,"z":32}},{"blockCount":133,"bytes":4072,"file":"chunks/y091-z096-x032.json","offset":{"x":32,"y":91,"z":96},"requirements":{"minecraft:bricks":11,"minecraft:glass":17,"minecraft:polished_diorite":93,"minecraft:sandstone":5,"minecraft:stone_bricks":7},"sha256":"6bd2ccdbca1605fc6ac03ca84fa7c6d88ebb2e2dcaaf6b1f1a3f4196c12df033","size":{"x":32,"y":1,"z":32}},{"blockCount":125,"bytes":3766,"file":"chunks/y091-z096-x064.json","offset":{"x":64,"y":91,"z":96},"requirements":{"minecraft:bricks":14,"minecraft:glass":16,"minecraft:oak_planks":1,"minecraft:polished_diorite":75,"minecraft:sandstone":8,"minecraft:stone_bricks":11},"sha256":"ec3d416678d2bc3b905beeb6db2c5b9b77499988b9e996d7d54e67123ea2dc9c","size":{"x":32,"y":1,"z":32}},{"blockCount":93,"bytes":3281,"file":"chunks/y091-z096-x096.json","offset":{"x":96,"y":91,"z":96},"requirements":{"minecraft:bricks":21,"minecraft:glass":12,"minecraft:oak_planks":3,"minecraft:polished_diorite":38,"minecraft:sandstone":11,"minecraft:stone_bricks":8},"sha256":"51179b0988463bc93cb73beb943b86cf4b7b3833664b39eb345edf455cd742a8","size":{"x":32,"y":1,"z":32}},{"blockCount":146,"bytes":4366,"file":"chunks/y091-z096-x128.json","offset":{"x":128,"y":91,"z":96},"requirements":{"minecraft:bricks":29,"minecraft:glass":19,"minecraft:oak_planks":4,"minecraft:polished_diorite":66,"minecraft:sandstone":15,"minecraft:stone_bricks":13},"sha256":"dda149f7ef577a41ab00392dfbfcb645f39c7773a14692e647657c1f2ed26358","size":{"x":32,"y":1,"z":32}},{"blockCount":136,"bytes":4214,"file":"chunks/y091-z096-x160.json","offset":{"x":160,"y":91,"z":96},"requirements":{"minecraft:bricks":14,"minecraft:glass":18,"minecraft:polished_diorite":86,"minecraft:sandstone":7,"minecraft:stone_bricks":11},"sha256":"55d337e9b4e9740717f35c563df7071f42859a635a53d7f7134075cb0ee8c1a4","size":{"x":32,"y":1,"z":32}},{"blockCount":223,"bytes":4968,"file":"chunks/y091-z096-x192.json","offset":{"x":192,"y":91,"z":96},"requirements":{"minecraft:bricks":107,"minecraft:glass":23,"minecraft:polished_diorite":72,"minecraft:sandstone":3,"minecraft:stone_bricks":18},"sha256":"46d44020168238031bcfd40056e2ad9a78989ec09cbed922b25b5df38fd66679","size":{"x":32,"y":1,"z":32}},{"blockCount":128,"bytes":3517,"file":"chunks/y091-z096-x224.json","offset":{"x":224,"y":91,"z":96},"requirements":{"minecraft:bricks":67,"minecraft:glass":13,"minecraft:polished_diorite":43,"minecraft:sandstone":2,"minecraft:stone_bricks":3},"sha256":"d55fcc6bd416b798a1ba42b109de643bc8c668db93996a03556aa7770b72b30c","size":{"x":32,"y":1,"z":32}},{"blockCount":50,"bytes":1988,"file":"chunks/y091-z128-x000.json","offset":{"x":0,"y":91,"z":128},"requirements":{"minecraft:polished_diorite":50},"sha256":"6119cda31d7965cd628842b87766bacfe7b3b592bf196d180c23dd360b778f2e","size":{"x":32,"y":1,"z":32}},{"blockCount":116,"bytes":3565,"file":"chunks/y091-z128-x032.json","offset":{"x":32,"y":91,"z":128},"requirements":{"minecraft:bricks":21,"minecraft:glass":31,"minecraft:polished_diorite":40,"minecraft:sandstone":13,"minecraft:stone_bricks":11},"sha256":"795b802c9cc9c111129f78dab130a2feffba5e851b013b0b2894b28e46a71a23","size":{"x":32,"y":1,"z":32}},{"blockCount":45,"bytes":1703,"file":"chunks/y091-z128-x064.json","offset":{"x":64,"y":91,"z":128},"requirements":{"minecraft:bricks":14,"minecraft:glass":16,"minecraft:oak_planks":1,"minecraft:sandstone":7,"minecraft:stone_bricks":7},"sha256":"5785c95bda77b065f62ffc23e84c282d835c4929292c56ed50de9b4cb72aeb79","size":{"x":32,"y":1,"z":32}},{"blockCount":14,"bytes":1076,"file":"chunks/y091-z128-x096.json","offset":{"x":96,"y":91,"z":128},"requirements":{"minecraft:bricks":7,"minecraft:glass":3,"minecraft:oak_planks":1,"minecraft:sandstone":2,"minecraft:stone_bricks":1},"sha256":"f4c382539ec09139290c9fd774a1bd280432b7249ed451908b2047ba4aefdf13","size":{"x":32,"y":1,"z":32}},{"blockCount":35,"bytes":1534,"file":"chunks/y091-z128-x128.json","offset":{"x":128,"y":91,"z":128},"requirements":{"minecraft:bricks":14,"minecraft:glass":10,"minecraft:oak_planks":2,"minecraft:sandstone":5,"minecraft:stone_bricks":4},"sha256":"6bc11bd0aebbe3c3765364ccf0d8a39afd7b25d688168cb77a61de91eb06c02d","size":{"x":32,"y":1,"z":32}},{"blockCount":46,"bytes":1756,"file":"chunks/y091-z128-x160.json","offset":{"x":160,"y":91,"z":128},"requirements":{"minecraft:bricks":14,"minecraft:glass":18,"minecraft:sandstone":7,"minecraft:stone_bricks":7},"sha256":"70fcdbc4f27e4a7a7358e56cb7f2cad597b0d195a6f8b348f2891abd148e8c2e","size":{"x":32,"y":1,"z":32}},{"blockCount":50,"bytes":1510,"file":"chunks/y091-z128-x192.json","offset":{"x":192,"y":91,"z":128},"requirements":{"minecraft:bricks":31,"minecraft:glass":11,"minecraft:sandstone":3,"minecraft:stone_bricks":5},"sha256":"dcf001777a88aaa8ed66b34b31b046e65fd94ecb0116a62daa68d031d2ab8044","size":{"x":32,"y":1,"z":32}},{"blockCount":86,"bytes":2709,"file":"chunks/y091-z128-x224.json","offset":{"x":224,"y":91,"z":128},"requirements":{"minecraft:bricks":22,"minecraft:glass":19,"minecraft:polished_diorite":32,"minecraft:sandstone":8,"minecraft:stone_bricks":5},"sha256":"63f17fadc29215d8e0ee0308b7b21ece1e9da49ec4e1d1a036d70e68b7d9fdaa","size":{"x":32,"y":1,"z":32}},{"blockCount":20,"bytes":1226,"file":"chunks/y091-z160-x000.json","offset":{"x":0,"y":91,"z":160},"requirements":{"minecraft:polished_diorite":20},"sha256":"19b644139c8ccec5a30b2960a452f6c9638fb80e2a36dc24b3fc2c06392265c3","size":{"x":32,"y":1,"z":32}},{"blockCount":87,"bytes":2821,"file":"chunks/y091-z160-x032.json","offset":{"x":32,"y":91,"z":160},"requirements":{"minecraft:polished_diorite":85,"minecraft:stone_bricks":2},"sha256":"7eb051260d586f54fd05e8e26b7ff9dd363235e88c51ede9a6012944eaa4c824","size":{"x":32,"y":1,"z":32}},{"blockCount":87,"bytes":2825,"file":"chunks/y091-z160-x064.json","offset":{"x":64,"y":91,"z":160},"requirements":{"minecraft:polished_diorite":82,"minecraft:sandstone":1,"minecraft:stone_bricks":4},"sha256":"58624ea23c0f12c8d85df77bcc3aa8cda73093f0fc28cd503273d3c41fa64e06","size":{"x":32,"y":1,"z":32}},{"blockCount":102,"bytes":3476,"file":"chunks/y091-z160-x096.json","offset":{"x":96,"y":91,"z":160},"requirements":{"minecraft:bricks":18,"minecraft:glass":15,"minecraft:oak_planks":2,"minecraft:polished_diorite":46,"minecraft:sandstone":11,"minecraft:stone_bricks":10},"sha256":"306cb0de40f9d0e052d89707ea6a483f2ab2b05017ac5abdfea2e69fe47f2b35","size":{"x":32,"y":1,"z":32}},{"blockCount":135,"bytes":4184,"file":"chunks/y091-z160-x128.json","offset":{"x":128,"y":91,"z":160},"requirements":{"minecraft:bricks":15,"minecraft:glass":13,"minecraft:oak_planks":2,"minecraft:polished_diorite":80,"minecraft:sandstone":13,"minecraft:stone_bricks":12},"sha256":"b0ff149d03cc27dcf40fd4525d1f59e86e379c0a1f235d8e4eac2f7f01e66e82","size":{"x":32,"y":1,"z":32}},{"blockCount":91,"bytes":3121,"file":"chunks/y091-z160-x160.json","offset":{"x":160,"y":91,"z":160},"requirements":{"minecraft:polished_diorite":87,"minecraft:stone_bricks":4},"sha256":"7a9a452b54c9cac705be2eececb4b2709399bc6e57c05c39079fb7b8d5c0058e","size":{"x":32,"y":1,"z":32}},{"blockCount":182,"bytes":4411,"file":"chunks/y091-z160-x192.json","offset":{"x":192,"y":91,"z":160},"requirements":{"minecraft:bricks":76,"minecraft:glass":12,"minecraft:polished_diorite":81,"minecraft:stone_bricks":13},"sha256":"6e0023ac80b63757da9086ed8373ad8362d2e68e84fb0be1b2acc3614a936eff","size":{"x":32,"y":1,"z":32}},{"blockCount":98,"bytes":3084,"file":"chunks/y091-z160-x224.json","offset":{"x":224,"y":91,"z":160},"requirements":{"minecraft:bricks":55,"minecraft:glass":12,"minecraft:polished_diorite":31},"sha256":"b11e63cb1d5105cbd94b34b5c22bbbc7eaf12fddc0af8e45a41f03a1ea7d7483","size":{"x":32,"y":1,"z":32}},{"blockCount":36,"bytes":1536,"file":"chunks/y091-z192-x064.json","offset":{"x":64,"y":91,"z":192},"requirements":{"minecraft:polished_diorite":36},"sha256":"c5c0f94051e6df1a9d8933b74c5ed764a65a37b232787124d34a19f40c7c6347","size":{"x":32,"y":1,"z":32}},{"blockCount":120,"bytes":3448,"file":"chunks/y091-z192-x096.json","offset":{"x":96,"y":91,"z":192},"requirements":{"minecraft:bricks":22,"minecraft:glass":27,"minecraft:oak_planks":1,"minecraft:polished_diorite":48,"minecraft:sandstone":11,"minecraft:stone_bricks":11},"sha256":"7150c6a3d8f7582b86df17e9aadc0121f7ccdea225fafc894a66c44c9a042833","size":{"x":32,"y":1,"z":32}},{"blockCount":121,"bytes":3531,"file":"chunks/y091-z192-x128.json","offset":{"x":128,"y":91,"z":192},"requirements":{"minecraft:bricks":16,"minecraft:glass":16,"minecraft:oak_planks":1,"minecraft:polished_diorite":72,"minecraft:sandstone":7,"minecraft:stone_bricks":9},"sha256":"7003374e7e5a6d40899f6a01a39ca5f5bfdd47155364b5afb9d98ce3373f1467","size":{"x":32,"y":1,"z":32}},{"blockCount":6,"bytes":844,"file":"chunks/y091-z192-x160.json","offset":{"x":160,"y":91,"z":192},"requirements":{"minecraft:polished_diorite":6},"sha256":"d85c8b07afc2fae6024ff90b8eba39d0f55be7d3838ff0ead5ec34527ea29b98","size":{"x":32,"y":1,"z":32}},{"blockCount":1,"bytes":635,"file":"chunks/y092-z000-x352.json","offset":{"x":352,"y":92,"z":0},"requirements":{"minecraft:glass":1},"sha256":"ac304037ace1152eb23d711b71afbf2352b0227eaac63c6feca86932e3e5ce15","size":{"x":32,"y":1,"z":32}},{"blockCount":48,"bytes":1726,"file":"chunks/y092-z064-x064.json","offset":{"x":64,"y":92,"z":64},"requirements":{"minecraft:polished_diorite":48},"sha256":"9909a6ba5798599b6945f12dad857468ad626615baa2bbab4543480065df0e31","size":{"x":32,"y":1,"z":32}},{"blockCount":161,"bytes":3911,"file":"chunks/y092-z064-x096.json","offset":{"x":96,"y":92,"z":64},"requirements":{"minecraft:bricks":26,"minecraft:glass":30,"minecraft:oak_planks":1,"minecraft:polished_diorite":48,"minecraft:sandstone":13,"minecraft:stone_bricks":43},"sha256":"9ad2339f27aa64ee637f3c0f320974dd438b73c1af62839bca71d90bebe55af7","size":{"x":32,"y":1,"z":32}},{"blockCount":161,"bytes":4297,"file":"chunks/y092-z064-x128.json","offset":{"x":128,"y":92,"z":64},"requirements":{"minecraft:bricks":17,"minecraft:glass":20,"minecraft:oak_planks":1,"minecraft:polished_diorite":87,"minecraft:sandstone":9,"minecraft:stone_bricks":27},"sha256":"71e1099ee416bc1dec08a7cfb42a8eb08aeefa7edb375028aff2db30f7dd4cc0","size":{"x":32,"y":1,"z":32}},{"blockCount":7,"bytes":881,"file":"chunks/y092-z064-x160.json","offset":{"x":160,"y":92,"z":64},"requirements":{"minecraft:polished_diorite":7},"sha256":"aad0e6aed72fc93690526cac1e2498fd781465a3e5ee25c93b68674d4fcfed12","size":{"x":32,"y":1,"z":32}},{"blockCount":9,"bytes":875,"file":"chunks/y092-z064-x192.json","offset":{"x":192,"y":92,"z":64},"requirements":{"minecraft:polished_diorite":9},"sha256":"8a721b705776392653f33dc6b14c2438a4bbe540075ae1d4ab4c4fe6025b2e71","size":{"x":32,"y":1,"z":32}},{"blockCount":12,"bytes":915,"file":"chunks/y092-z064-x224.json","offset":{"x":224,"y":92,"z":64},"requirements":{"minecraft:polished_diorite":12},"sha256":"43f6b18015fa9963745fd3d2ea92ea1426536794bbbf28c14405502bef57b84c","size":{"x":32,"y":1,"z":32}},{"blockCount":35,"bytes":1553,"file":"chunks/y092-z096-x000.json","offset":{"x":0,"y":92,"z":96},"requirements":{"minecraft:polished_diorite":35},"sha256":"0aab567faa39152cd15ee5ab01db3a63c76bbf88f0d72fe4fb7789d5864dbc75","size":{"x":32,"y":1,"z":32}},{"blockCount":143,"bytes":3939,"file":"chunks/y092-z096-x032.json","offset":{"x":32,"y":92,"z":96},"requirements":{"minecraft:bricks":11,"minecraft:glass":16,"minecraft:polished_diorite":94,"minecraft:sandstone":6,"minecraft:stone_bricks":16},"sha256":"ed2d5758e40dee461c2f9d8e7f72cfc34d4935b900b4e0deb2cb42af65e917c0","size":{"x":32,"y":1,"z":32}},{"blockCount":138,"bytes":3551,"file":"chunks/y092-z096-x064.json","offset":{"x":64,"y":92,"z":96},"requirements":{"minecraft:bricks":13,"minecraft:glass":16,"minecraft:polished_diorite":77,"minecraft:sandstone":8,"minecraft:stone_bricks":24},"sha256":"f0b7036bad6a60db6fba327abddc75e7e9825972709fb09a0959681ba4d43d28","size":{"x":32,"y":1,"z":32}},{"blockCount":103,"bytes":3294,"file":"chunks/y092-z096-x096.json","offset":{"x":96,"y":92,"z":96},"requirements":{"minecraft:bricks":16,"minecraft:glass":12,"minecraft:polished_diorite":40,"minecraft:sandstone":9,"minecraft:stone_bricks":26},"sha256":"2af12249f15e5c411b794bf39a7e3f34e65c42224a077ede656745cb50ff8812","size":{"x":32,"y":1,"z":32}},{"blockCount":162,"bytes":4265,"file":"chunks/y092-z096-x128.json","offset":{"x":128,"y":92,"z":96},"requirements":{"minecraft:bricks":23,"minecraft:glass":19,"minecraft:polished_diorite":69,"minecraft:sandstone":13,"minecraft:stone_bricks":38},"sha256":"ceb1b668e996d004175860e2326de9e8d65a6b2c9b29b6eca8fa0dd39358553a","size":{"x":32,"y":1,"z":32}},{"blockCount":150,"bytes":4043,"file":"chunks/y092-z096-x160.json","offset":{"x":160,"y":92,"z":96},"requirements":{"minecraft:bricks":14,"minecraft:glass":18,"minecraft:polished_diorite":89,"minecraft:sandstone":7,"minecraft:stone_bricks":22},"sha256":"065b7197065354438dbb5b33c665d4ecd51b6509d87a682c4c43bb16444bb6b8","size":{"x":32,"y":1,"z":32}},{"blockCount":231,"bytes":4967,"file":"chunks/y092-z096-x192.json","offset":{"x":192,"y":92,"z":96},"requirements":{"minecraft:bricks":110,"minecraft:glass":23,"minecraft:polished_diorite":74,"minecraft:sandstone":5,"minecraft:stone_bricks":19},"sha256":"8606dbe4be16f77dbc3362d3067db9384b6071996df3b8cbf67bafc98761ce4b","size":{"x":32,"y":1,"z":32}},{"blockCount":126,"bytes":3479,"file":"chunks/y092-z096-x224.json","offset":{"x":224,"y":92,"z":96},"requirements":{"minecraft:bricks":67,"minecraft:glass":13,"minecraft:polished_diorite":42,"minecraft:sandstone":2,"minecraft:stone_bricks":2},"sha256":"ffe35efa9507fec20eea8221ae68faa5691b6eb1e6a75212afdabb3ca262616a","size":{"x":32,"y":1,"z":32}},{"blockCount":48,"bytes":1874,"file":"chunks/y092-z128-x000.json","offset":{"x":0,"y":92,"z":128},"requirements":{"minecraft:polished_diorite":48},"sha256":"49b28dc75d893b923374e543219352e284f538bdb7e0b43fdfa4cd17e64e4ddc","size":{"x":32,"y":1,"z":32}},{"blockCount":120,"bytes":3584,"file":"chunks/y092-z128-x032.json","offset":{"x":32,"y":92,"z":128},"requirements":{"minecraft:bricks":21,"minecraft:glass":28,"minecraft:polished_diorite":36,"minecraft:sandstone":16,"minecraft:stone_bricks":19},"sha256":"9aff736f025c2163a57344fd8157c272583f91696dcb7a4d0b480d2e36b4a9a1","size":{"x":32,"y":1,"z":32}},{"blockCount":47,"bytes":1729,"file":"chunks/y092-z128-x064.json","offset":{"x":64,"y":92,"z":128},"requirements":{"minecraft:bricks":13,"minecraft:glass":16,"minecraft:polished_diorite":1,"minecraft:sandstone":7,"minecraft:stone_bricks":10},"sha256":"5a6cef9951b6a98e0dfa66ebadeb35e6348ccf2b3783174bb8df12f194b0b7cc","size":{"x":32,"y":1,"z":32}},{"blockCount":16,"bytes":1063,"file":"chunks/y092-z128-x096.json","offset":{"x":96,"y":92,"z":128},"requirements":{"minecraft:bricks":5,"minecraft:glass":3,"minecraft:polished_diorite":1,"minecraft:sandstone":1,"minecraft:stone_bricks":6},"sha256":"bd7fa64e37ddc6a360f8fe5600be06296aab0012f46cade14cb3d12d3d35cb61","size":{"x":32,"y":1,"z":32}},{"blockCount":39,"bytes":1503,"file":"chunks/y092-z128-x128.json","offset":{"x":128,"y":92,"z":128},"requirements":{"minecraft:bricks":11,"minecraft:glass":10,"minecraft:polished_diorite":2,"minecraft:sandstone":4,"minecraft:stone_bricks":12},"sha256":"39e65d88574ebb7d791f4edbe160b420f9bb8f74c41820470acae4fd73557d29","size":{"x":32,"y":1,"z":32}},{"blockCount":46,"bytes":1756,"file":"chunks/y092-z128-x160.json","offset":{"x":160,"y":92,"z":128},"requirements":{"minecraft:bricks":14,"minecraft:glass":18,"minecraft:sandstone":7,"minecraft:stone_bricks":7},"sha256":"50d3330a40484c05eb9e9e535e922924b16ea23d10e2229092ffa1b0d1203982","size":{"x":32,"y":1,"z":32}},{"blockCount":57,"bytes":1585,"file":"chunks/y092-z128-x192.json","offset":{"x":192,"y":92,"z":128},"requirements":{"minecraft:bricks":35,"minecraft:glass":11,"minecraft:sandstone":5,"minecraft:stone_bricks":6},"sha256":"70be7da0a8cbdd3ef4a3839541b672b78e42eac136c663c06352dbea48f82cc2","size":{"x":32,"y":1,"z":32}},{"blockCount":102,"bytes":3014,"file":"chunks/y092-z128-x224.json","offset":{"x":224,"y":92,"z":128},"requirements":{"minecraft:bricks":22,"minecraft:glass":19,"minecraft:polished_diorite":25,"minecraft:sandstone":8,"minecraft:stone_bricks":28},"sha256":"217f96d9a8a3ce616667dcc46d0490dca2ff69a5c59a408ed5c5fce83979d171","size":{"x":32,"y":1,"z":32}},{"blockCount":23,"bytes":1227,"file":"chunks/y092-z160-x000.json","offset":{"x":0,"y":92,"z":160},"requirements":{"minecraft:polished_diorite":23},"sha256":"e96d986271f9547145c35515a297e5382e4e5bb5eb4b86f1136859e43e46b9ff","size":{"x":32,"y":1,"z":32}},{"blockCount":93,"bytes":2629,"file":"chunks/y092-z160-x032.json","offset":{"x":32,"y":92,"z":160},"requirements":{"minecraft:polished_diorite":86,"minecraft:stone_bricks":7},"sha256":"9a134ac5bfabd92656ba6dfe42f7f8053d3cad7480adb1d4c6abe5fcb6c8c6bf","size":{"x":32,"y":1,"z":32}},{"blockCount":99,"bytes":2598,"file":"chunks/y092-z160-x064.json","offset":{"x":64,"y":92,"z":160},"requirements":{"minecraft:polished_diorite":84,"minecraft:sandstone":1,"minecraft:stone_bricks":14},"sha256":"8f5b2b306d886d7da72e15807d70c782a983bb298cfd038bca9041b9edeb30e7","size":{"x":32,"y":1,"z":32}},{"blockCount":112,"bytes":3546,"file":"chunks/y092-z160-x096.json","offset":{"x":96,"y":92,"z":160},"requirements":{"minecraft:bricks":15,"minecraft:glass":15,"minecraft:polished_diorite":46,"minecraft:sandstone":10,"minecraft:stone_bricks":26},"sha256":"016b5ebe7c0004bb91309a7b9aabb56507e158f338f877f4c661263c20d70d9b","size":{"x":32,"y":1,"z":32}},{"blockCount":150,"bytes":4178,"file":"chunks/y092-z160-x128.json","offset":{"x":128,"y":92,"z":160},"requirements":{"minecraft:bricks":13,"minecraft:glass":13,"minecraft:polished_diorite":81,"minecraft:sandstone":11,"minecraft:stone_bricks":32},"sha256":"91fcf2844d37f6e22cb58e0840c22ebe02255d39c77a01c39167d91ca22d00ab","size":{"x":32,"y":1,"z":32}},{"blockCount":105,"bytes":2932,"file":"chunks/y092-z160-x160.json","offset":{"x":160,"y":92,"z":160},"requirements":{"minecraft:polished_diorite":90,"minecraft:stone_bricks":15},"sha256":"48e8274dd1e3648606783356d6ba97cbf91f0e7b69a857f2d5bba0f3e0f274a7","size":{"x":32,"y":1,"z":32}},{"blockCount":183,"bytes":4335,"file":"chunks/y092-z160-x192.json","offset":{"x":192,"y":92,"z":160},"requirements":{"minecraft:bricks":75,"minecraft:glass":12,"minecraft:polished_diorite":83,"minecraft:stone_bricks":13},"sha256":"e32cdedb6e86730e57353aac5b3af61afa22dbe9e85b9ac5777c8e4cc43a9757","size":{"x":32,"y":1,"z":32}},{"blockCount":98,"bytes":3084,"file":"chunks/y092-z160-x224.json","offset":{"x":224,"y":92,"z":160},"requirements":{"minecraft:bricks":55,"minecraft:glass":12,"minecraft:polished_diorite":31},"sha256":"09a75e8670f89787e8545deb55c39c2c7f254fb273ca0bb120581c779d43a360","size":{"x":32,"y":1,"z":32}},{"blockCount":40,"bytes":1536,"file":"chunks/y092-z192-x064.json","offset":{"x":64,"y":92,"z":192},"requirements":{"minecraft:polished_diorite":40},"sha256":"ac948876eb8620fd7151c100671438da3ec619dc56a5c4e336b231e321f8b626","size":{"x":32,"y":1,"z":32}},{"blockCount":139,"bytes":3430,"file":"chunks/y092-z192-x096.json","offset":{"x":96,"y":92,"z":192},"requirements":{"minecraft:bricks":22,"minecraft:glass":27,"minecraft:oak_planks":1,"minecraft:polished_diorite":41,"minecraft:sandstone":11,"minecraft:stone_bricks":37},"sha256":"187e199cac9e1cf99bebed849ed01dabc4c972d4731251a7125827ab46b5c399","size":{"x":32,"y":1,"z":32}},{"blockCount":134,"bytes":3589,"file":"chunks/y092-z192-x128.json","offset":{"x":128,"y":92,"z":192},"requirements":{"minecraft:bricks":16,"minecraft:glass":16,"minecraft:oak_planks":1,"minecraft:polished_diorite":73,"minecraft:sandstone":7,"minecraft:stone_bricks":21},"sha256":"db8c332c438d1cb38e98827c15716abe9b72770c60eaebdd2154132eff973bd9","size":{"x":32,"y":1,"z":32}},{"blockCount":6,"bytes":844,"file":"chunks/y092-z192-x160.json","offset":{"x":160,"y":92,"z":192},"requirements":{"minecraft:polished_diorite":6},"sha256":"23becdf666d6ba6866afa673c27f8dd62fec9f8ff28cf3929fb81b75dfeda896","size":{"x":32,"y":1,"z":32}},{"blockCount":1,"bytes":635,"file":"chunks/y093-z000-x352.json","offset":{"x":352,"y":93,"z":0},"requirements":{"minecraft:glass":1},"sha256":"471dda4b8911f8d3fbd892b6ac18edfaaefe8bc63ec3e3052367c1ab6f32d223","size":{"x":32,"y":1,"z":32}},{"blockCount":48,"bytes":1992,"file":"chunks/y093-z064-x064.json","offset":{"x":64,"y":93,"z":64},"requirements":{"minecraft:polished_diorite":48},"sha256":"a305d18a3c40d4e73e00a568b9048672828241374024d5e242f8f47922af4e24","size":{"x":32,"y":1,"z":32}},{"blockCount":147,"bytes":4043,"file":"chunks/y093-z064-x096.json","offset":{"x":96,"y":93,"z":64},"requirements":{"minecraft:bricks":26,"minecraft:glass":39,"minecraft:oak_planks":1,"minecraft:polished_diorite":50,"minecraft:sandstone":13,"minecraft:stone_bricks":18},"sha256":"964681e52ca16548bccde3a2b3118d9ff2591c00b7453bf8dd97c3a4503a4938","size":{"x":32,"y":1,"z":32}},{"blockCount":152,"bytes":4506,"file":"chunks/y093-z064-x128.json","offset":{"x":128,"y":93,"z":64},"requirements":{"minecraft:bricks":17,"minecraft:glass":23,"minecraft:oak_planks":1,"minecraft:polished_diorite":89,"minecraft:sandstone":9,"minecraft:stone_bricks":13},"sha256":"113b37e3dd65aad7a4991ca74a181c88eff488f3b8147651e8d452f934c9c0ad","size":{"x":32,"y":1,"z":32}},{"blockCount":7,"bytes":881,"file":"chunks/y093-z064-x160.json","offset":{"x":160,"y":93,"z":64},"requirements":{"minecraft:polished_diorite":7},"sha256":"dda2d7f5f43700101108853e1f6da092f112f2daf7aab2adaf9dad423ba0cab4","size":{"x":32,"y":1,"z":32}},{"blockCount":9,"bytes":875,"file":"chunks/y093-z064-x192.json","offset":{"x":192,"y":93,"z":64},"requirements":{"minecraft:polished_diorite":9},"sha256":"c203c09e5d4b66090bf8efa7fa79ed2b77b76cab1c786236364d152e888b78f8","size":{"x":32,"y":1,"z":32}},{"blockCount":12,"bytes":915,"file":"chunks/y093-z064-x224.json","offset":{"x":224,"y":93,"z":64},"requirements":{"minecraft:polished_diorite":12},"sha256":"024102496e5f09bf14f0fe5f73276f1927dd6cfcc1d28832c5c48428923e2de3","size":{"x":32,"y":1,"z":32}},{"blockCount":34,"bytes":1591,"file":"chunks/y093-z096-x000.json","offset":{"x":0,"y":93,"z":96},"requirements":{"minecraft:polished_diorite":34},"sha256":"d4be75fc6d956d0b6872c62c48f719d36c74d28348573d53a09a0ed1480f929c","size":{"x":32,"y":1,"z":32}},{"blockCount":136,"bytes":3958,"file":"chunks/y093-z096-x032.json","offset":{"x":32,"y":93,"z":96},"requirements":{"minecraft:bricks":11,"minecraft:glass":17,"minecraft:polished_diorite":96,"minecraft:sandstone":5,"minecraft:stone_bricks":7},"sha256":"bd9080691473c4b56031a26bdb99ee5985823ef4e35a02789665a4d58c6813d1","size":{"x":32,"y":1,"z":32}},{"blockCount":130,"bytes":3855,"file":"chunks/y093-z096-x064.json","offset":{"x":64,"y":93,"z":96},"requirements":{"minecraft:bricks":13,"minecraft:glass":16,"minecraft:polished_diorite":79,"minecraft:sandstone":8,"minecraft:stone_bricks":14},"sha256":"7c517b498380a0cc1e37c8b28ff336d6f5806225d60c4d1da8ccf1181e10ffb3","size":{"x":32,"y":1,"z":32}},{"blockCount":97,"bytes":3180,"file":"chunks/y093-z096-x096.json","offset":{"x":96,"y":93,"z":96},"requirements":{"minecraft:bricks":14,"minecraft:glass":12,"minecraft:polished_diorite":43,"minecraft:sandstone":9,"minecraft:stone_bricks":19},"sha256":"aafccf311ba1aa4c8e0ee49f2f47f1a2b8b59f9d4b81fb7f7d601beee19af4ec","size":{"x":32,"y":1,"z":32}},{"blockCount":153,"bytes":4360,"file":"chunks/y093-z096-x128.json","offset":{"x":128,"y":93,"z":96},"requirements":{"minecraft:bricks":21,"minecraft:glass":19,"minecraft:polished_diorite":73,"minecraft:sandstone":13,"minecraft:stone_bricks":27},"sha256":"7a7343131f43e4e20cdaaea8cb21f1381f2c4809f5343a3083388c9f8fed91ff","size":{"x":32,"y":1,"z":32}},{"blockCount":141,"bytes":4253,"file":"chunks/y093-z096-x160.json","offset":{"x":160,"y":93,"z":96},"requirements":{"minecraft:bricks":14,"minecraft:glass":18,"minecraft:polished_diorite":91,"minecraft:sandstone":7,"minecraft:stone_bricks":11},"sha256":"ac65f8c230ca046011933050de8ee3b6f63b450be3268dd04638c98b172813bf","size":{"x":32,"y":1,"z":32}},{"blockCount":234,"bytes":5101,"file":"chunks/y093-z096-x192.json","offset":{"x":192,"y":93,"z":96},"requirements":{"minecraft:bricks":113,"minecraft:glass":23,"minecraft:polished_diorite":75,"minecraft:sandstone":5,"minecraft:stone_bricks":18},"sha256":"7167d8c52430924e036be792ffb25cc8dd267ccfe60048e06d57b00dea57826c","size":{"x":32,"y":1,"z":32}},{"blockCount":126,"bytes":3479,"file":"chunks/y093-z096-x224.json","offset":{"x":224,"y":93,"z":96},"requirements":{"minecraft:bricks":67,"minecraft:glass":13,"minecraft:polished_diorite":42,"minecraft:sandstone":2,"minecraft:stone_bricks":2},"sha256":"ef32b4552de81dcc234819916f3ada0aba43deb7912679cf2f7ae915b9d52266","size":{"x":32,"y":1,"z":32}},{"blockCount":47,"bytes":1798,"file":"chunks/y093-z128-x000.json","offset":{"x":0,"y":93,"z":128},"requirements":{"minecraft:polished_diorite":47},"sha256":"fa53d05a9921a4a391bd67c23c33adfe18e2aabc16fa24d95aacd452ba7232d0","size":{"x":32,"y":1,"z":32}},{"blockCount":116,"bytes":3603,"file":"chunks/y093-z128-x032.json","offset":{"x":32,"y":93,"z":128},"requirements":{"minecraft:bricks":21,"minecraft:glass":31,"minecraft:polished_diorite":32,"minecraft:sandstone":13,"minecraft:stone_bricks":19},"sha256":"0d2f96b041ef2e2de532870fdeea63dc4b1bbc5a6a9c1012fb8e37196c8191db","size":{"x":32,"y":1,"z":32}},{"blockCount":47,"bytes":1710,"file":"chunks/y093-z128-x064.json","offset":{"x":64,"y":93,"z":128},"requirements":{"minecraft:bricks":12,"minecraft:glass":16,"minecraft:polished_diorite":2,"minecraft:sandstone":7,"minecraft:stone_bricks":10},"sha256":"3ef8a2e19c9631451b9058ea1dc22560295498e8d912de80ad8dc11f37be1226","size":{"x":32,"y":1,"z":32}},{"blockCount":15,"bytes":1063,"file":"chunks/y093-z128-x096.json","offset":{"x":96,"y":93,"z":128},"requirements":{"minecraft:bricks":5,"minecraft:glass":3,"minecraft:polished_diorite":1,"minecraft:sandstone":1,"minecraft:stone_bricks":5},"sha256":"9818c7e94fa6c8db8a6a055c348419d33577a6363bdcd4e573392c7b6f86d880","size":{"x":32,"y":1,"z":32}},{"blockCount":38,"bytes":1522,"file":"chunks/y093-z128-x128.json","offset":{"x":128,"y":93,"z":128},"requirements":{"minecraft:bricks":10,"minecraft:glass":10,"minecraft:polished_diorite":3,"minecraft:sandstone":4,"minecraft:stone_bricks":11},"sha256":"171d6084107bd9a29c1f153abdc04b252bf8b9a696722455ea498fdcda0fdd22","size":{"x":32,"y":1,"z":32}},{"blockCount":46,"bytes":1756,"file":"chunks/y093-z128-x160.json","offset":{"x":160,"y":93,"z":128},"requirements":{"minecraft:bricks":14,"minecraft:glass":18,"minecraft:sandstone":7,"minecraft:stone_bricks":7},"sha256":"890ebac5ee884ed3c5df6fec12da4002bedc6d6918f8d69740491385a47b701b","size":{"x":32,"y":1,"z":32}},{"blockCount":57,"bytes":1585,"file":"chunks/y093-z128-x192.json","offset":{"x":192,"y":93,"z":128},"requirements":{"minecraft:bricks":35,"minecraft:glass":11,"minecraft:sandstone":5,"minecraft:stone_bricks":6},"sha256":"7279f357315c996df15d57231d7129f970eeba5a49904a9075130cc0b154ff57","size":{"x":32,"y":1,"z":32}},{"blockCount":95,"bytes":2633,"file":"chunks/y093-z128-x224.json","offset":{"x":224,"y":93,"z":128},"requirements":{"minecraft:bricks":22,"minecraft:glass":31,"minecraft:polished_diorite":25,"minecraft:sandstone":8,"minecraft:stone_bricks":9},"sha256":"ad28c6f49465109086aa2bcc1cba92cc3d6c69c801b09c164bf8d95cb0c7d1ea","size":{"x":32,"y":1,"z":32}},{"blockCount":23,"bytes":1265,"file":"chunks/y093-z160-x000.json","offset":{"x":0,"y":93,"z":160},"requirements":{"minecraft:polished_diorite":23},"sha256":"c7aa65b49bb52687a577753428b904dd807065ef6c0b67e5ea1ac0fedfa826d0","size":{"x":32,"y":1,"z":32}},{"blockCount":90,"bytes":2667,"file":"chunks/y093-z160-x032.json","offset":{"x":32,"y":93,"z":160},"requirements":{"minecraft:polished_diorite":88,"minecraft:stone_bricks":2},"sha256":"75e841c2aaf75e8fdb1713911b40a7a0126253869d7f22b29b848bedde278a18","size":{"x":32,"y":1,"z":32}},{"blockCount":91,"bytes":2939,"file":"chunks/y093-z160-x064.json","offset":{"x":64,"y":93,"z":160},"requirements":{"minecraft:polished_diorite":86,"minecraft:sandstone":1,"minecraft:stone_bricks":4},"sha256":"6a4971072bfbd25175c0448c026da1b46d8221d23463756edff5230c6a718da3","size":{"x":32,"y":1,"z":32}},{"blockCount":105,"bytes":3413,"file":"chunks/y093-z160-x096.json","offset":{"x":96,"y":93,"z":160},"requirements":{"minecraft:bricks":14,"minecraft:glass":15,"minecraft:polished_diorite":49,"minecraft:sandstone":10,"minecraft:stone_bricks":17},"sha256":"91bf47a7c962448068fe1730f10e36a86b07c662d070487de1c466d310c82834","size":{"x":32,"y":1,"z":32}},{"blockCount":140,"bytes":4254,"file":"chunks/y093-z160-x128.json","offset":{"x":128,"y":93,"z":160},"requirements":{"minecraft:bricks":12,"minecraft:glass":13,"minecraft:polished_diorite":85,"minecraft:sandstone":11,"minecraft:stone_bricks":19},"sha256":"92d424ba062018f2c03be009a6f5c22ba1c6a992c3032136f9455fb20cbb431b","size":{"x":32,"y":1,"z":32}},{"blockCount":96,"bytes":3160,"file":"chunks/y093-z160-x160.json","offset":{"x":160,"y":93,"z":160},"requirements":{"minecraft:polished_diorite":92,"minecraft:stone_bricks":4},"sha256":"3ba4a404cdb88a9e3cc60482e7f3471144b0a37a10a4d9337d65cdcfb2d3a549","size":{"x":32,"y":1,"z":32}},{"blockCount":186,"bytes":4449,"file":"chunks/y093-z160-x192.json","offset":{"x":192,"y":93,"z":160},"requirements":{"minecraft:bricks":78,"minecraft:glass":12,"minecraft:polished_diorite":84,"minecraft:stone_bricks":12},"sha256":"a7e061920797e7ec4c270eda054595fdd1979d2a0cabb949fc03497e1c1e0365","size":{"x":32,"y":1,"z":32}},{"blockCount":98,"bytes":3084,"file":"chunks/y093-z160-x224.json","offset":{"x":224,"y":93,"z":160},"requirements":{"minecraft:bricks":55,"minecraft:glass":12,"minecraft:polished_diorite":31},"sha256":"c5bb8616cc21fcba1f2f7c758097f5a40b692e83327289eefc7dcd07e42e9cb7","size":{"x":32,"y":1,"z":32}},{"blockCount":40,"bytes":1764,"file":"chunks/y093-z192-x064.json","offset":{"x":64,"y":93,"z":192},"requirements":{"minecraft:polished_diorite":40},"sha256":"e1cfce09c0983d5726a65d2e069b8cdd21e9e5c6ea92aa8f6428a647c4c70a7b","size":{"x":32,"y":1,"z":32}},{"blockCount":127,"bytes":3600,"file":"chunks/y093-z192-x096.json","offset":{"x":96,"y":93,"z":192},"requirements":{"minecraft:bricks":22,"minecraft:glass":36,"minecraft:oak_planks":1,"minecraft:polished_diorite":42,"minecraft:sandstone":11,"minecraft:stone_bricks":15},"sha256":"b49c8b9f1d45dd4c0963171c66614a9e05ccb404dfc84ac2db7ffd588e679641","size":{"x":32,"y":1,"z":32}},{"blockCount":127,"bytes":3798,"file":"chunks/y093-z192-x128.json","offset":{"x":128,"y":93,"z":192},"requirements":{"minecraft:bricks":16,"minecraft:glass":19,"minecraft:oak_planks":1,"minecraft:polished_diorite":74,"minecraft:sandstone":7,"minecraft:stone_bricks":10},"sha256":"551253db4f3f682022b5cf511907350ab23e3f350e658b73a779a1deb1a24379","size":{"x":32,"y":1,"z":32}},{"blockCount":6,"bytes":844,"file":"chunks/y093-z192-x160.json","offset":{"x":160,"y":93,"z":192},"requirements":{"minecraft:polished_diorite":6},"sha256":"e41c058d679bf928e66c3c9f6ecbb4abd15e837cb70d8c7e3a208289ef9302bb","size":{"x":32,"y":1,"z":32}},{"blockCount":75,"bytes":1992,"file":"chunks/y094-z064-x064.json","offset":{"x":64,"y":94,"z":64},"requirements":{"minecraft:polished_diorite":75},"sha256":"fcbccc7407a14e84170c5bbaf8267160d9ba355ccbbb584097269308aa1d1b1f","size":{"x":32,"y":1,"z":32}},{"blockCount":148,"bytes":3908,"file":"chunks/y094-z064-x096.json","offset":{"x":96,"y":94,"z":64},"requirements":{"minecraft:bricks":26,"minecraft:glass":30,"minecraft:oak_planks":1,"minecraft:polished_diorite":62,"minecraft:sandstone":16,"minecraft:stone_bricks":13},"sha256":"c1f4689bf425f1c89cffaf219fe532622d6281ff93941336aab40396f765aa81","size":{"x":32,"y":1,"z":32}},{"blockCount":176,"bytes":4527,"file":"chunks/y094-z064-x128.json","offset":{"x":128,"y":94,"z":64},"requirements":{"minecraft:bricks":17,"minecraft:glass":20,"minecraft:oak_planks":1,"minecraft:polished_diorite":115,"minecraft:sandstone":10,"minecraft:stone_bricks":13},"sha256":"60246eaca8bd02e5998ae7d762ef1fa4d30f3d7522fa82e62929fd4357e99110","size":{"x":32,"y":1,"z":32}},{"blockCount":12,"bytes":1077,"file":"chunks/y094-z064-x160.json","offset":{"x":160,"y":94,"z":64},"requirements":{"minecraft:polished_diorite":12},"sha256":"700c6a50537967f9212ca150b1b4ab2bee613a448b41b920375a91d7ca2f249d","size":{"x":32,"y":1,"z":32}},{"blockCount":9,"bytes":875,"file":"chunks/y094-z064-x192.json","offset":{"x":192,"y":94,"z":64},"requirements":{"minecraft:polished_diorite":9},"sha256":"9a28755114f7efff2bbfd01eeea2b92ac53e6bcdfa6aca0aaad13b535a99a4ae","size":{"x":32,"y":1,"z":32}},{"blockCount":12,"bytes":915,"file":"chunks/y094-z064-x224.json","offset":{"x":224,"y":94,"z":64},"requirements":{"minecraft:polished_diorite":12},"sha256":"3acdbf1d59455f1be32388ad97577a72cb566ffb2ba3f8828985faf9047bb497","size":{"x":32,"y":1,"z":32}},{"blockCount":49,"bytes":1632,"file":"chunks/y094-z096-x000.json","offset":{"x":0,"y":94,"z":96},"requirements":{"minecraft:polished_diorite":49},"sha256":"1543482da3dae51dbd84e82641920c3469ed98e5c860a2930d608effbfc1ebc5","size":{"x":32,"y":1,"z":32}},{"blockCount":157,"bytes":3956,"file":"chunks/y094-z096-x032.json","offset":{"x":32,"y":94,"z":96},"requirements":{"minecraft:bricks":11,"minecraft:glass":17,"minecraft:polished_diorite":117,"minecraft:sandstone":5,"minecraft:stone_bricks":7},"sha256":"93aa34806c1bd88b1431aa0e7ea10e137cd3f7a178ea0b8f3bda28aab259f11f","size":{"x":32,"y":1,"z":32}},{"blockCount":149,"bytes":3957,"file":"chunks/y094-z096-x064.json","offset":{"x":64,"y":94,"z":96},"requirements":{"minecraft:bricks":14,"minecraft:glass":16,"minecraft:oak_planks":1,"minecraft:polished_diorite":99,"minecraft:sandstone":8,"minecraft:stone_bricks":11},"sha256":"73b7a5ae7c5d174a94494f33eed9a55f742f21b2e23b5d64ef644bf780690ca4","size":{"x":32,"y":1,"z":32}},{"blockCount":93,"bytes":3282,"file":"chunks/y094-z096-x096.json","offset":{"x":96,"y":94,"z":96},"requirements":{"minecraft:bricks":19,"minecraft:glass":12,"minecraft:oak_planks":3,"minecraft:polished_diorite":38,"minecraft:sandstone":11,"minecraft:stone_bricks":10},"sha256":"d0ff71f275af549a8da2096922fb4c103e14caef857323780a9cecb414528a89","size":{"x":32,"y":1,"z":32}},{"blockCount":152,"bytes":4442,"file":"chunks/y094-z096-x128.json","offset":{"x":128,"y":94,"z":96},"requirements":{"minecraft:bricks":27,"minecraft:glass":19,"minecraft:oak_planks":4,"minecraft:polished_diorite":72,"minecraft:sandstone":15,"minecraft:stone_bricks":15},"sha256":"ea4a4442be8f2c6a3bfe552bf5c5b3a8f78d39290d9498264a46b8f3db4548de","size":{"x":32,"y":1,"z":32}},{"blockCount":169,"bytes":4405,"file":"chunks/y094-z096-x160.json","offset":{"x":160,"y":94,"z":96},"requirements":{"minecraft:bricks":14,"minecraft:glass":18,"minecraft:polished_diorite":119,"minecraft:sandstone":7,"minecraft:stone_bricks":11},"sha256":"ee453aab2b7634dd7ea061a1f05e922e2c5e6fa93136d7d0d416325a33fddef7","size":{"x":32,"y":1,"z":32}},{"blockCount":238,"bytes":5025,"file":"chunks/y094-z096-x192.json","offset":{"x":192,"y":94,"z":96},"requirements":{"minecraft:bricks":106,"minecraft:glass":23,"minecraft:polished_diorite":92,"minecraft:sandstone":3,"minecraft:stone_bricks":14},"sha256":"d2d64c25414b092821e1a414f91fbe7072d3c258cf86416acb47f4ad0f96dae9","size":{"x":32,"y":1,"z":32}},{"blockCount":128,"bytes":3517,"file":"chunks/y094-z096-x224.json","offset":{"x":224,"y":94,"z":96},"requirements":{"minecraft:bricks":67,"minecraft:glass":13,"minecraft:polished_diorite":43,"minecraft:sandstone":2,"minecraft:stone_bricks":3},"sha256":"6d31cc648064b9a37954c106116dc93716bd8b6bcb7369a3a398537f3eacd73b","size":{"x":32,"y":1,"z":32}}],"schema":1}
