{"entries":[{"blockCount":60,"bytes":1798,"file":"chunks/y094-z128-x000.json","offset":{"x":0,"y":94,"z":128},"requirements":{"minecraft:polished_diorite":60},"sha256":"8f7813887a67f22af864bd46deb9d87ae4a86e52973b5b93b1b6e65116bad59a","size":{"x":32,"y":1,"z":32}},{"blockCount":116,"bytes":3565,"file":"chunks/y094-z128-x032.json","offset":{"x":32,"y":94,"z":128},"requirements":{"minecraft:bricks":21,"minecraft:glass":31,"minecraft:polished_diorite":36,"minecraft:sandstone":13,"minecraft:stone_bricks":15},"sha256":"25ccf533dffa32ef77042ce4b930cba547dcfc5def2cbd7bb5901e5c3fd870bc","size":{"x":32,"y":1,"z":32}},{"blockCount":45,"bytes":1703,"file":"chunks/y094-z128-x064.json","offset":{"x":64,"y":94,"z":128},"requirements":{"minecraft:bricks":14,"minecraft:glass":16,"minecraft:oak_planks":1,"minecraft:sandstone":7,"minecraft:stone_bricks":7},"sha256":"15f88c5dcbb2b7ccd4effa20c8cdbfb61252c096bfac7c0cf06cafa2046b51b1","size":{"x":32,"y":1,"z":32}},{"blockCount":14,"bytes":1076,"file":"chunks/y094-z128-x096.json","offset":{"x":96,"y":94,"z":128},"requirements":{"minecraft:bricks":6,"minecraft:glass":3,"minecraft:oak_planks":1,"minecraft:sandstone":2,"minecraft:stone_bricks":2},"sha256":"f5c436089e0fe9403103cf8f10306664382d49842cf2c1d659d05fd03b0de405","size":{"x":32,"y":1,"z":32}},{"blockCount":35,"bytes":1534,"file":"chunks/y094-z128-x128.json","offset":{"x":128,"y":94,"z":128},"requirements":{"minecraft:bricks":13,"minecraft:glass":10,"minecraft:oak_planks":2,"minecraft:sandstone":5,"minecraft:stone_bricks":5},"sha256":"2090845a0a6d9c8a7dda1f50141783890ac78e27cc6a900881f506a08af37818","size":{"x":32,"y":1,"z":32}},{"blockCount":46,"bytes":1756,"file":"chunks/y094-z128-x160.json","offset":{"x":160,"y":94,"z":128},"requirements":{"minecraft:bricks":14,"minecraft:glass":18,"minecraft:sandstone":7,"minecraft:stone_bricks":7},"sha256":"f5db3826a7f3e51c77227058f017d16d346f62c29600d54436eb4204db762f8f","size":{"x":32,"y":1,"z":32}},{"blockCount":50,"bytes":1510,"file":"chunks/y094-z128-x192.json","offset":{"x":192,"y":94,"z":128},"requirements":{"minecraft:bricks":31,"minecraft:glass":11,"minecraft:sandstone":3,"minecraft:stone_bricks":5},"sha256":"6bd312f81d7c93995eebf95dd11be8806c2b9d06e5f857d764b2c8dd6c7cb08c","size":{"x":32,"y":1,"z":32}},{"blockCount":97,"bytes":2957,"file":"chunks/y094-z128-x224.json","offset":{"x":224,"y":94,"z":128},"requirements":{"minecraft:bricks":22,"minecraft:glass":19,"minecraft:polished_diorite":40,"minecraft:sandstone":12,"minecraft:stone_bricks":4},"sha256":"dd5d42fbb6dfb99f12732edda1fc5bbf3c69d1eba5dc9521ea670a98eb3f062c","size":{"x":32,"y":1,"z":32}},{"blockCount":31,"bytes":1305,"file":"chunks/y094-z160-x000.json","offset":{"x":0,"y":94,"z":160},"requirements":{"minecraft:polished_diorite":31},"sha256":"bbe2fefa8eefa40ed71a5b35948a16dd8ba2739a05d25f86f895b09e1f178259","size":{"x":32,"y":1,"z":32}},{"blockCount":111,"bytes":2705,"file":"chunks/y094-z160-x032.json","offset":{"x":32,"y":94,"z":160},"requirements":{"minecraft:polished_diorite":109,"minecraft:stone_bricks":2},"sha256":"24638f42f74fbe96de141a20f32665679f6db924a15b174f7df939f2f029ae69","size":{"x":32,"y":1,"z":32}},{"blockCount":117,"bytes":3055,"file":"chunks/y094-z160-x064.json","offset":{"x":64,"y":94,"z":160},"requirements":{"minecraft:polished_diorite":112,"minecraft:sandstone":1,"minecraft:stone_bricks":4},"sha256":"459e36e664ef347e9e50fb753c665c411484ccaa895b047870037439e96f611f","size":{"x":32,"y":1,"z":32}},{"blockCount":102,"bytes":3476,"file":"chunks/y094-z160-x096.json","offset":{"x":96,"y":94,"z":160},"requirements":{"minecraft:bricks":17,"minecraft:glass":15,"minecraft:oak_planks":2,"minecraft:polished_diorite":46,"minecraft:sandstone":11,"minecraft:stone_bricks":11},"sha256":"67ec7b9ea82471798e9e0ea1ecafa7462965399ccf42fb718a9c73b2a03f8862","size":{"x":32,"y":1,"z":32}},{"blockCount":146,"bytes":4317,"file":"chunks/y094-z160-x128.json","offset":{"x":128,"y":94,"z":160},"requirements":{"minecraft:bricks":15,"minecraft:glass":13,"minecraft:oak_planks":2,"minecraft:polished_diorite":91,"minecraft:sandstone":12,"minecraft:stone_bricks":13},"sha256":"f7e87be113d012a670c5a3cb835826c3ab313f94ac09706472355d2b2bcb12d0","size":{"x":32,"y":1,"z":32}},{"blockCount":125,"bytes":3351,"file":"chunks/y094-z160-x160.json","offset":{"x":160,"y":94,"z":160},"requirements":{"minecraft:polished_diorite":121,"minecraft:stone_bricks":4},"sha256":"f146f995a73c6b0afe19ae1f7b7470aa7f0e4e0a66ed7dae58cddb9815ebfeee","size":{"x":32,"y":1,"z":32}},{"blockCount":197,"bytes":4447,"file":"chunks/y094-z160-x192.json","offset":{"x":192,"y":94,"z":160},"requirements":{"minecraft:bricks":75,"minecraft:glass":12,"minecraft:polished_diorite":101,"minecraft:stone_bricks":9},"sha256":"132f7c5ce2d53d53b59c08be2c6a9e0735f3befac592d0c8663d5d9e87ea9605","size":{"x":32,"y":1,"z":32}},{"blockCount":98,"bytes":3084,"file":"chunks/y094-z160-x224.json","offset":{"x":224,"y":94,"z":160},"requirements":{"minecraft:bricks":55,"minecraft:glass":12,"minecraft:polished_diorite":31},"sha256":"69eb2565780c7e6c6a21e29b4e2ef1ba98e83426a24df594016e51c85b8dd72a","size":{"x":32,"y":1,"z":32}},{"blockCount":62,"bytes":1764,"file":"chunks/y094-z192-x064.json","offset":{"x":64,"y":94,"z":192},"requirements":{"minecraft:polished_diorite":62},"sha256":"9f910625313d5b9a512b7fe43c175085d5f60eb7c73fe783daa6e69207f76c11","size":{"x":32,"y":1,"z":32}},{"blockCount":128,"bytes":3465,"file":"chunks/y094-z192-x096.json","offset":{"x":96,"y":94,"z":192},"requirements":{"minecraft:bricks":22,"minecraft:glass":27,"minecraft:oak_planks":1,"minecraft:polished_diorite":54,"minecraft:sandstone":14,"minecraft:stone_bricks":10},"sha256":"eeb177c0db5a7c97965ceb48f6e619d9f10a8cf079e5a8b01bf85baa5bfad342","size":{"x":32,"y":1,"z":32}},{"blockCount":147,"bytes":3817,"file":"chunks/y094-z192-x128.json","offset":{"x":128,"y":94,"z":192},"requirements":{"minecraft:bricks":16,"minecraft:glass":16,"minecraft:oak_planks":1,"minecraft:polished_diorite":96,"minecraft:sandstone":8,"minecraft:stone_bricks":10},"sha256":"71707d3323b8c08c683af21f9f14b70ef86fce9799bf42dfd4e7f46e179a2c72","size":{"x":32,"y":1,"z":32}},{"blockCount":10,"bytes":1001,"file":"chunks/y094-z192-x160.json","offset":{"x":160,"y":94,"z":192},"requirements":{"minecraft:polished_diorite":10},"sha256":"8ad3ec1bc1f14e18e41b1459784e636c63626bd51cb2caed265fcbc78534819b","size":{"x":32,"y":1,"z":32}},{"blockCount":79,"bytes":2590,"file":"chunks/y095-z064-x064.json","offset":{"x":64,"y":95,"z":64},"requirements":{"minecraft:polished_diorite":59,"minecraft:stone_bricks":20},"sha256":"a7cdfc346b623a68f6b6fc26aa2ba7ab802465d935807d9d7d5c80b0fbbd9841","size":{"x":32,"y":1,"z":32}},{"blockCount":153,"bytes":3719,"file":"chunks/y095-z064-x096.json","offset":{"x":96,"y":95,"z":64},"requirements":{"minecraft:bricks":32,"minecraft:glass":30,"minecraft:oak_planks":1,"minecraft:polished_diorite":65,"minecraft:sandstone":14,"minecraft:stone_bricks":11},"sha256":"29065bc44b4244cc70ea7b41687168e5476fe1f87b1773ff8591bb091851f007","size":{"x":32,"y":1,"z":32}},{"blockCount":180,"bytes":4887,"file":"chunks/y095-z064-x128.json","offset":{"x":128,"y":95,"z":64},"requirements":{"minecraft:bricks":19,"minecraft:glass":20,"minecraft:oak_planks":1,"minecraft:polished_diorite":105,"minecraft:sandstone":9,"minecraft:stone_bricks":26},"sha256":"c1d6bad2924fafb5e20dfd968fe610c1a2dcf64cec54d5eec6a885e2eee16050","size":{"x":32,"y":1,"z":32}},{"blockCount":12,"bytes":1103,"file":"chunks/y095-z064-x160.json","offset":{"x":160,"y":95,"z":64},"requirements":{"minecraft:polished_diorite":7,"minecraft:stone_bricks":5},"sha256":"d81967e52cf3ead896015e56f81e7c5faf9aeaa1f5ed22b909fb28f3c8892676","size":{"x":32,"y":1,"z":32}},{"blockCount":9,"bytes":875,"file":"chunks/y095-z064-x192.json","offset":{"x":192,"y":95,"z":64},"requirements":{"minecraft:polished_diorite":9},"sha256":"3cd7e40242d3280f30a578a8c5a684de4b586b6c278dbab6e3bdce1be09dd52a","size":{"x":32,"y":1,"z":32}},{"blockCount":12,"bytes":915,"file":"chunks/y095-z064-x224.json","offset":{"x":224,"y":95,"z":64},"requirements":{"minecraft:polished_diorite":12},"sha256":"b6c828942376da3f519baacae594fcac48353ed2b7cd9a1c288cf4b05455b16b","size":{"x":32,"y":1,"z":32}},{"blockCount":52,"bytes":2022,"file":"chunks/y095-z096-x000.json","offset":{"x":0,"y":95,"z":96},"requirements":{"minecraft:polished_diorite":38,"minecraft:stone_bricks":14},"sha256":"3a0425a0832e53fe2bf8760c6f3bfebd568a3a1d507afbc1269168411d0ff4bd","size":{"x":32,"y":1,"z":32}},{"blockCount":164,"bytes":4607,"file":"chunks/y095-z096-x032.json","offset":{"x":32,"y":95,"z":96},"requirements":{"minecraft:bricks":11,"minecraft:glass":17,"minecraft:polished_diorite":106,"minecraft:sandstone":5,"minecraft:stone_bricks":25},"sha256":"03edef679f40f14ff325889dd8f5e61bff7a588155c8d494d825443a50b51e0c","size":{"x":32,"y":1,"z":32}},{"blockCount":153,"bytes":4339,"file":"chunks/y095-z096-x064.json","offset":{"x":64,"y":95,"z":96},"requirements":{"minecraft:bricks":14,"minecraft:glass":16,"minecraft:oak_planks":1,"minecraft:polished_diorite":87,"minecraft:sandstone":8,"minecraft:stone_bricks":27},"sha256":"2a05a5d5632c321b219f41540513b9f0bd28061e891b5193b66b11e3bf4a2f0a","size":{"x":32,"y":1,"z":32}},{"blockCount":91,"bytes":3224,"file":"chunks/y095-z096-x096.json","offset":{"x":96,"y":95,"z":96},"requirements":{"minecraft:bricks":19,"minecraft:glass":12,"minecraft:oak_planks":3,"minecraft:polished_diorite":38,"minecraft:sandstone":11,"minecraft:stone_bricks":8},"sha256":"b0dfa4e5814434bc575526c8bfd4185dc00b1e8556211765c05d44c32c8e51de","size":{"x":32,"y":1,"z":32}},{"blockCount":152,"bytes":4480,"file":"chunks/y095-z096-x128.json","offset":{"x":128,"y":95,"z":96},"requirements":{"minecraft:bricks":27,"minecraft:glass":19,"minecraft:oak_planks":4,"minecraft:polished_diorite":71,"minecraft:sandstone":15,"minecraft:stone_bricks":16},"sha256":"2cee9198651a5a0b15a26789edf15a1668dcf6aa1386a96a96e6672e36fd419b","size":{"x":32,"y":1,"z":32}},{"blockCount":173,"bytes":4941,"file":"chunks/y095-z096-x160.json","offset":{"x":160,"y":95,"z":96},"requirements":{"minecraft:bricks":14,"minecraft:glass":18,"minecraft:polished_diorite":102,"minecraft:sandstone":7,"minecraft:stone_bricks":32},"sha256":"f9d96ff2004f896533ebd6006acce2c665fb01185b485509052f8e760a91143b","size":{"x":32,"y":1,"z":32}},{"blockCount":250,"bytes":5500,"file":"chunks/y095-z096-x192.json","offset":{"x":192,"y":95,"z":96},"requirements":{"minecraft:bricks":115,"minecraft:glass":17,"minecraft:polished_diorite":90,"minecraft:sandstone":3,"minecraft:stone_bricks":25},"sha256":"c0204fd46d16feda7114862bfa6bd9d2e35fb52cc7916aa61efd523479b3aca7","size":{"x":32,"y":1,"z":32}},{"blockCount":134,"bytes":3592,"file":"chunks/y095-z096-x224.json","offset":{"x":224,"y":95,"z":96},"requirements":{"minecraft:bricks":74,"minecraft:glass":7,"minecraft:polished_diorite":49,"minecraft:sandstone":1,"minecraft:stone_bricks":3},"sha256":"23e6528f8d44906915fe385bdd3817e730e600b6a94eadb4ac780e88586e045d","size":{"x":32,"y":1,"z":32}},{"blockCount":66,"bytes":2169,"file":"chunks/y095-z128-x000.json","offset":{"x":0,"y":95,"z":128},"requirements":{"minecraft:polished_diorite":54,"minecraft:stone_bricks":12},"sha256":"76f66ef8732926b6b9aa65d04e4771c66381c4accd21bb4a3c9b964849f400bc","size":{"x":32,"y":1,"z":32}},{"blockCount":116,"bytes":3565,"file":"chunks/y095-z128-x032.json","offset":{"x":32,"y":95,"z":128},"requirements":{"minecraft:bricks":21,"minecraft:glass":31,"minecraft:polished_diorite":40,"minecraft:sandstone":13,"minecraft:stone_bricks":11},"sha256":"87a47fb93d2bb6900f9b9a98701de62a0f1de47f1394bd00577e4944481bd6e4","size":{"x":32,"y":1,"z":32}},{"blockCount":45,"bytes":1703,"file":"chunks/y095-z128-x064.json","offset":{"x":64,"y":95,"z":128},"requirements":{"minecraft:bricks":14,"minecraft:glass":16,"minecraft:oak_planks":1,"minecraft:sandstone":7,"minecraft:stone_bricks":7},"sha256":"dab7e3a3c1c92bf0de3d46c61edcb6e156d948f48066756a5f89176c77c883a3","size":{"x":32,"y":1,"z":32}},{"blockCount":13,"bytes":1038,"file":"chunks/y095-z128-x096.json","offset":{"x":96,"y":95,"z":128},"requirements":{"minecraft:bricks":6,"minecraft:glass":3,"minecraft:oak_planks":1,"minecraft:sandstone":2,"minecraft:stone_bricks":1},"sha256":"dae955e9a46119ecc4acc00e204e7c866cbeef7911134c507d30add5fb0135a8","size":{"x":32,"y":1,"z":32}},{"blockCount":34,"bytes":1496,"file":"chunks/y095-z128-x128.json","offset":{"x":128,"y":95,"z":128},"requirements":{"minecraft:bricks":13,"minecraft:glass":10,"minecraft:oak_planks":2,"minecraft:sandstone":5,"minecraft:stone_bricks":4},"sha256":"7a73a20e66ca356d950f9e369682d7ef46f2b42f7b529acf1f6e4be09b7eb092","size":{"x":32,"y":1,"z":32}},{"blockCount":46,"bytes":1756,"file":"chunks/y095-z128-x160.json","offset":{"x":160,"y":95,"z":128},"requirements":{"minecraft:bricks":14,"minecraft:glass":18,"minecraft:sandstone":7,"minecraft:stone_bricks":7},"sha256":"3099d234104238cc9d82cc92e8e94ecf9fa7eba3660846604b60c91f28f32a16","size":{"x":32,"y":1,"z":32}},{"blockCount":52,"bytes":1510,"file":"chunks/y095-z128-x192.json","offset":{"x":192,"y":95,"z":128},"requirements":{"minecraft:bricks":33,"minecraft:glass":11,"minecraft:sandstone":3,"minecraft:stone_bricks":5},"sha256":"e2acb117aa3522fe4faecb8bde7d1cb7f5e19eb9a32a65320a5be28e5cf907ec","size":{"x":32,"y":1,"z":32}},{"blockCount":105,"bytes":2919,"file":"chunks/y095-z128-x224.json","offset":{"x":224,"y":95,"z":128},"requirements":{"minecraft:bricks":29,"minecraft:glass":19,"minecraft:polished_diorite":44,"minecraft:sandstone":10,"minecraft:stone_bricks":3},"sha256":"debca7fe1fadf934e83638c82894421e236a21466bb5b603a48604a6b5828c3e","size":{"x":32,"y":1,"z":32}},{"blockCount":32,"bytes":1504,"file":"chunks/y095-z160-x000.json","offset":{"x":0,"y":95,"z":160},"requirements":{"minecraft:polished_diorite":22,"minecraft:stone_bricks":10},"sha256":"25a34a50c9b06d963de43ac3b3b3a063bc2936423cb521455b2fdaffceff9058","size":{"x":32,"y":1,"z":32}},{"blockCount":118,"bytes":3317,"file":"chunks/y095-z160-x032.json","offset":{"x":32,"y":95,"z":160},"requirements":{"minecraft:polished_diorite":98,"minecraft:stone_bricks":20},"sha256":"21925a19b79b2f5b0a624e81516f4f9f319671cc1d329f3cb8f2107636692d67","size":{"x":32,"y":1,"z":32}},{"blockCount":121,"bytes":3551,"file":"chunks/y095-z160-x064.json","offset":{"x":64,"y":95,"z":160},"requirements":{"minecraft:polished_diorite":96,"minecraft:sandstone":1,"minecraft:stone_bricks":24},"sha256":"22ad353f85a347800d22636af7b38d37b04cd2724b7abdf7e6216580a99fc810","size":{"x":32,"y":1,"z":32}},{"blockCount":101,"bytes":3457,"file":"chunks/y095-z160-x096.json","offset":{"x":96,"y":95,"z":160},"requirements":{"minecraft:bricks":17,"minecraft:glass":15,"minecraft:oak_planks":2,"minecraft:polished_diorite":46,"minecraft:sandstone":11,"minecraft:stone_bricks":10},"sha256":"14fb53239131e3e29813f8d5f205163973424760735456d87d9ab75ea797cabe","size":{"x":32,"y":1,"z":32}},{"blockCount":147,"bytes":4488,"file":"chunks/y095-z160-x128.json","offset":{"x":128,"y":95,"z":160},"requirements":{"minecraft:bricks":15,"minecraft:glass":13,"minecraft:oak_planks":2,"minecraft:polished_diorite":87,"minecraft:sandstone":12,"minecraft:stone_bricks":18},"sha256":"bbe4901f6d3bae5b54426c5e22eed26a7c6779c5d5f4a65b584dd1a1ce72e351","size":{"x":32,"y":1,"z":32}},{"blockCount":129,"bytes":3888,"file":"chunks/y095-z160-x160.json","offset":{"x":160,"y":95,"z":160},"requirements":{"minecraft:polished_diorite":103,"minecraft:stone_bricks":26},"sha256":"eda25b18daac1ff9b453ea506e9b7479b4bbcbb68e0e0319a2becf4864339ae0","size":{"x":32,"y":1,"z":32}},{"blockCount":207,"bytes":4941,"file":"chunks/y095-z160-x192.json","offset":{"x":192,"y":95,"z":160},"requirements":{"minecraft:bricks":82,"minecraft:glass":6,"minecraft:polished_diorite":99,"minecraft:stone_bricks":20},"sha256":"2e757918ff389a61412c0cd3b55a8beb1e4206d4b7db51f1891d48f487dada31","size":{"x":32,"y":1,"z":32}},{"blockCount":104,"bytes":3197,"file":"chunks/y095-z160-x224.json","offset":{"x":224,"y":95,"z":160},"requirements":{"minecraft:bricks":61,"minecraft:glass":6,"minecraft:polished_diorite":37},"sha256":"444c2f443537c37f4fcaea0a2562da111f6923c1d3e717c5c2df2d8b2d05932e","size":{"x":32,"y":1,"z":32}},{"blockCount":66,"bytes":2248,"file":"chunks/y095-z192-x064.json","offset":{"x":64,"y":95,"z":192},"requirements":{"minecraft:polished_diorite":50,"minecraft:stone_bricks":16},"sha256":"edd3a94ac47f77da4a175a684304549fb117ded9a3b0d4a5abebda774c358f81","size":{"x":32,"y":1,"z":32}},{"blockCount":133,"bytes":3275,"file":"chunks/y095-z192-x096.json","offset":{"x":96,"y":95,"z":192},"requirements":{"minecraft:bricks":28,"minecraft:glass":27,"minecraft:oak_planks":1,"minecraft:polished_diorite":57,"minecraft:sandstone":12,"minecraft:stone_bricks":8},"sha256":"934d4c7f92da1c62a2177fb5ecf635113301d663f1cc29b36815d80c5d426131","size":{"x":32,"y":1,"z":32}},{"blockCount":151,"bytes":4083,"file":"chunks/y095-z192-x128.json","offset":{"x":128,"y":95,"z":192},"requirements":{"minecraft:bricks":18,"minecraft:glass":16,"minecraft:oak_planks":1,"minecraft:polished_diorite":89,"minecraft:sandstone":7,"minecraft:stone_bricks":20},"sha256":"7191ba7db79e08a38d550432282e921dcbfc5e4767846e7cba6a2b97b36b480e","size":{"x":32,"y":1,"z":32}},{"blockCount":10,"bytes":1027,"file":"chunks/y095-z192-x160.json","offset":{"x":160,"y":95,"z":192},"requirements":{"minecraft:polished_diorite":6,"minecraft:stone_bricks":4},"sha256":"e226be1bc349fa10a8b5dd8c48a6a32983da1bca3a1f891882dfc56499e32835","size":{"x":32,"y":1,"z":32}},{"blockCount":66,"bytes":2666,"file":"chunks/y096-z064-x064.json","offset":{"x":64,"y":96,"z":64},"requirements":{"minecraft:polished_diorite":46,"minecraft:stone_bricks":20},"sha256":"f80d80032d3d3e968f9393fbe4cc696bab6958d6065d839682468402db766333","size":{"x":32,"y":1,"z":32}},{"blockCount":173,"bytes":4079,"file":"chunks/y096-z064-x096.json","offset":{"x":96,"y":96,"z":64},"requirements":{"minecraft:bricks":28,"minecraft:glass":30,"minecraft:oak_planks":1,"minecraft:polished_diorite":83,"minecraft:sandstone":19,"minecraft:stone_bricks":12},"sha256":"47f871744a7218d0364a99b330e5cd27acd70ed350756a12475d060c341f293f","size":{"x":32,"y":1,"z":32}},{"blockCount":189,"bytes":4979,"file":"chunks/y096-z064-x128.json","offset":{"x":128,"y":96,"z":64},"requirements":{"minecraft:bricks":18,"minecraft:glass":20,"minecraft:oak_planks":1,"minecraft:polished_diorite":112,"minecraft:sandstone":11,"minecraft:stone_bricks":27},"sha256":"29101e04ccec2de2b4327e75edf9d92d56ff7e7618f1f0bfb319497f303e1c4e","size":{"x":32,"y":1,"z":32}},{"blockCount":7,"bytes":908,"file":"chunks/y096-z064-x160.json","offset":{"x":160,"y":96,"z":64},"requirements":{"minecraft:polished_diorite":2,"minecraft:stone_bricks":5},"sha256":"2f82c4aaf220a1513574c85f77990904f25dda059436b5a73f7aeba216960cb1","size":{"x":32,"y":1,"z":32}},{"blockCount":19,"bytes":1029,"file":"chunks/y096-z064-x192.json","offset":{"x":192,"y":96,"z":64},"requirements":{"minecraft:polished_diorite":19},"sha256":"f659cf100c5c17a9710c41f6b882c3b2d4eeff98a82e780c2c3a91048bb12a8f","size":{"x":32,"y":1,"z":32}},{"blockCount":22,"bytes":1030,"file":"chunks/y096-z064-x224.json","offset":{"x":224,"y":96,"z":64},"requirements":{"minecraft:polished_diorite":22},"sha256":"1663488b4edce6c1dc4e2fc884771438d930bfa3e04d9ab90b9a3bcf9db73c26","size":{"x":32,"y":1,"z":32}},{"blockCount":42,"bytes":1927,"file":"chunks/y096-z096-x000.json","offset":{"x":0,"y":96,"z":96},"requirements":{"minecraft:polished_diorite":28,"minecraft:stone_bricks":14},"sha256":"aed683d7f4eda03ce830c1c9a4bc664121e5d77a60926a9dbd781c1596f2b970","size":{"x":32,"y":1,"z":32}},{"blockCount":160,"bytes":4702,"file":"chunks/y096-z096-x032.json","offset":{"x":32,"y":96,"z":96},"requirements":{"minecraft:bricks":11,"minecraft:glass":17,"minecraft:polished_diorite":100,"minecraft:sandstone":5,"minecraft:stone_bricks":27},"sha256":"2788b6b16779e7363d3eef0331e902fa7186c099929153687eaa7cb96f6e6b66","size":{"x":32,"y":1,"z":32}},{"blockCount":158,"bytes":4530,"file":"chunks/y096-z096-x064.json","offset":{"x":64,"y":96,"z":96},"requirements":{"minecraft:bricks":14,"minecraft:glass":16,"minecraft:oak_planks":1,"minecraft:polished_diorite":94,"minecraft:sandstone":8,"minecraft:stone_bricks":25},"sha256":"f315532e83d636fd5ba71ebeaa99e3a2d374ada42234d036c6c93dae3bdee994","size":{"x":32,"y":1,"z":32}},{"blockCount":98,"bytes":3224,"file":"chunks/y096-z096-x096.json","offset":{"x":96,"y":96,"z":96},"requirements":{"minecraft:bricks":19,"minecraft:glass":12,"minecraft:oak_planks":3,"minecraft:polished_diorite":45,"minecraft:sandstone":11,"minecraft:stone_bricks":8},"sha256":"6cc70baaaf568a5c22d9426da57fd39988e44e1a725a8f1d6befeafd13a0cf4f","size":{"x":32,"y":1,"z":32}},{"blockCount":167,"bytes":4574,"file":"chunks/y096-z096-x128.json","offset":{"x":128,"y":96,"z":96},"requirements":{"minecraft:bricks":27,"minecraft:glass":19,"minecraft:oak_planks":4,"minecraft:polished_diorite":86,"minecraft:sandstone":15,"minecraft:stone_bricks":16},"sha256":"b0ad45e51ed091c7974fc4e6e4cc446b0b97b8c42c121083257401b312d55529","size":{"x":32,"y":1,"z":32}},{"blockCount":169,"bytes":4943,"file":"chunks/y096-z096-x160.json","offset":{"x":160,"y":96,"z":96},"requirements":{"minecraft:bricks":14,"minecraft:glass":18,"minecraft:polished_diorite":98,"minecraft:sandstone":7,"minecraft:stone_bricks":32},"sha256":"8e6232f6f5556b94ab9e80f6bf2d803fa3cac8863572cd34d0368fce2b451966","size":{"x":32,"y":1,"z":32}},{"blockCount":268,"bytes":5371,"file":"chunks/y096-z096-x192.json","offset":{"x":192,"y":96,"z":96},"requirements":{"minecraft:bricks":122,"minecraft:glass":17,"minecraft:polished_diorite":101,"minecraft:sandstone":3,"minecraft:stone_bricks":25},"sha256":"a5f497823790dfaeb77cda09e88ad2d4cac2e6868e60e0ddad438a47dd18fe04","size":{"x":32,"y":1,"z":32}},{"blockCount":155,"bytes":3649,"file":"chunks/y096-z096-x224.json","offset":{"x":224,"y":96,"z":96},"requirements":{"minecraft:bricks":73,"minecraft:glass":7,"minecraft:polished_diorite":67,"minecraft:sandstone":1,"minecraft:stone_bricks":7},"sha256":"eaa45eca873e01e3471c274b9d7dff948cb23dd2eb22dbd4ef86046460415471","size":{"x":32,"y":1,"z":32}},{"blockCount":64,"bytes":2209,"file":"chunks/y096-z128-x000.json","offset":{"x":0,"y":96,"z":128},"requirements":{"minecraft:polished_diorite":52,"minecraft:stone_bricks":12},"sha256":"13aaa1ae7464e60340769e263eeda8ff197d769c2632a1965e3cfbca4d7ea176","size":{"x":32,"y":1,"z":32}},{"blockCount":127,"bytes":3641,"file":"chunks/y096-z128-x032.json","offset":{"x":32,"y":96,"z":128},"requirements":{"minecraft:bricks":21,"minecraft:glass":31,"minecraft:polished_diorite":43,"minecraft:sandstone":17,"minecraft:stone_bricks":15},"sha256":"7c119f22c414bc43499478faa3db283cd50576e374bd1eacafc8d76b551f5734","size":{"x":32,"y":1,"z":32}},{"blockCount":45,"bytes":1703,"file":"chunks/y096-z128-x064.json","offset":{"x":64,"y":96,"z":128},"requirements":{"minecraft:bricks":14,"minecraft:glass":16,"minecraft:oak_planks":1,"minecraft:sandstone":7,"minecraft:stone_bricks":7},"sha256":"df80c5700a09084f9166152027fe57284eb05e826daca2fd9841a95978915e53","size":{"x":32,"y":1,"z":32}},{"blockCount":13,"bytes":1038,"file":"chunks/y096-z128-x096.json","offset":{"x":96,"y":96,"z":128},"requirements":{"minecraft:bricks":6,"minecraft:glass":3,"minecraft:oak_planks":1,"minecraft:sandstone":2,"minecraft:stone_bricks":1},"sha256":"c5e1c4f65fc2541a06e2ca5b02a9bebc8b0566d40dd655b77d4c2989d59e21bd","size":{"x":32,"y":1,"z":32}},{"blockCount":34,"bytes":1496,"file":"chunks/y096-z128-x128.json","offset":{"x":128,"y":96,"z":128},"requirements":{"minecraft:bricks":13,"minecraft:glass":10,"minecraft:oak_planks":2,"minecraft:sandstone":5,"minecraft:stone_bricks":4},"sha256":"4577a1d8b89b2dec913e286159968dbca979e231eae663858a4ee7d2e5ed8071","size":{"x":32,"y":1,"z":32}},{"blockCount":46,"bytes":1756,"file":"chunks/y096-z128-x160.json","offset":{"x":160,"y":96,"z":128},"requirements":{"minecraft:bricks":14,"minecraft:glass":18,"minecraft:sandstone":7,"minecraft:stone_bricks":7},"sha256":"a32186ec574b1db7df926e6cd13d8d762e41903ab27cb8ecb47c5484f750b7ad","size":{"x":32,"y":1,"z":32}},{"blockCount":58,"bytes":1359,"file":"chunks/y096-z128-x192.json","offset":{"x":192,"y":96,"z":128},"requirements":{"minecraft:bricks":41,"minecraft:glass":11,"minecraft:sandstone":3,"minecraft:stone_bricks":3},"sha256":"8ff6e26c263eda515efc87b39a20aa03686bf7d8effcd7d63f2e822d8410cfeb","size":{"x":32,"y":1,"z":32}},{"blockCount":120,"bytes":3185,"file":"chunks/y096-z128-x224.json","offset":{"x":224,"y":96,"z":128},"requirements":{"minecraft:bricks":25,"minecraft:glass":19,"minecraft:polished_diorite":52,"minecraft:sandstone":17,"minecraft:stone_bricks":7},"sha256":"5222411361fda0a8089ceebe846d920367aa876dc24aa592392d256a245f7a4b","size":{"x":32,"y":1,"z":32}},{"blockCount":22,"bytes":1369,"file":"chunks/y096-z160-x000.json","offset":{"x":0,"y":96,"z":160},"requirements":{"minecraft:polished_diorite":12,"minecraft:stone_bricks":10},"sha256":"0b42bef84ade63ec2ac9372588f1458144dd4c321293c8b88d7e8fa44cde4bf8","size":{"x":32,"y":1,"z":32}},{"blockCount":109,"bytes":3356,"file":"chunks/y096-z160-x032.json","offset":{"x":32,"y":96,"z":160},"requirements":{"minecraft:polished_diorite":87,"minecraft:stone_bricks":22},"sha256":"9d75d3d66d67f9aa51bc61c6bd1f5deaad9b6763f6d880d71538509d5816f680","size":{"x":32,"y":1,"z":32}},{"blockCount":123,"bytes":3742,"file":"chunks/y096-z160-x064.json","offset":{"x":64,"y":96,"z":160},"requirements":{"minecraft:polished_diorite":100,"minecraft:sandstone":1,"minecraft:stone_bricks":22},"sha256":"0e8cf01465b9c1dd39789db1cf6795267c37de8873423eb5a30ead225188ca2c","size":{"x":32,"y":1,"z":32}},{"blockCount":110,"bytes":3457,"file":"chunks/y096-z160-x096.json","offset":{"x":96,"y":96,"z":160},"requirements":{"minecraft:bricks":17,"minecraft:glass":15,"minecraft:oak_planks":2,"minecraft:polished_diorite":55,"minecraft:sandstone":11,"minecraft:stone_bricks":10},"sha256":"b01127fc41723dc11f2df448057dc82b9803a61f6cd4aa8385f71ad428336df3","size":{"x":32,"y":1,"z":32}},{"blockCount":162,"bytes":4563,"file":"chunks/y096-z160-x128.json","offset":{"x":128,"y":96,"z":160},"requirements":{"minecraft:bricks":15,"minecraft:glass":13,"minecraft:oak_planks":2,"minecraft:polished_diorite":102,"minecraft:sandstone":12,"minecraft:stone_bricks":18},"sha256":"ee54fddd38551396fe8966e60df0965f93a48decf0f3bbaa853c8de6cba4c249","size":{"x":32,"y":1,"z":32}},{"blockCount":124,"bytes":3849,"file":"chunks/y096-z160-x160.json","offset":{"x":160,"y":96,"z":160},"requirements":{"minecraft:polished_diorite":98,"minecraft:stone_bricks":26},"sha256":"2dba2a31c70de36c5e1b310d4580a4ad82e0687ed5fb305eb6ce98134d712071","size":{"x":32,"y":1,"z":32}},{"blockCount":229,"bytes":5096,"file":"chunks/y096-z160-x192.json","offset":{"x":192,"y":96,"z":160},"requirements":{"minecraft:bricks":81,"minecraft:glass":6,"minecraft:polished_diorite":120,"minecraft:stone_bricks":22},"sha256":"3c03dea4c5bae61b1afe11ad4e0a51f97bf2c755931641cbf25b94d8cbefd977","size":{"x":32,"y":1,"z":32}},{"blockCount":126,"bytes":3312,"file":"chunks/y096-z160-x224.json","offset":{"x":224,"y":96,"z":160},"requirements":{"minecraft:bricks":61,"minecraft:glass":6,"minecraft:polished_diorite":59},"sha256":"92e7d4b5845fe4e92b7c6e64a8c345abda61b80faad19fa0bafcaab051ce2db7","size":{"x":32,"y":1,"z":32}},{"blockCount":56,"bytes":2324,"file":"chunks/y096-z192-x064.json","offset":{"x":64,"y":96,"z":192},"requirements":{"minecraft:polished_diorite":40,"minecraft:stone_bricks":16},"sha256":"66e39e48a038cc53e4a60009b37bef9d65bcc06fe7dd4d48e62383f411924ede","size":{"x":32,"y":1,"z":32}},{"blockCount":151,"bytes":3636,"file":"chunks/y096-z192-x096.json","offset":{"x":96,"y":96,"z":192},"requirements":{"minecraft:bricks":24,"minecraft:glass":27,"minecraft:oak_planks":1,"minecraft:polished_diorite":73,"minecraft:sandstone":17,"minecraft:stone_bricks":9},"sha256":"ba861aace0133222be988588fb6d9506ad092a4d11e6f24f56153caeb9368f95","size":{"x":32,"y":1,"z":32}},{"blockCount":160,"bytes":4213,"file":"chunks/y096-z192-x128.json","offset":{"x":128,"y":96,"z":192},"requirements":{"minecraft:bricks":17,"minecraft:glass":16,"minecraft:oak_planks":1,"minecraft:polished_diorite":96,"minecraft:sandstone":9,"minecraft:stone_bricks":21},"sha256":"fbc570f89c8aedc3d041c48813618f56273195c209d70d66dba4cb7b097a268e","size":{"x":32,"y":1,"z":32}},{"blockCount":6,"bytes":871,"file":"chunks/y096-z192-x160.json","offset":{"x":160,"y":96,"z":192},"requirements":{"minecraft:polished_diorite":2,"minecraft:stone_bricks":4},"sha256":"81ccbd2c3efc08ca386d6ca85e6053cea1ceab995f2f1a6853ecf9ab88347994","size":{"x":32,"y":1,"z":32}},{"blockCount":91,"bytes":3222,"file":"chunks/y097-z064-x064.json","offset":{"x":64,"y":97,"z":64},"requirements":{"minecraft:polished_diorite":41,"minecraft:stone_bricks":50},"sha256":"eea6a7cb384105f0a89a6b45ef54345742c0f2b5845228ccffba7505244e3d26","size":{"x":32,"y":1,"z":32}},{"blockCount":186,"bytes":4327,"file":"chunks/y097-z064-x096.json","offset":{"x":96,"y":97,"z":64},"requirements":{"minecraft:bricks":28,"minecraft:glass":33,"minecraft:oak_planks":1,"minecraft:polished_diorite":59,"minecraft:sandstone":18,"minecraft:stone_bricks":47},"sha256":"1daa1614071e3b4d29b7cfa3d3a7918ef6792e078be826ef0c3133937c1de42e","size":{"x":32,"y":1,"z":32}},{"blockCount":220,"bytes":5873,"file":"chunks/y097-z064-x128.json","offset":{"x":128,"y":97,"z":64},"requirements":{"minecraft:bricks":19,"minecraft:glass":20,"minecraft:oak_planks":1,"minecraft:polished_diorite":86,"minecraft:sandstone":9,"minecraft:stone_bricks":85},"sha256":"da2b95ad7a4b1e5ac5026ffc80c5e13961d4d13ec34219e1a0dd87aba9d02695","size":{"x":32,"y":1,"z":32}},{"blockCount":12,"bytes":909,"file":"chunks/y097-z064-x160.json","offset":{"x":160,"y":97,"z":64},"requirements":{"minecraft:polished_diorite":2,"minecraft:stone_bricks":10},"sha256":"695c96ec44203e9b70ff89cd0c68fa58bf928f874da81c6d9e20721928a0b01d","size":{"x":32,"y":1,"z":32}},{"blockCount":22,"bytes":1190,"file":"chunks/y097-z064-x192.json","offset":{"x":192,"y":97,"z":64},"requirements":{"minecraft:polished_diorite":10,"minecraft:stone_bricks":12},"sha256":"452ffb66f6002372dd58821938f5d6e13a5adba3e72702c61802d8136ab4a150","size":{"x":32,"y":1,"z":32}},{"blockCount":27,"bytes":1286,"file":"chunks/y097-z064-x224.json","offset":{"x":224,"y":97,"z":64},"requirements":{"minecraft:polished_diorite":11,"minecraft:stone_bricks":16},"sha256":"5db5e688a75e6486dca7d8d01bdcb012e9d0783e837039e49247c78481659bfc","size":{"x":32,"y":1,"z":32}},{"blockCount":57,"bytes":2214,"file":"chunks/y097-z096-x000.json","offset":{"x":0,"y":97,"z":96},"requirements":{"minecraft:polished_diorite":26,"minecraft:stone_bricks":31},"sha256":"40da597c5dc4c39121ed34107429eabf3a2438e95e185e0c6f379d85b0be0acd","size":{"x":32,"y":1,"z":32}},{"blockCount":197,"bytes":5347,"file":"chunks/y097-z096-x032.json","offset":{"x":32,"y":97,"z":96},"requirements":{"minecraft:bricks":11,"minecraft:glass":16,"minecraft:polished_diorite":87,"minecraft:sandstone":6,"minecraft:stone_bricks":77},"sha256":"4b9af6a03337e9338940ad24b598506a1eef353aeb16a958e92a65ce86bb7471","size":{"x":32,"y":1,"z":32}},{"blockCount":187,"bytes":4837,"file":"chunks/y097-z096-x064.json","offset":{"x":64,"y":97,"z":96},"requirements":{"minecraft:bricks":14,"minecraft:glass":16,"minecraft:oak_planks":1,"minecraft:polished_diorite":74,"minecraft:sandstone":8,"minecraft:stone_bricks":74},"sha256":"8f9eb3e19cecab58d33df6b4ff35f7286dfe0d027629e0bea882606ad0e872c6","size":{"x":32,"y":1,"z":32}},{"blockCount":102,"bytes":3434,"file":"chunks/y097-z096-x096.json","offset":{"x":96,"y":97,"z":96},"requirements":{"minecraft:bricks":19,"minecraft:glass":12,"minecraft:oak_planks":3,"minecraft:polished_diorite":37,"minecraft:sandstone":11,"minecraft:stone_bricks":20},"sha256":"df60602b3f333ad4d79488cdaf009f9ed3c9d878fbd49c3aae39149ca12b12e9","size":{"x":32,"y":1,"z":32}},{"blockCount":182,"bytes":4936,"file":"chunks/y097-z096-x128.json","offset":{"x":128,"y":97,"z":96},"requirements":{"minecraft:bricks":27,"minecraft:glass":19,"minecraft:oak_planks":4,"minecraft:polished_diorite":67,"minecraft:sandstone":15,"minecraft:stone_bricks":50},"sha256":"c0cbb3e265f5b8e4273f37df996efbcdb0f7cf70a54077f41ec475aed2f8af15","size":{"x":32,"y":1,"z":32}},{"blockCount":204,"bytes":5288,"file":"chunks/y097-z096-x160.json","offset":{"x":160,"y":97,"z":96},"requirements":{"minecraft:bricks":14,"minecraft:glass":18,"minecraft:polished_diorite":81,"minecraft:sandstone":7,"minecraft:stone_bricks":84},"sha256":"f600048cc68cf49062cbdaa335f53712fa07ebf51c683fd29111fba642f89b62","size":{"x":32,"y":1,"z":32}},{"blockCount":289,"bytes":6051,"file":"chunks/y097-z096-x192.json","offset":{"x":192,"y":97,"z":96},"requirements":{"minecraft:bricks":114,"minecraft:glass":20,"minecraft:polished_diorite":74,"minecraft:sandstone":5,"minecraft:stone_bricks":76},"sha256":"5a3afde4c99706ce19b1d8c0a453c3e867a842b7508d41b7eeb3c6b3c1fd0ddd","size":{"x":32,"y":1,"z":32}},{"blockCount":157,"bytes":3955,"file":"chunks/y097-z096-x224.json","offset":{"x":224,"y":97,"z":96},"requirements":{"minecraft:bricks":70,"minecraft:glass":10,"minecraft:polished_diorite":45,"minecraft:sandstone":1,"minecraft:stone_bricks":31},"sha256":"6ad60d986a777866291ed9dbccce0b864b4a77543c3f32d5b087e59e5d0898cb","size":{"x":32,"y":1,"z":32}},{"blockCount":77,"bytes":2573,"file":"chunks/y097-z128-x000.json","offset":{"x":0,"y":97,"z":128},"requirements":{"minecraft:polished_diorite":49,"minecraft:stone_bricks":28},"sha256":"20a03646b5fd7d6e17a2e7d91d00a11d46d26c8ff4fdb03b1ba15367cb90bcad","size":{"x":32,"y":1,"z":32}},{"blockCount":139,"bytes":4038,"file":"chunks/y097-z128-x032.json","offset":{"x":32,"y":97,"z":128},"requirements":{"minecraft:bricks":21,"minecraft:glass":26,"minecraft:polished_diorite":46,"minecraft:sandstone":18,"minecraft:stone_bricks":28},"sha256":"c39f24499b2ebe5c6c800edc1fbae3317745026b525bfe415d3d275ffeea05a9","size":{"x":32,"y":1,"z":32}},{"blockCount":45,"bytes":1703,"file":"chunks/y097-z128-x064.json","offset":{"x":64,"y":97,"z":128},"requirements":{"minecraft:bricks":14,"minecraft:glass":16,"minecraft:oak_planks":1,"minecraft:sandstone":7,"minecraft:stone_bricks":7},"sha256":"b4fc8c9e891da7e45f721cafea837c8b05e6869922a582e978b776b37ff3f3d5","size":{"x":32,"y":1,"z":32}},{"blockCount":13,"bytes":1038,"file":"chunks/y097-z128-x096.json","offset":{"x":96,"y":97,"z":128},"requirements":{"minecraft:bricks":6,"minecraft:glass":3,"minecraft:oak_planks":1,"minecraft:sandstone":2,"minecraft:stone_bricks":1},"sha256":"a202a30b6d9fe89524d74f2e002badee074beb9e24e7b6440f753829fde68f4c","size":{"x":32,"y":1,"z":32}},{"blockCount":34,"bytes":1496,"file":"chunks/y097-z128-x128.json","offset":{"x":128,"y":97,"z":128},"requirements":{"minecraft:bricks":13,"minecraft:glass":10,"minecraft:oak_planks":2,"minecraft:sandstone":5,"minecraft:stone_bricks":4},"sha256":"2c7447cc13b94105e5d61ab78a04ead5bbaddd91d91e4bf8e7aa679d760b1e46","size":{"x":32,"y":1,"z":32}},{"blockCount":46,"bytes":1756,"file":"chunks/y097-z128-x160.json","offset":{"x":160,"y":97,"z":128},"requirements":{"minecraft:bricks":14,"minecraft:glass":18,"minecraft:sandstone":7,"minecraft:stone_bricks":7},"sha256":"30b601e60e487165dee1713dae641cf220646c83ca8c0a392957c68606d341a5","size":{"x":32,"y":1,"z":32}},{"blockCount":56,"bytes":1585,"file":"chunks/y097-z128-x192.json","offset":{"x":192,"y":97,"z":128},"requirements":{"minecraft:bricks":35,"minecraft:glass":11,"minecraft:sandstone":5,"minecraft:stone_bricks":5},"sha256":"adfcdf1348fa9039e8c0134870a68ad231b2438f33f3d9c207519028971abc84","size":{"x":32,"y":1,"z":32}},{"blockCount":122,"bytes":3262,"file":"chunks/y097-z128-x224.json","offset":{"x":224,"y":97,"z":128},"requirements":{"minecraft:bricks":28,"minecraft:glass":22,"minecraft:polished_diorite":43,"minecraft:sandstone":14,"minecraft:stone_bricks":15},"sha256":"d240bb6364d03b45655e9de97c389bb6e93b69a12656acf7cb0918411198840a","size":{"x":32,"y":1,"z":32}},{"blockCount":31,"bytes":1522,"file":"chunks/y097-z160-x000.json","offset":{"x":0,"y":97,"z":160},"requirements":{"minecraft:polished_diorite":11,"minecraft:stone_bricks":20},"sha256":"204bf2e7778cdc6c1f567fb17cdb5dbd38f0e4ca30679fdf6b7383ce89f9ffc0","size":{"x":32,"y":1,"z":32}},{"blockCount":138,"bytes":3833,"file":"chunks/y097-z160-x032.json","offset":{"x":32,"y":97,"z":160},"requirements":{"minecraft:polished_diorite":77,"minecraft:stone_bricks":61},"sha256":"e166e16d2aa54f286488a609b7d26a08cb10272d7ebcea0a847c9539d3a3cf58","size":{"x":32,"y":1,"z":32}},{"blockCount":157,"bytes":4163,"file":"chunks/y097-z160-x064.json","offset":{"x":64,"y":97,"z":160},"requirements":{"minecraft:polished_diorite":79,"minecraft:sandstone":1,"minecraft:stone_bricks":77},"sha256":"7043049e93d6082752613c72cfcc5f26c7fe7f2cfd45dda332752dc209bc8633","size":{"x":32,"y":1,"z":32}},{"blockCount":116,"bytes":3742,"file":"chunks/y097-z160-x096.json","offset":{"x":96,"y":97,"z":160},"requirements":{"minecraft:bricks":17,"minecraft:glass":15,"minecraft:oak_planks":2,"minecraft:polished_diorite":45,"minecraft:sandstone":11,"minecraft:stone_bricks":26},"sha256":"6d70d36d967507cbb1d3019d6a1871d77ca76027151521c989852bbc6fd4aa71","size":{"x":32,"y":1,"z":32}},{"blockCount":183,"bytes":5096,"file":"chunks/y097-z160-x128.json","offset":{"x":128,"y":97,"z":160},"requirements":{"minecraft:bricks":15,"minecraft:glass":13,"minecraft:oak_planks":2,"minecraft:polished_diorite":79,"minecraft:sandstone":12,"minecraft:stone_bricks":62},"sha256":"bf29d55eefb5d8df65a78f3bc80bf4d03b25e84b06376e0e842e52b22935a7f7","size":{"x":32,"y":1,"z":32}},{"blockCount":160,"bytes":4176,"file":"chunks/y097-z160-x160.json","offset":{"x":160,"y":97,"z":160},"requirements":{"minecraft:polished_diorite":81,"minecraft:stone_bricks":79},"sha256":"8597ac0005f45d18d607469156d900e517687250e00c22f2d26b752e76a6586a","size":{"x":32,"y":1,"z":32}},{"blockCount":255,"bytes":5684,"file":"chunks/y097-z160-x192.json","offset":{"x":192,"y":97,"z":160},"requirements":{"minecraft:bricks":79,"minecraft:glass":9,"minecraft:polished_diorite":84,"minecraft:stone_bricks":83},"sha256":"9d4120cf69c4818e2a4490729d900b235a0f6685caab562d9a29f0f0067d24a9","size":{"x":32,"y":1,"z":32}},{"blockCount":132,"bytes":3720,"file":"chunks/y097-z160-x224.json","offset":{"x":224,"y":97,"z":160},"requirements":{"minecraft:bricks":58,"minecraft:glass":9,"minecraft:polished_diorite":33,"minecraft:stone_bricks":32},"sha256":"8f45a4e0751903e1093e1aa373ed957a77e4cb89b3c9a28c1173bc46be35ec46","size":{"x":32,"y":1,"z":32}},{"blockCount":76,"bytes":2783,"file":"chunks/y097-z192-x064.json","offset":{"x":64,"y":97,"z":192},"requirements":{"minecraft:polished_diorite":36,"minecraft:stone_bricks":40},"sha256":"a2826bc57db5d39a5932d384471ac022bdaa5d5332567a2a492b96a7a15bf191","size":{"x":32,"y":1,"z":32}},{"blockCount":162,"bytes":3771,"file":"chunks/y097-z192-x096.json","offset":{"x":96,"y":97,"z":192},"requirements":{"minecraft:bricks":24,"minecraft:glass":30,"minecraft:oak_planks":1,"minecraft:polished_diorite":52,"minecraft:sandstone":16,"minecraft:stone_bricks":39},"sha256":"66ea03513a7705754ba1b3b341403bb8114ce9e171de52563231dacbdf325737","size":{"x":32,"y":1,"z":32}},{"blockCount":185,"bytes":4938,"file":"chunks/y097-z192-x128.json","offset":{"x":128,"y":97,"z":192},"requirements":{"minecraft:bricks":18,"minecraft:glass":16,"minecraft:oak_planks":1,"minecraft:polished_diorite":74,"minecraft:sandstone":7,"minecraft:stone_bricks":69},"sha256":"be7e20124d39cb3b8dac98f38ec0a97e75a3eef5e5c4e09ec503d905ae31f7db","size":{"x":32,"y":1,"z":32}},{"blockCount":10,"bytes":871,"file":"chunks/y097-z192-x160.json","offset":{"x":160,"y":97,"z":192},"requirements":{"minecraft:polished_diorite":2,"minecraft:stone_bricks":8},"sha256":"6a2833ea65d6c90563a3c2dcd57c01051775d276f55a7e80ec3fe9ab4e1298ef","size":{"x":32,"y":1,"z":32}},{"blockCount":101,"bytes":3821,"file":"chunks/y098-z064-x064.json","offset":{"x":64,"y":98,"z":64},"requirements":{"minecraft:glass":14,"minecraft:polished_diorite":53,"minecraft:stone_bricks":34},"sha256":"2cc218f27dc3f2c1d4656c2df89e838132bfe6fdece8c2aea3e6a87ea041bf47","size":{"x":32,"y":1,"z":32}},{"blockCount":170,"bytes":4270,"file":"chunks/y098-z064-x096.json","offset":{"x":96,"y":98,"z":64},"requirements":{"minecraft:bricks":25,"minecraft:glass":33,"minecraft:oak_planks":1,"minecraft:polished_diorite":67,"minecraft:sandstone":18,"minecraft:stone_bricks":26},"sha256":"e424a68ddbd9053a41dead33d8f9843786c3f8d7fb3de87c4cb5b6b36efa5f13","size":{"x":32,"y":1,"z":32}},{"blockCount":220,"bytes":6169,"file":"chunks/y098-z064-x128.json","offset":{"x":128,"y":98,"z":64},"requirements":{"minecraft:bricks":18,"minecraft:glass":34,"minecraft:oak_planks":1,"minecraft:polished_diorite":105,"minecraft:sandstone":10,"minecraft:stone_bricks":52},"sha256":"c431f789ddbfd564ffe710ace0a1f5a794846ac11b07b7d169f984246d5d33c3","size":{"x":32,"y":1,"z":32}},{"blockCount":12,"bytes":1003,"file":"chunks/y098-z064-x160.json","offset":{"x":160,"y":98,"z":64},"requirements":{"minecraft:polished_diorite":5,"minecraft:stone_bricks":7},"sha256":"f2c5750d0ed30d6a4c387bc5b0ce4520b8b32772413f3737865bdbac3879d2f6","size":{"x":32,"y":1,"z":32}},{"blockCount":24,"bytes":1189,"file":"chunks/y098-z064-x192.json","offset":{"x":192,"y":98,"z":64},"requirements":{"minecraft:polished_diorite":17,"minecraft:stone_bricks":7},"sha256":"77c438d5440437a1ccaefe9610d45ca1e26e7f4292704daff02807c90b50dcaf","size":{"x":32,"y":1,"z":32}},{"blockCount":29,"bytes":1285,"file":"chunks/y098-z064-x224.json","offset":{"x":224,"y":98,"z":64},"requirements":{"minecraft:polished_diorite":21,"minecraft:stone_bricks":8},"sha256":"9365362de18a2bd8f8cec662992eb75034b0978e241c97a0735b4fb6e3bfa5c6","size":{"x":32,"y":1,"z":32}}],"schema":1}
