{"entries":[{"blockCount":81,"bytes":2714,"file":"chunks/y098-z096-x000.json","offset":{"x":0,"y":98,"z":96},"requirements":{"minecraft:glass":27,"minecraft:polished_diorite":33,"minecraft:stone_bricks":21},"sha256":"0e83ce4f0190a184237dc3c91a81b1182bb5d9922acd3537f2c76f20d53f58ea","size":{"x":32,"y":1,"z":32}},{"blockCount":200,"bytes":5460,"file":"chunks/y098-z096-x032.json","offset":{"x":32,"y":98,"z":96},"requirements":{"minecraft:bricks":11,"minecraft:glass":33,"minecraft:polished_diorite":103,"minecraft:sandstone":5,"minecraft:stone_bricks":48},"sha256":"643d552b0ccfbb4dca2d6d19f08ab072448bf90873c00791a948222af98707ac","size":{"x":32,"y":1,"z":32}},{"blockCount":189,"bytes":5196,"file":"chunks/y098-z096-x064.json","offset":{"x":64,"y":98,"z":96},"requirements":{"minecraft:bricks":14,"minecraft:glass":30,"minecraft:oak_planks":1,"minecraft:polished_diorite":88,"minecraft:sandstone":8,"minecraft:stone_bricks":48},"sha256":"ebf8834b3b4656a0d81f1cb661962615a110dba74a1351204ed27011c0ac9cf5","size":{"x":32,"y":1,"z":32}},{"blockCount":98,"bytes":3320,"file":"chunks/y098-z096-x096.json","offset":{"x":96,"y":98,"z":96},"requirements":{"minecraft:bricks":19,"minecraft:glass":12,"minecraft:oak_planks":3,"minecraft:polished_diorite":40,"minecraft:sandstone":11,"minecraft:stone_bricks":13},"sha256":"f26403c99115f79d74d753a546ad26acb1406fe69104c3b23d8237b8fb9e05d8","size":{"x":32,"y":1,"z":32}},{"blockCount":179,"bytes":5034,"file":"chunks/y098-z096-x128.json","offset":{"x":128,"y":98,"z":96},"requirements":{"minecraft:bricks":27,"minecraft:glass":25,"minecraft:oak_planks":4,"minecraft:polished_diorite":77,"minecraft:sandstone":15,"minecraft:stone_bricks":31},"sha256":"15181461c056f6dda18c20213c4196faac5158c5bd6fbdaeba511b48dc3f3e7d","size":{"x":32,"y":1,"z":32}},{"blockCount":206,"bytes":5570,"file":"chunks/y098-z096-x160.json","offset":{"x":160,"y":98,"z":96},"requirements":{"minecraft:bricks":14,"minecraft:glass":33,"minecraft:polished_diorite":98,"minecraft:sandstone":7,"minecraft:stone_bricks":54},"sha256":"a4cfe1c6cfc020322f7f0701f3d8548a5eba5cd17d220f2d99be52774895209f","size":{"x":32,"y":1,"z":32}},{"blockCount":280,"bytes":6015,"file":"chunks/y098-z096-x192.json","offset":{"x":192,"y":98,"z":96},"requirements":{"minecraft:bricks":115,"minecraft:glass":24,"minecraft:polished_diorite":88,"minecraft:sandstone":3,"minecraft:stone_bricks":50},"sha256":"b28f84468fc607ff56c8a23dc0f4e24237aac3b890a33b4eacd4f0c0e293d382","size":{"x":32,"y":1,"z":32}},{"blockCount":154,"bytes":3916,"file":"chunks/y098-z096-x224.json","offset":{"x":224,"y":98,"z":96},"requirements":{"minecraft:bricks":71,"minecraft:glass":8,"minecraft:polished_diorite":55,"minecraft:sandstone":1,"minecraft:stone_bricks":19},"sha256":"893000a57fac66cc00d37771a05d8c2336a3fc75409cee087da0fe2f9a09adb5","size":{"x":32,"y":1,"z":32}},{"blockCount":85,"bytes":2918,"file":"chunks/y098-z128-x000.json","offset":{"x":0,"y":98,"z":128},"requirements":{"minecraft:glass":10,"minecraft:polished_diorite":53,"minecraft:stone_bricks":22},"sha256":"dbee1a058c1138555881571fd822198d71bee719c45aab5e35df38594d32d27b","size":{"x":32,"y":1,"z":32}},{"blockCount":139,"bytes":3830,"file":"chunks/y098-z128-x032.json","offset":{"x":32,"y":98,"z":128},"requirements":{"minecraft:bricks":25,"minecraft:glass":29,"minecraft:polished_diorite":48,"minecraft:sandstone":15,"minecraft:stone_bricks":22},"sha256":"bab186ec5b335293ad103be7f404e9bc711ecb45abf25eba3609eb53e87a556c","size":{"x":32,"y":1,"z":32}},{"blockCount":45,"bytes":1703,"file":"chunks/y098-z128-x064.json","offset":{"x":64,"y":98,"z":128},"requirements":{"minecraft:bricks":14,"minecraft:glass":16,"minecraft:oak_planks":1,"minecraft:sandstone":7,"minecraft:stone_bricks":7},"sha256":"7b1e83591d07834949484ee4c10e8d6b524e9f415599d794c72c8e7d808ebd43","size":{"x":32,"y":1,"z":32}},{"blockCount":14,"bytes":1000,"file":"chunks/y098-z128-x096.json","offset":{"x":96,"y":98,"z":128},"requirements":{"minecraft:bricks":7,"minecraft:glass":3,"minecraft:oak_planks":1,"minecraft:sandstone":2,"minecraft:stone_bricks":1},"sha256":"2c533d6553e1f58c074e1224b78d3fedc3342cb71ec1f9ed24f7fdf2c01aa8b4","size":{"x":32,"y":1,"z":32}},{"blockCount":34,"bytes":1496,"file":"chunks/y098-z128-x128.json","offset":{"x":128,"y":98,"z":128},"requirements":{"minecraft:bricks":13,"minecraft:glass":10,"minecraft:oak_planks":2,"minecraft:sandstone":5,"minecraft:stone_bricks":4},"sha256":"a150b107fb98c0441c55fd39cbd24b4d280112ede1e7dc3d835b2bd8f9096847","size":{"x":32,"y":1,"z":32}},{"blockCount":46,"bytes":1756,"file":"chunks/y098-z128-x160.json","offset":{"x":160,"y":98,"z":128},"requirements":{"minecraft:bricks":14,"minecraft:glass":18,"minecraft:sandstone":7,"minecraft:stone_bricks":7},"sha256":"d0c784abed7d41392f90c56ec8e8322db93f6cf69bacacd7ab148d27940d4b8e","size":{"x":32,"y":1,"z":32}},{"blockCount":49,"bytes":1472,"file":"chunks/y098-z128-x192.json","offset":{"x":192,"y":98,"z":128},"requirements":{"minecraft:bricks":30,"minecraft:glass":11,"minecraft:sandstone":3,"minecraft:stone_bricks":5},"sha256":"c6b4345f518c2016c25cfda278b19f84f4160544c2cc5866cf8fecbf921a5780","size":{"x":32,"y":1,"z":32}},{"blockCount":110,"bytes":3185,"file":"chunks/y098-z128-x224.json","offset":{"x":224,"y":98,"z":128},"requirements":{"minecraft:bricks":24,"minecraft:glass":21,"minecraft:polished_diorite":42,"minecraft:sandstone":15,"minecraft:stone_bricks":8},"sha256":"e7b1057d46f60c02cf7eb6891af87045dc5147a21052802ba876b2ebf0bbeaae","size":{"x":32,"y":1,"z":32}},{"blockCount":48,"bytes":1870,"file":"chunks/y098-z160-x000.json","offset":{"x":0,"y":98,"z":160},"requirements":{"minecraft:glass":19,"minecraft:polished_diorite":14,"minecraft:stone_bricks":15},"sha256":"106b49f0ad301de9d393ddaf4f3006a46d2bbb3dbbbdb82647d6300edf100156","size":{"x":32,"y":1,"z":32}},{"blockCount":145,"bytes":4061,"file":"chunks/y098-z160-x032.json","offset":{"x":32,"y":98,"z":160},"requirements":{"minecraft:glass":16,"minecraft:polished_diorite":89,"minecraft:stone_bricks":40},"sha256":"ca714aa9633714c03ce3bdc0017e7b4df475356fcfeec8388b008c73591c370b","size":{"x":32,"y":1,"z":32}},{"blockCount":163,"bytes":4697,"file":"chunks/y098-z160-x064.json","offset":{"x":64,"y":98,"z":160},"requirements":{"minecraft:glass":18,"minecraft:polished_diorite":97,"minecraft:sandstone":1,"minecraft:stone_bricks":47},"sha256":"b18e0187d0dcfbf8a69e44169cffb84b19040ebb6270107adc9587e19f0232bb","size":{"x":32,"y":1,"z":32}},{"blockCount":110,"bytes":3590,"file":"chunks/y098-z160-x096.json","offset":{"x":96,"y":98,"z":160},"requirements":{"minecraft:bricks":17,"minecraft:glass":15,"minecraft:oak_planks":2,"minecraft:polished_diorite":49,"minecraft:sandstone":11,"minecraft:stone_bricks":16},"sha256":"7855e8ef6f8bb50256d22b31e6401fae80be41510e09000d4b17c1507d7ef0f9","size":{"x":32,"y":1,"z":32}},{"blockCount":182,"bytes":5291,"file":"chunks/y098-z160-x128.json","offset":{"x":128,"y":98,"z":160},"requirements":{"minecraft:bricks":15,"minecraft:glass":23,"minecraft:oak_planks":2,"minecraft:polished_diorite":94,"minecraft:sandstone":12,"minecraft:stone_bricks":36},"sha256":"7cff43d8f26e21fc4081a91ccd342a8b2a4a07c6c287575ee4b61c5f771414d8","size":{"x":32,"y":1,"z":32}},{"blockCount":162,"bytes":4516,"file":"chunks/y098-z160-x160.json","offset":{"x":160,"y":98,"z":160},"requirements":{"minecraft:glass":15,"minecraft:polished_diorite":99,"minecraft:stone_bricks":48},"sha256":"5c83b6f7f43fbd42a9b9da8e08ac0da3904eef4e231f4e997cb9838b7a0eb544","size":{"x":32,"y":1,"z":32}},{"blockCount":255,"bytes":5743,"file":"chunks/y098-z160-x192.json","offset":{"x":192,"y":98,"z":160},"requirements":{"minecraft:bricks":85,"minecraft:glass":13,"minecraft:polished_diorite":105,"minecraft:stone_bricks":52},"sha256":"a8a94fd630afa97e46cf8a817826f26542ba35027e61cd2ba740255ff25daa9a","size":{"x":32,"y":1,"z":32}},{"blockCount":135,"bytes":3682,"file":"chunks/y098-z160-x224.json","offset":{"x":224,"y":98,"z":160},"requirements":{"minecraft:bricks":61,"minecraft:glass":6,"minecraft:polished_diorite":49,"minecraft:stone_bricks":19},"sha256":"12df8e5da70a396c88d170ac90118908a93bcd2d3e588c7b606c2260770e6d8a","size":{"x":32,"y":1,"z":32}},{"blockCount":82,"bytes":3228,"file":"chunks/y098-z192-x064.json","offset":{"x":64,"y":98,"z":192},"requirements":{"minecraft:glass":10,"minecraft:polished_diorite":44,"minecraft:stone_bricks":28},"sha256":"611c97f1c2d4badc24c4c3259e3d904ebfb3874835849b7fbb7146040adfd85d","size":{"x":32,"y":1,"z":32}},{"blockCount":148,"bytes":3752,"file":"chunks/y098-z192-x096.json","offset":{"x":96,"y":98,"z":192},"requirements":{"minecraft:bricks":21,"minecraft:glass":30,"minecraft:oak_planks":1,"minecraft:polished_diorite":58,"minecraft:sandstone":16,"minecraft:stone_bricks":22},"sha256":"36cc88cdc95740da047a11c549a4966edb9766bc8fe26331ecd79d48bfdb8b53","size":{"x":32,"y":1,"z":32}},{"blockCount":183,"bytes":5132,"file":"chunks/y098-z192-x128.json","offset":{"x":128,"y":98,"z":192},"requirements":{"minecraft:bricks":17,"minecraft:glass":26,"minecraft:oak_planks":1,"minecraft:polished_diorite":88,"minecraft:sandstone":8,"minecraft:stone_bricks":43},"sha256":"615478dc3d1e05c713b5acf15e89573ab4721143420a0f9cd072653949185da4","size":{"x":32,"y":1,"z":32}},{"blockCount":10,"bytes":947,"file":"chunks/y098-z192-x160.json","offset":{"x":160,"y":98,"z":192},"requirements":{"minecraft:polished_diorite":4,"minecraft:stone_bricks":6},"sha256":"3552f98d72b48f67dd9a2acbfd0ecce93b0c6d62c3c31d9de41aea834dd93df9","size":{"x":32,"y":1,"z":32}},{"blockCount":78,"bytes":2975,"file":"chunks/y099-z064-x064.json","offset":{"x":64,"y":99,"z":64},"requirements":{"minecraft:polished_diorite":48,"minecraft:stone_bricks":30},"sha256":"dea3f7fd363981f0dfd1aa0dae8130bcb3eca11c267a2d368eb75bbdf143f009","size":{"x":32,"y":1,"z":32}},{"blockCount":182,"bytes":3758,"file":"chunks/y099-z064-x096.json","offset":{"x":96,"y":99,"z":64},"requirements":{"minecraft:bricks":29,"minecraft:glass":34,"minecraft:oak_planks":1,"minecraft:polished_diorite":77,"minecraft:sandstone":15,"minecraft:stone_bricks":26},"sha256":"df36aa1a38b25a625bc37b009b1fa0ad7491a4f4a797a588638b39e6f0c62f3d","size":{"x":32,"y":1,"z":32}},{"blockCount":207,"bytes":5247,"file":"chunks/y099-z064-x128.json","offset":{"x":128,"y":99,"z":64},"requirements":{"minecraft:bricks":22,"minecraft:glass":19,"minecraft:oak_planks":1,"minecraft:polished_diorite":107,"minecraft:sandstone":9,"minecraft:stone_bricks":49},"sha256":"2e9fd082589586d076bbcef9ac93dce0c30b870f08989ee34b5014ce560dd082","size":{"x":32,"y":1,"z":32}},{"blockCount":9,"bytes":908,"file":"chunks/y099-z064-x160.json","offset":{"x":160,"y":99,"z":64},"requirements":{"minecraft:polished_diorite":5,"minecraft:stone_bricks":4},"sha256":"19802fd35acf1e41bcd9aacbd813ad7deff78b880fdb9387a7ce687502adb5d6","size":{"x":32,"y":1,"z":32}},{"blockCount":27,"bytes":1095,"file":"chunks/y099-z064-x192.json","offset":{"x":192,"y":99,"z":64},"requirements":{"minecraft:polished_diorite":15,"minecraft:stone_bricks":12},"sha256":"3efa67677756bff2f142b00d63873cf1690dcb4a455b1c4e26e7fb96d3b4e584","size":{"x":32,"y":1,"z":32}},{"blockCount":33,"bytes":1096,"file":"chunks/y099-z064-x224.json","offset":{"x":224,"y":99,"z":64},"requirements":{"minecraft:polished_diorite":18,"minecraft:stone_bricks":15},"sha256":"c30c54fbbf5c89187e0bb5ed0e85fa8a93aabc7f2c85314616059338d6be156b","size":{"x":32,"y":1,"z":32}},{"blockCount":45,"bytes":2005,"file":"chunks/y099-z096-x000.json","offset":{"x":0,"y":99,"z":96},"requirements":{"minecraft:polished_diorite":31,"minecraft:stone_bricks":14},"sha256":"e130c21e0c0b86d47010a5e1db59931420d6bfaac94cdf03f8ba3805f88ca4f2","size":{"x":32,"y":1,"z":32}},{"blockCount":176,"bytes":4757,"file":"chunks/y099-z096-x032.json","offset":{"x":32,"y":99,"z":96},"requirements":{"minecraft:bricks":11,"minecraft:glass":17,"minecraft:polished_diorite":103,"minecraft:sandstone":5,"minecraft:stone_bricks":40},"sha256":"bf3a32f64aecb0ac733510b6dd123150163f5ac82e5023a7aa3a1fe628af2a0c","size":{"x":32,"y":1,"z":32}},{"blockCount":173,"bytes":4665,"file":"chunks/y099-z096-x064.json","offset":{"x":64,"y":99,"z":96},"requirements":{"minecraft:bricks":14,"minecraft:glass":16,"minecraft:oak_planks":1,"minecraft:polished_diorite":87,"minecraft:sandstone":8,"minecraft:stone_bricks":47},"sha256":"3cda5f6626f5fa66b9604ac6baed815ca85ca8a42fa342cd3b00f52d71e81bd7","size":{"x":32,"y":1,"z":32}},{"blockCount":100,"bytes":3301,"file":"chunks/y099-z096-x096.json","offset":{"x":96,"y":99,"z":96},"requirements":{"minecraft:bricks":19,"minecraft:glass":12,"minecraft:oak_planks":3,"minecraft:polished_diorite":44,"minecraft:sandstone":11,"minecraft:stone_bricks":11},"sha256":"c43c2b1cb7506533aa058660a64a3eb1d758961d3dcb4e47302927a6d6807a5e","size":{"x":32,"y":1,"z":32}},{"blockCount":177,"bytes":4784,"file":"chunks/y099-z096-x128.json","offset":{"x":128,"y":99,"z":96},"requirements":{"minecraft:bricks":27,"minecraft:glass":19,"minecraft:oak_planks":4,"minecraft:polished_diorite":78,"minecraft:sandstone":15,"minecraft:stone_bricks":34},"sha256":"3d899a9c3bf39e25a623b2feca1ac24b08ef1f81255c5afe979ce0e6c1ed298e","size":{"x":32,"y":1,"z":32}},{"blockCount":182,"bytes":4867,"file":"chunks/y099-z096-x160.json","offset":{"x":160,"y":99,"z":96},"requirements":{"minecraft:bricks":14,"minecraft:glass":18,"minecraft:polished_diorite":100,"minecraft:sandstone":7,"minecraft:stone_bricks":43},"sha256":"ab65afdb49d60773daaff5eacbe092b3edbfb5c976278fb0c0e8b02b0dbbe207","size":{"x":32,"y":1,"z":32}},{"blockCount":280,"bytes":5844,"file":"chunks/y099-z096-x192.json","offset":{"x":192,"y":99,"z":96},"requirements":{"minecraft:bricks":116,"minecraft:glass":17,"minecraft:polished_diorite":87,"minecraft:sandstone":3,"minecraft:stone_bricks":57},"sha256":"7470d2560f9df64412fba42d5a3fa5589a570c7d849146579b85a3a6030d9494","size":{"x":32,"y":1,"z":32}},{"blockCount":166,"bytes":4106,"file":"chunks/y099-z096-x224.json","offset":{"x":224,"y":99,"z":96},"requirements":{"minecraft:bricks":72,"minecraft:glass":7,"minecraft:polished_diorite":53,"minecraft:sandstone":1,"minecraft:stone_bricks":33},"sha256":"0a67e76423bbba357f2bb26c93279fd1b1c04edca3b337cc5fc7cc750ca86cbc","size":{"x":32,"y":1,"z":32}},{"blockCount":67,"bytes":2440,"file":"chunks/y099-z128-x000.json","offset":{"x":0,"y":99,"z":128},"requirements":{"minecraft:polished_diorite":51,"minecraft:stone_bricks":16},"sha256":"265d7a2e407111f3403db507ab0db54ef3b19d9104a7530c0f90da87f9630345","size":{"x":32,"y":1,"z":32}},{"blockCount":141,"bytes":3867,"file":"chunks/y099-z128-x032.json","offset":{"x":32,"y":99,"z":128},"requirements":{"minecraft:bricks":25,"minecraft:glass":29,"minecraft:polished_diorite":55,"minecraft:sandstone":11,"minecraft:stone_bricks":21},"sha256":"f545f9f2b6f8ef06d6b2ccf9711feda45466c595cf5d38335b85cd9f695de63c","size":{"x":32,"y":1,"z":32}},{"blockCount":45,"bytes":1703,"file":"chunks/y099-z128-x064.json","offset":{"x":64,"y":99,"z":128},"requirements":{"minecraft:bricks":14,"minecraft:glass":16,"minecraft:oak_planks":1,"minecraft:sandstone":7,"minecraft:stone_bricks":7},"sha256":"8e51de60002b76ec76cdc507fc76e187aa26d98bad95f8c8ceb7fbee94979df0","size":{"x":32,"y":1,"z":32}},{"blockCount":14,"bytes":1076,"file":"chunks/y099-z128-x096.json","offset":{"x":96,"y":99,"z":128},"requirements":{"minecraft:bricks":6,"minecraft:glass":3,"minecraft:oak_planks":1,"minecraft:sandstone":2,"minecraft:stone_bricks":2},"sha256":"a0f682aabe09d98d9320247144e8ecee2e0c444e0385a7e11afd56870cc7f07a","size":{"x":32,"y":1,"z":32}},{"blockCount":35,"bytes":1534,"file":"chunks/y099-z128-x128.json","offset":{"x":128,"y":99,"z":128},"requirements":{"minecraft:bricks":13,"minecraft:glass":10,"minecraft:oak_planks":2,"minecraft:sandstone":5,"minecraft:stone_bricks":5},"sha256":"008e758b946531bb487235ba322f79d63b135ed4165cda0139befb6ac0f81442","size":{"x":32,"y":1,"z":32}},{"blockCount":46,"bytes":1756,"file":"chunks/y099-z128-x160.json","offset":{"x":160,"y":99,"z":128},"requirements":{"minecraft:bricks":14,"minecraft:glass":18,"minecraft:sandstone":7,"minecraft:stone_bricks":7},"sha256":"12dbbf21e68de36cf98d2ca71ad39c61f50add10213d8c7ec10b1666b6bc7d47","size":{"x":32,"y":1,"z":32}},{"blockCount":50,"bytes":1510,"file":"chunks/y099-z128-x192.json","offset":{"x":192,"y":99,"z":128},"requirements":{"minecraft:bricks":30,"minecraft:glass":11,"minecraft:sandstone":3,"minecraft:stone_bricks":6},"sha256":"eb39072d4681851143d8bb83d4814d431d67291f805d17370582dd6a977217ac","size":{"x":32,"y":1,"z":32}},{"blockCount":127,"bytes":3319,"file":"chunks/y099-z128-x224.json","offset":{"x":224,"y":99,"z":128},"requirements":{"minecraft:bricks":31,"minecraft:glass":22,"minecraft:polished_diorite":49,"minecraft:sandstone":11,"minecraft:stone_bricks":14},"sha256":"e15914ff4e6bd54f26da05062ba09b780883f4844445fbcbc9bf84f1d735cef0","size":{"x":32,"y":1,"z":32}},{"blockCount":24,"bytes":1370,"file":"chunks/y099-z160-x000.json","offset":{"x":0,"y":99,"z":160},"requirements":{"minecraft:polished_diorite":14,"minecraft:stone_bricks":10},"sha256":"d631c96b48ac222152446d2d1e3ab8a98c73c9920c7d6d223059414e7860b437","size":{"x":32,"y":1,"z":32}},{"blockCount":119,"bytes":3395,"file":"chunks/y099-z160-x032.json","offset":{"x":32,"y":99,"z":160},"requirements":{"minecraft:polished_diorite":88,"minecraft:stone_bricks":31},"sha256":"4574023d72eaea9b1d70061081d529d8b497c47905650546616903e55ad905cc","size":{"x":32,"y":1,"z":32}},{"blockCount":140,"bytes":3934,"file":"chunks/y099-z160-x064.json","offset":{"x":64,"y":99,"z":160},"requirements":{"minecraft:polished_diorite":95,"minecraft:sandstone":1,"minecraft:stone_bricks":44},"sha256":"a5cf2695cbe0ed384a21dc371543810c41456cdff8d0344cbdc7e35dd42bbff8","size":{"x":32,"y":1,"z":32}},{"blockCount":111,"bytes":3495,"file":"chunks/y099-z160-x096.json","offset":{"x":96,"y":99,"z":160},"requirements":{"minecraft:bricks":17,"minecraft:glass":15,"minecraft:oak_planks":2,"minecraft:polished_diorite":54,"minecraft:sandstone":11,"minecraft:stone_bricks":12},"sha256":"07a420a2c8a9bc0447f5908de9514a201a06ebc6cb5246e742de74fa264b95b5","size":{"x":32,"y":1,"z":32}},{"blockCount":173,"bytes":4792,"file":"chunks/y099-z160-x128.json","offset":{"x":128,"y":99,"z":160},"requirements":{"minecraft:bricks":15,"minecraft:glass":13,"minecraft:oak_planks":2,"minecraft:polished_diorite":95,"minecraft:sandstone":12,"minecraft:stone_bricks":36},"sha256":"e352e9c223028e28cb371d70871511ffbdf80accca3a7c4e31f50b391b91459b","size":{"x":32,"y":1,"z":32}},{"blockCount":137,"bytes":3773,"file":"chunks/y099-z160-x160.json","offset":{"x":160,"y":99,"z":160},"requirements":{"minecraft:polished_diorite":101,"minecraft:stone_bricks":36},"sha256":"da05f04a6cccb2e37634cbc66d755ee161bbb2cd46a53a6791cdef606d3e29e1","size":{"x":32,"y":1,"z":32}},{"blockCount":257,"bytes":5457,"file":"chunks/y099-z160-x192.json","offset":{"x":192,"y":99,"z":160},"requirements":{"minecraft:bricks":86,"minecraft:glass":6,"minecraft:polished_diorite":102,"minecraft:stone_bricks":63},"sha256":"0930f1937a43e13018d960fb30a423e460d3f83c62566cfd6f5e5558839b806a","size":{"x":32,"y":1,"z":32}},{"blockCount":146,"bytes":3701,"file":"chunks/y099-z160-x224.json","offset":{"x":224,"y":99,"z":160},"requirements":{"minecraft:bricks":61,"minecraft:glass":6,"minecraft:polished_diorite":45,"minecraft:stone_bricks":34},"sha256":"b63723b83870d8b76aed9c5e044e64ef2a8f15854d57db6bc94d4995c99d8325","size":{"x":32,"y":1,"z":32}},{"blockCount":66,"bytes":2593,"file":"chunks/y099-z192-x064.json","offset":{"x":64,"y":99,"z":192},"requirements":{"minecraft:polished_diorite":40,"minecraft:stone_bricks":26},"sha256":"8eb0edba8859e2bfe6c6d62c1b0972d5b4df79e6d7c2833cfb26163042243378","size":{"x":32,"y":1,"z":32}},{"blockCount":160,"bytes":3316,"file":"chunks/y099-z192-x096.json","offset":{"x":96,"y":99,"z":192},"requirements":{"minecraft:bricks":25,"minecraft:glass":31,"minecraft:oak_planks":1,"minecraft:polished_diorite":67,"minecraft:sandstone":13,"minecraft:stone_bricks":23},"sha256":"a67f65791c4502489a3329e76df2e7e68613e45cf2875225c2cd117434761d0d","size":{"x":32,"y":1,"z":32}},{"blockCount":176,"bytes":4425,"file":"chunks/y099-z192-x128.json","offset":{"x":128,"y":99,"z":192},"requirements":{"minecraft:bricks":21,"minecraft:glass":15,"minecraft:oak_planks":1,"minecraft:polished_diorite":90,"minecraft:sandstone":7,"minecraft:stone_bricks":42},"sha256":"05d016b65997ea3965bbe37964e2567939dfe241485acc141bcd89b55313a97b","size":{"x":32,"y":1,"z":32}},{"blockCount":8,"bytes":871,"file":"chunks/y099-z192-x160.json","offset":{"x":160,"y":99,"z":192},"requirements":{"minecraft:polished_diorite":4,"minecraft:stone_bricks":4},"sha256":"a196d5ad0cd57382d6373afa1059dc3d04cc285ec8cecb38188e58ddcef78ef2","size":{"x":32,"y":1,"z":32}},{"blockCount":84,"bytes":2539,"file":"chunks/y100-z064-x064.json","offset":{"x":64,"y":100,"z":64},"requirements":{"minecraft:polished_diorite":70,"minecraft:stone_bricks":14},"sha256":"cb99d82712e42e8ca44cd706b77e7e66b6db95083391915a3c0e4a2a5dbdcba3","size":{"x":32,"y":1,"z":32}},{"blockCount":174,"bytes":4138,"file":"chunks/y100-z064-x096.json","offset":{"x":96,"y":100,"z":64},"requirements":{"minecraft:bricks":30,"minecraft:glass":35,"minecraft:oak_planks":1,"minecraft:polished_diorite":61,"minecraft:sandstone":15,"minecraft:stone_bricks":32},"sha256":"cffd0879ac195ed82f394799550564df15796269306b0b4a94922c308de83285","size":{"x":32,"y":1,"z":32}},{"blockCount":206,"bytes":5096,"file":"chunks/y100-z064-x128.json","offset":{"x":128,"y":100,"z":64},"requirements":{"minecraft:bricks":23,"minecraft:glass":20,"minecraft:oak_planks":1,"minecraft:polished_diorite":110,"minecraft:sandstone":9,"minecraft:stone_bricks":43},"sha256":"6565beb5c06a2521997bf6fdad1ed5c70dfaa5fe282a8961f200fa717849c7b7","size":{"x":32,"y":1,"z":32}},{"blockCount":14,"bytes":1143,"file":"chunks/y100-z064-x160.json","offset":{"x":160,"y":100,"z":64},"requirements":{"minecraft:polished_diorite":12,"minecraft:stone_bricks":2},"sha256":"e70894372b3a1c8ec4bde79d9968d2d8805312c9c710b709d24a9717ab9d623f","size":{"x":32,"y":1,"z":32}},{"blockCount":25,"bytes":1134,"file":"chunks/y100-z064-x192.json","offset":{"x":192,"y":100,"z":64},"requirements":{"minecraft:polished_diorite":14,"minecraft:stone_bricks":11},"sha256":"841672cdafa1f48c5148f3fab31e2ff65f00f38454153fa6f58761550730affd","size":{"x":32,"y":1,"z":32}},{"blockCount":31,"bytes":1230,"file":"chunks/y100-z064-x224.json","offset":{"x":224,"y":100,"z":64},"requirements":{"minecraft:polished_diorite":18,"minecraft:stone_bricks":13},"sha256":"91b7244100dc93ddf310ad1383a239030647ad4fe2b08e97dc934675bf05de78","size":{"x":32,"y":1,"z":32}},{"blockCount":57,"bytes":1911,"file":"chunks/y100-z096-x000.json","offset":{"x":0,"y":100,"z":96},"requirements":{"minecraft:polished_diorite":49,"minecraft:stone_bricks":8},"sha256":"765779bcc5dc9120767ceaf3d73c0280e9e80e1040261bb6548c4a2e4da0c595","size":{"x":32,"y":1,"z":32}},{"blockCount":180,"bytes":4661,"file":"chunks/y100-z096-x032.json","offset":{"x":32,"y":100,"z":96},"requirements":{"minecraft:bricks":11,"minecraft:glass":17,"minecraft:polished_diorite":116,"minecraft:sandstone":5,"minecraft:stone_bricks":31},"sha256":"2cd085e47279189a8e7c5cb3132211ce85340a440b58ca975d08e435b3888ca4","size":{"x":32,"y":1,"z":32}},{"blockCount":173,"bytes":4682,"file":"chunks/y100-z096-x064.json","offset":{"x":64,"y":100,"z":96},"requirements":{"minecraft:bricks":14,"minecraft:glass":16,"minecraft:oak_planks":1,"minecraft:polished_diorite":98,"minecraft:sandstone":8,"minecraft:stone_bricks":36},"sha256":"3a9cde0f3bfef97986f56d3f6c20b53841cd2abf0f8bc379e8eb9427ac4fdcce","size":{"x":32,"y":1,"z":32}},{"blockCount":99,"bytes":3417,"file":"chunks/y100-z096-x096.json","offset":{"x":96,"y":100,"z":96},"requirements":{"minecraft:bricks":20,"minecraft:glass":11,"minecraft:oak_planks":3,"minecraft:polished_diorite":38,"minecraft:sandstone":11,"minecraft:stone_bricks":16},"sha256":"353bc26a74698287a244f39541eb573d56346ea7bbfada703b237786efdcb5d4","size":{"x":32,"y":1,"z":32}},{"blockCount":171,"bytes":4862,"file":"chunks/y100-z096-x128.json","offset":{"x":128,"y":100,"z":96},"requirements":{"minecraft:bricks":28,"minecraft:glass":19,"minecraft:oak_planks":4,"minecraft:polished_diorite":73,"minecraft:sandstone":15,"minecraft:stone_bricks":32},"sha256":"b11e5c15190c425863c3fc82dc9826e10871ec952a10054e920bed25ffcb93cd","size":{"x":32,"y":1,"z":32}},{"blockCount":189,"bytes":4940,"file":"chunks/y100-z096-x160.json","offset":{"x":160,"y":100,"z":96},"requirements":{"minecraft:bricks":14,"minecraft:glass":18,"minecraft:polished_diorite":114,"minecraft:sandstone":7,"minecraft:stone_bricks":36},"sha256":"9333bb9af777b49bb1d9369a4fee818e03adef61e9d924702c1cd7f283168a8c","size":{"x":32,"y":1,"z":32}},{"blockCount":286,"bytes":5728,"file":"chunks/y100-z096-x192.json","offset":{"x":192,"y":100,"z":96},"requirements":{"minecraft:bricks":123,"minecraft:glass":14,"minecraft:polished_diorite":95,"minecraft:sandstone":3,"minecraft:stone_bricks":51},"sha256":"2446ebbe4edde0d525589e456a5a02c065d004899160e9e1f93ce9f1bb07d30a","size":{"x":32,"y":1,"z":32}},{"blockCount":161,"bytes":4088,"file":"chunks/y100-z096-x224.json","offset":{"x":224,"y":100,"z":96},"requirements":{"minecraft:bricks":75,"minecraft:glass":4,"minecraft:polished_diorite":52,"minecraft:sandstone":1,"minecraft:stone_bricks":29},"sha256":"c8ce4721f30f9840d0921d89596ddecd4da8a342d9f637a55fb68257bf9c0235","size":{"x":32,"y":1,"z":32}},{"blockCount":73,"bytes":2364,"file":"chunks/y100-z128-x000.json","offset":{"x":0,"y":100,"z":128},"requirements":{"minecraft:polished_diorite":62,"minecraft:stone_bricks":11},"sha256":"e1cd40ee0eaee4543e262e06434b503a723adb45e2041385bb81ff56e83836f6","size":{"x":32,"y":1,"z":32}},{"blockCount":142,"bytes":3831,"file":"chunks/y100-z128-x032.json","offset":{"x":32,"y":100,"z":128},"requirements":{"minecraft:bricks":29,"minecraft:glass":25,"minecraft:polished_diorite":50,"minecraft:sandstone":15,"minecraft:stone_bricks":23},"sha256":"8b3f67215529ec26caf5a1039e0f933e53c89aecdd59b27e93662db836cd3c98","size":{"x":32,"y":1,"z":32}},{"blockCount":45,"bytes":1704,"file":"chunks/y100-z128-x064.json","offset":{"x":64,"y":100,"z":128},"requirements":{"minecraft:bricks":14,"minecraft:glass":16,"minecraft:oak_planks":1,"minecraft:sandstone":7,"minecraft:stone_bricks":7},"sha256":"8f1a780f8474c51df75349ac1c4fb91d27bd2ea1a4dcaa3d800aba5ff4e94850","size":{"x":32,"y":1,"z":32}},{"blockCount":15,"bytes":1116,"file":"chunks/y100-z128-x096.json","offset":{"x":96,"y":100,"z":128},"requirements":{"minecraft:bricks":7,"minecraft:glass":3,"minecraft:oak_planks":1,"minecraft:sandstone":2,"minecraft:stone_bricks":2},"sha256":"ea63de87eec5cdf4cbad0bcd97ab8eb37e84520d5ed0d0ce8e0fa3e0beb8f778","size":{"x":32,"y":1,"z":32}},{"blockCount":35,"bytes":1554,"file":"chunks/y100-z128-x128.json","offset":{"x":128,"y":100,"z":128},"requirements":{"minecraft:bricks":14,"minecraft:glass":9,"minecraft:oak_planks":2,"minecraft:sandstone":5,"minecraft:stone_bricks":5},"sha256":"a0892c0988f0bb7e06338e5e1fb466aedc10f99294b1709f1fb268aeb283021d","size":{"x":32,"y":1,"z":32}},{"blockCount":46,"bytes":1757,"file":"chunks/y100-z128-x160.json","offset":{"x":160,"y":100,"z":128},"requirements":{"minecraft:bricks":14,"minecraft:glass":18,"minecraft:sandstone":7,"minecraft:stone_bricks":7},"sha256":"23b74e778d7456ddcf3fe6799abd3d9e4db1536af53efcd6337a5a76f694e731","size":{"x":32,"y":1,"z":32}},{"blockCount":50,"bytes":1511,"file":"chunks/y100-z128-x192.json","offset":{"x":192,"y":100,"z":128},"requirements":{"minecraft:bricks":30,"minecraft:glass":11,"minecraft:sandstone":3,"minecraft:stone_bricks":6},"sha256":"0411f3208f8a233a75c096f9ff24ae1d58b25eb14b322fb47c675087a5ebc794","size":{"x":32,"y":1,"z":32}},{"blockCount":120,"bytes":3301,"file":"chunks/y100-z128-x224.json","offset":{"x":224,"y":100,"z":128},"requirements":{"minecraft:bricks":33,"minecraft:glass":24,"minecraft:polished_diorite":37,"minecraft:sandstone":11,"minecraft:stone_bricks":15},"sha256":"14daf2cf9433c1165a0aa37cb182c9ea778baec175741365cae037e0660e22c3","size":{"x":32,"y":1,"z":32}},{"blockCount":34,"bytes":1429,"file":"chunks/y100-z160-x000.json","offset":{"x":0,"y":100,"z":160},"requirements":{"minecraft:polished_diorite":29,"minecraft:stone_bricks":5},"sha256":"503c13d4842f95ebe1b8aef38407455bd78a4cccd05c791aaf2c5c6ca4212cd6","size":{"x":32,"y":1,"z":32}},{"blockCount":126,"bytes":3279,"file":"chunks/y100-z160-x032.json","offset":{"x":32,"y":100,"z":160},"requirements":{"minecraft:polished_diorite":104,"minecraft:stone_bricks":22},"sha256":"79273ccc974648a8de9f730049647ec37b579f2498f5dd4d3890ae2c3e932bf1","size":{"x":32,"y":1,"z":32}},{"blockCount":142,"bytes":3858,"file":"chunks/y100-z160-x064.json","offset":{"x":64,"y":100,"z":160},"requirements":{"minecraft:polished_diorite":110,"minecraft:sandstone":1,"minecraft:stone_bricks":31},"sha256":"a1eec298b5d477e64f7008c8f4ab670b6d588d6700c59b4ade21d45c6823ee4e","size":{"x":32,"y":1,"z":32}},{"blockCount":110,"bytes":3629,"file":"chunks/y100-z160-x096.json","offset":{"x":96,"y":100,"z":160},"requirements":{"minecraft:bricks":17,"minecraft:glass":15,"minecraft:oak_planks":2,"minecraft:polished_diorite":46,"minecraft:sandstone":11,"minecraft:stone_bricks":19},"sha256":"cccac9afff64ab528aa1cdc9f908135bf5a9ef5f34086705b0bf15541336d51d","size":{"x":32,"y":1,"z":32}},{"blockCount":167,"bytes":4793,"file":"chunks/y100-z160-x128.json","offset":{"x":128,"y":100,"z":160},"requirements":{"minecraft:bricks":15,"minecraft:glass":13,"minecraft:oak_planks":2,"minecraft:polished_diorite":91,"minecraft:sandstone":12,"minecraft:stone_bricks":34},"sha256":"ee6415eacb8359512aba1ff3201a15fa6de9dd516f3354ebf2f6a1b578c66947","size":{"x":32,"y":1,"z":32}},{"blockCount":145,"bytes":3885,"file":"chunks/y100-z160-x160.json","offset":{"x":160,"y":100,"z":160},"requirements":{"minecraft:polished_diorite":116,"minecraft:stone_bricks":29},"sha256":"b5709d2b4bdf8f830a2d91f352b87defe945d5d61c10c19ec1c9b3e9306a6aa3","size":{"x":32,"y":1,"z":32}},{"blockCount":261,"bytes":5381,"file":"chunks/y100-z160-x192.json","offset":{"x":192,"y":100,"z":160},"requirements":{"minecraft:bricks":93,"minecraft:glass":3,"minecraft:polished_diorite":109,"minecraft:stone_bricks":56},"sha256":"8cf3ba4acbe74df1d7e287ce1a8f034859dd9e2fe4d7c4fec7dde2191f4b1091","size":{"x":32,"y":1,"z":32}},{"blockCount":141,"bytes":3740,"file":"chunks/y100-z160-x224.json","offset":{"x":224,"y":100,"z":160},"requirements":{"minecraft:bricks":64,"minecraft:glass":3,"minecraft:polished_diorite":45,"minecraft:stone_bricks":29},"sha256":"5da4c2a1fa7c0fa8cfea64ad0e3601e9e956051ed327391fe4c082d01f04c129","size":{"x":32,"y":1,"z":32}},{"blockCount":70,"bytes":2252,"file":"chunks/y100-z192-x064.json","offset":{"x":64,"y":100,"z":192},"requirements":{"minecraft:polished_diorite":58,"minecraft:stone_bricks":12},"sha256":"e4c568cae03ddac37d6d1b6541870099bf0ce602afc54e3380d0de9c38de5dfd","size":{"x":32,"y":1,"z":32}},{"blockCount":152,"bytes":3658,"file":"chunks/y100-z192-x096.json","offset":{"x":96,"y":100,"z":192},"requirements":{"minecraft:bricks":26,"minecraft:glass":32,"minecraft:oak_planks":1,"minecraft:polished_diorite":53,"minecraft:sandstone":13,"minecraft:stone_bricks":27},"sha256":"3b3ab2ffd59b455301e3c3bfdb6d5d6de36c1b1ea8bea8b735fe545f0faecdf4","size":{"x":32,"y":1,"z":32}},{"blockCount":174,"bytes":4293,"file":"chunks/y100-z192-x128.json","offset":{"x":128,"y":100,"z":192},"requirements":{"minecraft:bricks":22,"minecraft:glass":16,"minecraft:oak_planks":1,"minecraft:polished_diorite":92,"minecraft:sandstone":7,"minecraft:stone_bricks":36},"sha256":"7b7fff7b478fa383de2527765a8b15cbf2ef40240fc16eb7a1acecafccbcd7cb","size":{"x":32,"y":1,"z":32}},{"blockCount":12,"bytes":1067,"file":"chunks/y100-z192-x160.json","offset":{"x":160,"y":100,"z":192},"requirements":{"minecraft:polished_diorite":10,"minecraft:stone_bricks":2},"sha256":"40c6fac05a4f394c6538b96d8c3045bfdd776dc51ebc388ed8138a234eaf6416","size":{"x":32,"y":1,"z":32}},{"blockCount":77,"bytes":2515,"file":"chunks/y101-z064-x064.json","offset":{"x":64,"y":101,"z":64},"requirements":{"minecraft:polished_diorite":50,"minecraft:stone_bricks":27},"sha256":"f929365f40fbe26880711446448de3a34aea67806f67ee76e4553f3d22e5b1d0","size":{"x":32,"y":1,"z":32}},{"blockCount":166,"bytes":3815,"file":"chunks/y101-z064-x096.json","offset":{"x":96,"y":101,"z":64},"requirements":{"minecraft:bricks":31,"minecraft:glass":33,"minecraft:oak_planks":1,"minecraft:polished_diorite":64,"minecraft:sandstone":17,"minecraft:stone_bricks":20},"sha256":"d36a2889dd7a4b373f5c89856e49f03d31d922c0cd3b4dc56d1b18b5b1ce3603","size":{"x":32,"y":1,"z":32}},{"blockCount":191,"bytes":4811,"file":"chunks/y101-z064-x128.json","offset":{"x":128,"y":101,"z":64},"requirements":{"minecraft:bricks":24,"minecraft:glass":18,"minecraft:oak_planks":1,"minecraft:polished_diorite":99,"minecraft:sandstone":9,"minecraft:stone_bricks":40},"sha256":"d4be5674e655a02066c017329120ec4a8ab4b91181bb91e2c48a916e1797e08c","size":{"x":32,"y":1,"z":32}},{"blockCount":12,"bytes":1104,"file":"chunks/y101-z064-x160.json","offset":{"x":160,"y":101,"z":64},"requirements":{"minecraft:polished_diorite":7,"minecraft:stone_bricks":5},"sha256":"aa284c91117bda4db78dc93cc90cb94b562139fdd4b5ef0044ff0f99ed5ffe10","size":{"x":32,"y":1,"z":32}},{"blockCount":22,"bytes":1000,"file":"chunks/y101-z064-x192.json","offset":{"x":192,"y":101,"z":64},"requirements":{"minecraft:polished_diorite":14,"minecraft:stone_bricks":8},"sha256":"f5761dfc234783ac2cb3b434e0bff3ba821ce4f43b68e61af1b72b66840b7a8a","size":{"x":32,"y":1,"z":32}},{"blockCount":28,"bytes":1078,"file":"chunks/y101-z064-x224.json","offset":{"x":224,"y":101,"z":64},"requirements":{"minecraft:polished_diorite":17,"minecraft:stone_bricks":11},"sha256":"fec27e3f98feb895b0f6be0d44505d4bbea6b2a452698c52210f53f7f93a7c90","size":{"x":32,"y":1,"z":32}},{"blockCount":48,"bytes":1947,"file":"chunks/y101-z096-x000.json","offset":{"x":0,"y":101,"z":96},"requirements":{"minecraft:polished_diorite":33,"minecraft:stone_bricks":15},"sha256":"da85b27b20b2a04b43c141a70ea49a080549d8780902a306d75f06a0257b2223","size":{"x":32,"y":1,"z":32}},{"blockCount":163,"bytes":4565,"file":"chunks/y101-z096-x032.json","offset":{"x":32,"y":101,"z":96},"requirements":{"minecraft:bricks":11,"minecraft:glass":17,"minecraft:polished_diorite":96,"minecraft:sandstone":5,"minecraft:stone_bricks":34},"sha256":"fac24cb995d1c9ad6b3de9d633c060e177da371f5706011736a32f30d522e8ab","size":{"x":32,"y":1,"z":32}},{"blockCount":157,"bytes":4457,"file":"chunks/y101-z096-x064.json","offset":{"x":64,"y":101,"z":96},"requirements":{"minecraft:bricks":14,"minecraft:glass":16,"minecraft:oak_planks":1,"minecraft:polished_diorite":80,"minecraft:sandstone":8,"minecraft:stone_bricks":38},"sha256":"7010dcef439385887ff228de17784cb2c7c03b482a2158fe1dbe04248d5db974","size":{"x":32,"y":1,"z":32}},{"blockCount":93,"bytes":3303,"file":"chunks/y101-z096-x096.json","offset":{"x":96,"y":101,"z":96},"requirements":{"minecraft:bricks":20,"minecraft:glass":11,"minecraft:oak_planks":3,"minecraft:polished_diorite":38,"minecraft:sandstone":11,"minecraft:stone_bricks":10},"sha256":"75688336b4bfae397e137c2f5b05af3e23b3a77817260decfcfd4ac05116c449","size":{"x":32,"y":1,"z":32}},{"blockCount":159,"bytes":4615,"file":"chunks/y101-z096-x128.json","offset":{"x":128,"y":101,"z":96},"requirements":{"minecraft:bricks":28,"minecraft:glass":18,"minecraft:oak_planks":4,"minecraft:polished_diorite":68,"minecraft:sandstone":15,"minecraft:stone_bricks":26},"sha256":"67a91806d72d0cc56501fb479c41cd371ed8b17e18957709ecb26c84b168002a","size":{"x":32,"y":1,"z":32}},{"blockCount":171,"bytes":4863,"file":"chunks/y101-z096-x160.json","offset":{"x":160,"y":101,"z":96},"requirements":{"minecraft:bricks":14,"minecraft:glass":18,"minecraft:polished_diorite":93,"minecraft:sandstone":7,"minecraft:stone_bricks":39},"sha256":"1ac482f4ebd2a56cbdceac7ed5947fc2375481f4751ab2205297bb33d1dd99a3","size":{"x":32,"y":1,"z":32}},{"blockCount":269,"bytes":5599,"file":"chunks/y101-z096-x192.json","offset":{"x":192,"y":101,"z":96},"requirements":{"minecraft:bricks":126,"minecraft:glass":11,"minecraft:polished_diorite":83,"minecraft:sandstone":3,"minecraft:stone_bricks":46},"sha256":"1bd0f28e4002a9ea7518d9e9bcd0fff1e58d7cffb5ecbaaf510e306f494ff2e4","size":{"x":32,"y":1,"z":32}},{"blockCount":155,"bytes":3765,"file":"chunks/y101-z096-x224.json","offset":{"x":224,"y":101,"z":96},"requirements":{"minecraft:bricks":75,"minecraft:polished_diorite":54,"minecraft:sandstone":1,"minecraft:stone_bricks":25},"sha256":"f03fabd51ee54c9edd7104f96e1b2b3e22ec25a9cd8d521de27b614930a8b779","size":{"x":32,"y":1,"z":32}},{"blockCount":63,"bytes":2228,"file":"chunks/y101-z128-x000.json","offset":{"x":0,"y":101,"z":128},"requirements":{"minecraft:polished_diorite":50,"minecraft:stone_bricks":13},"sha256":"efea97ce0d622c5c99ef1ef73352e548be8f97c99654412e4a9e25e712edd967","size":{"x":32,"y":1,"z":32}},{"blockCount":142,"bytes":3907,"file":"chunks/y101-z128-x032.json","offset":{"x":32,"y":101,"z":128},"requirements":{"minecraft:bricks":33,"minecraft:glass":23,"minecraft:polished_diorite":55,"minecraft:sandstone":11,"minecraft:stone_bricks":20},"sha256":"e458a41bd728d542884d7b5fb78a8d6ceb89b0c9c1f0c02e63103a6734ae0470","size":{"x":32,"y":1,"z":32}},{"blockCount":45,"bytes":1704,"file":"chunks/y101-z128-x064.json","offset":{"x":64,"y":101,"z":128},"requirements":{"minecraft:bricks":14,"minecraft:glass":16,"minecraft:oak_planks":1,"minecraft:sandstone":7,"minecraft:stone_bricks":7},"sha256":"79ecdb5becbb835e71af5f2e43ed0c089b7d7fcbf56259ce43b195ab5cba5206","size":{"x":32,"y":1,"z":32}},{"blockCount":14,"bytes":1097,"file":"chunks/y101-z128-x096.json","offset":{"x":96,"y":101,"z":128},"requirements":{"minecraft:bricks":7,"minecraft:glass":2,"minecraft:oak_planks":1,"minecraft:sandstone":2,"minecraft:stone_bricks":2},"sha256":"88db7bbbb1c8cf0f1ae874368500e4e7350aef84e30e441406b37704703d9f9a","size":{"x":32,"y":1,"z":32}},{"blockCount":35,"bytes":1554,"file":"chunks/y101-z128-x128.json","offset":{"x":128,"y":101,"z":128},"requirements":{"minecraft:bricks":14,"minecraft:glass":9,"minecraft:oak_planks":2,"minecraft:sandstone":5,"minecraft:stone_bricks":5},"sha256":"8b1faf11dda7e6eef3bd8131b27c3419f2e569565e4eaa9a407c2bbba48ecfad","size":{"x":32,"y":1,"z":32}},{"blockCount":46,"bytes":1757,"file":"chunks/y101-z128-x160.json","offset":{"x":160,"y":101,"z":128},"requirements":{"minecraft:bricks":14,"minecraft:glass":18,"minecraft:sandstone":7,"minecraft:stone_bricks":7},"sha256":"f769211bf467b9ac2529ca302528e410a7c2160e3f0db22e82085de8fb9574e1","size":{"x":32,"y":1,"z":32}},{"blockCount":50,"bytes":1511,"file":"chunks/y101-z128-x192.json","offset":{"x":192,"y":101,"z":128},"requirements":{"minecraft:bricks":30,"minecraft:glass":11,"minecraft:sandstone":3,"minecraft:stone_bricks":6},"sha256":"b7ef7c30558018972c2ff24425ebd7e5f52928168dbe323bd5bbdf0722ea4307","size":{"x":32,"y":1,"z":32}},{"blockCount":125,"bytes":3111,"file":"chunks/y101-z128-x224.json","offset":{"x":224,"y":101,"z":128},"requirements":{"minecraft:bricks":35,"minecraft:glass":21,"minecraft:polished_diorite":44,"minecraft:sandstone":13,"minecraft:stone_bricks":12},"sha256":"71b78216c4d6bafb3f391952420eb57416ba357c0b95749f77a370d250a132c2","size":{"x":32,"y":1,"z":32}},{"blockCount":29,"bytes":1447,"file":"chunks/y101-z160-x000.json","offset":{"x":0,"y":101,"z":160},"requirements":{"minecraft:polished_diorite":19,"minecraft:stone_bricks":10},"sha256":"2ab6dd533e88c82d654242d09b84fccff740aed60e7877c810f437f7293720ec","size":{"x":32,"y":1,"z":32}},{"blockCount":111,"bytes":3241,"file":"chunks/y101-z160-x032.json","offset":{"x":32,"y":101,"z":160},"requirements":{"minecraft:polished_diorite":85,"minecraft:stone_bricks":26},"sha256":"91a5c99a9f5adc9e67dacf85ae4b11ffdca911a6bd951a915549be04a017ddfa","size":{"x":32,"y":1,"z":32}},{"blockCount":125,"bytes":3649,"file":"chunks/y101-z160-x064.json","offset":{"x":64,"y":101,"z":160},"requirements":{"minecraft:polished_diorite":88,"minecraft:sandstone":1,"minecraft:stone_bricks":36},"sha256":"c9074083df33e3899b4aa667f83c96f02da84126d53a53499fbcd37bb2387c08","size":{"x":32,"y":1,"z":32}},{"blockCount":102,"bytes":3477,"file":"chunks/y101-z160-x096.json","offset":{"x":96,"y":101,"z":160},"requirements":{"minecraft:bricks":17,"minecraft:glass":15,"minecraft:oak_planks":2,"minecraft:polished_diorite":46,"minecraft:sandstone":11,"minecraft:stone_bricks":11},"sha256":"38d37ac8a8da3b04406236b553f0aac2e4abb492890dd43c1197c1069846e7ac","size":{"x":32,"y":1,"z":32}},{"blockCount":153,"bytes":4527,"file":"chunks/y101-z160-x128.json","offset":{"x":128,"y":101,"z":160},"requirements":{"minecraft:bricks":15,"minecraft:glass":13,"minecraft:oak_planks":2,"minecraft:polished_diorite":83,"minecraft:sandstone":12,"minecraft:stone_bricks":28},"sha256":"7c4c292792a8efd47659ea008d7023b986228f46c5579dd775e1feff50e07faa","size":{"x":32,"y":1,"z":32}},{"blockCount":127,"bytes":3808,"file":"chunks/y101-z160-x160.json","offset":{"x":160,"y":101,"z":160},"requirements":{"minecraft:polished_diorite":94,"minecraft:stone_bricks":33},"sha256":"8aec70cde7d672771530d330d4ff39d60a76d062197680e270fdf7c83ef471d9","size":{"x":32,"y":1,"z":32}},{"blockCount":241,"bytes":5078,"file":"chunks/y101-z160-x192.json","offset":{"x":192,"y":101,"z":160},"requirements":{"minecraft:bricks":96,"minecraft:polished_diorite":97,"minecraft:stone_bricks":48},"sha256":"6b55e568eb81f8e24b05edd6ac6ebd2a18ec296b70498ad3f5031299cd236487","size":{"x":32,"y":1,"z":32}},{"blockCount":133,"bytes":3512,"file":"chunks/y101-z160-x224.json","offset":{"x":224,"y":101,"z":160},"requirements":{"minecraft:bricks":64,"minecraft:polished_diorite":43,"minecraft:stone_bricks":26},"sha256":"450370aa176e449286c5476236dc46a78c596715e946716b3a72a6dc90f44af9","size":{"x":32,"y":1,"z":32}},{"blockCount":64,"bytes":2211,"file":"chunks/y101-z192-x064.json","offset":{"x":64,"y":101,"z":192},"requirements":{"minecraft:polished_diorite":42,"minecraft:stone_bricks":22},"sha256":"3b37e3ea903960dee65d1897912d5557a633ccd4ccb85279fe9cbc495be39d69","size":{"x":32,"y":1,"z":32}},{"blockCount":146,"bytes":3373,"file":"chunks/y101-z192-x096.json","offset":{"x":96,"y":101,"z":192},"requirements":{"minecraft:bricks":27,"minecraft:glass":30,"minecraft:oak_planks":1,"minecraft:polished_diorite":56,"minecraft:sandstone":15,"minecraft:stone_bricks":17},"sha256":"43420254a16a3dd8afd07c5a10e9543420fe131e3616f72afbb111d13af27e63","size":{"x":32,"y":1,"z":32}}],"schema":1}
