{"entries":[{"blockCount":162,"bytes":4085,"file":"chunks/y101-z192-x128.json","offset":{"x":128,"y":101,"z":192},"requirements":{"minecraft:bricks":23,"minecraft:glass":14,"minecraft:oak_planks":1,"minecraft:polished_diorite":84,"minecraft:sandstone":7,"minecraft:stone_bricks":33},"sha256":"5f4601d272c6adf93ccff8b5d5b8d1e1aa715d414d106f651086fb1ab119def6","size":{"x":32,"y":1,"z":32}},{"blockCount":10,"bytes":1028,"file":"chunks/y101-z192-x160.json","offset":{"x":160,"y":101,"z":192},"requirements":{"minecraft:polished_diorite":6,"minecraft:stone_bricks":4},"sha256":"cb50e23ef41e835b2556a726fe8e799179522ed924405f19dfc6a113a56f73a4","size":{"x":32,"y":1,"z":32}},{"blockCount":43,"bytes":2059,"file":"chunks/y102-z064-x064.json","offset":{"x":64,"y":102,"z":64},"requirements":{"minecraft:polished_diorite":21,"minecraft:stone_bricks":22},"sha256":"c73971639f5b1756d6fee6a24c1b07afa10158e5d2f8503a986a649b4fffdfb7","size":{"x":32,"y":1,"z":32}},{"blockCount":180,"bytes":3968,"file":"chunks/y102-z064-x096.json","offset":{"x":96,"y":102,"z":64},"requirements":{"minecraft:bricks":33,"minecraft:glass":33,"minecraft:oak_planks":2,"minecraft:polished_diorite":70,"minecraft:sandstone":14,"minecraft:stone_bricks":28},"sha256":"68c97067dbf3360d04558ede6490ffd170da603147a413c3bb38e9b7d1f986d1","size":{"x":32,"y":1,"z":32}},{"blockCount":175,"bytes":4622,"file":"chunks/y102-z064-x128.json","offset":{"x":128,"y":102,"z":64},"requirements":{"minecraft:bricks":26,"minecraft:glass":18,"minecraft:oak_planks":2,"minecraft:polished_diorite":78,"minecraft:sandstone":7,"minecraft:stone_bricks":44},"sha256":"86938623c1299e969e883d3bbf801affb3826361d268a4b8f648e26acc8c9f72","size":{"x":32,"y":1,"z":32}},{"blockCount":7,"bytes":909,"file":"chunks/y102-z064-x160.json","offset":{"x":160,"y":102,"z":64},"requirements":{"minecraft:polished_diorite":2,"minecraft:stone_bricks":5},"sha256":"247fcee3b2764dec246e9d33f119aeb910590bc7489c0d05bbd8a0b612a78242","size":{"x":32,"y":1,"z":32}},{"blockCount":20,"bytes":981,"file":"chunks/y102-z064-x192.json","offset":{"x":192,"y":102,"z":64},"requirements":{"minecraft:polished_diorite":17,"minecraft:stone_bricks":3},"sha256":"2975296f69055f54ff95ae841750e9984a18100b99f0d223935a0659926cb50b","size":{"x":32,"y":1,"z":32}},{"blockCount":24,"bytes":1059,"file":"chunks/y102-z064-x224.json","offset":{"x":224,"y":102,"z":64},"requirements":{"minecraft:polished_diorite":20,"minecraft:stone_bricks":4},"sha256":"dbbfe34e97bbe50506c97d8ece5d5b83647cfc03b150d57159cdc3b18c9a0320","size":{"x":32,"y":1,"z":32}},{"blockCount":31,"bytes":1677,"file":"chunks/y102-z096-x000.json","offset":{"x":0,"y":102,"z":96},"requirements":{"minecraft:polished_diorite":16,"minecraft:stone_bricks":15},"sha256":"a943126a7478b88cdab6d3425caa5a5abd6e4368947be8aebe1ae0c68234c82b","size":{"x":32,"y":1,"z":32}},{"blockCount":141,"bytes":4220,"file":"chunks/y102-z096-x032.json","offset":{"x":32,"y":102,"z":96},"requirements":{"minecraft:bricks":11,"minecraft:glass":16,"minecraft:polished_diorite":69,"minecraft:sandstone":6,"minecraft:stone_bricks":39},"sha256":"42923d0a6c19b161de9f8dbaba8df620909fd6aca9efaa06fefed474b983cbb4","size":{"x":32,"y":1,"z":32}},{"blockCount":139,"bytes":3827,"file":"chunks/y102-z096-x064.json","offset":{"x":64,"y":102,"z":96},"requirements":{"minecraft:bricks":14,"minecraft:glass":16,"minecraft:oak_planks":1,"minecraft:polished_diorite":61,"minecraft:sandstone":8,"minecraft:stone_bricks":39},"sha256":"12d29962eca9a03e5b4e2c1856b158166fc2000c5ef1336f91471e88303c98cb","size":{"x":32,"y":1,"z":32}},{"blockCount":98,"bytes":3379,"file":"chunks/y102-z096-x096.json","offset":{"x":96,"y":102,"z":96},"requirements":{"minecraft:bricks":20,"minecraft:glass":11,"minecraft:oak_planks":3,"minecraft:polished_diorite":38,"minecraft:sandstone":11,"minecraft:stone_bricks":15},"sha256":"ba4f08736d6ae7bf014a216419920d815395986c42afd32669731359a896a1ea","size":{"x":32,"y":1,"z":32}},{"blockCount":157,"bytes":4501,"file":"chunks/y102-z096-x128.json","offset":{"x":128,"y":102,"z":96},"requirements":{"minecraft:bricks":28,"minecraft:glass":18,"minecraft:oak_planks":4,"minecraft:polished_diorite":62,"minecraft:sandstone":15,"minecraft:stone_bricks":30},"sha256":"a759c53a050b7bf35e8a35546990ab6d2843f888bce0e47657312ba96f1b8bf1","size":{"x":32,"y":1,"z":32}},{"blockCount":150,"bytes":4159,"file":"chunks/y102-z096-x160.json","offset":{"x":160,"y":102,"z":96},"requirements":{"minecraft:bricks":14,"minecraft:glass":18,"minecraft:polished_diorite":66,"minecraft:sandstone":7,"minecraft:stone_bricks":45},"sha256":"96b0c208ee7ecf36779c023773c564f604691cd0af57285620a8d6f98ad4a765","size":{"x":32,"y":1,"z":32}},{"blockCount":253,"bytes":5087,"file":"chunks/y102-z096-x192.json","offset":{"x":192,"y":102,"z":96},"requirements":{"minecraft:bricks":125,"minecraft:glass":11,"minecraft:polished_diorite":73,"minecraft:sandstone":3,"minecraft:stone_bricks":41},"sha256":"4ec52e2d6c2e459335858464c0ea12e9c6fdc551605ea3ee587c30bbd68cf981","size":{"x":32,"y":1,"z":32}},{"blockCount":150,"bytes":3595,"file":"chunks/y102-z096-x224.json","offset":{"x":224,"y":102,"z":96},"requirements":{"minecraft:bricks":73,"minecraft:polished_diorite":60,"minecraft:sandstone":1,"minecraft:stone_bricks":16},"sha256":"c086db1a7b061829c5cf63cb05de4bc16e17616aedb42145a3f400753f33d31b","size":{"x":32,"y":1,"z":32}},{"blockCount":44,"bytes":2037,"file":"chunks/y102-z128-x000.json","offset":{"x":0,"y":102,"z":128},"requirements":{"minecraft:polished_diorite":31,"minecraft:stone_bricks":13},"sha256":"4870e4b088de8687169520c63661c1b94a676b3367a502baa7fe3d95a9d66246","size":{"x":32,"y":1,"z":32}},{"blockCount":151,"bytes":4039,"file":"chunks/y102-z128-x032.json","offset":{"x":32,"y":102,"z":128},"requirements":{"minecraft:bricks":35,"minecraft:glass":20,"minecraft:polished_diorite":52,"minecraft:sandstone":16,"minecraft:stone_bricks":28},"sha256":"664e0a5aed6471a654f3f0db261f303cac63bf4ea24b1d8a5be19249af6db29e","size":{"x":32,"y":1,"z":32}},{"blockCount":45,"bytes":1704,"file":"chunks/y102-z128-x064.json","offset":{"x":64,"y":102,"z":128},"requirements":{"minecraft:bricks":14,"minecraft:glass":16,"minecraft:oak_planks":1,"minecraft:sandstone":7,"minecraft:stone_bricks":7},"sha256":"1b25e68782545685b5576923729b9173b2779c09535d09dbfbdd4459a0c94903","size":{"x":32,"y":1,"z":32}},{"blockCount":14,"bytes":1097,"file":"chunks/y102-z128-x096.json","offset":{"x":96,"y":102,"z":128},"requirements":{"minecraft:bricks":7,"minecraft:glass":2,"minecraft:oak_planks":1,"minecraft:sandstone":2,"minecraft:stone_bricks":2},"sha256":"fff377e6a8d7a683264d25dc91c2762fa83d93d62a50bb68e96d49c33f6387d8","size":{"x":32,"y":1,"z":32}},{"blockCount":35,"bytes":1554,"file":"chunks/y102-z128-x128.json","offset":{"x":128,"y":102,"z":128},"requirements":{"minecraft:bricks":14,"minecraft:glass":9,"minecraft:oak_planks":2,"minecraft:sandstone":5,"minecraft:stone_bricks":5},"sha256":"e011a467104073d1246a9d3f5418e43ff34fdbbdd694e86ea4de804e02db0bd1","size":{"x":32,"y":1,"z":32}},{"blockCount":46,"bytes":1757,"file":"chunks/y102-z128-x160.json","offset":{"x":160,"y":102,"z":128},"requirements":{"minecraft:bricks":14,"minecraft:glass":18,"minecraft:sandstone":7,"minecraft:stone_bricks":7},"sha256":"ba6d7a8e847952cdb80d5d153f85c284feaf7f8e2ba1218637279b96a1b0faf8","size":{"x":32,"y":1,"z":32}},{"blockCount":50,"bytes":1511,"file":"chunks/y102-z128-x192.json","offset":{"x":192,"y":102,"z":128},"requirements":{"minecraft:bricks":30,"minecraft:glass":11,"minecraft:sandstone":3,"minecraft:stone_bricks":6},"sha256":"456a53cca4e5218249b5205cce660658ea2572a8cf03e961c871bed315281d81","size":{"x":32,"y":1,"z":32}},{"blockCount":127,"bytes":3116,"file":"chunks/y102-z128-x224.json","offset":{"x":224,"y":102,"z":128},"requirements":{"minecraft:bricks":38,"minecraft:glass":21,"minecraft:oak_planks":2,"minecraft:polished_diorite":45,"minecraft:sandstone":8,"minecraft:stone_bricks":13},"sha256":"0998e8c95600e5d3079c383f2478307d5fd0097978abb75c376fd36bc1fd4e09","size":{"x":32,"y":1,"z":32}},{"blockCount":19,"bytes":1292,"file":"chunks/y102-z160-x000.json","offset":{"x":0,"y":102,"z":160},"requirements":{"minecraft:polished_diorite":9,"minecraft:stone_bricks":10},"sha256":"9534d28f35705030f4875520d679d5e37897616abc0964006b871241862f18e8","size":{"x":32,"y":1,"z":32}},{"blockCount":86,"bytes":2784,"file":"chunks/y102-z160-x032.json","offset":{"x":32,"y":102,"z":160},"requirements":{"minecraft:polished_diorite":57,"minecraft:stone_bricks":29},"sha256":"78bfea0cb372352f049524c71ac780db40d8e33946a1d0547ca62a1f8f6a2418","size":{"x":32,"y":1,"z":32}},{"blockCount":101,"bytes":2925,"file":"chunks/y102-z160-x064.json","offset":{"x":64,"y":102,"z":160},"requirements":{"minecraft:polished_diorite":64,"minecraft:sandstone":1,"minecraft:stone_bricks":36},"sha256":"7d68c1d18463f6adfd6168df2ddc34b6d71a808b8bc4463acb47b804605cf5a0","size":{"x":32,"y":1,"z":32}},{"blockCount":110,"bytes":3591,"file":"chunks/y102-z160-x096.json","offset":{"x":96,"y":102,"z":160},"requirements":{"minecraft:bricks":17,"minecraft:glass":15,"minecraft:oak_planks":2,"minecraft:polished_diorite":46,"minecraft:sandstone":11,"minecraft:stone_bricks":19},"sha256":"981397198a45fb379c44a34c45362da061723f074ff64404cd2d6dab3a1706d1","size":{"x":32,"y":1,"z":32}},{"blockCount":149,"bytes":4394,"file":"chunks/y102-z160-x128.json","offset":{"x":128,"y":102,"z":160},"requirements":{"minecraft:bricks":15,"minecraft:glass":13,"minecraft:oak_planks":2,"minecraft:polished_diorite":73,"minecraft:sandstone":12,"minecraft:stone_bricks":34},"sha256":"ebeaf5d4c7105a11509a628218ff526510500e977c66a9da9b91aca6ca3fe8b0","size":{"x":32,"y":1,"z":32}},{"blockCount":105,"bytes":3046,"file":"chunks/y102-z160-x160.json","offset":{"x":160,"y":102,"z":160},"requirements":{"minecraft:polished_diorite":66,"minecraft:stone_bricks":39},"sha256":"408c8f3802b34a2f65f7c03131ed5e76c31e7013301f41d22f0820f6ab047e18","size":{"x":32,"y":1,"z":32}},{"blockCount":223,"bytes":4547,"file":"chunks/y102-z160-x192.json","offset":{"x":192,"y":102,"z":160},"requirements":{"minecraft:bricks":95,"minecraft:polished_diorite":90,"minecraft:stone_bricks":38},"sha256":"2e72444992de6d124921b01a4f74adbebd165a17ffbeb66e371fee996ec68fbf","size":{"x":32,"y":1,"z":32}},{"blockCount":124,"bytes":3305,"file":"chunks/y102-z160-x224.json","offset":{"x":224,"y":102,"z":160},"requirements":{"minecraft:bricks":61,"minecraft:polished_diorite":52,"minecraft:stone_bricks":11},"sha256":"f4b0a1a0bfa377abd59611a19a221aedb0741f6f58518b0ade0e65f7ffdac6c0","size":{"x":32,"y":1,"z":32}},{"blockCount":36,"bytes":1831,"file":"chunks/y102-z192-x064.json","offset":{"x":64,"y":102,"z":192},"requirements":{"minecraft:polished_diorite":18,"minecraft:stone_bricks":18},"sha256":"fab3dd78afb7580374d4688e3eca82653da71afc77ed75a6f6c208029e0539aa","size":{"x":32,"y":1,"z":32}},{"blockCount":157,"bytes":3488,"file":"chunks/y102-z192-x096.json","offset":{"x":96,"y":102,"z":192},"requirements":{"minecraft:bricks":29,"minecraft:glass":30,"minecraft:oak_planks":2,"minecraft:polished_diorite":62,"minecraft:sandstone":12,"minecraft:stone_bricks":22},"sha256":"140f8dd1351e240d4b459be047225752fa976f88ce7b23472e2c689ac1cee313","size":{"x":32,"y":1,"z":32}},{"blockCount":148,"bytes":3895,"file":"chunks/y102-z192-x128.json","offset":{"x":128,"y":102,"z":192},"requirements":{"minecraft:bricks":25,"minecraft:glass":14,"minecraft:oak_planks":2,"minecraft:polished_diorite":67,"minecraft:sandstone":5,"minecraft:stone_bricks":35},"sha256":"ec5022fb38d0b1aa8611b72544ce65c43602fe38c9ebe8fb622b69affbd8286b","size":{"x":32,"y":1,"z":32}},{"blockCount":6,"bytes":872,"file":"chunks/y102-z192-x160.json","offset":{"x":160,"y":102,"z":192},"requirements":{"minecraft:polished_diorite":2,"minecraft:stone_bricks":4},"sha256":"dc6661de3f12927fc40dc5e7a8bfea7c23aecb355842ba2d7a77154a5202cb42","size":{"x":32,"y":1,"z":32}},{"blockCount":74,"bytes":2174,"file":"chunks/y103-z064-x064.json","offset":{"x":64,"y":103,"z":64},"requirements":{"minecraft:polished_diorite":63,"minecraft:stone_bricks":11},"sha256":"19ec411dc3096f03c46279ba872170b6c67e242290c6d571d50056f5e94853d9","size":{"x":32,"y":1,"z":32}},{"blockCount":165,"bytes":3835,"file":"chunks/y103-z064-x096.json","offset":{"x":96,"y":103,"z":64},"requirements":{"minecraft:bricks":35,"minecraft:glass":32,"minecraft:oak_planks":3,"minecraft:polished_diorite":67,"minecraft:sandstone":12,"minecraft:stone_bricks":16},"sha256":"1b4dfa75a5af99768928e3614d3293d386560673a5c3c3fb23b4f5e14a829afb","size":{"x":32,"y":1,"z":32}},{"blockCount":197,"bytes":4753,"file":"chunks/y103-z064-x128.json","offset":{"x":128,"y":103,"z":64},"requirements":{"minecraft:bricks":30,"minecraft:glass":17,"minecraft:oak_planks":1,"minecraft:polished_diorite":117,"minecraft:sandstone":8,"minecraft:stone_bricks":24},"sha256":"1f114a6beb0c00b4f16618a68fc003c731dc341147ac1896bb7f413f096ca4e9","size":{"x":32,"y":1,"z":32}},{"blockCount":9,"bytes":947,"file":"chunks/y103-z064-x160.json","offset":{"x":160,"y":103,"z":64},"requirements":{"minecraft:polished_diorite":7,"minecraft:stone_bricks":2},"sha256":"02c4d62beb5700ae9dfff5739557d3d42aabdfd1d6dd0b05584c124bdbb46a7d","size":{"x":32,"y":1,"z":32}},{"blockCount":20,"bytes":1019,"file":"chunks/y103-z064-x192.json","offset":{"x":192,"y":103,"z":64},"requirements":{"minecraft:polished_diorite":14,"minecraft:stone_bricks":6},"sha256":"9a781ebac384500730908bdb3579111c1b37216e600a668beb6966132bed05d8","size":{"x":32,"y":1,"z":32}},{"blockCount":24,"bytes":1097,"file":"chunks/y103-z064-x224.json","offset":{"x":224,"y":103,"z":64},"requirements":{"minecraft:polished_diorite":17,"minecraft:stone_bricks":7},"sha256":"ab611820e1d30fe18aa0db530fe75ac03a4e0eaf226999a1914f6c4eef08029e","size":{"x":32,"y":1,"z":32}},{"blockCount":49,"bytes":1714,"file":"chunks/y103-z096-x000.json","offset":{"x":0,"y":103,"z":96},"requirements":{"minecraft:polished_diorite":42,"minecraft:stone_bricks":7},"sha256":"fafcc51ed4533416aff652ba58ed6f1b02cd05a3c5bf17fcf1f00ada1a720f8b","size":{"x":32,"y":1,"z":32}},{"blockCount":171,"bytes":4432,"file":"chunks/y103-z096-x032.json","offset":{"x":32,"y":103,"z":96},"requirements":{"minecraft:bricks":15,"minecraft:glass":17,"minecraft:polished_diorite":116,"minecraft:sandstone":5,"minecraft:stone_bricks":18},"sha256":"5a2d5b1e0346b9974a6bbd4cf1f08fc6a2482e6ed0b844afa7c460d252168c4a","size":{"x":32,"y":1,"z":32}},{"blockCount":164,"bytes":4304,"file":"chunks/y103-z096-x064.json","offset":{"x":64,"y":103,"z":96},"requirements":{"minecraft:bricks":20,"minecraft:glass":16,"minecraft:oak_planks":1,"minecraft:polished_diorite":95,"minecraft:sandstone":9,"minecraft:stone_bricks":23},"sha256":"928a3115fcce0133c03aa481a00b26dac57c8e254a92ee2b8d437f544b207500","size":{"x":32,"y":1,"z":32}},{"blockCount":103,"bytes":3341,"file":"chunks/y103-z096-x096.json","offset":{"x":96,"y":103,"z":96},"requirements":{"minecraft:bricks":26,"minecraft:glass":11,"minecraft:oak_planks":3,"minecraft:polished_diorite":39,"minecraft:sandstone":14,"minecraft:stone_bricks":10},"sha256":"1ae00c48391467aea512136b46dd52f6dfceef913a42d801b2703101a21ee8dc","size":{"x":32,"y":1,"z":32}},{"blockCount":169,"bytes":4673,"file":"chunks/y103-z096-x128.json","offset":{"x":128,"y":103,"z":96},"requirements":{"minecraft:bricks":36,"minecraft:glass":18,"minecraft:oak_planks":4,"minecraft:polished_diorite":72,"minecraft:sandstone":19,"minecraft:stone_bricks":20},"sha256":"3c257250e41c26d168cb3a4ea65257408bee101cd4e2a41f348f3005eb0473f4","size":{"x":32,"y":1,"z":32}},{"blockCount":180,"bytes":4539,"file":"chunks/y103-z096-x160.json","offset":{"x":160,"y":103,"z":96},"requirements":{"minecraft:bricks":21,"minecraft:glass":18,"minecraft:polished_diorite":111,"minecraft:sandstone":7,"minecraft:stone_bricks":23},"sha256":"08d13d827f4186b0f883bc408adad6b57357ecdeaf891af89408ffda685140d3","size":{"x":32,"y":1,"z":32}},{"blockCount":281,"bytes":5579,"file":"chunks/y103-z096-x192.json","offset":{"x":192,"y":103,"z":96},"requirements":{"minecraft:bricks":131,"minecraft:glass":11,"minecraft:polished_diorite":94,"minecraft:sandstone":5,"minecraft:stone_bricks":40},"sha256":"e89dc2b91685e0bd35cde2579e0da770e97c820dba2b7a23d73800eb158e9dd4","size":{"x":32,"y":1,"z":32}},{"blockCount":147,"bytes":3671,"file":"chunks/y103-z096-x224.json","offset":{"x":224,"y":103,"z":96},"requirements":{"minecraft:bricks":73,"minecraft:polished_diorite":54,"minecraft:sandstone":1,"minecraft:stone_bricks":19},"sha256":"2e4a7862b7db7d5b9f2acef2903d984e0fff639baae43b07416ae2fab626d7e8","size":{"x":32,"y":1,"z":32}},{"blockCount":68,"bytes":2036,"file":"chunks/y103-z128-x000.json","offset":{"x":0,"y":103,"z":128},"requirements":{"minecraft:polished_diorite":62,"minecraft:stone_bricks":6},"sha256":"2d49cd665953f556f029f9f54231c0d33012a4b29342d91e2543047093c15886","size":{"x":32,"y":1,"z":32}},{"blockCount":155,"bytes":4078,"file":"chunks/y103-z128-x032.json","offset":{"x":32,"y":103,"z":128},"requirements":{"minecraft:bricks":40,"minecraft:glass":23,"minecraft:polished_diorite":56,"minecraft:sandstone":16,"minecraft:stone_bricks":20},"sha256":"b4d84ed73248f7acc830b7047ead250912545556a85e18e15120e2b3cba79f21","size":{"x":32,"y":1,"z":32}},{"blockCount":52,"bytes":1744,"file":"chunks/y103-z128-x064.json","offset":{"x":64,"y":103,"z":128},"requirements":{"minecraft:bricks":20,"minecraft:glass":16,"minecraft:oak_planks":1,"minecraft:sandstone":8,"minecraft:stone_bricks":7},"sha256":"0a3361b9f8725e0bf14c28d5d7d2132ebff837e86408c11d58387ab6a6c6dfa6","size":{"x":32,"y":1,"z":32}},{"blockCount":17,"bytes":1097,"file":"chunks/y103-z128-x096.json","offset":{"x":96,"y":103,"z":128},"requirements":{"minecraft:bricks":9,"minecraft:glass":2,"minecraft:oak_planks":1,"minecraft:sandstone":3,"minecraft:stone_bricks":2},"sha256":"f8391f77a5c686dee664d22a264ddcbc54daa2b6cbfb2a719cef1038ed2799f2","size":{"x":32,"y":1,"z":32}},{"blockCount":41,"bytes":1574,"file":"chunks/y103-z128-x128.json","offset":{"x":128,"y":103,"z":128},"requirements":{"minecraft:bricks":18,"minecraft:glass":9,"minecraft:oak_planks":2,"minecraft:sandstone":7,"minecraft:stone_bricks":5},"sha256":"17214e9f964658aac8154ea03ebb18aa87a408a0292d530e5f6ea6a2255d0470","size":{"x":32,"y":1,"z":32}},{"blockCount":53,"bytes":1740,"file":"chunks/y103-z128-x160.json","offset":{"x":160,"y":103,"z":128},"requirements":{"minecraft:bricks":21,"minecraft:glass":18,"minecraft:sandstone":7,"minecraft:stone_bricks":7},"sha256":"a484d950a58e603ad72e733832c7d5d622dcf9565fcf781edaf7f7f77ec50e91","size":{"x":32,"y":1,"z":32}},{"blockCount":57,"bytes":1702,"file":"chunks/y103-z128-x192.json","offset":{"x":192,"y":103,"z":128},"requirements":{"minecraft:bricks":35,"minecraft:glass":11,"minecraft:sandstone":5,"minecraft:stone_bricks":6},"sha256":"16b9c00a0af102f97dc9f45b6731930cdad9496453cc47a0b76a52ed8536ec81","size":{"x":32,"y":1,"z":32}},{"blockCount":114,"bytes":3002,"file":"chunks/y103-z128-x224.json","offset":{"x":224,"y":103,"z":128},"requirements":{"minecraft:bricks":36,"minecraft:glass":19,"minecraft:oak_planks":2,"minecraft:polished_diorite":40,"minecraft:sandstone":7,"minecraft:stone_bricks":10},"sha256":"1699e0db1c7aafcce29b8cd260538361052a3c61db9298df321ba718c09f74f1","size":{"x":32,"y":1,"z":32}},{"blockCount":31,"bytes":1330,"file":"chunks/y103-z160-x000.json","offset":{"x":0,"y":103,"z":160},"requirements":{"minecraft:polished_diorite":26,"minecraft:stone_bricks":5},"sha256":"36f141f0eec8b975eeaf9de2f42492ce202d28670f793421830bd739b511c497","size":{"x":32,"y":1,"z":32}},{"blockCount":118,"bytes":3089,"file":"chunks/y103-z160-x032.json","offset":{"x":32,"y":103,"z":160},"requirements":{"minecraft:polished_diorite":105,"minecraft:stone_bricks":13},"sha256":"43a810e810714eb030c7a77b9c8195665a6c00db7c3014c7be290260ba0c9584","size":{"x":32,"y":1,"z":32}},{"blockCount":124,"bytes":3381,"file":"chunks/y103-z160-x064.json","offset":{"x":64,"y":103,"z":160},"requirements":{"minecraft:polished_diorite":106,"minecraft:sandstone":1,"minecraft:stone_bricks":17},"sha256":"27ce9df968eaa074fd948a32aecceaf442c8f6d24e3eeffdc4e91c4fd453910a","size":{"x":32,"y":1,"z":32}},{"blockCount":111,"bytes":3515,"file":"chunks/y103-z160-x096.json","offset":{"x":96,"y":103,"z":160},"requirements":{"minecraft:bricks":22,"minecraft:glass":15,"minecraft:oak_planks":2,"minecraft:polished_diorite":48,"minecraft:sandstone":13,"minecraft:stone_bricks":11},"sha256":"59934a712e998b6844875905b994cdf840c33446f70ce2034ac5a866f9f47715","size":{"x":32,"y":1,"z":32}},{"blockCount":159,"bytes":4545,"file":"chunks/y103-z160-x128.json","offset":{"x":128,"y":103,"z":160},"requirements":{"minecraft:bricks":20,"minecraft:glass":13,"minecraft:oak_planks":2,"minecraft:polished_diorite":91,"minecraft:sandstone":14,"minecraft:stone_bricks":19},"sha256":"9771b6d1e2d586c7e25a474c3a86789bea17a1bf064c33da6058b9b7604acccf","size":{"x":32,"y":1,"z":32}},{"blockCount":128,"bytes":3462,"file":"chunks/y103-z160-x160.json","offset":{"x":160,"y":103,"z":160},"requirements":{"minecraft:polished_diorite":112,"minecraft:stone_bricks":16},"sha256":"4ebbdcdf8aeb58742ba75bc37f88b705c44c1a2a31e84d8e08882f837f172daa","size":{"x":32,"y":1,"z":32}},{"blockCount":244,"bytes":4888,"file":"chunks/y103-z160-x192.json","offset":{"x":192,"y":103,"z":160},"requirements":{"minecraft:bricks":96,"minecraft:polished_diorite":108,"minecraft:stone_bricks":40},"sha256":"ee5400ba993b5718fd089cd9aeabbbe5b96fb2484dc83cad28f73e3422f2f0e1","size":{"x":32,"y":1,"z":32}},{"blockCount":124,"bytes":3381,"file":"chunks/y103-z160-x224.json","offset":{"x":224,"y":103,"z":160},"requirements":{"minecraft:bricks":61,"minecraft:polished_diorite":43,"minecraft:stone_bricks":20},"sha256":"42e66e3fcf6d47a7254a7326a22e5ba860d4489bb730ea44fd9476033b10f9ea","size":{"x":32,"y":1,"z":32}},{"blockCount":62,"bytes":1945,"file":"chunks/y103-z192-x064.json","offset":{"x":64,"y":103,"z":192},"requirements":{"minecraft:polished_diorite":52,"minecraft:stone_bricks":10},"sha256":"8810ec4ce93771e6caecc117741f2e42b1ac40fe5098e037bb9f4ca86a183e7a","size":{"x":32,"y":1,"z":32}},{"blockCount":143,"bytes":3393,"file":"chunks/y103-z192-x096.json","offset":{"x":96,"y":103,"z":192},"requirements":{"minecraft:bricks":30,"minecraft:glass":29,"minecraft:oak_planks":3,"minecraft:polished_diorite":58,"minecraft:sandstone":10,"minecraft:stone_bricks":13},"sha256":"f721209ffa20d46b0196a50f6430cb64c88fb6bae2d77ba9e3826250f60151fe","size":{"x":32,"y":1,"z":32}},{"blockCount":166,"bytes":4065,"file":"chunks/y103-z192-x128.json","offset":{"x":128,"y":103,"z":192},"requirements":{"minecraft:bricks":28,"minecraft:glass":13,"minecraft:oak_planks":1,"minecraft:polished_diorite":98,"minecraft:sandstone":6,"minecraft:stone_bricks":20},"sha256":"40b1fa22b268ed79ab9b88c112c01eb17a975a10758bc846d1ae5db2f3930535","size":{"x":32,"y":1,"z":32}},{"blockCount":8,"bytes":910,"file":"chunks/y103-z192-x160.json","offset":{"x":160,"y":103,"z":192},"requirements":{"minecraft:polished_diorite":6,"minecraft:stone_bricks":2},"sha256":"48136a66821b6ac455c20233be068d273dd1dfbac068dd065a70001682fa615e","size":{"x":32,"y":1,"z":32}},{"blockCount":2,"bytes":685,"file":"chunks/y104-z064-x032.json","offset":{"x":32,"y":104,"z":64},"requirements":{"minecraft:polished_diorite":2},"sha256":"9352919d50dd142a2d705b1adb02e8d6a0ef6d83013c8df22f6bbf920e55c2c2","size":{"x":32,"y":1,"z":32}},{"blockCount":74,"bytes":1984,"file":"chunks/y104-z064-x064.json","offset":{"x":64,"y":104,"z":64},"requirements":{"minecraft:polished_diorite":54,"minecraft:stone_bricks":20},"sha256":"a2547a66f2fd2be5fe6b7280f83e8464cc746aabee1faea47214df0a86ec7943","size":{"x":32,"y":1,"z":32}},{"blockCount":171,"bytes":3930,"file":"chunks/y104-z064-x096.json","offset":{"x":96,"y":104,"z":64},"requirements":{"minecraft:bricks":29,"minecraft:glass":30,"minecraft:oak_planks":4,"minecraft:polished_diorite":74,"minecraft:sandstone":16,"minecraft:stone_bricks":18},"sha256":"f16d6b29e272500d1304d60dacfe0169dad9c698cef6f442977c0cd941a0bf9c","size":{"x":32,"y":1,"z":32}},{"blockCount":195,"bytes":4620,"file":"chunks/y104-z064-x128.json","offset":{"x":128,"y":104,"z":64},"requirements":{"minecraft:bricks":26,"minecraft:glass":17,"minecraft:oak_planks":2,"minecraft:polished_diorite":109,"minecraft:sandstone":8,"minecraft:stone_bricks":33},"sha256":"7186f68a97aa6b85f04f21f05492f38f6db909292d41b13abbfc43b20cf49454","size":{"x":32,"y":1,"z":32}},{"blockCount":19,"bytes":988,"file":"chunks/y104-z064-x160.json","offset":{"x":160,"y":104,"z":64},"requirements":{"minecraft:polished_diorite":14,"minecraft:stone_bricks":5},"sha256":"3fcf398b299382fd93e71fd7d8fc2aeef3892bd09a0280bb7345976a976e042a","size":{"x":32,"y":1,"z":32}},{"blockCount":23,"bytes":1056,"file":"chunks/y104-z064-x192.json","offset":{"x":192,"y":104,"z":64},"requirements":{"minecraft:polished_diorite":20,"minecraft:stone_bricks":3},"sha256":"51dd3fa08a3d41c54339cdb7b7d6e54f76f4ef688dad5c38d55f0bc05786648f","size":{"x":32,"y":1,"z":32}},{"blockCount":24,"bytes":1019,"file":"chunks/y104-z064-x224.json","offset":{"x":224,"y":104,"z":64},"requirements":{"minecraft:polished_diorite":21,"minecraft:stone_bricks":3},"sha256":"d3723e8b48c9772907a3015bf09ee7e385a16cc7368427b3c9d81ef334990aa8","size":{"x":32,"y":1,"z":32}},{"blockCount":43,"bytes":1658,"file":"chunks/y104-z096-x000.json","offset":{"x":0,"y":104,"z":96},"requirements":{"minecraft:polished_diorite":29,"minecraft:stone_bricks":14},"sha256":"bcc7d962ba0bdb25c3e48ba95374ec7344f73b82c12be855cf104746dca942f8","size":{"x":32,"y":1,"z":32}},{"blockCount":175,"bytes":4569,"file":"chunks/y104-z096-x032.json","offset":{"x":32,"y":104,"z":96},"requirements":{"minecraft:bricks":12,"minecraft:glass":17,"minecraft:polished_diorite":113,"minecraft:sandstone":5,"minecraft:stone_bricks":28},"sha256":"66419a74184f3e2894361d7d53cbd72c6b885039cd99d20d026ecbc6984184aa","size":{"x":32,"y":1,"z":32}},{"blockCount":168,"bytes":4121,"file":"chunks/y104-z096-x064.json","offset":{"x":64,"y":104,"z":96},"requirements":{"minecraft:bricks":16,"minecraft:glass":16,"minecraft:polished_diorite":94,"minecraft:sandstone":9,"minecraft:stone_bricks":33},"sha256":"7af20e46d05c2a9b359ad9668306b903013dcbd9085d0c94b8284c88d4a9b7e4","size":{"x":32,"y":1,"z":32}},{"blockCount":110,"bytes":3335,"file":"chunks/y104-z096-x096.json","offset":{"x":96,"y":104,"z":96},"requirements":{"minecraft:bricks":23,"minecraft:glass":11,"minecraft:polished_diorite":44,"minecraft:sandstone":14,"minecraft:stone_bricks":18},"sha256":"cd8e1369742b1d09fa9982be92b8ff64b252912169dc0ae156d1cd75948a17ab","size":{"x":32,"y":1,"z":32}},{"blockCount":175,"bytes":4477,"file":"chunks/y104-z096-x128.json","offset":{"x":128,"y":104,"z":96},"requirements":{"minecraft:bricks":32,"minecraft:glass":18,"minecraft:polished_diorite":77,"minecraft:sandstone":19,"minecraft:stone_bricks":29},"sha256":"7ca9d6271efabc77af25e0d6af2b70f7138ac8ae6db727c16429eceae69f6373","size":{"x":32,"y":1,"z":32}},{"blockCount":187,"bytes":4651,"file":"chunks/y104-z096-x160.json","offset":{"x":160,"y":104,"z":96},"requirements":{"minecraft:bricks":16,"minecraft:glass":18,"minecraft:polished_diorite":109,"minecraft:sandstone":7,"minecraft:stone_bricks":37},"sha256":"8d9bb3be450d71931fb1113e10015aa6c57d5639e78d8f3e6e74a3abd3670d9c","size":{"x":32,"y":1,"z":32}},{"blockCount":279,"bytes":5500,"file":"chunks/y104-z096-x192.json","offset":{"x":192,"y":104,"z":96},"requirements":{"minecraft:bricks":126,"minecraft:glass":11,"minecraft:polished_diorite":99,"minecraft:sandstone":5,"minecraft:stone_bricks":38},"sha256":"a3a08241f1b96f33e35104dfa74ea13b914ba9498ee9f000f3a034819defad6f","size":{"x":32,"y":1,"z":32}},{"blockCount":146,"bytes":3576,"file":"chunks/y104-z096-x224.json","offset":{"x":224,"y":104,"z":96},"requirements":{"minecraft:bricks":73,"minecraft:polished_diorite":61,"minecraft:sandstone":1,"minecraft:stone_bricks":11},"sha256":"4b4e501580283c559721a2d8e7cd3b4b55c0abd6283e8baf7ec545ce19296e96","size":{"x":32,"y":1,"z":32}},{"blockCount":74,"bytes":2206,"file":"chunks/y104-z128-x000.json","offset":{"x":0,"y":104,"z":128},"requirements":{"minecraft:polished_diorite":62,"minecraft:stone_bricks":12},"sha256":"da33fe7a5a4d0e1db22e7f29b5e81e0aa9dca4576171cc756494a0ca3c13995b","size":{"x":32,"y":1,"z":32}},{"blockCount":158,"bytes":4022,"file":"chunks/y104-z128-x032.json","offset":{"x":32,"y":104,"z":128},"requirements":{"minecraft:bricks":41,"minecraft:glass":23,"minecraft:polished_diorite":59,"minecraft:sandstone":15,"minecraft:stone_bricks":20},"sha256":"7537ff6ac3f11cd8cd8b4df42c7c58b1471b4c6bb32e8cf9285a12c09a76a55e","size":{"x":32,"y":1,"z":32}},{"blockCount":53,"bytes":1682,"file":"chunks/y104-z128-x064.json","offset":{"x":64,"y":104,"z":128},"requirements":{"minecraft:bricks":16,"minecraft:glass":16,"minecraft:sandstone":8,"minecraft:stone_bricks":13},"sha256":"e9a0f5cb86e69cb1d772a16b80701e6ec1be2c5a625df8aaf2750516d59897eb","size":{"x":32,"y":1,"z":32}},{"blockCount":17,"bytes":1053,"file":"chunks/y104-z128-x096.json","offset":{"x":96,"y":104,"z":128},"requirements":{"minecraft:bricks":8,"minecraft:glass":2,"minecraft:sandstone":3,"minecraft:stone_bricks":4},"sha256":"d0121c977f2f401b4423bcce82ac851ea81df140f4538741ccc803fcf1ec254a","size":{"x":32,"y":1,"z":32}},{"blockCount":42,"bytes":1474,"file":"chunks/y104-z128-x128.json","offset":{"x":128,"y":104,"z":128},"requirements":{"minecraft:bricks":16,"minecraft:glass":9,"minecraft:sandstone":7,"minecraft:stone_bricks":10},"sha256":"2980ab61d6aeca314743dd41f4c2d1967cc20b0770667dd4d47694d092f648bd","size":{"x":32,"y":1,"z":32}},{"blockCount":53,"bytes":1741,"file":"chunks/y104-z128-x160.json","offset":{"x":160,"y":104,"z":128},"requirements":{"minecraft:bricks":16,"minecraft:glass":18,"minecraft:sandstone":7,"minecraft:stone_bricks":12},"sha256":"88c35bf06cc7489481016aec6e8b4f105da4c8e5f0ebc2ee053c31afebaf5cf3","size":{"x":32,"y":1,"z":32}},{"blockCount":59,"bytes":1665,"file":"chunks/y104-z128-x192.json","offset":{"x":192,"y":104,"z":128},"requirements":{"minecraft:bricks":31,"minecraft:glass":11,"minecraft:sandstone":5,"minecraft:stone_bricks":12},"sha256":"ca321c9f0edde689a349310fb227603bc13a76177f601e6f8ec418b4381f5331","size":{"x":32,"y":1,"z":32}},{"blockCount":116,"bytes":3116,"file":"chunks/y104-z128-x224.json","offset":{"x":224,"y":104,"z":128},"requirements":{"minecraft:bricks":32,"minecraft:glass":17,"minecraft:oak_planks":4,"minecraft:polished_diorite":43,"minecraft:sandstone":11,"minecraft:stone_bricks":9},"sha256":"d6e254c44e78b0fa7689fc6062d5e1572902a205aef4920a692d74080d8e0026","size":{"x":32,"y":1,"z":32}},{"blockCount":27,"bytes":1255,"file":"chunks/y104-z160-x000.json","offset":{"x":0,"y":104,"z":160},"requirements":{"minecraft:polished_diorite":17,"minecraft:stone_bricks":10},"sha256":"bfcddd71b62894bba3c35828cca5ec26b8860266af5df43f1eb16891989e8e80","size":{"x":32,"y":1,"z":32}},{"blockCount":123,"bytes":3360,"file":"chunks/y104-z160-x032.json","offset":{"x":32,"y":104,"z":160},"requirements":{"minecraft:polished_diorite":103,"minecraft:stone_bricks":20},"sha256":"3e61868d9f5e9f573a35e8723a0cfc09e674a478c50c5ec30613a2b6c4f997bb","size":{"x":32,"y":1,"z":32}},{"blockCount":127,"bytes":3280,"file":"chunks/y104-z160-x064.json","offset":{"x":64,"y":104,"z":160},"requirements":{"minecraft:polished_diorite":102,"minecraft:sandstone":1,"minecraft:stone_bricks":24},"sha256":"86f2492143e21c9f721ac4d353a0a02f54b2fe3a94738473470a2c3e5963a244","size":{"x":32,"y":1,"z":32}},{"blockCount":119,"bytes":3547,"file":"chunks/y104-z160-x096.json","offset":{"x":96,"y":104,"z":160},"requirements":{"minecraft:bricks":19,"minecraft:glass":15,"minecraft:polished_diorite":54,"minecraft:sandstone":13,"minecraft:stone_bricks":18},"sha256":"889e7c2944495aa033fae0e0a9ed826fa685a2b57288bd985b0f143cc06567fe","size":{"x":32,"y":1,"z":32}},{"blockCount":164,"bytes":4425,"file":"chunks/y104-z160-x128.json","offset":{"x":128,"y":104,"z":160},"requirements":{"minecraft:bricks":17,"minecraft:glass":13,"minecraft:polished_diorite":94,"minecraft:sandstone":14,"minecraft:stone_bricks":26},"sha256":"a378bf453625a676b0b9a43f3ece79dc186bbe4e7f9039cf2ee8647cae862003","size":{"x":32,"y":1,"z":32}},{"blockCount":137,"bytes":3653,"file":"chunks/y104-z160-x160.json","offset":{"x":160,"y":104,"z":160},"requirements":{"minecraft:polished_diorite":111,"minecraft:stone_bricks":26},"sha256":"207a4fd3a39542ea11f5d6f114109bd2acdcb1411e3d7eab683adfc2798e0c07","size":{"x":32,"y":1,"z":32}},{"blockCount":243,"bytes":4903,"file":"chunks/y104-z160-x192.json","offset":{"x":192,"y":104,"z":160},"requirements":{"minecraft:bricks":95,"minecraft:polished_diorite":119,"minecraft:stone_bricks":29},"sha256":"d50aa24a8b3c6ad1f25deb5972e03e56f6379419f85872b276cef7bebf2a413d","size":{"x":32,"y":1,"z":32}},{"blockCount":121,"bytes":3169,"file":"chunks/y104-z160-x224.json","offset":{"x":224,"y":104,"z":160},"requirements":{"minecraft:bricks":61,"minecraft:polished_diorite":51,"minecraft:stone_bricks":9},"sha256":"aa0df2408e3875395159d6cf5a7506f2af70d20963e260e696492ac065553e33","size":{"x":32,"y":1,"z":32}},{"blockCount":62,"bytes":1717,"file":"chunks/y104-z192-x064.json","offset":{"x":64,"y":104,"z":192},"requirements":{"minecraft:polished_diorite":46,"minecraft:stone_bricks":16},"sha256":"6c9564f5b00493a77a8480f81758356853c01e252eea206b0bd3059dc9f402e8","size":{"x":32,"y":1,"z":32}},{"blockCount":148,"bytes":3430,"file":"chunks/y104-z192-x096.json","offset":{"x":96,"y":104,"z":192},"requirements":{"minecraft:bricks":25,"minecraft:glass":27,"minecraft:oak_planks":4,"minecraft:polished_diorite":64,"minecraft:sandstone":14,"minecraft:stone_bricks":14},"sha256":"c0a4288bcc5715ff3894374e4912b637de55a52193d9a4378356659e1bef2636","size":{"x":32,"y":1,"z":32}},{"blockCount":164,"bytes":3932,"file":"chunks/y104-z192-x128.json","offset":{"x":128,"y":104,"z":192},"requirements":{"minecraft:bricks":25,"minecraft:glass":13,"minecraft:oak_planks":2,"minecraft:polished_diorite":92,"minecraft:sandstone":6,"minecraft:stone_bricks":26},"sha256":"0e90d57c48f848445d49070a50c36526fedb5c8068afe1a62cccdc0bc24d4026","size":{"x":32,"y":1,"z":32}},{"blockCount":16,"bytes":873,"file":"chunks/y104-z192-x160.json","offset":{"x":160,"y":104,"z":192},"requirements":{"minecraft:polished_diorite":12,"minecraft:stone_bricks":4},"sha256":"3b038ca65f8b6659137c649587936a4609588d6baa1e2c4c1eea0173d3f1d746","size":{"x":32,"y":1,"z":32}},{"blockCount":2,"bytes":685,"file":"chunks/y105-z064-x032.json","offset":{"x":32,"y":105,"z":64},"requirements":{"minecraft:polished_diorite":2},"sha256":"70cd4ee370b4affd6f7722a0cf0637e39acf4db966d288937c7c67844950ca5d","size":{"x":32,"y":1,"z":32}},{"blockCount":69,"bytes":2420,"file":"chunks/y105-z064-x064.json","offset":{"x":64,"y":105,"z":64},"requirements":{"minecraft:polished_diorite":49,"minecraft:stone_bricks":20},"sha256":"b4d5da7d4cb94f3d47c9de3e0ab54afb67c7196188152f4d4f4dc4a91271fcf6","size":{"x":32,"y":1,"z":32}},{"blockCount":178,"bytes":4215,"file":"chunks/y105-z064-x096.json","offset":{"x":96,"y":105,"z":64},"requirements":{"minecraft:bricks":35,"minecraft:glass":28,"minecraft:oak_planks":4,"minecraft:polished_diorite":67,"minecraft:sandstone":13,"minecraft:stone_bricks":31},"sha256":"5f5db610f6045b18ea26b9b354b1d22a1e29810eb35026c3f2858d9e8c044e7c","size":{"x":32,"y":1,"z":32}},{"blockCount":196,"bytes":4976,"file":"chunks/y105-z064-x128.json","offset":{"x":128,"y":105,"z":64},"requirements":{"minecraft:bricks":24,"minecraft:glass":17,"minecraft:oak_planks":4,"minecraft:polished_diorite":99,"minecraft:sandstone":7,"minecraft:stone_bricks":45},"sha256":"3b3e863bcd644eb96935f0ffe64f7be9ecb26ae93af136f7f68c5d100d0cceaa","size":{"x":32,"y":1,"z":32}},{"blockCount":17,"bytes":1064,"file":"chunks/y105-z064-x160.json","offset":{"x":160,"y":105,"z":64},"requirements":{"minecraft:polished_diorite":12,"minecraft:stone_bricks":5},"sha256":"e9314497d4b48df275e6bee35bf656fc890bbbc40c95ad8e423033034cc1b3a4","size":{"x":32,"y":1,"z":32}},{"blockCount":28,"bytes":1190,"file":"chunks/y105-z064-x192.json","offset":{"x":192,"y":105,"z":64},"requirements":{"minecraft:polished_diorite":21,"minecraft:stone_bricks":7},"sha256":"6bdbb4d2838655f99c1691694e11353f5d6134c7295177951484ec7e64b07fff","size":{"x":32,"y":1,"z":32}},{"blockCount":31,"bytes":1248,"file":"chunks/y105-z064-x224.json","offset":{"x":224,"y":105,"z":64},"requirements":{"minecraft:polished_diorite":24,"minecraft:stone_bricks":7},"sha256":"8b4487f9fc40ee5a4a40c7a9ca528f2f9e97e9726cfe46645b015ba5a8a46fd6","size":{"x":32,"y":1,"z":32}},{"blockCount":41,"bytes":1772,"file":"chunks/y105-z096-x000.json","offset":{"x":0,"y":105,"z":96},"requirements":{"minecraft:polished_diorite":26,"minecraft:stone_bricks":15},"sha256":"62ca08977bcd8d7f90121f4a01a237f0290e0c14fdf7e30df94ac8e6e9533155","size":{"x":32,"y":1,"z":32}},{"blockCount":173,"bytes":5004,"file":"chunks/y105-z096-x032.json","offset":{"x":32,"y":105,"z":96},"requirements":{"minecraft:bricks":12,"minecraft:glass":17,"minecraft:polished_diorite":102,"minecraft:sandstone":5,"minecraft:stone_bricks":37},"sha256":"8cfa6ace0297bc1fedb3e91384d0e5601933f0bcc536d61d44db3532efed2531","size":{"x":32,"y":1,"z":32}},{"blockCount":168,"bytes":4657,"file":"chunks/y105-z096-x064.json","offset":{"x":64,"y":105,"z":96},"requirements":{"minecraft:bricks":17,"minecraft:glass":16,"minecraft:polished_diorite":83,"minecraft:sandstone":8,"minecraft:stone_bricks":44},"sha256":"0e3b068c5d5a3c04e53e266146bf7bd41a7a01eff7544777fb2d19f2770f39d0","size":{"x":32,"y":1,"z":32}},{"blockCount":113,"bytes":3525,"file":"chunks/y105-z096-x096.json","offset":{"x":96,"y":105,"z":96},"requirements":{"minecraft:bricks":26,"minecraft:glass":11,"minecraft:polished_diorite":38,"minecraft:sandstone":11,"minecraft:stone_bricks":27},"sha256":"45a9c5db5e80e3df76548771cf47951a8b308da02b9d579e678eb3c57f07fb9e","size":{"x":32,"y":1,"z":32}},{"blockCount":183,"bytes":4836,"file":"chunks/y105-z096-x128.json","offset":{"x":128,"y":105,"z":96},"requirements":{"minecraft:bricks":36,"minecraft:glass":18,"minecraft:polished_diorite":71,"minecraft:sandstone":15,"minecraft:stone_bricks":43},"sha256":"c1d34dc62e8ca72916e7fcb835c150fc05c6928759af55fc3aee8b2d2b2f1f70","size":{"x":32,"y":1,"z":32}},{"blockCount":181,"bytes":5258,"file":"chunks/y105-z096-x160.json","offset":{"x":160,"y":105,"z":96},"requirements":{"minecraft:bricks":16,"minecraft:glass":18,"minecraft:polished_diorite":93,"minecraft:sandstone":7,"minecraft:stone_bricks":47},"sha256":"bd84c2f8888543cb812d1767531a96322a6a44f3de877bf65861ba1b5cfaa714","size":{"x":32,"y":1,"z":32}},{"blockCount":285,"bytes":5896,"file":"chunks/y105-z096-x192.json","offset":{"x":192,"y":105,"z":96},"requirements":{"minecraft:bricks":119,"minecraft:glass":12,"minecraft:oak_planks":3,"minecraft:polished_diorite":93,"minecraft:sandstone":3,"minecraft:spruce_planks":1,"minecraft:stone_bricks":54},"sha256":"bff0f588e6ef8622167ee7d83beeda94c60403bd84433ad95dd06701bd1a8ff8","size":{"x":32,"y":1,"z":32}},{"blockCount":155,"bytes":3899,"file":"chunks/y105-z096-x224.json","offset":{"x":224,"y":105,"z":96},"requirements":{"minecraft:bricks":73,"minecraft:glass":1,"minecraft:polished_diorite":63,"minecraft:sandstone":1,"minecraft:stone_bricks":17},"sha256":"10480b1b44cde5b70f7703aff243b405358df394fffd1b61bc1213bd39e205b4","size":{"x":32,"y":1,"z":32}},{"blockCount":72,"bytes":2396,"file":"chunks/y105-z128-x000.json","offset":{"x":0,"y":105,"z":128},"requirements":{"minecraft:polished_diorite":57,"minecraft:stone_bricks":15},"sha256":"e3a141e10c873da73338d37e04125606a5fe76536fa8d7bb4444981050cfed43","size":{"x":32,"y":1,"z":32}},{"blockCount":160,"bytes":4117,"file":"chunks/y105-z128-x032.json","offset":{"x":32,"y":105,"z":128},"requirements":{"minecraft:bricks":43,"minecraft:glass":23,"minecraft:polished_diorite":54,"minecraft:sandstone":13,"minecraft:stone_bricks":27},"sha256":"b21df3896cd703eda9236e8e0f059d454cdbb103c777d589befe52ba73b8918b","size":{"x":32,"y":1,"z":32}},{"blockCount":54,"bytes":1663,"file":"chunks/y105-z128-x064.json","offset":{"x":64,"y":105,"z":128},"requirements":{"minecraft:bricks":17,"minecraft:glass":16,"minecraft:sandstone":7,"minecraft:stone_bricks":14},"sha256":"dc5bc0dcb7e76d1338b701841ba472f0dcbb72dcf2b87c2a363c55ae6252c5cb","size":{"x":32,"y":1,"z":32}},{"blockCount":18,"bytes":1053,"file":"chunks/y105-z128-x096.json","offset":{"x":96,"y":105,"z":128},"requirements":{"minecraft:bricks":9,"minecraft:glass":2,"minecraft:sandstone":2,"minecraft:stone_bricks":5},"sha256":"59d16001683762bf039753a738f7accf4642259b886eb0748d2fb90ddcc15204","size":{"x":32,"y":1,"z":32}},{"blockCount":44,"bytes":1474,"file":"chunks/y105-z128-x128.json","offset":{"x":128,"y":105,"z":128},"requirements":{"minecraft:bricks":18,"minecraft:glass":9,"minecraft:sandstone":5,"minecraft:stone_bricks":12},"sha256":"0572aef2e9ec5ee55a4931968bcff62d634b09caf53cd445ad1e599f23c0c5ec","size":{"x":32,"y":1,"z":32}},{"blockCount":53,"bytes":1741,"file":"chunks/y105-z128-x160.json","offset":{"x":160,"y":105,"z":128},"requirements":{"minecraft:bricks":16,"minecraft:glass":18,"minecraft:sandstone":7,"minecraft:stone_bricks":12},"sha256":"802f6de94cf665b2fc2565446fa1c1c07139a95b1843e6020679ebc326e77f34","size":{"x":32,"y":1,"z":32}},{"blockCount":61,"bytes":1514,"file":"chunks/y105-z128-x192.json","offset":{"x":192,"y":105,"z":128},"requirements":{"minecraft:bricks":33,"minecraft:glass":11,"minecraft:sandstone":3,"minecraft:stone_bricks":14},"sha256":"8c77309a1125600bde1f430c093034f7bc8d7e2fc7761cd542da85c52a8ff676","size":{"x":32,"y":1,"z":32}},{"blockCount":119,"bytes":3192,"file":"chunks/y105-z128-x224.json","offset":{"x":224,"y":105,"z":128},"requirements":{"minecraft:bricks":35,"minecraft:glass":15,"minecraft:oak_planks":6,"minecraft:polished_diorite":43,"minecraft:sandstone":7,"minecraft:stone_bricks":13},"sha256":"4bfdee80a0bec0a8d97a604f17745752ed5151d7bf72907ee4a0247768fd6447","size":{"x":32,"y":1,"z":32}}],"schema":1}
