{"entries":[{"blockCount":25,"bytes":1331,"file":"chunks/y105-z160-x000.json","offset":{"x":0,"y":105,"z":160},"requirements":{"minecraft:polished_diorite":15,"minecraft:stone_bricks":10},"sha256":"a1760c956575dfe85d42b25d7682f066c524033d7316c4c72a791330c38a318b","size":{"x":32,"y":1,"z":32}},{"blockCount":119,"bytes":3737,"file":"chunks/y105-z160-x032.json","offset":{"x":32,"y":105,"z":160},"requirements":{"minecraft:polished_diorite":93,"minecraft:stone_bricks":26},"sha256":"74bf741614a44f29f5236559e2e4351e4e10cbf1669856cfe0f39a4bb6deee03","size":{"x":32,"y":1,"z":32}},{"blockCount":125,"bytes":3910,"file":"chunks/y105-z160-x064.json","offset":{"x":64,"y":105,"z":160},"requirements":{"minecraft:polished_diorite":90,"minecraft:sandstone":1,"minecraft:stone_bricks":34},"sha256":"6b967ef8ca05c6ed1b40bff24dcab9c676cfe67dae551afa7d333d883e737115","size":{"x":32,"y":1,"z":32}},{"blockCount":121,"bytes":3775,"file":"chunks/y105-z160-x096.json","offset":{"x":96,"y":105,"z":160},"requirements":{"minecraft:bricks":21,"minecraft:glass":15,"minecraft:polished_diorite":46,"minecraft:sandstone":11,"minecraft:stone_bricks":28},"sha256":"0d6420bbaba640ed18761aec95b558a94b94da523d24171decee734cfab2b04a","size":{"x":32,"y":1,"z":32}},{"blockCount":169,"bytes":4841,"file":"chunks/y105-z160-x128.json","offset":{"x":128,"y":105,"z":160},"requirements":{"minecraft:bricks":19,"minecraft:glass":13,"minecraft:polished_diorite":85,"minecraft:sandstone":12,"minecraft:stone_bricks":40},"sha256":"a02fde8337d6ee669db2464f9f48124109407f5db56cc29fe2fb2f7061e0be67","size":{"x":32,"y":1,"z":32}},{"blockCount":131,"bytes":4260,"file":"chunks/y105-z160-x160.json","offset":{"x":160,"y":105,"z":160},"requirements":{"minecraft:polished_diorite":95,"minecraft:stone_bricks":36},"sha256":"f12d50569edfdbfc42fc87f13307d03d3441d39ba2be034eb4079eef63cdafd1","size":{"x":32,"y":1,"z":32}},{"blockCount":252,"bytes":5585,"file":"chunks/y105-z160-x192.json","offset":{"x":192,"y":105,"z":160},"requirements":{"minecraft:bricks":86,"minecraft:glass":1,"minecraft:oak_planks":3,"minecraft:polished_diorite":114,"minecraft:spruce_planks":1,"minecraft:stone_bricks":47},"sha256":"8d4d82e5b2ea87d84563abed3782f9734c8dfa3644fab6d482c39ebda77f5a99","size":{"x":32,"y":1,"z":32}},{"blockCount":136,"bytes":3608,"file":"chunks/y105-z160-x224.json","offset":{"x":224,"y":105,"z":160},"requirements":{"minecraft:bricks":60,"minecraft:glass":1,"minecraft:polished_diorite":58,"minecraft:stone_bricks":17},"sha256":"dc2a4aee6ac528688df63fdb859263fb5da806a462151f0e0bf0085b66b6a0ca","size":{"x":32,"y":1,"z":32}},{"blockCount":58,"bytes":2097,"file":"chunks/y105-z192-x064.json","offset":{"x":64,"y":105,"z":192},"requirements":{"minecraft:polished_diorite":42,"minecraft:stone_bricks":16},"sha256":"25ecd979b97edcc35f862ff2a8bdf084a1f27df2de89951b94d3fbd5f86d803b","size":{"x":32,"y":1,"z":32}},{"blockCount":155,"bytes":3697,"file":"chunks/y105-z192-x096.json","offset":{"x":96,"y":105,"z":192},"requirements":{"minecraft:bricks":31,"minecraft:glass":25,"minecraft:oak_planks":4,"minecraft:polished_diorite":59,"minecraft:sandstone":11,"minecraft:stone_bricks":25},"sha256":"cbac2f0b4f195f6f489fb2d951e2609ddbdb1dab563c20f5450189c8d1295aa1","size":{"x":32,"y":1,"z":32}},{"blockCount":166,"bytes":4212,"file":"chunks/y105-z192-x128.json","offset":{"x":128,"y":105,"z":192},"requirements":{"minecraft:bricks":23,"minecraft:glass":13,"minecraft:oak_planks":4,"minecraft:polished_diorite":85,"minecraft:sandstone":5,"minecraft:stone_bricks":36},"sha256":"dd264ee4fe1bbaf15fbff8187a3e3da26e738b8a533a559b8cba9883283d773f","size":{"x":32,"y":1,"z":32}},{"blockCount":14,"bytes":949,"file":"chunks/y105-z192-x160.json","offset":{"x":160,"y":105,"z":192},"requirements":{"minecraft:polished_diorite":10,"minecraft:stone_bricks":4},"sha256":"17c73cf1534949451b1434597b0996baa76eeb16a943df32d8ea29c0ee69849a","size":{"x":32,"y":1,"z":32}},{"blockCount":42,"bytes":1616,"file":"chunks/y106-z064-x064.json","offset":{"x":64,"y":106,"z":64},"requirements":{"minecraft:polished_diorite":37,"minecraft:stone_bricks":5},"sha256":"e38326cf0974985be741d7986e8237bb9d5c86adaf1eb954ff75f0d8fb8b9252","size":{"x":32,"y":1,"z":32}},{"blockCount":172,"bytes":4119,"file":"chunks/y106-z064-x096.json","offset":{"x":96,"y":106,"z":64},"requirements":{"minecraft:bricks":35,"minecraft:glass":27,"minecraft:oak_planks":4,"minecraft:polished_diorite":69,"minecraft:sandstone":17,"minecraft:stone_bricks":20},"sha256":"1a988bb659461c740a120cc67caeae4e0d02f259d8351dafbeaeed34461681be","size":{"x":32,"y":1,"z":32}},{"blockCount":174,"bytes":4388,"file":"chunks/y106-z064-x128.json","offset":{"x":128,"y":106,"z":64},"requirements":{"minecraft:bricks":27,"minecraft:glass":16,"minecraft:oak_planks":2,"minecraft:polished_diorite":95,"minecraft:sandstone":12,"minecraft:stone_bricks":22},"sha256":"3b1a2188aabe660153a737b118e4e20562ed14b06500db6f3565657b7d71609d","size":{"x":32,"y":1,"z":32}},{"blockCount":2,"bytes":688,"file":"chunks/y106-z064-x160.json","offset":{"x":160,"y":106,"z":64},"requirements":{"minecraft:polished_diorite":2},"sha256":"c9e2a3ad3480d29f3378d6ae29eed54f98f578cacb175b1e3e0a4b5eaa6672fe","size":{"x":32,"y":1,"z":32}},{"blockCount":24,"bytes":1038,"file":"chunks/y106-z064-x192.json","offset":{"x":192,"y":106,"z":64},"requirements":{"minecraft:polished_diorite":17,"minecraft:stone_bricks":7},"sha256":"808b1867dfb1fdd6d84ef3beaa0981c5f71456cd51d288785fcfcad3e6a6d0af","size":{"x":32,"y":1,"z":32}},{"blockCount":30,"bytes":1153,"file":"chunks/y106-z064-x224.json","offset":{"x":224,"y":106,"z":64},"requirements":{"minecraft:polished_diorite":21,"minecraft:stone_bricks":9},"sha256":"70f9da99ba06efb487d8526b1b25cb203a23b74cec8380c937d294f4a0c1c3e3","size":{"x":32,"y":1,"z":32}},{"blockCount":30,"bytes":1328,"file":"chunks/y106-z096-x000.json","offset":{"x":0,"y":106,"z":96},"requirements":{"minecraft:polished_diorite":29,"minecraft:stone_bricks":1},"sha256":"70a6fd02a9a83ab78436a113a693bf6fb6e5f44f09c9fbaf26e92cb0398ba206","size":{"x":32,"y":1,"z":32}},{"blockCount":147,"bytes":4152,"file":"chunks/y106-z096-x032.json","offset":{"x":32,"y":106,"z":96},"requirements":{"minecraft:bricks":12,"minecraft:glass":17,"minecraft:polished_diorite":99,"minecraft:sandstone":7,"minecraft:stone_bricks":12},"sha256":"cf5f13b3c0fba0b4d48dc55f5b27699b95f848a76a0c36ea247fa5decb46b0c6","size":{"x":32,"y":1,"z":32}},{"blockCount":140,"bytes":3862,"file":"chunks/y106-z096-x064.json","offset":{"x":64,"y":106,"z":96},"requirements":{"minecraft:bricks":16,"minecraft:glass":16,"minecraft:polished_diorite":74,"minecraft:sandstone":13,"minecraft:stone_bricks":21},"sha256":"540975924111970a6564b696da9ccec78c53dcd2323ebd091ec54b9f9787dfcd","size":{"x":32,"y":1,"z":32}},{"blockCount":107,"bytes":3297,"file":"chunks/y106-z096-x096.json","offset":{"x":96,"y":106,"z":96},"requirements":{"minecraft:bricks":23,"minecraft:glass":11,"minecraft:polished_diorite":38,"minecraft:sandstone":16,"minecraft:stone_bricks":19},"sha256":"49ff119d63f0fe69a4dba49a510b7cb062496cd28b6773d88d06479cab0f7f9e","size":{"x":32,"y":1,"z":32}},{"blockCount":173,"bytes":4456,"file":"chunks/y106-z096-x128.json","offset":{"x":128,"y":106,"z":96},"requirements":{"minecraft:bricks":32,"minecraft:glass":18,"minecraft:polished_diorite":69,"minecraft:sandstone":22,"minecraft:stone_bricks":32},"sha256":"852c40e9e040873a542e2abc2eea6f20e6c99d296600e94493c73de06fe9ccdf","size":{"x":32,"y":1,"z":32}},{"blockCount":143,"bytes":4143,"file":"chunks/y106-z096-x160.json","offset":{"x":160,"y":106,"z":96},"requirements":{"minecraft:bricks":16,"minecraft:glass":18,"minecraft:polished_diorite":81,"minecraft:sandstone":12,"minecraft:stone_bricks":16},"sha256":"d97c2790ec42130c93c6a2112aa09e6f68054263e74c1f85566a2d7cef7fbb58","size":{"x":32,"y":1,"z":32}},{"blockCount":259,"bytes":5425,"file":"chunks/y106-z096-x192.json","offset":{"x":192,"y":106,"z":96},"requirements":{"minecraft:bricks":116,"minecraft:glass":14,"minecraft:oak_planks":1,"minecraft:polished_diorite":84,"minecraft:sandstone":7,"minecraft:spruce_planks":2,"minecraft:stone_bricks":35},"sha256":"36186400ce5793c4f0122ec633002bcd6b7b012932fe978d1ae66405da053a40","size":{"x":32,"y":1,"z":32}},{"blockCount":153,"bytes":3899,"file":"chunks/y106-z096-x224.json","offset":{"x":224,"y":106,"z":96},"requirements":{"minecraft:bricks":71,"minecraft:glass":3,"minecraft:polished_diorite":60,"minecraft:sandstone":1,"minecraft:stone_bricks":18},"sha256":"f3436cf173d4eae7bd237868b0e80ce794ee77cecb44b87115bdb952e278e0b9","size":{"x":32,"y":1,"z":32}},{"blockCount":52,"bytes":1918,"file":"chunks/y106-z128-x000.json","offset":{"x":0,"y":106,"z":128},"requirements":{"minecraft:polished_diorite":49,"minecraft:stone_bricks":3},"sha256":"cbfbdfa502e933f9e6128e049c9adfba2ce23304c322978cfaf1dada3d26ac70","size":{"x":32,"y":1,"z":32}},{"blockCount":154,"bytes":4041,"file":"chunks/y106-z128-x032.json","offset":{"x":32,"y":106,"z":128},"requirements":{"minecraft:bricks":40,"minecraft:glass":23,"minecraft:polished_diorite":58,"minecraft:sandstone":14,"minecraft:stone_bricks":19},"sha256":"2aa13ec6f83248c9d5d7a9c49514f7b38864a203853579e98c7b3ead604132e8","size":{"x":32,"y":1,"z":32}},{"blockCount":54,"bytes":1721,"file":"chunks/y106-z128-x064.json","offset":{"x":64,"y":106,"z":128},"requirements":{"minecraft:bricks":16,"minecraft:glass":16,"minecraft:sandstone":12,"minecraft:stone_bricks":10},"sha256":"5dd4ded273992df6cd09922b84b5288d2417a4264a5ae0dfebcad7d5e0033584","size":{"x":32,"y":1,"z":32}},{"blockCount":18,"bytes":1015,"file":"chunks/y106-z128-x096.json","offset":{"x":96,"y":106,"z":128},"requirements":{"minecraft:bricks":8,"minecraft:glass":2,"minecraft:sandstone":3,"minecraft:stone_bricks":5},"sha256":"c2d95d48d84e7add2a953ec3452e9fd94b841ec52866138863df447530ce7513","size":{"x":32,"y":1,"z":32}},{"blockCount":44,"bytes":1417,"file":"chunks/y106-z128-x128.json","offset":{"x":128,"y":106,"z":128},"requirements":{"minecraft:bricks":16,"minecraft:glass":9,"minecraft:sandstone":8,"minecraft:stone_bricks":11},"sha256":"a7559d2df10a75f8a79b1247f3228dc85c53f862150095e766e4ee4f72f91509","size":{"x":32,"y":1,"z":32}},{"blockCount":53,"bytes":1836,"file":"chunks/y106-z128-x160.json","offset":{"x":160,"y":106,"z":128},"requirements":{"minecraft:bricks":16,"minecraft:glass":18,"minecraft:sandstone":12,"minecraft:stone_bricks":7},"sha256":"8aa3b63f26ba71aefad2d376736bab7a051a16b12e6a12f1d300255bb8e10f29","size":{"x":32,"y":1,"z":32}},{"blockCount":59,"bytes":1703,"file":"chunks/y106-z128-x192.json","offset":{"x":192,"y":106,"z":128},"requirements":{"minecraft:bricks":31,"minecraft:glass":11,"minecraft:sandstone":7,"minecraft:stone_bricks":10},"sha256":"cccdd6a140827f232c07ce35f0e9baa7eab8e2910b9af4708ba21d81dff9f356","size":{"x":32,"y":1,"z":32}},{"blockCount":122,"bytes":3268,"file":"chunks/y106-z128-x224.json","offset":{"x":224,"y":106,"z":128},"requirements":{"minecraft:bricks":35,"minecraft:glass":13,"minecraft:oak_planks":6,"minecraft:polished_diorite":46,"minecraft:sandstone":8,"minecraft:stone_bricks":14},"sha256":"d6d9bad5b972d707b71bb3a0811e76802c508968ef4cde450636365cd7b00dbe","size":{"x":32,"y":1,"z":32}},{"blockCount":18,"bytes":995,"file":"chunks/y106-z160-x000.json","offset":{"x":0,"y":106,"z":160},"requirements":{"minecraft:polished_diorite":18},"sha256":"b6d2262f99588c88517b53444a34a6d69bcf38494986f0378e72ed4e3498e8ca","size":{"x":32,"y":1,"z":32}},{"blockCount":90,"bytes":2712,"file":"chunks/y106-z160-x032.json","offset":{"x":32,"y":106,"z":160},"requirements":{"minecraft:polished_diorite":84,"minecraft:stone_bricks":6},"sha256":"9d6c63c885642f4bf50460af6a324cb39c368ffb40089d0fcabbe094b5b7a9ba","size":{"x":32,"y":1,"z":32}},{"blockCount":92,"bytes":2866,"file":"chunks/y106-z160-x064.json","offset":{"x":64,"y":106,"z":160},"requirements":{"minecraft:polished_diorite":79,"minecraft:sandstone":1,"minecraft:stone_bricks":12},"sha256":"e18d45601d7de0866a801dfbb5c6fe277be605714b2da721e3fa08ba7678a11e","size":{"x":32,"y":1,"z":32}},{"blockCount":113,"bytes":3528,"file":"chunks/y106-z160-x096.json","offset":{"x":96,"y":106,"z":160},"requirements":{"minecraft:bricks":19,"minecraft:glass":15,"minecraft:polished_diorite":46,"minecraft:sandstone":16,"minecraft:stone_bricks":17},"sha256":"2a287e6b7ca0fb077218d72ae6d84670b579dde96862981cd2177965b4ce0c51","size":{"x":32,"y":1,"z":32}},{"blockCount":154,"bytes":4366,"file":"chunks/y106-z160-x128.json","offset":{"x":128,"y":106,"z":160},"requirements":{"minecraft:bricks":17,"minecraft:glass":13,"minecraft:polished_diorite":82,"minecraft:sandstone":17,"minecraft:stone_bricks":25},"sha256":"7f992f3bad60145e2ad3b57bc2c6a36ffd9fd5d8a5ae5ca2beb94a75d47b1ab4","size":{"x":32,"y":1,"z":32}},{"blockCount":90,"bytes":2932,"file":"chunks/y106-z160-x160.json","offset":{"x":160,"y":106,"z":160},"requirements":{"minecraft:polished_diorite":81,"minecraft:stone_bricks":9},"sha256":"05bf8b48d4f9b002899505c99b470caac744d81428de8e205a47671bb3080772","size":{"x":32,"y":1,"z":32}},{"blockCount":224,"bytes":4755,"file":"chunks/y106-z160-x192.json","offset":{"x":192,"y":106,"z":160},"requirements":{"minecraft:bricks":85,"minecraft:glass":3,"minecraft:oak_planks":1,"minecraft:polished_diorite":101,"minecraft:spruce_planks":2,"minecraft:stone_bricks":32},"sha256":"3fcbd88e2b6962ac0cba3ca03cad1d83d19e44a15a5a7d8e4cc4bdefc7ea9ba7","size":{"x":32,"y":1,"z":32}},{"blockCount":136,"bytes":3551,"file":"chunks/y106-z160-x224.json","offset":{"x":224,"y":106,"z":160},"requirements":{"minecraft:bricks":58,"minecraft:glass":3,"minecraft:polished_diorite":54,"minecraft:stone_bricks":21},"sha256":"f841ad2e93cb29883cddd0a67e6fa8669cef1319e3563500ece4de3e666d65b8","size":{"x":32,"y":1,"z":32}},{"blockCount":36,"bytes":1484,"file":"chunks/y106-z192-x064.json","offset":{"x":64,"y":106,"z":192},"requirements":{"minecraft:polished_diorite":32,"minecraft:stone_bricks":4},"sha256":"6f139b51d511d3b645b09066c025c347915ab69b48fc58302256a7995eb2bf2c","size":{"x":32,"y":1,"z":32}},{"blockCount":151,"bytes":3677,"file":"chunks/y106-z192-x096.json","offset":{"x":96,"y":106,"z":192},"requirements":{"minecraft:bricks":31,"minecraft:glass":24,"minecraft:oak_planks":4,"minecraft:polished_diorite":61,"minecraft:sandstone":14,"minecraft:stone_bricks":17},"sha256":"c82a5d45fda29987d9bfae1ea0abdcdfeda954e8dd997c33c5f5489fbda92cd3","size":{"x":32,"y":1,"z":32}},{"blockCount":149,"bytes":3737,"file":"chunks/y106-z192-x128.json","offset":{"x":128,"y":106,"z":192},"requirements":{"minecraft:bricks":26,"minecraft:glass":12,"minecraft:oak_planks":2,"minecraft:polished_diorite":82,"minecraft:sandstone":9,"minecraft:stone_bricks":18},"sha256":"0ce1fa15cb337569dc131475a8af5a8d3605911a08d248c264776a41270bb8cc","size":{"x":32,"y":1,"z":32}},{"blockCount":2,"bytes":689,"file":"chunks/y106-z192-x160.json","offset":{"x":160,"y":106,"z":192},"requirements":{"minecraft:polished_diorite":2},"sha256":"3f5a5f88a00bce27e6ef78b6b45993d7113557aee5d482ffcc192db3ae85ea21","size":{"x":32,"y":1,"z":32}},{"blockCount":47,"bytes":1637,"file":"chunks/y107-z064-x064.json","offset":{"x":64,"y":107,"z":64},"requirements":{"minecraft:polished_diorite":35,"minecraft:stone_bricks":12},"sha256":"47251a0aca4d7b6d502bd064f48570fb6c0c9fe9761e239268899efbf3788516","size":{"x":32,"y":1,"z":32}},{"blockCount":179,"bytes":4025,"file":"chunks/y107-z064-x096.json","offset":{"x":96,"y":107,"z":64},"requirements":{"minecraft:bricks":39,"minecraft:glass":26,"minecraft:oak_planks":4,"minecraft:polished_diorite":79,"minecraft:sandstone":13,"minecraft:stone_bricks":18},"sha256":"09248779477d3cf7899abf25ec3daccef80c46dbb0355b312def600eddca36d8","size":{"x":32,"y":1,"z":32}},{"blockCount":185,"bytes":4601,"file":"chunks/y107-z064-x128.json","offset":{"x":128,"y":107,"z":64},"requirements":{"minecraft:bricks":26,"minecraft:glass":15,"minecraft:oak_planks":2,"minecraft:polished_diorite":108,"minecraft:sandstone":9,"minecraft:stone_bricks":25},"sha256":"37b6882adf9f39586049bc207c24c47b2b9d8ffab97191a118ddd4e691b9c7c8","size":{"x":32,"y":1,"z":32}},{"blockCount":20,"bytes":981,"file":"chunks/y107-z064-x192.json","offset":{"x":192,"y":107,"z":64},"requirements":{"minecraft:polished_diorite":15,"minecraft:stone_bricks":5},"sha256":"c32efc54c6655d6f02460a9dde8c9f59247a120eeb05889781cc8f41092eae0b","size":{"x":32,"y":1,"z":32}},{"blockCount":24,"bytes":1059,"file":"chunks/y107-z064-x224.json","offset":{"x":224,"y":107,"z":64},"requirements":{"minecraft:polished_diorite":18,"minecraft:stone_bricks":6},"sha256":"db1a259772457ab452e02cb499dafc6c3bc58b8c5098b02670e089f11621ca93","size":{"x":32,"y":1,"z":32}},{"blockCount":34,"bytes":1462,"file":"chunks/y107-z096-x000.json","offset":{"x":0,"y":107,"z":96},"requirements":{"minecraft:polished_diorite":28,"minecraft:stone_bricks":6},"sha256":"59e565bb254d4d038fc16e502f3366e947eb9bc0b7565e8dff9df1905850db41","size":{"x":32,"y":1,"z":32}},{"blockCount":155,"bytes":4073,"file":"chunks/y107-z096-x032.json","offset":{"x":32,"y":107,"z":96},"requirements":{"minecraft:bricks":13,"minecraft:glass":16,"minecraft:polished_diorite":99,"minecraft:sandstone":7,"minecraft:stone_bricks":20},"sha256":"b1eaf2374cafad8d7edb7623480f59d8c1045ac5d14e945e86a0a46b459e560b","size":{"x":32,"y":1,"z":32}},{"blockCount":150,"bytes":3601,"file":"chunks/y107-z096-x064.json","offset":{"x":64,"y":107,"z":96},"requirements":{"minecraft:bricks":18,"minecraft:glass":16,"minecraft:oak_planks":1,"minecraft:polished_diorite":82,"minecraft:sandstone":8,"minecraft:stone_bricks":25},"sha256":"1c375ceebb346ade0ba66f13c2cadf192093b1971b09ac9461a11dd76fc2c133","size":{"x":32,"y":1,"z":32}},{"blockCount":112,"bytes":3550,"file":"chunks/y107-z096-x096.json","offset":{"x":96,"y":107,"z":96},"requirements":{"minecraft:bricks":27,"minecraft:glass":11,"minecraft:oak_planks":3,"minecraft:polished_diorite":44,"minecraft:sandstone":11,"minecraft:stone_bricks":16},"sha256":"c08ece8a6a0fc03028cd7f0754c77fbb9276a982646670d57b6ae9bc151e5718","size":{"x":32,"y":1,"z":32}},{"blockCount":179,"bytes":4674,"file":"chunks/y107-z096-x128.json","offset":{"x":128,"y":107,"z":96},"requirements":{"minecraft:bricks":37,"minecraft:glass":18,"minecraft:oak_planks":4,"minecraft:polished_diorite":78,"minecraft:sandstone":15,"minecraft:stone_bricks":27},"sha256":"14cca0de6af009af01bf4d7cf723d76b6b44cb4addef211c5966d39004963efa","size":{"x":32,"y":1,"z":32}},{"blockCount":158,"bytes":3874,"file":"chunks/y107-z096-x160.json","offset":{"x":160,"y":107,"z":96},"requirements":{"minecraft:bricks":18,"minecraft:glass":18,"minecraft:polished_diorite":91,"minecraft:sandstone":7,"minecraft:stone_bricks":24},"sha256":"d332f585d9fab39e6d2ec618df3ee6e26eaf0e26af8cd8029c6df4c80d70bfff","size":{"x":32,"y":1,"z":32}},{"blockCount":262,"bytes":5389,"file":"chunks/y107-z096-x192.json","offset":{"x":192,"y":107,"z":96},"requirements":{"minecraft:bricks":123,"minecraft:glass":14,"minecraft:oak_planks":1,"minecraft:polished_diorite":85,"minecraft:sandstone":3,"minecraft:spruce_planks":2,"minecraft:stone_bricks":34},"sha256":"5192227d4928ecf6535a1ac1695997f4e940cec8d06a941ac47a68f549630198","size":{"x":32,"y":1,"z":32}},{"blockCount":145,"bytes":3823,"file":"chunks/y107-z096-x224.json","offset":{"x":224,"y":107,"z":96},"requirements":{"minecraft:bricks":73,"minecraft:glass":1,"minecraft:polished_diorite":52,"minecraft:sandstone":1,"minecraft:stone_bricks":18},"sha256":"d5582d3fd494eb84b51474406a36e882e28f22609aab262c84814e3b5cc00d93","size":{"x":32,"y":1,"z":32}},{"blockCount":56,"bytes":1956,"file":"chunks/y107-z128-x000.json","offset":{"x":0,"y":107,"z":128},"requirements":{"minecraft:polished_diorite":49,"minecraft:stone_bricks":7},"sha256":"0b55553d6be816fb1881ce4b74b653ca110b25f0f79681bacb94a73de9afda47","size":{"x":32,"y":1,"z":32}},{"blockCount":145,"bytes":3965,"file":"chunks/y107-z128-x032.json","offset":{"x":32,"y":107,"z":128},"requirements":{"minecraft:bricks":33,"minecraft:glass":25,"minecraft:polished_diorite":51,"minecraft:sandstone":18,"minecraft:stone_bricks":18},"sha256":"4a9bf0aeefea867344d993b7c79b577af725fb448a77220117f52610619df3f9","size":{"x":32,"y":1,"z":32}},{"blockCount":55,"bytes":1785,"file":"chunks/y107-z128-x064.json","offset":{"x":64,"y":107,"z":128},"requirements":{"minecraft:bricks":18,"minecraft:glass":16,"minecraft:oak_planks":1,"minecraft:sandstone":7,"minecraft:stone_bricks":13},"sha256":"9b5918c8ca6a4745fce1e58596db326e8adcfd8b9ac1b4efa63d35d6c7d6ae1c","size":{"x":32,"y":1,"z":32}},{"blockCount":19,"bytes":1156,"file":"chunks/y107-z128-x096.json","offset":{"x":96,"y":107,"z":128},"requirements":{"minecraft:bricks":10,"minecraft:glass":2,"minecraft:oak_planks":1,"minecraft:sandstone":2,"minecraft:stone_bricks":4},"sha256":"7c38caa8dd771b51da2937925c2f261a00e8ed2db251f672467d4a6ddf1661c2","size":{"x":32,"y":1,"z":32}},{"blockCount":45,"bytes":1653,"file":"chunks/y107-z128-x128.json","offset":{"x":128,"y":107,"z":128},"requirements":{"minecraft:bricks":19,"minecraft:glass":9,"minecraft:oak_planks":2,"minecraft:sandstone":5,"minecraft:stone_bricks":10},"sha256":"f69c8b12a6a51d16a5c66c7b45593499561f554c9d2788a67c61b9de40682524","size":{"x":32,"y":1,"z":32}},{"blockCount":55,"bytes":1819,"file":"chunks/y107-z128-x160.json","offset":{"x":160,"y":107,"z":128},"requirements":{"minecraft:bricks":18,"minecraft:glass":18,"minecraft:sandstone":7,"minecraft:stone_bricks":12},"sha256":"16b0579f2f82b061294de0cdcb79c5d2cd477043cd7c41cda57e593f55e20238","size":{"x":32,"y":1,"z":32}},{"blockCount":62,"bytes":1782,"file":"chunks/y107-z128-x192.json","offset":{"x":192,"y":107,"z":128},"requirements":{"minecraft:bricks":38,"minecraft:glass":11,"minecraft:sandstone":3,"minecraft:stone_bricks":10},"sha256":"1132357ca15b877fc3b9816ddb58cb9937370afb979724dc80643d849df6a6d3","size":{"x":32,"y":1,"z":32}},{"blockCount":122,"bytes":3287,"file":"chunks/y107-z128-x224.json","offset":{"x":224,"y":107,"z":128},"requirements":{"minecraft:bricks":37,"minecraft:glass":11,"minecraft:oak_planks":6,"minecraft:polished_diorite":46,"minecraft:sandstone":9,"minecraft:stone_bricks":13},"sha256":"119a7fa511ac931d0a922d496f534770345e70a899893744e6942452863896b2","size":{"x":32,"y":1,"z":32}},{"blockCount":20,"bytes":1079,"file":"chunks/y107-z160-x000.json","offset":{"x":0,"y":107,"z":160},"requirements":{"minecraft:polished_diorite":17,"minecraft:stone_bricks":3},"sha256":"bd9c12140e2937aa061816e849e1848c4c247a3bf0a5ec94d25fcaf54c32e568","size":{"x":32,"y":1,"z":32}},{"blockCount":101,"bytes":2710,"file":"chunks/y107-z160-x032.json","offset":{"x":32,"y":107,"z":160},"requirements":{"minecraft:polished_diorite":89,"minecraft:stone_bricks":12},"sha256":"686a5d5d9495f66e3da030a15d932a77dc073d759792ed07577a488dc4e7041c","size":{"x":32,"y":1,"z":32}},{"blockCount":102,"bytes":2561,"file":"chunks/y107-z160-x064.json","offset":{"x":64,"y":107,"z":160},"requirements":{"minecraft:polished_diorite":87,"minecraft:sandstone":1,"minecraft:stone_bricks":14},"sha256":"ccf5d7ab643f39f4618304b91ccaa60880b8894ae36dc3d0f2b81605f5523832","size":{"x":32,"y":1,"z":32}},{"blockCount":119,"bytes":3705,"file":"chunks/y107-z160-x096.json","offset":{"x":96,"y":107,"z":160},"requirements":{"minecraft:bricks":21,"minecraft:glass":15,"minecraft:oak_planks":2,"minecraft:polished_diorite":55,"minecraft:sandstone":11,"minecraft:stone_bricks":15},"sha256":"d67339926fd91821b63076c57f64f8017e2a2f329fa044819e93083c5ab493b2","size":{"x":32,"y":1,"z":32}},{"blockCount":162,"bytes":4450,"file":"chunks/y107-z160-x128.json","offset":{"x":128,"y":107,"z":160},"requirements":{"minecraft:bricks":19,"minecraft:glass":13,"minecraft:oak_planks":2,"minecraft:polished_diorite":94,"minecraft:sandstone":12,"minecraft:stone_bricks":22},"sha256":"8aa7d913e66fb4daa115c1a0034d73e14695d287e84ca34058fbabcc376424eb","size":{"x":32,"y":1,"z":32}},{"blockCount":103,"bytes":2643,"file":"chunks/y107-z160-x160.json","offset":{"x":160,"y":107,"z":160},"requirements":{"minecraft:polished_diorite":91,"minecraft:stone_bricks":12},"sha256":"91bcd203ca0a861f1f4d2b77186d8f197abbf5914d0b5669b7e905d506aec230","size":{"x":32,"y":1,"z":32}},{"blockCount":220,"bytes":4584,"file":"chunks/y107-z160-x192.json","offset":{"x":192,"y":107,"z":160},"requirements":{"minecraft:bricks":85,"minecraft:glass":3,"minecraft:oak_planks":1,"minecraft:polished_diorite":100,"minecraft:spruce_planks":2,"minecraft:stone_bricks":29},"sha256":"f3adad0824611b1b24d8ccab00e733ac889f701a21b8bd01f6a95c71054d005d","size":{"x":32,"y":1,"z":32}},{"blockCount":124,"bytes":3438,"file":"chunks/y107-z160-x224.json","offset":{"x":224,"y":107,"z":160},"requirements":{"minecraft:bricks":60,"minecraft:glass":1,"minecraft:polished_diorite":46,"minecraft:stone_bricks":17},"sha256":"99fcbbae6b09ca8c43e5927c1fb25d6fc44365af1006f6629268c22a67b811cd","size":{"x":32,"y":1,"z":32}},{"blockCount":40,"bytes":1485,"file":"chunks/y107-z192-x064.json","offset":{"x":64,"y":107,"z":192},"requirements":{"minecraft:polished_diorite":30,"minecraft:stone_bricks":10},"sha256":"68943a243ac2f68aa86d4038f07c25d8e0f0606d4ed32082d44ea42f7723eaa0","size":{"x":32,"y":1,"z":32}},{"blockCount":156,"bytes":3526,"file":"chunks/y107-z192-x096.json","offset":{"x":96,"y":107,"z":192},"requirements":{"minecraft:bricks":35,"minecraft:glass":23,"minecraft:oak_planks":4,"minecraft:polished_diorite":68,"minecraft:sandstone":11,"minecraft:stone_bricks":15},"sha256":"89d2125c039627991cdb8ffa04c59c41c0e3b1fdb7037d23a2cff33f20966fd2","size":{"x":32,"y":1,"z":32}},{"blockCount":157,"bytes":3894,"file":"chunks/y107-z192-x128.json","offset":{"x":128,"y":107,"z":192},"requirements":{"minecraft:bricks":25,"minecraft:glass":11,"minecraft:oak_planks":2,"minecraft:polished_diorite":92,"minecraft:sandstone":7,"minecraft:stone_bricks":20},"sha256":"278a9e7c6d105e0f7af4ceb7f947a858a61d3507df340c783c0a8e5a76bc1ec1","size":{"x":32,"y":1,"z":32}},{"blockCount":47,"bytes":1616,"file":"chunks/y108-z064-x064.json","offset":{"x":64,"y":108,"z":64},"requirements":{"minecraft:polished_diorite":40,"minecraft:stone_bricks":7},"sha256":"bb631a580a7685f3b0a01d2c9993264e1f535f529d65ed304023ddcaa42ee401","size":{"x":32,"y":1,"z":32}},{"blockCount":193,"bytes":4442,"file":"chunks/y108-z064-x096.json","offset":{"x":96,"y":108,"z":64},"requirements":{"minecraft:bricks":46,"minecraft:glass":20,"minecraft:oak_planks":4,"minecraft:polished_diorite":64,"minecraft:sandstone":17,"minecraft:stone_bricks":42},"sha256":"e3e443881cd5454ea06191928d0fc1bad04ed7856a94f644854682e7885374a5","size":{"x":32,"y":1,"z":32}},{"blockCount":195,"bytes":4788,"file":"chunks/y108-z064-x128.json","offset":{"x":128,"y":108,"z":64},"requirements":{"minecraft:bricks":29,"minecraft:glass":11,"minecraft:oak_planks":2,"minecraft:polished_diorite":97,"minecraft:sandstone":13,"minecraft:stone_bricks":43},"sha256":"27a6fa2b909411aa060f30dfa99d271f708ebac170bc1c8188e25a0f8b8ec5a9","size":{"x":32,"y":1,"z":32}},{"blockCount":29,"bytes":1095,"file":"chunks/y108-z064-x192.json","offset":{"x":192,"y":108,"z":64},"requirements":{"minecraft:polished_diorite":9,"minecraft:stone_bricks":20},"sha256":"8d07a00f458240c0b44994607a1a300b6e8e1f4d62143b385f0ac0b0052b5369","size":{"x":32,"y":1,"z":32}},{"blockCount":35,"bytes":1192,"file":"chunks/y108-z064-x224.json","offset":{"x":224,"y":108,"z":64},"requirements":{"minecraft:polished_diorite":11,"minecraft:stone_bricks":24},"sha256":"d0e489d2f8fb774d2c4d78a59ca8d0eca099cef06785efb371d9dd68f73301ba","size":{"x":32,"y":1,"z":32}},{"blockCount":33,"bytes":1406,"file":"chunks/y108-z096-x000.json","offset":{"x":0,"y":108,"z":96},"requirements":{"minecraft:polished_diorite":29,"minecraft:stone_bricks":4},"sha256":"37e55b3d49764058d5ceb4277789e40eb52b2c1a059388bd9417d76d1218b3f0","size":{"x":32,"y":1,"z":32}},{"blockCount":159,"bytes":4266,"file":"chunks/y108-z096-x032.json","offset":{"x":32,"y":108,"z":96},"requirements":{"minecraft:bricks":14,"minecraft:glass":14,"minecraft:polished_diorite":93,"minecraft:sandstone":10,"minecraft:stone_bricks":28},"sha256":"9d3b8d6618a6bc495d261c7b260d637ab8c97f9cf5b0b858ddabca7afac1395f","size":{"x":32,"y":1,"z":32}},{"blockCount":153,"bytes":4010,"file":"chunks/y108-z096-x064.json","offset":{"x":64,"y":108,"z":96},"requirements":{"minecraft:bricks":20,"minecraft:glass":12,"minecraft:polished_diorite":71,"minecraft:sandstone":13,"minecraft:stone_bricks":37},"sha256":"669f51675fc705f8139bdb26a36ff6d34a39324915bd19b4c9390a30ce408a14","size":{"x":32,"y":1,"z":32}},{"blockCount":110,"bytes":3644,"file":"chunks/y108-z096-x096.json","offset":{"x":96,"y":108,"z":96},"requirements":{"minecraft:bricks":25,"minecraft:glass":9,"minecraft:oak_planks":2,"minecraft:polished_diorite":36,"minecraft:sandstone":14,"minecraft:stone_bricks":24},"sha256":"50d7ccfe99143207f1f98357388506c307077e31d3bebeb93ca413728a5a2ad1","size":{"x":32,"y":1,"z":32}},{"blockCount":181,"bytes":4881,"file":"chunks/y108-z096-x128.json","offset":{"x":128,"y":108,"z":96},"requirements":{"minecraft:bricks":35,"minecraft:glass":15,"minecraft:oak_planks":2,"minecraft:polished_diorite":65,"minecraft:sandstone":20,"minecraft:stone_bricks":44},"sha256":"c4d4f1d13b69d40eaa397f1c7f13f701ac4a1bfee342ce2cb4a20410411026b1","size":{"x":32,"y":1,"z":32}},{"blockCount":158,"bytes":4274,"file":"chunks/y108-z096-x160.json","offset":{"x":160,"y":108,"z":96},"requirements":{"minecraft:bricks":21,"minecraft:glass":13,"minecraft:polished_diorite":81,"minecraft:sandstone":12,"minecraft:stone_bricks":31},"sha256":"5b43c0ac115e1c2bd8f0e08f748bf227c46a4985cb87a0f3cf67ab9755f0a052","size":{"x":32,"y":1,"z":32}},{"blockCount":392,"bytes":5736,"file":"chunks/y108-z096-x192.json","offset":{"x":192,"y":108,"z":96},"requirements":{"minecraft:bricks":118,"minecraft:glass":72,"minecraft:oak_planks":61,"minecraft:polished_diorite":67,"minecraft:sandstone":7,"minecraft:spruce_planks":2,"minecraft:stone_bricks":65},"sha256":"820081999d9fa48666d0de4ef0000ad01393bf9414d05030759a0441e1247ad1","size":{"x":32,"y":1,"z":32}},{"blockCount":452,"bytes":4188,"file":"chunks/y108-z096-x224.json","offset":{"x":224,"y":108,"z":96},"requirements":{"minecraft:bricks":74,"minecraft:glass":150,"minecraft:oak_planks":138,"minecraft:polished_diorite":39,"minecraft:sandstone":1,"minecraft:stone_bricks":50},"sha256":"230e0cd0e3807d3b9c9b951d7b8f6ddc071c1d2031e06d5c6c5bbef7c51be341","size":{"x":32,"y":1,"z":32}},{"blockCount":53,"bytes":2071,"file":"chunks/y108-z128-x000.json","offset":{"x":0,"y":108,"z":128},"requirements":{"minecraft:polished_diorite":45,"minecraft:stone_bricks":8},"sha256":"ce4f840707cfe71e5eb580728ef999ab5c2effc967355f265299d694afc47c4e","size":{"x":32,"y":1,"z":32}},{"blockCount":142,"bytes":4136,"file":"chunks/y108-z128-x032.json","offset":{"x":32,"y":108,"z":128},"requirements":{"minecraft:bricks":30,"minecraft:glass":27,"minecraft:polished_diorite":42,"minecraft:sandstone":20,"minecraft:stone_bricks":23},"sha256":"02233576c4644716fdada6d49ee0016fadfe7eda1e11b5d44990dd39d1a6b261","size":{"x":32,"y":1,"z":32}},{"blockCount":52,"bytes":1815,"file":"chunks/y108-z128-x064.json","offset":{"x":64,"y":108,"z":128},"requirements":{"minecraft:bricks":20,"minecraft:glass":12,"minecraft:sandstone":12,"minecraft:stone_bricks":8},"sha256":"9ed3ad6c4e578a90849fad2ace962e67e976fc69a3a37d57f1713adba9017694","size":{"x":32,"y":1,"z":32}},{"blockCount":16,"bytes":1117,"file":"chunks/y108-z128-x096.json","offset":{"x":96,"y":108,"z":128},"requirements":{"minecraft:bricks":8,"minecraft:glass":2,"minecraft:oak_planks":1,"minecraft:sandstone":2,"minecraft:stone_bricks":3},"sha256":"be708a39fb0eadcea8b6c8db6519cc9378ae7c9af04443c63e34cb78a239cf2e","size":{"x":32,"y":1,"z":32}},{"blockCount":41,"bytes":1613,"file":"chunks/y108-z128-x128.json","offset":{"x":128,"y":108,"z":128},"requirements":{"minecraft:bricks":18,"minecraft:glass":8,"minecraft:oak_planks":1,"minecraft:sandstone":7,"minecraft:stone_bricks":7},"sha256":"4ef1fd8a2e328d6ba0201a4c11a65358280b0f79974fc280e5f0967059e9d5d4","size":{"x":32,"y":1,"z":32}},{"blockCount":53,"bytes":1893,"file":"chunks/y108-z128-x160.json","offset":{"x":160,"y":108,"z":128},"requirements":{"minecraft:bricks":21,"minecraft:glass":13,"minecraft:sandstone":12,"minecraft:stone_bricks":7},"sha256":"2e0f3979c9afc38a3ac5131af50556ec3ade18412833625f7e43433bb5271159","size":{"x":32,"y":1,"z":32}},{"blockCount":57,"bytes":1740,"file":"chunks/y108-z128-x192.json","offset":{"x":192,"y":108,"z":128},"requirements":{"minecraft:bricks":33,"minecraft:glass":9,"minecraft:sandstone":7,"minecraft:stone_bricks":8},"sha256":"9921b8f7ec1a3cbd383826c7273eb9391f5cc4f51f0fcfe665cc300850bb2e9c","size":{"x":32,"y":1,"z":32}},{"blockCount":138,"bytes":3419,"file":"chunks/y108-z128-x224.json","offset":{"x":224,"y":108,"z":128},"requirements":{"minecraft:bricks":41,"minecraft:glass":9,"minecraft:oak_planks":6,"minecraft:polished_diorite":51,"minecraft:sandstone":9,"minecraft:stone_bricks":22},"sha256":"bab06297b82db4e56f03d7cf7ee9f9d3a543459752a2197944e2d429d72199db","size":{"x":32,"y":1,"z":32}},{"blockCount":18,"bytes":995,"file":"chunks/y108-z160-x000.json","offset":{"x":0,"y":108,"z":160},"requirements":{"minecraft:polished_diorite":18},"sha256":"8a5c0e1c8a0b311fed7c861451af6b90155b24cce49dfd7fe67462f4d17c93f0","size":{"x":32,"y":1,"z":32}},{"blockCount":100,"bytes":2710,"file":"chunks/y108-z160-x032.json","offset":{"x":32,"y":108,"z":160},"requirements":{"minecraft:polished_diorite":83,"minecraft:stone_bricks":17},"sha256":"3f464f88f66737feee382d2c6fc17cf225d99e9731b272d83d6bec6ec47dbf99","size":{"x":32,"y":1,"z":32}},{"blockCount":107,"bytes":2822,"file":"chunks/y108-z160-x064.json","offset":{"x":64,"y":108,"z":160},"requirements":{"minecraft:polished_diorite":77,"minecraft:stone_bricks":30},"sha256":"2ab35eedd9e8d20056d4a7a2cd1994831552a96f41a6589efb690f35f0ab88da","size":{"x":32,"y":1,"z":32}},{"blockCount":119,"bytes":3857,"file":"chunks/y108-z160-x096.json","offset":{"x":96,"y":108,"z":160},"requirements":{"minecraft:bricks":22,"minecraft:glass":12,"minecraft:oak_planks":1,"minecraft:polished_diorite":44,"minecraft:sandstone":14,"minecraft:stone_bricks":26},"sha256":"3cdb5bb1424ec1b03f319cc67e0cde6eef262a5cf718a162e28d4a69bd2ab3a3","size":{"x":32,"y":1,"z":32}},{"blockCount":169,"bytes":4695,"file":"chunks/y108-z160-x128.json","offset":{"x":128,"y":108,"z":160},"requirements":{"minecraft:bricks":20,"minecraft:glass":10,"minecraft:oak_planks":1,"minecraft:polished_diorite":79,"minecraft:sandstone":16,"minecraft:stone_bricks":43},"sha256":"8fb96bc9e64399eda33c7ca75bfe31b011d09d0f9dfc80c9e4ea464d6c984808","size":{"x":32,"y":1,"z":32}},{"blockCount":105,"bytes":2949,"file":"chunks/y108-z160-x160.json","offset":{"x":160,"y":108,"z":160},"requirements":{"minecraft:polished_diorite":81,"minecraft:stone_bricks":24},"sha256":"1b52e56b0a7d2dcea7b4fa7009915385b9d860912a1428276b8b94ebfd2d736d","size":{"x":32,"y":1,"z":32}},{"blockCount":364,"bytes":5086,"file":"chunks/y108-z160-x192.json","offset":{"x":192,"y":108,"z":160},"requirements":{"minecraft:bricks":85,"minecraft:glass":63,"minecraft:oak_planks":61,"minecraft:polished_diorite":76,"minecraft:spruce_planks":2,"minecraft:stone_bricks":77},"sha256":"ab52208207a44376f842379debe250dfc7bf576b60a56a382f392d5db967c021","size":{"x":32,"y":1,"z":32}},{"blockCount":435,"bytes":3859,"file":"chunks/y108-z160-x224.json","offset":{"x":224,"y":108,"z":160},"requirements":{"minecraft:bricks":61,"minecraft:glass":150,"minecraft:oak_planks":138,"minecraft:polished_diorite":26,"minecraft:stone_bricks":60},"sha256":"9608c3a753a57b39fb24f764579fbc78d0146a94b3399372158f7cf3a32ef7cc","size":{"x":32,"y":1,"z":32}},{"blockCount":40,"bytes":1484,"file":"chunks/y108-z192-x064.json","offset":{"x":64,"y":108,"z":192},"requirements":{"minecraft:polished_diorite":34,"minecraft:stone_bricks":6},"sha256":"5c483ac06a7fcf6e7e8c89b9f29b19e8cbd69bf8baaa39b894fae86f18cac62f","size":{"x":32,"y":1,"z":32}},{"blockCount":170,"bytes":3905,"file":"chunks/y108-z192-x096.json","offset":{"x":96,"y":108,"z":192},"requirements":{"minecraft:bricks":41,"minecraft:glass":18,"minecraft:oak_planks":4,"minecraft:polished_diorite":56,"minecraft:sandstone":14,"minecraft:stone_bricks":37},"sha256":"220feffbd8e36b636824a18a351a2c6b6251cfb2985dfd5a83a70ef3d4b171a8","size":{"x":32,"y":1,"z":32}},{"blockCount":167,"bytes":4061,"file":"chunks/y108-z192-x128.json","offset":{"x":128,"y":108,"z":192},"requirements":{"minecraft:bricks":27,"minecraft:glass":8,"minecraft:oak_planks":2,"minecraft:polished_diorite":83,"minecraft:sandstone":10,"minecraft:stone_bricks":37},"sha256":"fec7eb0ac642046b76309701085096d405cf4115a7b48ca9e27aa2939c1d91d0","size":{"x":32,"y":1,"z":32}},{"blockCount":40,"bytes":1608,"file":"chunks/y109-z064-x064.json","offset":{"x":64,"y":109,"z":64},"requirements":{"minecraft:polished_diorite":40},"sha256":"29858a1f112eb7a203dd7d81e6840578b40b21e99d1e0ba818bc9fbc26b8d389","size":{"x":32,"y":1,"z":32}},{"blockCount":190,"bytes":4214,"file":"chunks/y109-z064-x096.json","offset":{"x":96,"y":109,"z":64},"requirements":{"minecraft:bricks":49,"minecraft:glass":20,"minecraft:oak_planks":8,"minecraft:polished_diorite":74,"minecraft:sandstone":11,"minecraft:stone_bricks":28},"sha256":"25c3661f3a5e95ca33a6387bba24773aadbc38f3bf0d4ed2026b8d2660478146","size":{"x":32,"y":1,"z":32}},{"blockCount":179,"bytes":4693,"file":"chunks/y109-z064-x128.json","offset":{"x":128,"y":109,"z":64},"requirements":{"minecraft:bricks":26,"minecraft:glass":13,"minecraft:oak_planks":5,"minecraft:polished_diorite":106,"minecraft:sandstone":5,"minecraft:stone_bricks":24},"sha256":"8c6d47493328064c4f47ae8bfe07952aca4d9e53282ecc68a4ce51e7b119b03e","size":{"x":32,"y":1,"z":32}},{"blockCount":17,"bytes":980,"file":"chunks/y109-z064-x192.json","offset":{"x":192,"y":109,"z":64},"requirements":{"minecraft:polished_diorite":10,"minecraft:stone_bricks":7},"sha256":"9969e65a9ad9b5f95028dd60301f49b3240b3038f57ef8aaea5116e20cd7e404","size":{"x":32,"y":1,"z":32}},{"blockCount":20,"bytes":1019,"file":"chunks/y109-z064-x224.json","offset":{"x":224,"y":109,"z":64},"requirements":{"minecraft:polished_diorite":13,"minecraft:stone_bricks":7},"sha256":"71bf48a200153a22618f65608643e14ca8de844f69177bdd0c405dcbffca482f","size":{"x":32,"y":1,"z":32}},{"blockCount":32,"bytes":1387,"file":"chunks/y109-z096-x000.json","offset":{"x":0,"y":109,"z":96},"requirements":{"minecraft:polished_diorite":31,"minecraft:stone_bricks":1},"sha256":"8c457ef7d010ae07c54bf8be44ce44f96cda80e3ef56ba02def1b657b0829201","size":{"x":32,"y":1,"z":32}},{"blockCount":151,"bytes":4001,"file":"chunks/y109-z096-x032.json","offset":{"x":32,"y":109,"z":96},"requirements":{"minecraft:bricks":14,"minecraft:glass":13,"minecraft:polished_diorite":100,"minecraft:sandstone":4,"minecraft:stone_bricks":20},"sha256":"78f84fcd1163086205e6830cf40474830f0c89497eee01b7a9cc3de0ab151937","size":{"x":32,"y":1,"z":32}},{"blockCount":144,"bytes":3764,"file":"chunks/y109-z096-x064.json","offset":{"x":64,"y":109,"z":96},"requirements":{"minecraft:bricks":20,"minecraft:glass":14,"minecraft:oak_planks":2,"minecraft:polished_diorite":79,"minecraft:sandstone":5,"minecraft:stone_bricks":24},"sha256":"2c952b37fb9845000afc2f0f4189e4d91ca532ad15b518d21436365dec1ee4aa","size":{"x":32,"y":1,"z":32}},{"blockCount":108,"bytes":3568,"file":"chunks/y109-z096-x096.json","offset":{"x":96,"y":109,"z":96},"requirements":{"minecraft:bricks":26,"minecraft:glass":10,"minecraft:oak_planks":6,"minecraft:polished_diorite":41,"minecraft:sandstone":5,"minecraft:stone_bricks":20},"sha256":"594e3a7180ec294aff4fa3f241b28c537a50db3654a92c52bd87405d194a6719","size":{"x":32,"y":1,"z":32}},{"blockCount":171,"bytes":4785,"file":"chunks/y109-z096-x128.json","offset":{"x":128,"y":109,"z":96},"requirements":{"minecraft:bricks":36,"minecraft:glass":17,"minecraft:oak_planks":8,"minecraft:polished_diorite":73,"minecraft:sandstone":7,"minecraft:stone_bricks":30},"sha256":"7c227def9792f17ac65f0d7677f44ce7c991cabad370dfa5178937f0ce46c0a6","size":{"x":32,"y":1,"z":32}},{"blockCount":155,"bytes":4063,"file":"chunks/y109-z096-x160.json","offset":{"x":160,"y":109,"z":96},"requirements":{"minecraft:bricks":21,"minecraft:glass":15,"minecraft:polished_diorite":90,"minecraft:sandstone":5,"minecraft:stone_bricks":24},"sha256":"014f8ba6f491b107586a7b59d2d67c309815cdfc949d8551bc1e9559060a2b1d","size":{"x":32,"y":1,"z":32}},{"blockCount":315,"bytes":7188,"file":"chunks/y109-z096-x192.json","offset":{"x":192,"y":109,"z":96},"requirements":{"minecraft:bricks":120,"minecraft:glass":13,"minecraft:oak_planks":1,"minecraft:polished_diorite":75,"minecraft:sandstone":2,"minecraft:spruce_planks":62,"minecraft:stone_bricks":42},"sha256":"9f302b36da4223262c0f5d2100f5111d916ea1f933c37164839443f509034f32","size":{"x":32,"y":1,"z":32}},{"blockCount":285,"bytes":8782,"file":"chunks/y109-z096-x224.json","offset":{"x":224,"y":109,"z":96},"requirements":{"minecraft:bricks":74,"minecraft:polished_diorite":41,"minecraft:sandstone":1,"minecraft:spruce_planks":150,"minecraft:stone_bricks":19},"sha256":"4776827cb81cc7dc43756021694d2fffd5794844dc0bb3409b70f052256fc282","size":{"x":32,"y":1,"z":32}},{"blockCount":53,"bytes":1862,"file":"chunks/y109-z128-x000.json","offset":{"x":0,"y":109,"z":128},"requirements":{"minecraft:polished_diorite":50,"minecraft:stone_bricks":3},"sha256":"ecba15a8770608202dfebcc446ed50ceb535917cc0a4eef1e62cd878ffa25f3d","size":{"x":32,"y":1,"z":32}},{"blockCount":135,"bytes":3869,"file":"chunks/y109-z128-x032.json","offset":{"x":32,"y":109,"z":128},"requirements":{"minecraft:bricks":28,"minecraft:glass":28,"minecraft:polished_diorite":47,"minecraft:sandstone":8,"minecraft:stone_bricks":24},"sha256":"e8bbda6e4e887734ca5d46b7f7af19464f375a5b8022d9e62842ea0a0638e51c","size":{"x":32,"y":1,"z":32}},{"blockCount":54,"bytes":1764,"file":"chunks/y109-z128-x064.json","offset":{"x":64,"y":109,"z":128},"requirements":{"minecraft:bricks":20,"minecraft:glass":14,"minecraft:oak_planks":2,"minecraft:sandstone":4,"minecraft:stone_bricks":14},"sha256":"f319bdf207aaa56b5a8ad9d29dc8d96309f6b978182c1038400064a9cde941b2","size":{"x":32,"y":1,"z":32}},{"blockCount":15,"bytes":1055,"file":"chunks/y109-z128-x096.json","offset":{"x":96,"y":109,"z":128},"requirements":{"minecraft:bricks":8,"minecraft:glass":2,"minecraft:oak_planks":2,"minecraft:stone_bricks":3},"sha256":"6d7715f291b950d4ddb347331d636d0405bc8b4253ffe13f374db99f82862906","size":{"x":32,"y":1,"z":32}},{"blockCount":41,"bytes":1556,"file":"chunks/y109-z128-x128.json","offset":{"x":128,"y":109,"z":128},"requirements":{"minecraft:bricks":18,"minecraft:glass":9,"minecraft:oak_planks":4,"minecraft:sandstone":1,"minecraft:stone_bricks":9},"sha256":"3441493ffdbe59ca44f9fc6386690a18acb64e8ef99c2ed60cb4115b3135e313","size":{"x":32,"y":1,"z":32}}],"schema":1}
