{"entries":[{"blockCount":55,"bytes":1798,"file":"chunks/y109-z128-x160.json","offset":{"x":160,"y":109,"z":128},"requirements":{"minecraft:bricks":21,"minecraft:glass":15,"minecraft:sandstone":5,"minecraft:stone_bricks":14},"sha256":"a92976832a95401abcb5b8da86752fbd2c031e5a54ee53f46da40830561b1988","size":{"x":32,"y":1,"z":32}},{"blockCount":57,"bytes":1629,"file":"chunks/y109-z128-x192.json","offset":{"x":192,"y":109,"z":128},"requirements":{"minecraft:bricks":34,"minecraft:glass":10,"minecraft:sandstone":2,"minecraft:stone_bricks":11},"sha256":"0e2a3eb398210a2a2c7340576fafbbe8f3faec8b50c502bfbbb499b41cf1a80a","size":{"x":32,"y":1,"z":32}},{"blockCount":134,"bytes":3363,"file":"chunks/y109-z128-x224.json","offset":{"x":224,"y":109,"z":128},"requirements":{"minecraft:bricks":41,"minecraft:glass":7,"minecraft:oak_planks":13,"minecraft:polished_diorite":53,"minecraft:sandstone":7,"minecraft:stone_bricks":13},"sha256":"6db8a114b557662dd17faa1eb7c7c14f064e37e0edadc2badb30000ac6dfce6d","size":{"x":32,"y":1,"z":32}},{"blockCount":17,"bytes":995,"file":"chunks/y109-z160-x000.json","offset":{"x":0,"y":109,"z":160},"requirements":{"minecraft:polished_diorite":17},"sha256":"4f3e2e853a6acd2223bd24c6742243369abe4d7dde358daacf78db2c13fd208a","size":{"x":32,"y":1,"z":32}},{"blockCount":95,"bytes":2594,"file":"chunks/y109-z160-x032.json","offset":{"x":32,"y":109,"z":160},"requirements":{"minecraft:polished_diorite":89,"minecraft:stone_bricks":6},"sha256":"9258079b1ef295280185a23b5025f3ae996788fd20045f2a2edcc0dfbd6617a6","size":{"x":32,"y":1,"z":32}},{"blockCount":95,"bytes":2665,"file":"chunks/y109-z160-x064.json","offset":{"x":64,"y":109,"z":160},"requirements":{"minecraft:polished_diorite":85,"minecraft:stone_bricks":10},"sha256":"f1c3844d4a157b8464375a983a2a133b48993eff7d4abd2860aed0537917ae53","size":{"x":32,"y":1,"z":32}},{"blockCount":115,"bytes":3723,"file":"chunks/y109-z160-x096.json","offset":{"x":96,"y":109,"z":160},"requirements":{"minecraft:bricks":22,"minecraft:glass":14,"minecraft:oak_planks":4,"minecraft:polished_diorite":50,"minecraft:sandstone":3,"minecraft:stone_bricks":22},"sha256":"4f4b331c4289cbb69af55ab7a20215b45df5b5ac60e8526c5e99cc4b104498c8","size":{"x":32,"y":1,"z":32}},{"blockCount":153,"bytes":4542,"file":"chunks/y109-z160-x128.json","offset":{"x":128,"y":109,"z":160},"requirements":{"minecraft:bricks":20,"minecraft:glass":12,"minecraft:oak_planks":4,"minecraft:polished_diorite":88,"minecraft:sandstone":3,"minecraft:stone_bricks":26},"sha256":"f77b8eb21515ed9326f33f527beb431140fe6c3f97216570819e6e59148ad4ed","size":{"x":32,"y":1,"z":32}},{"blockCount":100,"bytes":2834,"file":"chunks/y109-z160-x160.json","offset":{"x":160,"y":109,"z":160},"requirements":{"minecraft:polished_diorite":90,"minecraft:stone_bricks":10},"sha256":"244138df849374acdc3d9233c0b042511a6d6632241fb6f2e36304cb40260e06","size":{"x":32,"y":1,"z":32}},{"blockCount":275,"bytes":6573,"file":"chunks/y109-z160-x192.json","offset":{"x":192,"y":109,"z":160},"requirements":{"minecraft:bricks":86,"minecraft:glass":3,"minecraft:oak_planks":1,"minecraft:polished_diorite":85,"minecraft:spruce_planks":62,"minecraft:stone_bricks":38},"sha256":"f720c16e3399cbd5870438c8a5fc1f50a66c3d1526ab758aeb8e388de4e48934","size":{"x":32,"y":1,"z":32}},{"blockCount":263,"bytes":8452,"file":"chunks/y109-z160-x224.json","offset":{"x":224,"y":109,"z":160},"requirements":{"minecraft:bricks":61,"minecraft:polished_diorite":31,"minecraft:spruce_planks":150,"minecraft:stone_bricks":21},"sha256":"19e0045b03081b63e3113289b5428526bdb367b8c78226bab4289877b5cbfe52","size":{"x":32,"y":1,"z":32}},{"blockCount":34,"bytes":1457,"file":"chunks/y109-z192-x064.json","offset":{"x":64,"y":109,"z":192},"requirements":{"minecraft:polished_diorite":34},"sha256":"dc7a52c1d0420211297000c38147fdae5b4a0b3a3762aa1a4b065bf20485dbcb","size":{"x":32,"y":1,"z":32}},{"blockCount":167,"bytes":3714,"file":"chunks/y109-z192-x096.json","offset":{"x":96,"y":109,"z":192},"requirements":{"minecraft:bricks":44,"minecraft:glass":17,"minecraft:oak_planks":8,"minecraft:polished_diorite":65,"minecraft:sandstone":10,"minecraft:stone_bricks":23},"sha256":"0f13a4a0d3a74a849296ebbb97db52ed6a5a1305992d8cd4d32896e94035c2eb","size":{"x":32,"y":1,"z":32}},{"blockCount":152,"bytes":4004,"file":"chunks/y109-z192-x128.json","offset":{"x":128,"y":109,"z":192},"requirements":{"minecraft:bricks":24,"minecraft:glass":9,"minecraft:oak_planks":5,"minecraft:polished_diorite":91,"minecraft:sandstone":4,"minecraft:stone_bricks":19},"sha256":"f88e91e23d8a3acbcc6b339b267d827b411560729bc4760ff353defa0c8493a5","size":{"x":32,"y":1,"z":32}},{"blockCount":62,"bytes":1978,"file":"chunks/y110-z064-x064.json","offset":{"x":64,"y":110,"z":64},"requirements":{"minecraft:polished_diorite":18,"minecraft:stone_bricks":44},"sha256":"5b8f2654019a23bb494befc71d69d4471245dca5d47b69b6334b70d24a085442","size":{"x":32,"y":1,"z":32}},{"blockCount":204,"bytes":4366,"file":"chunks/y110-z064-x096.json","offset":{"x":96,"y":110,"z":64},"requirements":{"minecraft:bricks":55,"minecraft:glass":14,"minecraft:oak_planks":9,"minecraft:polished_diorite":77,"minecraft:sandstone":16,"minecraft:stone_bricks":33},"sha256":"b3df27ceff59973b9e21d2041684d9257b31bf853d99e24b6f0e04d220a565cd","size":{"x":32,"y":1,"z":32}},{"blockCount":211,"bytes":4994,"file":"chunks/y110-z064-x128.json","offset":{"x":128,"y":110,"z":64},"requirements":{"minecraft:bricks":32,"minecraft:glass":9,"minecraft:oak_planks":1,"minecraft:polished_diorite":84,"minecraft:sandstone":13,"minecraft:stone_bricks":72},"sha256":"6817900c3fe99d842443761bc299a6fd49ae14d182cea706a5e5999fa61595ed","size":{"x":32,"y":1,"z":32}},{"blockCount":27,"bytes":1133,"file":"chunks/y110-z064-x192.json","offset":{"x":192,"y":110,"z":64},"requirements":{"minecraft:polished_diorite":9,"minecraft:stone_bricks":18},"sha256":"802b926dd7e0fb3d6b085c68cc9c2d6149a4b767ad7be4e1085525a5f17a54b3","size":{"x":32,"y":1,"z":32}},{"blockCount":32,"bytes":1230,"file":"chunks/y110-z064-x224.json","offset":{"x":224,"y":110,"z":64},"requirements":{"minecraft:polished_diorite":12,"minecraft:stone_bricks":20},"sha256":"a2c7184b18f4b1b6a4f35e5bebb3adb9607e8d796a5ad67585bc2b6edceffac7","size":{"x":32,"y":1,"z":32}},{"blockCount":39,"bytes":1504,"file":"chunks/y110-z096-x000.json","offset":{"x":0,"y":110,"z":96},"requirements":{"minecraft:polished_diorite":14,"minecraft:stone_bricks":25},"sha256":"1e983f7baf4df346b0640b3a25cb2c72881cb4cd5d4a2d77b493b721ca2c5f38","size":{"x":32,"y":1,"z":32}},{"blockCount":174,"bytes":4128,"file":"chunks/y110-z096-x032.json","offset":{"x":32,"y":110,"z":96},"requirements":{"minecraft:bricks":18,"minecraft:glass":11,"minecraft:polished_diorite":73,"minecraft:sandstone":8,"minecraft:stone_bricks":64},"sha256":"ead767ac27add852652c423211dd710db7806dbdd12a0dc42da1b30e45390c9b","size":{"x":32,"y":1,"z":32}},{"blockCount":166,"bytes":4068,"file":"chunks/y110-z096-x064.json","offset":{"x":64,"y":110,"z":96},"requirements":{"minecraft:bricks":25,"minecraft:glass":10,"minecraft:polished_diorite":62,"minecraft:sandstone":10,"minecraft:stone_bricks":59},"sha256":"706e9516ad1877b04070bdb2145760951a3b80bcf317a976daf718cee74d0cfa","size":{"x":32,"y":1,"z":32}},{"blockCount":112,"bytes":3587,"file":"chunks/y110-z096-x096.json","offset":{"x":96,"y":110,"z":96},"requirements":{"minecraft:bricks":31,"minecraft:glass":8,"minecraft:oak_planks":2,"minecraft:polished_diorite":41,"minecraft:sandstone":11,"minecraft:stone_bricks":19},"sha256":"f871ad17121b37785bbe6cb8d687fa8b3fa106d7e3a54f276b96126b341c7c15","size":{"x":32,"y":1,"z":32}},{"blockCount":187,"bytes":4955,"file":"chunks/y110-z096-x128.json","offset":{"x":128,"y":110,"z":96},"requirements":{"minecraft:bricks":43,"minecraft:glass":13,"minecraft:oak_planks":2,"minecraft:polished_diorite":68,"minecraft:sandstone":18,"minecraft:stone_bricks":43},"sha256":"37b924385577ad9bebbd4e5e6b1326e096b1952f292fb019e657e7c0d2e9223b","size":{"x":32,"y":1,"z":32}},{"blockCount":177,"bytes":4255,"file":"chunks/y110-z096-x160.json","offset":{"x":160,"y":110,"z":96},"requirements":{"minecraft:bricks":26,"minecraft:glass":11,"minecraft:polished_diorite":68,"minecraft:sandstone":8,"minecraft:stone_bricks":64},"sha256":"743e74470609874e8d651218db0029ab3ddd3dc2d99ea66482039f65af403b2b","size":{"x":32,"y":1,"z":32}},{"blockCount":398,"bytes":5698,"file":"chunks/y110-z096-x192.json","offset":{"x":192,"y":110,"z":96},"requirements":{"minecraft:bricks":125,"minecraft:glass":11,"minecraft:oak_planks":1,"minecraft:polished_diorite":58,"minecraft:sandstone":4,"minecraft:spruce_planks":121,"minecraft:stone_bricks":78},"sha256":"e6188f68ef3b95d45ba990702448553b7a9721c5c4eeb72b0f70d46ed2d05adf","size":{"x":32,"y":1,"z":32}},{"blockCount":446,"bytes":4074,"file":"chunks/y110-z096-x224.json","offset":{"x":224,"y":110,"z":96},"requirements":{"minecraft:bricks":74,"minecraft:polished_diorite":41,"minecraft:sandstone":1,"minecraft:spruce_planks":288,"minecraft:stone_bricks":42},"sha256":"f7d25ec93a38c68555e96cc7d7353d91fc9cb8271dee6538a796c1b0487c21a0","size":{"x":32,"y":1,"z":32}},{"blockCount":59,"bytes":1960,"file":"chunks/y110-z128-x000.json","offset":{"x":0,"y":110,"z":128},"requirements":{"minecraft:polished_diorite":28,"minecraft:stone_bricks":31},"sha256":"1a6e6c0c2251fe8509a2d6031c9b39f018382ca23467321d600ecdd29f393028","size":{"x":32,"y":1,"z":32}},{"blockCount":125,"bytes":3661,"file":"chunks/y110-z128-x032.json","offset":{"x":32,"y":110,"z":128},"requirements":{"minecraft:bricks":32,"minecraft:glass":26,"minecraft:polished_diorite":41,"minecraft:sandstone":13,"minecraft:stone_bricks":13},"sha256":"ae86cc02c86bd81db8e2bcfb0754e1f816acad646b62bf1920400f9bc550c4df","size":{"x":32,"y":1,"z":32}},{"blockCount":51,"bytes":1682,"file":"chunks/y110-z128-x064.json","offset":{"x":64,"y":110,"z":128},"requirements":{"minecraft:bricks":25,"minecraft:glass":10,"minecraft:sandstone":10,"minecraft:stone_bricks":6},"sha256":"de227a63feb9dee8fb4446e16aa2322ea92e0d9dd3c3c19e5d0b33e2a408faac","size":{"x":32,"y":1,"z":32}},{"blockCount":18,"bytes":1118,"file":"chunks/y110-z128-x096.json","offset":{"x":96,"y":110,"z":128},"requirements":{"minecraft:bricks":11,"minecraft:glass":2,"minecraft:oak_planks":1,"minecraft:sandstone":2,"minecraft:stone_bricks":2},"sha256":"720e5e57b515e13e209110f5a65b5bb561806e676146c2c75297a74dddcc7e0e","size":{"x":32,"y":1,"z":32}},{"blockCount":43,"bytes":1631,"file":"chunks/y110-z128-x128.json","offset":{"x":128,"y":110,"z":128},"requirements":{"minecraft:bricks":22,"minecraft:glass":7,"minecraft:oak_planks":1,"minecraft:sandstone":8,"minecraft:stone_bricks":5},"sha256":"40dbde04f88474d147cd1bb5f4f87772d7a614cde7957d5a47b16eb9f1aae771","size":{"x":32,"y":1,"z":32}},{"blockCount":50,"bytes":1683,"file":"chunks/y110-z128-x160.json","offset":{"x":160,"y":110,"z":128},"requirements":{"minecraft:bricks":26,"minecraft:glass":11,"minecraft:sandstone":8,"minecraft:stone_bricks":5},"sha256":"e3e99c3136ca0fa5b35cb2d85ca21efa1614d8d2c3d7843e067123a3c378c909","size":{"x":32,"y":1,"z":32}},{"blockCount":57,"bytes":1627,"file":"chunks/y110-z128-x192.json","offset":{"x":192,"y":110,"z":128},"requirements":{"minecraft:bricks":39,"minecraft:glass":8,"minecraft:sandstone":4,"minecraft:stone_bricks":6},"sha256":"ec21fba98734801fe1922e946659d2cb3d2bedc38fb348d5e37c740385113851","size":{"x":32,"y":1,"z":32}},{"blockCount":145,"bytes":3592,"file":"chunks/y110-z128-x224.json","offset":{"x":224,"y":110,"z":128},"requirements":{"minecraft:bricks":43,"minecraft:glass":5,"minecraft:oak_planks":10,"minecraft:polished_diorite":53,"minecraft:sandstone":12,"minecraft:stone_bricks":22},"sha256":"74481c25acdc92f3be61cac42b59cbc2f15f746addd767d53e6e3d5f38fe3f2c","size":{"x":32,"y":1,"z":32}},{"blockCount":20,"bytes":1041,"file":"chunks/y110-z160-x000.json","offset":{"x":0,"y":110,"z":160},"requirements":{"minecraft:polished_diorite":4,"minecraft:stone_bricks":16},"sha256":"79878813de90e489a22829bf0e40aaa7c123eed5ee556d3c839adb35f4271031","size":{"x":32,"y":1,"z":32}},{"blockCount":116,"bytes":2727,"file":"chunks/y110-z160-x032.json","offset":{"x":32,"y":110,"z":160},"requirements":{"minecraft:polished_diorite":61,"minecraft:stone_bricks":55},"sha256":"c32237d15fd6c0fba81e145318126de96548a9b9eb84f454592d24a3a4e45c9b","size":{"x":32,"y":1,"z":32}},{"blockCount":125,"bytes":3069,"file":"chunks/y110-z160-x064.json","offset":{"x":64,"y":110,"z":160},"requirements":{"minecraft:polished_diorite":64,"minecraft:stone_bricks":61},"sha256":"7ea804ab1772ca5e7b7ec527a74698693a4345932c9b3a9297332e54398b9901","size":{"x":32,"y":1,"z":32}},{"blockCount":119,"bytes":3724,"file":"chunks/y110-z160-x096.json","offset":{"x":96,"y":110,"z":160},"requirements":{"minecraft:bricks":27,"minecraft:glass":10,"minecraft:oak_planks":1,"minecraft:polished_diorite":50,"minecraft:sandstone":10,"minecraft:stone_bricks":21},"sha256":"5fb2dbff53b129180d118ba707c9eba5f4d1f66964096616361e377e00f11fef","size":{"x":32,"y":1,"z":32}},{"blockCount":174,"bytes":4769,"file":"chunks/y110-z160-x128.json","offset":{"x":128,"y":110,"z":160},"requirements":{"minecraft:bricks":25,"minecraft:glass":9,"minecraft:oak_planks":1,"minecraft:polished_diorite":79,"minecraft:sandstone":10,"minecraft:stone_bricks":50},"sha256":"104f9810d23cec721e46b33f44b2fee380ed64b9d991c58ea491ea87b5e5aa2b","size":{"x":32,"y":1,"z":32}},{"blockCount":127,"bytes":3102,"file":"chunks/y110-z160-x160.json","offset":{"x":160,"y":110,"z":160},"requirements":{"minecraft:polished_diorite":68,"minecraft:stone_bricks":59},"sha256":"44c2f0fa252cec5ef22a2a4717a4147b1cb7595418eeb6d3adc114d830bc40e3","size":{"x":32,"y":1,"z":32}},{"blockCount":368,"bytes":5217,"file":"chunks/y110-z160-x192.json","offset":{"x":192,"y":110,"z":160},"requirements":{"minecraft:bricks":86,"minecraft:glass":3,"minecraft:oak_planks":1,"minecraft:polished_diorite":67,"minecraft:spruce_planks":121,"minecraft:stone_bricks":90},"sha256":"f515fe53710a1132476e2a02a1d653f47aaa8f1d8c8b842b36e4bc395d7ea43b","size":{"x":32,"y":1,"z":32}},{"blockCount":427,"bytes":3840,"file":"chunks/y110-z160-x224.json","offset":{"x":224,"y":110,"z":160},"requirements":{"minecraft:bricks":61,"minecraft:polished_diorite":28,"minecraft:spruce_planks":288,"minecraft:stone_bricks":50},"sha256":"720a23a4a48090c4effbf7a818ff9bbaa01512699bf0f3be0fa6ab78e237794d","size":{"x":32,"y":1,"z":32}},{"blockCount":52,"bytes":1789,"file":"chunks/y110-z192-x064.json","offset":{"x":64,"y":110,"z":192},"requirements":{"minecraft:polished_diorite":16,"minecraft:stone_bricks":36},"sha256":"ef9d7d1af92b95fa031763c55abe538cfc8eb8b46124d5c8feb056b9dab81c62","size":{"x":32,"y":1,"z":32}},{"blockCount":180,"bytes":3791,"file":"chunks/y110-z192-x096.json","offset":{"x":96,"y":110,"z":192},"requirements":{"minecraft:bricks":49,"minecraft:glass":11,"minecraft:oak_planks":9,"minecraft:polished_diorite":68,"minecraft:sandstone":14,"minecraft:stone_bricks":29},"sha256":"0264469c4210cd9d44dccad93679c4287f701fb0bf77a3eb1cc114f355ec443c","size":{"x":32,"y":1,"z":32}},{"blockCount":180,"bytes":4289,"file":"chunks/y110-z192-x128.json","offset":{"x":128,"y":110,"z":192},"requirements":{"minecraft:bricks":29,"minecraft:glass":6,"minecraft:oak_planks":1,"minecraft:polished_diorite":73,"minecraft:sandstone":11,"minecraft:stone_bricks":60},"sha256":"9be8c6c586e3cf967d342e2290aef3ba99c8ca2533d416535f80cdfdcd249909","size":{"x":32,"y":1,"z":32}},{"blockCount":53,"bytes":2168,"file":"chunks/y111-z064-x064.json","offset":{"x":64,"y":111,"z":64},"requirements":{"minecraft:polished_diorite":42,"minecraft:stone_bricks":11},"sha256":"06bc26705507583aebe8ed4ce6193c9abeb17f687132b898d0fe91e85bde602f","size":{"x":32,"y":1,"z":32}},{"blockCount":198,"bytes":4063,"file":"chunks/y111-z064-x096.json","offset":{"x":96,"y":111,"z":64},"requirements":{"minecraft:bricks":62,"minecraft:glass":10,"minecraft:oak_planks":10,"minecraft:polished_diorite":85,"minecraft:sandstone":11,"minecraft:stone_bricks":20},"sha256":"03ec3abb7de4960942dfdee751f3d428d583796aea47990fed49baf0657ba370","size":{"x":32,"y":1,"z":32}},{"blockCount":192,"bytes":5052,"file":"chunks/y111-z064-x128.json","offset":{"x":128,"y":111,"z":64},"requirements":{"minecraft:bricks":37,"minecraft:glass":6,"minecraft:oak_planks":4,"minecraft:polished_diorite":112,"minecraft:sandstone":6,"minecraft:stone_bricks":27},"sha256":"653a0dfefc0a7816a0a3713b5c65fd54f0fcff05fc73672a8ba963c638d0abd9","size":{"x":32,"y":1,"z":32}},{"blockCount":21,"bytes":1019,"file":"chunks/y111-z064-x192.json","offset":{"x":192,"y":111,"z":64},"requirements":{"minecraft:polished_diorite":14,"minecraft:stone_bricks":7},"sha256":"d39bb54f0be7070cacb4b8dd6cb8096c1e31078e514c77c1bf0f06df7083eaf7","size":{"x":32,"y":1,"z":32}},{"blockCount":25,"bytes":1097,"file":"chunks/y111-z064-x224.json","offset":{"x":224,"y":111,"z":64},"requirements":{"minecraft:polished_diorite":17,"minecraft:stone_bricks":8},"sha256":"b09aa0e9a7e098137c58b93464e4369ed970d6be18dba2ed8ef838a7305b0672","size":{"x":32,"y":1,"z":32}},{"blockCount":33,"bytes":1540,"file":"chunks/y111-z096-x000.json","offset":{"x":0,"y":111,"z":96},"requirements":{"minecraft:polished_diorite":27,"minecraft:stone_bricks":6},"sha256":"d09cc13e3e6d191df41c3c36ed91ad0498328c4404bdd7af12750a19cbb50a89","size":{"x":32,"y":1,"z":32}},{"blockCount":162,"bytes":4289,"file":"chunks/y111-z096-x032.json","offset":{"x":32,"y":111,"z":96},"requirements":{"minecraft:bricks":24,"minecraft:glass":5,"minecraft:polished_diorite":103,"minecraft:sandstone":7,"minecraft:stone_bricks":23},"sha256":"5a96078e7f4cb6517f9d6d6172ac0ddb0b87c0ca407939472573d7a7bbb393dc","size":{"x":32,"y":1,"z":32}},{"blockCount":152,"bytes":3805,"file":"chunks/y111-z096-x064.json","offset":{"x":64,"y":111,"z":96},"requirements":{"minecraft:bricks":33,"minecraft:glass":6,"minecraft:polished_diorite":86,"minecraft:sandstone":5,"minecraft:stone_bricks":22},"sha256":"6e5f1fb21134c245040df928095f608818539aa4f775d6be9b0c51ca239997c3","size":{"x":32,"y":1,"z":32}},{"blockCount":105,"bytes":3435,"file":"chunks/y111-z096-x096.json","offset":{"x":96,"y":111,"z":96},"requirements":{"minecraft:bricks":42,"minecraft:glass":3,"minecraft:oak_planks":2,"minecraft:polished_diorite":43,"minecraft:sandstone":5,"minecraft:stone_bricks":10},"sha256":"7d936059fe189ae495eda11ac8f09eacf0529d0d3340aa2e672ba133b0f8ef2e","size":{"x":32,"y":1,"z":32}},{"blockCount":173,"bytes":4708,"file":"chunks/y111-z096-x128.json","offset":{"x":128,"y":111,"z":96},"requirements":{"minecraft:bricks":58,"minecraft:glass":6,"minecraft:oak_planks":2,"minecraft:polished_diorite":77,"minecraft:sandstone":9,"minecraft:stone_bricks":21},"sha256":"ae12ed88dd2ae7c73d524b9bed770724a89bf39da663931a523065a557b97054","size":{"x":32,"y":1,"z":32}},{"blockCount":166,"bytes":4211,"file":"chunks/y111-z096-x160.json","offset":{"x":160,"y":111,"z":96},"requirements":{"minecraft:bricks":36,"minecraft:glass":6,"minecraft:polished_diorite":100,"minecraft:sandstone":4,"minecraft:stone_bricks":20},"sha256":"872dcd2a929382593bacd16742275d6083d72277b1a780209cb3f715874b5e86","size":{"x":32,"y":1,"z":32}},{"blockCount":269,"bytes":5629,"file":"chunks/y111-z096-x192.json","offset":{"x":192,"y":111,"z":96},"requirements":{"minecraft:bricks":128,"minecraft:glass":5,"minecraft:oak_planks":7,"minecraft:polished_diorite":88,"minecraft:sandstone":2,"minecraft:stone_bricks":39},"sha256":"5a850c8a3c75989cf1f3b7a3250d3e0b8b77d82331b1ad6cf5e0a5b9afbdf14e","size":{"x":32,"y":1,"z":32}},{"blockCount":148,"bytes":4034,"file":"chunks/y111-z096-x224.json","offset":{"x":224,"y":111,"z":96},"requirements":{"minecraft:bricks":63,"minecraft:oak_planks":15,"minecraft:polished_diorite":49,"minecraft:sandstone":1,"minecraft:stone_bricks":20},"sha256":"08019c2b49d2b9711c8c2db280eff486c2c0e9a1c66ca01586458672ece1a835","size":{"x":32,"y":1,"z":32}},{"blockCount":53,"bytes":1921,"file":"chunks/y111-z128-x000.json","offset":{"x":0,"y":111,"z":128},"requirements":{"minecraft:polished_diorite":45,"minecraft:stone_bricks":8},"sha256":"76d380f6590b20db4367388cb541eedf5874a546ac181ce2e44b3002389c1479","size":{"x":32,"y":1,"z":32}},{"blockCount":134,"bytes":3604,"file":"chunks/y111-z128-x032.json","offset":{"x":32,"y":111,"z":128},"requirements":{"minecraft:bricks":40,"minecraft:glass":19,"minecraft:polished_diorite":47,"minecraft:sandstone":15,"minecraft:stone_bricks":13},"sha256":"f414bcf4b4a3cb3ca7d5ed1ab1682ad3fe71365ffee3a5f2ac7cc50e9bc47bd9","size":{"x":32,"y":1,"z":32}},{"blockCount":54,"bytes":1645,"file":"chunks/y111-z128-x064.json","offset":{"x":64,"y":111,"z":128},"requirements":{"minecraft:bricks":33,"minecraft:glass":6,"minecraft:sandstone":5,"minecraft:stone_bricks":10},"sha256":"1c5c84794a23c4edc5317f1bca2099672daf5ecddad069f822fc0ca059aa88f2","size":{"x":32,"y":1,"z":32}},{"blockCount":19,"bytes":1099,"file":"chunks/y111-z128-x096.json","offset":{"x":96,"y":111,"z":128},"requirements":{"minecraft:bricks":15,"minecraft:oak_planks":1,"minecraft:sandstone":1,"minecraft:stone_bricks":2},"sha256":"c1288ecb4d674568e6eae84d09422289fb37d1f8caeffdd799bcb6f076c0e860","size":{"x":32,"y":1,"z":32}},{"blockCount":45,"bytes":1614,"file":"chunks/y111-z128-x128.json","offset":{"x":128,"y":111,"z":128},"requirements":{"minecraft:bricks":30,"minecraft:glass":3,"minecraft:oak_planks":1,"minecraft:sandstone":4,"minecraft:stone_bricks":7},"sha256":"476158ee16238359bbbb4255a994c36750d42adc5071de9c2f14de044322404d","size":{"x":32,"y":1,"z":32}},{"blockCount":55,"bytes":1722,"file":"chunks/y111-z128-x160.json","offset":{"x":160,"y":111,"z":128},"requirements":{"minecraft:bricks":36,"minecraft:glass":6,"minecraft:sandstone":4,"minecraft:stone_bricks":9},"sha256":"3b3bd1cd2bf2c1aafa381cbb385b8119be7a73b272555e2e3bc2affc596f33ae","size":{"x":32,"y":1,"z":32}},{"blockCount":59,"bytes":1572,"file":"chunks/y111-z128-x192.json","offset":{"x":192,"y":111,"z":128},"requirements":{"minecraft:bricks":46,"minecraft:glass":3,"minecraft:sandstone":2,"minecraft:stone_bricks":8},"sha256":"fb25507cc871d8b1945b14d851bcfc9d92e8d666123b6f2f8f656bfd4f554fdc","size":{"x":32,"y":1,"z":32}},{"blockCount":140,"bytes":3477,"file":"chunks/y111-z128-x224.json","offset":{"x":224,"y":111,"z":128},"requirements":{"minecraft:bricks":45,"minecraft:glass":4,"minecraft:oak_planks":14,"minecraft:polished_diorite":54,"minecraft:sandstone":8,"minecraft:stone_bricks":15},"sha256":"35e6858a4abf2a754c808b03cf5efece2aada49cae5c7abea15617f753e053c5","size":{"x":32,"y":1,"z":32}},{"blockCount":14,"bytes":1078,"file":"chunks/y111-z160-x000.json","offset":{"x":0,"y":111,"z":160},"requirements":{"minecraft:polished_diorite":10,"minecraft:stone_bricks":4},"sha256":"7352f3fc139836e3cc8329d0afced18079fd5d0cb3117fc8de4727103e2055f4","size":{"x":32,"y":1,"z":32}},{"blockCount":103,"bytes":2944,"file":"chunks/y111-z160-x032.json","offset":{"x":32,"y":111,"z":160},"requirements":{"minecraft:polished_diorite":89,"minecraft:stone_bricks":14},"sha256":"04e92e32e7d0f9f5d5bc3cd9cdc9cc88a22744783de0478f83ff6366ad633486","size":{"x":32,"y":1,"z":32}},{"blockCount":105,"bytes":2902,"file":"chunks/y111-z160-x064.json","offset":{"x":64,"y":111,"z":160},"requirements":{"minecraft:polished_diorite":92,"minecraft:stone_bricks":13},"sha256":"72e270ec03485ecda7b65fceedd37cefbeead3e76b382b1ced5525a32bb70cab","size":{"x":32,"y":1,"z":32}},{"blockCount":110,"bytes":3532,"file":"chunks/y111-z160-x096.json","offset":{"x":96,"y":111,"z":160},"requirements":{"minecraft:bricks":35,"minecraft:glass":5,"minecraft:oak_planks":1,"minecraft:polished_diorite":54,"minecraft:sandstone":5,"minecraft:stone_bricks":10},"sha256":"9776161aa972f0a78257b06ae634daac426250b35145e2e76add3d258e41d112","size":{"x":32,"y":1,"z":32}},{"blockCount":155,"bytes":4559,"file":"chunks/y111-z160-x128.json","offset":{"x":128,"y":111,"z":160},"requirements":{"minecraft:bricks":33,"minecraft:glass":5,"minecraft:oak_planks":1,"minecraft:polished_diorite":94,"minecraft:sandstone":5,"minecraft:stone_bricks":17},"sha256":"5ac03dd4a90367cba8b950722927c5dd6d078f4b70aed801e43768622aaa8a53","size":{"x":32,"y":1,"z":32}},{"blockCount":111,"bytes":2998,"file":"chunks/y111-z160-x160.json","offset":{"x":160,"y":111,"z":160},"requirements":{"minecraft:polished_diorite":100,"minecraft:stone_bricks":11},"sha256":"e4e66cafffad8eb8579a0fe10517e8ccd43fafb670b35a4fbf66632bfc969cc7","size":{"x":32,"y":1,"z":32}},{"blockCount":231,"bytes":5108,"file":"chunks/y111-z160-x192.json","offset":{"x":192,"y":111,"z":160},"requirements":{"minecraft:bricks":82,"minecraft:glass":2,"minecraft:oak_planks":7,"minecraft:polished_diorite":102,"minecraft:stone_bricks":38},"sha256":"7504056e226996d4e774e1adbd6184ce367388ce51537e544ce814a805bd20f1","size":{"x":32,"y":1,"z":32}},{"blockCount":131,"bytes":3706,"file":"chunks/y111-z160-x224.json","offset":{"x":224,"y":111,"z":160},"requirements":{"minecraft:bricks":50,"minecraft:oak_planks":15,"minecraft:polished_diorite":43,"minecraft:stone_bricks":23},"sha256":"ff68a9c9ea4a6e69de16562a96c823b04df92a413e224411b7e0514a137590f7","size":{"x":32,"y":1,"z":32}},{"blockCount":46,"bytes":1941,"file":"chunks/y111-z192-x064.json","offset":{"x":64,"y":111,"z":192},"requirements":{"minecraft:polished_diorite":36,"minecraft:stone_bricks":10},"sha256":"bb690d6c3a5e500c32f7d9888c1772fb8da7c097656324becf4e78dc0bb17b58","size":{"x":32,"y":1,"z":32}},{"blockCount":174,"bytes":3525,"file":"chunks/y111-z192-x096.json","offset":{"x":96,"y":111,"z":192},"requirements":{"minecraft:bricks":54,"minecraft:glass":8,"minecraft:oak_planks":10,"minecraft:polished_diorite":74,"minecraft:sandstone":10,"minecraft:stone_bricks":18},"sha256":"4c552c18dbcd6bf707052f57807f690f77020efbb83fb4a77e098b8e85d5201d","size":{"x":32,"y":1,"z":32}},{"blockCount":164,"bytes":4307,"file":"chunks/y111-z192-x128.json","offset":{"x":128,"y":111,"z":192},"requirements":{"minecraft:bricks":32,"minecraft:glass":4,"minecraft:oak_planks":4,"minecraft:polished_diorite":95,"minecraft:sandstone":5,"minecraft:stone_bricks":24},"sha256":"4c5d2fdb06f0c0c8fecf11864eaec48706fcead42c56f39772ccc019e5a73a8e","size":{"x":32,"y":1,"z":32}},{"blockCount":53,"bytes":1874,"file":"chunks/y112-z064-x064.json","offset":{"x":64,"y":112,"z":64},"requirements":{"minecraft:polished_diorite":53},"sha256":"0ef9c2666ee9a467cf70f3a41b86e1d0c73527bba58fc1caf7ac2917e601d661","size":{"x":32,"y":1,"z":32}},{"blockCount":203,"bytes":4422,"file":"chunks/y112-z064-x096.json","offset":{"x":96,"y":112,"z":64},"requirements":{"minecraft:bricks":63,"minecraft:glass":6,"minecraft:oak_planks":10,"minecraft:polished_diorite":82,"minecraft:sandstone":16,"minecraft:stone_bricks":26},"sha256":"5d0fc6b740884bdd906180deffacfb7992a9825630d60cd28d23537d9092168d","size":{"x":32,"y":1,"z":32}},{"blockCount":194,"bytes":5014,"file":"chunks/y112-z064-x128.json","offset":{"x":128,"y":112,"z":64},"requirements":{"minecraft:bricks":39,"minecraft:glass":2,"minecraft:oak_planks":3,"minecraft:polished_diorite":118,"minecraft:sandstone":13,"minecraft:stone_bricks":19},"sha256":"0b1ccb0a817be70ed5e8a788509fcca4b18854ba172029ae3a4373fe00616e1a","size":{"x":32,"y":1,"z":32}},{"blockCount":21,"bytes":1151,"file":"chunks/y112-z064-x192.json","offset":{"x":192,"y":112,"z":64},"requirements":{"minecraft:polished_diorite":12,"minecraft:stone_bricks":9},"sha256":"6ccf157d4ac923d1dfbfb3d2bf017587b2a4887b0c72b7819433450eaaee6aa9","size":{"x":32,"y":1,"z":32}},{"blockCount":24,"bytes":1210,"file":"chunks/y112-z064-x224.json","offset":{"x":224,"y":112,"z":64},"requirements":{"minecraft:polished_diorite":14,"minecraft:stone_bricks":10},"sha256":"737eda3fd5c003223cc66d47bc2d114d8ead57c3c2393eb9224ef943447c0ec5","size":{"x":32,"y":1,"z":32}},{"blockCount":31,"bytes":1426,"file":"chunks/y112-z096-x000.json","offset":{"x":0,"y":112,"z":96},"requirements":{"minecraft:polished_diorite":30,"minecraft:stone_bricks":1},"sha256":"75aa103363524503848c6fdbe2fa67859d88f4bdf20f800109368bcca9ba1e47","size":{"x":32,"y":1,"z":32}},{"blockCount":164,"bytes":4252,"file":"chunks/y112-z096-x032.json","offset":{"x":32,"y":112,"z":96},"requirements":{"minecraft:bricks":25,"minecraft:glass":1,"minecraft:polished_diorite":114,"minecraft:sandstone":9,"minecraft:stone_bricks":15},"sha256":"f16670b6323ebea5b6767b89aa4b6d0c1816cf0d24204a5b48d0bac21519e2fd","size":{"x":32,"y":1,"z":32}},{"blockCount":158,"bytes":3857,"file":"chunks/y112-z096-x064.json","offset":{"x":64,"y":112,"z":96},"requirements":{"minecraft:bricks":36,"minecraft:glass":2,"minecraft:polished_diorite":92,"minecraft:sandstone":13,"minecraft:stone_bricks":15},"sha256":"99acc99f4eb1665730fd3a1f58fe15a7095bb05c4c7be616ed91986853e46d4e","size":{"x":32,"y":1,"z":32}},{"blockCount":108,"bytes":3511,"file":"chunks/y112-z096-x096.json","offset":{"x":96,"y":112,"z":96},"requirements":{"minecraft:bricks":40,"minecraft:glass":1,"minecraft:oak_planks":2,"minecraft:polished_diorite":41,"minecraft:sandstone":11,"minecraft:stone_bricks":13},"sha256":"3d64285ea779b841ba1c761b4d911bd7c9d6141bad9b673afdbce8a1c83bb46c","size":{"x":32,"y":1,"z":32}},{"blockCount":175,"bytes":4823,"file":"chunks/y112-z096-x128.json","offset":{"x":128,"y":112,"z":96},"requirements":{"minecraft:bricks":57,"minecraft:glass":2,"minecraft:oak_planks":2,"minecraft:polished_diorite":79,"minecraft:sandstone":15,"minecraft:stone_bricks":20},"sha256":"59ce8e9c514f2074493c2ee2cd9cd0470ad5668ca8f18bce9afbb608bf0053a8","size":{"x":32,"y":1,"z":32}},{"blockCount":173,"bytes":4379,"file":"chunks/y112-z096-x160.json","offset":{"x":160,"y":112,"z":96},"requirements":{"minecraft:bricks":38,"minecraft:glass":2,"minecraft:polished_diorite":105,"minecraft:sandstone":13,"minecraft:stone_bricks":15},"sha256":"1bc16d6415227c4d1b6c1cc21089e3084e04b21f1cc30bc25e83505aab3a28c8","size":{"x":32,"y":1,"z":32}},{"blockCount":276,"bytes":5703,"file":"chunks/y112-z096-x192.json","offset":{"x":192,"y":112,"z":96},"requirements":{"minecraft:bricks":130,"minecraft:glass":1,"minecraft:oak_planks":7,"minecraft:polished_diorite":89,"minecraft:sandstone":8,"minecraft:stone_bricks":41},"sha256":"09b6125eb4f171fb86633449d4a280055fc4388a0f662be43eded9b695a44a4e","size":{"x":32,"y":1,"z":32}},{"blockCount":150,"bytes":4110,"file":"chunks/y112-z096-x224.json","offset":{"x":224,"y":112,"z":96},"requirements":{"minecraft:bricks":63,"minecraft:oak_planks":15,"minecraft:polished_diorite":45,"minecraft:sandstone":1,"minecraft:stone_bricks":26},"sha256":"362003b2306a6459349da559126567ca0fa38d5b68f26c8dd1f18816bd7b61d6","size":{"x":32,"y":1,"z":32}},{"blockCount":51,"bytes":1788,"file":"chunks/y112-z128-x000.json","offset":{"x":0,"y":112,"z":128},"requirements":{"minecraft:polished_diorite":50,"minecraft:stone_bricks":1},"sha256":"71945b370ad7df160d8c26ed3df518208d47825ab8dce25496f4657591a86b85","size":{"x":32,"y":1,"z":32}},{"blockCount":135,"bytes":3850,"file":"chunks/y112-z128-x032.json","offset":{"x":32,"y":112,"z":128},"requirements":{"minecraft:bricks":37,"minecraft:glass":15,"minecraft:polished_diorite":52,"minecraft:sandstone":18,"minecraft:stone_bricks":13},"sha256":"eaab87664476892a76254561b58f86edba243f8b46d80db28376548dd8118844","size":{"x":32,"y":1,"z":32}},{"blockCount":56,"bytes":1832,"file":"chunks/y112-z128-x064.json","offset":{"x":64,"y":112,"z":128},"requirements":{"minecraft:bricks":36,"minecraft:glass":2,"minecraft:sandstone":13,"minecraft:stone_bricks":5},"sha256":"9bbc0b2896e234098426513c5256b2298919efb791d2e5c599c086f2a9d2506a","size":{"x":32,"y":1,"z":32}},{"blockCount":16,"bytes":1079,"file":"chunks/y112-z128-x096.json","offset":{"x":96,"y":112,"z":128},"requirements":{"minecraft:bricks":12,"minecraft:oak_planks":1,"minecraft:sandstone":1,"minecraft:stone_bricks":2},"sha256":"ec6b9f5fa0023852593c4081247c1fd9c9ab7f978ac6010c0bb58a843e330e37","size":{"x":32,"y":1,"z":32}},{"blockCount":42,"bytes":1633,"file":"chunks/y112-z128-x128.json","offset":{"x":128,"y":112,"z":128},"requirements":{"minecraft:bricks":28,"minecraft:glass":1,"minecraft:oak_planks":1,"minecraft:sandstone":7,"minecraft:stone_bricks":5},"sha256":"521bcd279761bf305357de738678f263cd8024b70b4c5aa9cde109343c9cfd85","size":{"x":32,"y":1,"z":32}},{"blockCount":57,"bytes":1853,"file":"chunks/y112-z128-x160.json","offset":{"x":160,"y":112,"z":128},"requirements":{"minecraft:bricks":38,"minecraft:glass":2,"minecraft:sandstone":13,"minecraft:stone_bricks":4},"sha256":"87099a5e02e5c798e63a3c2eb7ed5588212c54587f32a780148b47befad0b08b","size":{"x":32,"y":1,"z":32}},{"blockCount":60,"bytes":1682,"file":"chunks/y112-z128-x192.json","offset":{"x":192,"y":112,"z":128},"requirements":{"minecraft:bricks":46,"minecraft:glass":1,"minecraft:sandstone":8,"minecraft:stone_bricks":5},"sha256":"4a8bac5f766674e49cdf6a4388a607bc74497156293c29b346e9a17bb6993267","size":{"x":32,"y":1,"z":32}},{"blockCount":143,"bytes":3534,"file":"chunks/y112-z128-x224.json","offset":{"x":224,"y":112,"z":128},"requirements":{"minecraft:bricks":44,"minecraft:glass":4,"minecraft:oak_planks":13,"minecraft:polished_diorite":57,"minecraft:sandstone":8,"minecraft:stone_bricks":17},"sha256":"0a4fc05c60fdc17f0cdd4d4407defa49c393ad918b027080c5480272b79374a4","size":{"x":32,"y":1,"z":32}},{"blockCount":14,"bytes":956,"file":"chunks/y112-z160-x000.json","offset":{"x":0,"y":112,"z":160},"requirements":{"minecraft:polished_diorite":14},"sha256":"a1defb27ff3f1f36d0d88534d7f9122b70db27617defec6c740a44cb6be16d72","size":{"x":32,"y":1,"z":32}},{"blockCount":108,"bytes":2887,"file":"chunks/y112-z160-x032.json","offset":{"x":32,"y":112,"z":160},"requirements":{"minecraft:polished_diorite":100,"minecraft:stone_bricks":8},"sha256":"572b9ba4a39ea44ed6ca1be3b9bf9cb7b9daf66775f19bdfce191c34082d1b37","size":{"x":32,"y":1,"z":32}},{"blockCount":109,"bytes":2805,"file":"chunks/y112-z160-x064.json","offset":{"x":64,"y":112,"z":160},"requirements":{"minecraft:polished_diorite":99,"minecraft:stone_bricks":10},"sha256":"c69c8518c9cdae79be1142d756bcb0528b79e9b4f38f2c7c9bf924f5753fc555","size":{"x":32,"y":1,"z":32}},{"blockCount":116,"bytes":3704,"file":"chunks/y112-z160-x096.json","offset":{"x":96,"y":112,"z":160},"requirements":{"minecraft:bricks":37,"minecraft:glass":2,"minecraft:oak_planks":1,"minecraft:polished_diorite":51,"minecraft:sandstone":11,"minecraft:stone_bricks":14},"sha256":"9e236f33dba574ee916e52fab577e379e1ed9a928fd4eeec2f4e3aae7ee6a152","size":{"x":32,"y":1,"z":32}},{"blockCount":163,"bytes":4693,"file":"chunks/y112-z160-x128.json","offset":{"x":128,"y":112,"z":160},"requirements":{"minecraft:bricks":35,"minecraft:glass":2,"minecraft:oak_planks":1,"minecraft:polished_diorite":96,"minecraft:sandstone":11,"minecraft:stone_bricks":18},"sha256":"85fac281886089476dca76afd8e6ec5ecfe804520725b3dc4452cb9bd831b022","size":{"x":32,"y":1,"z":32}},{"blockCount":116,"bytes":3055,"file":"chunks/y112-z160-x160.json","offset":{"x":160,"y":112,"z":160},"requirements":{"minecraft:polished_diorite":105,"minecraft:stone_bricks":11},"sha256":"537dd8f7398fbb52e270b5bcd336f57541f89e8f15f8904af372bfdcb72e1280","size":{"x":32,"y":1,"z":32}},{"blockCount":237,"bytes":5166,"file":"chunks/y112-z160-x192.json","offset":{"x":192,"y":112,"z":160},"requirements":{"minecraft:bricks":84,"minecraft:oak_planks":7,"minecraft:polished_diorite":101,"minecraft:stone_bricks":45},"sha256":"5b3d0744a9a15cea58c34606cb6722e06fd7ef1ba583c2c093b7a5891cb7e292","size":{"x":32,"y":1,"z":32}},{"blockCount":129,"bytes":3875,"file":"chunks/y112-z160-x224.json","offset":{"x":224,"y":112,"z":160},"requirements":{"minecraft:bricks":50,"minecraft:oak_planks":15,"minecraft:polished_diorite":35,"minecraft:stone_bricks":29},"sha256":"3e62554ead8b9ee4f390b6ad1ffb01f22ad86eb3518d250e722ee6a39be9fc0a","size":{"x":32,"y":1,"z":32}},{"blockCount":46,"bytes":1685,"file":"chunks/y112-z192-x064.json","offset":{"x":64,"y":112,"z":192},"requirements":{"minecraft:polished_diorite":46},"sha256":"a3a3f803c4fb41dc9a48dca9661570fdfbb90535aad7e615c5fafaa6a4e7e747","size":{"x":32,"y":1,"z":32}},{"blockCount":177,"bytes":3827,"file":"chunks/y112-z192-x096.json","offset":{"x":96,"y":112,"z":192},"requirements":{"minecraft:bricks":54,"minecraft:glass":5,"minecraft:oak_planks":10,"minecraft:polished_diorite":72,"minecraft:sandstone":13,"minecraft:stone_bricks":23},"sha256":"dec4411082b2a47371cc117ba178762a71faab1c6407bb19dbf1d7a940eb058f","size":{"x":32,"y":1,"z":32}},{"blockCount":164,"bytes":4291,"file":"chunks/y112-z192-x128.json","offset":{"x":128,"y":112,"z":192},"requirements":{"minecraft:bricks":33,"minecraft:glass":1,"minecraft:oak_planks":3,"minecraft:polished_diorite":101,"minecraft:sandstone":10,"minecraft:stone_bricks":16},"sha256":"0c468603201baed39da6c38a0107b7c9f39cdf7c71104c4a93155a59b2f2623d","size":{"x":32,"y":1,"z":32}},{"blockCount":72,"bytes":2263,"file":"chunks/y113-z064-x064.json","offset":{"x":64,"y":113,"z":64},"requirements":{"minecraft:polished_diorite":37,"minecraft:stone_bricks":35},"sha256":"ee8661e26c3b83df5f724e158d4fd4df05fe6856f7c2e1dc152fc61914c2291f","size":{"x":32,"y":1,"z":32}},{"blockCount":229,"bytes":4479,"file":"chunks/y113-z064-x096.json","offset":{"x":96,"y":113,"z":64},"requirements":{"minecraft:bricks":68,"minecraft:glass":3,"minecraft:oak_planks":7,"minecraft:polished_diorite":96,"minecraft:sandstone":14,"minecraft:stone_bricks":41},"sha256":"3bd384349a7f3d1dbc8335669873e06ab9676a97ad4a9b84e008b63117ab7349","size":{"x":32,"y":1,"z":32}},{"blockCount":240,"bytes":5450,"file":"chunks/y113-z064-x128.json","offset":{"x":128,"y":113,"z":64},"requirements":{"minecraft:bricks":44,"minecraft:oak_planks":2,"minecraft:polished_diorite":111,"minecraft:sandstone":10,"minecraft:stone_bricks":73},"sha256":"ad4b7d929414386df2187f4e8902bb40e20a66f08434687c3a00c97a22e2f55a","size":{"x":32,"y":1,"z":32}},{"blockCount":25,"bytes":1172,"file":"chunks/y113-z064-x192.json","offset":{"x":192,"y":113,"z":64},"requirements":{"minecraft:polished_diorite":12,"minecraft:stone_bricks":13},"sha256":"644aa0c92b5aaac7f63e4e7120a39e65233643ce533c5e79f4257a91373a878a","size":{"x":32,"y":1,"z":32}},{"blockCount":31,"bytes":1230,"file":"chunks/y113-z064-x224.json","offset":{"x":224,"y":113,"z":64},"requirements":{"minecraft:polished_diorite":15,"minecraft:stone_bricks":16},"sha256":"170139e53b3d23816c27a6815ef81a0d68d9263e7395a74dd120423e5ef2613a","size":{"x":32,"y":1,"z":32}},{"blockCount":36,"bytes":1502,"file":"chunks/y113-z096-x000.json","offset":{"x":0,"y":113,"z":96},"requirements":{"minecraft:polished_diorite":16,"minecraft:stone_bricks":20},"sha256":"bc3290d7d593517721dfa9c6efdea684ba8f8c3240719d8010e1becd3d4a8e5d","size":{"x":32,"y":1,"z":32}},{"blockCount":201,"bytes":4775,"file":"chunks/y113-z096-x032.json","offset":{"x":32,"y":113,"z":96},"requirements":{"minecraft:bricks":28,"minecraft:polished_diorite":103,"minecraft:sandstone":4,"minecraft:stone_bricks":66},"sha256":"6d2ee89e02f69909a73a950974ab97d09e7e5ad19f0f863aeb4ed357f2f78a5b","size":{"x":32,"y":1,"z":32}},{"blockCount":202,"bytes":4238,"file":"chunks/y113-z096-x064.json","offset":{"x":64,"y":113,"z":96},"requirements":{"minecraft:bricks":40,"minecraft:polished_diorite":94,"minecraft:sandstone":8,"minecraft:stone_bricks":60},"sha256":"a311337ce60873646a962b9cc8b263e158ae500887cdf4a72dd9ac14709fd25c","size":{"x":32,"y":1,"z":32}},{"blockCount":118,"bytes":3579,"file":"chunks/y113-z096-x096.json","offset":{"x":96,"y":113,"z":96},"requirements":{"minecraft:bricks":44,"minecraft:polished_diorite":48,"minecraft:sandstone":6,"minecraft:stone_bricks":20},"sha256":"5e4824f837f9d1e184d195d0d8e6035b3faa98190f35f334067a9ab09eacf4cc","size":{"x":32,"y":1,"z":32}},{"blockCount":207,"bytes":4910,"file":"chunks/y113-z096-x128.json","offset":{"x":128,"y":113,"z":96},"requirements":{"minecraft:bricks":62,"minecraft:polished_diorite":89,"minecraft:sandstone":9,"minecraft:stone_bricks":47},"sha256":"7895075143a33b0d26a24eed242f72daded402dd2f306119c54ea42d773c0e50","size":{"x":32,"y":1,"z":32}},{"blockCount":215,"bytes":4659,"file":"chunks/y113-z096-x160.json","offset":{"x":160,"y":113,"z":96},"requirements":{"minecraft:bricks":42,"minecraft:polished_diorite":102,"minecraft:sandstone":9,"minecraft:stone_bricks":62},"sha256":"6ab6e85f761a2c2a38ab1935466ac06c936e0d72f2b8ad6f77e4a008b3b98bc1","size":{"x":32,"y":1,"z":32}},{"blockCount":297,"bytes":5975,"file":"chunks/y113-z096-x192.json","offset":{"x":192,"y":113,"z":96},"requirements":{"minecraft:bricks":131,"minecraft:oak_planks":7,"minecraft:polished_diorite":88,"minecraft:sandstone":6,"minecraft:spruce_planks":2,"minecraft:stone_bricks":63},"sha256":"84002ab2ff0d1cb0d653c99231285ef7c739eded8919d640a754ad2db4f0e524","size":{"x":32,"y":1,"z":32}},{"blockCount":162,"bytes":4271,"file":"chunks/y113-z096-x224.json","offset":{"x":224,"y":113,"z":96},"requirements":{"minecraft:bricks":63,"minecraft:oak_planks":15,"minecraft:polished_diorite":45,"minecraft:sandstone":1,"minecraft:spruce_planks":2,"minecraft:stone_bricks":36},"sha256":"b2b97838fd9f47adfeabbf2a1739c946b4acd3fbaad765dcd44345979f3752af","size":{"x":32,"y":1,"z":32}},{"blockCount":63,"bytes":1979,"file":"chunks/y113-z128-x000.json","offset":{"x":0,"y":113,"z":128},"requirements":{"minecraft:polished_diorite":41,"minecraft:stone_bricks":22},"sha256":"abdd65f4be3ece5a5a73fdcfae5643cff2e7aa92d16e20fbe06ee5e6a9c12345","size":{"x":32,"y":1,"z":32}},{"blockCount":134,"bytes":3659,"file":"chunks/y113-z128-x032.json","offset":{"x":32,"y":113,"z":128},"requirements":{"minecraft:bricks":40,"minecraft:glass":13,"minecraft:polished_diorite":43,"minecraft:sandstone":12,"minecraft:stone_bricks":26},"sha256":"87fd37c8b4f131ffc73fac1dc548af5b14cbcf4aac8f93b9b5e025f56d125921","size":{"x":32,"y":1,"z":32}},{"blockCount":57,"bytes":1640,"file":"chunks/y113-z128-x064.json","offset":{"x":64,"y":113,"z":128},"requirements":{"minecraft:bricks":40,"minecraft:sandstone":8,"minecraft:stone_bricks":9},"sha256":"c9cb2babb58fe843d421d4f1d4e06be8de20777265dfaa2da7b3b84b32fc89af","size":{"x":32,"y":1,"z":32}},{"blockCount":16,"bytes":1055,"file":"chunks/y113-z128-x096.json","offset":{"x":96,"y":113,"z":128},"requirements":{"minecraft:bricks":14,"minecraft:sandstone":1,"minecraft:stone_bricks":1},"sha256":"fa6937dbbf687850f3c8d6cf4acfd37d89045bf55159bfeb3e28c64f56a4ec1a","size":{"x":32,"y":1,"z":32}},{"blockCount":41,"bytes":1436,"file":"chunks/y113-z128-x128.json","offset":{"x":128,"y":113,"z":128},"requirements":{"minecraft:bricks":31,"minecraft:sandstone":4,"minecraft:stone_bricks":6},"sha256":"dc7b0f647578141d5496e5e7880e5063990c3442363758f745b56d8dde2e094c","size":{"x":32,"y":1,"z":32}}],"schema":1}
