{"entries":[{"blockCount":59,"bytes":1680,"file":"chunks/y113-z128-x160.json","offset":{"x":160,"y":113,"z":128},"requirements":{"minecraft:bricks":42,"minecraft:sandstone":9,"minecraft:stone_bricks":8},"sha256":"8e917e1fafa748ce549ea601e37749df3a1e01d776c857488794a6abf565566b","size":{"x":32,"y":1,"z":32}},{"blockCount":59,"bytes":1548,"file":"chunks/y113-z128-x192.json","offset":{"x":192,"y":113,"z":128},"requirements":{"minecraft:bricks":47,"minecraft:sandstone":6,"minecraft:stone_bricks":6},"sha256":"56903f56617eb71d7e9bd8ef5d1af5f4fa41ba7288973e6d2492f9fd28c62890","size":{"x":32,"y":1,"z":32}},{"blockCount":147,"bytes":3515,"file":"chunks/y113-z128-x224.json","offset":{"x":224,"y":113,"z":128},"requirements":{"minecraft:bricks":47,"minecraft:glass":3,"minecraft:oak_planks":9,"minecraft:polished_diorite":55,"minecraft:sandstone":11,"minecraft:stone_bricks":22},"sha256":"821fdf5760700e1fec44ff66379e216f838a39ab10b58902dd3628e46144b194","size":{"x":32,"y":1,"z":32}},{"blockCount":17,"bytes":1020,"file":"chunks/y113-z160-x000.json","offset":{"x":0,"y":113,"z":160},"requirements":{"minecraft:polished_diorite":5,"minecraft:stone_bricks":12},"sha256":"15a944dadb1ece7b655abcabadc2ec21cc69ae4e2eac5af1eb1510cf1cbf7bf1","size":{"x":32,"y":1,"z":32}},{"blockCount":138,"bytes":3357,"file":"chunks/y113-z160-x032.json","offset":{"x":32,"y":113,"z":160},"requirements":{"minecraft:polished_diorite":90,"minecraft:stone_bricks":48},"sha256":"048423bfb7c617f5a265096b74c766de4a539ab7aadd9307288dded122c0de7c","size":{"x":32,"y":1,"z":32}},{"blockCount":155,"bytes":3396,"file":"chunks/y113-z160-x064.json","offset":{"x":64,"y":113,"z":160},"requirements":{"minecraft:polished_diorite":97,"minecraft:stone_bricks":58},"sha256":"83491205e9b070a3c9a5d500f421bf040600ddbbc1db3eb52a17d724f07a444e","size":{"x":32,"y":1,"z":32}},{"blockCount":133,"bytes":3905,"file":"chunks/y113-z160-x096.json","offset":{"x":96,"y":113,"z":160},"requirements":{"minecraft:bricks":39,"minecraft:polished_diorite":61,"minecraft:sandstone":8,"minecraft:stone_bricks":25},"sha256":"4e3f6aff834a942070294fa8ef89b03b456e9341633210fd0d410f895cae4fb7","size":{"x":32,"y":1,"z":32}},{"blockCount":206,"bytes":5028,"file":"chunks/y113-z160-x128.json","offset":{"x":128,"y":113,"z":160},"requirements":{"minecraft:bricks":39,"minecraft:polished_diorite":105,"minecraft:sandstone":8,"minecraft:stone_bricks":54},"sha256":"76458ffc6dae3eac9df47e00fe92477860f043cb7bba2878a05581bed8193cb9","size":{"x":32,"y":1,"z":32}},{"blockCount":156,"bytes":3507,"file":"chunks/y113-z160-x160.json","offset":{"x":160,"y":113,"z":160},"requirements":{"minecraft:polished_diorite":102,"minecraft:stone_bricks":54},"sha256":"b7915d0aeb321616afab9e13c87027603da2637fbc7ff34ddc42dd2f7872ea78","size":{"x":32,"y":1,"z":32}},{"blockCount":263,"bytes":5593,"file":"chunks/y113-z160-x192.json","offset":{"x":192,"y":113,"z":160},"requirements":{"minecraft:bricks":84,"minecraft:oak_planks":7,"minecraft:polished_diorite":100,"minecraft:spruce_planks":2,"minecraft:stone_bricks":70},"sha256":"8c89a1df2810ee6e62a5dd7a2eccd6dda225efb394e83eb0b2351498641a3f4f","size":{"x":32,"y":1,"z":32}},{"blockCount":141,"bytes":4056,"file":"chunks/y113-z160-x224.json","offset":{"x":224,"y":113,"z":160},"requirements":{"minecraft:bricks":50,"minecraft:oak_planks":15,"minecraft:polished_diorite":37,"minecraft:spruce_planks":2,"minecraft:stone_bricks":37},"sha256":"adf4aa2da774d728559040639145f7ed2507cf0e9efde2f1c97b7730a6759288","size":{"x":32,"y":1,"z":32}},{"blockCount":62,"bytes":2017,"file":"chunks/y113-z192-x064.json","offset":{"x":64,"y":113,"z":192},"requirements":{"minecraft:polished_diorite":34,"minecraft:stone_bricks":28},"sha256":"5629738528e4b8fddcf7e8a5c4b81aa7bd740499f5a6d3a1853cbab7c3862274","size":{"x":32,"y":1,"z":32}},{"blockCount":199,"bytes":3733,"file":"chunks/y113-z192-x096.json","offset":{"x":96,"y":113,"z":192},"requirements":{"minecraft:bricks":60,"minecraft:glass":3,"minecraft:oak_planks":7,"minecraft:polished_diorite":83,"minecraft:sandstone":11,"minecraft:stone_bricks":35},"sha256":"3b576496b74c73efbe6a11a4bde765105b31c0d6ccbcad0165ea460037e4d4a7","size":{"x":32,"y":1,"z":32}},{"blockCount":200,"bytes":4554,"file":"chunks/y113-z192-x128.json","offset":{"x":128,"y":113,"z":192},"requirements":{"minecraft:bricks":36,"minecraft:oak_planks":2,"minecraft:polished_diorite":95,"minecraft:sandstone":7,"minecraft:stone_bricks":60},"sha256":"758dd7f5a7ea315a53996ff4377c727ce695d81c42f8722b6e4fd1ca58d53ead","size":{"x":32,"y":1,"z":32}},{"blockCount":58,"bytes":2301,"file":"chunks/y114-z064-x064.json","offset":{"x":64,"y":114,"z":64},"requirements":{"minecraft:polished_diorite":44,"minecraft:stone_bricks":14},"sha256":"1cd76071357e109ea71cb6e51407fee7c7c3c528b0b24c4d7e67a6ea99d44751","size":{"x":32,"y":1,"z":32}},{"blockCount":238,"bytes":4706,"file":"chunks/y114-z064-x096.json","offset":{"x":96,"y":114,"z":64},"requirements":{"minecraft:bricks":76,"minecraft:glass":1,"minecraft:oak_planks":13,"minecraft:polished_diorite":99,"minecraft:sandstone":5,"minecraft:stone_bricks":44},"sha256":"539d90485abf8156c281d5f7a89b2ad5609e6bd150ff3e3d1760a2cf0e1af4c9","size":{"x":32,"y":1,"z":32}},{"blockCount":227,"bytes":5527,"file":"chunks/y114-z064-x128.json","offset":{"x":128,"y":114,"z":64},"requirements":{"minecraft:bricks":46,"minecraft:oak_planks":4,"minecraft:polished_diorite":121,"minecraft:sandstone":5,"minecraft:stone_bricks":51},"sha256":"05d602d54832008faacef6d689224a9a06a7f692383eb51c0946975f5a0da083","size":{"x":32,"y":1,"z":32}},{"blockCount":31,"bytes":1096,"file":"chunks/y114-z064-x192.json","offset":{"x":192,"y":114,"z":64},"requirements":{"minecraft:polished_diorite":16,"minecraft:stone_bricks":15},"sha256":"c2bf58fd980ac4e36915f6803e8707019eb53c427546849ab56b86af070cef6e","size":{"x":32,"y":1,"z":32}},{"blockCount":37,"bytes":1154,"file":"chunks/y114-z064-x224.json","offset":{"x":224,"y":114,"z":64},"requirements":{"minecraft:polished_diorite":19,"minecraft:stone_bricks":18},"sha256":"71e8f440cd378cbbc0707e6e56368d18c9460d404ce8b02459fa139d0e2a605c","size":{"x":32,"y":1,"z":32}},{"blockCount":31,"bytes":1577,"file":"chunks/y114-z096-x000.json","offset":{"x":0,"y":114,"z":96},"requirements":{"minecraft:polished_diorite":23,"minecraft:stone_bricks":8},"sha256":"6efd53a5a383f4a4abd9991399817aab74c7da9ddd3409c0c088b9eff6fc414a","size":{"x":32,"y":1,"z":32}},{"blockCount":196,"bytes":4775,"file":"chunks/y114-z096-x032.json","offset":{"x":32,"y":114,"z":96},"requirements":{"minecraft:bricks":31,"minecraft:polished_diorite":116,"minecraft:sandstone":3,"minecraft:stone_bricks":46},"sha256":"21fd460f5b2b4eab481fba476ef41f945be3bbf2c55d20636a2c12d1ae312c11","size":{"x":32,"y":1,"z":32}},{"blockCount":191,"bytes":4296,"file":"chunks/y114-z096-x064.json","offset":{"x":64,"y":114,"z":96},"requirements":{"minecraft:bricks":43,"minecraft:polished_diorite":96,"minecraft:sandstone":5,"minecraft:stone_bricks":47},"sha256":"b91248963a630df57c3004688efb3c5db764fffe1e822e47f3848329183e97bf","size":{"x":32,"y":1,"z":32}},{"blockCount":122,"bytes":3656,"file":"chunks/y114-z096-x096.json","offset":{"x":96,"y":114,"z":96},"requirements":{"minecraft:bricks":47,"minecraft:polished_diorite":48,"minecraft:sandstone":5,"minecraft:stone_bricks":22},"sha256":"64efcc0afe3963e409c6e638bad37aa5d8d55fe1a85293b21cd2835e47a081d5","size":{"x":32,"y":1,"z":32}},{"blockCount":209,"bytes":5025,"file":"chunks/y114-z096-x128.json","offset":{"x":128,"y":114,"z":96},"requirements":{"minecraft:bricks":68,"minecraft:polished_diorite":89,"minecraft:sandstone":7,"minecraft:stone_bricks":45},"sha256":"5b5e5b98d9e854546354c2bff3e62cc83418f2c565eaa567de15d1042c44ca31","size":{"x":32,"y":1,"z":32}},{"blockCount":206,"bytes":4585,"file":"chunks/y114-z096-x160.json","offset":{"x":160,"y":114,"z":96},"requirements":{"minecraft:bricks":49,"minecraft:polished_diorite":108,"minecraft:sandstone":5,"minecraft:stone_bricks":44},"sha256":"105ab46c20d3ba6fae7fe1f99ddd39b7541fba1a5cd022029bf3903685ebc607","size":{"x":32,"y":1,"z":32}},{"blockCount":306,"bytes":6035,"file":"chunks/y114-z096-x192.json","offset":{"x":192,"y":114,"z":96},"requirements":{"minecraft:bricks":134,"minecraft:oak_planks":7,"minecraft:polished_diorite":97,"minecraft:sandstone":4,"minecraft:spruce_planks":2,"minecraft:stone_bricks":62},"sha256":"6598de0c3dec33d8cabfe943ce08c6fbff515d73fc1af85aa72af8d7afc2b8f6","size":{"x":32,"y":1,"z":32}},{"blockCount":172,"bytes":4482,"file":"chunks/y114-z096-x224.json","offset":{"x":224,"y":114,"z":96},"requirements":{"minecraft:bricks":65,"minecraft:oak_planks":15,"minecraft:polished_diorite":53,"minecraft:sandstone":1,"minecraft:spruce_planks":2,"minecraft:stone_bricks":36},"sha256":"9ead2a26520072bcbef39210be72ed0602e49820d2c189c95668c9c3eaf96c4b","size":{"x":32,"y":1,"z":32}},{"blockCount":58,"bytes":2226,"file":"chunks/y114-z128-x000.json","offset":{"x":0,"y":114,"z":128},"requirements":{"minecraft:polished_diorite":44,"minecraft:stone_bricks":14},"sha256":"c24cae1cd10e4c8aa26718afe2210e01cc03505a3bdcb2bff632d306ae9ee62a","size":{"x":32,"y":1,"z":32}},{"blockCount":165,"bytes":3982,"file":"chunks/y114-z128-x032.json","offset":{"x":32,"y":114,"z":128},"requirements":{"minecraft:bricks":51,"minecraft:glass":14,"minecraft:polished_diorite":62,"minecraft:sandstone":14,"minecraft:stone_bricks":24},"sha256":"67f59cdadc50255af316968926ec6e9f43f0ac98e830e9e5af0dd70a3419d423","size":{"x":32,"y":1,"z":32}},{"blockCount":58,"bytes":1643,"file":"chunks/y114-z128-x064.json","offset":{"x":64,"y":114,"z":128},"requirements":{"minecraft:bricks":43,"minecraft:sandstone":5,"minecraft:stone_bricks":10},"sha256":"1ad020b63ff8795745a950a5aca165fbebe5d28209c1f8b5409d0f69725f1f06","size":{"x":32,"y":1,"z":32}},{"blockCount":18,"bytes":1093,"file":"chunks/y114-z128-x096.json","offset":{"x":96,"y":114,"z":128},"requirements":{"minecraft:bricks":15,"minecraft:sandstone":1,"minecraft:stone_bricks":2},"sha256":"68bb6e338423840bfcf0921fedf71aed24dd1b26208f05a82f798d6140d1f5b1","size":{"x":32,"y":1,"z":32}},{"blockCount":44,"bytes":1512,"file":"chunks/y114-z128-x128.json","offset":{"x":128,"y":114,"z":128},"requirements":{"minecraft:bricks":35,"minecraft:sandstone":3,"minecraft:stone_bricks":6},"sha256":"0056c36866217bb741e516a0df80c5afe982c5c8d6f815f7bf83a6b6d2e3e731","size":{"x":32,"y":1,"z":32}},{"blockCount":62,"bytes":1645,"file":"chunks/y114-z128-x160.json","offset":{"x":160,"y":114,"z":128},"requirements":{"minecraft:bricks":46,"minecraft:sandstone":5,"minecraft:stone_bricks":11},"sha256":"300caf8c38275c03f7538b7749625f0e719927bb202a7a0937d0acb462f0aa04","size":{"x":32,"y":1,"z":32}},{"blockCount":61,"bytes":1588,"file":"chunks/y114-z128-x192.json","offset":{"x":192,"y":114,"z":128},"requirements":{"minecraft:bricks":47,"minecraft:sandstone":4,"minecraft:stone_bricks":10},"sha256":"ffb508f3e6d8ca31dfe4642b2ba030a035e0e5e17bd724f0f25c8ad632eb8fc4","size":{"x":32,"y":1,"z":32}},{"blockCount":151,"bytes":3572,"file":"chunks/y114-z128-x224.json","offset":{"x":224,"y":114,"z":128},"requirements":{"minecraft:bricks":51,"minecraft:glass":1,"minecraft:oak_planks":17,"minecraft:polished_diorite":61,"minecraft:sandstone":3,"minecraft:stone_bricks":18},"sha256":"0e98737eb5453c7aa012092c00888d6412c05fe51ac6d21bc062c601dffb14ff","size":{"x":32,"y":1,"z":32}},{"blockCount":13,"bytes":1038,"file":"chunks/y114-z160-x000.json","offset":{"x":0,"y":114,"z":160},"requirements":{"minecraft:polished_diorite":9,"minecraft:stone_bricks":4},"sha256":"6efc0c62df226b12b3fb9a2a21f9b7264728f9a26948dd324c85f1a2caaf53a1","size":{"x":32,"y":1,"z":32}},{"blockCount":125,"bytes":3283,"file":"chunks/y114-z160-x032.json","offset":{"x":32,"y":114,"z":160},"requirements":{"minecraft:polished_diorite":97,"minecraft:stone_bricks":28},"sha256":"015f5cd990d69a13c5a795dcfbe867ad5ba370e24ef880f93dd7a1a6207c4728","size":{"x":32,"y":1,"z":32}},{"blockCount":141,"bytes":3435,"file":"chunks/y114-z160-x064.json","offset":{"x":64,"y":114,"z":160},"requirements":{"minecraft:polished_diorite":102,"minecraft:stone_bricks":39},"sha256":"c6d0cf56d526b4ac0c519973d67941621b1ca8c25db2d5e6da3475cef0881cf3","size":{"x":32,"y":1,"z":32}},{"blockCount":136,"bytes":3943,"file":"chunks/y114-z160-x096.json","offset":{"x":96,"y":114,"z":160},"requirements":{"minecraft:bricks":42,"minecraft:polished_diorite":61,"minecraft:sandstone":5,"minecraft:stone_bricks":28},"sha256":"54210cca8266016d25c36b269ac1eda831fc384c0adee61d035002a01d766fa3","size":{"x":32,"y":1,"z":32}},{"blockCount":204,"bytes":5142,"file":"chunks/y114-z160-x128.json","offset":{"x":128,"y":114,"z":160},"requirements":{"minecraft:bricks":42,"minecraft:polished_diorite":108,"minecraft:sandstone":5,"minecraft:stone_bricks":49},"sha256":"74b734259a52792a179a9d03a21d1a98071fe05eb4cd5f81b566af6d4e7a225a","size":{"x":32,"y":1,"z":32}},{"blockCount":141,"bytes":3565,"file":"chunks/y114-z160-x160.json","offset":{"x":160,"y":114,"z":160},"requirements":{"minecraft:polished_diorite":108,"minecraft:stone_bricks":33},"sha256":"3746c838cea65ace1c07cdb7bc8a394aa49d2a9aba645ef494593297e10fc08d","size":{"x":32,"y":1,"z":32}},{"blockCount":275,"bytes":5574,"file":"chunks/y114-z160-x192.json","offset":{"x":192,"y":114,"z":160},"requirements":{"minecraft:bricks":86,"minecraft:oak_planks":7,"minecraft:polished_diorite":113,"minecraft:spruce_planks":2,"minecraft:stone_bricks":67},"sha256":"72841013392c1e95db4d826df7c0adb840ccbeb395fcdcf8ac0f065ad370d69d","size":{"x":32,"y":1,"z":32}},{"blockCount":161,"bytes":4134,"file":"chunks/y114-z160-x224.json","offset":{"x":224,"y":114,"z":160},"requirements":{"minecraft:bricks":52,"minecraft:oak_planks":15,"minecraft:polished_diorite":49,"minecraft:spruce_planks":2,"minecraft:stone_bricks":43},"sha256":"2970439e521862b5c4a084b137277836d01a8f2659bf4071cdf02152b4253e7d","size":{"x":32,"y":1,"z":32}},{"blockCount":50,"bytes":2055,"file":"chunks/y114-z192-x064.json","offset":{"x":64,"y":114,"z":192},"requirements":{"minecraft:polished_diorite":38,"minecraft:stone_bricks":12},"sha256":"4216f4e8b581d5eb55664044403c0be7d2312178c7972b0e81ef78896f0a031b","size":{"x":32,"y":1,"z":32}},{"blockCount":207,"bytes":3998,"file":"chunks/y114-z192-x096.json","offset":{"x":96,"y":114,"z":192},"requirements":{"minecraft:bricks":67,"minecraft:glass":1,"minecraft:oak_planks":13,"minecraft:polished_diorite":86,"minecraft:sandstone":4,"minecraft:stone_bricks":36},"sha256":"4a002351e8557e60dfee2d2f8b56946a70b172d7a573623e76a76c40c4440fd9","size":{"x":32,"y":1,"z":32}},{"blockCount":188,"bytes":4592,"file":"chunks/y114-z192-x128.json","offset":{"x":128,"y":114,"z":192},"requirements":{"minecraft:bricks":37,"minecraft:oak_planks":4,"minecraft:polished_diorite":102,"minecraft:sandstone":4,"minecraft:stone_bricks":41},"sha256":"8898719e02301b63cce50bc4fc6158269cdc9bab6ca9385af8c36ae1ce02f2da","size":{"x":32,"y":1,"z":32}},{"blockCount":58,"bytes":2072,"file":"chunks/y115-z064-x064.json","offset":{"x":64,"y":115,"z":64},"requirements":{"minecraft:polished_diorite":53,"minecraft:stone_bricks":5},"sha256":"7dd5591bdcfd5c99576ed567935158c5ffc49eb58bb02aedfe8ea8f6219696f9","size":{"x":32,"y":1,"z":32}},{"blockCount":216,"bytes":4554,"file":"chunks/y115-z064-x096.json","offset":{"x":96,"y":115,"z":64},"requirements":{"minecraft:bricks":77,"minecraft:oak_planks":6,"minecraft:polished_diorite":88,"minecraft:sandstone":14,"minecraft:stone_bricks":31},"sha256":"84630426ce1be6fff6c1fb9528876317e74ca13823caa3e6086a7d55e197d628","size":{"x":32,"y":1,"z":32}},{"blockCount":211,"bytes":5223,"file":"chunks/y115-z064-x128.json","offset":{"x":128,"y":115,"z":64},"requirements":{"minecraft:bricks":50,"minecraft:oak_planks":3,"minecraft:polished_diorite":117,"minecraft:sandstone":8,"minecraft:stone_bricks":33},"sha256":"7278f1d5789c63f23912b8a788d3cbbef8ae2d023472ed44be00aece9e48becb","size":{"x":32,"y":1,"z":32}},{"blockCount":28,"bytes":1077,"file":"chunks/y115-z064-x192.json","offset":{"x":192,"y":115,"z":64},"requirements":{"minecraft:polished_diorite":15,"minecraft:stone_bricks":13},"sha256":"e7de49d37e82a55f1739a3631a1d2608d9031c955e8bb6398b7812e905f9fb0c","size":{"x":32,"y":1,"z":32}},{"blockCount":33,"bytes":1192,"file":"chunks/y115-z064-x224.json","offset":{"x":224,"y":115,"z":64},"requirements":{"minecraft:polished_diorite":17,"minecraft:stone_bricks":16},"sha256":"b3d11653fc7e5db0f9602ec5b466e5685c128f2a968194b155d26bbc8d32b71c","size":{"x":32,"y":1,"z":32}},{"blockCount":26,"bytes":1328,"file":"chunks/y115-z096-x000.json","offset":{"x":0,"y":115,"z":96},"requirements":{"minecraft:polished_diorite":24,"minecraft:stone_bricks":2},"sha256":"f7ecdd6ff02990319e3cb5f19c9bce031e6c57828c1ce76fe50bdad06f04fc70","size":{"x":32,"y":1,"z":32}},{"blockCount":179,"bytes":4359,"file":"chunks/y115-z096-x032.json","offset":{"x":32,"y":115,"z":96},"requirements":{"minecraft:bricks":36,"minecraft:polished_diorite":116,"minecraft:sandstone":6,"minecraft:stone_bricks":21},"sha256":"b0e2e9a197cc6b5cd9914a7b739824dfbe7eef73e0f8f5083414b9ba69f29c13","size":{"x":32,"y":1,"z":32}},{"blockCount":181,"bytes":4167,"file":"chunks/y115-z096-x064.json","offset":{"x":64,"y":115,"z":96},"requirements":{"minecraft:bricks":51,"minecraft:polished_diorite":96,"minecraft:sandstone":7,"minecraft:stone_bricks":27},"sha256":"8044c36488905c9cf4d9d28ced1f88750cc06234d5a50aa6e0bf1e9d09958663","size":{"x":32,"y":1,"z":32}},{"blockCount":124,"bytes":3543,"file":"chunks/y115-z096-x096.json","offset":{"x":96,"y":115,"z":96},"requirements":{"minecraft:bricks":58,"minecraft:polished_diorite":43,"minecraft:sandstone":8,"minecraft:stone_bricks":15},"sha256":"5e8df3873a6498861704a8559046f7ddbdd2ec46cc09cd7690797eeb4cca0759","size":{"x":32,"y":1,"z":32}},{"blockCount":205,"bytes":5046,"file":"chunks/y115-z096-x128.json","offset":{"x":128,"y":115,"z":96},"requirements":{"minecraft:bricks":81,"minecraft:polished_diorite":84,"minecraft:sandstone":11,"minecraft:stone_bricks":29},"sha256":"841d48d55923fdc501b8adeadf7214973516822d98940f434191277c07f126b6","size":{"x":32,"y":1,"z":32}},{"blockCount":195,"bytes":4627,"file":"chunks/y115-z096-x160.json","offset":{"x":160,"y":115,"z":96},"requirements":{"minecraft:bricks":53,"minecraft:polished_diorite":108,"minecraft:sandstone":7,"minecraft:stone_bricks":27},"sha256":"9edfbc35d14200414693bee2f59fef8ab76e5d8cb8e3a9de1615d089b1042278","size":{"x":32,"y":1,"z":32}},{"blockCount":334,"bytes":6265,"file":"chunks/y115-z096-x192.json","offset":{"x":192,"y":115,"z":96},"requirements":{"minecraft:bricks":151,"minecraft:glass":2,"minecraft:oak_planks":24,"minecraft:polished_diorite":97,"minecraft:sandstone":6,"minecraft:spruce_planks":2,"minecraft:stone_bricks":52},"sha256":"719e07915e3f16735fa1fe52641e5a019a4d73b606ef3b3eb351e9dc37e3330a","size":{"x":32,"y":1,"z":32}},{"blockCount":220,"bytes":4751,"file":"chunks/y115-z096-x224.json","offset":{"x":224,"y":115,"z":96},"requirements":{"minecraft:bricks":74,"minecraft:glass":7,"minecraft:oak_planks":51,"minecraft:polished_diorite":48,"minecraft:sandstone":1,"minecraft:spruce_planks":2,"minecraft:stone_bricks":37},"sha256":"6d6a31844f05121fddd1cc558d48f676185e454f151102b5cd7df720cf917fa1","size":{"x":32,"y":1,"z":32}},{"blockCount":51,"bytes":1881,"file":"chunks/y115-z128-x000.json","offset":{"x":0,"y":115,"z":128},"requirements":{"minecraft:polished_diorite":47,"minecraft:stone_bricks":4},"sha256":"b6aa0cc5a84d9dbbbe38819f2507be1b58df8799be2a1e760e7a07578cdfe324","size":{"x":32,"y":1,"z":32}},{"blockCount":149,"bytes":3868,"file":"chunks/y115-z128-x032.json","offset":{"x":32,"y":115,"z":128},"requirements":{"minecraft:bricks":55,"minecraft:glass":14,"minecraft:polished_diorite":50,"minecraft:sandstone":16,"minecraft:stone_bricks":14},"sha256":"7ca1c65bbe0ff09e50fd53cd10d497da537e8f442e94a9af53c6e636f8ae4b6e","size":{"x":32,"y":1,"z":32}},{"blockCount":64,"bytes":1797,"file":"chunks/y115-z128-x064.json","offset":{"x":64,"y":115,"z":128},"requirements":{"minecraft:bricks":51,"minecraft:sandstone":7,"minecraft:stone_bricks":6},"sha256":"aa67527aa26ec6227a9f627dfdcc9bd91d719f121fa733939c943bfd71a37c9a","size":{"x":32,"y":1,"z":32}},{"blockCount":23,"bytes":1132,"file":"chunks/y115-z128-x096.json","offset":{"x":96,"y":115,"z":128},"requirements":{"minecraft:bricks":19,"minecraft:sandstone":2,"minecraft:stone_bricks":2},"sha256":"5fc00799f90934cd9082bf03f54fee8a2d0b9f845925af68e467ecfcf598e0e1","size":{"x":32,"y":1,"z":32}},{"blockCount":51,"bytes":1667,"file":"chunks/y115-z128-x128.json","offset":{"x":128,"y":115,"z":128},"requirements":{"minecraft:bricks":42,"minecraft:sandstone":5,"minecraft:stone_bricks":4},"sha256":"d253be194b3ebe6faf61dfc832053dc6b7607cdcbf7cf4d70b5597898233d335","size":{"x":32,"y":1,"z":32}},{"blockCount":68,"bytes":1895,"file":"chunks/y115-z128-x160.json","offset":{"x":160,"y":115,"z":128},"requirements":{"minecraft:bricks":54,"minecraft:sandstone":7,"minecraft:stone_bricks":7},"sha256":"f0cde27aeae088f0073dc5e867d2df6723caecd6edec1577913fad92e2708eba","size":{"x":32,"y":1,"z":32}},{"blockCount":67,"bytes":1819,"file":"chunks/y115-z128-x192.json","offset":{"x":192,"y":115,"z":128},"requirements":{"minecraft:bricks":55,"minecraft:sandstone":6,"minecraft:stone_bricks":6},"sha256":"a18d1832288b60ed48946605f24d22e557b19b1ac88ff8fa3ac0f42cea26aad3","size":{"x":32,"y":1,"z":32}},{"blockCount":143,"bytes":3533,"file":"chunks/y115-z128-x224.json","offset":{"x":224,"y":115,"z":128},"requirements":{"minecraft:bricks":48,"minecraft:oak_planks":7,"minecraft:polished_diorite":57,"minecraft:sandstone":13,"minecraft:stone_bricks":18},"sha256":"32c0869adeb8897ff58b61688485d60a301c02a7517ebd60ef5469633a743523","size":{"x":32,"y":1,"z":32}},{"blockCount":13,"bytes":917,"file":"chunks/y115-z160-x000.json","offset":{"x":0,"y":115,"z":160},"requirements":{"minecraft:polished_diorite":13},"sha256":"8d7ad8d37614749714c1899a89eb7886a068023ee2275d7bae57bae1e2b1b772","size":{"x":32,"y":1,"z":32}},{"blockCount":115,"bytes":2906,"file":"chunks/y115-z160-x032.json","offset":{"x":32,"y":115,"z":160},"requirements":{"minecraft:polished_diorite":102,"minecraft:stone_bricks":13},"sha256":"0878eec22df8e898af51bb655678d84778f288f6b7aa5811e71a1a6e7e021875","size":{"x":32,"y":1,"z":32}},{"blockCount":125,"bytes":3151,"file":"chunks/y115-z160-x064.json","offset":{"x":64,"y":115,"z":160},"requirements":{"minecraft:polished_diorite":103,"minecraft:stone_bricks":22},"sha256":"179118c1d255889adf01f299ded0619100b317d7d515ff4802fabfcb35dc36ba","size":{"x":32,"y":1,"z":32}},{"blockCount":130,"bytes":3734,"file":"chunks/y115-z160-x096.json","offset":{"x":96,"y":115,"z":160},"requirements":{"minecraft:bricks":49,"minecraft:polished_diorite":55,"minecraft:sandstone":8,"minecraft:stone_bricks":18},"sha256":"21e6f2cc65d4ce9b35ad92292a91224b3e99f6eb97ed84bdc79b51251cbd6d45","size":{"x":32,"y":1,"z":32}},{"blockCount":190,"bytes":4857,"file":"chunks/y115-z160-x128.json","offset":{"x":128,"y":115,"z":160},"requirements":{"minecraft:bricks":49,"minecraft:polished_diorite":103,"minecraft:sandstone":8,"minecraft:stone_bricks":30},"sha256":"2917860f7df66b10f3b90a8f623ba298d145c9a6461fa0d293d256e8141d6731","size":{"x":32,"y":1,"z":32}},{"blockCount":128,"bytes":3263,"file":"chunks/y115-z160-x160.json","offset":{"x":160,"y":115,"z":160},"requirements":{"minecraft:polished_diorite":108,"minecraft:stone_bricks":20},"sha256":"cb4f7ecb88d80e412c3284e002b266049a0520fe3d73f24edaba3cc1c537b244","size":{"x":32,"y":1,"z":32}},{"blockCount":295,"bytes":5533,"file":"chunks/y115-z160-x192.json","offset":{"x":192,"y":115,"z":160},"requirements":{"minecraft:bricks":96,"minecraft:glass":2,"minecraft:oak_planks":24,"minecraft:polished_diorite":112,"minecraft:spruce_planks":2,"minecraft:stone_bricks":59},"sha256":"81c2a25d2eda17a4278055798c0435517856baf10b5f9851758f774edf5d2223","size":{"x":32,"y":1,"z":32}},{"blockCount":206,"bytes":4479,"file":"chunks/y115-z160-x224.json","offset":{"x":224,"y":115,"z":160},"requirements":{"minecraft:bricks":61,"minecraft:glass":7,"minecraft:oak_planks":51,"minecraft:polished_diorite":44,"minecraft:spruce_planks":2,"minecraft:stone_bricks":41},"sha256":"6681f51b196233ca4bcca52fbe2b9a2a42415c886ed6fda3cdf96b6d891c4172","size":{"x":32,"y":1,"z":32}},{"blockCount":50,"bytes":1864,"file":"chunks/y115-z192-x064.json","offset":{"x":64,"y":115,"z":192},"requirements":{"minecraft:polished_diorite":46,"minecraft:stone_bricks":4},"sha256":"89dd71df7135c1f6eda8da5447775cf8a670409c6da6662ef31705bb91fd98a8","size":{"x":32,"y":1,"z":32}},{"blockCount":187,"bytes":3903,"file":"chunks/y115-z192-x096.json","offset":{"x":96,"y":115,"z":192},"requirements":{"minecraft:bricks":67,"minecraft:oak_planks":6,"minecraft:polished_diorite":76,"minecraft:sandstone":12,"minecraft:stone_bricks":26},"sha256":"31786dad9081b8ec03cd6a9dd3ac9f442eae7f73a0abe2374e47c8862b01e72d","size":{"x":32,"y":1,"z":32}},{"blockCount":174,"bytes":4382,"file":"chunks/y115-z192-x128.json","offset":{"x":128,"y":115,"z":192},"requirements":{"minecraft:bricks":40,"minecraft:oak_planks":3,"minecraft:polished_diorite":98,"minecraft:sandstone":6,"minecraft:stone_bricks":27},"sha256":"69a170dda81f435ec0117ddf08638d4ac52daf2971d976994c2bd75304dbd007","size":{"x":32,"y":1,"z":32}},{"blockCount":60,"bytes":2130,"file":"chunks/y116-z064-x064.json","offset":{"x":64,"y":116,"z":64},"requirements":{"minecraft:polished_diorite":45,"minecraft:stone_bricks":15},"sha256":"8ecd7a5429fddcd6ac2967be62f095a14e1aebe88c12be8f029d19a895456c97","size":{"x":32,"y":1,"z":32}},{"blockCount":219,"bytes":4421,"file":"chunks/y116-z064-x096.json","offset":{"x":96,"y":116,"z":64},"requirements":{"minecraft:bricks":80,"minecraft:oak_planks":11,"minecraft:polished_diorite":95,"minecraft:sandstone":9,"minecraft:stone_bricks":24},"sha256":"7f34915cd318401999f5b018e1114fe333e8b2312a73ae9144339521e752cca1","size":{"x":32,"y":1,"z":32}},{"blockCount":212,"bytes":5069,"file":"chunks/y116-z064-x128.json","offset":{"x":128,"y":116,"z":64},"requirements":{"minecraft:bricks":53,"minecraft:oak_planks":4,"minecraft:polished_diorite":116,"minecraft:sandstone":7,"minecraft:stone_bricks":32},"sha256":"292a8edf75da77e401e41669b48e90b1b14a153bfa43db977b796b6a2597806b","size":{"x":32,"y":1,"z":32}},{"blockCount":28,"bytes":1039,"file":"chunks/y116-z064-x192.json","offset":{"x":192,"y":116,"z":64},"requirements":{"minecraft:polished_diorite":14,"minecraft:stone_bricks":14},"sha256":"16062d512a96cb1420275dadc38828c3ffe5f163132f276f665c60eb43ca00cd","size":{"x":32,"y":1,"z":32}},{"blockCount":33,"bytes":1154,"file":"chunks/y116-z064-x224.json","offset":{"x":224,"y":116,"z":64},"requirements":{"minecraft:polished_diorite":17,"minecraft:stone_bricks":16},"sha256":"778065967812a17c699c4ca7892300a674728b28f2166c18a7141df90a88db84","size":{"x":32,"y":1,"z":32}},{"blockCount":32,"bytes":1404,"file":"chunks/y116-z096-x000.json","offset":{"x":0,"y":116,"z":96},"requirements":{"minecraft:polished_diorite":25,"minecraft:stone_bricks":7},"sha256":"f20e7910e5b03c800a845b732bdc9dbc9a22df09ebeac320584efa03d2f9ec2c","size":{"x":32,"y":1,"z":32}},{"blockCount":183,"bytes":4315,"file":"chunks/y116-z096-x032.json","offset":{"x":32,"y":116,"z":96},"requirements":{"minecraft:bricks":35,"minecraft:polished_diorite":114,"minecraft:sandstone":4,"minecraft:stone_bricks":30},"sha256":"c9e397bd1c50dfcf6e2af61df9aa8d0246c293c4b87f194ea10a3d0ad3cfdd1e","size":{"x":32,"y":1,"z":32}},{"blockCount":177,"bytes":3858,"file":"chunks/y116-z096-x064.json","offset":{"x":64,"y":116,"z":96},"requirements":{"minecraft:bricks":52,"minecraft:polished_diorite":90,"minecraft:sandstone":5,"minecraft:stone_bricks":30},"sha256":"f44381fd1e9fa28fb582b4f67f57e8c919596807b040b5d95303b626f6878616","size":{"x":32,"y":1,"z":32}},{"blockCount":120,"bytes":3466,"file":"chunks/y116-z096-x096.json","offset":{"x":96,"y":116,"z":96},"requirements":{"minecraft:bricks":60,"minecraft:polished_diorite":45,"minecraft:sandstone":5,"minecraft:stone_bricks":10},"sha256":"123a7a917b7711e38d9e08fea1a71db581465508c689179a940c36b899652d39","size":{"x":32,"y":1,"z":32}},{"blockCount":197,"bytes":4779,"file":"chunks/y116-z096-x128.json","offset":{"x":128,"y":116,"z":96},"requirements":{"minecraft:bricks":85,"minecraft:polished_diorite":82,"minecraft:sandstone":7,"minecraft:stone_bricks":23},"sha256":"21ff8fecf83d4a1b4511bf3c77aba7d30a255bbfa1c554b5be7c57af45545924","size":{"x":32,"y":1,"z":32}},{"blockCount":195,"bytes":4104,"file":"chunks/y116-z096-x160.json","offset":{"x":160,"y":116,"z":96},"requirements":{"minecraft:bricks":56,"minecraft:polished_diorite":103,"minecraft:sandstone":5,"minecraft:stone_bricks":31},"sha256":"8287dd13a4ec1e92d571222b4229479d87053393bb542326e2633e5dda8c4810","size":{"x":32,"y":1,"z":32}},{"blockCount":329,"bytes":5762,"file":"chunks/y116-z096-x192.json","offset":{"x":192,"y":116,"z":96},"requirements":{"minecraft:bricks":174,"minecraft:oak_planks":2,"minecraft:polished_diorite":89,"minecraft:sandstone":4,"minecraft:spruce_planks":7,"minecraft:stone_bricks":53},"sha256":"2e04dab8f3e7fa59354430f3d5515bbed8eb080054a28d501d0ca6ddbdd50e35","size":{"x":32,"y":1,"z":32}},{"blockCount":225,"bytes":4428,"file":"chunks/y116-z096-x224.json","offset":{"x":224,"y":116,"z":96},"requirements":{"minecraft:bricks":120,"minecraft:oak_planks":5,"minecraft:polished_diorite":47,"minecraft:sandstone":1,"minecraft:spruce_planks":16,"minecraft:stone_bricks":36},"sha256":"f4b8bfa366f2b5ab9ead038a33458fc8c32cff99ca25157d75a317080cb8f872","size":{"x":32,"y":1,"z":32}},{"blockCount":55,"bytes":2033,"file":"chunks/y116-z128-x000.json","offset":{"x":0,"y":116,"z":128},"requirements":{"minecraft:polished_diorite":46,"minecraft:stone_bricks":9},"sha256":"d929a47b9eec2eabf542dcf3ad4cbff137a3fb6463c7e34c4f6e439708b27ff3","size":{"x":32,"y":1,"z":32}},{"blockCount":145,"bytes":3697,"file":"chunks/y116-z128-x032.json","offset":{"x":32,"y":116,"z":128},"requirements":{"minecraft:bricks":53,"minecraft:glass":11,"minecraft:polished_diorite":55,"minecraft:sandstone":13,"minecraft:stone_bricks":13},"sha256":"1023d3e4fcaa448bdde457e1403a9aefd8a401ed028086f8bae5dae5b99ea6bb","size":{"x":32,"y":1,"z":32}},{"blockCount":66,"bytes":1566,"file":"chunks/y116-z128-x064.json","offset":{"x":64,"y":116,"z":128},"requirements":{"minecraft:bricks":52,"minecraft:sandstone":5,"minecraft:stone_bricks":9},"sha256":"5e6a8bb79777042a151cc74e9653c071116ba98bfe35996102e02c950e5096dc","size":{"x":32,"y":1,"z":32}},{"blockCount":21,"bytes":1112,"file":"chunks/y116-z128-x096.json","offset":{"x":96,"y":116,"z":128},"requirements":{"minecraft:bricks":19,"minecraft:sandstone":1,"minecraft:stone_bricks":1},"sha256":"a594017b262763ba9d7149a951569e4235f41607e1988d55281aeb168c0307f8","size":{"x":32,"y":1,"z":32}},{"blockCount":50,"bytes":1514,"file":"chunks/y116-z128-x128.json","offset":{"x":128,"y":116,"z":128},"requirements":{"minecraft:bricks":43,"minecraft:sandstone":3,"minecraft:stone_bricks":4},"sha256":"427ea7126258c65b47320c4a81a8080f9e7a2b48adae33a6df7a32ba7fd4a1c9","size":{"x":32,"y":1,"z":32}},{"blockCount":71,"bytes":1551,"file":"chunks/y116-z128-x160.json","offset":{"x":160,"y":116,"z":128},"requirements":{"minecraft:bricks":56,"minecraft:sandstone":5,"minecraft:stone_bricks":10},"sha256":"381f01066bac7b4ff5092f3f05cb537f767c040f1c320fe8ef3c92833003ec72","size":{"x":32,"y":1,"z":32}},{"blockCount":70,"bytes":1512,"file":"chunks/y116-z128-x192.json","offset":{"x":192,"y":116,"z":128},"requirements":{"minecraft:bricks":58,"minecraft:sandstone":4,"minecraft:stone_bricks":8},"sha256":"483a294d6b87a03cf60c57132ae2addf7d176476fc524dd5fe843965a03e2dec","size":{"x":32,"y":1,"z":32}},{"blockCount":150,"bytes":3438,"file":"chunks/y116-z128-x224.json","offset":{"x":224,"y":116,"z":128},"requirements":{"minecraft:bricks":50,"minecraft:oak_planks":13,"minecraft:polished_diorite":64,"minecraft:sandstone":7,"minecraft:stone_bricks":16},"sha256":"fc0688d8b53c27db5caa2ce6ffec0149e6df8ee08907d23c4f5b5d69c7599e9d","size":{"x":32,"y":1,"z":32}},{"blockCount":17,"bytes":1020,"file":"chunks/y116-z160-x000.json","offset":{"x":0,"y":116,"z":160},"requirements":{"minecraft:polished_diorite":13,"minecraft:stone_bricks":4},"sha256":"d380cc2afb4e2435c6b3612f4d38fdaff515053c866f73c953eb1555807bebe4","size":{"x":32,"y":1,"z":32}},{"blockCount":112,"bytes":2879,"file":"chunks/y116-z160-x032.json","offset":{"x":32,"y":116,"z":160},"requirements":{"minecraft:polished_diorite":93,"minecraft:stone_bricks":19},"sha256":"788877a8fcdae2990d093bae3f2a6e4cdbe976fa9ab9d8ef3e31c358ad2fccfa","size":{"x":32,"y":1,"z":32}},{"blockCount":121,"bytes":3089,"file":"chunks/y116-z160-x064.json","offset":{"x":64,"y":116,"z":160},"requirements":{"minecraft:polished_diorite":97,"minecraft:stone_bricks":24},"sha256":"3db7913b97d4c4ef1c247db2e6ff13e99cfb51364dd359edbe67757b33186198","size":{"x":32,"y":1,"z":32}},{"blockCount":127,"bytes":3639,"file":"chunks/y116-z160-x096.json","offset":{"x":96,"y":116,"z":160},"requirements":{"minecraft:bricks":52,"minecraft:polished_diorite":57,"minecraft:sandstone":5,"minecraft:stone_bricks":13},"sha256":"32a5d5a8b88f1063aeca3c5bacd660a1a833665ffcb7167ca37933fb92980aa8","size":{"x":32,"y":1,"z":32}},{"blockCount":184,"bytes":4724,"file":"chunks/y116-z160-x128.json","offset":{"x":128,"y":116,"z":160},"requirements":{"minecraft:bricks":52,"minecraft:polished_diorite":101,"minecraft:sandstone":5,"minecraft:stone_bricks":26},"sha256":"008d99a2927ffb8a1961d58fee49747c15dde6df27557826a5a0d765c8804c9d","size":{"x":32,"y":1,"z":32}},{"blockCount":124,"bytes":3141,"file":"chunks/y116-z160-x160.json","offset":{"x":160,"y":116,"z":160},"requirements":{"minecraft:polished_diorite":103,"minecraft:stone_bricks":21},"sha256":"105ce718870d765c6603e0498c001c2ff28c74133ef6a6960460be73a835a855","size":{"x":32,"y":1,"z":32}},{"blockCount":287,"bytes":5303,"file":"chunks/y116-z160-x192.json","offset":{"x":192,"y":116,"z":160},"requirements":{"minecraft:bricks":116,"minecraft:oak_planks":2,"minecraft:polished_diorite":103,"minecraft:spruce_planks":7,"minecraft:stone_bricks":59},"sha256":"aabc28b739b3c812a2e8344e321702196ba503bc34be035ef59862fb422fe352","size":{"x":32,"y":1,"z":32}},{"blockCount":213,"bytes":4194,"file":"chunks/y116-z160-x224.json","offset":{"x":224,"y":116,"z":160},"requirements":{"minecraft:bricks":107,"minecraft:oak_planks":5,"minecraft:polished_diorite":43,"minecraft:spruce_planks":16,"minecraft:stone_bricks":42},"sha256":"f15f122654371029db5b7941779351943784fdbccbfb3c4692759c8a0b2122ac","size":{"x":32,"y":1,"z":32}},{"blockCount":50,"bytes":1903,"file":"chunks/y116-z192-x064.json","offset":{"x":64,"y":116,"z":192},"requirements":{"minecraft:polished_diorite":38,"minecraft:stone_bricks":12},"sha256":"197394942dfeb7055a52f8901f4b440620a55bad4de314f3a528983a97041923","size":{"x":32,"y":1,"z":32}},{"blockCount":191,"bytes":3808,"file":"chunks/y116-z192-x096.json","offset":{"x":96,"y":116,"z":192},"requirements":{"minecraft:bricks":69,"minecraft:oak_planks":11,"minecraft:polished_diorite":83,"minecraft:sandstone":8,"minecraft:stone_bricks":20},"sha256":"94e23ed5f99473c2f572e94ba4d6b2dffd3e115202e74ca5cedb9b1ce46d813d","size":{"x":32,"y":1,"z":32}},{"blockCount":174,"bytes":4267,"file":"chunks/y116-z192-x128.json","offset":{"x":128,"y":116,"z":192},"requirements":{"minecraft:bricks":42,"minecraft:oak_planks":4,"minecraft:polished_diorite":97,"minecraft:sandstone":6,"minecraft:stone_bricks":25},"sha256":"1170ed9c47657b9b0e550623b58877f797caeb52b2607c5f4ac0860b732fe105","size":{"x":32,"y":1,"z":32}},{"blockCount":69,"bytes":2458,"file":"chunks/y117-z064-x064.json","offset":{"x":64,"y":117,"z":64},"requirements":{"minecraft:polished_diorite":44,"minecraft:stone_bricks":25},"sha256":"81ea9505c3927450f93538b97f1877c65cf9264530849ce1c81c3ee835780c36","size":{"x":32,"y":1,"z":32}},{"blockCount":233,"bytes":4326,"file":"chunks/y117-z064-x096.json","offset":{"x":96,"y":117,"z":64},"requirements":{"minecraft:bricks":58,"minecraft:oak_planks":12,"minecraft:polished_diorite":117,"minecraft:sandstone":8,"minecraft:stone_bricks":38},"sha256":"e9edc3688906656e53519ea89d98b9718a70df7565b706d888d554f460ee0a3d","size":{"x":32,"y":1,"z":32}},{"blockCount":228,"bytes":5188,"file":"chunks/y117-z064-x128.json","offset":{"x":128,"y":117,"z":64},"requirements":{"minecraft:bricks":33,"minecraft:oak_planks":5,"minecraft:polished_diorite":134,"minecraft:sandstone":6,"minecraft:stone_bricks":50},"sha256":"ebb8f67128f8787d44e4474162084bc86c00e089ed89d4a58896506b2dad99a6","size":{"x":32,"y":1,"z":32}},{"blockCount":5,"bytes":800,"file":"chunks/y117-z064-x160.json","offset":{"x":160,"y":117,"z":64},"requirements":{"minecraft:stone_bricks":5},"sha256":"c088e8111c1f0954d625e25e557add08a67f8b1f3a16562a596284bd24a376c3","size":{"x":32,"y":1,"z":32}},{"blockCount":31,"bytes":1210,"file":"chunks/y117-z064-x192.json","offset":{"x":192,"y":117,"z":64},"requirements":{"minecraft:polished_diorite":18,"minecraft:stone_bricks":13},"sha256":"70f89ac072f5912825804eecc03d80ab7d9ec48ccddbeb48460d8881f43f3b07","size":{"x":32,"y":1,"z":32}},{"blockCount":37,"bytes":1268,"file":"chunks/y117-z064-x224.json","offset":{"x":224,"y":117,"z":64},"requirements":{"minecraft:polished_diorite":21,"minecraft:stone_bricks":16},"sha256":"522d4534c611166cee5bfa65607576da38cb71d67e4da590b0eecc4babb6b6bb","size":{"x":32,"y":1,"z":32}},{"blockCount":39,"bytes":1676,"file":"chunks/y117-z096-x000.json","offset":{"x":0,"y":117,"z":96},"requirements":{"minecraft:polished_diorite":22,"minecraft:stone_bricks":17},"sha256":"bdadedaac11fe1835e58564416b969784cf9a92bd84892456e98ae0725de7641","size":{"x":32,"y":1,"z":32}},{"blockCount":198,"bytes":4892,"file":"chunks/y117-z096-x032.json","offset":{"x":32,"y":117,"z":96},"requirements":{"minecraft:bricks":27,"minecraft:polished_diorite":118,"minecraft:sandstone":7,"minecraft:stone_bricks":46},"sha256":"705ee8d091225ba509f7c083adf58e9e3905fdeb9ba44401fe686ef38ca1fcff","size":{"x":32,"y":1,"z":32}},{"blockCount":189,"bytes":4297,"file":"chunks/y117-z096-x064.json","offset":{"x":64,"y":117,"z":96},"requirements":{"minecraft:bricks":28,"minecraft:polished_diorite":112,"minecraft:sandstone":5,"minecraft:stone_bricks":44},"sha256":"4aa69eb3652f4a5d32ac7c10cef2525e2298f71a224994bb05b86356a321a3b2","size":{"x":32,"y":1,"z":32}},{"blockCount":124,"bytes":3581,"file":"chunks/y117-z096-x096.json","offset":{"x":96,"y":117,"z":96},"requirements":{"minecraft:bricks":41,"minecraft:polished_diorite":64,"minecraft:sandstone":5,"minecraft:stone_bricks":14},"sha256":"b6db58483df3a70ab386e113e0d7b81d7560a41b500f31bb33ab0ba4fa9157a5","size":{"x":32,"y":1,"z":32}},{"blockCount":205,"bytes":4990,"file":"chunks/y117-z096-x128.json","offset":{"x":128,"y":117,"z":96},"requirements":{"minecraft:bricks":60,"minecraft:polished_diorite":106,"minecraft:sandstone":7,"minecraft:stone_bricks":32},"sha256":"8b781c8aeaed1072a918a7b2998f8734a2296e238b7d177e6be04fb5b7931bd7","size":{"x":32,"y":1,"z":32}},{"blockCount":209,"bytes":4679,"file":"chunks/y117-z096-x160.json","offset":{"x":160,"y":117,"z":96},"requirements":{"minecraft:bricks":27,"minecraft:polished_diorite":129,"minecraft:sandstone":5,"minecraft:stone_bricks":48},"sha256":"650f2650645627f0c6550f4c6413b5a4da3c692b72cf94b38b4952f6bb6086f9","size":{"x":32,"y":1,"z":32}},{"blockCount":370,"bytes":6496,"file":"chunks/y117-z096-x192.json","offset":{"x":192,"y":117,"z":96},"requirements":{"minecraft:bricks":159,"minecraft:oak_planks":24,"minecraft:polished_diorite":125,"minecraft:sandstone":4,"minecraft:stone_bricks":58},"sha256":"efe36dbe6dda2ad9163a3855938f6f40395ca77597ed423085d6c31734d3867a","size":{"x":32,"y":1,"z":32}},{"blockCount":262,"bytes":5392,"file":"chunks/y117-z096-x224.json","offset":{"x":224,"y":117,"z":96},"requirements":{"minecraft:bricks":118,"minecraft:oak_planks":47,"minecraft:polished_diorite":60,"minecraft:sandstone":1,"minecraft:spruce_planks":1,"minecraft:stone_bricks":35},"sha256":"ffae5669b69a2fee716a3fb978635b5cf7b0015ddc7f38f41a224df1c9548fdc","size":{"x":32,"y":1,"z":32}},{"blockCount":62,"bytes":2227,"file":"chunks/y117-z128-x000.json","offset":{"x":0,"y":117,"z":128},"requirements":{"minecraft:polished_diorite":43,"minecraft:stone_bricks":19},"sha256":"e698f212b4d1d2e219c985ef99928e3c8eed0458dae99be03ba9add75a198d32","size":{"x":32,"y":1,"z":32}},{"blockCount":170,"bytes":4154,"file":"chunks/y117-z128-x032.json","offset":{"x":32,"y":117,"z":128},"requirements":{"minecraft:bricks":44,"minecraft:glass":11,"minecraft:polished_diorite":78,"minecraft:sandstone":15,"minecraft:stone_bricks":22},"sha256":"2eb61045ad3bd6949ea1cf414595a73ffceba55b01b980e727d64a904ee9c7be","size":{"x":32,"y":1,"z":32}},{"blockCount":66,"bytes":1749,"file":"chunks/y117-z128-x064.json","offset":{"x":64,"y":117,"z":128},"requirements":{"minecraft:bricks":29,"minecraft:polished_diorite":23,"minecraft:sandstone":5,"minecraft:stone_bricks":9},"sha256":"9e17ed9f5da54f0f8c1f169859319547d4099e85bfcf3c07a1d1675ec42ee999","size":{"x":32,"y":1,"z":32}},{"blockCount":22,"bytes":1277,"file":"chunks/y117-z128-x096.json","offset":{"x":96,"y":117,"z":128},"requirements":{"minecraft:bricks":15,"minecraft:polished_diorite":5,"minecraft:sandstone":1,"minecraft:stone_bricks":1},"sha256":"3347b5691f226c05e940c29b71bc9c88e8958e3a8e72dfd13bfb61b1ea67086d","size":{"x":32,"y":1,"z":32}}],"schema":1}
