{"entries":[{"blockCount":51,"bytes":1736,"file":"chunks/y117-z128-x128.json","offset":{"x":128,"y":117,"z":128},"requirements":{"minecraft:bricks":31,"minecraft:polished_diorite":13,"minecraft:sandstone":3,"minecraft:stone_bricks":4},"sha256":"56875f6792c4f79ca9d116aa23a073c4e0dceb6f8fd11eb0fa947e99d6202dc5","size":{"x":32,"y":1,"z":32}},{"blockCount":71,"bytes":1735,"file":"chunks/y117-z128-x160.json","offset":{"x":160,"y":117,"z":128},"requirements":{"minecraft:bricks":27,"minecraft:polished_diorite":29,"minecraft:sandstone":5,"minecraft:stone_bricks":10},"sha256":"28984c4f0db992e688cc91fde39fdfe66db51db40d1e8bd36e5f8448260dc3f6","size":{"x":32,"y":1,"z":32}},{"blockCount":70,"bytes":1676,"file":"chunks/y117-z128-x192.json","offset":{"x":192,"y":117,"z":128},"requirements":{"minecraft:bricks":30,"minecraft:polished_diorite":28,"minecraft:sandstone":4,"minecraft:stone_bricks":8},"sha256":"68aadd326b667a20ecdfa278cae3bffa37f17b6b3ea4b8a77ab29c76b466359d","size":{"x":32,"y":1,"z":32}},{"blockCount":159,"bytes":3514,"file":"chunks/y117-z128-x224.json","offset":{"x":224,"y":117,"z":128},"requirements":{"minecraft:bricks":48,"minecraft:oak_planks":15,"minecraft:polished_diorite":70,"minecraft:sandstone":5,"minecraft:stone_bricks":21},"sha256":"3143fc7b2c6255e7e961d2ce09b72f40883093db82f38b98c0e48e30c0120474","size":{"x":32,"y":1,"z":32}},{"blockCount":23,"bytes":1254,"file":"chunks/y117-z160-x000.json","offset":{"x":0,"y":117,"z":160},"requirements":{"minecraft:polished_diorite":13,"minecraft:stone_bricks":10},"sha256":"b8232152a0ebf816279466b1d2446b96d338f969345ae62fe67cf57043cd0df6","size":{"x":32,"y":1,"z":32}},{"blockCount":125,"bytes":3340,"file":"chunks/y117-z160-x032.json","offset":{"x":32,"y":117,"z":160},"requirements":{"minecraft:polished_diorite":93,"minecraft:stone_bricks":32},"sha256":"c5e93ea8ad247fb32bcfb9d592a7112a82fd4fbcc2682ec7c0f87171d664093f","size":{"x":32,"y":1,"z":32}},{"blockCount":135,"bytes":3396,"file":"chunks/y117-z160-x064.json","offset":{"x":64,"y":117,"z":160},"requirements":{"minecraft:polished_diorite":95,"minecraft:stone_bricks":40},"sha256":"23cabb83f48c5136689e31d70e49d9cef18d61d3d3e08934c7f7a35202fcf497","size":{"x":32,"y":1,"z":32}},{"blockCount":130,"bytes":3620,"file":"chunks/y117-z160-x096.json","offset":{"x":96,"y":117,"z":160},"requirements":{"minecraft:bricks":31,"minecraft:polished_diorite":76,"minecraft:sandstone":5,"minecraft:stone_bricks":18},"sha256":"898928ac0254044aa0d60e64bb9f17c771a32598f811c907ad53944602f665e6","size":{"x":32,"y":1,"z":32}},{"blockCount":193,"bytes":4764,"file":"chunks/y117-z160-x128.json","offset":{"x":128,"y":117,"z":160},"requirements":{"minecraft:bricks":32,"minecraft:polished_diorite":119,"minecraft:sandstone":5,"minecraft:stone_bricks":37},"sha256":"41277affd443e62d45ede9bf92d3cca327af64b9a19d38b51637e0d0252fb30c","size":{"x":32,"y":1,"z":32}},{"blockCount":139,"bytes":3605,"file":"chunks/y117-z160-x160.json","offset":{"x":160,"y":117,"z":160},"requirements":{"minecraft:polished_diorite":100,"minecraft:stone_bricks":39},"sha256":"89cb06e9494a756f78280f4a5c93c7f432ec6d0233a9060fceae222c8732c5b1","size":{"x":32,"y":1,"z":32}},{"blockCount":331,"bytes":6018,"file":"chunks/y117-z160-x192.json","offset":{"x":192,"y":117,"z":160},"requirements":{"minecraft:bricks":129,"minecraft:oak_planks":24,"minecraft:polished_diorite":115,"minecraft:stone_bricks":63},"sha256":"107fbd8934abca12e132b74eab75d0fa84783e135908182cde2e6d55219dd9be","size":{"x":32,"y":1,"z":32}},{"blockCount":245,"bytes":5215,"file":"chunks/y117-z160-x224.json","offset":{"x":224,"y":117,"z":160},"requirements":{"minecraft:bricks":105,"minecraft:oak_planks":47,"minecraft:polished_diorite":55,"minecraft:spruce_planks":1,"minecraft:stone_bricks":37},"sha256":"51ee3a4092e1a662a44ba109e1e980d2f68110013b3650776f45d78e5bdf43f5","size":{"x":32,"y":1,"z":32}},{"blockCount":58,"bytes":2173,"file":"chunks/y117-z192-x064.json","offset":{"x":64,"y":117,"z":192},"requirements":{"minecraft:polished_diorite":38,"minecraft:stone_bricks":20},"sha256":"ae1f9340d5db3295ef9d8c5963be395e5cf7149669b9fec5f0b6b27cf6748fef","size":{"x":32,"y":1,"z":32}},{"blockCount":205,"bytes":3675,"file":"chunks/y117-z192-x096.json","offset":{"x":96,"y":117,"z":192},"requirements":{"minecraft:bricks":52,"minecraft:oak_planks":12,"minecraft:polished_diorite":101,"minecraft:sandstone":7,"minecraft:stone_bricks":33},"sha256":"c6298588e73779f8671b7d80d44886f67ad3b44ef8d1112b2867bc3c1fa33a6f","size":{"x":32,"y":1,"z":32}},{"blockCount":190,"bytes":4347,"file":"chunks/y117-z192-x128.json","offset":{"x":128,"y":117,"z":192},"requirements":{"minecraft:bricks":27,"minecraft:oak_planks":5,"minecraft:polished_diorite":112,"minecraft:sandstone":5,"minecraft:stone_bricks":41},"sha256":"269db84e14469d7a80a211adca81002e1b99e0621b1765c965b6a944710ecedf","size":{"x":32,"y":1,"z":32}},{"blockCount":4,"bytes":763,"file":"chunks/y117-z192-x160.json","offset":{"x":160,"y":117,"z":192},"requirements":{"minecraft:stone_bricks":4},"sha256":"1cc679852ba08f29b7ef2dbb0f9e003e3b41f97d400d2509dfd3ab6351ec8c1e","size":{"x":32,"y":1,"z":32}},{"blockCount":108,"bytes":2287,"file":"chunks/y118-z064-x064.json","offset":{"x":64,"y":118,"z":64},"requirements":{"minecraft:polished_diorite":57,"minecraft:stone_bricks":51},"sha256":"3811c6d2505305fb806032568edbd1515ac843690ce107c4e617cfe3e8a7983c","size":{"x":32,"y":1,"z":32}},{"blockCount":255,"bytes":4366,"file":"chunks/y118-z064-x096.json","offset":{"x":96,"y":118,"z":64},"requirements":{"minecraft:bricks":58,"minecraft:oak_planks":5,"minecraft:polished_diorite":120,"minecraft:sandstone":16,"minecraft:stone_bricks":56},"sha256":"bf872d50a36d0e50ccf3a55feddfc8040bbcf75a66638e31e0de2b0a6a8e8e45","size":{"x":32,"y":1,"z":32}},{"blockCount":285,"bytes":4876,"file":"chunks/y118-z064-x128.json","offset":{"x":128,"y":118,"z":64},"requirements":{"minecraft:bricks":32,"minecraft:oak_planks":2,"minecraft:polished_diorite":152,"minecraft:sandstone":10,"minecraft:stone_bricks":89},"sha256":"4e585cf6d7934ad5d904be401b61e4b1c1ccc54c2f1976f7b6c78df13fb2ae7a","size":{"x":32,"y":1,"z":32}},{"blockCount":7,"bytes":878,"file":"chunks/y118-z064-x160.json","offset":{"x":160,"y":118,"z":64},"requirements":{"minecraft:stone_bricks":7},"sha256":"1b79178f9b8bf15a41d57e2544cfdb88f61586b29275471a02e8913ef308aa8d","size":{"x":32,"y":1,"z":32}},{"blockCount":47,"bytes":1078,"file":"chunks/y118-z064-x192.json","offset":{"x":192,"y":118,"z":64},"requirements":{"minecraft:polished_diorite":21,"minecraft:stone_bricks":26},"sha256":"c3ae45201dfd06282475df669e7c8852910d47d167ea82e6ebf345a212581297","size":{"x":32,"y":1,"z":32}},{"blockCount":60,"bytes":1118,"file":"chunks/y118-z064-x224.json","offset":{"x":224,"y":118,"z":64},"requirements":{"minecraft:polished_diorite":28,"minecraft:stone_bricks":32},"sha256":"72e7bdf6842e4db6fa3fa7f151cd89cc3b62b900ca90a74e7e1df83e24e5590d","size":{"x":32,"y":1,"z":32}},{"blockCount":62,"bytes":1563,"file":"chunks/y118-z096-x000.json","offset":{"x":0,"y":118,"z":96},"requirements":{"minecraft:polished_diorite":32,"minecraft:stone_bricks":30},"sha256":"9ea04f784454ba77a7789dd56ec10ceff7271c6b585ba01f2eddfa85474b0a54","size":{"x":32,"y":1,"z":32}},{"blockCount":242,"bytes":4199,"file":"chunks/y118-z096-x032.json","offset":{"x":32,"y":118,"z":96},"requirements":{"minecraft:bricks":27,"minecraft:polished_diorite":134,"minecraft:sandstone":5,"minecraft:stone_bricks":76},"sha256":"fba306d4c272f73381da38b063cc7000533394605f8207f4f48d9a824fe6d29c","size":{"x":32,"y":1,"z":32}},{"blockCount":235,"bytes":4394,"file":"chunks/y118-z096-x064.json","offset":{"x":64,"y":118,"z":96},"requirements":{"minecraft:bricks":22,"minecraft:polished_diorite":129,"minecraft:sandstone":7,"minecraft:stone_bricks":77},"sha256":"07bde5c0f815eb720fed4452c57e9024625900bbb4eaa3f0bc66f035b328a328","size":{"x":32,"y":1,"z":32}},{"blockCount":141,"bytes":3809,"file":"chunks/y118-z096-x096.json","offset":{"x":96,"y":118,"z":96},"requirements":{"minecraft:bricks":37,"minecraft:polished_diorite":75,"minecraft:sandstone":9,"minecraft:stone_bricks":20},"sha256":"2c7b464730d455847896a80d633fb8382060c9b5df49c888ff80f281696e150e","size":{"x":32,"y":1,"z":32}},{"blockCount":240,"bytes":5292,"file":"chunks/y118-z096-x128.json","offset":{"x":128,"y":118,"z":96},"requirements":{"minecraft:bricks":51,"minecraft:polished_diorite":126,"minecraft:sandstone":13,"minecraft:stone_bricks":50},"sha256":"9743ea4708cb38f6f43a029c2d7ca39b8f29854aaafdf8288dc65e5b7bf0d34d","size":{"x":32,"y":1,"z":32}},{"blockCount":259,"bytes":4483,"file":"chunks/y118-z096-x160.json","offset":{"x":160,"y":118,"z":96},"requirements":{"minecraft:bricks":22,"minecraft:polished_diorite":148,"minecraft:sandstone":6,"minecraft:stone_bricks":83},"sha256":"e64280fa2ddaecfbb92c42a32c19ac9d7223b2416e3ced4c1c839b29998ddad9","size":{"x":32,"y":1,"z":32}},{"blockCount":424,"bytes":5602,"file":"chunks/y118-z096-x192.json","offset":{"x":192,"y":118,"z":96},"requirements":{"minecraft:bricks":159,"minecraft:oak_planks":2,"minecraft:polished_diorite":157,"minecraft:sandstone":7,"minecraft:stone_bricks":99},"sha256":"407bca1d28415876fd815b847c2ebde423e974e28315a9091e00b9fca311d63b","size":{"x":32,"y":1,"z":32}},{"blockCount":296,"bytes":5010,"file":"chunks/y118-z096-x224.json","offset":{"x":224,"y":118,"z":96},"requirements":{"minecraft:bricks":103,"minecraft:oak_planks":6,"minecraft:polished_diorite":116,"minecraft:sandstone":1,"minecraft:stone_bricks":70},"sha256":"efa9360b4f2770ad25d25eb0b4b9972b1b6cc8ce87254a2689178490ed801aec","size":{"x":32,"y":1,"z":32}},{"blockCount":86,"bytes":1963,"file":"chunks/y118-z128-x000.json","offset":{"x":0,"y":118,"z":128},"requirements":{"minecraft:polished_diorite":45,"minecraft:stone_bricks":41},"sha256":"8626b45619b2eb1c886fa92938ee7586df2026484443b414302d2c6e4ae7627f","size":{"x":32,"y":1,"z":32}},{"blockCount":166,"bytes":4095,"file":"chunks/y118-z128-x032.json","offset":{"x":32,"y":118,"z":128},"requirements":{"minecraft:bricks":47,"minecraft:glass":9,"minecraft:polished_diorite":78,"minecraft:sandstone":13,"minecraft:stone_bricks":19},"sha256":"66b4e33d3a74bc3d030c571c322b2db33faab0d7f949a5415e51d3b863d4c258","size":{"x":32,"y":1,"z":32}},{"blockCount":82,"bytes":2210,"file":"chunks/y118-z128-x064.json","offset":{"x":64,"y":118,"z":128},"requirements":{"minecraft:bricks":32,"minecraft:polished_diorite":29,"minecraft:sandstone":7,"minecraft:stone_bricks":14},"sha256":"ee35cc2fcd32b998860c71e7582b60d2f70913094e5937729e820b4c995592e0","size":{"x":32,"y":1,"z":32}},{"blockCount":30,"bytes":1430,"file":"chunks/y118-z128-x096.json","offset":{"x":96,"y":118,"z":128},"requirements":{"minecraft:bricks":18,"minecraft:polished_diorite":7,"minecraft:sandstone":3,"minecraft:stone_bricks":2},"sha256":"8fd5597b1daaf361457b589549bc3557d37f2bf69c4d086cc15a89007f2c1756","size":{"x":32,"y":1,"z":32}},{"blockCount":68,"bytes":2174,"file":"chunks/y118-z128-x128.json","offset":{"x":128,"y":118,"z":128},"requirements":{"minecraft:bricks":35,"minecraft:polished_diorite":19,"minecraft:sandstone":7,"minecraft:stone_bricks":7},"sha256":"9d53a442060a3673649ba628520d97955ed22cacff772e748ddc380c37b9fe8b","size":{"x":32,"y":1,"z":32}},{"blockCount":86,"bytes":2156,"file":"chunks/y118-z128-x160.json","offset":{"x":160,"y":118,"z":128},"requirements":{"minecraft:bricks":32,"minecraft:polished_diorite":33,"minecraft:sandstone":6,"minecraft:stone_bricks":15},"sha256":"ff1a09df3384862d894f2b7077507094c9ee57a728afa778012c0c5fa8444b4b","size":{"x":32,"y":1,"z":32}},{"blockCount":86,"bytes":2079,"file":"chunks/y118-z128-x192.json","offset":{"x":192,"y":118,"z":128},"requirements":{"minecraft:bricks":33,"minecraft:polished_diorite":33,"minecraft:sandstone":7,"minecraft:stone_bricks":13},"sha256":"2bf2508b38533e569cdf8f87601715ed53ffaff1bf022e1748aac771ff83a7dd","size":{"x":32,"y":1,"z":32}},{"blockCount":181,"bytes":3553,"file":"chunks/y118-z128-x224.json","offset":{"x":224,"y":118,"z":128},"requirements":{"minecraft:bricks":49,"minecraft:oak_planks":5,"minecraft:polished_diorite":72,"minecraft:sandstone":15,"minecraft:stone_bricks":40},"sha256":"eae15a0972032b401d0b1102078f5b83e659f75dffd79d325abb5b79f9f91ba4","size":{"x":32,"y":1,"z":32}},{"blockCount":40,"bytes":1217,"file":"chunks/y118-z160-x000.json","offset":{"x":0,"y":118,"z":160},"requirements":{"minecraft:polished_diorite":21,"minecraft:stone_bricks":19},"sha256":"919225aaeca6328d445650f6010d14e8769416cc33859d911de21c0df51b42f9","size":{"x":32,"y":1,"z":32}},{"blockCount":166,"bytes":2822,"file":"chunks/y118-z160-x032.json","offset":{"x":32,"y":118,"z":160},"requirements":{"minecraft:polished_diorite":103,"minecraft:stone_bricks":63},"sha256":"bd75687f609587b22e9939a94ba2a33ae6f576fbdc93ccb6b2d406ac4e5b5441","size":{"x":32,"y":1,"z":32}},{"blockCount":180,"bytes":3415,"file":"chunks/y118-z160-x064.json","offset":{"x":64,"y":118,"z":160},"requirements":{"minecraft:polished_diorite":108,"minecraft:stone_bricks":72},"sha256":"8bcb8f5dedc676d304501fdff9557a9db5fc32102a26e521126271aa8ac1ea36","size":{"x":32,"y":1,"z":32}},{"blockCount":144,"bytes":3810,"file":"chunks/y118-z160-x096.json","offset":{"x":96,"y":118,"z":160},"requirements":{"minecraft:bricks":27,"minecraft:polished_diorite":86,"minecraft:sandstone":7,"minecraft:stone_bricks":24},"sha256":"22ca1bfb291ce3ee7a01a3551395b55b12faeb0089058b9e939eb974b8a66064","size":{"x":32,"y":1,"z":32}},{"blockCount":228,"bytes":4798,"file":"chunks/y118-z160-x128.json","offset":{"x":128,"y":118,"z":160},"requirements":{"minecraft:bricks":27,"minecraft:polished_diorite":137,"minecraft:sandstone":7,"minecraft:stone_bricks":57},"sha256":"946772846cfa24b0b707bb374ebe3e310f7f4c2710587a8dcf289a7ae66083bd","size":{"x":32,"y":1,"z":32}},{"blockCount":184,"bytes":3388,"file":"chunks/y118-z160-x160.json","offset":{"x":160,"y":118,"z":160},"requirements":{"minecraft:polished_diorite":115,"minecraft:stone_bricks":69},"sha256":"0c6b92b93c5074b438dc63cd318cbe387d2b06944e7d7d6840afd0fc514b7cb4","size":{"x":32,"y":1,"z":32}},{"blockCount":393,"bytes":4949,"file":"chunks/y118-z160-x192.json","offset":{"x":192,"y":118,"z":160},"requirements":{"minecraft:bricks":134,"minecraft:oak_planks":2,"minecraft:polished_diorite":145,"minecraft:stone_bricks":112},"sha256":"e5c14f1f15f7b790738c9ded4e62c57e84f2857ad6a56bbd2d37a103f091ca42","size":{"x":32,"y":1,"z":32}},{"blockCount":289,"bytes":4585,"file":"chunks/y118-z160-x224.json","offset":{"x":224,"y":118,"z":160},"requirements":{"minecraft:bricks":92,"minecraft:oak_planks":6,"minecraft:polished_diorite":118,"minecraft:stone_bricks":73},"sha256":"2d3981417738af0de1b840b18b9b0a2ce24c15dfa316c27aec2aebe33029ae37","size":{"x":32,"y":1,"z":32}},{"blockCount":90,"bytes":2021,"file":"chunks/y118-z192-x064.json","offset":{"x":64,"y":118,"z":192},"requirements":{"minecraft:polished_diorite":48,"minecraft:stone_bricks":42},"sha256":"7fd182a5922f9525f8a2441c3965d55eb35438e52e1c2e8f0f0818e2319d6160","size":{"x":32,"y":1,"z":32}},{"blockCount":224,"bytes":3696,"file":"chunks/y118-z192-x096.json","offset":{"x":96,"y":118,"z":192},"requirements":{"minecraft:bricks":52,"minecraft:oak_planks":5,"minecraft:polished_diorite":102,"minecraft:sandstone":15,"minecraft:stone_bricks":50},"sha256":"d1f18b5b266d87edb03da4fc88cec840d03ce812d02c0f0a2bac0332432ef6d5","size":{"x":32,"y":1,"z":32}},{"blockCount":237,"bytes":4132,"file":"chunks/y118-z192-x128.json","offset":{"x":128,"y":118,"z":192},"requirements":{"minecraft:bricks":26,"minecraft:oak_planks":2,"minecraft:polished_diorite":125,"minecraft:sandstone":9,"minecraft:stone_bricks":75},"sha256":"3f9440585eba9a11c58aff3909ac28fdb734300610b6d27563a28f7f197a5044","size":{"x":32,"y":1,"z":32}},{"blockCount":6,"bytes":841,"file":"chunks/y118-z192-x160.json","offset":{"x":160,"y":118,"z":192},"requirements":{"minecraft:stone_bricks":6},"sha256":"299d9839406e713abd23b596d315596ea808da82cd6f3310d792d50feb8dbf9a","size":{"x":32,"y":1,"z":32}},{"blockCount":63,"bytes":2362,"file":"chunks/y119-z064-x064.json","offset":{"x":64,"y":119,"z":64},"requirements":{"minecraft:polished_diorite":54,"minecraft:stone_bricks":9},"sha256":"dda02223e352867436fa8d85deb77ce63f58842fd6f8f6e080765334d9123c69","size":{"x":32,"y":1,"z":32}},{"blockCount":219,"bytes":3872,"file":"chunks/y119-z064-x096.json","offset":{"x":96,"y":119,"z":64},"requirements":{"minecraft:bricks":51,"minecraft:oak_planks":10,"minecraft:polished_diorite":95,"minecraft:sandstone":11,"minecraft:stone_bricks":52},"sha256":"1cd16e2709186b47cc2fe39ab3868ce86b6bbcecfbb150145d204502eb6fb4c9","size":{"x":32,"y":1,"z":32}},{"blockCount":218,"bytes":4842,"file":"chunks/y119-z064-x128.json","offset":{"x":128,"y":119,"z":64},"requirements":{"minecraft:bricks":29,"minecraft:oak_planks":6,"minecraft:polished_diorite":124,"minecraft:sandstone":5,"minecraft:stone_bricks":54},"sha256":"1d02d0d2d4ee156dfd115802b82f61aa22d8d7bc49c13b479a86418902039df5","size":{"x":32,"y":1,"z":32}},{"blockCount":7,"bytes":882,"file":"chunks/y119-z064-x160.json","offset":{"x":160,"y":119,"z":64},"requirements":{"minecraft:polished_diorite":7},"sha256":"2c9cc53c352d1d961142747c48d46ca4930efb11f48c85908dd96fa8d91b3bd9","size":{"x":32,"y":1,"z":32}},{"blockCount":31,"bytes":1288,"file":"chunks/y119-z064-x192.json","offset":{"x":192,"y":119,"z":64},"requirements":{"minecraft:glass":9,"minecraft:polished_diorite":12,"minecraft:stone_bricks":10},"sha256":"572f79166726594e7cca06b8cc726de85e2f8e39cefcc4f8ba06692ce930dfcc","size":{"x":32,"y":1,"z":32}},{"blockCount":46,"bytes":1768,"file":"chunks/y119-z064-x224.json","offset":{"x":224,"y":119,"z":64},"requirements":{"minecraft:glass":9,"minecraft:polished_diorite":18,"minecraft:stone_bricks":19},"sha256":"bad156525500ff9bb9893f7c6d2d7f670828717032fe9191102b7bec0cc24788","size":{"x":32,"y":1,"z":32}},{"blockCount":39,"bytes":1808,"file":"chunks/y119-z096-x000.json","offset":{"x":0,"y":119,"z":96},"requirements":{"minecraft:polished_diorite":32,"minecraft:stone_bricks":7},"sha256":"a0bb1a0db4f31f51fed3a0fd25e8ee220ecb403f425d73af4c38de378d92e9d5","size":{"x":32,"y":1,"z":32}},{"blockCount":184,"bytes":4923,"file":"chunks/y119-z096-x032.json","offset":{"x":32,"y":119,"z":96},"requirements":{"minecraft:bricks":29,"minecraft:polished_diorite":107,"minecraft:sandstone":5,"minecraft:stone_bricks":43},"sha256":"d809357cab8f4585ef42df3fc85d6b2c0649c1d9d3982b679787e313642bc0f8","size":{"x":32,"y":1,"z":32}},{"blockCount":185,"bytes":4181,"file":"chunks/y119-z096-x064.json","offset":{"x":64,"y":119,"z":96},"requirements":{"minecraft:bricks":17,"minecraft:polished_diorite":116,"minecraft:sandstone":5,"minecraft:stone_bricks":47},"sha256":"fe51cd14a08ef690b0c1e92867be1be11c4a49228c3a68143e9b39d06de8cf0a","size":{"x":32,"y":1,"z":32}},{"blockCount":133,"bytes":3656,"file":"chunks/y119-z096-x096.json","offset":{"x":96,"y":119,"z":96},"requirements":{"minecraft:bricks":31,"minecraft:polished_diorite":68,"minecraft:sandstone":5,"minecraft:stone_bricks":29},"sha256":"7a5ec89adf65e07eb5c96cba1bae4fa8fa5f94a55dcb7e0372c8baf043f71f83","size":{"x":32,"y":1,"z":32}},{"blockCount":211,"bytes":5043,"file":"chunks/y119-z096-x128.json","offset":{"x":128,"y":119,"z":96},"requirements":{"minecraft:bricks":42,"minecraft:polished_diorite":113,"minecraft:sandstone":8,"minecraft:stone_bricks":48},"sha256":"47016682c3277d02971d045a3979ba52909bd2b0cb70a38dc08f3f1f084f8f24","size":{"x":32,"y":1,"z":32}},{"blockCount":203,"bytes":4637,"file":"chunks/y119-z096-x160.json","offset":{"x":160,"y":119,"z":96},"requirements":{"minecraft:bricks":18,"minecraft:polished_diorite":131,"minecraft:sandstone":4,"minecraft:stone_bricks":50},"sha256":"f0f882994da52f3ceffc134b48feedbd0093602d3c8fe27ab013503e66fc3ff7","size":{"x":32,"y":1,"z":32}},{"blockCount":360,"bytes":6211,"file":"chunks/y119-z096-x192.json","offset":{"x":192,"y":119,"z":96},"requirements":{"minecraft:bricks":112,"minecraft:glass":12,"minecraft:oak_planks":2,"minecraft:polished_diorite":163,"minecraft:sandstone":4,"minecraft:stone_bricks":67},"sha256":"1fa6b68f06356733d056908a9008efb4728ed34546f7841c04ba807ca06323eb","size":{"x":32,"y":1,"z":32}},{"blockCount":265,"bytes":4875,"file":"chunks/y119-z096-x224.json","offset":{"x":224,"y":119,"z":96},"requirements":{"minecraft:bricks":68,"minecraft:glass":19,"minecraft:oak_planks":6,"minecraft:polished_diorite":127,"minecraft:sandstone":1,"minecraft:stone_bricks":44},"sha256":"b8beb7eee30ab721bb62346eb38a78cb677952f6b17acb115b8c8d7a214195ca","size":{"x":32,"y":1,"z":32}},{"blockCount":58,"bytes":2245,"file":"chunks/y119-z128-x000.json","offset":{"x":0,"y":119,"z":128},"requirements":{"minecraft:polished_diorite":43,"minecraft:stone_bricks":15},"sha256":"ed388daa83a7fe76946a433ebbb6599d30831b040ef83bd0f9506df8b3cbda02","size":{"x":32,"y":1,"z":32}},{"blockCount":180,"bytes":4284,"file":"chunks/y119-z128-x032.json","offset":{"x":32,"y":119,"z":128},"requirements":{"minecraft:bricks":56,"minecraft:glass":5,"minecraft:polished_diorite":76,"minecraft:sandstone":16,"minecraft:stone_bricks":27},"sha256":"62b0688f5553d1bbc8c225d07d76dc6451e43e72c05c576db976e4c49beb0627","size":{"x":32,"y":1,"z":32}},{"blockCount":85,"bytes":2075,"file":"chunks/y119-z128-x064.json","offset":{"x":64,"y":119,"z":128},"requirements":{"minecraft:bricks":27,"minecraft:polished_diorite":34,"minecraft:sandstone":5,"minecraft:stone_bricks":19},"sha256":"fcdc5acd54be572e949a2f4882071ff78efa52c07677e9c7368a473b4441420a","size":{"x":32,"y":1,"z":32}},{"blockCount":28,"bytes":1391,"file":"chunks/y119-z128-x096.json","offset":{"x":96,"y":119,"z":128},"requirements":{"minecraft:bricks":16,"minecraft:polished_diorite":8,"minecraft:sandstone":1,"minecraft:stone_bricks":3},"sha256":"b8a989626b61b6a9004a472fecc9dd5b27518df5a754645448774c8d37b8268d","size":{"x":32,"y":1,"z":32}},{"blockCount":67,"bytes":2134,"file":"chunks/y119-z128-x128.json","offset":{"x":128,"y":119,"z":128},"requirements":{"minecraft:bricks":29,"minecraft:polished_diorite":23,"minecraft:sandstone":4,"minecraft:stone_bricks":11},"sha256":"d4a54d44b19c582b3b08530e9d5039f88b8245232756b3d70ef830ac1aa7786a","size":{"x":32,"y":1,"z":32}},{"blockCount":88,"bytes":2078,"file":"chunks/y119-z128-x160.json","offset":{"x":160,"y":119,"z":128},"requirements":{"minecraft:bricks":28,"minecraft:polished_diorite":37,"minecraft:sandstone":4,"minecraft:stone_bricks":19},"sha256":"24593bf0912ce2b419232e9c0e99199e20b47f012e17c9061fbd32487360ef19","size":{"x":32,"y":1,"z":32}},{"blockCount":89,"bytes":1983,"file":"chunks/y119-z128-x192.json","offset":{"x":192,"y":119,"z":128},"requirements":{"minecraft:bricks":29,"minecraft:polished_diorite":36,"minecraft:sandstone":4,"minecraft:stone_bricks":20},"sha256":"fb271d105d86d4b2937199b83f9be58e52410797ff40c6878f18b0bef7febe72","size":{"x":32,"y":1,"z":32}},{"blockCount":163,"bytes":3800,"file":"chunks/y119-z128-x224.json","offset":{"x":224,"y":119,"z":128},"requirements":{"minecraft:bricks":45,"minecraft:glass":7,"minecraft:oak_planks":14,"minecraft:polished_diorite":67,"minecraft:sandstone":7,"minecraft:stone_bricks":23},"sha256":"bbed8866000c911e437b0c8f38da8fda5a309999c8d65457df65abd013cc6e42","size":{"x":32,"y":1,"z":32}},{"blockCount":27,"bytes":1444,"file":"chunks/y119-z160-x000.json","offset":{"x":0,"y":119,"z":160},"requirements":{"minecraft:polished_diorite":23,"minecraft:stone_bricks":4},"sha256":"a484ed9a1f0c975e4da078090448584065523df1f24f6d7720392bc5fb92cf2c","size":{"x":32,"y":1,"z":32}},{"blockCount":112,"bytes":3394,"file":"chunks/y119-z160-x032.json","offset":{"x":32,"y":119,"z":160},"requirements":{"minecraft:polished_diorite":82,"minecraft:stone_bricks":30},"sha256":"40144f031a62d3ac53e637386e08a5584d844874f37f2ba141713034c2b2a9e1","size":{"x":32,"y":1,"z":32}},{"blockCount":119,"bytes":3261,"file":"chunks/y119-z160-x064.json","offset":{"x":64,"y":119,"z":160},"requirements":{"minecraft:polished_diorite":91,"minecraft:stone_bricks":28},"sha256":"84bd01e65119d5cdd73211954a17d9faef6706ce260a05012cb6b2aab3621c44","size":{"x":32,"y":1,"z":32}},{"blockCount":137,"bytes":3601,"file":"chunks/y119-z160-x096.json","offset":{"x":96,"y":119,"z":160},"requirements":{"minecraft:bricks":22,"minecraft:polished_diorite":76,"minecraft:sandstone":5,"minecraft:stone_bricks":34},"sha256":"5673aad50be746e8d80999c018797b094000aea0644e3b79c3d7cfb68bd2ee88","size":{"x":32,"y":1,"z":32}},{"blockCount":188,"bytes":4592,"file":"chunks/y119-z160-x128.json","offset":{"x":128,"y":119,"z":160},"requirements":{"minecraft:bricks":22,"minecraft:polished_diorite":116,"minecraft:sandstone":5,"minecraft:stone_bricks":45},"sha256":"943b10ed0d8176b4d18b5a1122beb8fe3ced7c0bb150ae0e17c868ea31d1bef8","size":{"x":32,"y":1,"z":32}},{"blockCount":126,"bytes":3600,"file":"chunks/y119-z160-x160.json","offset":{"x":160,"y":119,"z":160},"requirements":{"minecraft:polished_diorite":95,"minecraft:stone_bricks":31},"sha256":"e0bf1bca8c8ab7864e2de783e6f45069f5dc64dc46df3d1f10a75ec366f0677a","size":{"x":32,"y":1,"z":32}},{"blockCount":310,"bytes":5823,"file":"chunks/y119-z160-x192.json","offset":{"x":192,"y":119,"z":160},"requirements":{"minecraft:bricks":91,"minecraft:glass":21,"minecraft:oak_planks":2,"minecraft:polished_diorite":139,"minecraft:stone_bricks":57},"sha256":"b3cfaa912c03015f247035e88f039106e44b54f8c649b8d2d7fc6d2e9b9a3198","size":{"x":32,"y":1,"z":32}},{"blockCount":252,"bytes":4930,"file":"chunks/y119-z160-x224.json","offset":{"x":224,"y":119,"z":160},"requirements":{"minecraft:bricks":58,"minecraft:glass":21,"minecraft:oak_planks":6,"minecraft:polished_diorite":117,"minecraft:stone_bricks":50},"sha256":"3995e47cb1e2ec24d6eddbac44777fcd0479c59bc94563656eaa892f8e489c00","size":{"x":32,"y":1,"z":32}},{"blockCount":54,"bytes":2096,"file":"chunks/y119-z192-x064.json","offset":{"x":64,"y":119,"z":192},"requirements":{"minecraft:polished_diorite":46,"minecraft:stone_bricks":8},"sha256":"c8fd1006e8c1ffa996268f73b6c5b504030d83111395fd1dc4f81407c4213ab9","size":{"x":32,"y":1,"z":32}},{"blockCount":189,"bytes":3315,"file":"chunks/y119-z192-x096.json","offset":{"x":96,"y":119,"z":192},"requirements":{"minecraft:bricks":46,"minecraft:oak_planks":10,"minecraft:polished_diorite":79,"minecraft:sandstone":10,"minecraft:stone_bricks":44},"sha256":"4e005b195435d754c87058785c436b39e8475c8ed2a97c5900b44d906046cc96","size":{"x":32,"y":1,"z":32}},{"blockCount":180,"bytes":4098,"file":"chunks/y119-z192-x128.json","offset":{"x":128,"y":119,"z":192},"requirements":{"minecraft:bricks":24,"minecraft:oak_planks":6,"minecraft:polished_diorite":101,"minecraft:sandstone":4,"minecraft:stone_bricks":45},"sha256":"f5bea6dc22b628af830070fa72ebbcbe5a75c2e1321d59e6de4fce20c84ec1dc","size":{"x":32,"y":1,"z":32}},{"blockCount":6,"bytes":845,"file":"chunks/y119-z192-x160.json","offset":{"x":160,"y":119,"z":192},"requirements":{"minecraft:polished_diorite":6},"sha256":"561533f177b6cda54fac6f5eaa3c180530cd811bbfd10bd99b80dd28b87e5110","size":{"x":32,"y":1,"z":32}},{"blockCount":39,"bytes":1984,"file":"chunks/y120-z064-x064.json","offset":{"x":64,"y":120,"z":64},"requirements":{"minecraft:polished_diorite":20,"minecraft:stone_bricks":19},"sha256":"5dab5f81ba16abfb28aa2d22633d51d547d90098a160b1ab6fe58568b59dfca9","size":{"x":32,"y":1,"z":32}},{"blockCount":222,"bytes":4041,"file":"chunks/y120-z064-x096.json","offset":{"x":96,"y":120,"z":64},"requirements":{"minecraft:bricks":50,"minecraft:oak_planks":6,"minecraft:polished_diorite":132,"minecraft:sandstone":12,"minecraft:stone_bricks":22},"sha256":"a6f361088d80c2091d521bc3cc710b55fe8dc9039c95333a974221691747f3ab","size":{"x":32,"y":1,"z":32}},{"blockCount":202,"bytes":4697,"file":"chunks/y120-z064-x128.json","offset":{"x":128,"y":120,"z":64},"requirements":{"minecraft:bricks":25,"minecraft:oak_planks":2,"minecraft:polished_diorite":133,"minecraft:sandstone":6,"minecraft:stone_bricks":36},"sha256":"cb6c7954aa39b8c79d6357d0d31371dece07de10a05deb1f6e47c579df8dbc13","size":{"x":32,"y":1,"z":32}},{"blockCount":2,"bytes":688,"file":"chunks/y120-z064-x160.json","offset":{"x":160,"y":120,"z":64},"requirements":{"minecraft:polished_diorite":2},"sha256":"3deb91c00f7e76d90fc7938b9c128664d10189bdd126102222f5f438e96c4df8","size":{"x":32,"y":1,"z":32}},{"blockCount":34,"bytes":1231,"file":"chunks/y120-z064-x192.json","offset":{"x":192,"y":120,"z":64},"requirements":{"minecraft:glass":9,"minecraft:polished_diorite":10,"minecraft:stone_bricks":15},"sha256":"c0bc55b3391cdd0910b30f47110fc9de3f3a6e9bb37cdd2e2162f07ea9303247","size":{"x":32,"y":1,"z":32}},{"blockCount":53,"bytes":1787,"file":"chunks/y120-z064-x224.json","offset":{"x":224,"y":120,"z":64},"requirements":{"minecraft:glass":9,"minecraft:polished_diorite":20,"minecraft:stone_bricks":24},"sha256":"e85aa41d80f2eba44acf1c0bd45d50d625ef4faefcbfe43d8a9cd6bb20097455","size":{"x":32,"y":1,"z":32}},{"blockCount":25,"bytes":1503,"file":"chunks/y120-z096-x000.json","offset":{"x":0,"y":120,"z":96},"requirements":{"minecraft:polished_diorite":14,"minecraft:stone_bricks":11},"sha256":"ffd84493545052d69fccd5575b509cd190967e9a09307314a7eaf8728896904a","size":{"x":32,"y":1,"z":32}},{"blockCount":168,"bytes":4185,"file":"chunks/y120-z096-x032.json","offset":{"x":32,"y":120,"z":96},"requirements":{"minecraft:bricks":29,"minecraft:polished_diorite":109,"minecraft:sandstone":2,"minecraft:stone_bricks":28},"sha256":"0307470ddd6615afe895010a86d70ecdc40010cfdc667784dcac528dea058816","size":{"x":32,"y":1,"z":32}},{"blockCount":174,"bytes":3344,"file":"chunks/y120-z096-x064.json","offset":{"x":64,"y":120,"z":96},"requirements":{"minecraft:bricks":16,"minecraft:polished_diorite":121,"minecraft:sandstone":2,"minecraft:stone_bricks":35},"sha256":"6e1f89201ab4bdce28ea2ec023ba105d67b5d9911411b05c09dae38569b9a88e","size":{"x":32,"y":1,"z":32}},{"blockCount":139,"bytes":3752,"file":"chunks/y120-z096-x096.json","offset":{"x":96,"y":120,"z":96},"requirements":{"minecraft:bricks":29,"minecraft:polished_diorite":88,"minecraft:sandstone":4,"minecraft:stone_bricks":18},"sha256":"1c8f7c3ce52efd78d35ca3b9b39f02002ca19b3fd63d65a14c912aa6e4847a49","size":{"x":32,"y":1,"z":32}},{"blockCount":215,"bytes":4837,"file":"chunks/y120-z096-x128.json","offset":{"x":128,"y":120,"z":96},"requirements":{"minecraft:bricks":38,"minecraft:polished_diorite":140,"minecraft:sandstone":5,"minecraft:stone_bricks":32},"sha256":"8f99c03ca60044f9868820127aaa990d967e69ea87324c0d6887439e4f15c845","size":{"x":32,"y":1,"z":32}},{"blockCount":184,"bytes":3628,"file":"chunks/y120-z096-x160.json","offset":{"x":160,"y":120,"z":96},"requirements":{"minecraft:bricks":16,"minecraft:polished_diorite":128,"minecraft:sandstone":2,"minecraft:stone_bricks":38},"sha256":"985f9ed61535f90d2c3925830ea5a7ed433204cfa50d464933e1dd4e4ea87890","size":{"x":32,"y":1,"z":32}},{"blockCount":342,"bytes":5812,"file":"chunks/y120-z096-x192.json","offset":{"x":192,"y":120,"z":96},"requirements":{"minecraft:bricks":107,"minecraft:glass":12,"minecraft:oak_planks":2,"minecraft:polished_diorite":154,"minecraft:sandstone":2,"minecraft:stone_bricks":65},"sha256":"80db6989b6f5844debb658d6fbc69d14431dbcf8b11ef11d21044ff9f63d4777","size":{"x":32,"y":1,"z":32}},{"blockCount":257,"bytes":5122,"file":"chunks/y120-z096-x224.json","offset":{"x":224,"y":120,"z":96},"requirements":{"minecraft:bricks":67,"minecraft:glass":20,"minecraft:oak_planks":6,"minecraft:polished_diorite":108,"minecraft:sandstone":1,"minecraft:stone_bricks":55},"sha256":"b811f2f564a0f057c0a93aed43cbb35e23937d6f9f3f7faf9b5c56fb714dc253","size":{"x":32,"y":1,"z":32}},{"blockCount":40,"bytes":1941,"file":"chunks/y120-z128-x000.json","offset":{"x":0,"y":120,"z":128},"requirements":{"minecraft:polished_diorite":25,"minecraft:stone_bricks":15},"sha256":"c1e7d56edb2ffe4c2f7df3c50b55c918686229a5ca849a5360eecd579c834523","size":{"x":32,"y":1,"z":32}},{"blockCount":193,"bytes":4247,"file":"chunks/y120-z128-x032.json","offset":{"x":32,"y":120,"z":128},"requirements":{"minecraft:bricks":58,"minecraft:polished_diorite":110,"minecraft:sandstone":12,"minecraft:stone_bricks":13},"sha256":"11d4a4fd5f90e128652e1a501a07ab7098d85f306c040f8cc7e854267203437d","size":{"x":32,"y":1,"z":32}},{"blockCount":83,"bytes":1942,"file":"chunks/y120-z128-x064.json","offset":{"x":64,"y":120,"z":128},"requirements":{"minecraft:bricks":26,"minecraft:polished_diorite":36,"minecraft:sandstone":2,"minecraft:stone_bricks":19},"sha256":"b9fac506e1dee01ca2d6c0201a05059e86d91560adbad5af899631d8d95b07f4","size":{"x":32,"y":1,"z":32}},{"blockCount":30,"bytes":1449,"file":"chunks/y120-z128-x096.json","offset":{"x":96,"y":120,"z":128},"requirements":{"minecraft:bricks":16,"minecraft:polished_diorite":9,"minecraft:sandstone":2,"minecraft:stone_bricks":3},"sha256":"9e29218fb47552712426e7caa8b26e54aca843b6a7ce53fd94bde17cb713f875","size":{"x":32,"y":1,"z":32}},{"blockCount":68,"bytes":2022,"file":"chunks/y120-z128-x128.json","offset":{"x":128,"y":120,"z":128},"requirements":{"minecraft:bricks":28,"minecraft:polished_diorite":25,"minecraft:sandstone":3,"minecraft:stone_bricks":12},"sha256":"61aad8b68599e58908e7593027bd20e20809722001aa54dbb9cc306ac3c3ccc7","size":{"x":32,"y":1,"z":32}},{"blockCount":85,"bytes":2001,"file":"chunks/y120-z128-x160.json","offset":{"x":160,"y":120,"z":128},"requirements":{"minecraft:bricks":26,"minecraft:polished_diorite":39,"minecraft:sandstone":2,"minecraft:stone_bricks":18},"sha256":"f82c982ca5f8e564c71b5e8ac1c4cc4a9e6c78d647f1014a23dca807f12c4986","size":{"x":32,"y":1,"z":32}},{"blockCount":87,"bytes":1963,"file":"chunks/y120-z128-x192.json","offset":{"x":192,"y":120,"z":128},"requirements":{"minecraft:bricks":27,"minecraft:polished_diorite":41,"minecraft:sandstone":2,"minecraft:stone_bricks":17},"sha256":"f03bedaf8f54454cfebcbac8b9f15640b207f12622458f1e0df087224d510454","size":{"x":32,"y":1,"z":32}},{"blockCount":163,"bytes":3762,"file":"chunks/y120-z128-x224.json","offset":{"x":224,"y":120,"z":128},"requirements":{"minecraft:bricks":46,"minecraft:glass":8,"minecraft:oak_planks":8,"minecraft:polished_diorite":63,"minecraft:sandstone":13,"minecraft:stone_bricks":25},"sha256":"e1b71f40abe33bf56a0e4f7b2090fbc790d8ea2ba1b3f9341a7ffc12c46a587d","size":{"x":32,"y":1,"z":32}},{"blockCount":17,"bytes":1213,"file":"chunks/y120-z160-x000.json","offset":{"x":0,"y":120,"z":160},"requirements":{"minecraft:polished_diorite":9,"minecraft:stone_bricks":8},"sha256":"cb91da6178ae65c0c4e401d7b33edb5b7effcd51a1d86efbcfb73893b683ce3a","size":{"x":32,"y":1,"z":32}},{"blockCount":91,"bytes":2768,"file":"chunks/y120-z160-x032.json","offset":{"x":32,"y":120,"z":160},"requirements":{"minecraft:polished_diorite":69,"minecraft:stone_bricks":22},"sha256":"2a561c6205a555d0fadf11609c5fbec62e2ccf63a78c6a6d8401d5ab152a84d4","size":{"x":32,"y":1,"z":32}},{"blockCount":106,"bytes":2518,"file":"chunks/y120-z160-x064.json","offset":{"x":64,"y":120,"z":160},"requirements":{"minecraft:polished_diorite":87,"minecraft:stone_bricks":19},"sha256":"4a347a85c5435c8e241251cce8cf5f94505c0e64c403528b50e5ba4eea2d7d78","size":{"x":32,"y":1,"z":32}},{"blockCount":144,"bytes":3659,"file":"chunks/y120-z160-x096.json","offset":{"x":96,"y":120,"z":160},"requirements":{"minecraft:bricks":19,"minecraft:polished_diorite":102,"minecraft:sandstone":3,"minecraft:stone_bricks":20},"sha256":"5d8c6bcb2e7b501d895d076e421f1a44d698bb35a01a1127606a5708ac4a4d14","size":{"x":32,"y":1,"z":32}},{"blockCount":191,"bytes":4479,"file":"chunks/y120-z160-x128.json","offset":{"x":128,"y":120,"z":160},"requirements":{"minecraft:bricks":19,"minecraft:polished_diorite":141,"minecraft:sandstone":3,"minecraft:stone_bricks":28},"sha256":"c77ae08a450d270715f7eab9690859258709094a474896c2d47fa0eac4866abb","size":{"x":32,"y":1,"z":32}},{"blockCount":109,"bytes":2572,"file":"chunks/y120-z160-x160.json","offset":{"x":160,"y":120,"z":160},"requirements":{"minecraft:polished_diorite":90,"minecraft:stone_bricks":19},"sha256":"b77e382f0a8442e481cf8ecc6ec38bba62229dfb62c5e4544251d46c116998cc","size":{"x":32,"y":1,"z":32}},{"blockCount":297,"bytes":5406,"file":"chunks/y120-z160-x192.json","offset":{"x":192,"y":120,"z":160},"requirements":{"minecraft:bricks":87,"minecraft:glass":21,"minecraft:oak_planks":2,"minecraft:polished_diorite":124,"minecraft:stone_bricks":63},"sha256":"7dca0cca1757bb79bc305bba2d2dea67b8c4724ecb3fc0a65c96c9537100993d","size":{"x":32,"y":1,"z":32}},{"blockCount":250,"bytes":5158,"file":"chunks/y120-z160-x224.json","offset":{"x":224,"y":120,"z":160},"requirements":{"minecraft:bricks":58,"minecraft:glass":21,"minecraft:oak_planks":6,"minecraft:polished_diorite":103,"minecraft:stone_bricks":62},"sha256":"6c4cc921334659e81fcca1ed044ac508d4ee8806728c772fde1ed3728a7cfaf6","size":{"x":32,"y":1,"z":32}},{"blockCount":34,"bytes":1793,"file":"chunks/y120-z192-x064.json","offset":{"x":64,"y":120,"z":192},"requirements":{"minecraft:polished_diorite":18,"minecraft:stone_bricks":16},"sha256":"ed6d16cf59c505b7483d259a00f90817dab2b3996cf8b554a5ee1b7228216572","size":{"x":32,"y":1,"z":32}},{"blockCount":190,"bytes":3408,"file":"chunks/y120-z192-x096.json","offset":{"x":96,"y":120,"z":192},"requirements":{"minecraft:bricks":46,"minecraft:oak_planks":6,"minecraft:polished_diorite":109,"minecraft:sandstone":12,"minecraft:stone_bricks":17},"sha256":"d2531d3d299e44ab70d41a748b40218cf8c49541c21f8ebfec41b6a58d09d1af","size":{"x":32,"y":1,"z":32}},{"blockCount":164,"bytes":3953,"file":"chunks/y120-z192-x128.json","offset":{"x":128,"y":120,"z":192},"requirements":{"minecraft:bricks":21,"minecraft:oak_planks":2,"minecraft:polished_diorite":108,"minecraft:sandstone":5,"minecraft:stone_bricks":28},"sha256":"84df85da4c20c350133ac7aeef48b5ff0f510d55eb94fc68775360a8534a7e6a","size":{"x":32,"y":1,"z":32}},{"blockCount":2,"bytes":689,"file":"chunks/y120-z192-x160.json","offset":{"x":160,"y":120,"z":192},"requirements":{"minecraft:polished_diorite":2},"sha256":"387cf9af4300369fd96daca067b4571ee17488eeedbc5824a7f8ccf221b9831f","size":{"x":32,"y":1,"z":32}},{"blockCount":39,"bytes":1984,"file":"chunks/y121-z064-x064.json","offset":{"x":64,"y":121,"z":64},"requirements":{"minecraft:polished_diorite":20,"minecraft:stone_bricks":19},"sha256":"801e5069aa17225b0f202152ac6c276a27e99628a5dc31b0f92eb44c96f1fc73","size":{"x":32,"y":1,"z":32}},{"blockCount":213,"bytes":4043,"file":"chunks/y121-z064-x096.json","offset":{"x":96,"y":121,"z":64},"requirements":{"minecraft:bricks":53,"minecraft:oak_planks":8,"minecraft:polished_diorite":126,"minecraft:sandstone":11,"minecraft:stone_bricks":15},"sha256":"f1dad9438f023c8bccb53be6319d16c094d102557b5de6b0ccdce026e6e77ac1","size":{"x":32,"y":1,"z":32}},{"blockCount":197,"bytes":4734,"file":"chunks/y121-z064-x128.json","offset":{"x":128,"y":121,"z":64},"requirements":{"minecraft:bricks":33,"minecraft:oak_planks":4,"minecraft:polished_diorite":127,"minecraft:sandstone":3,"minecraft:stone_bricks":30},"sha256":"3d6aa1c22f0dbe68d57200d3b937cff1d603c58c170a41f4e988f9c0821fc144","size":{"x":32,"y":1,"z":32}},{"blockCount":2,"bytes":688,"file":"chunks/y121-z064-x160.json","offset":{"x":160,"y":121,"z":64},"requirements":{"minecraft:polished_diorite":2},"sha256":"2593a23e18e7328c8266c6106a49806cfe1df932d8c1254c4a921a7dc6e654c5","size":{"x":32,"y":1,"z":32}},{"blockCount":18,"bytes":1211,"file":"chunks/y121-z064-x192.json","offset":{"x":192,"y":121,"z":64},"requirements":{"minecraft:glass":3,"minecraft:polished_diorite":12,"minecraft:stone_bricks":3},"sha256":"0c224c41154cfeae13d67f9facef4cc6a98e6245b2af8ea035eb47246410c9ff","size":{"x":32,"y":1,"z":32}},{"blockCount":37,"bytes":1654,"file":"chunks/y121-z064-x224.json","offset":{"x":224,"y":121,"z":64},"requirements":{"minecraft:glass":3,"minecraft:polished_diorite":23,"minecraft:stone_bricks":11},"sha256":"08dbea978446f3793cfe75dabf6179437d5a937806363f383357aa96f94e053c","size":{"x":32,"y":1,"z":32}},{"blockCount":25,"bytes":1503,"file":"chunks/y121-z096-x000.json","offset":{"x":0,"y":121,"z":96},"requirements":{"minecraft:polished_diorite":14,"minecraft:stone_bricks":11},"sha256":"990d7e3d40b92ea63a9c68846537453ab7c5f23fa9812f1a6403661754dd8103","size":{"x":32,"y":1,"z":32}},{"blockCount":161,"bytes":4470,"file":"chunks/y121-z096-x032.json","offset":{"x":32,"y":121,"z":96},"requirements":{"minecraft:bricks":27,"minecraft:polished_diorite":105,"minecraft:sandstone":1,"minecraft:stone_bricks":28},"sha256":"42913d344e038dc6140d8225ec39f5715af4233bf62d85e18c101bfa7ca87051","size":{"x":32,"y":1,"z":32}},{"blockCount":167,"bytes":3631,"file":"chunks/y121-z096-x064.json","offset":{"x":64,"y":121,"z":96},"requirements":{"minecraft:bricks":23,"minecraft:polished_diorite":115,"minecraft:sandstone":2,"minecraft:stone_bricks":27},"sha256":"b90bb867e960e27ba66834792f61eb6c5caf51414f46ceeaf646c5e879e50c08","size":{"x":32,"y":1,"z":32}},{"blockCount":130,"bytes":3714,"file":"chunks/y121-z096-x096.json","offset":{"x":96,"y":121,"z":96},"requirements":{"minecraft:bricks":40,"minecraft:polished_diorite":75,"minecraft:sandstone":4,"minecraft:stone_bricks":11},"sha256":"8b66203a952e57cb419b9d849cbe0e223f787defb32b83b83bf88021ac7a9d00","size":{"x":32,"y":1,"z":32}}],"schema":1}
