{"entries":[{"blockCount":202,"bytes":4875,"file":"chunks/y121-z096-x128.json","offset":{"x":128,"y":121,"z":96},"requirements":{"minecraft:bricks":50,"minecraft:polished_diorite":125,"minecraft:sandstone":5,"minecraft:stone_bricks":22},"sha256":"08cf0b2931218640336b6ca74545411575f2624bac509fd30df71142be013774","size":{"x":32,"y":1,"z":32}},{"blockCount":178,"bytes":3820,"file":"chunks/y121-z096-x160.json","offset":{"x":160,"y":121,"z":96},"requirements":{"minecraft:bricks":24,"minecraft:polished_diorite":123,"minecraft:sandstone":2,"minecraft:stone_bricks":29},"sha256":"993d9aea8dd111b481098c1d194afcd20d3f7cbcb5a45a0543278569b36538fd","size":{"x":32,"y":1,"z":32}},{"blockCount":309,"bytes":5689,"file":"chunks/y121-z096-x192.json","offset":{"x":192,"y":121,"z":96},"requirements":{"minecraft:bricks":112,"minecraft:glass":4,"minecraft:oak_planks":2,"minecraft:polished_diorite":156,"minecraft:sandstone":3,"minecraft:spruce_planks":1,"minecraft:stone_bricks":31},"sha256":"f2de1228713a77e78a9f136faa9b189eca63d4798f3a534b7b2444dfea21e4a3","size":{"x":32,"y":1,"z":32}},{"blockCount":207,"bytes":4760,"file":"chunks/y121-z096-x224.json","offset":{"x":224,"y":121,"z":96},"requirements":{"minecraft:bricks":67,"minecraft:glass":7,"minecraft:oak_planks":6,"minecraft:polished_diorite":113,"minecraft:sandstone":1,"minecraft:stone_bricks":13},"sha256":"5a39c6d40f7cb211605aa6a0fd303466ebd32829ad0d04354d17950e79a61c0e","size":{"x":32,"y":1,"z":32}},{"blockCount":40,"bytes":1941,"file":"chunks/y121-z128-x000.json","offset":{"x":0,"y":121,"z":128},"requirements":{"minecraft:polished_diorite":25,"minecraft:stone_bricks":15},"sha256":"cfdbe4fb9b614984b2e36fe793ad1814787d059db2950352b580bc599968216a","size":{"x":32,"y":1,"z":32}},{"blockCount":208,"bytes":4607,"file":"chunks/y121-z128-x032.json","offset":{"x":32,"y":121,"z":128},"requirements":{"minecraft:bricks":77,"minecraft:polished_diorite":114,"minecraft:sandstone":7,"minecraft:stone_bricks":10},"sha256":"231e5a8d99ee37046e898ce24cc57388afc1cc4ed51f7b57a8ad73e3e737a1cb","size":{"x":32,"y":1,"z":32}},{"blockCount":94,"bytes":2305,"file":"chunks/y121-z128-x064.json","offset":{"x":64,"y":121,"z":128},"requirements":{"minecraft:bricks":43,"minecraft:polished_diorite":38,"minecraft:sandstone":2,"minecraft:stone_bricks":11},"sha256":"4b5717ae0b196166b72fc0299d947a5db9c471eb90e4faa73bf329415470b865","size":{"x":32,"y":1,"z":32}},{"blockCount":34,"bytes":1546,"file":"chunks/y121-z128-x096.json","offset":{"x":96,"y":121,"z":128},"requirements":{"minecraft:bricks":21,"minecraft:polished_diorite":9,"minecraft:sandstone":2,"minecraft:stone_bricks":2},"sha256":"1c9927389274709a28ec861b9034422da22028d1c665c435caa9c04fcb9a6e38","size":{"x":32,"y":1,"z":32}},{"blockCount":75,"bytes":2233,"file":"chunks/y121-z128-x128.json","offset":{"x":128,"y":121,"z":128},"requirements":{"minecraft:bricks":39,"minecraft:polished_diorite":25,"minecraft:sandstone":3,"minecraft:stone_bricks":8},"sha256":"a207f22f24dc790943acbef168bb8b3aca18d3b82246a65c31f0f6030eeab281","size":{"x":32,"y":1,"z":32}},{"blockCount":98,"bytes":2307,"file":"chunks/y121-z128-x160.json","offset":{"x":160,"y":121,"z":128},"requirements":{"minecraft:bricks":44,"minecraft:polished_diorite":42,"minecraft:sandstone":2,"minecraft:stone_bricks":10},"sha256":"71b0fb6f0461e61a8523e4837efddda778a3d3c5aba03f602fe6302a3788b395","size":{"x":32,"y":1,"z":32}},{"blockCount":98,"bytes":2231,"file":"chunks/y121-z128-x192.json","offset":{"x":192,"y":121,"z":128},"requirements":{"minecraft:bricks":41,"minecraft:polished_diorite":44,"minecraft:sandstone":3,"minecraft:stone_bricks":10},"sha256":"b06088aeaca4b4b00620689cad352b6641aa48628c584ac2ccb08e3e45e3ab7c","size":{"x":32,"y":1,"z":32}},{"blockCount":141,"bytes":3687,"file":"chunks/y121-z128-x224.json","offset":{"x":224,"y":121,"z":128},"requirements":{"minecraft:bricks":41,"minecraft:glass":3,"minecraft:oak_planks":12,"minecraft:polished_diorite":63,"minecraft:sandstone":11,"minecraft:stone_bricks":11},"sha256":"09a855a31fd05841fe35c379241b31fb4bd41d0e420b7a8bf136acc6fb7b6037","size":{"x":32,"y":1,"z":32}},{"blockCount":17,"bytes":1213,"file":"chunks/y121-z160-x000.json","offset":{"x":0,"y":121,"z":160},"requirements":{"minecraft:polished_diorite":9,"minecraft:stone_bricks":8},"sha256":"50384798c8e2dfb9afe079c0c27f000b8192a92cfd7b530aeae1adb630accbe4","size":{"x":32,"y":1,"z":32}},{"blockCount":87,"bytes":2920,"file":"chunks/y121-z160-x032.json","offset":{"x":32,"y":121,"z":160},"requirements":{"minecraft:polished_diorite":65,"minecraft:stone_bricks":22},"sha256":"f8fa70229be183221b77e8edf31cead248c8b78b83b8e98028ca1bc083dd44df","size":{"x":32,"y":1,"z":32}},{"blockCount":98,"bytes":2822,"file":"chunks/y121-z160-x064.json","offset":{"x":64,"y":121,"z":160},"requirements":{"minecraft:polished_diorite":79,"minecraft:stone_bricks":19},"sha256":"d9f40b574b5c6093194f98d3faa78c96b550832eb27b4eea70900da94a983618","size":{"x":32,"y":1,"z":32}},{"blockCount":131,"bytes":3620,"file":"chunks/y121-z160-x096.json","offset":{"x":96,"y":121,"z":160},"requirements":{"minecraft:bricks":29,"minecraft:polished_diorite":87,"minecraft:sandstone":2,"minecraft:stone_bricks":13},"sha256":"1a5d71536f97a396131941faea0d92754782e8e4988b23c888a0aebe0e07b820","size":{"x":32,"y":1,"z":32}},{"blockCount":175,"bytes":4552,"file":"chunks/y121-z160-x128.json","offset":{"x":128,"y":121,"z":160},"requirements":{"minecraft:bricks":29,"minecraft:polished_diorite":123,"minecraft:sandstone":2,"minecraft:stone_bricks":21},"sha256":"8f87dc03bfa53de2f3b3255ef79418d0f65339f0a24e1d080041f1840ece0ffb","size":{"x":32,"y":1,"z":32}},{"blockCount":100,"bytes":2914,"file":"chunks/y121-z160-x160.json","offset":{"x":160,"y":121,"z":160},"requirements":{"minecraft:polished_diorite":81,"minecraft:stone_bricks":19},"sha256":"e612029ef01dbbda5f99d55120f5c209933eb940d12f00136ae9d3d4ace461da","size":{"x":32,"y":1,"z":32}},{"blockCount":245,"bytes":5300,"file":"chunks/y121-z160-x192.json","offset":{"x":192,"y":121,"z":160},"requirements":{"minecraft:bricks":86,"minecraft:glass":7,"minecraft:oak_planks":2,"minecraft:polished_diorite":125,"minecraft:spruce_planks":1,"minecraft:stone_bricks":24},"sha256":"39d5066b5736821789989ec834c4fb9003f0d23bc1fddd508058a2466e728770","size":{"x":32,"y":1,"z":32}},{"blockCount":200,"bytes":4758,"file":"chunks/y121-z160-x224.json","offset":{"x":224,"y":121,"z":160},"requirements":{"minecraft:bricks":57,"minecraft:glass":7,"minecraft:oak_planks":6,"minecraft:polished_diorite":109,"minecraft:stone_bricks":21},"sha256":"0ac151fbbfb19da0c2df3d6382595b96cdac658fd2f96e34e0fb1f21189136be","size":{"x":32,"y":1,"z":32}},{"blockCount":34,"bytes":1793,"file":"chunks/y121-z192-x064.json","offset":{"x":64,"y":121,"z":192},"requirements":{"minecraft:polished_diorite":18,"minecraft:stone_bricks":16},"sha256":"2f1b130d31a263ccae3cdb395a2c2f7d4f3ac53b7ca7035528968e349a90cf14","size":{"x":32,"y":1,"z":32}},{"blockCount":182,"bytes":3410,"file":"chunks/y121-z192-x096.json","offset":{"x":96,"y":121,"z":192},"requirements":{"minecraft:bricks":47,"minecraft:oak_planks":8,"minecraft:polished_diorite":105,"minecraft:sandstone":11,"minecraft:stone_bricks":11},"sha256":"57b72f1bf275a27313e9d456bbf54d0499b0d5aa500223f7d4913641c4a20dae","size":{"x":32,"y":1,"z":32}},{"blockCount":161,"bytes":3971,"file":"chunks/y121-z192-x128.json","offset":{"x":128,"y":121,"z":192},"requirements":{"minecraft:bricks":27,"minecraft:oak_planks":4,"minecraft:polished_diorite":104,"minecraft:sandstone":3,"minecraft:stone_bricks":23},"sha256":"46600a95769eb5abf129bd94ec991ba2ac864a394ba5c7ebfaf593080fac3b64","size":{"x":32,"y":1,"z":32}},{"blockCount":2,"bytes":689,"file":"chunks/y121-z192-x160.json","offset":{"x":160,"y":121,"z":192},"requirements":{"minecraft:polished_diorite":2},"sha256":"7618d42d2a3d11a14ce607894424287eb1fa4613c7a31d077cc4146fbc13a559","size":{"x":32,"y":1,"z":32}},{"blockCount":27,"bytes":1527,"file":"chunks/y122-z064-x064.json","offset":{"x":64,"y":122,"z":64},"requirements":{"minecraft:polished_diorite":18,"minecraft:stone_bricks":9},"sha256":"6107b179746fb38b5acf608e7dfdfd6a5b6c24f0db728d2a836e48617015d7b7","size":{"x":32,"y":1,"z":32}},{"blockCount":220,"bytes":4269,"file":"chunks/y122-z064-x096.json","offset":{"x":96,"y":122,"z":64},"requirements":{"minecraft:bricks":59,"minecraft:oak_planks":9,"minecraft:polished_diorite":134,"minecraft:sandstone":12,"minecraft:stone_bricks":6},"sha256":"8be40327d14c4eb0648e33b871cbf19c97105a54cb351c563e7dde16a46d6174","size":{"x":32,"y":1,"z":32}},{"blockCount":192,"bytes":4545,"file":"chunks/y122-z064-x128.json","offset":{"x":128,"y":122,"z":64},"requirements":{"minecraft:bricks":43,"minecraft:oak_planks":3,"minecraft:polished_diorite":131,"minecraft:sandstone":3,"minecraft:stone_bricks":12},"sha256":"f00452be4070db478b01e2b1d1ea21f596453c8fc9c1c762e65f328b0b129ec0","size":{"x":32,"y":1,"z":32}},{"blockCount":2,"bytes":688,"file":"chunks/y122-z064-x160.json","offset":{"x":160,"y":122,"z":64},"requirements":{"minecraft:polished_diorite":2},"sha256":"1520073028cb83bb932be527a6de81ed27bdcbca30cae09baa07bdf8b6ccb2c9","size":{"x":32,"y":1,"z":32}},{"blockCount":13,"bytes":1058,"file":"chunks/y122-z064-x192.json","offset":{"x":192,"y":122,"z":64},"requirements":{"minecraft:polished_diorite":10,"minecraft:stone_bricks":3},"sha256":"50a0f3cf7ac2df564852f3f2fdfc7c17e32ccb1e71a56b841c20f252670b37c3","size":{"x":32,"y":1,"z":32}},{"blockCount":26,"bytes":1364,"file":"chunks/y122-z064-x224.json","offset":{"x":224,"y":122,"z":64},"requirements":{"minecraft:polished_diorite":19,"minecraft:stone_bricks":7},"sha256":"76fba0b3f1c486c74c09c24d495e12f4cd668d732b18db3299b1f37e6478a076","size":{"x":32,"y":1,"z":32}},{"blockCount":19,"bytes":1274,"file":"chunks/y122-z096-x000.json","offset":{"x":0,"y":122,"z":96},"requirements":{"minecraft:polished_diorite":14,"minecraft:stone_bricks":5},"sha256":"df0381164517d7caf162416a2b2f16c0963f57d7dd07bbee242da63cd1e8e3a4","size":{"x":32,"y":1,"z":32}},{"blockCount":170,"bytes":3896,"file":"chunks/y122-z096-x032.json","offset":{"x":32,"y":122,"z":96},"requirements":{"minecraft:bricks":35,"minecraft:polished_diorite":119,"minecraft:stone_bricks":16},"sha256":"f10d979e4fb9b59252cd04da16e5b236c835cd9de212a166168456899507f700","size":{"x":32,"y":1,"z":32}},{"blockCount":164,"bytes":2716,"file":"chunks/y122-z096-x064.json","offset":{"x":64,"y":122,"z":96},"requirements":{"minecraft:bricks":38,"minecraft:polished_diorite":118,"minecraft:stone_bricks":8},"sha256":"66499a59dfe83f8e649daabf18a6e3caf490b8821a389c0e5da1ad84d247e27a","size":{"x":32,"y":1,"z":32}},{"blockCount":128,"bytes":3708,"file":"chunks/y122-z096-x096.json","offset":{"x":96,"y":122,"z":96},"requirements":{"minecraft:bricks":52,"minecraft:polished_diorite":75,"minecraft:stone_bricks":1},"sha256":"f23c0fb584b5a315348368a345fa65a3277f2cab7d74de9604025e6011ab08da","size":{"x":32,"y":1,"z":32}},{"blockCount":199,"bytes":4566,"file":"chunks/y122-z096-x128.json","offset":{"x":128,"y":122,"z":96},"requirements":{"minecraft:bricks":69,"minecraft:polished_diorite":126,"minecraft:stone_bricks":4},"sha256":"2761ae36ace3fd8d55d06317e9e77818593633ccbf08d12f6b74c9d37212e1ce","size":{"x":32,"y":1,"z":32}},{"blockCount":175,"bytes":2965,"file":"chunks/y122-z096-x160.json","offset":{"x":160,"y":122,"z":96},"requirements":{"minecraft:bricks":39,"minecraft:polished_diorite":127,"minecraft:stone_bricks":9},"sha256":"5a22c69a8c7b225be4789e3cde54e24745b5706a47e779ae44bc562abee96016","size":{"x":32,"y":1,"z":32}},{"blockCount":294,"bytes":4833,"file":"chunks/y122-z096-x192.json","offset":{"x":192,"y":122,"z":96},"requirements":{"minecraft:bricks":122,"minecraft:oak_planks":2,"minecraft:polished_diorite":150,"minecraft:spruce_planks":7,"minecraft:stone_bricks":13},"sha256":"28d87d34ad49c496af58974e592ee9a3d3cb80b85173b8acdc3f296e01a027e5","size":{"x":32,"y":1,"z":32}},{"blockCount":189,"bytes":4303,"file":"chunks/y122-z096-x224.json","offset":{"x":224,"y":122,"z":96},"requirements":{"minecraft:bricks":66,"minecraft:oak_planks":6,"minecraft:polished_diorite":106,"minecraft:sandstone":1,"minecraft:stone_bricks":10},"sha256":"61699ae0698cc41eac478369404335aec3b75d6e8b08660d0a42e68754cc8368","size":{"x":32,"y":1,"z":32}},{"blockCount":34,"bytes":1712,"file":"chunks/y122-z128-x000.json","offset":{"x":0,"y":122,"z":128},"requirements":{"minecraft:polished_diorite":25,"minecraft:stone_bricks":9},"sha256":"4947958d5c7b1bfb43409119316dbc688bc19d0c8b338bb2e600835f8f90084a","size":{"x":32,"y":1,"z":32}},{"blockCount":263,"bytes":5423,"file":"chunks/y122-z128-x032.json","offset":{"x":32,"y":122,"z":128},"requirements":{"minecraft:bricks":120,"minecraft:polished_diorite":128,"minecraft:sandstone":5,"minecraft:stone_bricks":10},"sha256":"8f75e880a92343a57cd4ee07f6375455579ee5c3483aa24311769fa018877c64","size":{"x":32,"y":1,"z":32}},{"blockCount":81,"bytes":1745,"file":"chunks/y122-z128-x064.json","offset":{"x":64,"y":122,"z":128},"requirements":{"minecraft:bricks":48,"minecraft:polished_diorite":33},"sha256":"4d12dca03f3fbb74aad314772ce8df25ae844cbe8dec453b6dcb998ca80bb4c3","size":{"x":32,"y":1,"z":32}},{"blockCount":27,"bytes":1361,"file":"chunks/y122-z128-x096.json","offset":{"x":96,"y":122,"z":128},"requirements":{"minecraft:bricks":23,"minecraft:polished_diorite":4},"sha256":"a10764eb3ced77df187d6f438ef07e7022059006436773ca350f3e2eaec42404","size":{"x":32,"y":1,"z":32}},{"blockCount":69,"bytes":1857,"file":"chunks/y122-z128-x128.json","offset":{"x":128,"y":122,"z":128},"requirements":{"minecraft:bricks":44,"minecraft:polished_diorite":25},"sha256":"89d0cbe526e652069cc9c9ee97e7ca7f5e8ff3aa1d09144288b69cfd756614d7","size":{"x":32,"y":1,"z":32}},{"blockCount":88,"bytes":1766,"file":"chunks/y122-z128-x160.json","offset":{"x":160,"y":122,"z":128},"requirements":{"minecraft:bricks":49,"minecraft:polished_diorite":39},"sha256":"51024371e439b11ff06a131ea3cee3e575b06846c310b13b2245d67d9970fe6f","size":{"x":32,"y":1,"z":32}},{"blockCount":87,"bytes":1766,"file":"chunks/y122-z128-x192.json","offset":{"x":192,"y":122,"z":128},"requirements":{"minecraft:bricks":49,"minecraft:polished_diorite":38},"sha256":"531ad9e4f8b97c502a78875da3260b4b62e2b18ed13ea5e02a860cee0f495d67","size":{"x":32,"y":1,"z":32}},{"blockCount":140,"bytes":3590,"file":"chunks/y122-z128-x224.json","offset":{"x":224,"y":122,"z":128},"requirements":{"minecraft:bricks":40,"minecraft:oak_planks":12,"minecraft:polished_diorite":65,"minecraft:sandstone":14,"minecraft:stone_bricks":9},"sha256":"3575e7c699a689fea9bfda175fd4d83b6a69c5c226f020bc43a6e6a97fd34742","size":{"x":32,"y":1,"z":32}},{"blockCount":13,"bytes":1061,"file":"chunks/y122-z160-x000.json","offset":{"x":0,"y":122,"z":160},"requirements":{"minecraft:polished_diorite":9,"minecraft:stone_bricks":4},"sha256":"e6deff20a2b4ae9e16ae6da0eff83d9ded391958bfc0396d05842d0481843842","size":{"x":32,"y":1,"z":32}},{"blockCount":79,"bytes":2314,"file":"chunks/y122-z160-x032.json","offset":{"x":32,"y":122,"z":160},"requirements":{"minecraft:polished_diorite":67,"minecraft:stone_bricks":12},"sha256":"77dc5116416a56c6db41cd512517a83995e2364c1802370cf102e408e8fb4b5f","size":{"x":32,"y":1,"z":32}},{"blockCount":96,"bytes":2022,"file":"chunks/y122-z160-x064.json","offset":{"x":64,"y":122,"z":160},"requirements":{"minecraft:polished_diorite":87,"minecraft:stone_bricks":9},"sha256":"80838f037ce066e6cba46057e06931f203358d69f3506b0fd4f5c52ade07f20f","size":{"x":32,"y":1,"z":32}},{"blockCount":136,"bytes":3728,"file":"chunks/y122-z160-x096.json","offset":{"x":96,"y":122,"z":160},"requirements":{"minecraft:bricks":40,"minecraft:polished_diorite":94,"minecraft:stone_bricks":2},"sha256":"edb0bcfec905d4dee42b4b16a4f5626625ce8e33744c8d76ebf3e3463e548eac","size":{"x":32,"y":1,"z":32}},{"blockCount":180,"bytes":4319,"file":"chunks/y122-z160-x128.json","offset":{"x":128,"y":122,"z":160},"requirements":{"minecraft:bricks":40,"minecraft:polished_diorite":134,"minecraft:stone_bricks":6},"sha256":"ddae9398ec3b7e10caa184e25c6efae9db2e64b034eed8625d6af71007bf2e9b","size":{"x":32,"y":1,"z":32}},{"blockCount":97,"bytes":2118,"file":"chunks/y122-z160-x160.json","offset":{"x":160,"y":122,"z":160},"requirements":{"minecraft:polished_diorite":88,"minecraft:stone_bricks":9},"sha256":"f0127208c3228944aa4ac9c6c1f35b6d89916adbb9d8fab1728bdd67ca2ae488","size":{"x":32,"y":1,"z":32}},{"blockCount":228,"bytes":4445,"file":"chunks/y122-z160-x192.json","offset":{"x":192,"y":122,"z":160},"requirements":{"minecraft:bricks":80,"minecraft:oak_planks":2,"minecraft:polished_diorite":123,"minecraft:spruce_planks":7,"minecraft:stone_bricks":16},"sha256":"8a6212c84b2ca038a41062e99553cbd0366d4b97f1af2a7c4837982ea36d928f","size":{"x":32,"y":1,"z":32}},{"blockCount":178,"bytes":4184,"file":"chunks/y122-z160-x224.json","offset":{"x":224,"y":122,"z":160},"requirements":{"minecraft:bricks":56,"minecraft:oak_planks":6,"minecraft:polished_diorite":102,"minecraft:stone_bricks":14},"sha256":"aa5d592bc69fd417f25b4395c29bd7c51ab09792db857e9c59f2b6cf2d39d9dd","size":{"x":32,"y":1,"z":32}},{"blockCount":24,"bytes":1412,"file":"chunks/y122-z192-x064.json","offset":{"x":64,"y":122,"z":192},"requirements":{"minecraft:polished_diorite":16,"minecraft:stone_bricks":8},"sha256":"9462dab1288fb20c76a158a404688d890a60c39eb5ad8f7d25abe1cc46479abc","size":{"x":32,"y":1,"z":32}},{"blockCount":187,"bytes":3617,"file":"chunks/y122-z192-x096.json","offset":{"x":96,"y":122,"z":192},"requirements":{"minecraft:bricks":50,"minecraft:oak_planks":9,"minecraft:polished_diorite":111,"minecraft:sandstone":12,"minecraft:stone_bricks":5},"sha256":"795fb47bdeaf3f0290342f8996e0a80c66c0380ca95ee54afb76db61fe0d3071","size":{"x":32,"y":1,"z":32}},{"blockCount":155,"bytes":3799,"file":"chunks/y122-z192-x128.json","offset":{"x":128,"y":122,"z":192},"requirements":{"minecraft:bricks":34,"minecraft:oak_planks":3,"minecraft:polished_diorite":106,"minecraft:sandstone":3,"minecraft:stone_bricks":9},"sha256":"011107af5399944ea7f7e754ac37aa53adf37c15b5a3e9ec7dd65941a4a92448","size":{"x":32,"y":1,"z":32}},{"blockCount":2,"bytes":689,"file":"chunks/y122-z192-x160.json","offset":{"x":160,"y":122,"z":192},"requirements":{"minecraft:polished_diorite":2},"sha256":"b4c2cbc9f97b54267b85ca8b646c645a86ff21e166e09095bfc2e7b132cef41d","size":{"x":32,"y":1,"z":32}},{"blockCount":29,"bytes":1375,"file":"chunks/y123-z064-x064.json","offset":{"x":64,"y":123,"z":64},"requirements":{"minecraft:polished_diorite":27,"minecraft:stone_bricks":2},"sha256":"b50f5581a5657ba02197a1555f5d5a0fcdff27ea3e51911b82a580ae0318b0b3","size":{"x":32,"y":1,"z":32}},{"blockCount":204,"bytes":4481,"file":"chunks/y123-z064-x096.json","offset":{"x":96,"y":123,"z":64},"requirements":{"minecraft:bricks":56,"minecraft:oak_planks":6,"minecraft:polished_diorite":107,"minecraft:sandstone":15,"minecraft:stone_bricks":20},"sha256":"7d3cd5c71aeb64e235dc9d6e8e66ce434294b9723a3ace25a04e768c21958fd0","size":{"x":32,"y":1,"z":32}},{"blockCount":177,"bytes":4810,"file":"chunks/y123-z064-x128.json","offset":{"x":128,"y":123,"z":64},"requirements":{"minecraft:bricks":42,"minecraft:oak_planks":2,"minecraft:polished_diorite":110,"minecraft:sandstone":4,"minecraft:stone_bricks":19},"sha256":"a229449e1ac6a94d1d1635529e45e6c6bc7d78f127f8bd758aa45c110b259e4f","size":{"x":32,"y":1,"z":32}},{"blockCount":2,"bytes":688,"file":"chunks/y123-z064-x160.json","offset":{"x":160,"y":123,"z":64},"requirements":{"minecraft:polished_diorite":2},"sha256":"780621fee423cc108e531e07f642a0f4066308411d8b447eb92900bfe9b12a59","size":{"x":32,"y":1,"z":32}},{"blockCount":17,"bytes":1077,"file":"chunks/y123-z064-x192.json","offset":{"x":192,"y":123,"z":64},"requirements":{"minecraft:polished_diorite":11,"minecraft:stone_bricks":6},"sha256":"645b1b1eb7f2015c1b700744b89e190f6676a65814276b4f020a26692693d9e7","size":{"x":32,"y":1,"z":32}},{"blockCount":26,"bytes":1307,"file":"chunks/y123-z064-x224.json","offset":{"x":224,"y":123,"z":64},"requirements":{"minecraft:polished_diorite":16,"minecraft:stone_bricks":10},"sha256":"88099ff34d7a8b7d945c85f6f75390b4236dcd85a2dade3e253b2a3bcfe48b7a","size":{"x":32,"y":1,"z":32}},{"blockCount":20,"bytes":1198,"file":"chunks/y123-z096-x000.json","offset":{"x":0,"y":123,"z":96},"requirements":{"minecraft:polished_diorite":19,"minecraft:stone_bricks":1},"sha256":"b4800f53f21dd327a8cf53e5962f7037e77281c58fc0f9f0cbf7b35606f7966b","size":{"x":32,"y":1,"z":32}},{"blockCount":160,"bytes":3410,"file":"chunks/y123-z096-x032.json","offset":{"x":32,"y":123,"z":96},"requirements":{"minecraft:bricks":50,"minecraft:polished_diorite":91,"minecraft:sandstone":2,"minecraft:stone_bricks":17},"sha256":"ef9513fa78a0af9ced4ce15a192e45abe034ea1bffac6ed7adfa6c6144b181fc","size":{"x":32,"y":1,"z":32}},{"blockCount":146,"bytes":2730,"file":"chunks/y123-z096-x064.json","offset":{"x":64,"y":123,"z":96},"requirements":{"minecraft:bricks":35,"minecraft:polished_diorite":92,"minecraft:stone_bricks":19},"sha256":"11bdd5b2dc810ceb57c6f4b1989c773987d8e45d7da0cf548c56e1d5ea8e9dae","size":{"x":32,"y":1,"z":32}},{"blockCount":118,"bytes":4037,"file":"chunks/y123-z096-x096.json","offset":{"x":96,"y":123,"z":96},"requirements":{"minecraft:bricks":52,"minecraft:polished_diorite":53,"minecraft:sandstone":1,"minecraft:stone_bricks":12},"sha256":"39b5432b1ae00c987e986766511b1073dc5e3c88a83325843a32a522ad4fac90","size":{"x":32,"y":1,"z":32}},{"blockCount":181,"bytes":4932,"file":"chunks/y123-z096-x128.json","offset":{"x":128,"y":123,"z":96},"requirements":{"minecraft:bricks":69,"minecraft:polished_diorite":89,"minecraft:sandstone":1,"minecraft:stone_bricks":22},"sha256":"202a1eca9ea548aecddf9dc3150cf250924030882e446c023b35a5e6a6be9b66","size":{"x":32,"y":1,"z":32}},{"blockCount":157,"bytes":2981,"file":"chunks/y123-z096-x160.json","offset":{"x":160,"y":123,"z":96},"requirements":{"minecraft:bricks":34,"minecraft:polished_diorite":106,"minecraft:stone_bricks":17},"sha256":"86c10c1b7a7b376eb9317db549d370a085506d971565482ace65baa88a945048","size":{"x":32,"y":1,"z":32}},{"blockCount":295,"bytes":5020,"file":"chunks/y123-z096-x192.json","offset":{"x":192,"y":123,"z":96},"requirements":{"minecraft:bricks":117,"minecraft:oak_planks":2,"minecraft:polished_diorite":145,"minecraft:spruce_planks":14,"minecraft:stone_bricks":17},"sha256":"13996fd97a4bc77080f5372778d897884598590bb2e689e6574d507675609039","size":{"x":32,"y":1,"z":32}},{"blockCount":196,"bytes":4494,"file":"chunks/y123-z096-x224.json","offset":{"x":224,"y":123,"z":96},"requirements":{"minecraft:bricks":64,"minecraft:oak_planks":6,"minecraft:polished_diorite":109,"minecraft:sandstone":2,"minecraft:stone_bricks":15},"sha256":"03460db895bedefa99db7af4286448ba393fa4cfe4173e4e77e8a2a03f7c82df","size":{"x":32,"y":1,"z":32}},{"blockCount":36,"bytes":1560,"file":"chunks/y123-z128-x000.json","offset":{"x":0,"y":123,"z":128},"requirements":{"minecraft:polished_diorite":32,"minecraft:stone_bricks":4},"sha256":"57388a81ad9395db0f6f5b4938548d6ed46353a7ae1e8475bac13f291add2890","size":{"x":32,"y":1,"z":32}},{"blockCount":267,"bytes":4173,"file":"chunks/y123-z128-x032.json","offset":{"x":32,"y":123,"z":128},"requirements":{"minecraft:bricks":149,"minecraft:polished_diorite":98,"minecraft:sandstone":2,"minecraft:stone_bricks":18},"sha256":"c9e858c7f876ecf45ecf3435dacaec2c64d198d5927b50fcc2afdd0e547b3732","size":{"x":32,"y":1,"z":32}},{"blockCount":88,"bytes":2197,"file":"chunks/y123-z128-x064.json","offset":{"x":64,"y":123,"z":128},"requirements":{"minecraft:bricks":55,"minecraft:polished_diorite":33},"sha256":"bb8c195b1ff0d48275f569b282f752776c530b573226cf74e4efd98d8e8d3e19","size":{"x":32,"y":1,"z":32}},{"blockCount":30,"bytes":1560,"file":"chunks/y123-z128-x096.json","offset":{"x":96,"y":123,"z":128},"requirements":{"minecraft:bricks":25,"minecraft:polished_diorite":4,"minecraft:sandstone":1},"sha256":"489d272b2fc9ee6ffd5af6a7bd88058c685dcd2b442c6981f4e435f2be89fbd5","size":{"x":32,"y":1,"z":32}},{"blockCount":76,"bytes":2264,"file":"chunks/y123-z128-x128.json","offset":{"x":128,"y":123,"z":128},"requirements":{"minecraft:bricks":50,"minecraft:polished_diorite":25,"minecraft:sandstone":1},"sha256":"d9f3516923ffad7f0c186ab2c0e52254194474163b9d56b4afe98163de203db2","size":{"x":32,"y":1,"z":32}},{"blockCount":93,"bytes":2218,"file":"chunks/y123-z128-x160.json","offset":{"x":160,"y":123,"z":128},"requirements":{"minecraft:bricks":54,"minecraft:polished_diorite":39},"sha256":"551872b5ede068d8e02ac09d58c2b8f0154890e7eb39bc087e03e66d929cffb1","size":{"x":32,"y":1,"z":32}},{"blockCount":92,"bytes":2142,"file":"chunks/y123-z128-x192.json","offset":{"x":192,"y":123,"z":128},"requirements":{"minecraft:bricks":54,"minecraft:polished_diorite":38},"sha256":"3bd4f955ca3b5d2abce2aad9c8e46ebb17efdee9185100ddecd80d5c1722de7a","size":{"x":32,"y":1,"z":32}},{"blockCount":140,"bytes":3666,"file":"chunks/y123-z128-x224.json","offset":{"x":224,"y":123,"z":128},"requirements":{"minecraft:bricks":37,"minecraft:oak_planks":8,"minecraft:polished_diorite":64,"minecraft:sandstone":17,"minecraft:stone_bricks":14},"sha256":"6b06000d1031c7f33abca42a0af7fc60691ead48864b075cc506f5026d146166","size":{"x":32,"y":1,"z":32}},{"blockCount":14,"bytes":986,"file":"chunks/y123-z160-x000.json","offset":{"x":0,"y":123,"z":160},"requirements":{"minecraft:polished_diorite":13,"minecraft:stone_bricks":1},"sha256":"8a512b7c0a24d302471c30de59637df26555aabd44a1cfb9655520270e720755","size":{"x":32,"y":1,"z":32}},{"blockCount":75,"bytes":2218,"file":"chunks/y123-z160-x032.json","offset":{"x":32,"y":123,"z":160},"requirements":{"minecraft:polished_diorite":64,"minecraft:stone_bricks":11},"sha256":"f18c0e6c7620dd3c680f9c04be06aa2a647e561a963513cf97371b7155ae336f","size":{"x":32,"y":1,"z":32}},{"blockCount":81,"bytes":2022,"file":"chunks/y123-z160-x064.json","offset":{"x":64,"y":123,"z":160},"requirements":{"minecraft:polished_diorite":62,"minecraft:stone_bricks":19},"sha256":"c0a045f1b5ce85160f5ed0aaca46493d9ce416644d475633a0a5a2dc0b6a7df5","size":{"x":32,"y":1,"z":32}},{"blockCount":123,"bytes":4128,"file":"chunks/y123-z160-x096.json","offset":{"x":96,"y":123,"z":160},"requirements":{"minecraft:bricks":43,"minecraft:polished_diorite":64,"minecraft:stone_bricks":16},"sha256":"d32a5b572ad018ddef92f5ed201bc0eae4b216ca6d0a22b2ac68ce2fb16cbc34","size":{"x":32,"y":1,"z":32}},{"blockCount":159,"bytes":4737,"file":"chunks/y123-z160-x128.json","offset":{"x":128,"y":123,"z":160},"requirements":{"minecraft:bricks":43,"minecraft:polished_diorite":90,"minecraft:stone_bricks":26},"sha256":"ad08eafdb8536f4bd5fccac97b3cbd6e952c5c7a5c5f41824adc2956b205913e","size":{"x":32,"y":1,"z":32}},{"blockCount":84,"bytes":2137,"file":"chunks/y123-z160-x160.json","offset":{"x":160,"y":123,"z":160},"requirements":{"minecraft:polished_diorite":67,"minecraft:stone_bricks":17},"sha256":"e4ff699fe5c876ded96cee7af3b567676a89269b528e6f4dabad558dd249f685","size":{"x":32,"y":1,"z":32}},{"blockCount":236,"bytes":4541,"file":"chunks/y123-z160-x192.json","offset":{"x":192,"y":123,"z":160},"requirements":{"minecraft:bricks":78,"minecraft:oak_planks":2,"minecraft:polished_diorite":119,"minecraft:spruce_planks":14,"minecraft:stone_bricks":23},"sha256":"e9385680e16f0a13df3ab145ac7796abad90859077f1f89e149f533c845055e0","size":{"x":32,"y":1,"z":32}},{"blockCount":181,"bytes":4241,"file":"chunks/y123-z160-x224.json","offset":{"x":224,"y":123,"z":160},"requirements":{"minecraft:bricks":55,"minecraft:oak_planks":6,"minecraft:polished_diorite":102,"minecraft:stone_bricks":18},"sha256":"2adc5761869f82aa31618d03f69bbf1ee61015b0968aa504b8f3556b8c2c3035","size":{"x":32,"y":1,"z":32}},{"blockCount":26,"bytes":1260,"file":"chunks/y123-z192-x064.json","offset":{"x":64,"y":123,"z":192},"requirements":{"minecraft:polished_diorite":24,"minecraft:stone_bricks":2},"sha256":"fee4629e4a2631a207ac900e0a5dd08ef51eb9d48962c9715311ce265cd0e97a","size":{"x":32,"y":1,"z":32}},{"blockCount":175,"bytes":3714,"file":"chunks/y123-z192-x096.json","offset":{"x":96,"y":123,"z":192},"requirements":{"minecraft:bricks":46,"minecraft:oak_planks":6,"minecraft:polished_diorite":92,"minecraft:sandstone":15,"minecraft:stone_bricks":16},"sha256":"3c8100253d38123a32c6370643ea31e776825cd975793a463212857d75460a79","size":{"x":32,"y":1,"z":32}},{"blockCount":145,"bytes":3970,"file":"chunks/y123-z192-x128.json","offset":{"x":128,"y":123,"z":192},"requirements":{"minecraft:bricks":32,"minecraft:oak_planks":2,"minecraft:polished_diorite":92,"minecraft:sandstone":4,"minecraft:stone_bricks":15},"sha256":"232360c1ae4d20512c8abd36a6f2dc9021598bf642d585a90079a00950587df1","size":{"x":32,"y":1,"z":32}},{"blockCount":2,"bytes":689,"file":"chunks/y123-z192-x160.json","offset":{"x":160,"y":123,"z":192},"requirements":{"minecraft:polished_diorite":2},"sha256":"a104eedae08fdb3b231d5d024e92b9100472c66f560ef0673e8ff1b9b7bf4431","size":{"x":32,"y":1,"z":32}},{"blockCount":20,"bytes":1180,"file":"chunks/y124-z064-x064.json","offset":{"x":64,"y":124,"z":64},"requirements":{"minecraft:polished_diorite":18,"minecraft:stone_bricks":2},"sha256":"ba16e5f42f91e6ca664e0af1e6db8e23d6e616d0d6e48bad7077f841ae24359d","size":{"x":32,"y":1,"z":32}},{"blockCount":214,"bytes":4308,"file":"chunks/y124-z064-x096.json","offset":{"x":96,"y":124,"z":64},"requirements":{"minecraft:bricks":50,"minecraft:oak_planks":8,"minecraft:polished_diorite":135,"minecraft:sandstone":14,"minecraft:stone_bricks":7},"sha256":"79f55dfde3fbda2a07178f6dca69f31c767910519f0dc523bd8bcd34d88068eb","size":{"x":32,"y":1,"z":32}},{"blockCount":179,"bytes":4296,"file":"chunks/y124-z064-x128.json","offset":{"x":128,"y":124,"z":64},"requirements":{"minecraft:bricks":39,"minecraft:oak_planks":3,"minecraft:polished_diorite":131,"minecraft:sandstone":3,"minecraft:stone_bricks":3},"sha256":"c82d7e512d14f6c42c63d52213d93da1fb828dcca35a49295125481e114a42df","size":{"x":32,"y":1,"z":32}},{"blockCount":10,"bytes":917,"file":"chunks/y124-z064-x192.json","offset":{"x":192,"y":124,"z":64},"requirements":{"minecraft:polished_diorite":10},"sha256":"0a4f96cbdaef03d295ba76eabe1d1577d7f4cb3d57d81816bde2b30ba5f9f008","size":{"x":32,"y":1,"z":32}},{"blockCount":15,"bytes":1071,"file":"chunks/y124-z064-x224.json","offset":{"x":224,"y":124,"z":64},"requirements":{"minecraft:polished_diorite":15},"sha256":"e0e3a686680999b8ea8cde82258002043701d9dac8456083e30891b193a43a95","size":{"x":32,"y":1,"z":32}},{"blockCount":13,"bytes":1004,"file":"chunks/y124-z096-x000.json","offset":{"x":0,"y":124,"z":96},"requirements":{"minecraft:polished_diorite":12,"minecraft:stone_bricks":1},"sha256":"85f14e062bdc21cd45eafbd56c7f18bab6dde8a674af1103fe56dcb686d3bcc4","size":{"x":32,"y":1,"z":32}},{"blockCount":123,"bytes":2798,"file":"chunks/y124-z096-x032.json","offset":{"x":32,"y":124,"z":96},"requirements":{"minecraft:bricks":18,"minecraft:polished_diorite":100,"minecraft:sandstone":1,"minecraft:stone_bricks":4},"sha256":"988af60fdff32a8e8e87bafbcad4a036ab4d4152406ec67b397dd2522c0d328a","size":{"x":32,"y":1,"z":32}},{"blockCount":154,"bytes":2563,"file":"chunks/y124-z096-x064.json","offset":{"x":64,"y":124,"z":96},"requirements":{"minecraft:bricks":32,"minecraft:polished_diorite":118,"minecraft:sandstone":2,"minecraft:stone_bricks":2},"sha256":"262217d013318d9f147e0539f3b5d5726a1dfd0f13dfedff90c100e93d24e8d6","size":{"x":32,"y":1,"z":32}},{"blockCount":127,"bytes":3724,"file":"chunks/y124-z096-x096.json","offset":{"x":96,"y":124,"z":96},"requirements":{"minecraft:bricks":47,"minecraft:polished_diorite":76,"minecraft:sandstone":4},"sha256":"de03428479915038084dadd0c98df436c3386a2742aaaf842a30b0eb65573c4e","size":{"x":32,"y":1,"z":32}},{"blockCount":196,"bytes":4573,"file":"chunks/y124-z096-x128.json","offset":{"x":128,"y":124,"z":96},"requirements":{"minecraft:bricks":62,"minecraft:polished_diorite":128,"minecraft:sandstone":5,"minecraft:stone_bricks":1},"sha256":"ae0e17dea0215c9618cc7981aae66f99d4e4473d0d803dd089eff9eb6a911c91","size":{"x":32,"y":1,"z":32}},{"blockCount":162,"bytes":2717,"file":"chunks/y124-z096-x160.json","offset":{"x":160,"y":124,"z":96},"requirements":{"minecraft:bricks":32,"minecraft:polished_diorite":126,"minecraft:sandstone":2,"minecraft:stone_bricks":2},"sha256":"e1298312b7163d550a37aaae455b8d28ca50ccc8efdcc453282ac00a328ca6eb","size":{"x":32,"y":1,"z":32}},{"blockCount":327,"bytes":4873,"file":"chunks/y124-z096-x192.json","offset":{"x":192,"y":124,"z":96},"requirements":{"minecraft:bricks":131,"minecraft:glass":22,"minecraft:oak_planks":2,"minecraft:polished_diorite":151,"minecraft:sandstone":3,"minecraft:spruce_planks":16,"minecraft:stone_bricks":2},"sha256":"eebf3dcaec2d049d1fe3bc67dc48b929636dfcadd0f4a91763ad8fb9dd8ef57c","size":{"x":32,"y":1,"z":32}},{"blockCount":217,"bytes":4536,"file":"chunks/y124-z096-x224.json","offset":{"x":224,"y":124,"z":96},"requirements":{"minecraft:bricks":64,"minecraft:glass":39,"minecraft:oak_planks":6,"minecraft:polished_diorite":107,"minecraft:sandstone":1},"sha256":"8f0b0fd2cc375df8be4806929c88a0f3cf82df06e94bbfc46c2f994b89790696","size":{"x":32,"y":1,"z":32}},{"blockCount":22,"bytes":1254,"file":"chunks/y124-z128-x000.json","offset":{"x":0,"y":124,"z":128},"requirements":{"minecraft:polished_diorite":18,"minecraft:stone_bricks":4},"sha256":"09fa45539e3127d18ded41a80439f1feefd85e37e8f4ae30623d32c3fa04f35d","size":{"x":32,"y":1,"z":32}},{"blockCount":156,"bytes":3872,"file":"chunks/y124-z128-x032.json","offset":{"x":32,"y":124,"z":128},"requirements":{"minecraft:bricks":49,"minecraft:polished_diorite":96,"minecraft:sandstone":2,"minecraft:stone_bricks":9},"sha256":"62b8655a21d20eb6c8799e5fd69b50c6f7ab8d934df3a8d985fd1405157999cc","size":{"x":32,"y":1,"z":32}},{"blockCount":77,"bytes":1919,"file":"chunks/y124-z128-x064.json","offset":{"x":64,"y":124,"z":128},"requirements":{"minecraft:bricks":42,"minecraft:polished_diorite":33,"minecraft:sandstone":2},"sha256":"b9a9888c61be080ebedb0418b26986f76efa55b6da638734bcafc60da6f8648c","size":{"x":32,"y":1,"z":32}},{"blockCount":29,"bytes":1482,"file":"chunks/y124-z128-x096.json","offset":{"x":96,"y":124,"z":128},"requirements":{"minecraft:bricks":23,"minecraft:polished_diorite":4,"minecraft:sandstone":2},"sha256":"f606ce9efe6c576f44ca69019ee867795dbcbc929b90bff9bb7ba2acb1a4fb4b","size":{"x":32,"y":1,"z":32}},{"blockCount":70,"bytes":2073,"file":"chunks/y124-z128-x128.json","offset":{"x":128,"y":124,"z":128},"requirements":{"minecraft:bricks":42,"minecraft:polished_diorite":25,"minecraft:sandstone":3},"sha256":"92a54deec97f7fd610d181fbc188742feb75f905b9c2df898ca44cd5b4c94bf9","size":{"x":32,"y":1,"z":32}},{"blockCount":83,"bytes":1864,"file":"chunks/y124-z128-x160.json","offset":{"x":160,"y":124,"z":128},"requirements":{"minecraft:bricks":42,"minecraft:polished_diorite":39,"minecraft:sandstone":2},"sha256":"48c29c452be6e3a2d43069e8ca8013bb6e28afd48156209a87d63615ceabdcd2","size":{"x":32,"y":1,"z":32}},{"blockCount":86,"bytes":1959,"file":"chunks/y124-z128-x192.json","offset":{"x":192,"y":124,"z":128},"requirements":{"minecraft:bricks":45,"minecraft:polished_diorite":38,"minecraft:sandstone":3},"sha256":"8894ed38684a0c1ae8d6255a16116a95aab4221952404f9ca0543c7d7b551985","size":{"x":32,"y":1,"z":32}},{"blockCount":131,"bytes":3419,"file":"chunks/y124-z128-x224.json","offset":{"x":224,"y":124,"z":128},"requirements":{"minecraft:bricks":34,"minecraft:oak_planks":11,"minecraft:polished_diorite":64,"minecraft:sandstone":15,"minecraft:stone_bricks":7},"sha256":"ffdc970e43bb4d39c7e4a8c57fd75a208273e99417b18602653ebe15cbb325d4","size":{"x":32,"y":1,"z":32}},{"blockCount":9,"bytes":867,"file":"chunks/y124-z160-x000.json","offset":{"x":0,"y":124,"z":160},"requirements":{"minecraft:polished_diorite":8,"minecraft:stone_bricks":1},"sha256":"159f4fafb32da045d0b0c3426925922d0c076a0085bdefe7a2542c71c7349853","size":{"x":32,"y":1,"z":32}},{"blockCount":68,"bytes":1796,"file":"chunks/y124-z160-x032.json","offset":{"x":32,"y":124,"z":160},"requirements":{"minecraft:polished_diorite":64,"minecraft:stone_bricks":4},"sha256":"48cd1775410d241521644821e93d9c55a280358e4124ad11db891cfa20c28981","size":{"x":32,"y":1,"z":32}},{"blockCount":89,"bytes":1696,"file":"chunks/y124-z160-x064.json","offset":{"x":64,"y":124,"z":160},"requirements":{"minecraft:polished_diorite":87,"minecraft:stone_bricks":2},"sha256":"34437f7a76ccbfdafd744bf805d2aafb3210a6418322530e7237339ed706ef61","size":{"x":32,"y":1,"z":32}},{"blockCount":133,"bytes":3725,"file":"chunks/y124-z160-x096.json","offset":{"x":96,"y":124,"z":160},"requirements":{"minecraft:bricks":36,"minecraft:polished_diorite":95,"minecraft:sandstone":2},"sha256":"cdd3f8c5d36588e1b3f910d087321b3983d706c1dbc8374b9dadbfbbd5311650","size":{"x":32,"y":1,"z":32}},{"blockCount":175,"bytes":4212,"file":"chunks/y124-z160-x128.json","offset":{"x":128,"y":124,"z":160},"requirements":{"minecraft:bricks":36,"minecraft:polished_diorite":136,"minecraft:sandstone":2,"minecraft:stone_bricks":1},"sha256":"5fb7d204a1c969f8d66e4a459a7bd3105c56ee62b7262f4096851604a00af686","size":{"x":32,"y":1,"z":32}},{"blockCount":89,"bytes":1732,"file":"chunks/y124-z160-x160.json","offset":{"x":160,"y":124,"z":160},"requirements":{"minecraft:polished_diorite":87,"minecraft:stone_bricks":2},"sha256":"749e87d66c15630535bfe4367c29be6c40bc07d6413b80b2549c9da80861835c","size":{"x":32,"y":1,"z":32}},{"blockCount":261,"bytes":4143,"file":"chunks/y124-z160-x192.json","offset":{"x":192,"y":124,"z":160},"requirements":{"minecraft:bricks":95,"minecraft:glass":22,"minecraft:oak_planks":2,"minecraft:polished_diorite":124,"minecraft:spruce_planks":16,"minecraft:stone_bricks":2},"sha256":"dfcb1920a728abb1cca500df83bb0cfb630334b2ec02e123430313b36642260c","size":{"x":32,"y":1,"z":32}},{"blockCount":199,"bytes":4264,"file":"chunks/y124-z160-x224.json","offset":{"x":224,"y":124,"z":160},"requirements":{"minecraft:bricks":55,"minecraft:glass":39,"minecraft:oak_planks":6,"minecraft:polished_diorite":99},"sha256":"c0372657a791e583cb8f04f1df9db18f6cad4171199843fdc1ea8f85cb6c0059","size":{"x":32,"y":1,"z":32}},{"blockCount":18,"bytes":1104,"file":"chunks/y124-z192-x064.json","offset":{"x":64,"y":124,"z":192},"requirements":{"minecraft:polished_diorite":16,"minecraft:stone_bricks":2},"sha256":"41ded3fa59537f2ad6b4768a7a659c45db3b4582f49dc44fabd6f9c4909b2f19","size":{"x":32,"y":1,"z":32}},{"blockCount":183,"bytes":3580,"file":"chunks/y124-z192-x096.json","offset":{"x":96,"y":124,"z":192},"requirements":{"minecraft:bricks":42,"minecraft:oak_planks":8,"minecraft:polished_diorite":112,"minecraft:sandstone":14,"minecraft:stone_bricks":7},"sha256":"c47e26db92750edfdcc2ff0f398d9dc5d047f1a97c9684da34b87a6c0cf5fd91","size":{"x":32,"y":1,"z":32}},{"blockCount":146,"bytes":3609,"file":"chunks/y124-z192-x128.json","offset":{"x":128,"y":124,"z":192},"requirements":{"minecraft:bricks":31,"minecraft:oak_planks":3,"minecraft:polished_diorite":106,"minecraft:sandstone":3,"minecraft:stone_bricks":3},"sha256":"8ad1b2377a13d311b4719330325e0c8d24688fe8c1e26c616fa953efe3bf5ae7","size":{"x":32,"y":1,"z":32}},{"blockCount":20,"bytes":1180,"file":"chunks/y125-z064-x064.json","offset":{"x":64,"y":125,"z":64},"requirements":{"minecraft:polished_diorite":9,"minecraft:stone_bricks":11},"sha256":"91cd08b5e7f0f0838502b97bc05bd884816fc4ce06b9cf71f5fd306a70021161","size":{"x":32,"y":1,"z":32}},{"blockCount":227,"bytes":4444,"file":"chunks/y125-z064-x096.json","offset":{"x":96,"y":125,"z":64},"requirements":{"minecraft:bricks":59,"minecraft:oak_planks":10,"minecraft:polished_diorite":109,"minecraft:sandstone":10,"minecraft:stone_bricks":39},"sha256":"9e191cf20ef00e1d312ab588ea307126c48bf7e96c0d12014df450ca47fefa07","size":{"x":32,"y":1,"z":32}},{"blockCount":198,"bytes":4355,"file":"chunks/y125-z064-x128.json","offset":{"x":128,"y":125,"z":64},"requirements":{"minecraft:bricks":45,"minecraft:oak_planks":3,"minecraft:polished_diorite":107,"minecraft:sandstone":2,"minecraft:stone_bricks":41},"sha256":"1dfe31d0dc10d2a83bee2c6292bb071d742234358481b9f5ab1fbe3c94ffacae","size":{"x":32,"y":1,"z":32}},{"blockCount":10,"bytes":917,"file":"chunks/y125-z064-x192.json","offset":{"x":192,"y":125,"z":64},"requirements":{"minecraft:polished_diorite":10},"sha256":"2b81b5cb92faddadebf84af621e37cdb8e50e1578e176fbcd411f1a21f278113","size":{"x":32,"y":1,"z":32}}],"schema":1}
