{"entries":[{"blockCount":15,"bytes":1071,"file":"chunks/y125-z064-x224.json","offset":{"x":224,"y":125,"z":64},"requirements":{"minecraft:polished_diorite":15},"sha256":"18e3c64b14a884fc5ffc4fc3468db64b7d842fbac227e1b0cf98cf6c491fc33b","size":{"x":32,"y":1,"z":32}},{"blockCount":14,"bytes":1042,"file":"chunks/y125-z096-x000.json","offset":{"x":0,"y":125,"z":96},"requirements":{"minecraft:polished_diorite":8,"minecraft:stone_bricks":6},"sha256":"a5258d784a415f17001da05fcb7d8c8b86e5d35dacfee163a63813d166035a6c","size":{"x":32,"y":1,"z":32}},{"blockCount":135,"bytes":2830,"file":"chunks/y125-z096-x032.json","offset":{"x":32,"y":125,"z":96},"requirements":{"minecraft:bricks":14,"minecraft:polished_diorite":77,"minecraft:stone_bricks":44},"sha256":"7e7f0d8c06317bf6b7e471596858f2830e4833ae6c5df1ec46b3473c9eab560e","size":{"x":32,"y":1,"z":32}},{"blockCount":166,"bytes":2712,"file":"chunks/y125-z096-x064.json","offset":{"x":64,"y":125,"z":96},"requirements":{"minecraft:bricks":36,"minecraft:polished_diorite":90,"minecraft:stone_bricks":40},"sha256":"c4f07773cdb772f3c6c2960a1f2e86dbbf1169ccec3327e333f225a9abd6b5e2","size":{"x":32,"y":1,"z":32}},{"blockCount":166,"bytes":3995,"file":"chunks/y125-z096-x096.json","offset":{"x":96,"y":125,"z":96},"requirements":{"minecraft:bricks":57,"minecraft:glass":2,"minecraft:polished_diorite":87,"minecraft:stone_bricks":20},"sha256":"6cf306efbbca82efd7c89a7674f04535023f55434c358315737ded36fee4d783","size":{"x":32,"y":1,"z":32}},{"blockCount":258,"bytes":4796,"file":"chunks/y125-z096-x128.json","offset":{"x":128,"y":125,"z":96},"requirements":{"minecraft:bricks":76,"minecraft:glass":3,"minecraft:polished_diorite":140,"minecraft:stone_bricks":39},"sha256":"a0ff0cf8a1a292fde13fd533eb900b7c544699b40b1365ef572e41cc0be7acf6","size":{"x":32,"y":1,"z":32}},{"blockCount":170,"bytes":2904,"file":"chunks/y125-z096-x160.json","offset":{"x":160,"y":125,"z":96},"requirements":{"minecraft:bricks":37,"minecraft:polished_diorite":92,"minecraft:stone_bricks":41},"sha256":"dfaf6358624914e340844092a2a9c5751a86fa43cfd0f40d98070a80f540c870","size":{"x":32,"y":1,"z":32}},{"blockCount":394,"bytes":4617,"file":"chunks/y125-z096-x192.json","offset":{"x":192,"y":125,"z":96},"requirements":{"minecraft:bricks":97,"minecraft:polished_diorite":122,"minecraft:spruce_planks":152,"minecraft:stone_bricks":23},"sha256":"b211e855e86e7adc0170d5d3507d32542d665e3077c6de897d795e8d1014f269","size":{"x":32,"y":1,"z":32}},{"blockCount":385,"bytes":3533,"file":"chunks/y125-z096-x224.json","offset":{"x":224,"y":125,"z":96},"requirements":{"minecraft:bricks":65,"minecraft:polished_diorite":110,"minecraft:sandstone":1,"minecraft:spruce_planks":209},"sha256":"2ed21f4872a332acf95122b6aff93e2700c1a7966530fe8af666c913a718e568","size":{"x":32,"y":1,"z":32}},{"blockCount":25,"bytes":1372,"file":"chunks/y125-z128-x000.json","offset":{"x":0,"y":125,"z":128},"requirements":{"minecraft:polished_diorite":14,"minecraft:stone_bricks":11},"sha256":"91546dff3334be7becc86b4eccfaf036f0bb159c3bec18caa96a61ddb8d9bafa","size":{"x":32,"y":1,"z":32}},{"blockCount":190,"bytes":3859,"file":"chunks/y125-z128-x032.json","offset":{"x":32,"y":125,"z":128},"requirements":{"minecraft:bricks":46,"minecraft:polished_diorite":94,"minecraft:stone_bricks":50},"sha256":"470ade99664daf0eddccc1465d7b04e6d0eda0d024f453a8d296418be1511de1","size":{"x":32,"y":1,"z":32}},{"blockCount":98,"bytes":2321,"file":"chunks/y125-z128-x064.json","offset":{"x":64,"y":125,"z":128},"requirements":{"minecraft:bricks":56,"minecraft:glass":4,"minecraft:polished_diorite":38},"sha256":"efeb62b2d5f572252bdbb85df9743927feef840bec2b8b2470e089397ea0bdcc","size":{"x":32,"y":1,"z":32}},{"blockCount":40,"bytes":1653,"file":"chunks/y125-z128-x096.json","offset":{"x":96,"y":125,"z":128},"requirements":{"minecraft:bricks":30,"minecraft:glass":3,"minecraft:polished_diorite":7},"sha256":"40d9abedb50008a5c5ec2e257e7923d7a3fcaf682daa0cf0a4f007a053abfee4","size":{"x":32,"y":1,"z":32}},{"blockCount":84,"bytes":2321,"file":"chunks/y125-z128-x128.json","offset":{"x":128,"y":125,"z":128},"requirements":{"minecraft:bricks":54,"minecraft:glass":5,"minecraft:polished_diorite":25},"sha256":"a751e035b55737efe0cc07757da7744e074545cd7b61e5a2b3002d920ccb9848","size":{"x":32,"y":1,"z":32}},{"blockCount":100,"bytes":2361,"file":"chunks/y125-z128-x160.json","offset":{"x":160,"y":125,"z":128},"requirements":{"minecraft:bricks":57,"minecraft:glass":4,"minecraft:polished_diorite":39},"sha256":"4378989e01a9087c8b75c2c079bac07ca4ecce07f1b1be9aa45f5099192c36a2","size":{"x":32,"y":1,"z":32}},{"blockCount":94,"bytes":2226,"file":"chunks/y125-z128-x192.json","offset":{"x":192,"y":125,"z":128},"requirements":{"minecraft:bricks":54,"minecraft:glass":2,"minecraft:polished_diorite":38},"sha256":"c80802e18b067832a7b7b7c6ddea2928fc0b4dbdbe3c6d1f31fb8f4f0084faf8","size":{"x":32,"y":1,"z":32}},{"blockCount":134,"bytes":3572,"file":"chunks/y125-z128-x224.json","offset":{"x":224,"y":125,"z":128},"requirements":{"minecraft:bricks":38,"minecraft:oak_planks":13,"minecraft:polished_diorite":59,"minecraft:sandstone":11,"minecraft:stone_bricks":13},"sha256":"9000cdc17a3251649b0610345a22e919f14839dd0097c31fad0f09bc514e83b1","size":{"x":32,"y":1,"z":32}},{"blockCount":9,"bytes":867,"file":"chunks/y125-z160-x000.json","offset":{"x":0,"y":125,"z":160},"requirements":{"minecraft:polished_diorite":4,"minecraft:stone_bricks":5},"sha256":"5f1f496d07babaab614a0d8bb11576a790437f0477267fa5dedda94b68f2f4fb","size":{"x":32,"y":1,"z":32}},{"blockCount":66,"bytes":1909,"file":"chunks/y125-z160-x032.json","offset":{"x":32,"y":125,"z":160},"requirements":{"minecraft:polished_diorite":35,"minecraft:stone_bricks":31},"sha256":"d2930352487d75b18cffc32a932ca2dfe44fe6bc42bb93b42aebef3fdca9bdf0","size":{"x":32,"y":1,"z":32}},{"blockCount":94,"bytes":1979,"file":"chunks/y125-z160-x064.json","offset":{"x":64,"y":125,"z":160},"requirements":{"minecraft:polished_diorite":53,"minecraft:stone_bricks":41},"sha256":"85ceaa93f5122ff2208477ce4072d403fe086aa913317b3e6a9288be58cd40d1","size":{"x":32,"y":1,"z":32}},{"blockCount":170,"bytes":4148,"file":"chunks/y125-z160-x096.json","offset":{"x":96,"y":125,"z":160},"requirements":{"minecraft:bricks":45,"minecraft:glass":2,"minecraft:polished_diorite":95,"minecraft:stone_bricks":28},"sha256":"d05ce447c51eacab14f1b18cece87520c9a9c1ace5caa33d013087291de22b77","size":{"x":32,"y":1,"z":32}},{"blockCount":216,"bytes":4606,"file":"chunks/y125-z160-x128.json","offset":{"x":128,"y":125,"z":160},"requirements":{"minecraft:bricks":44,"minecraft:glass":2,"minecraft:polished_diorite":122,"minecraft:stone_bricks":48},"sha256":"d4e1769af297aabbe3414c7b629c2f32aa622b055161f61bcae41389f6fd38c9","size":{"x":32,"y":1,"z":32}},{"blockCount":87,"bytes":2053,"file":"chunks/y125-z160-x160.json","offset":{"x":160,"y":125,"z":160},"requirements":{"minecraft:polished_diorite":46,"minecraft:stone_bricks":41},"sha256":"5eb29e75b50a48a20c08d8601c715499508a68b8f57dc2bd3650c630962592f4","size":{"x":32,"y":1,"z":32}},{"blockCount":326,"bytes":4021,"file":"chunks/y125-z160-x192.json","offset":{"x":192,"y":125,"z":160},"requirements":{"minecraft:bricks":58,"minecraft:polished_diorite":93,"minecraft:spruce_planks":152,"minecraft:stone_bricks":23},"sha256":"563e7971f07220a64250fb1b05a6eb76c2054261987f23fbefba6dc6c6c6334c","size":{"x":32,"y":1,"z":32}},{"blockCount":364,"bytes":3280,"file":"chunks/y125-z160-x224.json","offset":{"x":224,"y":125,"z":160},"requirements":{"minecraft:bricks":56,"minecraft:polished_diorite":99,"minecraft:spruce_planks":209},"sha256":"8fd25e229b1cbaee12bb442d377925727ee91c44cc9a901cc84799d5c160fa3d","size":{"x":32,"y":1,"z":32}},{"blockCount":18,"bytes":1104,"file":"chunks/y125-z192-x064.json","offset":{"x":64,"y":125,"z":192},"requirements":{"minecraft:polished_diorite":8,"minecraft:stone_bricks":10},"sha256":"9893e3a912cd434d2068b456781295c6313ca1f5bffbab4f376715132b6fdc69","size":{"x":32,"y":1,"z":32}},{"blockCount":193,"bytes":3601,"file":"chunks/y125-z192-x096.json","offset":{"x":96,"y":125,"z":192},"requirements":{"minecraft:bricks":48,"minecraft:oak_planks":10,"minecraft:polished_diorite":94,"minecraft:sandstone":10,"minecraft:stone_bricks":31},"sha256":"a7fcd452fc1059d07607cf3cf8ff29e617789182f06f038cf1965d91077a962b","size":{"x":32,"y":1,"z":32}},{"blockCount":157,"bytes":3572,"file":"chunks/y125-z192-x128.json","offset":{"x":128,"y":125,"z":192},"requirements":{"minecraft:bricks":35,"minecraft:oak_planks":3,"minecraft:polished_diorite":85,"minecraft:sandstone":2,"minecraft:stone_bricks":32},"sha256":"11bcf3a512cb7ba2dfe0ac5389b6730a636ba00f35bd25e247644cb527c34a1a","size":{"x":32,"y":1,"z":32}},{"blockCount":20,"bytes":1180,"file":"chunks/y126-z064-x064.json","offset":{"x":64,"y":126,"z":64},"requirements":{"minecraft:polished_diorite":9,"minecraft:stone_bricks":11},"sha256":"f0d01051df016d6d95113a1db45b0b5b9854038facfc86872bf91a627360b9e7","size":{"x":32,"y":1,"z":32}},{"blockCount":224,"bytes":5238,"file":"chunks/y126-z064-x096.json","offset":{"x":96,"y":126,"z":64},"requirements":{"minecraft:bricks":52,"minecraft:cobbled_deepslate":23,"minecraft:glass":14,"minecraft:oak_planks":10,"minecraft:polished_diorite":77,"minecraft:sandstone":10,"minecraft:stone_bricks":38},"sha256":"abb7c8a90f88cc37c57a15888308881df80abc61522291495208eea7e72c378e","size":{"x":32,"y":1,"z":32}},{"blockCount":184,"bytes":5144,"file":"chunks/y126-z064-x128.json","offset":{"x":128,"y":126,"z":64},"requirements":{"minecraft:bricks":38,"minecraft:cobbled_deepslate":24,"minecraft:oak_planks":2,"minecraft:polished_diorite":64,"minecraft:sandstone":3,"minecraft:stone_bricks":53},"sha256":"dcc3a3f347af851f4a367e8dad4ff5bec46b6a8852c3dbbd47b07a4316d617b8","size":{"x":32,"y":1,"z":32}},{"blockCount":24,"bytes":1078,"file":"chunks/y126-z064-x192.json","offset":{"x":192,"y":126,"z":64},"requirements":{"minecraft:polished_diorite":11,"minecraft:stone_bricks":13},"sha256":"4844c2face2e5a6a3cc40f2c539d2f253ee1d59339cf5b8456c911da41f6aa07","size":{"x":32,"y":1,"z":32}},{"blockCount":32,"bytes":1288,"file":"chunks/y126-z064-x224.json","offset":{"x":224,"y":126,"z":64},"requirements":{"minecraft:polished_diorite":15,"minecraft:stone_bricks":17},"sha256":"22be87e4e667cf2d7885b6dcc6d13454b8edae3772d66d23e8bff431053a2115","size":{"x":32,"y":1,"z":32}},{"blockCount":14,"bytes":1042,"file":"chunks/y126-z096-x000.json","offset":{"x":0,"y":126,"z":96},"requirements":{"minecraft:polished_diorite":7,"minecraft:stone_bricks":7},"sha256":"20654dd111c5e25d171504a808bfbf1918feded4d4970a3ab17f85dfc7f99baa","size":{"x":32,"y":1,"z":32}},{"blockCount":127,"bytes":3305,"file":"chunks/y126-z096-x032.json","offset":{"x":32,"y":126,"z":96},"requirements":{"minecraft:bricks":13,"minecraft:cobbled_deepslate":21,"minecraft:glass":20,"minecraft:polished_diorite":41,"minecraft:sandstone":1,"minecraft:stone_bricks":31},"sha256":"8aa047b8e33d5e9773fda2eaa9554906d37403b45765884f314a07fdd8af39f3","size":{"x":32,"y":1,"z":32}},{"blockCount":147,"bytes":3158,"file":"chunks/y126-z096-x064.json","offset":{"x":64,"y":126,"z":96},"requirements":{"minecraft:bricks":35,"minecraft:cobbled_deepslate":29,"minecraft:glass":17,"minecraft:polished_diorite":39,"minecraft:stone_bricks":27},"sha256":"7dae101663cf527bd72c0dad016bd0e83c2ae24c7c0ef2ed4cf4a7b7ff38c45a","size":{"x":32,"y":1,"z":32}},{"blockCount":127,"bytes":4466,"file":"chunks/y126-z096-x096.json","offset":{"x":96,"y":126,"z":96},"requirements":{"minecraft:bricks":50,"minecraft:cobbled_deepslate":30,"minecraft:glass":15,"minecraft:polished_diorite":20,"minecraft:stone_bricks":12},"sha256":"5848709e507425db99c2a68bf651a3124a4e5247adff1ede9c6eaec303319f3b","size":{"x":32,"y":1,"z":32}},{"blockCount":197,"bytes":5527,"file":"chunks/y126-z096-x128.json","offset":{"x":128,"y":126,"z":96},"requirements":{"minecraft:bricks":69,"minecraft:cobbled_deepslate":43,"minecraft:glass":25,"minecraft:polished_diorite":36,"minecraft:stone_bricks":24},"sha256":"1d3480bbf5ad1e52bd1246caae0a69f591b2d0ebbbb9b0c17eae7a358c0121f9","size":{"x":32,"y":1,"z":32}},{"blockCount":148,"bytes":3293,"file":"chunks/y126-z096-x160.json","offset":{"x":160,"y":126,"z":96},"requirements":{"minecraft:bricks":34,"minecraft:cobbled_deepslate":30,"minecraft:glass":15,"minecraft:polished_diorite":41,"minecraft:stone_bricks":28},"sha256":"0b954b0b21c3aefc6f4e1a78cef04b048362fd254802f9b1e8d8adc752b93807","size":{"x":32,"y":1,"z":32}},{"blockCount":278,"bytes":5307,"file":"chunks/y126-z096-x192.json","offset":{"x":192,"y":126,"z":96},"requirements":{"minecraft:bricks":93,"minecraft:cobbled_deepslate":26,"minecraft:glass":21,"minecraft:polished_diorite":77,"minecraft:spruce_planks":4,"minecraft:stone_bricks":57},"sha256":"587cd4c6fb27c9bd2c4bf954bd907e1163e64eb8f5829ee76ad3a240cc11475c","size":{"x":32,"y":1,"z":32}},{"blockCount":201,"bytes":4265,"file":"chunks/y126-z096-x224.json","offset":{"x":224,"y":126,"z":96},"requirements":{"minecraft:bricks":64,"minecraft:cobbled_deepslate":3,"minecraft:glass":4,"minecraft:polished_diorite":87,"minecraft:sandstone":2,"minecraft:stone_bricks":41},"sha256":"28929d491e756c78f257e5449002d627c2b45bed4a1999ad8a5d0c5430b2a03c","size":{"x":32,"y":1,"z":32}},{"blockCount":25,"bytes":1396,"file":"chunks/y126-z128-x000.json","offset":{"x":0,"y":126,"z":128},"requirements":{"minecraft:polished_diorite":11,"minecraft:sandstone":2,"minecraft:stone_bricks":12},"sha256":"e07d557d710894953db12bb86812473fe588b6891f74d6405bdfd9b6b167b708","size":{"x":32,"y":1,"z":32}},{"blockCount":163,"bytes":4927,"file":"chunks/y126-z128-x032.json","offset":{"x":32,"y":126,"z":128},"requirements":{"minecraft:bricks":41,"minecraft:cobbled_deepslate":46,"minecraft:glass":35,"minecraft:polished_diorite":24,"minecraft:stone_bricks":17},"sha256":"a37e93b725c83c2cc2968e6e35928e8d28824bf303e5cbd7fbaa39dc7702e55d","size":{"x":32,"y":1,"z":32}},{"blockCount":91,"bytes":2298,"file":"chunks/y126-z128-x064.json","offset":{"x":64,"y":126,"z":128},"requirements":{"minecraft:bricks":45,"minecraft:cobbled_deepslate":26,"minecraft:glass":4,"minecraft:polished_diorite":5,"minecraft:stone_bricks":11},"sha256":"9efb3214e256fe1c6bec52bf91d86cd6d9f358f72cba013d1f0a7e46320e6f16","size":{"x":32,"y":1,"z":32}},{"blockCount":36,"bytes":1577,"file":"chunks/y126-z128-x096.json","offset":{"x":96,"y":126,"z":128},"requirements":{"minecraft:bricks":25,"minecraft:cobbled_deepslate":8,"minecraft:glass":3},"sha256":"95abe4822aa28d48f7905a4c36d9ea4a145756021b26ef2f5cfd93d59ee0f6fd","size":{"x":32,"y":1,"z":32}},{"blockCount":77,"bytes":2207,"file":"chunks/y126-z128-x128.json","offset":{"x":128,"y":126,"z":128},"requirements":{"minecraft:bricks":45,"minecraft:cobbled_deepslate":22,"minecraft:glass":5,"minecraft:polished_diorite":2,"minecraft:stone_bricks":3},"sha256":"4c50173807ac1df373d58ae23ff3da98b0c7fa8618f06b6f619d284ac1feecb7","size":{"x":32,"y":1,"z":32}},{"blockCount":90,"bytes":2263,"file":"chunks/y126-z128-x160.json","offset":{"x":160,"y":126,"z":128},"requirements":{"minecraft:bricks":44,"minecraft:cobbled_deepslate":26,"minecraft:glass":4,"minecraft:polished_diorite":5,"minecraft:stone_bricks":11},"sha256":"473ef5ea4d26ab5e960417fe4e67c2e5a47106c911dacccb99f5206c8c618034","size":{"x":32,"y":1,"z":32}},{"blockCount":94,"bytes":2203,"file":"chunks/y126-z128-x192.json","offset":{"x":192,"y":126,"z":128},"requirements":{"minecraft:bricks":43,"minecraft:cobbled_deepslate":28,"minecraft:glass":2,"minecraft:polished_diorite":7,"minecraft:stone_bricks":14},"sha256":"684ca13fc533da6c87f127930b5d7b536bd444ffe26f751181e29af0f44e7934","size":{"x":32,"y":1,"z":32}},{"blockCount":165,"bytes":3908,"file":"chunks/y126-z128-x224.json","offset":{"x":224,"y":126,"z":128},"requirements":{"minecraft:bricks":35,"minecraft:cobbled_deepslate":2,"minecraft:oak_planks":12,"minecraft:polished_diorite":66,"minecraft:sandstone":11,"minecraft:stone_bricks":39},"sha256":"1d4d39f527c78f4109796b78c4770636411350123b2cb90cc303244504b7cd2b","size":{"x":32,"y":1,"z":32}},{"blockCount":9,"bytes":867,"file":"chunks/y126-z160-x000.json","offset":{"x":0,"y":126,"z":160},"requirements":{"minecraft:polished_diorite":4,"minecraft:stone_bricks":5},"sha256":"53b9d37b87866a34d60e78c91bb5a1454a918572e38f654cdd76c5a6cb511e59","size":{"x":32,"y":1,"z":32}},{"blockCount":59,"bytes":2067,"file":"chunks/y126-z160-x032.json","offset":{"x":32,"y":126,"z":160},"requirements":{"minecraft:glass":8,"minecraft:polished_diorite":29,"minecraft:sandstone":1,"minecraft:stone_bricks":21},"sha256":"46d2d81fdb2279af3c674dc4ae4e7abb450176021d2618d5163d032d0b3dca94","size":{"x":32,"y":1,"z":32}},{"blockCount":72,"bytes":2228,"file":"chunks/y126-z160-x064.json","offset":{"x":64,"y":126,"z":160},"requirements":{"minecraft:glass":17,"minecraft:polished_diorite":35,"minecraft:stone_bricks":20},"sha256":"07446b9fb1ba1acdfb15909fc19ede4d49df84e3cb9b1c9141526729a63b001f","size":{"x":32,"y":1,"z":32}},{"blockCount":129,"bytes":4771,"file":"chunks/y126-z160-x096.json","offset":{"x":96,"y":126,"z":160},"requirements":{"minecraft:bricks":40,"minecraft:cobbled_deepslate":30,"minecraft:glass":19,"minecraft:polished_diorite":26,"minecraft:stone_bricks":14},"sha256":"c8e5b0d8019073313a53f755efd905b5c70f18c6b5955ac697c01b87d81b9100","size":{"x":32,"y":1,"z":32}},{"blockCount":161,"bytes":5398,"file":"chunks/y126-z160-x128.json","offset":{"x":128,"y":126,"z":160},"requirements":{"minecraft:bricks":39,"minecraft:cobbled_deepslate":30,"minecraft:glass":17,"minecraft:polished_diorite":41,"minecraft:stone_bricks":34},"sha256":"13e5ca330fa075240a0cb0c0870b35da1dea0801298f6965786ef7bda5b17d7f","size":{"x":32,"y":1,"z":32}},{"blockCount":72,"bytes":2264,"file":"chunks/y126-z160-x160.json","offset":{"x":160,"y":126,"z":160},"requirements":{"minecraft:glass":15,"minecraft:polished_diorite":36,"minecraft:stone_bricks":21},"sha256":"f3244b3505506ce347411e768198ea767a6512849c8a7e5541b888f156cb7c1d","size":{"x":32,"y":1,"z":32}},{"blockCount":218,"bytes":4590,"file":"chunks/y126-z160-x192.json","offset":{"x":192,"y":126,"z":160},"requirements":{"minecraft:bricks":58,"minecraft:glass":21,"minecraft:polished_diorite":81,"minecraft:spruce_planks":4,"minecraft:stone_bricks":54},"sha256":"8ecc6f27a29cb6023852348faa77b5275743ad6033da9ef6cd99286022cead2e","size":{"x":32,"y":1,"z":32}},{"blockCount":179,"bytes":3866,"file":"chunks/y126-z160-x224.json","offset":{"x":224,"y":126,"z":160},"requirements":{"minecraft:bricks":58,"minecraft:glass":4,"minecraft:polished_diorite":78,"minecraft:stone_bricks":39},"sha256":"3ab92d58c5ffd588aef3643dcf465a15799cb4dd32329b45e068946f6b29a6a2","size":{"x":32,"y":1,"z":32}},{"blockCount":18,"bytes":1104,"file":"chunks/y126-z192-x064.json","offset":{"x":64,"y":126,"z":192},"requirements":{"minecraft:polished_diorite":8,"minecraft:stone_bricks":10},"sha256":"0f87e5a07c42a9b036b108720298a5218e9b195839c13e61961569a1bdb06a76","size":{"x":32,"y":1,"z":32}},{"blockCount":194,"bytes":4225,"file":"chunks/y126-z192-x096.json","offset":{"x":96,"y":126,"z":192},"requirements":{"minecraft:bricks":42,"minecraft:cobbled_deepslate":17,"minecraft:glass":10,"minecraft:oak_planks":10,"minecraft:polished_diorite":71,"minecraft:sandstone":10,"minecraft:stone_bricks":34},"sha256":"efa81e0e88a3679f4385c7bbe9a0ccc8eda53f9db99a52ae23facc5b2fb5aa68","size":{"x":32,"y":1,"z":32}},{"blockCount":153,"bytes":4191,"file":"chunks/y126-z192-x128.json","offset":{"x":128,"y":126,"z":192},"requirements":{"minecraft:bricks":29,"minecraft:cobbled_deepslate":18,"minecraft:oak_planks":2,"minecraft:polished_diorite":57,"minecraft:sandstone":3,"minecraft:stone_bricks":44},"sha256":"695b081ac0e5034112c0bc3a44a45e7019278e9bba3d628db8c2f4700884eae9","size":{"x":32,"y":1,"z":32}},{"blockCount":20,"bytes":1180,"file":"chunks/y127-z064-x064.json","offset":{"x":64,"y":127,"z":64},"requirements":{"minecraft:polished_diorite":18,"minecraft:stone_bricks":2},"sha256":"c83dc8c6e260727c9972d772e21af8636f55caa419e05279d0dbaede4152a040","size":{"x":32,"y":1,"z":32}},{"blockCount":187,"bytes":5519,"file":"chunks/y127-z064-x096.json","offset":{"x":96,"y":127,"z":64},"requirements":{"minecraft:bricks":42,"minecraft:cobbled_deepslate":22,"minecraft:oak_planks":7,"minecraft:polished_diorite":59,"minecraft:sandstone":13,"minecraft:stone_bricks":44},"sha256":"539f0180e221dbd4dae3f3bbf93dfd870f2204dd00c8791360832325def659f3","size":{"x":32,"y":1,"z":32}},{"blockCount":149,"bytes":5334,"file":"chunks/y127-z064-x128.json","offset":{"x":128,"y":127,"z":64},"requirements":{"minecraft:bricks":33,"minecraft:cobbled_deepslate":22,"minecraft:oak_planks":2,"minecraft:polished_diorite":49,"minecraft:sandstone":3,"minecraft:stone_bricks":40},"sha256":"77db13747caa181d9f9836e997bd4b8edc3a85700cb4cf4f8fcdf90e220786b5","size":{"x":32,"y":1,"z":32}},{"blockCount":16,"bytes":1096,"file":"chunks/y127-z064-x192.json","offset":{"x":192,"y":127,"z":64},"requirements":{"minecraft:polished_diorite":11,"minecraft:stone_bricks":5},"sha256":"cca064dd0d871ffca3f0f4aa0e12db9a5f9a155aa21b81190537fd34d165748d","size":{"x":32,"y":1,"z":32}},{"blockCount":21,"bytes":1288,"file":"chunks/y127-z064-x224.json","offset":{"x":224,"y":127,"z":64},"requirements":{"minecraft:polished_diorite":15,"minecraft:stone_bricks":6},"sha256":"576a927e6438282f3a80c14fa1cb673ef1bb68be064e35e434271e514c8d6a18","size":{"x":32,"y":1,"z":32}},{"blockCount":13,"bytes":1004,"file":"chunks/y127-z096-x000.json","offset":{"x":0,"y":127,"z":96},"requirements":{"minecraft:polished_diorite":11,"minecraft:stone_bricks":2},"sha256":"2c94bdb2b47b1396c605502672e18cfadfef8c85d4648038b3f9933524636234","size":{"x":32,"y":1,"z":32}},{"blockCount":108,"bytes":3209,"file":"chunks/y127-z096-x032.json","offset":{"x":32,"y":127,"z":96},"requirements":{"minecraft:bricks":12,"minecraft:cobbled_deepslate":20,"minecraft:polished_diorite":39,"minecraft:sandstone":1,"minecraft:stone_bricks":36},"sha256":"5c6431c1333bc89356adbbc3f4c6b9c4f676360521d21ff3e35c48eb074f34d6","size":{"x":32,"y":1,"z":32}},{"blockCount":133,"bytes":2934,"file":"chunks/y127-z096-x064.json","offset":{"x":64,"y":127,"z":96},"requirements":{"minecraft:bricks":34,"minecraft:cobbled_deepslate":29,"minecraft:polished_diorite":32,"minecraft:sandstone":2,"minecraft:stone_bricks":36},"sha256":"44a5e5eb930c1d5ff77522a98913e44d484839179f8a0d51952d9e1cc2581d65","size":{"x":32,"y":1,"z":32}},{"blockCount":123,"bytes":4717,"file":"chunks/y127-z096-x096.json","offset":{"x":96,"y":127,"z":96},"requirements":{"minecraft:bricks":50,"minecraft:cobbled_deepslate":28,"minecraft:glass":2,"minecraft:polished_diorite":11,"minecraft:sandstone":5,"minecraft:stone_bricks":27},"sha256":"04fb0fa7007e2c971d6db959f5706196ca7e47d4ddc75bfc4cb5262b4dd0efbf","size":{"x":32,"y":1,"z":32}},{"blockCount":187,"bytes":5702,"file":"chunks/y127-z096-x128.json","offset":{"x":128,"y":127,"z":96},"requirements":{"minecraft:bricks":68,"minecraft:cobbled_deepslate":43,"minecraft:glass":3,"minecraft:polished_diorite":24,"minecraft:sandstone":6,"minecraft:stone_bricks":43},"sha256":"64e192b6f33bd2b1683ef9f9f7e00e3ad12f76131cccbec1699d32dc70daf141","size":{"x":32,"y":1,"z":32}},{"blockCount":135,"bytes":3070,"file":"chunks/y127-z096-x160.json","offset":{"x":160,"y":127,"z":96},"requirements":{"minecraft:bricks":34,"minecraft:cobbled_deepslate":29,"minecraft:polished_diorite":35,"minecraft:sandstone":2,"minecraft:stone_bricks":35},"sha256":"9c77d64f74eecdb3591863b4562f06f00d4f352e6dd318106c9edfee77648367","size":{"x":32,"y":1,"z":32}},{"blockCount":244,"bytes":5142,"file":"chunks/y127-z096-x192.json","offset":{"x":192,"y":127,"z":96},"requirements":{"minecraft:bricks":70,"minecraft:cobbled_deepslate":32,"minecraft:glass":5,"minecraft:polished_diorite":81,"minecraft:sandstone":3,"minecraft:spruce_planks":17,"minecraft:stone_bricks":36},"sha256":"ba91c16d532622115151f77e91a4aba52fd9d39f0bef0c044ed701e3962910d4","size":{"x":32,"y":1,"z":32}},{"blockCount":152,"bytes":4167,"file":"chunks/y127-z096-x224.json","offset":{"x":224,"y":127,"z":96},"requirements":{"minecraft:bricks":43,"minecraft:cobbled_deepslate":5,"minecraft:glass":14,"minecraft:polished_diorite":71,"minecraft:sandstone":1,"minecraft:stone_bricks":18},"sha256":"a1365e01c979ba144f0d858d7edb774fec25b0fc5663b1a0672a45d0bd2c735b","size":{"x":32,"y":1,"z":32}},{"blockCount":22,"bytes":1254,"file":"chunks/y127-z128-x000.json","offset":{"x":0,"y":127,"z":128},"requirements":{"minecraft:polished_diorite":15,"minecraft:stone_bricks":7},"sha256":"0428093ae2534c8aa93be8ff85cc86ddae3928831b029342899f58802dfef37b","size":{"x":32,"y":1,"z":32}},{"blockCount":143,"bytes":4911,"file":"chunks/y127-z128-x032.json","offset":{"x":32,"y":127,"z":128},"requirements":{"minecraft:bricks":43,"minecraft:cobbled_deepslate":46,"minecraft:polished_diorite":14,"minecraft:sandstone":2,"minecraft:stone_bricks":38},"sha256":"7e235b90a654a21a9ea594305b89beafa66171c66176e661a46a9145194aef4a","size":{"x":32,"y":1,"z":32}},{"blockCount":101,"bytes":2626,"file":"chunks/y127-z128-x064.json","offset":{"x":64,"y":127,"z":128},"requirements":{"minecraft:bricks":58,"minecraft:cobbled_deepslate":29,"minecraft:glass":4,"minecraft:polished_diorite":5,"minecraft:sandstone":2,"minecraft:stone_bricks":3},"sha256":"a74e227d6427ef028654417c48b2725533ad6abff72bd5aabbad593e99181809","size":{"x":32,"y":1,"z":32}},{"blockCount":41,"bytes":1894,"file":"chunks/y127-z128-x096.json","offset":{"x":96,"y":127,"z":128},"requirements":{"minecraft:bricks":27,"minecraft:cobbled_deepslate":7,"minecraft:glass":3,"minecraft:sandstone":3,"minecraft:stone_bricks":1},"sha256":"19d2438800ba70e09ee2140d456fabb19d0c1351e6cc1d20c48f73e07f3a21ac","size":{"x":32,"y":1,"z":32}},{"blockCount":86,"bytes":2688,"file":"chunks/y127-z128-x128.json","offset":{"x":128,"y":127,"z":128},"requirements":{"minecraft:bricks":52,"minecraft:cobbled_deepslate":22,"minecraft:glass":5,"minecraft:polished_diorite":2,"minecraft:sandstone":4,"minecraft:stone_bricks":1},"sha256":"183e3bb76e4da5011625d03c979c41a18247296b95e2db30e281b9973a33fb2e","size":{"x":32,"y":1,"z":32}},{"blockCount":101,"bytes":2608,"file":"chunks/y127-z128-x160.json","offset":{"x":160,"y":127,"z":128},"requirements":{"minecraft:bricks":58,"minecraft:cobbled_deepslate":30,"minecraft:glass":4,"minecraft:polished_diorite":5,"minecraft:sandstone":2,"minecraft:stone_bricks":2},"sha256":"b3314c82cebf56be446cfa005cbc8c017cc6e2c84774d5b378c0254a726b6c99","size":{"x":32,"y":1,"z":32}},{"blockCount":106,"bytes":2667,"file":"chunks/y127-z128-x192.json","offset":{"x":192,"y":127,"z":128},"requirements":{"minecraft:bricks":57,"minecraft:cobbled_deepslate":32,"minecraft:glass":2,"minecraft:polished_diorite":8,"minecraft:sandstone":3,"minecraft:stone_bricks":4},"sha256":"a7a15966f7b81f239e51f4ffe65f95913c7e9cde46fcf86828463c3d5cdf4380","size":{"x":32,"y":1,"z":32}},{"blockCount":121,"bytes":3660,"file":"chunks/y127-z128-x224.json","offset":{"x":224,"y":127,"z":128},"requirements":{"minecraft:bricks":16,"minecraft:cobbled_deepslate":4,"minecraft:oak_planks":9,"minecraft:polished_diorite":58,"minecraft:sandstone":13,"minecraft:stone_bricks":21},"sha256":"442ee2403ac3d140c2a33da5573004862561230402025b246ffe75b1c4230085","size":{"x":32,"y":1,"z":32}},{"blockCount":9,"bytes":867,"file":"chunks/y127-z160-x000.json","offset":{"x":0,"y":127,"z":160},"requirements":{"minecraft:polished_diorite":8,"minecraft:stone_bricks":1},"sha256":"c36f893c562d44b283b7b2ac292ad1e0e69eeae562111b1a54880d28a4d34fdc","size":{"x":32,"y":1,"z":32}},{"blockCount":53,"bytes":1986,"file":"chunks/y127-z160-x032.json","offset":{"x":32,"y":127,"z":160},"requirements":{"minecraft:polished_diorite":31,"minecraft:stone_bricks":22},"sha256":"59e6db4997a02437ab7c0fdbd9b05554d273199ee5159d56c9e3c425af3cccfb","size":{"x":32,"y":1,"z":32}},{"blockCount":62,"bytes":2095,"file":"chunks/y127-z160-x064.json","offset":{"x":64,"y":127,"z":160},"requirements":{"minecraft:polished_diorite":29,"minecraft:stone_bricks":33},"sha256":"189db73c442dfea8ec705a84d191edddbec0944ad19e3d29abff25a1920556d5","size":{"x":32,"y":1,"z":32}},{"blockCount":125,"bytes":5022,"file":"chunks/y127-z160-x096.json","offset":{"x":96,"y":127,"z":160},"requirements":{"minecraft:bricks":46,"minecraft:cobbled_deepslate":30,"minecraft:glass":2,"minecraft:polished_diorite":14,"minecraft:sandstone":2,"minecraft:stone_bricks":31},"sha256":"11e92b1f035ac84a2e926c67cde5854284c6b64406e18eb8a7a9d798a4883ed6","size":{"x":32,"y":1,"z":32}},{"blockCount":142,"bytes":5174,"file":"chunks/y127-z160-x128.json","offset":{"x":128,"y":127,"z":160},"requirements":{"minecraft:bricks":45,"minecraft:cobbled_deepslate":31,"minecraft:glass":2,"minecraft:polished_diorite":27,"minecraft:sandstone":2,"minecraft:stone_bricks":35},"sha256":"8f3b7d3492b36def9b41063a7ecfc10fadd354c6596f8f0fab43a6bfad0ce856","size":{"x":32,"y":1,"z":32}},{"blockCount":62,"bytes":2112,"file":"chunks/y127-z160-x160.json","offset":{"x":160,"y":127,"z":160},"requirements":{"minecraft:polished_diorite":30,"minecraft:stone_bricks":32},"sha256":"b5c59a02012ec6a47648689063e00db5a3706fd92b75e3a7d8b3115150d5ff7d","size":{"x":32,"y":1,"z":32}},{"blockCount":178,"bytes":4508,"file":"chunks/y127-z160-x192.json","offset":{"x":192,"y":127,"z":160},"requirements":{"minecraft:bricks":35,"minecraft:cobbled_deepslate":1,"minecraft:glass":5,"minecraft:polished_diorite":84,"minecraft:spruce_planks":17,"minecraft:stone_bricks":36},"sha256":"291e94cfeb7b4c142dd383763e5c8c49d39f58782eb565c84a04ae5c86065ea8","size":{"x":32,"y":1,"z":32}},{"blockCount":137,"bytes":3845,"file":"chunks/y127-z160-x224.json","offset":{"x":224,"y":127,"z":160},"requirements":{"minecraft:bricks":40,"minecraft:glass":14,"minecraft:polished_diorite":68,"minecraft:stone_bricks":15},"sha256":"1d86e5f2d9c9428b9f12c52a2bd054cccbd9e1797d47e7ec31f8825bd6210862","size":{"x":32,"y":1,"z":32}},{"blockCount":18,"bytes":1104,"file":"chunks/y127-z192-x064.json","offset":{"x":64,"y":127,"z":192},"requirements":{"minecraft:polished_diorite":16,"minecraft:stone_bricks":2},"sha256":"ce95842addf4f7c356e5372fe9e2e8771cd4e9dae37915cd63f885424bce518f","size":{"x":32,"y":1,"z":32}},{"blockCount":158,"bytes":4525,"file":"chunks/y127-z192-x096.json","offset":{"x":96,"y":127,"z":192},"requirements":{"minecraft:bricks":30,"minecraft:cobbled_deepslate":16,"minecraft:oak_planks":7,"minecraft:polished_diorite":56,"minecraft:sandstone":13,"minecraft:stone_bricks":36},"sha256":"3883d528f99575c0b1bb8aa94374690c23ebad20f37957aa4c8c791ac46ccc8c","size":{"x":32,"y":1,"z":32}},{"blockCount":116,"bytes":4227,"file":"chunks/y127-z192-x128.json","offset":{"x":128,"y":127,"z":192},"requirements":{"minecraft:bricks":22,"minecraft:cobbled_deepslate":16,"minecraft:oak_planks":2,"minecraft:polished_diorite":44,"minecraft:sandstone":3,"minecraft:stone_bricks":29},"sha256":"d728070570ec4424c041a1b4e6bf5ccc1abda067b1266eabfc64434fbbdd48ff","size":{"x":32,"y":1,"z":32}},{"blockCount":16,"bytes":1160,"file":"chunks/y128-z064-x064.json","offset":{"x":64,"y":128,"z":64},"requirements":{"minecraft:polished_diorite":9,"minecraft:stone_bricks":7},"sha256":"0153b0f54cd5e56eb336f4525ed98c73688592d25756fadc6fd2a7edcfd1685b","size":{"x":32,"y":1,"z":32}},{"blockCount":188,"bytes":5043,"file":"chunks/y128-z064-x096.json","offset":{"x":96,"y":128,"z":64},"requirements":{"minecraft:bricks":41,"minecraft:cobbled_deepslate":23,"minecraft:oak_planks":8,"minecraft:polished_diorite":66,"minecraft:sandstone":11,"minecraft:stone_bricks":39},"sha256":"620e18865405e383382fa714887c9645f4eb911d277d043d34d7b4f70328be5b","size":{"x":32,"y":1,"z":32}},{"blockCount":146,"bytes":4822,"file":"chunks/y128-z064-x128.json","offset":{"x":128,"y":128,"z":64},"requirements":{"minecraft:bricks":35,"minecraft:cobbled_deepslate":25,"minecraft:oak_planks":2,"minecraft:polished_diorite":43,"minecraft:sandstone":2,"minecraft:stone_bricks":39},"sha256":"b04797520c50ba0bda1a9458f18494a21c63f82247b41c1be9b441ac46e89f46","size":{"x":32,"y":1,"z":32}},{"blockCount":11,"bytes":981,"file":"chunks/y128-z064-x192.json","offset":{"x":192,"y":128,"z":64},"requirements":{"minecraft:polished_diorite":6,"minecraft:stone_bricks":5},"sha256":"96bd25f657229326e6a7d52a2be653608fc865f7a9848f9947c3cb7409a0d6fb","size":{"x":32,"y":1,"z":32}},{"blockCount":15,"bytes":1135,"file":"chunks/y128-z064-x224.json","offset":{"x":224,"y":128,"z":64},"requirements":{"minecraft:polished_diorite":6,"minecraft:stone_bricks":9},"sha256":"03fcdfaa8686fac14975b3577638583c36b1ff39aba2025aad48d3f4c923f8a0","size":{"x":32,"y":1,"z":32}},{"blockCount":9,"bytes":886,"file":"chunks/y128-z096-x000.json","offset":{"x":0,"y":128,"z":96},"requirements":{"minecraft:polished_diorite":6,"minecraft:stone_bricks":3},"sha256":"185d304c16cf5ef14ece80b230f5700fbe3b7644d0dfbe7b1d4e310271d735a6","size":{"x":32,"y":1,"z":32}},{"blockCount":98,"bytes":2996,"file":"chunks/y128-z096-x032.json","offset":{"x":32,"y":128,"z":96},"requirements":{"minecraft:bricks":11,"minecraft:cobbled_deepslate":21,"minecraft:polished_diorite":29,"minecraft:stone_bricks":37},"sha256":"a0e50af350f8b5a9d240be2fc1f0e8c23b56f488d4e28901f133df19a8b3bee2","size":{"x":32,"y":1,"z":32}},{"blockCount":133,"bytes":3185,"file":"chunks/y128-z096-x064.json","offset":{"x":64,"y":128,"z":96},"requirements":{"minecraft:bricks":38,"minecraft:cobbled_deepslate":28,"minecraft:polished_diorite":26,"minecraft:stone_bricks":41},"sha256":"f0859e90748b36d96926aadcd6117a36adfa4d6edad445768febd13fed40909a","size":{"x":32,"y":1,"z":32}},{"blockCount":123,"bytes":4408,"file":"chunks/y128-z096-x096.json","offset":{"x":96,"y":128,"z":96},"requirements":{"minecraft:bricks":55,"minecraft:cobbled_deepslate":27,"minecraft:glass":2,"minecraft:polished_diorite":13,"minecraft:stone_bricks":26},"sha256":"5e562025c26c81dd6b504122634054e6028a7d1725f8fcf74d9eca0762fc4334","size":{"x":32,"y":1,"z":32}},{"blockCount":186,"bytes":5512,"file":"chunks/y128-z096-x128.json","offset":{"x":128,"y":128,"z":96},"requirements":{"minecraft:bricks":75,"minecraft:cobbled_deepslate":46,"minecraft:glass":3,"minecraft:polished_diorite":24,"minecraft:stone_bricks":38},"sha256":"eaf7ceb9a5dc0a02a556d2852a9bad65838c1f528bd1a08cbca1973b4700e349","size":{"x":32,"y":1,"z":32}},{"blockCount":136,"bytes":3260,"file":"chunks/y128-z096-x160.json","offset":{"x":160,"y":128,"z":96},"requirements":{"minecraft:bricks":44,"minecraft:cobbled_deepslate":29,"minecraft:polished_diorite":28,"minecraft:stone_bricks":35},"sha256":"071511c34ca89a7c79ce36c6e80334314a54fe146899a4e052d19d0f4b327de0","size":{"x":32,"y":1,"z":32}},{"blockCount":220,"bytes":5216,"file":"chunks/y128-z096-x192.json","offset":{"x":192,"y":128,"z":96},"requirements":{"minecraft:bricks":77,"minecraft:cobbled_deepslate":30,"minecraft:glass":5,"minecraft:polished_diorite":66,"minecraft:spruce_planks":3,"minecraft:stone_bricks":39},"sha256":"8bc9c1b9a40dd67e1876044114ed2ee8cfe4c3182afcfcd10b96f621a042af19","size":{"x":32,"y":1,"z":32}},{"blockCount":135,"bytes":3749,"file":"chunks/y128-z096-x224.json","offset":{"x":224,"y":128,"z":96},"requirements":{"minecraft:bricks":42,"minecraft:cobbled_deepslate":4,"minecraft:glass":14,"minecraft:polished_diorite":58,"minecraft:sandstone":1,"minecraft:stone_bricks":16},"sha256":"8766b2762460c9f18b426fea196ed1c97ef643fd3f96e2d96b22ab4fc4775760","size":{"x":32,"y":1,"z":32}},{"blockCount":18,"bytes":1137,"file":"chunks/y128-z128-x000.json","offset":{"x":0,"y":128,"z":128},"requirements":{"minecraft:polished_diorite":8,"minecraft:stone_bricks":10},"sha256":"e0b28875871e62a5a4034a2cf6edea133d7a095691e14f9ad84a799ab3b1acfa","size":{"x":32,"y":1,"z":32}},{"blockCount":130,"bytes":4317,"file":"chunks/y128-z128-x032.json","offset":{"x":32,"y":128,"z":128},"requirements":{"minecraft:bricks":44,"minecraft:cobbled_deepslate":42,"minecraft:polished_diorite":15,"minecraft:stone_bricks":29},"sha256":"f4e4ff29eb7deb57b71c511061ed4e0c8678f06b2e038f8591ebcebc7066a1b5","size":{"x":32,"y":1,"z":32}},{"blockCount":99,"bytes":2401,"file":"chunks/y128-z128-x064.json","offset":{"x":64,"y":128,"z":128},"requirements":{"minecraft:bricks":52,"minecraft:cobbled_deepslate":29,"minecraft:glass":4,"minecraft:polished_diorite":7,"minecraft:stone_bricks":7},"sha256":"f446708e14c74bbe73abaee67f2abf1f7d651673024ea2c6694203b2948f8aa5","size":{"x":32,"y":1,"z":32}},{"blockCount":42,"bytes":1729,"file":"chunks/y128-z128-x096.json","offset":{"x":96,"y":128,"z":128},"requirements":{"minecraft:bricks":29,"minecraft:cobbled_deepslate":10,"minecraft:glass":3},"sha256":"4610ad38f3b62e64b0dd7c3cdb5b0aca47e40ebae00069e726d5c49466858816","size":{"x":32,"y":1,"z":32}},{"blockCount":88,"bytes":2418,"file":"chunks/y128-z128-x128.json","offset":{"x":128,"y":128,"z":128},"requirements":{"minecraft:bricks":53,"minecraft:cobbled_deepslate":24,"minecraft:glass":5,"minecraft:polished_diorite":3,"minecraft:stone_bricks":3},"sha256":"b6d576239aef32fa25fe2c2012c6608f1c6a9d8be2b04c54fe19e5ec3355afdb","size":{"x":32,"y":1,"z":32}},{"blockCount":101,"bytes":2477,"file":"chunks/y128-z128-x160.json","offset":{"x":160,"y":128,"z":128},"requirements":{"minecraft:bricks":53,"minecraft:cobbled_deepslate":28,"minecraft:glass":4,"minecraft:polished_diorite":7,"minecraft:stone_bricks":9},"sha256":"36f419d667857c374020acdc4698460a4d572667f5a2f4a080b7d61d4d0a33cc","size":{"x":32,"y":1,"z":32}},{"blockCount":107,"bytes":2703,"file":"chunks/y128-z128-x192.json","offset":{"x":192,"y":128,"z":128},"requirements":{"minecraft:bricks":56,"minecraft:cobbled_deepslate":28,"minecraft:glass":2,"minecraft:polished_diorite":13,"minecraft:stone_bricks":8},"sha256":"db35241921006c17fc3f1e772ba85eadb3be54010602603d29fafa640fdc8ca0","size":{"x":32,"y":1,"z":32}},{"blockCount":112,"bytes":3129,"file":"chunks/y128-z128-x224.json","offset":{"x":224,"y":128,"z":128},"requirements":{"minecraft:bricks":16,"minecraft:cobbled_deepslate":4,"minecraft:oak_planks":10,"minecraft:polished_diorite":59,"minecraft:sandstone":12,"minecraft:stone_bricks":11},"sha256":"187ae92eecc37db1837a66aabf98d9a0228d9ec24d5b8677b4a039533d895e0e","size":{"x":32,"y":1,"z":32}},{"blockCount":5,"bytes":790,"file":"chunks/y128-z160-x000.json","offset":{"x":0,"y":128,"z":160},"requirements":{"minecraft:polished_diorite":4,"minecraft:stone_bricks":1},"sha256":"64c4c05c16e244a22c9c3c19ccfcc7e8019cab7587f7d569ca32904878997fe4","size":{"x":32,"y":1,"z":32}},{"blockCount":44,"bytes":1909,"file":"chunks/y128-z160-x032.json","offset":{"x":32,"y":128,"z":160},"requirements":{"minecraft:polished_diorite":20,"minecraft:stone_bricks":24},"sha256":"67cde97ecd18ea54fcd8296cda7b16c0756acb72c500bb11f3d7c592f6bede57","size":{"x":32,"y":1,"z":32}},{"blockCount":54,"bytes":2174,"file":"chunks/y128-z160-x064.json","offset":{"x":64,"y":128,"z":160},"requirements":{"minecraft:polished_diorite":20,"minecraft:stone_bricks":34},"sha256":"9639d8fb67ff0cdbe34041d4c55456ee2cf3a7c8e198d76166fb8a8f2a98556c","size":{"x":32,"y":1,"z":32}},{"blockCount":119,"bytes":4637,"file":"chunks/y128-z160-x096.json","offset":{"x":96,"y":128,"z":160},"requirements":{"minecraft:bricks":45,"minecraft:cobbled_deepslate":27,"minecraft:glass":2,"minecraft:polished_diorite":16,"minecraft:stone_bricks":29},"sha256":"552c89a5de1ad28c539e87eb6ba182529d9523379b0f5037d858f0becd3c46eb","size":{"x":32,"y":1,"z":32}},{"blockCount":145,"bytes":5248,"file":"chunks/y128-z160-x128.json","offset":{"x":128,"y":128,"z":160},"requirements":{"minecraft:bricks":45,"minecraft:cobbled_deepslate":31,"minecraft:glass":2,"minecraft:polished_diorite":25,"minecraft:stone_bricks":42},"sha256":"a4a48a3d618725f70fc4fea2ca5e988401049115cb65cfccd7f5581a6eaffcf2","size":{"x":32,"y":1,"z":32}},{"blockCount":53,"bytes":2112,"file":"chunks/y128-z160-x160.json","offset":{"x":160,"y":128,"z":160},"requirements":{"minecraft:polished_diorite":21,"minecraft:stone_bricks":32},"sha256":"364b3de2622aa4615b5b05ea67d13ce0c33464f0f784571c2188474422ad61fb","size":{"x":32,"y":1,"z":32}},{"blockCount":140,"bytes":4148,"file":"chunks/y128-z160-x192.json","offset":{"x":192,"y":128,"z":160},"requirements":{"minecraft:bricks":34,"minecraft:cobbled_deepslate":1,"minecraft:glass":5,"minecraft:polished_diorite":59,"minecraft:spruce_planks":3,"minecraft:stone_bricks":38},"sha256":"250ebef5e928b082763ae9ff93e08f1f9d4716c65d29552f836ea6f908deefb1","size":{"x":32,"y":1,"z":32}},{"blockCount":121,"bytes":3541,"file":"chunks/y128-z160-x224.json","offset":{"x":224,"y":128,"z":160},"requirements":{"minecraft:bricks":39,"minecraft:glass":14,"minecraft:polished_diorite":49,"minecraft:stone_bricks":19},"sha256":"900902c083a4ef36571f276ccec76e0fff415810f480bf5e5913fda00c83b520","size":{"x":32,"y":1,"z":32}},{"blockCount":14,"bytes":1103,"file":"chunks/y128-z192-x064.json","offset":{"x":64,"y":128,"z":192},"requirements":{"minecraft:polished_diorite":8,"minecraft:stone_bricks":6},"sha256":"ec3f7ea499c11dc02388a70931dbd065e2ad4f4a71a6dbc429d90b7fc1bf0a39","size":{"x":32,"y":1,"z":32}},{"blockCount":161,"bytes":4164,"file":"chunks/y128-z192-x096.json","offset":{"x":96,"y":128,"z":192},"requirements":{"minecraft:bricks":30,"minecraft:cobbled_deepslate":15,"minecraft:oak_planks":8,"minecraft:polished_diorite":63,"minecraft:sandstone":11,"minecraft:stone_bricks":34},"sha256":"d9d67d3f9bb4ae1bfd03b0fef0f6dcb33acb1e14228f1c02635d1e1f9768e7a4","size":{"x":32,"y":1,"z":32}},{"blockCount":117,"bytes":3942,"file":"chunks/y128-z192-x128.json","offset":{"x":128,"y":128,"z":192},"requirements":{"minecraft:bricks":24,"minecraft:cobbled_deepslate":17,"minecraft:oak_planks":2,"minecraft:polished_diorite":39,"minecraft:sandstone":2,"minecraft:stone_bricks":33},"sha256":"770e8f24ee00f32daa84dcac437622a949b2b5000a557add6c3709decf9bb9ed","size":{"x":32,"y":1,"z":32}},{"blockCount":16,"bytes":1160,"file":"chunks/y129-z064-x064.json","offset":{"x":64,"y":129,"z":64},"requirements":{"minecraft:polished_diorite":9,"minecraft:stone_bricks":7},"sha256":"655f6ca0ea2d1426273d9eee8b866b830bdcbbcd03d2cabc2fab8a3f3399ea3d","size":{"x":32,"y":1,"z":32}},{"blockCount":184,"bytes":5366,"file":"chunks/y129-z064-x096.json","offset":{"x":96,"y":129,"z":64},"requirements":{"minecraft:bricks":40,"minecraft:cobbled_deepslate":22,"minecraft:oak_planks":7,"minecraft:polished_diorite":69,"minecraft:sandstone":13,"minecraft:stone_bricks":33},"sha256":"5469bad01e34da7a0e4cadef5c45798794191ae90a3a58bbe50da2fef6839550","size":{"x":32,"y":1,"z":32}},{"blockCount":142,"bytes":5050,"file":"chunks/y129-z064-x128.json","offset":{"x":128,"y":129,"z":64},"requirements":{"minecraft:bricks":30,"minecraft:cobbled_deepslate":24,"minecraft:oak_planks":1,"minecraft:polished_diorite":53,"minecraft:sandstone":4,"minecraft:stone_bricks":30},"sha256":"f7102a7ee4486d65a569bacda3788a151e70a7983e303497aeb589e81951108c","size":{"x":32,"y":1,"z":32}},{"blockCount":17,"bytes":1077,"file":"chunks/y129-z064-x192.json","offset":{"x":192,"y":129,"z":64},"requirements":{"minecraft:polished_diorite":11,"minecraft:stone_bricks":6},"sha256":"e968e953e9217a450d2480af9916a702f10a39ec42a96a7b28613f9f098e8a3d","size":{"x":32,"y":1,"z":32}}],"schema":1}
