{"entries":[{"blockCount":25,"bytes":1307,"file":"chunks/y129-z064-x224.json","offset":{"x":224,"y":129,"z":64},"requirements":{"minecraft:polished_diorite":15,"minecraft:stone_bricks":10},"sha256":"85ac0d82f5d28e3210031faed11a41d6b5a06d9ff21db194ca3798e3ba769d41","size":{"x":32,"y":1,"z":32}},{"blockCount":9,"bytes":905,"file":"chunks/y129-z096-x000.json","offset":{"x":0,"y":129,"z":96},"requirements":{"minecraft:polished_diorite":6,"minecraft:stone_bricks":3},"sha256":"4faa20ca9e633f9ff76d797b5fa791bdcf26e0315e701d93e92e3413e77d0db7","size":{"x":32,"y":1,"z":32}},{"blockCount":98,"bytes":3128,"file":"chunks/y129-z096-x032.json","offset":{"x":32,"y":129,"z":96},"requirements":{"minecraft:bricks":12,"minecraft:cobbled_deepslate":20,"minecraft:polished_diorite":37,"minecraft:stone_bricks":29},"sha256":"574041deffcc4e34f9b1b114fcea86e2c029f103e3ecb2c1257bf2daca5c746c","size":{"x":32,"y":1,"z":32}},{"blockCount":128,"bytes":3218,"file":"chunks/y129-z096-x064.json","offset":{"x":64,"y":129,"z":96},"requirements":{"minecraft:bricks":35,"minecraft:cobbled_deepslate":30,"minecraft:polished_diorite":35,"minecraft:stone_bricks":28},"sha256":"6e5473c10b98e23dd19097bd2384dfb08cb58f4c1102e37fe3243539566b73a7","size":{"x":32,"y":1,"z":32}},{"blockCount":131,"bytes":4622,"file":"chunks/y129-z096-x096.json","offset":{"x":96,"y":129,"z":96},"requirements":{"minecraft:bricks":59,"minecraft:cobbled_deepslate":32,"minecraft:glass":2,"minecraft:polished_diorite":18,"minecraft:sandstone":4,"minecraft:stone_bricks":16},"sha256":"1c4aef1a8a6e4b2591ac02e05aa1aabd3ab004864b35deee0bf152e50b3bef42","size":{"x":32,"y":1,"z":32}},{"blockCount":184,"bytes":5612,"file":"chunks/y129-z096-x128.json","offset":{"x":128,"y":129,"z":96},"requirements":{"minecraft:bricks":68,"minecraft:cobbled_deepslate":45,"minecraft:glass":3,"minecraft:polished_diorite":33,"minecraft:sandstone":4,"minecraft:stone_bricks":31},"sha256":"e5c83a64ebfd5bb17d60ed3537dd9de203c3e090110a0bea5d45747d00d89950","size":{"x":32,"y":1,"z":32}},{"blockCount":129,"bytes":3388,"file":"chunks/y129-z096-x160.json","offset":{"x":160,"y":129,"z":96},"requirements":{"minecraft:bricks":34,"minecraft:cobbled_deepslate":27,"minecraft:polished_diorite":39,"minecraft:stone_bricks":29},"sha256":"2dc783955c3788d319305ba724d87b723fa1ae9effe1d2512a25473c78989964","size":{"x":32,"y":1,"z":32}},{"blockCount":224,"bytes":5294,"file":"chunks/y129-z096-x192.json","offset":{"x":192,"y":129,"z":96},"requirements":{"minecraft:bricks":70,"minecraft:cobbled_deepslate":29,"minecraft:glass":5,"minecraft:oak_planks":1,"minecraft:polished_diorite":84,"minecraft:spruce_planks":3,"minecraft:stone_bricks":32},"sha256":"3e477b3767c23ee0d8308b4dcee45f55f68e197cb1cc66cb8d1a19797eac3dc4","size":{"x":32,"y":1,"z":32}},{"blockCount":148,"bytes":3920,"file":"chunks/y129-z096-x224.json","offset":{"x":224,"y":129,"z":96},"requirements":{"minecraft:bricks":41,"minecraft:cobbled_deepslate":4,"minecraft:glass":14,"minecraft:polished_diorite":72,"minecraft:sandstone":2,"minecraft:stone_bricks":15},"sha256":"dd666644e6bd24f706d2e7ed7563ffdf61e4ab4d4b444ea7dfc4b2b9b298e02d","size":{"x":32,"y":1,"z":32}},{"blockCount":16,"bytes":1120,"file":"chunks/y129-z128-x000.json","offset":{"x":0,"y":129,"z":128},"requirements":{"minecraft:polished_diorite":10,"minecraft:stone_bricks":6},"sha256":"9eebc63c15a4905c5f1cebfbe4b1f55475b7115a16379a4ffa5e37b6d75edfa2","size":{"x":32,"y":1,"z":32}},{"blockCount":139,"bytes":4473,"file":"chunks/y129-z128-x032.json","offset":{"x":32,"y":129,"z":128},"requirements":{"minecraft:bricks":45,"minecraft:cobbled_deepslate":49,"minecraft:polished_diorite":22,"minecraft:sandstone":3,"minecraft:stone_bricks":20},"sha256":"9c59ca5d4d9aa2e39b636ee63c2711b2c2e9262ee443e7c44a71428282838abc","size":{"x":32,"y":1,"z":32}},{"blockCount":108,"bytes":2878,"file":"chunks/y129-z128-x064.json","offset":{"x":64,"y":129,"z":128},"requirements":{"minecraft:bricks":59,"minecraft:cobbled_deepslate":30,"minecraft:glass":4,"minecraft:polished_diorite":9,"minecraft:sandstone":4,"minecraft:stone_bricks":2},"sha256":"8a157e54082ea15599c0bb19de854703bb0a8b18a899c3cc8b494a51b1a1152f","size":{"x":32,"y":1,"z":32}},{"blockCount":49,"bytes":2048,"file":"chunks/y129-z128-x096.json","offset":{"x":96,"y":129,"z":128},"requirements":{"minecraft:bricks":32,"minecraft:cobbled_deepslate":9,"minecraft:glass":3,"minecraft:sandstone":4,"minecraft:stone_bricks":1},"sha256":"7c49e053ac091cf19d936417a09b36c6014c7206cd17b45b8919c0fdda06fb28","size":{"x":32,"y":1,"z":32}},{"blockCount":99,"bytes":2902,"file":"chunks/y129-z128-x128.json","offset":{"x":128,"y":129,"z":128},"requirements":{"minecraft:bricks":59,"minecraft:cobbled_deepslate":24,"minecraft:glass":5,"minecraft:polished_diorite":4,"minecraft:sandstone":6,"minecraft:stone_bricks":1},"sha256":"6f11ab81657e052fbd08f2f2290565f07f6298f0db7eddfc7e7d4ee87a1950ab","size":{"x":32,"y":1,"z":32}},{"blockCount":108,"bytes":2955,"file":"chunks/y129-z128-x160.json","offset":{"x":160,"y":129,"z":128},"requirements":{"minecraft:bricks":58,"minecraft:cobbled_deepslate":30,"minecraft:glass":4,"minecraft:polished_diorite":10,"minecraft:sandstone":4,"minecraft:stone_bricks":2},"sha256":"65192ff0f613ca2d550958860a10cd7bc7bd420eb5712a857009857108fe1b1f","size":{"x":32,"y":1,"z":32}},{"blockCount":120,"bytes":3218,"file":"chunks/y129-z128-x192.json","offset":{"x":192,"y":129,"z":128},"requirements":{"minecraft:bricks":58,"minecraft:cobbled_deepslate":28,"minecraft:glass":2,"minecraft:oak_planks":1,"minecraft:polished_diorite":17,"minecraft:sandstone":6,"minecraft:spruce_planks":3,"minecraft:stone_bricks":5},"sha256":"e8a17865c9cc56e8a27bcf03ed6b300e74fb1a6f6429da0c9bf1a47a9b269d63","size":{"x":32,"y":1,"z":32}},{"blockCount":111,"bytes":3280,"file":"chunks/y129-z128-x224.json","offset":{"x":224,"y":129,"z":128},"requirements":{"minecraft:bricks":15,"minecraft:cobbled_deepslate":2,"minecraft:oak_planks":8,"minecraft:polished_diorite":56,"minecraft:sandstone":13,"minecraft:stone_bricks":17},"sha256":"fbe021b9e331f50e5b4b41bc817234a89384385e2374443a2442d6784270b54b","size":{"x":32,"y":1,"z":32}},{"blockCount":5,"bytes":790,"file":"chunks/y129-z160-x000.json","offset":{"x":0,"y":129,"z":160},"requirements":{"minecraft:polished_diorite":4,"minecraft:stone_bricks":1},"sha256":"a30effe23c4f3254353a6525d25236d315fefcc01118ba9d9b1b8fceaf0addf2","size":{"x":32,"y":1,"z":32}},{"blockCount":43,"bytes":1985,"file":"chunks/y129-z160-x032.json","offset":{"x":32,"y":129,"z":160},"requirements":{"minecraft:polished_diorite":25,"minecraft:stone_bricks":18},"sha256":"aa5cac4e86dcac8b85a2c3c631e1e309d83f508f7c1930f400a1fd0f5cf64ed1","size":{"x":32,"y":1,"z":32}},{"blockCount":54,"bytes":2364,"file":"chunks/y129-z160-x064.json","offset":{"x":64,"y":129,"z":160},"requirements":{"minecraft:polished_diorite":27,"minecraft:stone_bricks":27},"sha256":"16609168c111a35af9e35d4e3ff1dd2b5de2193b9d15362ced00a0ac8cbaaf49","size":{"x":32,"y":1,"z":32}},{"blockCount":126,"bytes":4946,"file":"chunks/y129-z160-x096.json","offset":{"x":96,"y":129,"z":160},"requirements":{"minecraft:bricks":50,"minecraft:cobbled_deepslate":31,"minecraft:glass":2,"minecraft:polished_diorite":24,"minecraft:sandstone":2,"minecraft:stone_bricks":17},"sha256":"59ed08b99817293663d56182009b1031312d55e7b3d1787e9acd3d96caa0828d","size":{"x":32,"y":1,"z":32}},{"blockCount":142,"bytes":5500,"file":"chunks/y129-z160-x128.json","offset":{"x":128,"y":129,"z":160},"requirements":{"minecraft:bricks":40,"minecraft:cobbled_deepslate":31,"minecraft:glass":2,"minecraft:polished_diorite":36,"minecraft:sandstone":2,"minecraft:stone_bricks":31},"sha256":"aa905864029e66a787b632b3c5fe3c51d6e26291cb7621417c0bab94bdaff5c6","size":{"x":32,"y":1,"z":32}},{"blockCount":53,"bytes":2302,"file":"chunks/y129-z160-x160.json","offset":{"x":160,"y":129,"z":160},"requirements":{"minecraft:polished_diorite":29,"minecraft:stone_bricks":24},"sha256":"17f5e678249b4a6345f8a38d6aef07260b28203b42a64c99c074c9f91f5eb557","size":{"x":32,"y":1,"z":32}},{"blockCount":151,"bytes":4424,"file":"chunks/y129-z160-x192.json","offset":{"x":192,"y":129,"z":160},"requirements":{"minecraft:bricks":34,"minecraft:cobbled_deepslate":1,"minecraft:glass":5,"minecraft:polished_diorite":78,"minecraft:stone_bricks":33},"sha256":"e33771d34e9f51df1b2c263cc249453832a6f2b1804da45bd696475196c2b804","size":{"x":32,"y":1,"z":32}},{"blockCount":139,"bytes":3787,"file":"chunks/y129-z160-x224.json","offset":{"x":224,"y":129,"z":160},"requirements":{"minecraft:bricks":39,"minecraft:glass":14,"minecraft:polished_diorite":68,"minecraft:stone_bricks":18},"sha256":"28eb62296dc513d2750f19c24336e3f46a5c16352507c5d743aa0d0a6af983b6","size":{"x":32,"y":1,"z":32}},{"blockCount":14,"bytes":1103,"file":"chunks/y129-z192-x064.json","offset":{"x":64,"y":129,"z":192},"requirements":{"minecraft:polished_diorite":8,"minecraft:stone_bricks":6},"sha256":"4353965486a4b3289f078b50d594b4caefb68f9cd5f760226937a0c20a0aa7fc","size":{"x":32,"y":1,"z":32}},{"blockCount":157,"bytes":4430,"file":"chunks/y129-z192-x096.json","offset":{"x":96,"y":129,"z":192},"requirements":{"minecraft:bricks":29,"minecraft:cobbled_deepslate":18,"minecraft:oak_planks":7,"minecraft:polished_diorite":63,"minecraft:sandstone":13,"minecraft:stone_bricks":27},"sha256":"8cd5957663a610fd88ff0c000b5d1a1d87962538ec0ba71f4a1ab04e2cc74b01","size":{"x":32,"y":1,"z":32}},{"blockCount":115,"bytes":4132,"file":"chunks/y129-z192-x128.json","offset":{"x":128,"y":129,"z":192},"requirements":{"minecraft:bricks":21,"minecraft:cobbled_deepslate":17,"minecraft:oak_planks":1,"minecraft:polished_diorite":46,"minecraft:sandstone":4,"minecraft:stone_bricks":26},"sha256":"b770b54735592f2574f658418cd02ec6c448fea1b67bd56e8c57e80badf5dca9","size":{"x":32,"y":1,"z":32}},{"blockCount":13,"bytes":1063,"file":"chunks/y130-z064-x064.json","offset":{"x":64,"y":130,"z":64},"requirements":{"minecraft:polished_diorite":9,"minecraft:stone_bricks":4},"sha256":"e5f68ce70c06ef44c674363260c64f4c0e820f236b5de703c1a467550a3bd461","size":{"x":32,"y":1,"z":32}},{"blockCount":182,"bytes":5101,"file":"chunks/y130-z064-x096.json","offset":{"x":96,"y":130,"z":64},"requirements":{"minecraft:bricks":40,"minecraft:cobbled_deepslate":24,"minecraft:oak_planks":7,"minecraft:polished_diorite":76,"minecraft:sandstone":11,"minecraft:stone_bricks":24},"sha256":"a8d5745652dcbe320b7dedc034ba8c5365d5e2e5aa4d8028b4de251dc0651838","size":{"x":32,"y":1,"z":32}},{"blockCount":132,"bytes":4518,"file":"chunks/y130-z064-x128.json","offset":{"x":128,"y":130,"z":64},"requirements":{"minecraft:bricks":30,"minecraft:cobbled_deepslate":23,"minecraft:oak_planks":1,"minecraft:polished_diorite":52,"minecraft:sandstone":2,"minecraft:stone_bricks":24},"sha256":"5230f403b80928598d4264c82d4401cb4fc0fb5b89b8f8a946f337b4e5c12180","size":{"x":32,"y":1,"z":32}},{"blockCount":11,"bytes":955,"file":"chunks/y130-z064-x192.json","offset":{"x":192,"y":130,"z":64},"requirements":{"minecraft:polished_diorite":11},"sha256":"d5e875b4587e564b6a51db1cbbcd5cb02d92d90f10b27e03957eb2fb38352ec0","size":{"x":32,"y":1,"z":32}},{"blockCount":15,"bytes":1109,"file":"chunks/y130-z064-x224.json","offset":{"x":224,"y":130,"z":64},"requirements":{"minecraft:polished_diorite":15},"sha256":"16d74afed0ec58451ffa9d1402abe6996da4c703228d16492ddbf822fc109f52","size":{"x":32,"y":1,"z":32}},{"blockCount":9,"bytes":886,"file":"chunks/y130-z096-x000.json","offset":{"x":0,"y":130,"z":96},"requirements":{"minecraft:polished_diorite":6,"minecraft:stone_bricks":3},"sha256":"ece7601050714b6c96917dc99e8ee735edcccc14e8c4b23ab82e6ed6061e63a8","size":{"x":32,"y":1,"z":32}},{"blockCount":86,"bytes":2728,"file":"chunks/y130-z096-x032.json","offset":{"x":32,"y":130,"z":96},"requirements":{"minecraft:bricks":8,"minecraft:cobbled_deepslate":19,"minecraft:polished_diorite":37,"minecraft:stone_bricks":22},"sha256":"e984176cb4ce0954a55798e673de60c512956c285f5dc700f6c28ea58ca55cde","size":{"x":32,"y":1,"z":32}},{"blockCount":119,"bytes":3066,"file":"chunks/y130-z096-x064.json","offset":{"x":64,"y":130,"z":96},"requirements":{"minecraft:bricks":32,"minecraft:cobbled_deepslate":28,"minecraft:polished_diorite":35,"minecraft:stone_bricks":24},"sha256":"0eebdcedf2160a2847cf27b95e889431ed7786559b5820cf2b3e8ff932d06174","size":{"x":32,"y":1,"z":32}},{"blockCount":134,"bytes":4674,"file":"chunks/y130-z096-x096.json","offset":{"x":96,"y":130,"z":96},"requirements":{"minecraft:bricks":65,"minecraft:cobbled_deepslate":36,"minecraft:glass":2,"minecraft:polished_diorite":18,"minecraft:stone_bricks":13},"sha256":"6ce0c69b6496f41520e413dc0b55f494a6ea2110e01b593122c7e7357d53c5dd","size":{"x":32,"y":1,"z":32}},{"blockCount":174,"bytes":5097,"file":"chunks/y130-z096-x128.json","offset":{"x":128,"y":130,"z":96},"requirements":{"minecraft:bricks":64,"minecraft:cobbled_deepslate":48,"minecraft:glass":3,"minecraft:polished_diorite":33,"minecraft:stone_bricks":26},"sha256":"40611e6eb6eaff3f43e859449a231118953d7c33df515ccc04dfb62978d4f0ed","size":{"x":32,"y":1,"z":32}},{"blockCount":121,"bytes":3142,"file":"chunks/y130-z096-x160.json","offset":{"x":160,"y":130,"z":96},"requirements":{"minecraft:bricks":32,"minecraft:cobbled_deepslate":28,"minecraft:polished_diorite":39,"minecraft:stone_bricks":22},"sha256":"8c3ceb620fd8649c114405c2d7d973bee12657f755155f533e0c5cf34eef4849","size":{"x":32,"y":1,"z":32}},{"blockCount":220,"bytes":5141,"file":"chunks/y130-z096-x192.json","offset":{"x":192,"y":130,"z":96},"requirements":{"minecraft:bricks":76,"minecraft:cobbled_deepslate":29,"minecraft:glass":5,"minecraft:oak_planks":1,"minecraft:polished_diorite":81,"minecraft:spruce_planks":3,"minecraft:stone_bricks":25},"sha256":"4072fe4089c02e7f064f5443880875a991ebdb9396dd9253e4ee62e5f31ed960","size":{"x":32,"y":1,"z":32}},{"blockCount":134,"bytes":3691,"file":"chunks/y130-z096-x224.json","offset":{"x":224,"y":130,"z":96},"requirements":{"minecraft:bricks":41,"minecraft:cobbled_deepslate":4,"minecraft:glass":14,"minecraft:polished_diorite":71,"minecraft:sandstone":1,"minecraft:stone_bricks":3},"sha256":"69769a5f1c2cb5b56add2a7c2f16cdf07240faa662b6b5f02056ea9555e575f0","size":{"x":32,"y":1,"z":32}},{"blockCount":14,"bytes":1063,"file":"chunks/y130-z128-x000.json","offset":{"x":0,"y":130,"z":128},"requirements":{"minecraft:polished_diorite":10,"minecraft:stone_bricks":4},"sha256":"ed6a277a4b3bd842794542624ee0468819f0dc4f51e808062ca44c5e26e928db","size":{"x":32,"y":1,"z":32}},{"blockCount":132,"bytes":4220,"file":"chunks/y130-z128-x032.json","offset":{"x":32,"y":130,"z":128},"requirements":{"minecraft:bricks":53,"minecraft:cobbled_deepslate":41,"minecraft:polished_diorite":22,"minecraft:stone_bricks":16},"sha256":"6f3ac4b484a433c2702b06c9969d239d6ad42415756049d42408314884bc24c4","size":{"x":32,"y":1,"z":32}},{"blockCount":111,"bytes":3028,"file":"chunks/y130-z128-x064.json","offset":{"x":64,"y":130,"z":128},"requirements":{"minecraft:bricks":64,"minecraft:cobbled_deepslate":31,"minecraft:glass":4,"minecraft:polished_diorite":9,"minecraft:stone_bricks":3},"sha256":"e7db66975c539609338da1e3f2104ff7da25012d540446300b1c72cfd3d5b23f","size":{"x":32,"y":1,"z":32}},{"blockCount":54,"bytes":2103,"file":"chunks/y130-z128-x096.json","offset":{"x":96,"y":130,"z":128},"requirements":{"minecraft:bricks":39,"minecraft:cobbled_deepslate":10,"minecraft:glass":3,"minecraft:stone_bricks":2},"sha256":"44dd1074c8b5edce437e675ab666f2923c26c9f1fbaff1e3b2f0877195c1db63","size":{"x":32,"y":1,"z":32}},{"blockCount":107,"bytes":3165,"file":"chunks/y130-z128-x128.json","offset":{"x":128,"y":130,"z":128},"requirements":{"minecraft:bricks":70,"minecraft:cobbled_deepslate":26,"minecraft:glass":5,"minecraft:polished_diorite":4,"minecraft:stone_bricks":2},"sha256":"da53871ee86817c5127df0fc55a61796af6206787bdbc8aa6d551f41c643f3cc","size":{"x":32,"y":1,"z":32}},{"blockCount":112,"bytes":3298,"file":"chunks/y130-z128-x160.json","offset":{"x":160,"y":130,"z":128},"requirements":{"minecraft:bricks":64,"minecraft:cobbled_deepslate":24,"minecraft:glass":4,"minecraft:polished_diorite":10,"minecraft:stone_bricks":10},"sha256":"745614877cb889766b95c0dfc41afba343bda9f0c9da9fc09a35b50e60c0ae51","size":{"x":32,"y":1,"z":32}},{"blockCount":131,"bytes":3424,"file":"chunks/y130-z128-x192.json","offset":{"x":192,"y":130,"z":128},"requirements":{"minecraft:bricks":74,"minecraft:cobbled_deepslate":30,"minecraft:glass":2,"minecraft:oak_planks":1,"minecraft:polished_diorite":14,"minecraft:spruce_planks":3,"minecraft:stone_bricks":7},"sha256":"69cb62df37c6a4af52fc07e6cf30a58dd6048ad397fc88a2b20dd06e17d3100e","size":{"x":32,"y":1,"z":32}},{"blockCount":107,"bytes":3032,"file":"chunks/y130-z128-x224.json","offset":{"x":224,"y":130,"z":128},"requirements":{"minecraft:bricks":12,"minecraft:cobbled_deepslate":4,"minecraft:oak_planks":8,"minecraft:polished_diorite":63,"minecraft:sandstone":12,"minecraft:stone_bricks":8},"sha256":"54c94efc863f66fa1d19125fc3500f4bd632d77fce208b11736f704b6457e051","size":{"x":32,"y":1,"z":32}},{"blockCount":5,"bytes":790,"file":"chunks/y130-z160-x000.json","offset":{"x":0,"y":130,"z":160},"requirements":{"minecraft:polished_diorite":4,"minecraft:stone_bricks":1},"sha256":"7100d88e6c6252cda638b1ab632ba860339838ede29a889364e0812ef9addfa8","size":{"x":32,"y":1,"z":32}},{"blockCount":38,"bytes":1795,"file":"chunks/y130-z160-x032.json","offset":{"x":32,"y":130,"z":160},"requirements":{"minecraft:polished_diorite":25,"minecraft:stone_bricks":13},"sha256":"8fb14670b62e39733b7580a3652aa443263b6d0dcac9f08d54f16f95a5e9f126","size":{"x":32,"y":1,"z":32}},{"blockCount":45,"bytes":2020,"file":"chunks/y130-z160-x064.json","offset":{"x":64,"y":130,"z":160},"requirements":{"minecraft:polished_diorite":27,"minecraft:stone_bricks":18},"sha256":"303dad9247ed328693b0b029e4913fb37af5c5f0c6ec546f0564bb248127a50c","size":{"x":32,"y":1,"z":32}},{"blockCount":128,"bytes":4979,"file":"chunks/y130-z160-x096.json","offset":{"x":96,"y":130,"z":160},"requirements":{"minecraft:bricks":56,"minecraft:cobbled_deepslate":28,"minecraft:glass":2,"minecraft:polished_diorite":24,"minecraft:stone_bricks":18},"sha256":"f91fbf88051ecbed4a5d8d95ce69a9aaae2005597288b530794c271aedf60ae7","size":{"x":32,"y":1,"z":32}},{"blockCount":129,"bytes":4795,"file":"chunks/y130-z160-x128.json","offset":{"x":128,"y":130,"z":160},"requirements":{"minecraft:bricks":36,"minecraft:cobbled_deepslate":31,"minecraft:glass":2,"minecraft:polished_diorite":36,"minecraft:stone_bricks":24},"sha256":"486b6d78328e04c524d0ead09d0c2dcf7c8ac64e2a7f97395e155dd1e2c5d84e","size":{"x":32,"y":1,"z":32}},{"blockCount":45,"bytes":2016,"file":"chunks/y130-z160-x160.json","offset":{"x":160,"y":130,"z":160},"requirements":{"minecraft:polished_diorite":29,"minecraft:stone_bricks":16},"sha256":"227a5055bb3be28e07ff196cddeadc0834102cb8b2406b6551df69bddae92fb1","size":{"x":32,"y":1,"z":32}},{"blockCount":134,"bytes":4049,"file":"chunks/y130-z160-x192.json","offset":{"x":192,"y":130,"z":160},"requirements":{"minecraft:bricks":34,"minecraft:glass":5,"minecraft:polished_diorite":78,"minecraft:stone_bricks":17},"sha256":"834a596478bd20a1f08b3aa967532f21773f5592789d2eb6947dc4bd8b08aa8c","size":{"x":32,"y":1,"z":32}},{"blockCount":121,"bytes":3475,"file":"chunks/y130-z160-x224.json","offset":{"x":224,"y":130,"z":160},"requirements":{"minecraft:bricks":39,"minecraft:glass":14,"minecraft:polished_diorite":68},"sha256":"2ffce3b252a2d5e932f003ac3b74e31949f574a8b5a06b3f501b2b3e35e63dd3","size":{"x":32,"y":1,"z":32}},{"blockCount":12,"bytes":1025,"file":"chunks/y130-z192-x064.json","offset":{"x":64,"y":130,"z":192},"requirements":{"minecraft:polished_diorite":8,"minecraft:stone_bricks":4},"sha256":"acf3381dfa43f54c231345d1a5dd83b79aed9b8cd12afef86e4795fc4e2affc7","size":{"x":32,"y":1,"z":32}},{"blockCount":155,"bytes":4203,"file":"chunks/y130-z192-x096.json","offset":{"x":96,"y":130,"z":192},"requirements":{"minecraft:bricks":28,"minecraft:cobbled_deepslate":15,"minecraft:oak_planks":7,"minecraft:polished_diorite":70,"minecraft:sandstone":11,"minecraft:stone_bricks":24},"sha256":"0bc5961f31e18a515ea8a64bc4336aaa89d877c144dd8671d0e26f03857acad6","size":{"x":32,"y":1,"z":32}},{"blockCount":108,"bytes":3733,"file":"chunks/y130-z192-x128.json","offset":{"x":128,"y":130,"z":192},"requirements":{"minecraft:bricks":22,"minecraft:cobbled_deepslate":17,"minecraft:oak_planks":1,"minecraft:polished_diorite":45,"minecraft:sandstone":2,"minecraft:stone_bricks":21},"sha256":"4cc3e160f64aa80e1416c879fd9d59db014ad7019f2999c15f8784172d43f26b","size":{"x":32,"y":1,"z":32}},{"blockCount":13,"bytes":1063,"file":"chunks/y131-z064-x064.json","offset":{"x":64,"y":131,"z":64},"requirements":{"minecraft:polished_diorite":9,"minecraft:stone_bricks":4},"sha256":"7ef622e97a939b0411b181b37e678def8b59f81dc5650576c860ad26a584fa24","size":{"x":32,"y":1,"z":32}},{"blockCount":211,"bytes":4719,"file":"chunks/y131-z064-x096.json","offset":{"x":96,"y":131,"z":64},"requirements":{"minecraft:bricks":53,"minecraft:cobbled_deepslate":23,"minecraft:oak_planks":7,"minecraft:polished_diorite":98,"minecraft:sandstone":13,"minecraft:stone_bricks":17},"sha256":"e2df643bd3b22b38e00d3e526a1e337aa34b9c9ca3c340b882eba2bce3a04c78","size":{"x":32,"y":1,"z":32}},{"blockCount":165,"bytes":4308,"file":"chunks/y131-z064-x128.json","offset":{"x":128,"y":131,"z":64},"requirements":{"minecraft:bricks":41,"minecraft:cobbled_deepslate":23,"minecraft:oak_planks":2,"minecraft:polished_diorite":81,"minecraft:sandstone":3,"minecraft:stone_bricks":15},"sha256":"0fcb0716ec89595725a441acb1d3111194c6e4cca339e4d08afd9e2861a82d63","size":{"x":32,"y":1,"z":32}},{"blockCount":11,"bytes":955,"file":"chunks/y131-z064-x192.json","offset":{"x":192,"y":131,"z":64},"requirements":{"minecraft:polished_diorite":11},"sha256":"07babc3bb84b416699e83b6c2b90052ba00adeddaca1d0a1769164c9867c7258","size":{"x":32,"y":1,"z":32}},{"blockCount":15,"bytes":1109,"file":"chunks/y131-z064-x224.json","offset":{"x":224,"y":131,"z":64},"requirements":{"minecraft:polished_diorite":15},"sha256":"438cfa4e2498618a9bd3c8810be176946c57d1a6ac0d567969fdbc003e0a5367","size":{"x":32,"y":1,"z":32}},{"blockCount":10,"bytes":944,"file":"chunks/y131-z096-x000.json","offset":{"x":0,"y":131,"z":96},"requirements":{"minecraft:polished_diorite":8,"minecraft:stone_bricks":2},"sha256":"3a56afeab635a6b8a600fe2c859001fdf0f968ce56d3336b7694febeab23862a","size":{"x":32,"y":1,"z":32}},{"blockCount":100,"bytes":2593,"file":"chunks/y131-z096-x032.json","offset":{"x":32,"y":131,"z":96},"requirements":{"minecraft:bricks":5,"minecraft:cobbled_deepslate":20,"minecraft:polished_diorite":61,"minecraft:stone_bricks":14},"sha256":"bc0a1572ee4ee63417702dbf36a83bbb367af5c8eee30a89b965217e4a50fb1c","size":{"x":32,"y":1,"z":32}},{"blockCount":151,"bytes":2928,"file":"chunks/y131-z096-x064.json","offset":{"x":64,"y":131,"z":96},"requirements":{"minecraft:bricks":42,"minecraft:cobbled_deepslate":30,"minecraft:polished_diorite":64,"minecraft:stone_bricks":15},"sha256":"cfa530359992e83933c4d0184eb801335f0db8ba878b58dbf76c09b6fb7de2aa","size":{"x":32,"y":1,"z":32}},{"blockCount":152,"bytes":4313,"file":"chunks/y131-z096-x096.json","offset":{"x":96,"y":131,"z":96},"requirements":{"minecraft:bricks":68,"minecraft:cobbled_deepslate":36,"minecraft:glass":2,"minecraft:polished_diorite":37,"minecraft:sandstone":3,"minecraft:stone_bricks":6},"sha256":"36b1408079660984fde72ddde70dfa82b795608e33dfc76135d6ce5b0ddb46d0","size":{"x":32,"y":1,"z":32}},{"blockCount":205,"bytes":5103,"file":"chunks/y131-z096-x128.json","offset":{"x":128,"y":131,"z":96},"requirements":{"minecraft:bricks":71,"minecraft:cobbled_deepslate":45,"minecraft:glass":3,"minecraft:polished_diorite":64,"minecraft:sandstone":3,"minecraft:stone_bricks":19},"sha256":"d2c9d5508e17c2a41ae5f2d3200397b3f1eb6752008c780f606f9ac125396c32","size":{"x":32,"y":1,"z":32}},{"blockCount":154,"bytes":3022,"file":"chunks/y131-z096-x160.json","offset":{"x":160,"y":131,"z":96},"requirements":{"minecraft:bricks":43,"minecraft:cobbled_deepslate":29,"minecraft:polished_diorite":68,"minecraft:stone_bricks":14},"sha256":"26a621cadc25114acb8a1deb30c6c2810a074cd232bdf4426acd0a9e9563d52d","size":{"x":32,"y":1,"z":32}},{"blockCount":242,"bytes":5062,"file":"chunks/y131-z096-x192.json","offset":{"x":192,"y":131,"z":96},"requirements":{"minecraft:bricks":83,"minecraft:cobbled_deepslate":30,"minecraft:glass":5,"minecraft:oak_planks":2,"minecraft:polished_diorite":100,"minecraft:spruce_planks":3,"minecraft:stone_bricks":19},"sha256":"c0137a8d052ac202c394c43ce5ab62d5b27f5fbd02db28f3fceb8703b6179a8a","size":{"x":32,"y":1,"z":32}},{"blockCount":136,"bytes":3710,"file":"chunks/y131-z096-x224.json","offset":{"x":224,"y":131,"z":96},"requirements":{"minecraft:bricks":43,"minecraft:cobbled_deepslate":4,"minecraft:glass":14,"minecraft:polished_diorite":72,"minecraft:sandstone":1,"minecraft:stone_bricks":2},"sha256":"ffd8d528e49c5608cbaa6e4653fd331266f5d5b284f4147a55f3961484f7e925","size":{"x":32,"y":1,"z":32}},{"blockCount":17,"bytes":1199,"file":"chunks/y131-z128-x000.json","offset":{"x":0,"y":131,"z":128},"requirements":{"minecraft:polished_diorite":14,"minecraft:stone_bricks":3},"sha256":"ce0eb7d8c391ea09d90b0c274e2d4ab43a7e48e0811ff071bf9332cbc848631f","size":{"x":32,"y":1,"z":32}},{"blockCount":147,"bytes":4173,"file":"chunks/y131-z128-x032.json","offset":{"x":32,"y":131,"z":128},"requirements":{"minecraft:bricks":44,"minecraft:cobbled_deepslate":43,"minecraft:polished_diorite":43,"minecraft:sandstone":3,"minecraft:stone_bricks":14},"sha256":"9788e64f80a79b8f7a030eb7fe9b5e4d6efb4e4b5dd904e4ae087ce8f798af73","size":{"x":32,"y":1,"z":32}},{"blockCount":138,"bytes":3226,"file":"chunks/y131-z128-x064.json","offset":{"x":64,"y":131,"z":128},"requirements":{"minecraft:bricks":75,"minecraft:cobbled_deepslate":27,"minecraft:glass":4,"minecraft:polished_diorite":21,"minecraft:sandstone":4,"minecraft:stone_bricks":7},"sha256":"73c7cf7448e9d2dc9aa7aad049f6e9f22eece69ad8c37fb307e50b6a32cdf076","size":{"x":32,"y":1,"z":32}},{"blockCount":56,"bytes":2197,"file":"chunks/y131-z128-x096.json","offset":{"x":96,"y":131,"z":128},"requirements":{"minecraft:bricks":36,"minecraft:cobbled_deepslate":12,"minecraft:glass":3,"minecraft:sandstone":5},"sha256":"bff82ed4cbb540e4d08ac771b057a8217e305364817bac15818b65e0c92ec6e8","size":{"x":32,"y":1,"z":32}},{"blockCount":122,"bytes":3364,"file":"chunks/y131-z128-x128.json","offset":{"x":128,"y":131,"z":128},"requirements":{"minecraft:bricks":73,"minecraft:cobbled_deepslate":25,"minecraft:glass":5,"minecraft:polished_diorite":9,"minecraft:sandstone":7,"minecraft:stone_bricks":3},"sha256":"6434cf7f36c4fed3bf8c857ba0a163a838481d3e52cec23f5e403e7dcf4a41ad","size":{"x":32,"y":1,"z":32}},{"blockCount":137,"bytes":3285,"file":"chunks/y131-z128-x160.json","offset":{"x":160,"y":131,"z":128},"requirements":{"minecraft:bricks":73,"minecraft:cobbled_deepslate":25,"minecraft:glass":4,"minecraft:polished_diorite":22,"minecraft:sandstone":4,"minecraft:stone_bricks":9},"sha256":"582f24cfedbbd74f2d5a101ce0295638710df6f85fdd791418b3486bb3f18ea9","size":{"x":32,"y":1,"z":32}},{"blockCount":153,"bytes":3640,"file":"chunks/y131-z128-x192.json","offset":{"x":192,"y":131,"z":128},"requirements":{"minecraft:bricks":81,"minecraft:cobbled_deepslate":29,"minecraft:glass":2,"minecraft:oak_planks":2,"minecraft:polished_diorite":22,"minecraft:sandstone":6,"minecraft:spruce_planks":3,"minecraft:stone_bricks":8},"sha256":"adb717cd08d2c17be82191e1aa5bc019c067e1193abbaa26c8624ee743caed68","size":{"x":32,"y":1,"z":32}},{"blockCount":107,"bytes":3165,"file":"chunks/y131-z128-x224.json","offset":{"x":224,"y":131,"z":128},"requirements":{"minecraft:bricks":16,"minecraft:cobbled_deepslate":3,"minecraft:oak_planks":9,"minecraft:polished_diorite":57,"minecraft:sandstone":13,"minecraft:stone_bricks":9},"sha256":"2c6d8d0f4a1c07736f60afee1a8a9f129a8972c46d8ddddb219d3c9eec66bbef","size":{"x":32,"y":1,"z":32}},{"blockCount":5,"bytes":790,"file":"chunks/y131-z160-x000.json","offset":{"x":0,"y":131,"z":160},"requirements":{"minecraft:polished_diorite":4,"minecraft:stone_bricks":1},"sha256":"fdae162c2d7f2e54e3b3ce748b07a0b8cc35adac66d98b454f8174f25b1fac8d","size":{"x":32,"y":1,"z":32}},{"blockCount":44,"bytes":1774,"file":"chunks/y131-z160-x032.json","offset":{"x":32,"y":131,"z":160},"requirements":{"minecraft:polished_diorite":36,"minecraft:stone_bricks":8},"sha256":"4c0290cd45249fa4bae3881755ab1e7965082822adbb2b9df197f7c35db45318","size":{"x":32,"y":1,"z":32}},{"blockCount":55,"bytes":2075,"file":"chunks/y131-z160-x064.json","offset":{"x":64,"y":131,"z":160},"requirements":{"minecraft:polished_diorite":44,"minecraft:stone_bricks":11},"sha256":"500c895db6dd6400b6e848131adc9085492b087ebbd93c5be3d441264138d2f4","size":{"x":32,"y":1,"z":32}},{"blockCount":155,"bytes":4541,"file":"chunks/y131-z160-x096.json","offset":{"x":96,"y":131,"z":160},"requirements":{"minecraft:bricks":65,"minecraft:cobbled_deepslate":29,"minecraft:glass":2,"minecraft:polished_diorite":48,"minecraft:sandstone":2,"minecraft:stone_bricks":9},"sha256":"ff7a778623d02130d8e9f75781ff7e8235ffcbbd94c88389615d4782d3ef11bd","size":{"x":32,"y":1,"z":32}},{"blockCount":160,"bytes":4800,"file":"chunks/y131-z160-x128.json","offset":{"x":128,"y":131,"z":160},"requirements":{"minecraft:bricks":45,"minecraft:cobbled_deepslate":29,"minecraft:glass":2,"minecraft:polished_diorite":67,"minecraft:sandstone":2,"minecraft:stone_bricks":15},"sha256":"83dc5293c75a4a4e8e5e9740b409ea93c369b85febe6f5960405d3a4e3287138","size":{"x":32,"y":1,"z":32}},{"blockCount":55,"bytes":2032,"file":"chunks/y131-z160-x160.json","offset":{"x":160,"y":131,"z":160},"requirements":{"minecraft:polished_diorite":46,"minecraft:stone_bricks":9},"sha256":"f446c4ac011b54636f9496f06470d7eea30781e8fe2bb9c507ef205f12d35760","size":{"x":32,"y":1,"z":32}},{"blockCount":140,"bytes":4023,"file":"chunks/y131-z160-x192.json","offset":{"x":192,"y":131,"z":160},"requirements":{"minecraft:bricks":34,"minecraft:cobbled_deepslate":1,"minecraft:glass":5,"minecraft:polished_diorite":89,"minecraft:stone_bricks":11},"sha256":"34efd18c504a5afebf0d00872e90ad981341518fe0d2f927a052d1518f08d3ea","size":{"x":32,"y":1,"z":32}},{"blockCount":121,"bytes":3475,"file":"chunks/y131-z160-x224.json","offset":{"x":224,"y":131,"z":160},"requirements":{"minecraft:bricks":39,"minecraft:glass":14,"minecraft:polished_diorite":68},"sha256":"785bcb00012d8db1b227c3f585eafeddca4aeca71833e63cd85770b7937da56c","size":{"x":32,"y":1,"z":32}},{"blockCount":12,"bytes":1025,"file":"chunks/y131-z192-x064.json","offset":{"x":64,"y":131,"z":192},"requirements":{"minecraft:polished_diorite":8,"minecraft:stone_bricks":4},"sha256":"e2b7de5491581839b90f36ca3c28428c8862c5eeb854804d9efb308d77e911bc","size":{"x":32,"y":1,"z":32}},{"blockCount":177,"bytes":3879,"file":"chunks/y131-z192-x096.json","offset":{"x":96,"y":131,"z":192},"requirements":{"minecraft:bricks":38,"minecraft:cobbled_deepslate":17,"minecraft:oak_planks":7,"minecraft:polished_diorite":87,"minecraft:sandstone":13,"minecraft:stone_bricks":15},"sha256":"11bb24ecd80e5645a285f476b76d881eff261525299a3a2186ad2f1c233d8202","size":{"x":32,"y":1,"z":32}},{"blockCount":134,"bytes":3581,"file":"chunks/y131-z192-x128.json","offset":{"x":128,"y":131,"z":192},"requirements":{"minecraft:bricks":30,"minecraft:cobbled_deepslate":18,"minecraft:oak_planks":2,"minecraft:polished_diorite":69,"minecraft:sandstone":3,"minecraft:stone_bricks":12},"sha256":"a5cb685c3487739850da3ff63c4e2f0cfbce99c4774d6d0a373ad21656287807","size":{"x":32,"y":1,"z":32}},{"blockCount":11,"bytes":985,"file":"chunks/y132-z064-x064.json","offset":{"x":64,"y":132,"z":64},"requirements":{"minecraft:polished_diorite":2,"minecraft:stone_bricks":9},"sha256":"f7c71eac9b0f125a4a9c42b658483e3eceacbb5263fa8bba17a7eaa7e9ed11d5","size":{"x":32,"y":1,"z":32}},{"blockCount":194,"bytes":5119,"file":"chunks/y132-z064-x096.json","offset":{"x":96,"y":132,"z":64},"requirements":{"minecraft:bricks":41,"minecraft:cobbled_deepslate":23,"minecraft:oak_planks":9,"minecraft:polished_diorite":82,"minecraft:sandstone":8,"minecraft:stone_bricks":31},"sha256":"f86157f56ab1cce9e9d94684de5474188e212f307889b6d95d6d4c46226c1755","size":{"x":32,"y":1,"z":32}},{"blockCount":144,"bytes":4553,"file":"chunks/y132-z064-x128.json","offset":{"x":128,"y":132,"z":64},"requirements":{"minecraft:bricks":31,"minecraft:cobbled_deepslate":22,"minecraft:oak_planks":1,"minecraft:polished_diorite":51,"minecraft:sandstone":1,"minecraft:stone_bricks":38},"sha256":"65bd127293f618adb8a86c0829383e34cd7c02424d4d3c66d1e75e405fcfc52b","size":{"x":32,"y":1,"z":32}},{"blockCount":17,"bytes":1077,"file":"chunks/y132-z064-x192.json","offset":{"x":192,"y":132,"z":64},"requirements":{"minecraft:polished_diorite":11,"minecraft:stone_bricks":6},"sha256":"1e3d638fc978f24c232c5a6685311a2933d1c4a3b012b63b62171fd21aa68ad4","size":{"x":32,"y":1,"z":32}},{"blockCount":25,"bytes":1307,"file":"chunks/y132-z064-x224.json","offset":{"x":224,"y":132,"z":64},"requirements":{"minecraft:polished_diorite":15,"minecraft:stone_bricks":10},"sha256":"31c44255a3309ad0ce6f43c632018ecc63e4bcf5f0c7ec39d4b291e3b29eb747","size":{"x":32,"y":1,"z":32}},{"blockCount":9,"bytes":925,"file":"chunks/y132-z096-x000.json","offset":{"x":0,"y":132,"z":96},"requirements":{"minecraft:polished_diorite":3,"minecraft:stone_bricks":6},"sha256":"82dafefabd0637e410045b77251010b3dfc12e2c3c0baee1ce6c3f7942d9489d","size":{"x":32,"y":1,"z":32}},{"blockCount":86,"bytes":2570,"file":"chunks/y132-z096-x032.json","offset":{"x":32,"y":132,"z":96},"requirements":{"minecraft:cobbled_deepslate":19,"minecraft:polished_diorite":37,"minecraft:stone_bricks":30},"sha256":"bd3b1eb62d3c5cc8b6a6db5459c95235b61d94affd448fc7b3f0ec30724d00ea","size":{"x":32,"y":1,"z":32}},{"blockCount":126,"bytes":2941,"file":"chunks/y132-z096-x064.json","offset":{"x":64,"y":132,"z":96},"requirements":{"minecraft:bricks":28,"minecraft:cobbled_deepslate":28,"minecraft:polished_diorite":39,"minecraft:stone_bricks":31},"sha256":"1b66204818aa32dd4f6520a0f9e05cce50638a39235b2ba4d9b3b050b67d1acc","size":{"x":32,"y":1,"z":32}},{"blockCount":154,"bytes":5037,"file":"chunks/y132-z096-x096.json","offset":{"x":96,"y":132,"z":96},"requirements":{"minecraft:bricks":62,"minecraft:cobbled_deepslate":36,"minecraft:glass":2,"minecraft:polished_diorite":25,"minecraft:stone_bricks":29},"sha256":"8a5bcf25bd13cf7b2b598b5d968b1091ceac41860ec03ac4825a58e4fb437b38","size":{"x":32,"y":1,"z":32}},{"blockCount":189,"bytes":5266,"file":"chunks/y132-z096-x128.json","offset":{"x":128,"y":132,"z":96},"requirements":{"minecraft:bricks":59,"minecraft:cobbled_deepslate":48,"minecraft:glass":3,"minecraft:polished_diorite":42,"minecraft:stone_bricks":37},"sha256":"4e1d2229729197e158f6bfe1b32432ae76ba7f756619dce6457fe35fa94fd7e5","size":{"x":32,"y":1,"z":32}},{"blockCount":129,"bytes":3019,"file":"chunks/y132-z096-x160.json","offset":{"x":160,"y":132,"z":96},"requirements":{"minecraft:bricks":27,"minecraft:cobbled_deepslate":29,"minecraft:polished_diorite":41,"minecraft:stone_bricks":32},"sha256":"8ac9ef5d2b5f9c0d3d16b034187fe4298c0cf0d4148979943a50095b0f2bc127","size":{"x":32,"y":1,"z":32}},{"blockCount":238,"bytes":5252,"file":"chunks/y132-z096-x192.json","offset":{"x":192,"y":132,"z":96},"requirements":{"minecraft:bricks":69,"minecraft:cobbled_deepslate":33,"minecraft:glass":5,"minecraft:oak_planks":2,"minecraft:polished_diorite":85,"minecraft:spruce_planks":3,"minecraft:stone_bricks":41},"sha256":"daaaa38539ac9595c87daf4601b762764a85484b8096abff9ef823745fb1a518","size":{"x":32,"y":1,"z":32}},{"blockCount":147,"bytes":3858,"file":"chunks/y132-z096-x224.json","offset":{"x":224,"y":132,"z":96},"requirements":{"minecraft:bricks":41,"minecraft:cobbled_deepslate":4,"minecraft:glass":14,"minecraft:polished_diorite":69,"minecraft:stone_bricks":19},"sha256":"885b8a7db1c687449927c02b123dccf550cc08716b5e0c3dcc97f19b188a3f70","size":{"x":32,"y":1,"z":32}},{"blockCount":16,"bytes":1180,"file":"chunks/y132-z128-x000.json","offset":{"x":0,"y":132,"z":128},"requirements":{"minecraft:polished_diorite":6,"minecraft:stone_bricks":10},"sha256":"b2e562d3c8fdde340ca12637eea4941b7ba255cf2d03ef6ddc7632623f05207d","size":{"x":32,"y":1,"z":32}},{"blockCount":138,"bytes":4126,"file":"chunks/y132-z128-x032.json","offset":{"x":32,"y":132,"z":128},"requirements":{"minecraft:bricks":49,"minecraft:cobbled_deepslate":36,"minecraft:polished_diorite":28,"minecraft:stone_bricks":25},"sha256":"fb986739cb7944ca40daf2ac06a685fa84988be38e232e5b4a8f6dc3b41aefb8","size":{"x":32,"y":1,"z":32}},{"blockCount":139,"bytes":3631,"file":"chunks/y132-z128-x064.json","offset":{"x":64,"y":132,"z":128},"requirements":{"minecraft:bricks":66,"minecraft:cobbled_deepslate":31,"minecraft:glass":4,"minecraft:polished_diorite":11,"minecraft:stone_bricks":27},"sha256":"b316f9840012a451d79a7814276f416ae3e07b2c1441ba167a9cf6e50a59cffe","size":{"x":32,"y":1,"z":32}},{"blockCount":77,"bytes":2736,"file":"chunks/y132-z128-x096.json","offset":{"x":96,"y":132,"z":128},"requirements":{"minecraft:bricks":47,"minecraft:cobbled_deepslate":14,"minecraft:glass":3,"minecraft:stone_bricks":13},"sha256":"628f4f5ac9b269dccce15ecda67de8b7de738de586aea7917872d4b88158d457","size":{"x":32,"y":1,"z":32}},{"blockCount":142,"bytes":4179,"file":"chunks/y132-z128-x128.json","offset":{"x":128,"y":132,"z":128},"requirements":{"minecraft:bricks":80,"minecraft:cobbled_deepslate":26,"minecraft:glass":5,"minecraft:polished_diorite":5,"minecraft:stone_bricks":26},"sha256":"b88427ed64e27822435e5ce9c4bae0e30b9aca76a3877e8bf258af0a5b3bb378","size":{"x":32,"y":1,"z":32}},{"blockCount":143,"bytes":3860,"file":"chunks/y132-z128-x160.json","offset":{"x":160,"y":132,"z":128},"requirements":{"minecraft:bricks":67,"minecraft:cobbled_deepslate":28,"minecraft:glass":4,"minecraft:polished_diorite":12,"minecraft:stone_bricks":32},"sha256":"e113f31620e58d3b15a5d0c31bc924d182dd4228ddd9d35f4ed0ba90d0fa7f2d","size":{"x":32,"y":1,"z":32}},{"blockCount":156,"bytes":4117,"file":"chunks/y132-z128-x192.json","offset":{"x":192,"y":132,"z":128},"requirements":{"minecraft:bricks":77,"minecraft:cobbled_deepslate":31,"minecraft:glass":2,"minecraft:oak_planks":2,"minecraft:polished_diorite":18,"minecraft:spruce_planks":3,"minecraft:stone_bricks":23},"sha256":"9dc4af4fe76f85bc6a9e6af0e13afd3df76aff235e2e871ac267b8dc16721940","size":{"x":32,"y":1,"z":32}},{"blockCount":112,"bytes":3147,"file":"chunks/y132-z128-x224.json","offset":{"x":224,"y":132,"z":128},"requirements":{"minecraft:bricks":12,"minecraft:cobbled_deepslate":3,"minecraft:oak_planks":10,"minecraft:polished_diorite":61,"minecraft:sandstone":9,"minecraft:stone_bricks":17},"sha256":"797b02f06727621680b0a886b32037d81062eec1daede0290d907fd07039e9a3","size":{"x":32,"y":1,"z":32}},{"blockCount":5,"bytes":790,"file":"chunks/y132-z160-x000.json","offset":{"x":0,"y":132,"z":160},"requirements":{"minecraft:polished_diorite":1,"minecraft:stone_bricks":4},"sha256":"4b4b92bc8f2a74a25c0aa52e764d1ce97f6c85ed45c1347c446076d881825393","size":{"x":32,"y":1,"z":32}},{"blockCount":39,"bytes":1754,"file":"chunks/y132-z160-x032.json","offset":{"x":32,"y":132,"z":160},"requirements":{"minecraft:polished_diorite":21,"minecraft:stone_bricks":18},"sha256":"6ba9c9244da013a014f796f56ae1fce7bca41891ec8dd59142d811b2d1687f1f","size":{"x":32,"y":1,"z":32}},{"blockCount":46,"bytes":1994,"file":"chunks/y132-z160-x064.json","offset":{"x":64,"y":132,"z":160},"requirements":{"minecraft:polished_diorite":28,"minecraft:stone_bricks":18},"sha256":"13771b64d11c75946766683d11031e5f4c0f69a92189ed846191a90d73d5378f","size":{"x":32,"y":1,"z":32}},{"blockCount":150,"bytes":5245,"file":"chunks/y132-z160-x096.json","offset":{"x":96,"y":132,"z":160},"requirements":{"minecraft:bricks":58,"minecraft:cobbled_deepslate":30,"minecraft:glass":2,"minecraft:polished_diorite":32,"minecraft:stone_bricks":28},"sha256":"63ca5e38c592c6dbdd1305bdc64025bcad24a198d71a386d0d3a8204344b0478","size":{"x":32,"y":1,"z":32}},{"blockCount":146,"bytes":4985,"file":"chunks/y132-z160-x128.json","offset":{"x":128,"y":132,"z":160},"requirements":{"minecraft:bricks":38,"minecraft:cobbled_deepslate":29,"minecraft:glass":2,"minecraft:polished_diorite":44,"minecraft:stone_bricks":33},"sha256":"f233a8a835d45375c253f92213c863d95e4564ce8ce3381c2eff45c5559aa609","size":{"x":32,"y":1,"z":32}},{"blockCount":48,"bytes":2051,"file":"chunks/y132-z160-x160.json","offset":{"x":160,"y":132,"z":160},"requirements":{"minecraft:polished_diorite":29,"minecraft:stone_bricks":19},"sha256":"b216f4ab9796c9df01d11af759b80e62e5ecd77e51b3682e1a0edfbfeda5ae07","size":{"x":32,"y":1,"z":32}},{"blockCount":149,"bytes":4232,"file":"chunks/y132-z160-x192.json","offset":{"x":192,"y":132,"z":160},"requirements":{"minecraft:bricks":34,"minecraft:cobbled_deepslate":1,"minecraft:glass":5,"minecraft:polished_diorite":78,"minecraft:stone_bricks":31},"sha256":"8167b682e67cb23fa631f2a386fa36795153cf2b1d56fa48539abc254d77f8f4","size":{"x":32,"y":1,"z":32}},{"blockCount":139,"bytes":3787,"file":"chunks/y132-z160-x224.json","offset":{"x":224,"y":132,"z":160},"requirements":{"minecraft:bricks":39,"minecraft:glass":14,"minecraft:polished_diorite":68,"minecraft:stone_bricks":18},"sha256":"76c854c82d7ae93e26a1813078a15db3b0e3952987dbc9e5328b8429e93c13d6","size":{"x":32,"y":1,"z":32}},{"blockCount":10,"bytes":947,"file":"chunks/y132-z192-x064.json","offset":{"x":64,"y":132,"z":192},"requirements":{"minecraft:polished_diorite":2,"minecraft:stone_bricks":8},"sha256":"13ab5dbbe498b36bcc167eb40e0d7b58b7f8f6f2d3885cbb2a84c00bfa4013fd","size":{"x":32,"y":1,"z":32}},{"blockCount":162,"bytes":4163,"file":"chunks/y132-z192-x096.json","offset":{"x":96,"y":132,"z":192},"requirements":{"minecraft:bricks":28,"minecraft:cobbled_deepslate":16,"minecraft:oak_planks":9,"minecraft:polished_diorite":75,"minecraft:sandstone":8,"minecraft:stone_bricks":26},"sha256":"fd0d3216421e68b1305e7a7589e42a0bc312478e095df9efe2e5d011a698c082","size":{"x":32,"y":1,"z":32}},{"blockCount":115,"bytes":3732,"file":"chunks/y132-z192-x128.json","offset":{"x":128,"y":132,"z":192},"requirements":{"minecraft:bricks":22,"minecraft:cobbled_deepslate":18,"minecraft:oak_planks":1,"minecraft:polished_diorite":44,"minecraft:sandstone":1,"minecraft:stone_bricks":29},"sha256":"5af8877e43a77641fae9aab3d5f72bf5bf318cf364415ac6196e5301386b0e1a","size":{"x":32,"y":1,"z":32}},{"blockCount":11,"bytes":985,"file":"chunks/y133-z064-x064.json","offset":{"x":64,"y":133,"z":64},"requirements":{"minecraft:polished_diorite":9,"minecraft:stone_bricks":2},"sha256":"2a02db598c245a1381a932a42b80b8770832f98270c436c429c87bff5a416f0f","size":{"x":32,"y":1,"z":32}},{"blockCount":171,"bytes":4930,"file":"chunks/y133-z064-x096.json","offset":{"x":96,"y":133,"z":64},"requirements":{"minecraft:bricks":41,"minecraft:cobbled_deepslate":24,"minecraft:oak_planks":12,"minecraft:polished_diorite":59,"minecraft:sandstone":7,"minecraft:stone_bricks":28},"sha256":"86782e7e3ebcdfa25e0d99abbe494d3a1cafe52c0330c07476a0654215641f1f","size":{"x":32,"y":1,"z":32}},{"blockCount":122,"bytes":4553,"file":"chunks/y133-z064-x128.json","offset":{"x":128,"y":133,"z":64},"requirements":{"minecraft:bricks":28,"minecraft:cobbled_deepslate":24,"minecraft:oak_planks":1,"minecraft:polished_diorite":40,"minecraft:sandstone":3,"minecraft:stone_bricks":26},"sha256":"e5ff591a02bed67c2a460093bde927360daf684de70d7a918dca6ebdaa4c1efe","size":{"x":32,"y":1,"z":32}},{"blockCount":11,"bytes":981,"file":"chunks/y133-z064-x192.json","offset":{"x":192,"y":133,"z":64},"requirements":{"minecraft:polished_diorite":6,"minecraft:stone_bricks":5},"sha256":"5489d08bd8a9fddff4ed6fe3a0253a36e5c57963dbb1ca7902517c7fe0f04748","size":{"x":32,"y":1,"z":32}}],"schema":1}
