{"entries":[{"blockCount":15,"bytes":1135,"file":"chunks/y133-z064-x224.json","offset":{"x":224,"y":133,"z":64},"requirements":{"minecraft:polished_diorite":6,"minecraft:stone_bricks":9},"sha256":"504bc9cf7ce5bb55e31ba9e12ea17a6aa2fd2e2278e0426f18843f0557b3d891","size":{"x":32,"y":1,"z":32}},{"blockCount":8,"bytes":886,"file":"chunks/y133-z096-x000.json","offset":{"x":0,"y":133,"z":96},"requirements":{"minecraft:polished_diorite":6,"minecraft:stone_bricks":2},"sha256":"509eddbab25c6a16d6a10839d797d53499b60c2ed5e4ca5c89705efc8384aa27","size":{"x":32,"y":1,"z":32}},{"blockCount":71,"bytes":2514,"file":"chunks/y133-z096-x032.json","offset":{"x":32,"y":133,"z":96},"requirements":{"minecraft:cobbled_deepslate":17,"minecraft:polished_diorite":29,"minecraft:stone_bricks":25},"sha256":"f04c99c57b23706a3f326cd8037cb7006e5073ee2e037929e3d05bb661ec9950","size":{"x":32,"y":1,"z":32}},{"blockCount":99,"bytes":2432,"file":"chunks/y133-z096-x064.json","offset":{"x":64,"y":133,"z":96},"requirements":{"minecraft:bricks":21,"minecraft:cobbled_deepslate":30,"minecraft:polished_diorite":26,"minecraft:stone_bricks":22},"sha256":"0edd12828958f548c56191d50d5987b00724c6e710302bf1542576396c91bb74","size":{"x":32,"y":1,"z":32}},{"blockCount":137,"bytes":4717,"file":"chunks/y133-z096-x096.json","offset":{"x":96,"y":133,"z":96},"requirements":{"minecraft:bricks":56,"minecraft:cobbled_deepslate":36,"minecraft:glass":3,"minecraft:polished_diorite":13,"minecraft:sandstone":3,"minecraft:stone_bricks":26},"sha256":"5dd6eeb1b3031a2b32cf62feb1feb1af72563b68c771a42cf67762e3e400bba4","size":{"x":32,"y":1,"z":32}},{"blockCount":161,"bytes":5138,"file":"chunks/y133-z096-x128.json","offset":{"x":128,"y":133,"z":96},"requirements":{"minecraft:bricks":51,"minecraft:cobbled_deepslate":46,"minecraft:glass":3,"minecraft:polished_diorite":24,"minecraft:sandstone":3,"minecraft:stone_bricks":34},"sha256":"1f810bcc0f33be2778332fbb3e4de6aae7ddfed3545a2029003a210e395ba0bc","size":{"x":32,"y":1,"z":32}},{"blockCount":102,"bytes":2644,"file":"chunks/y133-z096-x160.json","offset":{"x":160,"y":133,"z":96},"requirements":{"minecraft:bricks":20,"minecraft:cobbled_deepslate":29,"minecraft:polished_diorite":28,"minecraft:stone_bricks":25},"sha256":"eabf53059d3fb8a45e0bab15a18d9e9caa64344e097e8dc35891e50e91048184","size":{"x":32,"y":1,"z":32}},{"blockCount":214,"bytes":5065,"file":"chunks/y133-z096-x192.json","offset":{"x":192,"y":133,"z":96},"requirements":{"minecraft:bricks":62,"minecraft:cobbled_deepslate":30,"minecraft:glass":6,"minecraft:oak_planks":3,"minecraft:polished_diorite":64,"minecraft:spruce_planks":3,"minecraft:stone_bricks":46},"sha256":"e1be3e97a5943131cbd9503680f1ca9a1c15daf1b5731aee1ea849b6849f8b61","size":{"x":32,"y":1,"z":32}},{"blockCount":133,"bytes":3687,"file":"chunks/y133-z096-x224.json","offset":{"x":224,"y":133,"z":96},"requirements":{"minecraft:bricks":41,"minecraft:cobbled_deepslate":4,"minecraft:glass":14,"minecraft:polished_diorite":55,"minecraft:stone_bricks":19},"sha256":"fc43d867a9364c76e13e025faa48ecac1fcfb452d7677040b3548f501c1d73bc","size":{"x":32,"y":1,"z":32}},{"blockCount":13,"bytes":1062,"file":"chunks/y133-z128-x000.json","offset":{"x":0,"y":133,"z":128},"requirements":{"minecraft:polished_diorite":8,"minecraft:stone_bricks":5},"sha256":"3f17c1d47b4d4a101c7d55ced44a82cbfc9bb9346092e2bf6b90a03ffddc2ac9","size":{"x":32,"y":1,"z":32}},{"blockCount":126,"bytes":4175,"file":"chunks/y133-z128-x032.json","offset":{"x":32,"y":133,"z":128},"requirements":{"minecraft:bricks":47,"minecraft:cobbled_deepslate":42,"minecraft:polished_diorite":15,"minecraft:sandstone":3,"minecraft:stone_bricks":19},"sha256":"1bbe4368d2e725acec9be74d0842cbd6ba913a55beb84991ea418dc9e2580d11","size":{"x":32,"y":1,"z":32}},{"blockCount":126,"bytes":3332,"file":"chunks/y133-z128-x064.json","offset":{"x":64,"y":133,"z":128},"requirements":{"minecraft:bricks":63,"minecraft:cobbled_deepslate":31,"minecraft:glass":4,"minecraft:polished_diorite":7,"minecraft:sandstone":4,"minecraft:stone_bricks":17},"sha256":"0096db585f033627998f7a118344343dce46663d8d73648b9072cd90872ff360","size":{"x":32,"y":1,"z":32}},{"blockCount":85,"bytes":2798,"file":"chunks/y133-z128-x096.json","offset":{"x":96,"y":133,"z":128},"requirements":{"minecraft:bricks":53,"minecraft:cobbled_deepslate":14,"minecraft:glass":3,"minecraft:sandstone":5,"minecraft:stone_bricks":10},"sha256":"f9bf9bf4a3c21b5bf536f69887a8c9094d9a451d7aca20dcf862304bc74928d8","size":{"x":32,"y":1,"z":32}},{"blockCount":142,"bytes":3994,"file":"chunks/y133-z128-x128.json","offset":{"x":128,"y":133,"z":128},"requirements":{"minecraft:bricks":82,"minecraft:cobbled_deepslate":26,"minecraft:glass":5,"minecraft:polished_diorite":3,"minecraft:sandstone":7,"minecraft:stone_bricks":19},"sha256":"d5b7a08cda1d0f17f6024fcfddf7fbd70b050f4286801509e7a396e48edd7f2e","size":{"x":32,"y":1,"z":32}},{"blockCount":132,"bytes":3542,"file":"chunks/y133-z128-x160.json","offset":{"x":160,"y":133,"z":128},"requirements":{"minecraft:bricks":66,"minecraft:cobbled_deepslate":30,"minecraft:glass":4,"minecraft:polished_diorite":7,"minecraft:sandstone":4,"minecraft:stone_bricks":21},"sha256":"183c782ab116c6bf40719c78b9b585a4db9b61087931f7c167c74a7df3c9676c","size":{"x":32,"y":1,"z":32}},{"blockCount":153,"bytes":4050,"file":"chunks/y133-z128-x192.json","offset":{"x":192,"y":133,"z":128},"requirements":{"minecraft:bricks":75,"minecraft:cobbled_deepslate":33,"minecraft:glass":2,"minecraft:oak_planks":3,"minecraft:polished_diorite":12,"minecraft:sandstone":6,"minecraft:spruce_planks":3,"minecraft:stone_bricks":19},"sha256":"343811541b107a4763f7b07777ed399edad13301bfd915ef8b2f06608acc7043","size":{"x":32,"y":1,"z":32}},{"blockCount":103,"bytes":3090,"file":"chunks/y133-z128-x224.json","offset":{"x":224,"y":133,"z":128},"requirements":{"minecraft:bricks":13,"minecraft:cobbled_deepslate":4,"minecraft:oak_planks":13,"minecraft:polished_diorite":52,"minecraft:sandstone":8,"minecraft:stone_bricks":13},"sha256":"83b42751d78006ba44201dd54a046ea0608490cc61c8a2bb5556d8c508ce68fa","size":{"x":32,"y":1,"z":32}},{"blockCount":5,"bytes":790,"file":"chunks/y133-z160-x000.json","offset":{"x":0,"y":133,"z":160},"requirements":{"minecraft:polished_diorite":4,"minecraft:stone_bricks":1},"sha256":"47d8e859d009d5712597f583bf4d3e22dd7d5ccebb78edcc6762b26633efabf8","size":{"x":32,"y":1,"z":32}},{"blockCount":33,"bytes":1717,"file":"chunks/y133-z160-x032.json","offset":{"x":32,"y":133,"z":160},"requirements":{"minecraft:polished_diorite":20,"minecraft:stone_bricks":13},"sha256":"5139786b27748857a306e3b82f58fac383540397979976a5a256e068821c943c","size":{"x":32,"y":1,"z":32}},{"blockCount":36,"bytes":1863,"file":"chunks/y133-z160-x064.json","offset":{"x":64,"y":133,"z":160},"requirements":{"minecraft:polished_diorite":20,"minecraft:stone_bricks":16},"sha256":"ec92b28937b65dda432c408fe79a0c7850df736f2be0fa56a3470ab413119dd2","size":{"x":32,"y":1,"z":32}},{"blockCount":130,"bytes":4908,"file":"chunks/y133-z160-x096.json","offset":{"x":96,"y":133,"z":160},"requirements":{"minecraft:bricks":54,"minecraft:cobbled_deepslate":28,"minecraft:glass":2,"minecraft:polished_diorite":16,"minecraft:sandstone":2,"minecraft:stone_bricks":28},"sha256":"b378ee118708c2e2aa423becfd00871aa61ee137643ae5f67c0331bb8c780a98","size":{"x":32,"y":1,"z":32}},{"blockCount":122,"bytes":5028,"file":"chunks/y133-z160-x128.json","offset":{"x":128,"y":133,"z":160},"requirements":{"minecraft:bricks":34,"minecraft:cobbled_deepslate":28,"minecraft:glass":2,"minecraft:polished_diorite":25,"minecraft:sandstone":2,"minecraft:stone_bricks":31},"sha256":"0a77acea62868e4f8974a5d8865e89f9f5d3ca16ec979cfc5b84b67bdc4100bb","size":{"x":32,"y":1,"z":32}},{"blockCount":38,"bytes":1939,"file":"chunks/y133-z160-x160.json","offset":{"x":160,"y":133,"z":160},"requirements":{"minecraft:polished_diorite":21,"minecraft:stone_bricks":17},"sha256":"a4a59e6f5cef8b39c8bc6bda696864aa2be951bf56be628e635e20d907458fc0","size":{"x":32,"y":1,"z":32}},{"blockCount":132,"bytes":4030,"file":"chunks/y133-z160-x192.json","offset":{"x":192,"y":133,"z":160},"requirements":{"minecraft:bricks":35,"minecraft:glass":6,"minecraft:polished_diorite":58,"minecraft:stone_bricks":33},"sha256":"53fe6a3bb08d6908f3349db1c9d2f1c4a2191efd00b8040d46630f372fc4786c","size":{"x":32,"y":1,"z":32}},{"blockCount":121,"bytes":3541,"file":"chunks/y133-z160-x224.json","offset":{"x":224,"y":133,"z":160},"requirements":{"minecraft:bricks":39,"minecraft:glass":14,"minecraft:polished_diorite":49,"minecraft:stone_bricks":19},"sha256":"b395c2b5f5aed5a8b229553328dc86a5d3ad0ae5b43ba38cdca483a93ca93778","size":{"x":32,"y":1,"z":32}},{"blockCount":10,"bytes":947,"file":"chunks/y133-z192-x064.json","offset":{"x":64,"y":133,"z":192},"requirements":{"minecraft:polished_diorite":8,"minecraft:stone_bricks":2},"sha256":"1492bd57a1ec2504e15dc157af554c229fd8bd557c4a77f88f86ea166d052851","size":{"x":32,"y":1,"z":32}},{"blockCount":145,"bytes":4050,"file":"chunks/y133-z192-x096.json","offset":{"x":96,"y":133,"z":192},"requirements":{"minecraft:bricks":30,"minecraft:cobbled_deepslate":17,"minecraft:oak_planks":12,"minecraft:polished_diorite":56,"minecraft:sandstone":7,"minecraft:stone_bricks":23},"sha256":"e6091412de2c585dc99b4fd9bb53d81eb2d37d124ba7f97a916d5f64fee34d85","size":{"x":32,"y":1,"z":32}},{"blockCount":99,"bytes":3713,"file":"chunks/y133-z192-x128.json","offset":{"x":128,"y":133,"z":192},"requirements":{"minecraft:bricks":21,"minecraft:cobbled_deepslate":16,"minecraft:oak_planks":1,"minecraft:polished_diorite":36,"minecraft:sandstone":3,"minecraft:stone_bricks":22},"sha256":"11f62006c7819d8f3bdcfaa100b066e20db7479338ab1779a7073a7c77508d60","size":{"x":32,"y":1,"z":32}},{"blockCount":2,"bytes":683,"file":"chunks/y134-z064-x064.json","offset":{"x":64,"y":134,"z":64},"requirements":{"minecraft:stone_bricks":2},"sha256":"ee307c106550756113cf1144dc961859409c72061ff987ebd0cc8bc78c2620fb","size":{"x":32,"y":1,"z":32}},{"blockCount":205,"bytes":4726,"file":"chunks/y134-z064-x096.json","offset":{"x":96,"y":134,"z":64},"requirements":{"minecraft:bricks":43,"minecraft:cobbled_deepslate":23,"minecraft:oak_planks":8,"minecraft:polished_diorite":104,"minecraft:sandstone":9,"minecraft:stone_bricks":18},"sha256":"6f0c8d536523adfa8e780c35f3c3b3383acee734b27b592fd80ac115d360216c","size":{"x":32,"y":1,"z":32}},{"blockCount":147,"bytes":4020,"file":"chunks/y134-z064-x128.json","offset":{"x":128,"y":134,"z":64},"requirements":{"minecraft:bricks":34,"minecraft:cobbled_deepslate":20,"minecraft:oak_planks":1,"minecraft:polished_diorite":70,"minecraft:sandstone":1,"minecraft:stone_bricks":21},"sha256":"b55aed962f10b252572e46da5c6ed629965660b468201f06e05e75ea2a2a4405","size":{"x":32,"y":1,"z":32}},{"blockCount":11,"bytes":981,"file":"chunks/y134-z064-x192.json","offset":{"x":192,"y":134,"z":64},"requirements":{"minecraft:polished_diorite":6,"minecraft:stone_bricks":5},"sha256":"2580c7556ae0ff0ba538f7f7302c67ca742e6a2cafe10e997a9c13e3120a4487","size":{"x":32,"y":1,"z":32}},{"blockCount":15,"bytes":1135,"file":"chunks/y134-z064-x224.json","offset":{"x":224,"y":134,"z":64},"requirements":{"minecraft:polished_diorite":6,"minecraft:stone_bricks":9},"sha256":"6ffc575d330fdbc260c86ba7e9168a8ea80e1e9ea0ec7114c89bab1333df9a77","size":{"x":32,"y":1,"z":32}},{"blockCount":3,"bytes":731,"file":"chunks/y134-z096-x000.json","offset":{"x":0,"y":134,"z":96},"requirements":{"minecraft:polished_diorite":1,"minecraft:stone_bricks":2},"sha256":"39aa43a43f913c2105fe1d2a43979dfe1c7c42942c29e634094ccac324702722","size":{"x":32,"y":1,"z":32}},{"blockCount":82,"bytes":2147,"file":"chunks/y134-z096-x032.json","offset":{"x":32,"y":134,"z":96},"requirements":{"minecraft:cobbled_deepslate":18,"minecraft:polished_diorite":51,"minecraft:stone_bricks":13},"sha256":"9d3a9597b80da745843e1a6f724edd6584f7d7ac284141cbdd077d5c96e892df","size":{"x":32,"y":1,"z":32}},{"blockCount":115,"bytes":2368,"file":"chunks/y134-z096-x064.json","offset":{"x":64,"y":134,"z":96},"requirements":{"minecraft:bricks":15,"minecraft:cobbled_deepslate":30,"minecraft:polished_diorite":57,"minecraft:stone_bricks":13},"sha256":"1ab1432392f6996790e155ca58df7ff8975d22c76f8dea2f83c732c3d567fd3e","size":{"x":32,"y":1,"z":32}},{"blockCount":153,"bytes":4755,"file":"chunks/y134-z096-x096.json","offset":{"x":96,"y":134,"z":96},"requirements":{"minecraft:bricks":54,"minecraft:cobbled_deepslate":36,"minecraft:glass":3,"minecraft:polished_diorite":37,"minecraft:stone_bricks":23},"sha256":"ff70da67639b83d2248b9133e3d8448a9a34e85cabeee9d18f35104e30ba86a6","size":{"x":32,"y":1,"z":32}},{"blockCount":188,"bytes":4869,"file":"chunks/y134-z096-x128.json","offset":{"x":128,"y":134,"z":96},"requirements":{"minecraft:bricks":51,"minecraft:cobbled_deepslate":48,"minecraft:glass":3,"minecraft:polished_diorite":61,"minecraft:stone_bricks":25},"sha256":"faa8d31b1d186812330c6fbe2e2ba069ba0f4d0df905e1aaac4270cec63205b0","size":{"x":32,"y":1,"z":32}},{"blockCount":117,"bytes":2558,"file":"chunks/y134-z096-x160.json","offset":{"x":160,"y":134,"z":96},"requirements":{"minecraft:bricks":15,"minecraft:cobbled_deepslate":26,"minecraft:polished_diorite":59,"minecraft:stone_bricks":17},"sha256":"5f708b5a2e997802767598d3e00f66988da4b78eed7fd52d394c217e04133263","size":{"x":32,"y":1,"z":32}},{"blockCount":219,"bytes":4911,"file":"chunks/y134-z096-x192.json","offset":{"x":192,"y":134,"z":96},"requirements":{"minecraft:bricks":53,"minecraft:cobbled_deepslate":33,"minecraft:glass":6,"minecraft:oak_planks":3,"minecraft:polished_diorite":85,"minecraft:spruce_planks":3,"minecraft:stone_bricks":36},"sha256":"b2247074dff726d45ea3d7c12d5d62a21153125938ca89ffeb92893996a8ae23","size":{"x":32,"y":1,"z":32}},{"blockCount":131,"bytes":3725,"file":"chunks/y134-z096-x224.json","offset":{"x":224,"y":134,"z":96},"requirements":{"minecraft:bricks":40,"minecraft:cobbled_deepslate":3,"minecraft:glass":14,"minecraft:polished_diorite":53,"minecraft:stone_bricks":21},"sha256":"e3e3a7a05d3dbbfa4e4f12f9d3e01fcd3a2ec20e1ffcc052ef0d1e329db60c4b","size":{"x":32,"y":1,"z":32}},{"blockCount":6,"bytes":869,"file":"chunks/y134-z128-x000.json","offset":{"x":0,"y":134,"z":128},"requirements":{"minecraft:polished_diorite":3,"minecraft:stone_bricks":3},"sha256":"87fe544e7f78a35708cbe1441f4475598a25bb6d718129cffe267d4190a1e058","size":{"x":32,"y":1,"z":32}},{"blockCount":150,"bytes":4167,"file":"chunks/y134-z128-x032.json","offset":{"x":32,"y":134,"z":128},"requirements":{"minecraft:bricks":47,"minecraft:cobbled_deepslate":40,"minecraft:polished_diorite":47,"minecraft:stone_bricks":16},"sha256":"b6093e668c03ab2fb77444921de02e6d8504deee84269f618264103c20927e54","size":{"x":32,"y":1,"z":32}},{"blockCount":150,"bytes":3384,"file":"chunks/y134-z128-x064.json","offset":{"x":64,"y":134,"z":128},"requirements":{"minecraft:bricks":79,"minecraft:cobbled_deepslate":29,"minecraft:glass":4,"minecraft:polished_diorite":21,"minecraft:stone_bricks":17},"sha256":"cd07ae2106d23fef62b209bb398ca45cba44b1bfba91ca631d8d6ff42c5612d7","size":{"x":32,"y":1,"z":32}},{"blockCount":90,"bytes":2853,"file":"chunks/y134-z128-x096.json","offset":{"x":96,"y":134,"z":128},"requirements":{"minecraft:bricks":61,"minecraft:cobbled_deepslate":14,"minecraft:glass":3,"minecraft:stone_bricks":12},"sha256":"725e01b777d671c6d57ee1f32beaeb581f7d992c64a9dc2c0afd0d2871e496c0","size":{"x":32,"y":1,"z":32}},{"blockCount":154,"bytes":3987,"file":"chunks/y134-z128-x128.json","offset":{"x":128,"y":134,"z":128},"requirements":{"minecraft:bricks":94,"minecraft:cobbled_deepslate":29,"minecraft:glass":5,"minecraft:polished_diorite":9,"minecraft:stone_bricks":17},"sha256":"bb87f44e4c12284a617be8d4e8b4d135d02dabddf4e07f05eafdc9c35852ba02","size":{"x":32,"y":1,"z":32}},{"blockCount":161,"bytes":3556,"file":"chunks/y134-z128-x160.json","offset":{"x":160,"y":134,"z":128},"requirements":{"minecraft:bricks":87,"minecraft:cobbled_deepslate":29,"minecraft:glass":4,"minecraft:polished_diorite":22,"minecraft:stone_bricks":19},"sha256":"558f9922fb1c2ed66fa6d46a2bc5325dd499a59a24f4da394e6d6d0f41cad02b","size":{"x":32,"y":1,"z":32}},{"blockCount":173,"bytes":4101,"file":"chunks/y134-z128-x192.json","offset":{"x":192,"y":134,"z":128},"requirements":{"minecraft:bricks":90,"minecraft:cobbled_deepslate":35,"minecraft:glass":2,"minecraft:oak_planks":3,"minecraft:polished_diorite":22,"minecraft:spruce_planks":3,"minecraft:stone_bricks":18},"sha256":"e2f32fc833d253e55c6d171e44c7802f7dd2a20e6e9be5f50f3d9afa93283ce8","size":{"x":32,"y":1,"z":32}},{"blockCount":107,"bytes":2995,"file":"chunks/y134-z128-x224.json","offset":{"x":224,"y":134,"z":128},"requirements":{"minecraft:bricks":12,"minecraft:cobbled_deepslate":3,"minecraft:oak_planks":9,"minecraft:polished_diorite":60,"minecraft:sandstone":10,"minecraft:stone_bricks":13},"sha256":"df616c67b7874ba2df2b1eb6d44199b9293441c4a5688e0608dad5e6d6300b60","size":{"x":32,"y":1,"z":32}},{"blockCount":1,"bytes":643,"file":"chunks/y134-z160-x000.json","offset":{"x":0,"y":134,"z":160},"requirements":{"minecraft:stone_bricks":1},"sha256":"da00845c0a78012472c1d3399f6e1c66679f6dd8e9ea200cb8c92ad2f27045ae","size":{"x":32,"y":1,"z":32}},{"blockCount":32,"bytes":1424,"file":"chunks/y134-z160-x032.json","offset":{"x":32,"y":134,"z":160},"requirements":{"minecraft:polished_diorite":24,"minecraft:stone_bricks":8},"sha256":"beefd05236d764928e3571ff9589b46c01c7a6c8a1ac65d8a52d3896ef7471a8","size":{"x":32,"y":1,"z":32}},{"blockCount":45,"bytes":1742,"file":"chunks/y134-z160-x064.json","offset":{"x":64,"y":134,"z":160},"requirements":{"minecraft:polished_diorite":36,"minecraft:stone_bricks":9},"sha256":"57ae95c3ddb30be8417b558ff41602a814662426a6811863752514e2babdf77c","size":{"x":32,"y":1,"z":32}},{"blockCount":154,"bytes":4963,"file":"chunks/y134-z160-x096.json","offset":{"x":96,"y":134,"z":160},"requirements":{"minecraft:bricks":56,"minecraft:cobbled_deepslate":29,"minecraft:glass":2,"minecraft:polished_diorite":48,"minecraft:stone_bricks":19},"sha256":"5cc9cfca42da0d0ccce9d6258807eeb9c3ac9fd6cbc8f85c2cb192ad68b75e5e","size":{"x":32,"y":1,"z":32}},{"blockCount":153,"bytes":4700,"file":"chunks/y134-z160-x128.json","offset":{"x":128,"y":134,"z":160},"requirements":{"minecraft:bricks":40,"minecraft:cobbled_deepslate":27,"minecraft:glass":2,"minecraft:polished_diorite":63,"minecraft:stone_bricks":21},"sha256":"19174a2a35e3cec0ccbdaf5c09c361b75ff629bdc2f680a3d924d7874cec5a95","size":{"x":32,"y":1,"z":32}},{"blockCount":46,"bytes":1761,"file":"chunks/y134-z160-x160.json","offset":{"x":160,"y":134,"z":160},"requirements":{"minecraft:polished_diorite":37,"minecraft:stone_bricks":9},"sha256":"56e97267438cb89c0953fd11f6a07165f8e19983015ee2294d22ea2e9efa187c","size":{"x":32,"y":1,"z":32}},{"blockCount":135,"bytes":3877,"file":"chunks/y134-z160-x192.json","offset":{"x":192,"y":134,"z":160},"requirements":{"minecraft:bricks":35,"minecraft:glass":6,"minecraft:polished_diorite":69,"minecraft:stone_bricks":25},"sha256":"6302f05f87dd33dafa89bbbfcf2b99ee8d9c09bedaf2c3dd18dbe7a591458c9b","size":{"x":32,"y":1,"z":32}},{"blockCount":121,"bytes":3541,"file":"chunks/y134-z160-x224.json","offset":{"x":224,"y":134,"z":160},"requirements":{"minecraft:bricks":39,"minecraft:glass":14,"minecraft:polished_diorite":49,"minecraft:stone_bricks":19},"sha256":"20c6796418025c5cd78c10c094eaacb661911b3afd6493eeada743362c6711f0","size":{"x":32,"y":1,"z":32}},{"blockCount":2,"bytes":684,"file":"chunks/y134-z192-x064.json","offset":{"x":64,"y":134,"z":192},"requirements":{"minecraft:stone_bricks":2},"sha256":"7b787f31a3ca55d039dec0ded46e972a6a5d2b3973298a42381708913e50e67e","size":{"x":32,"y":1,"z":32}},{"blockCount":172,"bytes":3805,"file":"chunks/y134-z192-x096.json","offset":{"x":96,"y":134,"z":192},"requirements":{"minecraft:bricks":30,"minecraft:cobbled_deepslate":15,"minecraft:oak_planks":8,"minecraft:polished_diorite":93,"minecraft:sandstone":9,"minecraft:stone_bricks":17},"sha256":"682bb96f79f16f09dd9567a6c3ac25070190e1839f8588bece46928a89c5c8b2","size":{"x":32,"y":1,"z":32}},{"blockCount":118,"bytes":3293,"file":"chunks/y134-z192-x128.json","offset":{"x":128,"y":134,"z":192},"requirements":{"minecraft:bricks":25,"minecraft:cobbled_deepslate":16,"minecraft:oak_planks":1,"minecraft:polished_diorite":59,"minecraft:sandstone":1,"minecraft:stone_bricks":16},"sha256":"814313b228404c0ea0e2cb9eb0088e3b1b3e2fd747dfd09f801cdb0a1d9bde93","size":{"x":32,"y":1,"z":32}},{"blockCount":2,"bytes":683,"file":"chunks/y135-z064-x064.json","offset":{"x":64,"y":135,"z":64},"requirements":{"minecraft:stone_bricks":2},"sha256":"15ccdf5f3fbbee6de6b21b364518b161b57f356c9043ca9f36d41f170c4d50a3","size":{"x":32,"y":1,"z":32}},{"blockCount":198,"bytes":4591,"file":"chunks/y135-z064-x096.json","offset":{"x":96,"y":135,"z":64},"requirements":{"minecraft:bricks":45,"minecraft:cobbled_deepslate":23,"minecraft:oak_planks":9,"minecraft:polished_diorite":81,"minecraft:sandstone":9,"minecraft:stone_bricks":31},"sha256":"0271d28562d2f5e0fbc9a341abd5cece1dd65f698485e752739ba8cd081b441b","size":{"x":32,"y":1,"z":32}},{"blockCount":144,"bytes":4058,"file":"chunks/y135-z064-x128.json","offset":{"x":128,"y":135,"z":64},"requirements":{"minecraft:bricks":37,"minecraft:cobbled_deepslate":25,"minecraft:oak_planks":1,"minecraft:polished_diorite":52,"minecraft:sandstone":2,"minecraft:stone_bricks":27},"sha256":"4d6b0fd9d6f239f072f32997ff261138ce510c68bdef77b5126f6ff4414c8802","size":{"x":32,"y":1,"z":32}},{"blockCount":12,"bytes":943,"file":"chunks/y135-z064-x192.json","offset":{"x":192,"y":135,"z":64},"requirements":{"minecraft:polished_diorite":6,"minecraft:stone_bricks":6},"sha256":"38a21d8e603dd7ca08d03b4ccdd9d4f9ae21a25bd3acb1f7ed527d276be0573a","size":{"x":32,"y":1,"z":32}},{"blockCount":17,"bytes":1060,"file":"chunks/y135-z064-x224.json","offset":{"x":224,"y":135,"z":64},"requirements":{"minecraft:polished_diorite":6,"minecraft:stone_bricks":11},"sha256":"adbaa228e602fe91510409640c0cb3997307629aa6af43701029801d7dcdf5fd","size":{"x":32,"y":1,"z":32}},{"blockCount":2,"bytes":681,"file":"chunks/y135-z096-x000.json","offset":{"x":0,"y":135,"z":96},"requirements":{"minecraft:stone_bricks":2},"sha256":"8e37de565d796c88a8f559d44de86b1c5bf50610bf0167a26dfceb8a8727ba62","size":{"x":32,"y":1,"z":32}},{"blockCount":79,"bytes":2146,"file":"chunks/y135-z096-x032.json","offset":{"x":32,"y":135,"z":96},"requirements":{"minecraft:cobbled_deepslate":17,"minecraft:polished_diorite":41,"minecraft:stone_bricks":21},"sha256":"ef910ec0100c63c6e7dc03ea696872370192a2383842bbe868f57d2572018f09","size":{"x":32,"y":1,"z":32}},{"blockCount":109,"bytes":2463,"file":"chunks/y135-z096-x064.json","offset":{"x":64,"y":135,"z":96},"requirements":{"minecraft:bricks":14,"minecraft:cobbled_deepslate":29,"minecraft:polished_diorite":41,"minecraft:stone_bricks":25},"sha256":"2e036a9ac0510832efbfdff518a0dedaf5ead2b481db76f8a6dd9ed9d67908b5","size":{"x":32,"y":1,"z":32}},{"blockCount":151,"bytes":4276,"file":"chunks/y135-z096-x096.json","offset":{"x":96,"y":135,"z":96},"requirements":{"minecraft:bricks":54,"minecraft:cobbled_deepslate":39,"minecraft:polished_diorite":28,"minecraft:stone_bricks":30},"sha256":"17091bdc4a237febcd8325d255723ceb9fcc2a4274f962ec24d7ad1c7b1db292","size":{"x":32,"y":1,"z":32}},{"blockCount":185,"bytes":4678,"file":"chunks/y135-z096-x128.json","offset":{"x":128,"y":135,"z":96},"requirements":{"minecraft:bricks":52,"minecraft:cobbled_deepslate":52,"minecraft:polished_diorite":46,"minecraft:stone_bricks":35},"sha256":"79a31a7cfa95e4a8b5540f5cc15a6e49c387600c56e96e4b9a0a0d1d637f6d60","size":{"x":32,"y":1,"z":32}},{"blockCount":112,"bytes":2464,"file":"chunks/y135-z096-x160.json","offset":{"x":160,"y":135,"z":96},"requirements":{"minecraft:bricks":15,"minecraft:cobbled_deepslate":29,"minecraft:polished_diorite":43,"minecraft:stone_bricks":25},"sha256":"05877c8e30ab311ee51c52df78a907c906bec21a694d04cc25b7433b672787ab","size":{"x":32,"y":1,"z":32}},{"blockCount":217,"bytes":4741,"file":"chunks/y135-z096-x192.json","offset":{"x":192,"y":135,"z":96},"requirements":{"minecraft:bricks":51,"minecraft:cobbled_deepslate":33,"minecraft:glass":6,"minecraft:oak_planks":4,"minecraft:polished_diorite":75,"minecraft:spruce_planks":3,"minecraft:stone_bricks":45},"sha256":"e22a28da8da8299e2ea6427f2c770cd44a759ea7a573d87c8f0f0a1652dd1414","size":{"x":32,"y":1,"z":32}},{"blockCount":133,"bytes":3478,"file":"chunks/y135-z096-x224.json","offset":{"x":224,"y":135,"z":96},"requirements":{"minecraft:bricks":40,"minecraft:cobbled_deepslate":4,"minecraft:glass":14,"minecraft:polished_diorite":53,"minecraft:stone_bricks":22},"sha256":"fb92f557453e160a049f5b6f66c581961e065aa67be6ab63f6084c6b9be7cd19","size":{"x":32,"y":1,"z":32}},{"blockCount":5,"bytes":800,"file":"chunks/y135-z128-x000.json","offset":{"x":0,"y":135,"z":128},"requirements":{"minecraft:stone_bricks":5},"sha256":"e3b5f2f52143bfca59e67b860e5da3f76775001bc2697463d9a85870ab98a503","size":{"x":32,"y":1,"z":32}},{"blockCount":157,"bytes":4127,"file":"chunks/y135-z128-x032.json","offset":{"x":32,"y":135,"z":128},"requirements":{"minecraft:bricks":45,"minecraft:cobbled_deepslate":51,"minecraft:polished_diorite":33,"minecraft:sandstone":1,"minecraft:stone_bricks":27},"sha256":"efee7aadf96ba41f7d97b2e8235476bdf25a89000f29fc6a3a1af28ee89435a1","size":{"x":32,"y":1,"z":32}},{"blockCount":169,"bytes":3208,"file":"chunks/y135-z128-x064.json","offset":{"x":64,"y":135,"z":128},"requirements":{"minecraft:bricks":96,"minecraft:cobbled_deepslate":31,"minecraft:polished_diorite":11,"minecraft:stone_bricks":31},"sha256":"2592606b17acfcc93635d7436ea30224c78bd0d3be03d3abb1bb480bda59f56c","size":{"x":32,"y":1,"z":32}},{"blockCount":96,"bytes":2859,"file":"chunks/y135-z128-x096.json","offset":{"x":96,"y":135,"z":128},"requirements":{"minecraft:bricks":62,"minecraft:cobbled_deepslate":12,"minecraft:sandstone":2,"minecraft:stone_bricks":20},"sha256":"cedd98e681ad01836831c46f64a0fc1351bd4109c154d3fb54a5165f800bd654","size":{"x":32,"y":1,"z":32}},{"blockCount":170,"bytes":3741,"file":"chunks/y135-z128-x128.json","offset":{"x":128,"y":135,"z":128},"requirements":{"minecraft:bricks":104,"minecraft:cobbled_deepslate":30,"minecraft:polished_diorite":5,"minecraft:sandstone":2,"minecraft:stone_bricks":29},"sha256":"1c9d2df5efa4c1806f22b8879e60e8cf858c9340d0c1c6f60a7cc5fa663ebf46","size":{"x":32,"y":1,"z":32}},{"blockCount":173,"bytes":3550,"file":"chunks/y135-z128-x160.json","offset":{"x":160,"y":135,"z":128},"requirements":{"minecraft:bricks":95,"minecraft:cobbled_deepslate":29,"minecraft:polished_diorite":12,"minecraft:stone_bricks":37},"sha256":"2a01dcf813fdc10ff05f69393700289a48f199a08225934663742c5886d9faaa","size":{"x":32,"y":1,"z":32}},{"blockCount":188,"bytes":3891,"file":"chunks/y135-z128-x192.json","offset":{"x":192,"y":135,"z":128},"requirements":{"minecraft:bricks":106,"minecraft:cobbled_deepslate":33,"minecraft:oak_planks":4,"minecraft:polished_diorite":17,"minecraft:spruce_planks":3,"minecraft:stone_bricks":25},"sha256":"4d28db037f857d5f8acf4b82d5d4cbfab0512ab6823285e13e41d6bf484eeaae","size":{"x":32,"y":1,"z":32}},{"blockCount":102,"bytes":3015,"file":"chunks/y135-z128-x224.json","offset":{"x":224,"y":135,"z":128},"requirements":{"minecraft:bricks":11,"minecraft:cobbled_deepslate":2,"minecraft:oak_planks":10,"minecraft:polished_diorite":51,"minecraft:sandstone":11,"minecraft:stone_bricks":17},"sha256":"9f6a2919178a76bfab707f8f1d274339db92e388ec3402218ba40ae4167a9977","size":{"x":32,"y":1,"z":32}},{"blockCount":1,"bytes":643,"file":"chunks/y135-z160-x000.json","offset":{"x":0,"y":135,"z":160},"requirements":{"minecraft:stone_bricks":1},"sha256":"10e6d252a5538f247b5a99a4578c2937a010756d1abeae5c3633781a5d65cd82","size":{"x":32,"y":1,"z":32}},{"blockCount":31,"bytes":1424,"file":"chunks/y135-z160-x032.json","offset":{"x":32,"y":135,"z":160},"requirements":{"minecraft:polished_diorite":22,"minecraft:stone_bricks":9},"sha256":"f6071696e449d4300aac6d68aeeb3bb14d44cf9c83228dee4077f18ec7f1a237","size":{"x":32,"y":1,"z":32}},{"blockCount":42,"bytes":1781,"file":"chunks/y135-z160-x064.json","offset":{"x":64,"y":135,"z":160},"requirements":{"minecraft:polished_diorite":30,"minecraft:stone_bricks":12},"sha256":"02e2224534f79a177dbef7cddc782c8c798a8f33208be3381b32ce9c8a38f2c3","size":{"x":32,"y":1,"z":32}},{"blockCount":155,"bytes":4465,"file":"chunks/y135-z160-x096.json","offset":{"x":96,"y":135,"z":160},"requirements":{"minecraft:bricks":60,"minecraft:cobbled_deepslate":28,"minecraft:polished_diorite":35,"minecraft:stone_bricks":32},"sha256":"5a422d8a297ee09e3aeb89e460abbddd223e60ef784de00e57738566c56d93df","size":{"x":32,"y":1,"z":32}},{"blockCount":157,"bytes":4623,"file":"chunks/y135-z160-x128.json","offset":{"x":128,"y":135,"z":160},"requirements":{"minecraft:bricks":48,"minecraft:cobbled_deepslate":29,"minecraft:polished_diorite":48,"minecraft:stone_bricks":32},"sha256":"7b56b928655e68dddac35051de1174e0e3a40125cde91f49361239ebb6d4e0c4","size":{"x":32,"y":1,"z":32}},{"blockCount":43,"bytes":1762,"file":"chunks/y135-z160-x160.json","offset":{"x":160,"y":135,"z":160},"requirements":{"minecraft:polished_diorite":31,"minecraft:stone_bricks":12},"sha256":"6783edf89afb26d0ef7c255aabf0384e40340e28942279b6c18c8d75f93bf4cd","size":{"x":32,"y":1,"z":32}},{"blockCount":139,"bytes":3611,"file":"chunks/y135-z160-x192.json","offset":{"x":192,"y":135,"z":160},"requirements":{"minecraft:bricks":37,"minecraft:glass":6,"minecraft:polished_diorite":64,"minecraft:stone_bricks":32},"sha256":"aef7373970afb04711e14350732a00a4b30384bfcc5ff684467fcab6ecde9feb","size":{"x":32,"y":1,"z":32}},{"blockCount":126,"bytes":3351,"file":"chunks/y135-z160-x224.json","offset":{"x":224,"y":135,"z":160},"requirements":{"minecraft:bricks":39,"minecraft:glass":14,"minecraft:polished_diorite":49,"minecraft:stone_bricks":24},"sha256":"51d528bb51e827f94b6f2b5c4c7faa0add047f18c034837084700ef1133c60ed","size":{"x":32,"y":1,"z":32}},{"blockCount":2,"bytes":684,"file":"chunks/y135-z192-x064.json","offset":{"x":64,"y":135,"z":192},"requirements":{"minecraft:stone_bricks":2},"sha256":"1e45aa0c8fb0a122cac0d52038eb13e543e07753121145003a811329c799df00","size":{"x":32,"y":1,"z":32}},{"blockCount":162,"bytes":3786,"file":"chunks/y135-z192-x096.json","offset":{"x":96,"y":135,"z":192},"requirements":{"minecraft:bricks":29,"minecraft:cobbled_deepslate":18,"minecraft:oak_planks":9,"minecraft:polished_diorite":74,"minecraft:sandstone":9,"minecraft:stone_bricks":23},"sha256":"7876a17389970cfc5c0f73784f7a817d1fa4f288aaeeda86be0e0ee063cf07ac","size":{"x":32,"y":1,"z":32}},{"blockCount":112,"bytes":3350,"file":"chunks/y135-z192-x128.json","offset":{"x":128,"y":135,"z":192},"requirements":{"minecraft:bricks":25,"minecraft:cobbled_deepslate":18,"minecraft:oak_planks":1,"minecraft:polished_diorite":45,"minecraft:sandstone":2,"minecraft:stone_bricks":21},"sha256":"8cef899ca14fc37216bd36712cf8c3e7df75c7c8634c5527a9fd667b85a69b50","size":{"x":32,"y":1,"z":32}},{"blockCount":2,"bytes":680,"file":"chunks/y136-z064-x064.json","offset":{"x":64,"y":136,"z":64},"requirements":{"minecraft:sandstone":2},"sha256":"2c60839312c35147f2e5e254343086e4166121af53bdacc361313c2e4793e1ba","size":{"x":32,"y":1,"z":32}},{"blockCount":182,"bytes":4630,"file":"chunks/y136-z064-x096.json","offset":{"x":96,"y":136,"z":64},"requirements":{"minecraft:bricks":42,"minecraft:cobbled_deepslate":24,"minecraft:oak_planks":8,"minecraft:polished_diorite":73,"minecraft:sandstone":8,"minecraft:stone_bricks":27},"sha256":"40db404913e875576d6911ed042b5919025b56988e81042b39417d85486d15cd","size":{"x":32,"y":1,"z":32}},{"blockCount":130,"bytes":4058,"file":"chunks/y136-z064-x128.json","offset":{"x":128,"y":136,"z":64},"requirements":{"minecraft:bricks":35,"minecraft:cobbled_deepslate":21,"minecraft:oak_planks":2,"minecraft:polished_diorite":41,"minecraft:sandstone":3,"minecraft:stone_bricks":28},"sha256":"044620e3c1d2ecd747435dc46c95dc405ce142610d631780c8ba9ee16ae82d27","size":{"x":32,"y":1,"z":32}},{"blockCount":7,"bytes":827,"file":"chunks/y136-z064-x192.json","offset":{"x":192,"y":136,"z":64},"requirements":{"minecraft:polished_diorite":6,"minecraft:stone_bricks":1},"sha256":"a06d932f0fd83a5ff0656755a1bd8b82f34329731748929d00718e7cbdd3d510","size":{"x":32,"y":1,"z":32}},{"blockCount":8,"bytes":867,"file":"chunks/y136-z064-x224.json","offset":{"x":224,"y":136,"z":64},"requirements":{"minecraft:polished_diorite":6,"minecraft:stone_bricks":2},"sha256":"d7273709bc8c0e43ef7209453bf1155e2fd2014cb17b2846708630e6949f7947","size":{"x":32,"y":1,"z":32}},{"blockCount":2,"bytes":705,"file":"chunks/y136-z096-x000.json","offset":{"x":0,"y":136,"z":96},"requirements":{"minecraft:sandstone":1,"minecraft:stone_bricks":1},"sha256":"06b3bd34646307eae20480c870c387ab1c9c55c1fadac51c4d87842fc0b0a878","size":{"x":32,"y":1,"z":32}},{"blockCount":65,"bytes":2209,"file":"chunks/y136-z096-x032.json","offset":{"x":32,"y":136,"z":96},"requirements":{"minecraft:cobbled_deepslate":13,"minecraft:polished_diorite":33,"minecraft:sandstone":3,"minecraft:stone_bricks":16},"sha256":"2f39acaae4386fffe6ec5031ab76e7037b5b253a7c660ad31788fb86e55aefe2","size":{"x":32,"y":1,"z":32}},{"blockCount":85,"bytes":2542,"file":"chunks/y136-z096-x064.json","offset":{"x":64,"y":136,"z":96},"requirements":{"minecraft:cobbled_deepslate":28,"minecraft:polished_diorite":31,"minecraft:sandstone":2,"minecraft:stone_bricks":24},"sha256":"139d523191b73233cfa4adaca083b90101de3b10857bdc45d4faf2c1740cca93","size":{"x":32,"y":1,"z":32}},{"blockCount":126,"bytes":4048,"file":"chunks/y136-z096-x096.json","offset":{"x":96,"y":136,"z":96},"requirements":{"minecraft:bricks":46,"minecraft:cobbled_deepslate":36,"minecraft:polished_diorite":22,"minecraft:stone_bricks":22},"sha256":"6520e3c3703dd50093910de24638696e158040bc86b881db9df0547af02d4d7f","size":{"x":32,"y":1,"z":32}},{"blockCount":159,"bytes":4701,"file":"chunks/y136-z096-x128.json","offset":{"x":128,"y":136,"z":96},"requirements":{"minecraft:bricks":41,"minecraft:cobbled_deepslate":51,"minecraft:polished_diorite":36,"minecraft:sandstone":1,"minecraft:stone_bricks":30},"sha256":"382cd3934cdf11fc766dd86e49b9bf3bd0e74242f5842462a16d3f1f40a23c7e","size":{"x":32,"y":1,"z":32}},{"blockCount":87,"bytes":2543,"file":"chunks/y136-z096-x160.json","offset":{"x":160,"y":136,"z":96},"requirements":{"minecraft:cobbled_deepslate":29,"minecraft:polished_diorite":33,"minecraft:sandstone":2,"minecraft:stone_bricks":23},"sha256":"447181fa2dac3bb4316d96553f94acbf28879e23ed999ceea3ce278ccb2a3506","size":{"x":32,"y":1,"z":32}},{"blockCount":179,"bytes":4490,"file":"chunks/y136-z096-x192.json","offset":{"x":192,"y":136,"z":96},"requirements":{"minecraft:bricks":37,"minecraft:cobbled_deepslate":38,"minecraft:glass":6,"minecraft:oak_planks":4,"minecraft:polished_diorite":70,"minecraft:sandstone":2,"minecraft:stone_bricks":22},"sha256":"3d9009ebd06f91ceace94c0e513dded33e1051258fae6170e61d9b2276775d2a","size":{"x":32,"y":1,"z":32}},{"blockCount":116,"bytes":3230,"file":"chunks/y136-z096-x224.json","offset":{"x":224,"y":136,"z":96},"requirements":{"minecraft:bricks":39,"minecraft:cobbled_deepslate":3,"minecraft:glass":14,"minecraft:polished_diorite":50,"minecraft:stone_bricks":10},"sha256":"493f6248d374f88cc0a69e3514fa2ffc973ff3c79dacb34a15fbfb97ce71c33a","size":{"x":32,"y":1,"z":32}},{"blockCount":5,"bytes":824,"file":"chunks/y136-z128-x000.json","offset":{"x":0,"y":136,"z":128},"requirements":{"minecraft:sandstone":2,"minecraft:stone_bricks":3},"sha256":"cf710a6910940d3b3bdad11cdb3ce45e989585ba5973f642ac6aad9f263d7f64","size":{"x":32,"y":1,"z":32}},{"blockCount":133,"bytes":4050,"file":"chunks/y136-z128-x032.json","offset":{"x":32,"y":136,"z":128},"requirements":{"minecraft:bricks":43,"minecraft:cobbled_deepslate":42,"minecraft:polished_diorite":24,"minecraft:stone_bricks":24},"sha256":"befbecfd6221baef5a603f2705edd9538b89883cf9e6820c67dbaadc39c24eab","size":{"x":32,"y":1,"z":32}},{"blockCount":147,"bytes":2784,"file":"chunks/y136-z128-x064.json","offset":{"x":64,"y":136,"z":128},"requirements":{"minecraft:bricks":95,"minecraft:cobbled_deepslate":30,"minecraft:polished_diorite":6,"minecraft:stone_bricks":16},"sha256":"c3a05899582d1c98c3074e56f7b2e2ea6be68c5e6105f52b846a8b9864d83531","size":{"x":32,"y":1,"z":32}},{"blockCount":84,"bytes":2565,"file":"chunks/y136-z128-x096.json","offset":{"x":96,"y":136,"z":128},"requirements":{"minecraft:bricks":63,"minecraft:cobbled_deepslate":16,"minecraft:stone_bricks":5},"sha256":"c72cf4817004577c60661577a0c348e2dfdd64560f26f0e2d90b7fede65c9bde","size":{"x":32,"y":1,"z":32}},{"blockCount":144,"bytes":3334,"file":"chunks/y136-z128-x128.json","offset":{"x":128,"y":136,"z":128},"requirements":{"minecraft:bricks":99,"minecraft:cobbled_deepslate":31,"minecraft:polished_diorite":3,"minecraft:stone_bricks":11},"sha256":"494e399fe3e061f9fe1d18f81613684af066dcf7dd9c08793ae3c8d69c6369b5","size":{"x":32,"y":1,"z":32}},{"blockCount":153,"bytes":2918,"file":"chunks/y136-z128-x160.json","offset":{"x":160,"y":136,"z":128},"requirements":{"minecraft:bricks":100,"minecraft:cobbled_deepslate":32,"minecraft:polished_diorite":7,"minecraft:stone_bricks":14},"sha256":"934dd98f14134c4d7d461d57a40862f3f0bb749f2a3f5316eab903a857db8425","size":{"x":32,"y":1,"z":32}},{"blockCount":177,"bytes":3924,"file":"chunks/y136-z128-x192.json","offset":{"x":192,"y":136,"z":128},"requirements":{"minecraft:bricks":98,"minecraft:cobbled_deepslate":37,"minecraft:oak_planks":4,"minecraft:polished_diorite":14,"minecraft:spruce_planks":6,"minecraft:stone_bricks":18},"sha256":"ced948d9d16a6c07340dda495b5e3b7de6e19f7f0bb17037466ee74986acb573","size":{"x":32,"y":1,"z":32}},{"blockCount":98,"bytes":2803,"file":"chunks/y136-z128-x224.json","offset":{"x":224,"y":136,"z":128},"requirements":{"minecraft:bricks":12,"minecraft:cobbled_deepslate":3,"minecraft:oak_planks":10,"minecraft:polished_diorite":55,"minecraft:sandstone":9,"minecraft:stone_bricks":9},"sha256":"2ab9dd809bcd7cc5790cc19c2aa3f4130e87f11a893b4e30148e335d80164ff2","size":{"x":32,"y":1,"z":32}},{"blockCount":1,"bytes":640,"file":"chunks/y136-z160-x000.json","offset":{"x":0,"y":136,"z":160},"requirements":{"minecraft:sandstone":1},"sha256":"51cf8805f593b4bd6cd511d75a57cb941d3736a62f2bbf0f141511b0239ce71d","size":{"x":32,"y":1,"z":32}},{"blockCount":28,"bytes":1505,"file":"chunks/y136-z160-x032.json","offset":{"x":32,"y":136,"z":160},"requirements":{"minecraft:polished_diorite":19,"minecraft:sandstone":3,"minecraft:stone_bricks":6},"sha256":"40e665f294579e0ecf85e1397c1877ffa3ffd411784e85661ff00961aad3fa4e","size":{"x":32,"y":1,"z":32}},{"blockCount":37,"bytes":1862,"file":"chunks/y136-z160-x064.json","offset":{"x":64,"y":136,"z":160},"requirements":{"minecraft:polished_diorite":25,"minecraft:sandstone":2,"minecraft:stone_bricks":10},"sha256":"3c52f71318865a64ad47a2316d2366a0b127bea2d87b2a3eb75d3f13f32c38cf","size":{"x":32,"y":1,"z":32}},{"blockCount":128,"bytes":4202,"file":"chunks/y136-z160-x096.json","offset":{"x":96,"y":136,"z":160},"requirements":{"minecraft:bricks":51,"minecraft:cobbled_deepslate":27,"minecraft:polished_diorite":27,"minecraft:stone_bricks":23},"sha256":"24b5779c540d9231f923f3dfd61603f7644b69171377ee842a8259faf7ce8b89","size":{"x":32,"y":1,"z":32}},{"blockCount":136,"bytes":4666,"file":"chunks/y136-z160-x128.json","offset":{"x":128,"y":136,"z":160},"requirements":{"minecraft:bricks":43,"minecraft:cobbled_deepslate":30,"minecraft:polished_diorite":38,"minecraft:sandstone":1,"minecraft:stone_bricks":24},"sha256":"c7d7f1b994af52e26ce81080fa47480c52821a5bc74853e7bc6f170d84209489","size":{"x":32,"y":1,"z":32}},{"blockCount":38,"bytes":1881,"file":"chunks/y136-z160-x160.json","offset":{"x":160,"y":136,"z":160},"requirements":{"minecraft:polished_diorite":26,"minecraft:sandstone":2,"minecraft:stone_bricks":10},"sha256":"6c824883c96797d64c741baacfa7df9cbea00832cb05556c4d56c98f778e78c7","size":{"x":32,"y":1,"z":32}},{"blockCount":120,"bytes":3406,"file":"chunks/y136-z160-x192.json","offset":{"x":192,"y":136,"z":160},"requirements":{"minecraft:bricks":37,"minecraft:glass":6,"minecraft:polished_diorite":64,"minecraft:sandstone":2,"minecraft:stone_bricks":11},"sha256":"63a8e77d17cc1fda2f711cf38fb3685f014fec4fbac6f45e4d4d0b78b3bb229b","size":{"x":32,"y":1,"z":32}},{"blockCount":107,"bytes":3045,"file":"chunks/y136-z160-x224.json","offset":{"x":224,"y":136,"z":160},"requirements":{"minecraft:bricks":39,"minecraft:glass":14,"minecraft:polished_diorite":49,"minecraft:stone_bricks":5},"sha256":"d07ef89efebb7e899c3223dfdc695a4b575d946fc06c8b4c4c305aca26c42988","size":{"x":32,"y":1,"z":32}},{"blockCount":2,"bytes":681,"file":"chunks/y136-z192-x064.json","offset":{"x":64,"y":136,"z":192},"requirements":{"minecraft:sandstone":2},"sha256":"83c37555b13c51842dd6e83ff450102839b504ded906b2e6d98dac053567983f","size":{"x":32,"y":1,"z":32}},{"blockCount":152,"bytes":3862,"file":"chunks/y136-z192-x096.json","offset":{"x":96,"y":136,"z":192},"requirements":{"minecraft:bricks":28,"minecraft:cobbled_deepslate":16,"minecraft:oak_planks":8,"minecraft:polished_diorite":68,"minecraft:sandstone":8,"minecraft:stone_bricks":24},"sha256":"436d730411bf0183f43d21bc377066f0e0850bfb1e785afc241dce17baaec922","size":{"x":32,"y":1,"z":32}},{"blockCount":103,"bytes":3350,"file":"chunks/y136-z192-x128.json","offset":{"x":128,"y":136,"z":192},"requirements":{"minecraft:bricks":24,"minecraft:cobbled_deepslate":13,"minecraft:oak_planks":2,"minecraft:polished_diorite":36,"minecraft:sandstone":3,"minecraft:stone_bricks":25},"sha256":"b43d12df063a4fbb322aacd8906ffad18b4d8aed9b82e5810b8f17ffe9431dc9","size":{"x":32,"y":1,"z":32}},{"blockCount":2,"bytes":683,"file":"chunks/y137-z064-x064.json","offset":{"x":64,"y":137,"z":64},"requirements":{"minecraft:stone_bricks":2},"sha256":"a697459a49a29fd04d93d3f78f1ddd5196a9b9f9e990c2218ec1b68912b1cbaa","size":{"x":32,"y":1,"z":32}},{"blockCount":165,"bytes":4022,"file":"chunks/y137-z064-x096.json","offset":{"x":96,"y":137,"z":64},"requirements":{"minecraft:bricks":47,"minecraft:cobbled_deepslate":23,"minecraft:oak_planks":11,"minecraft:polished_diorite":68,"minecraft:sandstone":6,"minecraft:stone_bricks":10},"sha256":"2e529be189dc30ce52f447ca9830f4a5af301fc0dbf3f83eaf458d12f641495d","size":{"x":32,"y":1,"z":32}},{"blockCount":114,"bytes":3429,"file":"chunks/y137-z064-x128.json","offset":{"x":128,"y":137,"z":64},"requirements":{"minecraft:bricks":38,"minecraft:cobbled_deepslate":22,"minecraft:oak_planks":1,"minecraft:polished_diorite":41,"minecraft:sandstone":3,"minecraft:stone_bricks":9},"sha256":"ca17c1dfbd3335ee08ff20c86a2bc9c37fe50776ad3a19311cf0a2dd8c88822c","size":{"x":32,"y":1,"z":32}},{"blockCount":7,"bytes":827,"file":"chunks/y137-z064-x192.json","offset":{"x":192,"y":137,"z":64},"requirements":{"minecraft:polished_diorite":6,"minecraft:stone_bricks":1},"sha256":"b20d2e1effce886005da76f415329a072483b83a76fb85942b0c2540f619640a","size":{"x":32,"y":1,"z":32}}],"schema":1}
