{"entries":[{"blockCount":8,"bytes":867,"file":"chunks/y137-z064-x224.json","offset":{"x":224,"y":137,"z":64},"requirements":{"minecraft:polished_diorite":6,"minecraft:stone_bricks":2},"sha256":"26a70ca8b7c726864fbde2be188be114e8c50d26afeea3510e56c65e1bab11aa","size":{"x":32,"y":1,"z":32}},{"blockCount":1,"bytes":642,"file":"chunks/y137-z096-x000.json","offset":{"x":0,"y":137,"z":96},"requirements":{"minecraft:stone_bricks":1},"sha256":"60caa06dc9ef593dc948fd66f7671dda33f9c642a1e3e34392624faf990ad754","size":{"x":32,"y":1,"z":32}},{"blockCount":50,"bytes":1614,"file":"chunks/y137-z096-x032.json","offset":{"x":32,"y":137,"z":96},"requirements":{"minecraft:cobbled_deepslate":13,"minecraft:polished_diorite":33,"minecraft:stone_bricks":4},"sha256":"20b53a240efd060f15726051aeeab58cd06f0bd37720bf63bd501b47c4e7347c","size":{"x":32,"y":1,"z":32}},{"blockCount":65,"bytes":1722,"file":"chunks/y137-z096-x064.json","offset":{"x":64,"y":137,"z":96},"requirements":{"minecraft:cobbled_deepslate":28,"minecraft:polished_diorite":31,"minecraft:stone_bricks":6},"sha256":"e66483ef9386b20abf842bb8bf6f90e93b1a08cd5ff574fa3e18f54eeb379097","size":{"x":32,"y":1,"z":32}},{"blockCount":119,"bytes":3864,"file":"chunks/y137-z096-x096.json","offset":{"x":96,"y":137,"z":96},"requirements":{"minecraft:bricks":51,"minecraft:cobbled_deepslate":38,"minecraft:polished_diorite":22,"minecraft:sandstone":3,"minecraft:stone_bricks":5},"sha256":"cea99b7359550e74241c2a35d1bd0ed85f481c366f0b73371eda193a3a16466c","size":{"x":32,"y":1,"z":32}},{"blockCount":140,"bytes":4053,"file":"chunks/y137-z096-x128.json","offset":{"x":128,"y":137,"z":96},"requirements":{"minecraft:bricks":42,"minecraft:cobbled_deepslate":51,"minecraft:polished_diorite":36,"minecraft:sandstone":3,"minecraft:stone_bricks":8},"sha256":"7e4e41594dbb28f10aba9a8c5a82ba4aedc7836bb36048d7e930264244be5f8a","size":{"x":32,"y":1,"z":32}},{"blockCount":67,"bytes":1725,"file":"chunks/y137-z096-x160.json","offset":{"x":160,"y":137,"z":96},"requirements":{"minecraft:cobbled_deepslate":29,"minecraft:polished_diorite":33,"minecraft:stone_bricks":5},"sha256":"df1121fc8d05d49491aeffa2af68a4afb9aedb5dd3da3dab4e7851c829efc45e","size":{"x":32,"y":1,"z":32}},{"blockCount":167,"bytes":4003,"file":"chunks/y137-z096-x192.json","offset":{"x":192,"y":137,"z":96},"requirements":{"minecraft:bricks":37,"minecraft:cobbled_deepslate":36,"minecraft:glass":6,"minecraft:oak_planks":2,"minecraft:polished_diorite":69,"minecraft:spruce_planks":2,"minecraft:stone_bricks":15},"sha256":"d27baadd3e92d4446c87230276db45a18078676c3f4eeb6a61a9fa2465f3f8ce","size":{"x":32,"y":1,"z":32}},{"blockCount":115,"bytes":3248,"file":"chunks/y137-z096-x224.json","offset":{"x":224,"y":137,"z":96},"requirements":{"minecraft:bricks":39,"minecraft:cobbled_deepslate":3,"minecraft:glass":14,"minecraft:polished_diorite":50,"minecraft:stone_bricks":9},"sha256":"c807fd968410b9546dd382b8d2d52c6b7f2971583ecc57b8960c598f472f79ea","size":{"x":32,"y":1,"z":32}},{"blockCount":2,"bytes":682,"file":"chunks/y137-z128-x000.json","offset":{"x":0,"y":137,"z":128},"requirements":{"minecraft:stone_bricks":2},"sha256":"f88eb494290a0e863c58420345709533a748e7b1e018d2cbba350c7ca585f22c","size":{"x":32,"y":1,"z":32}},{"blockCount":133,"bytes":3635,"file":"chunks/y137-z128-x032.json","offset":{"x":32,"y":137,"z":128},"requirements":{"minecraft:bricks":45,"minecraft:cobbled_deepslate":50,"minecraft:polished_diorite":24,"minecraft:sandstone":3,"minecraft:stone_bricks":11},"sha256":"4df78195be97ad774823fa0360759d902c0465662e697b7fc33c083f3b3ba8a5","size":{"x":32,"y":1,"z":32}},{"blockCount":148,"bytes":2314,"file":"chunks/y137-z128-x064.json","offset":{"x":64,"y":137,"z":128},"requirements":{"minecraft:bricks":106,"minecraft:cobbled_deepslate":30,"minecraft:polished_diorite":6,"minecraft:sandstone":4,"minecraft:stone_bricks":2},"sha256":"db82b657864be94b7ad0da3655c191811f5defba5b01cf52f32ee50190c706a0","size":{"x":32,"y":1,"z":32}},{"blockCount":85,"bytes":2670,"file":"chunks/y137-z128-x096.json","offset":{"x":96,"y":137,"z":128},"requirements":{"minecraft:bricks":62,"minecraft:cobbled_deepslate":17,"minecraft:sandstone":5,"minecraft:stone_bricks":1},"sha256":"b820d8b3a5ad043c76e280db59ffe11876ed9b444427dedf19e5c856a01820a5","size":{"x":32,"y":1,"z":32}},{"blockCount":143,"bytes":2950,"file":"chunks/y137-z128-x128.json","offset":{"x":128,"y":137,"z":128},"requirements":{"minecraft:bricks":100,"minecraft:cobbled_deepslate":33,"minecraft:polished_diorite":3,"minecraft:sandstone":7},"sha256":"bbc6612aeb64035600be1b327421ba57ccebe1abed1670d46da4145a03f0037c","size":{"x":32,"y":1,"z":32}},{"blockCount":155,"bytes":2525,"file":"chunks/y137-z128-x160.json","offset":{"x":160,"y":137,"z":128},"requirements":{"minecraft:bricks":112,"minecraft:cobbled_deepslate":29,"minecraft:polished_diorite":7,"minecraft:sandstone":4,"minecraft:stone_bricks":3},"sha256":"3223ab4ca78282af87f030e3d744a9adae70c9826028322368d3919d2ec1324e","size":{"x":32,"y":1,"z":32}},{"blockCount":191,"bytes":3722,"file":"chunks/y137-z128-x192.json","offset":{"x":192,"y":137,"z":128},"requirements":{"minecraft:bricks":108,"minecraft:cobbled_deepslate":36,"minecraft:oak_planks":2,"minecraft:polished_diorite":14,"minecraft:sandstone":6,"minecraft:spruce_planks":8,"minecraft:stone_bricks":17},"sha256":"d06f536ba8598f2d4f21353a78484a7f8f7449a11bc4d3c8fc65bb3ee1ec69ee","size":{"x":32,"y":1,"z":32}},{"blockCount":94,"bytes":2880,"file":"chunks/y137-z128-x224.json","offset":{"x":224,"y":137,"z":128},"requirements":{"minecraft:bricks":12,"minecraft:cobbled_deepslate":3,"minecraft:oak_planks":12,"minecraft:polished_diorite":50,"minecraft:sandstone":7,"minecraft:stone_bricks":10},"sha256":"11a6529799835594e870cb69ae06909cb87a29c51f656733a8f5915569f91e91","size":{"x":32,"y":1,"z":32}},{"blockCount":1,"bytes":643,"file":"chunks/y137-z160-x000.json","offset":{"x":0,"y":137,"z":160},"requirements":{"minecraft:stone_bricks":1},"sha256":"e096120ba440b5928a64c0567a3ad933f5211c160a728e5751f05eaa02f86bf3","size":{"x":32,"y":1,"z":32}},{"blockCount":22,"bytes":1253,"file":"chunks/y137-z160-x032.json","offset":{"x":32,"y":137,"z":160},"requirements":{"minecraft:polished_diorite":19,"minecraft:stone_bricks":3},"sha256":"5220e8a7c7645e30793698949857d7e31f217e4abaa90e0c11aca703bd6569bc","size":{"x":32,"y":1,"z":32}},{"blockCount":27,"bytes":1459,"file":"chunks/y137-z160-x064.json","offset":{"x":64,"y":137,"z":160},"requirements":{"minecraft:polished_diorite":25,"minecraft:stone_bricks":2},"sha256":"e56126ef3d1e55e53b75e522af11171ffc67503ca165950ee055e2fd5726dc06","size":{"x":32,"y":1,"z":32}},{"blockCount":114,"bytes":3845,"file":"chunks/y137-z160-x096.json","offset":{"x":96,"y":137,"z":160},"requirements":{"minecraft:bricks":53,"minecraft:cobbled_deepslate":29,"minecraft:polished_diorite":27,"minecraft:sandstone":2,"minecraft:stone_bricks":3},"sha256":"f0726aeae296693d57304b5839309198dbf486c625ba3bf6bf3b18f8ce20e69a","size":{"x":32,"y":1,"z":32}},{"blockCount":119,"bytes":3999,"file":"chunks/y137-z160-x128.json","offset":{"x":128,"y":137,"z":160},"requirements":{"minecraft:bricks":46,"minecraft:cobbled_deepslate":31,"minecraft:polished_diorite":38,"minecraft:sandstone":2,"minecraft:stone_bricks":2},"sha256":"6452b31700f5fa37824a7d0d5d1390fa644de5f042b68f35ca0ddfb137a5d1ba","size":{"x":32,"y":1,"z":32}},{"blockCount":28,"bytes":1478,"file":"chunks/y137-z160-x160.json","offset":{"x":160,"y":137,"z":160},"requirements":{"minecraft:polished_diorite":26,"minecraft:stone_bricks":2},"sha256":"13bc24adb4da8ffcf81815da16ba105f668e9424b39c14d28e8560f730fb9ba0","size":{"x":32,"y":1,"z":32}},{"blockCount":114,"bytes":3193,"file":"chunks/y137-z160-x192.json","offset":{"x":192,"y":137,"z":160},"requirements":{"minecraft:bricks":37,"minecraft:glass":6,"minecraft:polished_diorite":63,"minecraft:stone_bricks":8},"sha256":"a36887efe9e698907b09d8c264ab5a28b95b3aa8e148e6cc2fc4f30d466f2606","size":{"x":32,"y":1,"z":32}},{"blockCount":107,"bytes":3045,"file":"chunks/y137-z160-x224.json","offset":{"x":224,"y":137,"z":160},"requirements":{"minecraft:bricks":39,"minecraft:glass":14,"minecraft:polished_diorite":49,"minecraft:stone_bricks":5},"sha256":"ce1469ed9c739d25768901f62a9fafdb0677a394e71bc8377cc9bcea9e8af47c","size":{"x":32,"y":1,"z":32}},{"blockCount":2,"bytes":684,"file":"chunks/y137-z192-x064.json","offset":{"x":64,"y":137,"z":192},"requirements":{"minecraft:stone_bricks":2},"sha256":"665db878724e1e1a640f5870022188088a7ead79691b9dc4aa517d4b0ea40750","size":{"x":32,"y":1,"z":32}},{"blockCount":140,"bytes":3406,"file":"chunks/y137-z192-x096.json","offset":{"x":96,"y":137,"z":192},"requirements":{"minecraft:bricks":34,"minecraft:cobbled_deepslate":15,"minecraft:oak_planks":11,"minecraft:polished_diorite":63,"minecraft:sandstone":6,"minecraft:stone_bricks":11},"sha256":"9f860d08bdd03e052713fe1d370a86b2a013535be4e20b0ceca3c2a8fd943b2d","size":{"x":32,"y":1,"z":32}},{"blockCount":90,"bytes":2854,"file":"chunks/y137-z192-x128.json","offset":{"x":128,"y":137,"z":192},"requirements":{"minecraft:bricks":26,"minecraft:cobbled_deepslate":15,"minecraft:oak_planks":1,"minecraft:polished_diorite":36,"minecraft:sandstone":3,"minecraft:stone_bricks":9},"sha256":"d203ff9d6c848d775b55ad007ebb774269c4562cf580ad21aa3ade6fa2e9b5fa","size":{"x":32,"y":1,"z":32}},{"blockCount":2,"bytes":683,"file":"chunks/y138-z064-x064.json","offset":{"x":64,"y":138,"z":64},"requirements":{"minecraft:stone_bricks":2},"sha256":"a49f0d9b6e028f0b01a76abffd9e31ae772ab51ae72c052b34e364be01ea1d8a","size":{"x":32,"y":1,"z":32}},{"blockCount":173,"bytes":4116,"file":"chunks/y138-z064-x096.json","offset":{"x":96,"y":138,"z":64},"requirements":{"minecraft:bricks":47,"minecraft:cobbled_deepslate":23,"minecraft:oak_planks":9,"minecraft:polished_diorite":67,"minecraft:sandstone":6,"minecraft:stone_bricks":21},"sha256":"095a225fd63bb33ee50b1c41f18f65612ed46e0fb9d742b7b1b4992a7f427068","size":{"x":32,"y":1,"z":32}},{"blockCount":119,"bytes":3468,"file":"chunks/y138-z064-x128.json","offset":{"x":128,"y":138,"z":64},"requirements":{"minecraft:bricks":35,"minecraft:cobbled_deepslate":23,"minecraft:oak_planks":2,"minecraft:polished_diorite":39,"minecraft:sandstone":1,"minecraft:stone_bricks":19},"sha256":"34305c77ef0ee10a89c44e8aa7cf0972c181d566bb6abf2d034dd6b5ef734315","size":{"x":32,"y":1,"z":32}},{"blockCount":8,"bytes":827,"file":"chunks/y138-z064-x192.json","offset":{"x":192,"y":138,"z":64},"requirements":{"minecraft:polished_diorite":7,"minecraft:stone_bricks":1},"sha256":"bee4a29a443dfef4c6c9ce9b611379a0a43e11361ed917e77e95f8fc3d6c969c","size":{"x":32,"y":1,"z":32}},{"blockCount":9,"bytes":867,"file":"chunks/y138-z064-x224.json","offset":{"x":224,"y":138,"z":64},"requirements":{"minecraft:polished_diorite":7,"minecraft:stone_bricks":2},"sha256":"a00f3e7df44e7b1c2eadd2b5be13094400ba0f93f75bcfc5e2f15cfd21d11305","size":{"x":32,"y":1,"z":32}},{"blockCount":1,"bytes":642,"file":"chunks/y138-z096-x000.json","offset":{"x":0,"y":138,"z":96},"requirements":{"minecraft:stone_bricks":1},"sha256":"79ed01e6d8dc8ade2d4862807ea25b6e290aa94c6966f9a7e52f3d7de2e3fe40","size":{"x":32,"y":1,"z":32}},{"blockCount":44,"bytes":1674,"file":"chunks/y138-z096-x032.json","offset":{"x":32,"y":138,"z":96},"requirements":{"minecraft:polished_diorite":33,"minecraft:stone_bricks":11},"sha256":"6fe74bac4a906da5c3f3d84a29285a9630c9bd092d46539a0bbd60ac510513fc","size":{"x":32,"y":1,"z":32}},{"blockCount":43,"bytes":1781,"file":"chunks/y138-z096-x064.json","offset":{"x":64,"y":138,"z":96},"requirements":{"minecraft:polished_diorite":31,"minecraft:stone_bricks":12},"sha256":"24e04c2edbbe827cb3e81877d1928353e42148dbfd31a28a23c7692ff5e5e65b","size":{"x":32,"y":1,"z":32}},{"blockCount":114,"bytes":3769,"file":"chunks/y138-z096-x096.json","offset":{"x":96,"y":138,"z":96},"requirements":{"minecraft:bricks":52,"minecraft:cobbled_deepslate":28,"minecraft:polished_diorite":22,"minecraft:sandstone":2,"minecraft:stone_bricks":10},"sha256":"9de02044d090268caf8013a048949a67b4926a7bc5ef364c8b46e206db7271f1","size":{"x":32,"y":1,"z":32}},{"blockCount":120,"bytes":3934,"file":"chunks/y138-z096-x128.json","offset":{"x":128,"y":138,"z":96},"requirements":{"minecraft:bricks":41,"minecraft:cobbled_deepslate":30,"minecraft:polished_diorite":36,"minecraft:stone_bricks":13},"sha256":"b31fa7acef6a4cc785e88a02122ea16b457a7d2c7755b059a60de82ff9c048b7","size":{"x":32,"y":1,"z":32}},{"blockCount":45,"bytes":1782,"file":"chunks/y138-z096-x160.json","offset":{"x":160,"y":138,"z":96},"requirements":{"minecraft:polished_diorite":33,"minecraft:stone_bricks":12},"sha256":"459fb78644f0eeef85b3dede3eac664e0b4983c43869e3eabfcfd4c52fc858b2","size":{"x":32,"y":1,"z":32}},{"blockCount":149,"bytes":3916,"file":"chunks/y138-z096-x192.json","offset":{"x":192,"y":138,"z":96},"requirements":{"minecraft:bricks":37,"minecraft:cobbled_deepslate":13,"minecraft:glass":6,"minecraft:oak_planks":5,"minecraft:polished_diorite":73,"minecraft:stone_bricks":15},"sha256":"685056b0963220afe9e132edba71d7db641261446f169df8dbe40a419bd3519d","size":{"x":32,"y":1,"z":32}},{"blockCount":114,"bytes":3120,"file":"chunks/y138-z096-x224.json","offset":{"x":224,"y":138,"z":96},"requirements":{"minecraft:bricks":39,"minecraft:glass":14,"minecraft:polished_diorite":52,"minecraft:stone_bricks":9},"sha256":"e37cdb35efce79622664e187e0ceed3056fdd416898487b1a38c8e456578bba5","size":{"x":32,"y":1,"z":32}},{"blockCount":2,"bytes":682,"file":"chunks/y138-z128-x000.json","offset":{"x":0,"y":138,"z":128},"requirements":{"minecraft:stone_bricks":2},"sha256":"f7a9dbfb690e8fe623ab992cf46a7f3154641892fc4f80742dbbf2747bfc76fa","size":{"x":32,"y":1,"z":32}},{"blockCount":141,"bytes":3731,"file":"chunks/y138-z128-x032.json","offset":{"x":32,"y":138,"z":128},"requirements":{"minecraft:bricks":46,"minecraft:cobbled_deepslate":48,"minecraft:polished_diorite":24,"minecraft:sandstone":1,"minecraft:stone_bricks":22},"sha256":"bc5943240dd18f44cc7af014430c443bf798f5d9bb0cc4d338f00c8db91cbe0b","size":{"x":32,"y":1,"z":32}},{"blockCount":175,"bytes":2849,"file":"chunks/y138-z128-x064.json","offset":{"x":64,"y":138,"z":128},"requirements":{"minecraft:bricks":98,"minecraft:cobbled_deepslate":55,"minecraft:polished_diorite":6,"minecraft:sandstone":2,"minecraft:stone_bricks":14},"sha256":"146c8ebcf5b691c51e33053af836274c9528d15995021964263b7a5cef490a0c","size":{"x":32,"y":1,"z":32}},{"blockCount":109,"bytes":3015,"file":"chunks/y138-z128-x096.json","offset":{"x":96,"y":138,"z":128},"requirements":{"minecraft:bricks":75,"minecraft:cobbled_deepslate":30,"minecraft:sandstone":1,"minecraft:stone_bricks":3},"sha256":"c2e7df75f295c7259e7b6d7a672548cf4bbf414b69582bd4be670b8358012647","size":{"x":32,"y":1,"z":32}},{"blockCount":171,"bytes":3493,"file":"chunks/y138-z128-x128.json","offset":{"x":128,"y":138,"z":128},"requirements":{"minecraft:bricks":101,"minecraft:cobbled_deepslate":55,"minecraft:polished_diorite":3,"minecraft:sandstone":2,"minecraft:stone_bricks":10},"sha256":"299dc506eb8d5acdd7072275b46f676d636e9f2f4b981e65b7a5716bc46b48f9","size":{"x":32,"y":1,"z":32}},{"blockCount":186,"bytes":2719,"file":"chunks/y138-z128-x160.json","offset":{"x":160,"y":138,"z":128},"requirements":{"minecraft:bricks":108,"minecraft:cobbled_deepslate":61,"minecraft:polished_diorite":7,"minecraft:sandstone":2,"minecraft:stone_bricks":8},"sha256":"61ee244a091d27106e91d743403c447f5c39046149e09e1ea10d9078acf03113","size":{"x":32,"y":1,"z":32}},{"blockCount":208,"bytes":3878,"file":"chunks/y138-z128-x192.json","offset":{"x":192,"y":138,"z":128},"requirements":{"minecraft:bricks":102,"minecraft:cobbled_deepslate":64,"minecraft:oak_planks":5,"minecraft:polished_diorite":15,"minecraft:sandstone":2,"minecraft:spruce_planks":6,"minecraft:stone_bricks":14},"sha256":"974f9f373012eb7af7dcf365b02161871c3dd530bfd8240bc60ebff29b9f8214","size":{"x":32,"y":1,"z":32}},{"blockCount":98,"bytes":2746,"file":"chunks/y138-z128-x224.json","offset":{"x":224,"y":138,"z":128},"requirements":{"minecraft:bricks":14,"minecraft:cobbled_deepslate":8,"minecraft:oak_planks":11,"minecraft:polished_diorite":49,"minecraft:sandstone":6,"minecraft:stone_bricks":10},"sha256":"84a5dc0ecb3f951184a30426e7c670785e9b9ff28542f7807ccb7b25bc517cdf","size":{"x":32,"y":1,"z":32}},{"blockCount":1,"bytes":643,"file":"chunks/y138-z160-x000.json","offset":{"x":0,"y":138,"z":160},"requirements":{"minecraft:stone_bricks":1},"sha256":"41efc0cb4762f79236bae82a0f7e4461f10e945fb9eaf974dbb487841d1719ed","size":{"x":32,"y":1,"z":32}},{"blockCount":25,"bytes":1309,"file":"chunks/y138-z160-x032.json","offset":{"x":32,"y":138,"z":160},"requirements":{"minecraft:polished_diorite":19,"minecraft:stone_bricks":6},"sha256":"ab41bb1d6b2f9b46d0e5f3cd0df77fda7e767b21164509f5041673d771fb55c0","size":{"x":32,"y":1,"z":32}},{"blockCount":32,"bytes":1571,"file":"chunks/y138-z160-x064.json","offset":{"x":64,"y":138,"z":160},"requirements":{"minecraft:polished_diorite":25,"minecraft:stone_bricks":7},"sha256":"758bf00ef84c2463cd7717a4e3918c098fd68e65d529754b3d9fadc6af32041c","size":{"x":32,"y":1,"z":32}},{"blockCount":121,"bytes":3807,"file":"chunks/y138-z160-x096.json","offset":{"x":96,"y":138,"z":160},"requirements":{"minecraft:bricks":51,"minecraft:cobbled_deepslate":31,"minecraft:polished_diorite":27,"minecraft:sandstone":3,"minecraft:stone_bricks":9},"sha256":"e2d31dec0d9579cfc3e0242e6e96175a68ae46239cec583b1c64f199a3c32ee5","size":{"x":32,"y":1,"z":32}},{"blockCount":124,"bytes":3936,"file":"chunks/y138-z160-x128.json","offset":{"x":128,"y":138,"z":160},"requirements":{"minecraft:bricks":43,"minecraft:cobbled_deepslate":30,"minecraft:polished_diorite":38,"minecraft:stone_bricks":13},"sha256":"64156ac09b8929259a064be0752884433482534b29c37b8a7c54179a6459da09","size":{"x":32,"y":1,"z":32}},{"blockCount":33,"bytes":1571,"file":"chunks/y138-z160-x160.json","offset":{"x":160,"y":138,"z":160},"requirements":{"minecraft:polished_diorite":26,"minecraft:stone_bricks":7},"sha256":"b9a4fa17a9878ac20b939529af4e1a87411d12faec2325824c641dbf60d435a3","size":{"x":32,"y":1,"z":32}},{"blockCount":119,"bytes":3173,"file":"chunks/y138-z160-x192.json","offset":{"x":192,"y":138,"z":160},"requirements":{"minecraft:bricks":37,"minecraft:glass":6,"minecraft:polished_diorite":67,"minecraft:stone_bricks":9},"sha256":"7beb7f1fbbce218903e5a5e0e1c5f198acba40332418c65fd263f790c75ff95a","size":{"x":32,"y":1,"z":32}},{"blockCount":110,"bytes":3045,"file":"chunks/y138-z160-x224.json","offset":{"x":224,"y":138,"z":160},"requirements":{"minecraft:bricks":39,"minecraft:glass":14,"minecraft:polished_diorite":52,"minecraft:stone_bricks":5},"sha256":"db11bb9c7c8a95dca34ca15692ec0941adb975e63c2478ae1acb6c49b4cc7682","size":{"x":32,"y":1,"z":32}},{"blockCount":2,"bytes":684,"file":"chunks/y138-z192-x064.json","offset":{"x":64,"y":138,"z":192},"requirements":{"minecraft:stone_bricks":2},"sha256":"9e2a20d4a7306f6cd6ca3d0c998d0cc15faef64058d9a43fed652dbef1159a2c","size":{"x":32,"y":1,"z":32}},{"blockCount":147,"bytes":3500,"file":"chunks/y138-z192-x096.json","offset":{"x":96,"y":138,"z":192},"requirements":{"minecraft:bricks":36,"minecraft:cobbled_deepslate":16,"minecraft:oak_planks":9,"minecraft:polished_diorite":62,"minecraft:sandstone":5,"minecraft:stone_bricks":19},"sha256":"92939f61a4c8b1a51787c93c8d3dd469c2b5b82be190382abd53a21e14a73483","size":{"x":32,"y":1,"z":32}},{"blockCount":94,"bytes":2893,"file":"chunks/y138-z192-x128.json","offset":{"x":128,"y":138,"z":192},"requirements":{"minecraft:bricks":24,"minecraft:cobbled_deepslate":16,"minecraft:oak_planks":2,"minecraft:polished_diorite":34,"minecraft:sandstone":1,"minecraft:stone_bricks":17},"sha256":"2dccf2c5956fad0de99b360e97ed747243d319ef7e28d6dc62b770335c2f829d","size":{"x":32,"y":1,"z":32}},{"blockCount":11,"bytes":978,"file":"chunks/y139-z064-x064.json","offset":{"x":64,"y":139,"z":64},"requirements":{"minecraft:sandstone":2,"minecraft:stone_bricks":9},"sha256":"76ecf50907df9de4dd50e547d67034cf7e0abe3e6b25195e8506381bf5ffd25a","size":{"x":32,"y":1,"z":32}},{"blockCount":161,"bytes":4151,"file":"chunks/y139-z064-x096.json","offset":{"x":96,"y":139,"z":64},"requirements":{"minecraft:bricks":44,"minecraft:cobbled_deepslate":25,"minecraft:oak_planks":8,"minecraft:polished_diorite":73,"minecraft:sandstone":5,"minecraft:stone_bricks":6},"sha256":"ef397443658576f1f8caa2b6c31c78d9c82ce445953e34402119c82ff434c207","size":{"x":32,"y":1,"z":32}},{"blockCount":115,"bytes":3786,"file":"chunks/y139-z064-x128.json","offset":{"x":128,"y":139,"z":64},"requirements":{"minecraft:bricks":26,"minecraft:cobbled_deepslate":24,"minecraft:polished_diorite":49,"minecraft:sandstone":4,"minecraft:stone_bricks":12},"sha256":"0c9495a646a7e39532d8c3bd9445a4fbe5a17951be9f65af2d4e86f7d72c68e9","size":{"x":32,"y":1,"z":32}},{"blockCount":10,"bytes":846,"file":"chunks/y139-z064-x192.json","offset":{"x":192,"y":139,"z":64},"requirements":{"minecraft:polished_diorite":3,"minecraft:stone_bricks":7},"sha256":"e616f69d1569240f50cc0e1579f4bb11a201b7b8eb5a12c45f85d0de02f6bd4a","size":{"x":32,"y":1,"z":32}},{"blockCount":11,"bytes":886,"file":"chunks/y139-z064-x224.json","offset":{"x":224,"y":139,"z":64},"requirements":{"minecraft:polished_diorite":3,"minecraft:stone_bricks":8},"sha256":"e6a78d33e3f83f4a423e0a2d9f6b6e4dc4f4c0f0faf89756ea3a8fbd4ffbf5f7","size":{"x":32,"y":1,"z":32}},{"blockCount":6,"bytes":821,"file":"chunks/y139-z096-x000.json","offset":{"x":0,"y":139,"z":96},"requirements":{"minecraft:sandstone":1,"minecraft:stone_bricks":5},"sha256":"b4659ecfb734a3b06df32f01be1540adeebecfb69f0d958c018e3d848e9b31d4","size":{"x":32,"y":1,"z":32}},{"blockCount":48,"bytes":1894,"file":"chunks/y139-z096-x032.json","offset":{"x":32,"y":139,"z":96},"requirements":{"minecraft:polished_diorite":33,"minecraft:sandstone":3,"minecraft:stone_bricks":12},"sha256":"f1e7926ba5d8773405caec2926bbb8ed897b0ab575430a9b12f51281c25ebd25","size":{"x":32,"y":1,"z":32}},{"blockCount":40,"bytes":1772,"file":"chunks/y139-z096-x064.json","offset":{"x":64,"y":139,"z":96},"requirements":{"minecraft:polished_diorite":31,"minecraft:sandstone":2,"minecraft:stone_bricks":7},"sha256":"ae4726e84618a439a07c2e4f777cbc75b84a8b3cd3a46571ddc0146533e3e3a0","size":{"x":32,"y":1,"z":32}},{"blockCount":118,"bytes":4126,"file":"chunks/y139-z096-x096.json","offset":{"x":96,"y":139,"z":96},"requirements":{"minecraft:bricks":52,"minecraft:cobbled_deepslate":28,"minecraft:polished_diorite":28,"minecraft:sandstone":6,"minecraft:stone_bricks":4},"sha256":"170927c40c7fd0e71b70be4fdc699056579fe64f979e29168cac597d817c1a2e","size":{"x":32,"y":1,"z":32}},{"blockCount":115,"bytes":4091,"file":"chunks/y139-z096-x128.json","offset":{"x":128,"y":139,"z":96},"requirements":{"minecraft:bricks":37,"minecraft:cobbled_deepslate":28,"minecraft:polished_diorite":42,"minecraft:sandstone":1,"minecraft:stone_bricks":7},"sha256":"76b86914c7ad993203a5854d73bb82b0d3e9a6bb683bdd6d2a7f6caffdf2b20c","size":{"x":32,"y":1,"z":32}},{"blockCount":44,"bytes":1889,"file":"chunks/y139-z096-x160.json","offset":{"x":160,"y":139,"z":96},"requirements":{"minecraft:polished_diorite":33,"minecraft:sandstone":2,"minecraft:stone_bricks":9},"sha256":"f3f166261e34812af457dfb45d1d7d5ca876af53ce4a0811d9414883b4c7d45c","size":{"x":32,"y":1,"z":32}},{"blockCount":152,"bytes":4094,"file":"chunks/y139-z096-x192.json","offset":{"x":192,"y":139,"z":96},"requirements":{"minecraft:bricks":37,"minecraft:cobbled_deepslate":16,"minecraft:glass":6,"minecraft:oak_planks":2,"minecraft:polished_diorite":64,"minecraft:sandstone":2,"minecraft:stone_bricks":25},"sha256":"93ffaba25b2100d94a7b1dc63d7d1e37f8a78ce255f7974889a1618fed8b1db6","size":{"x":32,"y":1,"z":32}},{"blockCount":117,"bytes":3139,"file":"chunks/y139-z096-x224.json","offset":{"x":224,"y":139,"z":96},"requirements":{"minecraft:bricks":39,"minecraft:glass":14,"minecraft:polished_diorite":44,"minecraft:stone_bricks":20},"sha256":"5c47a47085ca6bf3f9c44cde6e6cef50dad189fe6b101204628cb3239dd30820","size":{"x":32,"y":1,"z":32}},{"blockCount":9,"bytes":899,"file":"chunks/y139-z128-x000.json","offset":{"x":0,"y":139,"z":128},"requirements":{"minecraft:sandstone":2,"minecraft:stone_bricks":7},"sha256":"b11bcc6aed892934ffca64ddafa30383b9868b7e7679b9eb44e9387540aa0a62","size":{"x":32,"y":1,"z":32}},{"blockCount":141,"bytes":3691,"file":"chunks/y139-z128-x032.json","offset":{"x":32,"y":139,"z":128},"requirements":{"minecraft:bricks":48,"minecraft:cobbled_deepslate":53,"minecraft:polished_diorite":24,"minecraft:sandstone":3,"minecraft:stone_bricks":13},"sha256":"7b6c5c998f1ab8028039a39a33c3057fb214c41724e63b71ea35bf4a602532be","size":{"x":32,"y":1,"z":32}},{"blockCount":180,"bytes":2810,"file":"chunks/y139-z128-x064.json","offset":{"x":64,"y":139,"z":128},"requirements":{"minecraft:bricks":106,"minecraft:cobbled_deepslate":56,"minecraft:polished_diorite":6,"minecraft:sandstone":4,"minecraft:stone_bricks":8},"sha256":"004080656e4d6706c59bbb2f0ebf9d3a39fc925de97019cc921bc9993df9ed96","size":{"x":32,"y":1,"z":32}},{"blockCount":132,"bytes":3428,"file":"chunks/y139-z128-x096.json","offset":{"x":96,"y":139,"z":128},"requirements":{"minecraft:bricks":91,"minecraft:cobbled_deepslate":29,"minecraft:sandstone":8,"minecraft:stone_bricks":4},"sha256":"1e5a1d0e2eecb052f2e423ce53d4c98098b5cbf2c5c44df7ed6bd38dd3fb1457","size":{"x":32,"y":1,"z":32}},{"blockCount":186,"bytes":3470,"file":"chunks/y139-z128-x128.json","offset":{"x":128,"y":139,"z":128},"requirements":{"minecraft:bricks":116,"minecraft:cobbled_deepslate":56,"minecraft:polished_diorite":3,"minecraft:sandstone":4,"minecraft:stone_bricks":7},"sha256":"c6e4c2b73a2795e404a7e2be2ac1a8512d2b904b43c8587acb2bcd58b44ed04e","size":{"x":32,"y":1,"z":32}},{"blockCount":189,"bytes":2851,"file":"chunks/y139-z128-x160.json","offset":{"x":160,"y":139,"z":128},"requirements":{"minecraft:bricks":114,"minecraft:cobbled_deepslate":59,"minecraft:polished_diorite":7,"minecraft:sandstone":4,"minecraft:stone_bricks":5},"sha256":"ac897773c1d969fbf67eaf3ed20536c0903c821a1fb01ee071a2279e34c6e90e","size":{"x":32,"y":1,"z":32}},{"blockCount":213,"bytes":3991,"file":"chunks/y139-z128-x192.json","offset":{"x":192,"y":139,"z":128},"requirements":{"minecraft:bricks":106,"minecraft:cobbled_deepslate":69,"minecraft:oak_planks":2,"minecraft:polished_diorite":8,"minecraft:sandstone":6,"minecraft:spruce_planks":6,"minecraft:stone_bricks":16},"sha256":"e13c6cc84ad606268f97ecf330529eb31fb3fa36d904e636c0cdca21ddaf24da","size":{"x":32,"y":1,"z":32}},{"blockCount":91,"bytes":2650,"file":"chunks/y139-z128-x224.json","offset":{"x":224,"y":139,"z":128},"requirements":{"minecraft:bricks":12,"minecraft:cobbled_deepslate":6,"minecraft:oak_planks":8,"minecraft:polished_diorite":45,"minecraft:sandstone":5,"minecraft:stone_bricks":15},"sha256":"99be4f6cfc55811fd39dd29270d5ba834c3f17224d45176b0eb73e49df145504","size":{"x":32,"y":1,"z":32}},{"blockCount":5,"bytes":783,"file":"chunks/y139-z160-x000.json","offset":{"x":0,"y":139,"z":160},"requirements":{"minecraft:sandstone":1,"minecraft:stone_bricks":4},"sha256":"4cd096911ffb64b2b52886ba529e9269b134363c76c88e4343ce58bde249c586","size":{"x":32,"y":1,"z":32}},{"blockCount":34,"bytes":1626,"file":"chunks/y139-z160-x032.json","offset":{"x":32,"y":139,"z":160},"requirements":{"minecraft:polished_diorite":19,"minecraft:sandstone":3,"minecraft:stone_bricks":12},"sha256":"5d77e03b9580fdffe8b8de8cfdbd6085058f19ceec3676b42c2d5cd73a754549","size":{"x":32,"y":1,"z":32}},{"blockCount":35,"bytes":1715,"file":"chunks/y139-z160-x064.json","offset":{"x":64,"y":139,"z":160},"requirements":{"minecraft:polished_diorite":25,"minecraft:sandstone":2,"minecraft:stone_bricks":8},"sha256":"7704180714cac128b9b42c0a8a4cd5b180c25515501b7ada973c5cfa7f88c1ac","size":{"x":32,"y":1,"z":32}},{"blockCount":119,"bytes":4126,"file":"chunks/y139-z160-x096.json","offset":{"x":96,"y":139,"z":160},"requirements":{"minecraft:bricks":46,"minecraft:cobbled_deepslate":30,"minecraft:polished_diorite":37,"minecraft:sandstone":4,"minecraft:stone_bricks":2},"sha256":"90b922716eefa44887aae198f27677552976c99e098629517931591259b55c34","size":{"x":32,"y":1,"z":32}},{"blockCount":119,"bytes":4243,"file":"chunks/y139-z160-x128.json","offset":{"x":128,"y":139,"z":160},"requirements":{"minecraft:bricks":34,"minecraft:cobbled_deepslate":31,"minecraft:polished_diorite":48,"minecraft:sandstone":1,"minecraft:stone_bricks":5},"sha256":"3785409d00fe851ef8c3e2e435e114d07ad81df624255396b5d40c554e7526b3","size":{"x":32,"y":1,"z":32}},{"blockCount":37,"bytes":1772,"file":"chunks/y139-z160-x160.json","offset":{"x":160,"y":139,"z":160},"requirements":{"minecraft:polished_diorite":26,"minecraft:sandstone":2,"minecraft:stone_bricks":9},"sha256":"91729468c42b50dd29cf6a5db3dfeeb564f01a94e928bf56c3ad450c1e8784e3","size":{"x":32,"y":1,"z":32}},{"blockCount":129,"bytes":3446,"file":"chunks/y139-z160-x192.json","offset":{"x":192,"y":139,"z":160},"requirements":{"minecraft:bricks":37,"minecraft:glass":6,"minecraft:polished_diorite":59,"minecraft:sandstone":2,"minecraft:stone_bricks":25},"sha256":"19f4272fd0f0a73d1dece87bca68c872be14068dec9132a6c5af0f5ae6608c1e","size":{"x":32,"y":1,"z":32}},{"blockCount":116,"bytes":3141,"file":"chunks/y139-z160-x224.json","offset":{"x":224,"y":139,"z":160},"requirements":{"minecraft:bricks":39,"minecraft:glass":14,"minecraft:polished_diorite":44,"minecraft:stone_bricks":19},"sha256":"1f53afd240c7f963b5b653009ef8e4d9e7fc907399172eba09e74c52d1223e02","size":{"x":32,"y":1,"z":32}},{"blockCount":10,"bytes":940,"file":"chunks/y139-z192-x064.json","offset":{"x":64,"y":139,"z":192},"requirements":{"minecraft:sandstone":2,"minecraft:stone_bricks":8},"sha256":"717d2cf3f843c5f07ce39cced865ba3dc1c08017dacff9300b87b88596f6faa1","size":{"x":32,"y":1,"z":32}},{"blockCount":135,"bytes":3479,"file":"chunks/y139-z192-x096.json","offset":{"x":96,"y":139,"z":192},"requirements":{"minecraft:bricks":34,"minecraft:cobbled_deepslate":18,"minecraft:oak_planks":8,"minecraft:polished_diorite":64,"minecraft:sandstone":5,"minecraft:stone_bricks":6},"sha256":"182d621c730aee9d31a405d23a17bb8cd37e68890905ff83ae36c3662c66bccc","size":{"x":32,"y":1,"z":32}},{"blockCount":90,"bytes":3098,"file":"chunks/y139-z192-x128.json","offset":{"x":128,"y":139,"z":192},"requirements":{"minecraft:bricks":18,"minecraft:cobbled_deepslate":17,"minecraft:polished_diorite":40,"minecraft:sandstone":4,"minecraft:stone_bricks":11},"sha256":"62ca9a93df4a20517d908ae6dee44cd774a2520db5a2e956380ae4e833e3ff73","size":{"x":32,"y":1,"z":32}},{"blockCount":2,"bytes":683,"file":"chunks/y140-z064-x064.json","offset":{"x":64,"y":140,"z":64},"requirements":{"minecraft:stone_bricks":2},"sha256":"de5063998f675db8d97ac87bad4a4c78893ab3d2ce5cdbdf6bfa5b7218518aac","size":{"x":32,"y":1,"z":32}},{"blockCount":157,"bytes":3962,"file":"chunks/y140-z064-x096.json","offset":{"x":96,"y":140,"z":64},"requirements":{"minecraft:bricks":50,"minecraft:cobbled_deepslate":22,"minecraft:oak_planks":5,"minecraft:polished_diorite":64,"minecraft:sandstone":5,"minecraft:stone_bricks":11},"sha256":"4373b5d34ced479308bb4c0dec0410ce079307a9d75ba9e61985189b8112fb3a","size":{"x":32,"y":1,"z":32}},{"blockCount":96,"bytes":3233,"file":"chunks/y140-z064-x128.json","offset":{"x":128,"y":140,"z":64},"requirements":{"minecraft:bricks":24,"minecraft:cobbled_deepslate":22,"minecraft:polished_diorite":40,"minecraft:sandstone":1,"minecraft:stone_bricks":9},"sha256":"a40efbc46fa04f82b88f0c9beaf449ed8ea976dc6487233da21cc27d62fb7113","size":{"x":32,"y":1,"z":32}},{"blockCount":10,"bytes":826,"file":"chunks/y140-z064-x192.json","offset":{"x":192,"y":140,"z":64},"requirements":{"minecraft:polished_diorite":7,"minecraft:stone_bricks":3},"sha256":"cef358067dd15572330ddcad003404b033a146168ff038e9ac0c0a36784f8cf0","size":{"x":32,"y":1,"z":32}},{"blockCount":10,"bytes":827,"file":"chunks/y140-z064-x224.json","offset":{"x":224,"y":140,"z":64},"requirements":{"minecraft:polished_diorite":7,"minecraft:stone_bricks":3},"sha256":"7abfc6cff70e08f2b88555d68c7ac482b7bbd09f6d6bce2fc944090b54d91e12","size":{"x":32,"y":1,"z":32}},{"blockCount":1,"bytes":642,"file":"chunks/y140-z096-x000.json","offset":{"x":0,"y":140,"z":96},"requirements":{"minecraft:stone_bricks":1},"sha256":"287f59a70e9156872704146054ac97822496b0e22c79b3587eb7b511c6933fa5","size":{"x":32,"y":1,"z":32}},{"blockCount":36,"bytes":1523,"file":"chunks/y140-z096-x032.json","offset":{"x":32,"y":140,"z":96},"requirements":{"minecraft:polished_diorite":33,"minecraft:stone_bricks":3},"sha256":"f74a22e83a9522ce6e516a55286764e392261c38d56ecd61d9a646e2b86b828b","size":{"x":32,"y":1,"z":32}},{"blockCount":33,"bytes":1555,"file":"chunks/y140-z096-x064.json","offset":{"x":64,"y":140,"z":96},"requirements":{"minecraft:polished_diorite":31,"minecraft:stone_bricks":2},"sha256":"680546ba2418f12e53c43ed53a771929ef24abefa187d5eb3b34119d14dcab30","size":{"x":32,"y":1,"z":32}},{"blockCount":117,"bytes":3817,"file":"chunks/y140-z096-x096.json","offset":{"x":96,"y":140,"z":96},"requirements":{"minecraft:bricks":62,"minecraft:cobbled_deepslate":31,"minecraft:polished_diorite":22,"minecraft:stone_bricks":2},"sha256":"7f8681019615db2ba9227571d35405677aba3a794ace6631293579f19fba4355","size":{"x":32,"y":1,"z":32}},{"blockCount":98,"bytes":3668,"file":"chunks/y140-z096-x128.json","offset":{"x":128,"y":140,"z":96},"requirements":{"minecraft:bricks":29,"minecraft:cobbled_deepslate":28,"minecraft:polished_diorite":36,"minecraft:stone_bricks":5},"sha256":"ad835d910896a61c90f97b978f9ab3a21a0d61bf41882267635243e2481b960f","size":{"x":32,"y":1,"z":32}},{"blockCount":35,"bytes":1595,"file":"chunks/y140-z096-x160.json","offset":{"x":160,"y":140,"z":96},"requirements":{"minecraft:polished_diorite":33,"minecraft:stone_bricks":2},"sha256":"a8a2b048955633324fa7ea372d8225c978c2746f512c57b84f0c37b5e9e86354","size":{"x":32,"y":1,"z":32}},{"blockCount":144,"bytes":3690,"file":"chunks/y140-z096-x192.json","offset":{"x":192,"y":140,"z":96},"requirements":{"minecraft:bricks":37,"minecraft:cobbled_deepslate":16,"minecraft:glass":6,"minecraft:oak_planks":2,"minecraft:polished_diorite":73,"minecraft:stone_bricks":10},"sha256":"655b53df3b1e2804a9e8a5aba88901d992f100511f072a8d8f2ba7384507f666","size":{"x":32,"y":1,"z":32}},{"blockCount":116,"bytes":3044,"file":"chunks/y140-z096-x224.json","offset":{"x":224,"y":140,"z":96},"requirements":{"minecraft:bricks":39,"minecraft:glass":14,"minecraft:polished_diorite":52,"minecraft:stone_bricks":11},"sha256":"5c1970e1ca8d0199c3897de3121e1ad878c339e893dc00e614d560891f8161d2","size":{"x":32,"y":1,"z":32}},{"blockCount":2,"bytes":682,"file":"chunks/y140-z128-x000.json","offset":{"x":0,"y":140,"z":128},"requirements":{"minecraft:stone_bricks":2},"sha256":"17f7357812e4fbfd6de716c533c6e3384d92cb21d78df8a72e5f7674cfaf25b7","size":{"x":32,"y":1,"z":32}},{"blockCount":133,"bytes":3959,"file":"chunks/y140-z128-x032.json","offset":{"x":32,"y":140,"z":128},"requirements":{"minecraft:bricks":36,"minecraft:cobbled_deepslate":44,"minecraft:oak_planks":1,"minecraft:polished_diorite":24,"minecraft:sandstone":1,"minecraft:stone_bricks":27},"sha256":"64af42b409a0e1737d5330c19324a5788c51c20b8f7c32b1ac54b171e575c10d","size":{"x":32,"y":1,"z":32}},{"blockCount":160,"bytes":2972,"file":"chunks/y140-z128-x064.json","offset":{"x":64,"y":140,"z":128},"requirements":{"minecraft:bricks":90,"minecraft:cobbled_deepslate":55,"minecraft:polished_diorite":6,"minecraft:stone_bricks":9},"sha256":"16e0f299fceedf4957b28851d4eb40d4f590850ff07632c0c14657cdf8d1560e","size":{"x":32,"y":1,"z":32}},{"blockCount":141,"bytes":3787,"file":"chunks/y140-z128-x096.json","offset":{"x":96,"y":140,"z":128},"requirements":{"minecraft:bricks":104,"minecraft:cobbled_deepslate":32,"minecraft:stone_bricks":5},"sha256":"5b9d1cc764885a30f436759e403b9f4c226b5be5870c62163251af70dd810d83","size":{"x":32,"y":1,"z":32}},{"blockCount":172,"bytes":3414,"file":"chunks/y140-z128-x128.json","offset":{"x":128,"y":140,"z":128},"requirements":{"minecraft:bricks":102,"minecraft:cobbled_deepslate":60,"minecraft:polished_diorite":3,"minecraft:stone_bricks":7},"sha256":"5b53da8246850670982294aff9fb723fc999e7c9d5d71a596037926c27c87098","size":{"x":32,"y":1,"z":32}},{"blockCount":166,"bytes":3089,"file":"chunks/y140-z128-x160.json","offset":{"x":160,"y":140,"z":128},"requirements":{"minecraft:bricks":94,"minecraft:cobbled_deepslate":60,"minecraft:polished_diorite":7,"minecraft:stone_bricks":5},"sha256":"66c1f8abc98f5c33d4e4623f102d6540223dfb4313554c4f8246354ed1192df4","size":{"x":32,"y":1,"z":32}},{"blockCount":195,"bytes":4155,"file":"chunks/y140-z128-x192.json","offset":{"x":192,"y":140,"z":128},"requirements":{"minecraft:bricks":88,"minecraft:cobbled_deepslate":72,"minecraft:oak_planks":6,"minecraft:polished_diorite":15,"minecraft:spruce_planks":6,"minecraft:stone_bricks":8},"sha256":"cc428343ce8116b2b3e516d36e88da14523add6bfbc2ce911bba15a10c59daf8","size":{"x":32,"y":1,"z":32}},{"blockCount":91,"bytes":2611,"file":"chunks/y140-z128-x224.json","offset":{"x":224,"y":140,"z":128},"requirements":{"minecraft:bricks":14,"minecraft:cobbled_deepslate":7,"minecraft:oak_planks":5,"minecraft:polished_diorite":47,"minecraft:sandstone":6,"minecraft:stone_bricks":12},"sha256":"34b41766a60de3a9a19b7a0e0f4c692bcd71a36478b669b9a7f8258dda647bd4","size":{"x":32,"y":1,"z":32}},{"blockCount":1,"bytes":643,"file":"chunks/y140-z160-x000.json","offset":{"x":0,"y":140,"z":160},"requirements":{"minecraft:stone_bricks":1},"sha256":"7b0318862a27a9bacf4ce84d604c3292ee05728fa36a5fc86ac0591c3300d6e5","size":{"x":32,"y":1,"z":32}},{"blockCount":22,"bytes":1253,"file":"chunks/y140-z160-x032.json","offset":{"x":32,"y":140,"z":160},"requirements":{"minecraft:polished_diorite":19,"minecraft:stone_bricks":3},"sha256":"b88f716aaa941503bb8106746a002e0902209dd4dffe3e301995760b7882bb62","size":{"x":32,"y":1,"z":32}},{"blockCount":27,"bytes":1459,"file":"chunks/y140-z160-x064.json","offset":{"x":64,"y":140,"z":160},"requirements":{"minecraft:polished_diorite":25,"minecraft:stone_bricks":2},"sha256":"7b24ffed8c2809cdce2db197ad2971e2dfa08cd3ebed09078eb0735f919934aa","size":{"x":32,"y":1,"z":32}},{"blockCount":114,"bytes":3798,"file":"chunks/y140-z160-x096.json","offset":{"x":96,"y":140,"z":160},"requirements":{"minecraft:bricks":55,"minecraft:cobbled_deepslate":27,"minecraft:polished_diorite":27,"minecraft:stone_bricks":5},"sha256":"14aebe10beab1566def13f236ad9bdf933f00e859051f11527e04f1e3d638c9e","size":{"x":32,"y":1,"z":32}},{"blockCount":102,"bytes":3801,"file":"chunks/y140-z160-x128.json","offset":{"x":128,"y":140,"z":160},"requirements":{"minecraft:bricks":31,"minecraft:cobbled_deepslate":26,"minecraft:polished_diorite":38,"minecraft:stone_bricks":7},"sha256":"6476786fbf373a2b3258e7307efe153b0d7016ce3658453e2ab6a41ca10c6256","size":{"x":32,"y":1,"z":32}},{"blockCount":28,"bytes":1478,"file":"chunks/y140-z160-x160.json","offset":{"x":160,"y":140,"z":160},"requirements":{"minecraft:polished_diorite":26,"minecraft:stone_bricks":2},"sha256":"1d6260f32fc5310a8f7b845b98e79b9e5387cc2c63297077bd35975f8218f990","size":{"x":32,"y":1,"z":32}},{"blockCount":121,"bytes":3136,"file":"chunks/y140-z160-x192.json","offset":{"x":192,"y":140,"z":160},"requirements":{"minecraft:bricks":37,"minecraft:glass":6,"minecraft:polished_diorite":67,"minecraft:stone_bricks":11},"sha256":"eb61795dc33c3cb9d326976450d77e522ce840ade809f11e424c13d854cd78f4","size":{"x":32,"y":1,"z":32}},{"blockCount":114,"bytes":3005,"file":"chunks/y140-z160-x224.json","offset":{"x":224,"y":140,"z":160},"requirements":{"minecraft:bricks":39,"minecraft:glass":14,"minecraft:polished_diorite":52,"minecraft:stone_bricks":9},"sha256":"d9e7ca8c118b42030de3e0d2f3b08e435c88b86a1a0b00bcee4b9876ef24a9ee","size":{"x":32,"y":1,"z":32}},{"blockCount":2,"bytes":684,"file":"chunks/y140-z192-x064.json","offset":{"x":64,"y":140,"z":192},"requirements":{"minecraft:stone_bricks":2},"sha256":"4660883ed821cb87553fdc747436320c57992ab5a0881bc40c0569a68b2f1e47","size":{"x":32,"y":1,"z":32}},{"blockCount":134,"bytes":3346,"file":"chunks/y140-z192-x096.json","offset":{"x":96,"y":140,"z":192},"requirements":{"minecraft:bricks":39,"minecraft:cobbled_deepslate":17,"minecraft:oak_planks":5,"minecraft:polished_diorite":59,"minecraft:sandstone":5,"minecraft:stone_bricks":9},"sha256":"a368944e106f51e57f6868aa7682216211e98da650871282f496da6d6e22ee67","size":{"x":32,"y":1,"z":32}},{"blockCount":77,"bytes":2639,"file":"chunks/y140-z192-x128.json","offset":{"x":128,"y":140,"z":192},"requirements":{"minecraft:bricks":17,"minecraft:cobbled_deepslate":16,"minecraft:polished_diorite":35,"minecraft:sandstone":1,"minecraft:stone_bricks":8},"sha256":"89d7449f7927d9b978e0745b9704fe09f47a024d1decd6f87533ceb01833b5f3","size":{"x":32,"y":1,"z":32}},{"blockCount":2,"bytes":683,"file":"chunks/y141-z064-x064.json","offset":{"x":64,"y":141,"z":64},"requirements":{"minecraft:stone_bricks":2},"sha256":"411f5c8a6483bc0c1b171772df7ca5b675aa598eea5520f6364f8f60ecb5662d","size":{"x":32,"y":1,"z":32}},{"blockCount":165,"bytes":4510,"file":"chunks/y141-z064-x096.json","offset":{"x":96,"y":141,"z":64},"requirements":{"minecraft:bricks":45,"minecraft:cobbled_deepslate":24,"minecraft:oak_planks":4,"minecraft:polished_diorite":31,"minecraft:sandstone":7,"minecraft:stone_bricks":54},"sha256":"5f360588f52693f93df5c5be8027cff1559308c6963a32ab46e1a7d3f287d955","size":{"x":32,"y":1,"z":32}},{"blockCount":102,"bytes":3552,"file":"chunks/y141-z064-x128.json","offset":{"x":128,"y":141,"z":64},"requirements":{"minecraft:bricks":15,"minecraft:cobbled_deepslate":23,"minecraft:polished_diorite":10,"minecraft:stone_bricks":54},"sha256":"465aa1079c14ce29b860a173ab8ec38a4f7d526a39ae96d9fba6aeb1955992d5","size":{"x":32,"y":1,"z":32}},{"blockCount":10,"bytes":788,"file":"chunks/y141-z064-x192.json","offset":{"x":192,"y":141,"z":64},"requirements":{"minecraft:polished_diorite":7,"minecraft:stone_bricks":3},"sha256":"1cc0522cc707fff178dcf35fe1cc3d852a804b49ddc212d8e57d9590a910f1ee","size":{"x":32,"y":1,"z":32}}],"schema":1}
