{"entries":[{"blockCount":10,"bytes":789,"file":"chunks/y141-z064-x224.json","offset":{"x":224,"y":141,"z":64},"requirements":{"minecraft:polished_diorite":7,"minecraft:stone_bricks":3},"sha256":"21e158e6eb3b4de9938f271f6a24210e0b32981783e082d19bb533dc6a67097b","size":{"x":32,"y":1,"z":32}},{"blockCount":1,"bytes":642,"file":"chunks/y141-z096-x000.json","offset":{"x":0,"y":141,"z":96},"requirements":{"minecraft:stone_bricks":1},"sha256":"3de19852f71b71fe59e54585572b16ee106ad2b8b28cb9ce70469fe9cca48c13","size":{"x":32,"y":1,"z":32}},{"blockCount":44,"bytes":1578,"file":"chunks/y141-z096-x032.json","offset":{"x":32,"y":141,"z":96},"requirements":{"minecraft:polished_diorite":5,"minecraft:stone_bricks":39},"sha256":"9ddad3a5c58d8d311f86845c0d4853f8bc196fa36caf2ca28043aeb6abd083a7","size":{"x":32,"y":1,"z":32}},{"blockCount":43,"bytes":1647,"file":"chunks/y141-z096-x064.json","offset":{"x":64,"y":141,"z":96},"requirements":{"minecraft:polished_diorite":4,"minecraft:stone_bricks":39},"sha256":"0c1579ab50fe4718f5fa8759fc89e943022ba39bd4946b2d5c1bf47b9ddb001b","size":{"x":32,"y":1,"z":32}},{"blockCount":139,"bytes":4714,"file":"chunks/y141-z096-x096.json","offset":{"x":96,"y":141,"z":96},"requirements":{"minecraft:bricks":62,"minecraft:cobbled_deepslate":30,"minecraft:polished_diorite":3,"minecraft:sandstone":6,"minecraft:stone_bricks":38},"sha256":"b6dcbcd1f4a093722d26427b57cc690c4576389c115fc53cb94540f1c5cfc1f4","size":{"x":32,"y":1,"z":32}},{"blockCount":113,"bytes":4122,"file":"chunks/y141-z096-x128.json","offset":{"x":128,"y":141,"z":96},"requirements":{"minecraft:bricks":23,"minecraft:cobbled_deepslate":29,"minecraft:polished_diorite":5,"minecraft:stone_bricks":56},"sha256":"5e0f9f7a9d9ac9b81b5164b6f483e8842fbc9079111d4b9d8484791c5d6e33cd","size":{"x":32,"y":1,"z":32}},{"blockCount":45,"bytes":1629,"file":"chunks/y141-z096-x160.json","offset":{"x":160,"y":141,"z":96},"requirements":{"minecraft:polished_diorite":4,"minecraft:stone_bricks":41},"sha256":"08c3034de64bed2d933959167bd30d20b612e5502613e08830c634e1e209110d","size":{"x":32,"y":1,"z":32}},{"blockCount":149,"bytes":3710,"file":"chunks/y141-z096-x192.json","offset":{"x":192,"y":141,"z":96},"requirements":{"minecraft:bricks":37,"minecraft:cobbled_deepslate":15,"minecraft:glass":6,"minecraft:polished_diorite":53,"minecraft:spruce_planks":2,"minecraft:stone_bricks":36},"sha256":"5c0c623c527dc460e621b7068669e8b8e130ac33731b94604a710f64f3aa21d9","size":{"x":32,"y":1,"z":32}},{"blockCount":116,"bytes":3045,"file":"chunks/y141-z096-x224.json","offset":{"x":224,"y":141,"z":96},"requirements":{"minecraft:bricks":39,"minecraft:glass":14,"minecraft:polished_diorite":52,"minecraft:stone_bricks":11},"sha256":"eecab77b387882b755e2572fc5291b5bb645572620fedf947ec93afed5e99454","size":{"x":32,"y":1,"z":32}},{"blockCount":2,"bytes":682,"file":"chunks/y141-z128-x000.json","offset":{"x":0,"y":141,"z":128},"requirements":{"minecraft:stone_bricks":2},"sha256":"1092e26f512b8a479a2440af22792960a5ce24f68a957e9f8470f1d00718a9cd","size":{"x":32,"y":1,"z":32}},{"blockCount":162,"bytes":3993,"file":"chunks/y141-z128-x032.json","offset":{"x":32,"y":141,"z":128},"requirements":{"minecraft:bricks":32,"minecraft:cobbled_deepslate":55,"minecraft:glass":1,"minecraft:oak_planks":2,"minecraft:polished_diorite":1,"minecraft:sandstone":3,"minecraft:stone_bricks":68},"sha256":"556acc14260ca1f8110848ff8c1aa835c55daecb366e1dbc9d6955594b0e4b24","size":{"x":32,"y":1,"z":32}},{"blockCount":175,"bytes":3120,"file":"chunks/y141-z128-x064.json","offset":{"x":64,"y":141,"z":128},"requirements":{"minecraft:bricks":76,"minecraft:cobbled_deepslate":55,"minecraft:sandstone":4,"minecraft:stone_bricks":40},"sha256":"50169333c9a09fb2299603394a5296de1ce7ea8b39411ce1aed4658125350799","size":{"x":32,"y":1,"z":32}},{"blockCount":167,"bytes":4600,"file":"chunks/y141-z128-x096.json","offset":{"x":96,"y":141,"z":128},"requirements":{"minecraft:bricks":111,"minecraft:cobbled_deepslate":29,"minecraft:oak_planks":1,"minecraft:sandstone":8,"minecraft:stone_bricks":18},"sha256":"5c8e301a90284777ce15c04be2e6ae2fe111608f5e3dbc2817b76e25af7ab166","size":{"x":32,"y":1,"z":32}},{"blockCount":195,"bytes":3773,"file":"chunks/y141-z128-x128.json","offset":{"x":128,"y":141,"z":128},"requirements":{"minecraft:bricks":96,"minecraft:cobbled_deepslate":58,"minecraft:oak_planks":3,"minecraft:sandstone":4,"minecraft:stone_bricks":34},"sha256":"e58d04089c22b63f8ca8186acbc2d82b8b704f72f6ec428c68fb84e8825e25a2","size":{"x":32,"y":1,"z":32}},{"blockCount":179,"bytes":3101,"file":"chunks/y141-z128-x160.json","offset":{"x":160,"y":141,"z":128},"requirements":{"minecraft:bricks":74,"minecraft:cobbled_deepslate":57,"minecraft:sandstone":4,"minecraft:stone_bricks":44},"sha256":"6ad8531120a74ce6098f84327767afe191590a0c5321a387db2886f29b15564e","size":{"x":32,"y":1,"z":32}},{"blockCount":209,"bytes":4350,"file":"chunks/y141-z128-x192.json","offset":{"x":192,"y":141,"z":128},"requirements":{"minecraft:bricks":76,"minecraft:cobbled_deepslate":72,"minecraft:oak_planks":4,"minecraft:polished_diorite":7,"minecraft:sandstone":6,"minecraft:spruce_planks":8,"minecraft:stone_bricks":36},"sha256":"de26e794ada856a5b34a06d9ba7a50dc3b63a87503bb6812fa57f48b0882fa67","size":{"x":32,"y":1,"z":32}},{"blockCount":83,"bytes":2517,"file":"chunks/y141-z128-x224.json","offset":{"x":224,"y":141,"z":128},"requirements":{"minecraft:bricks":12,"minecraft:cobbled_deepslate":7,"minecraft:oak_planks":4,"minecraft:polished_diorite":42,"minecraft:sandstone":5,"minecraft:stone_bricks":13},"sha256":"fc44cd1a7c70a2f02de35f13a3b018e81b044be377d1c5bd537b9df9ad5a96fe","size":{"x":32,"y":1,"z":32}},{"blockCount":1,"bytes":643,"file":"chunks/y141-z160-x000.json","offset":{"x":0,"y":141,"z":160},"requirements":{"minecraft:stone_bricks":1},"sha256":"a8ddaecda6b1813e3c4413aaacf95ffde872d295e5bdd3dbe435c060e73bb244","size":{"x":32,"y":1,"z":32}},{"blockCount":25,"bytes":1290,"file":"chunks/y141-z160-x032.json","offset":{"x":32,"y":141,"z":160},"requirements":{"minecraft:polished_diorite":4,"minecraft:stone_bricks":21},"sha256":"74836d6fc3cc5b2a80711e65d4c8be88ececaeae7a4d25f5727e9a59ab8e9ede","size":{"x":32,"y":1,"z":32}},{"blockCount":32,"bytes":1514,"file":"chunks/y141-z160-x064.json","offset":{"x":64,"y":141,"z":160},"requirements":{"minecraft:polished_diorite":4,"minecraft:stone_bricks":28},"sha256":"7d20b91929975151435c56a0dd33788681d01b5f197de36321a96a059261c784","size":{"x":32,"y":1,"z":32}},{"blockCount":135,"bytes":4638,"file":"chunks/y141-z160-x096.json","offset":{"x":96,"y":141,"z":160},"requirements":{"minecraft:bricks":55,"minecraft:cobbled_deepslate":26,"minecraft:polished_diorite":3,"minecraft:sandstone":4,"minecraft:stone_bricks":47},"sha256":"0e2ba7ce5a755c6fdb1674d9f8012e681eae4e11b42f881ad8b00fdc962b6b4f","size":{"x":32,"y":1,"z":32}},{"blockCount":115,"bytes":4199,"file":"chunks/y141-z160-x128.json","offset":{"x":128,"y":141,"z":160},"requirements":{"minecraft:bricks":25,"minecraft:cobbled_deepslate":28,"minecraft:polished_diorite":5,"minecraft:stone_bricks":57},"sha256":"93b011797e59a1f340f70191cc3edc67d53231eec13c254b4de98a974596c32d","size":{"x":32,"y":1,"z":32}},{"blockCount":33,"bytes":1514,"file":"chunks/y141-z160-x160.json","offset":{"x":160,"y":141,"z":160},"requirements":{"minecraft:polished_diorite":4,"minecraft:stone_bricks":29},"sha256":"5cbc23cf45580324e87fcc304338bdb7857f051a1111a0b527b04663ff503068","size":{"x":32,"y":1,"z":32}},{"blockCount":124,"bytes":3135,"file":"chunks/y141-z160-x192.json","offset":{"x":192,"y":141,"z":160},"requirements":{"minecraft:bricks":37,"minecraft:glass":6,"minecraft:polished_diorite":53,"minecraft:stone_bricks":28},"sha256":"03e4740dfe213439f388491cbefc74ed64a6213e79d5d4944aca3e7ad953a469","size":{"x":32,"y":1,"z":32}},{"blockCount":114,"bytes":2967,"file":"chunks/y141-z160-x224.json","offset":{"x":224,"y":141,"z":160},"requirements":{"minecraft:bricks":39,"minecraft:glass":14,"minecraft:polished_diorite":52,"minecraft:stone_bricks":9},"sha256":"d3bd9616a021507723f91b35bd923eb367bb381a3ea951fbaf87c4a3eb568aba","size":{"x":32,"y":1,"z":32}},{"blockCount":2,"bytes":684,"file":"chunks/y141-z192-x064.json","offset":{"x":64,"y":141,"z":192},"requirements":{"minecraft:stone_bricks":2},"sha256":"60c35ea895ec63513c67bc70c622a662c55650d8d3e0cbfdf357810d919e7f5c","size":{"x":32,"y":1,"z":32}},{"blockCount":138,"bytes":3726,"file":"chunks/y141-z192-x096.json","offset":{"x":96,"y":141,"z":192},"requirements":{"minecraft:bricks":34,"minecraft:cobbled_deepslate":14,"minecraft:oak_planks":4,"minecraft:polished_diorite":31,"minecraft:sandstone":7,"minecraft:stone_bricks":48},"sha256":"aa1abbf9b13bffb6e8c2f74cdf1034645e96314aad28f7f4b0550de88d4db2b8","size":{"x":32,"y":1,"z":32}},{"blockCount":81,"bytes":2901,"file":"chunks/y141-z192-x128.json","offset":{"x":128,"y":141,"z":192},"requirements":{"minecraft:bricks":10,"minecraft:cobbled_deepslate":15,"minecraft:polished_diorite":10,"minecraft:stone_bricks":46},"sha256":"c21dd9ab180f82b0cb7845c52f9931e5da36421300b2ce3cccf7057475470ec1","size":{"x":32,"y":1,"z":32}},{"blockCount":198,"bytes":5275,"file":"chunks/y142-z064-x096.json","offset":{"x":96,"y":142,"z":64},"requirements":{"minecraft:bricks":57,"minecraft:cobbled_deepslate":19,"minecraft:oak_planks":26,"minecraft:polished_diorite":51,"minecraft:sandstone":4,"minecraft:stone_bricks":41},"sha256":"9ca61b669fa3f51a6522e1dbb7bcc50321b4f5a506c3ea300f35f6b0ca25934a","size":{"x":32,"y":1,"z":32}},{"blockCount":106,"bytes":3539,"file":"chunks/y142-z064-x128.json","offset":{"x":128,"y":142,"z":64},"requirements":{"minecraft:bricks":9,"minecraft:cobbled_deepslate":24,"minecraft:oak_planks":26,"minecraft:polished_diorite":28,"minecraft:stone_bricks":19},"sha256":"1de29b822d8d82580cc0a924ff4e7b0081157c44b26502fc036267353289009f","size":{"x":32,"y":1,"z":32}},{"blockCount":10,"bytes":864,"file":"chunks/y142-z064-x192.json","offset":{"x":192,"y":142,"z":64},"requirements":{"minecraft:polished_diorite":7,"minecraft:stone_bricks":3},"sha256":"4331fbcdc7e0ced39b5c932a19b0275cd751f7fa6b4dcda7af247e7b65017273","size":{"x":32,"y":1,"z":32}},{"blockCount":10,"bytes":865,"file":"chunks/y142-z064-x224.json","offset":{"x":224,"y":142,"z":64},"requirements":{"minecraft:polished_diorite":7,"minecraft:stone_bricks":3},"sha256":"4c19800577afb93b4eb39866d2383f8d9473f2c17e46a73b303830f6ff9ff483","size":{"x":32,"y":1,"z":32}},{"blockCount":33,"bytes":1653,"file":"chunks/y142-z096-x032.json","offset":{"x":32,"y":142,"z":96},"requirements":{"minecraft:polished_diorite":23,"minecraft:stone_bricks":10},"sha256":"27918b3734d162f840840f5602ada9b6f283f040b2f571857b1bae1f295e70bb","size":{"x":32,"y":1,"z":32}},{"blockCount":31,"bytes":1647,"file":"chunks/y142-z096-x064.json","offset":{"x":64,"y":142,"z":96},"requirements":{"minecraft:polished_diorite":22,"minecraft:stone_bricks":9},"sha256":"3ecc89a8dcb3c51aacdf935c9c479612180e76b6c3fde07aec1bd4b9a1a0a78a","size":{"x":32,"y":1,"z":32}},{"blockCount":195,"bytes":5809,"file":"chunks/y142-z096-x096.json","offset":{"x":96,"y":142,"z":96},"requirements":{"minecraft:bricks":76,"minecraft:cobbled_deepslate":25,"minecraft:oak_planks":37,"minecraft:polished_diorite":15,"minecraft:stone_bricks":42},"sha256":"3de1e381a84e5cb8024ba12bb0b18d27c8437427807dfcdcdd3cfbd1de58d76e","size":{"x":32,"y":1,"z":32}},{"blockCount":121,"bytes":4016,"file":"chunks/y142-z096-x128.json","offset":{"x":128,"y":142,"z":96},"requirements":{"minecraft:bricks":10,"minecraft:cobbled_deepslate":30,"minecraft:oak_planks":37,"minecraft:polished_diorite":25,"minecraft:stone_bricks":19},"sha256":"9678596be9d98b6cffa03777dc55163847cc0a395bce1549578f62687c9307d2","size":{"x":32,"y":1,"z":32}},{"blockCount":33,"bytes":1706,"file":"chunks/y142-z096-x160.json","offset":{"x":160,"y":142,"z":96},"requirements":{"minecraft:polished_diorite":24,"minecraft:stone_bricks":9},"sha256":"52afa76b9cd9f0b4a6660de9d2cb8665810e1cf42c1e42b9f64fea4784685ed8","size":{"x":32,"y":1,"z":32}},{"blockCount":143,"bytes":3709,"file":"chunks/y142-z096-x192.json","offset":{"x":192,"y":142,"z":96},"requirements":{"minecraft:bricks":38,"minecraft:cobbled_deepslate":12,"minecraft:glass":6,"minecraft:oak_planks":3,"minecraft:polished_diorite":67,"minecraft:stone_bricks":17},"sha256":"d49865bf749955e7ed1df7c485f16f90d237aef2abab306aa2de55f8045685c4","size":{"x":32,"y":1,"z":32}},{"blockCount":118,"bytes":3101,"file":"chunks/y142-z096-x224.json","offset":{"x":224,"y":142,"z":96},"requirements":{"minecraft:bricks":42,"minecraft:glass":11,"minecraft:polished_diorite":55,"minecraft:stone_bricks":10},"sha256":"a08ed7ca4cf7b4d6ca2c59966258ca53437a63814543cecab7a93dae3f2bcb21","size":{"x":32,"y":1,"z":32}},{"blockCount":171,"bytes":4011,"file":"chunks/y142-z128-x032.json","offset":{"x":32,"y":142,"z":128},"requirements":{"minecraft:bricks":31,"minecraft:cobbled_deepslate":53,"minecraft:oak_planks":32,"minecraft:polished_diorite":17,"minecraft:sandstone":1,"minecraft:stone_bricks":37},"sha256":"156c3e62b6c916231e9b92db7ce5539be588cb038b91695387758a0259105a5c","size":{"x":32,"y":1,"z":32}},{"blockCount":254,"bytes":3439,"file":"chunks/y142-z128-x064.json","offset":{"x":64,"y":142,"z":128},"requirements":{"minecraft:bricks":80,"minecraft:cobbled_deepslate":60,"minecraft:oak_planks":74,"minecraft:polished_diorite":4,"minecraft:stone_bricks":36},"sha256":"ecdda82afc1697f7fc2a396f16f25594c3cdd14dbab1274479438bcbde7463ce","size":{"x":32,"y":1,"z":32}},{"blockCount":270,"bytes":5520,"file":"chunks/y142-z128-x096.json","offset":{"x":96,"y":142,"z":128},"requirements":{"minecraft:bricks":132,"minecraft:cobbled_deepslate":36,"minecraft:oak_planks":48,"minecraft:spruce_planks":2,"minecraft:stone_bricks":52},"sha256":"6f45c7e43f26b0b33215213f8637fad857f0a4485fa995d36c27e593597fdd90","size":{"x":32,"y":1,"z":32}},{"blockCount":288,"bytes":4098,"file":"chunks/y142-z128-x128.json","offset":{"x":128,"y":142,"z":128},"requirements":{"minecraft:bricks":84,"minecraft:cobbled_deepslate":60,"minecraft:oak_planks":82,"minecraft:polished_diorite":2,"minecraft:spruce_planks":2,"minecraft:stone_bricks":58},"sha256":"ea90a549a4a8775ac696f28ca06b54a63475ba152f0cb3e09e10cd6c823b7ec8","size":{"x":32,"y":1,"z":32}},{"blockCount":257,"bytes":3478,"file":"chunks/y142-z128-x160.json","offset":{"x":160,"y":142,"z":128},"requirements":{"minecraft:bricks":78,"minecraft:cobbled_deepslate":62,"minecraft:oak_planks":74,"minecraft:polished_diorite":5,"minecraft:stone_bricks":38},"sha256":"5b0cbb7ab77c1566d160517704421b13b315ca8ae3061929111d3a9db4d73587","size":{"x":32,"y":1,"z":32}},{"blockCount":277,"bytes":4805,"file":"chunks/y142-z128-x192.json","offset":{"x":192,"y":142,"z":128},"requirements":{"minecraft:bricks":80,"minecraft:cobbled_deepslate":66,"minecraft:glass":1,"minecraft:oak_planks":71,"minecraft:polished_diorite":11,"minecraft:spruce_planks":6,"minecraft:stone_bricks":42},"sha256":"e99dbd0ed4eacb179bccda598ace2b8394788391f2055450e51221205a4b5a6c","size":{"x":32,"y":1,"z":32}},{"blockCount":87,"bytes":2459,"file":"chunks/y142-z128-x224.json","offset":{"x":224,"y":142,"z":128},"requirements":{"minecraft:bricks":14,"minecraft:cobbled_deepslate":7,"minecraft:oak_planks":4,"minecraft:polished_diorite":40,"minecraft:sandstone":4,"minecraft:stone_bricks":18},"sha256":"a026d415efdfd62e1d17b59d445baf9ebeb3a063ab3dd51b859a110ae997f7ff","size":{"x":32,"y":1,"z":32}},{"blockCount":19,"bytes":1249,"file":"chunks/y142-z160-x032.json","offset":{"x":32,"y":142,"z":160},"requirements":{"minecraft:polished_diorite":14,"minecraft:stone_bricks":5},"sha256":"dd4d3ce7581cba1a1e502fa9e9b844be10159b97f705bacafc11bec90917994e","size":{"x":32,"y":1,"z":32}},{"blockCount":25,"bytes":1474,"file":"chunks/y142-z160-x064.json","offset":{"x":64,"y":142,"z":160},"requirements":{"minecraft:polished_diorite":18,"minecraft:stone_bricks":7},"sha256":"351ba1e7c4f8585cbf15395593ce5797daa71175ea553cc0cc41dfa9419860d2","size":{"x":32,"y":1,"z":32}},{"blockCount":188,"bytes":5656,"file":"chunks/y142-z160-x096.json","offset":{"x":96,"y":142,"z":160},"requirements":{"minecraft:bricks":69,"minecraft:cobbled_deepslate":27,"minecraft:oak_planks":37,"minecraft:polished_diorite":19,"minecraft:stone_bricks":36},"sha256":"b99365e3bb706c8966b11c53b673c4962a9838f536de0c57b24f064f5e7c19c1","size":{"x":32,"y":1,"z":32}},{"blockCount":125,"bytes":4112,"file":"chunks/y142-z160-x128.json","offset":{"x":128,"y":142,"z":160},"requirements":{"minecraft:bricks":13,"minecraft:cobbled_deepslate":31,"minecraft:oak_planks":37,"minecraft:polished_diorite":27,"minecraft:stone_bricks":17},"sha256":"cecdf84e6ed0ec11f8d34e3a47348f9edc60e1e2d2bc4132612926a92bc556ec","size":{"x":32,"y":1,"z":32}},{"blockCount":26,"bytes":1513,"file":"chunks/y142-z160-x160.json","offset":{"x":160,"y":142,"z":160},"requirements":{"minecraft:polished_diorite":19,"minecraft:stone_bricks":7},"sha256":"142e7313d1ab71391c925b0a714393579e9d4ecde99d9a9378cbbc960323152d","size":{"x":32,"y":1,"z":32}},{"blockCount":120,"bytes":3174,"file":"chunks/y142-z160-x192.json","offset":{"x":192,"y":142,"z":160},"requirements":{"minecraft:bricks":38,"minecraft:glass":5,"minecraft:polished_diorite":63,"minecraft:stone_bricks":14},"sha256":"2e2e12955545804f4110c571e21bba8cce99ec2f9435fe155a7d55c995d87f3c","size":{"x":32,"y":1,"z":32}},{"blockCount":117,"bytes":3062,"file":"chunks/y142-z160-x224.json","offset":{"x":224,"y":142,"z":160},"requirements":{"minecraft:bricks":42,"minecraft:glass":11,"minecraft:polished_diorite":55,"minecraft:stone_bricks":9},"sha256":"340649651cb2f970957bbd3d2e9acceaf950190579173774409df5fa9ab6cf94","size":{"x":32,"y":1,"z":32}},{"blockCount":160,"bytes":4319,"file":"chunks/y142-z192-x096.json","offset":{"x":96,"y":142,"z":192},"requirements":{"minecraft:bricks":41,"minecraft:cobbled_deepslate":16,"minecraft:oak_planks":21,"minecraft:polished_diorite":47,"minecraft:sandstone":4,"minecraft:stone_bricks":31},"sha256":"4dc648ecb3198e80c4ac484a8a75149c0541ee54b6a04c5c6d9f9a2bc4b39915","size":{"x":32,"y":1,"z":32}},{"blockCount":82,"bytes":2887,"file":"chunks/y142-z192-x128.json","offset":{"x":128,"y":142,"z":192},"requirements":{"minecraft:bricks":6,"minecraft:cobbled_deepslate":18,"minecraft:oak_planks":18,"minecraft:polished_diorite":24,"minecraft:stone_bricks":16},"sha256":"b748c5fb2ef065ecce6e6f73bedf5b76922c32fe50df853e8362eb9decc26b98","size":{"x":32,"y":1,"z":32}},{"blockCount":197,"bytes":5726,"file":"chunks/y143-z064-x096.json","offset":{"x":96,"y":143,"z":64},"requirements":{"minecraft:bricks":59,"minecraft:cobbled_deepslate":23,"minecraft:glass":1,"minecraft:oak_planks":8,"minecraft:polished_diorite":60,"minecraft:sandstone":6,"minecraft:spruce_planks":3,"minecraft:stone_bricks":37},"sha256":"6e038823967c0e09ee55fab796345654853c6cf4dc7d4729e51966d5b2b76a03","size":{"x":32,"y":1,"z":32}},{"blockCount":79,"bytes":3109,"file":"chunks/y143-z064-x128.json","offset":{"x":128,"y":143,"z":64},"requirements":{"minecraft:cobbled_deepslate":24,"minecraft:glass":1,"minecraft:oak_planks":2,"minecraft:polished_diorite":37,"minecraft:spruce_planks":3,"minecraft:stone_bricks":12},"sha256":"d5e855cf33977244874e72edf6588f8ed103fd8f67775f61447cc183f3f35d5a","size":{"x":32,"y":1,"z":32}},{"blockCount":15,"bytes":960,"file":"chunks/y143-z064-x192.json","offset":{"x":192,"y":143,"z":64},"requirements":{"minecraft:polished_diorite":7,"minecraft:stone_bricks":8},"sha256":"9639f49f6973c8366ca806dbe20c75d128f07a54f86589b96aad5f41aea8f1a1","size":{"x":32,"y":1,"z":32}},{"blockCount":15,"bytes":961,"file":"chunks/y143-z064-x224.json","offset":{"x":224,"y":143,"z":64},"requirements":{"minecraft:polished_diorite":7,"minecraft:stone_bricks":8},"sha256":"480f6b2230109b7c9f79e8dc67cda52d6e785f1f7aae21119f067f163990c9e5","size":{"x":32,"y":1,"z":32}},{"blockCount":33,"bytes":1378,"file":"chunks/y143-z096-x032.json","offset":{"x":32,"y":143,"z":96},"requirements":{"minecraft:polished_diorite":33},"sha256":"4da05ea1f020d45cd7caad6e89846520b049fa9d4bcf9ee8ac5da44e47e89684","size":{"x":32,"y":1,"z":32}},{"blockCount":31,"bytes":1449,"file":"chunks/y143-z096-x064.json","offset":{"x":64,"y":143,"z":96},"requirements":{"minecraft:polished_diorite":31},"sha256":"c66a4e5d937f0006070f3ca8e834b1f2da55fe26bc8ca8436ee4a41074a9ebce","size":{"x":32,"y":1,"z":32}},{"blockCount":204,"bytes":6549,"file":"chunks/y143-z096-x096.json","offset":{"x":96,"y":143,"z":96},"requirements":{"minecraft:bricks":82,"minecraft:cobbled_deepslate":30,"minecraft:glass":2,"minecraft:oak_planks":10,"minecraft:polished_diorite":22,"minecraft:sandstone":6,"minecraft:spruce_planks":5,"minecraft:stone_bricks":47},"sha256":"e9732b9e71b4b3f010e23fc0f4d1f891a01ada7ea523b950862907cdfc1d7f9a","size":{"x":32,"y":1,"z":32}},{"blockCount":85,"bytes":3485,"file":"chunks/y143-z096-x128.json","offset":{"x":128,"y":143,"z":96},"requirements":{"minecraft:cobbled_deepslate":28,"minecraft:glass":2,"minecraft:polished_diorite":36,"minecraft:spruce_planks":5,"minecraft:stone_bricks":14},"sha256":"522b9c2a2e02b8e7147a240824990f95a88031e4e2b60115ff3f0c6050da0e8c","size":{"x":32,"y":1,"z":32}},{"blockCount":33,"bytes":1489,"file":"chunks/y143-z096-x160.json","offset":{"x":160,"y":143,"z":96},"requirements":{"minecraft:polished_diorite":33},"sha256":"af681eaa47fa98f0d4af7025f673de567b148505ef549cc2b5a810c4d63a891b","size":{"x":32,"y":1,"z":32}},{"blockCount":147,"bytes":3646,"file":"chunks/y143-z096-x192.json","offset":{"x":192,"y":143,"z":96},"requirements":{"minecraft:bricks":38,"minecraft:cobbled_deepslate":10,"minecraft:glass":7,"minecraft:polished_diorite":74,"minecraft:stone_bricks":18},"sha256":"2f1a4f745f94d4336c5f3d7a9380ca9b3789a91c58cc6b7c01052cc487c9f633","size":{"x":32,"y":1,"z":32}},{"blockCount":126,"bytes":3234,"file":"chunks/y143-z096-x224.json","offset":{"x":224,"y":143,"z":96},"requirements":{"minecraft:bricks":42,"minecraft:glass":11,"minecraft:polished_diorite":55,"minecraft:stone_bricks":18},"sha256":"43b99498ad2dae9e2b3f40b1e524ffd7ff2767dc648bfcfef21ca2dfc409d295","size":{"x":32,"y":1,"z":32}},{"blockCount":146,"bytes":3999,"file":"chunks/y143-z128-x032.json","offset":{"x":32,"y":143,"z":128},"requirements":{"minecraft:bricks":25,"minecraft:cobbled_deepslate":52,"minecraft:glass":2,"minecraft:oak_planks":4,"minecraft:polished_diorite":24,"minecraft:sandstone":3,"minecraft:spruce_planks":2,"minecraft:stone_bricks":34},"sha256":"222c722480ee6142a0cfa9c545f30b6fcc76f53ece15d39f8aefe8134c03dfc3","size":{"x":32,"y":1,"z":32}},{"blockCount":226,"bytes":4177,"file":"chunks/y143-z128-x064.json","offset":{"x":64,"y":143,"z":128},"requirements":{"minecraft:bricks":76,"minecraft:cobbled_deepslate":58,"minecraft:glass":2,"minecraft:oak_planks":10,"minecraft:polished_diorite":6,"minecraft:sandstone":4,"minecraft:spruce_planks":10,"minecraft:stone_bricks":60},"sha256":"9705612a13e01bc62e215ed05bd0d137502952f79b9bd54db607ee03cfae9abe","size":{"x":32,"y":1,"z":32}},{"blockCount":264,"bytes":6356,"file":"chunks/y143-z128-x096.json","offset":{"x":96,"y":143,"z":128},"requirements":{"minecraft:bricks":129,"minecraft:cobbled_deepslate":38,"minecraft:glass":3,"minecraft:oak_planks":8,"minecraft:sandstone":8,"minecraft:spruce_planks":7,"minecraft:stone_bricks":71},"sha256":"6d2227ce23bca1a2d51872bba226292987b3cef2568c8122729876d8f625ef8d","size":{"x":32,"y":1,"z":32}},{"blockCount":242,"bytes":4465,"file":"chunks/y143-z128-x128.json","offset":{"x":128,"y":143,"z":128},"requirements":{"minecraft:bricks":82,"minecraft:cobbled_deepslate":61,"minecraft:glass":5,"minecraft:oak_planks":10,"minecraft:polished_diorite":3,"minecraft:sandstone":4,"minecraft:spruce_planks":11,"minecraft:stone_bricks":66},"sha256":"0945418aeac8cf689c6716384ce9f868eedc5c43d36e46aa0aced800e7c6403d","size":{"x":32,"y":1,"z":32}},{"blockCount":225,"bytes":4199,"file":"chunks/y143-z128-x160.json","offset":{"x":160,"y":143,"z":128},"requirements":{"minecraft:bricks":74,"minecraft:cobbled_deepslate":58,"minecraft:glass":2,"minecraft:oak_planks":10,"minecraft:polished_diorite":7,"minecraft:sandstone":4,"minecraft:spruce_planks":10,"minecraft:stone_bricks":60},"sha256":"fe5aa842bdd20fae6e4db9a4078ade2a5d25bb782742a62a11ddd4f54667a755","size":{"x":32,"y":1,"z":32}},{"blockCount":256,"bytes":5420,"file":"chunks/y143-z128-x192.json","offset":{"x":192,"y":143,"z":128},"requirements":{"minecraft:bricks":74,"minecraft:cobbled_deepslate":67,"minecraft:glass":4,"minecraft:oak_planks":14,"minecraft:polished_diorite":13,"minecraft:sandstone":6,"minecraft:spruce_planks":16,"minecraft:stone_bricks":62},"sha256":"e44d8426fc9f6344ec66b7043fc217d8e4ac836e63ae0e47ce9edeb469fb88a7","size":{"x":32,"y":1,"z":32}},{"blockCount":82,"bytes":2457,"file":"chunks/y143-z128-x224.json","offset":{"x":224,"y":143,"z":128},"requirements":{"minecraft:bricks":9,"minecraft:cobbled_deepslate":6,"minecraft:oak_planks":4,"minecraft:polished_diorite":40,"minecraft:sandstone":4,"minecraft:stone_bricks":19},"sha256":"e23dfde1ecd1b0bc3918b8adfb97b39a223c6afbc8f607acbaf57127c692b057","size":{"x":32,"y":1,"z":32}},{"blockCount":19,"bytes":1108,"file":"chunks/y143-z160-x032.json","offset":{"x":32,"y":143,"z":160},"requirements":{"minecraft:polished_diorite":19},"sha256":"367c7fd47deeccd14311c3de5c52eb674c4d0997711a9f9ea498218def76eb23","size":{"x":32,"y":1,"z":32}},{"blockCount":25,"bytes":1352,"file":"chunks/y143-z160-x064.json","offset":{"x":64,"y":143,"z":160},"requirements":{"minecraft:polished_diorite":25},"sha256":"27f5b58e425caeb98933a39106a7196fe9d3a0b123489d6c9b72dcb960057284","size":{"x":32,"y":1,"z":32}},{"blockCount":200,"bytes":6474,"file":"chunks/y143-z160-x096.json","offset":{"x":96,"y":143,"z":160},"requirements":{"minecraft:bricks":81,"minecraft:cobbled_deepslate":30,"minecraft:glass":1,"minecraft:oak_planks":10,"minecraft:polished_diorite":27,"minecraft:sandstone":4,"minecraft:spruce_planks":5,"minecraft:stone_bricks":42},"sha256":"2ff0a65a834dc756664d18544b606eb872279a4c05805e5580b92990a6515559","size":{"x":32,"y":1,"z":32}},{"blockCount":89,"bytes":3637,"file":"chunks/y143-z160-x128.json","offset":{"x":128,"y":143,"z":160},"requirements":{"minecraft:cobbled_deepslate":30,"minecraft:glass":1,"minecraft:polished_diorite":38,"minecraft:spruce_planks":5,"minecraft:stone_bricks":15},"sha256":"222905244c6c65397b9c3fc91bf63554ee1eda702f06b55c7596a73c719702c5","size":{"x":32,"y":1,"z":32}},{"blockCount":26,"bytes":1372,"file":"chunks/y143-z160-x160.json","offset":{"x":160,"y":143,"z":160},"requirements":{"minecraft:polished_diorite":26},"sha256":"e849777733762ff7639b6a05ac0d3bc213d69e17993e24f8cd9a31e28b4cb240","size":{"x":32,"y":1,"z":32}},{"blockCount":129,"bytes":3251,"file":"chunks/y143-z160-x192.json","offset":{"x":192,"y":143,"z":160},"requirements":{"minecraft:bricks":38,"minecraft:glass":5,"minecraft:polished_diorite":68,"minecraft:stone_bricks":18},"sha256":"9baaf1adc81b0ecfae0e775b2e56481a04f46649703601b37ce90b2a8d212c03","size":{"x":32,"y":1,"z":32}},{"blockCount":126,"bytes":3235,"file":"chunks/y143-z160-x224.json","offset":{"x":224,"y":143,"z":160},"requirements":{"minecraft:bricks":42,"minecraft:glass":11,"minecraft:polished_diorite":55,"minecraft:stone_bricks":18},"sha256":"3b069af78d3e19ece0ffeb5a683ec2b0b7b562a3ee42ab114269176755beb0d9","size":{"x":32,"y":1,"z":32}},{"blockCount":157,"bytes":4597,"file":"chunks/y143-z192-x096.json","offset":{"x":96,"y":143,"z":192},"requirements":{"minecraft:bricks":41,"minecraft:cobbled_deepslate":16,"minecraft:glass":1,"minecraft:oak_planks":7,"minecraft:polished_diorite":55,"minecraft:sandstone":6,"minecraft:spruce_planks":2,"minecraft:stone_bricks":29},"sha256":"f057fe4dabfe83deca90f9dd18362e6add13d81f22d6a3d7c587af6c7f8c4587","size":{"x":32,"y":1,"z":32}},{"blockCount":63,"bytes":2551,"file":"chunks/y143-z192-x128.json","offset":{"x":128,"y":143,"z":192},"requirements":{"minecraft:cobbled_deepslate":18,"minecraft:glass":1,"minecraft:oak_planks":2,"minecraft:polished_diorite":32,"minecraft:spruce_planks":2,"minecraft:stone_bricks":8},"sha256":"c7030f068ea6daadaf64359b89d4e5c9a559696f5930e6b193bf618157f92dcf","size":{"x":32,"y":1,"z":32}},{"blockCount":219,"bytes":6080,"file":"chunks/y144-z064-x096.json","offset":{"x":96,"y":144,"z":64},"requirements":{"minecraft:bricks":56,"minecraft:cobbled_deepslate":25,"minecraft:glass":1,"minecraft:oak_planks":7,"minecraft:polished_diorite":38,"minecraft:sandstone":4,"minecraft:spruce_planks":7,"minecraft:stone_bricks":81},"sha256":"9b657142a41d3120116fdb567ba05ee366d4b60d321d49846f2849e448f4370a","size":{"x":32,"y":1,"z":32}},{"blockCount":79,"bytes":2862,"file":"chunks/y144-z064-x128.json","offset":{"x":128,"y":144,"z":64},"requirements":{"minecraft:cobbled_deepslate":24,"minecraft:glass":1,"minecraft:oak_planks":1,"minecraft:polished_diorite":15,"minecraft:spruce_planks":1,"minecraft:stone_bricks":37},"sha256":"70c5d7a405df3b87a4f252b4cdc7b72507873b37863652e2a395d18da6465843","size":{"x":32,"y":1,"z":32}},{"blockCount":17,"bytes":961,"file":"chunks/y144-z064-x192.json","offset":{"x":192,"y":144,"z":64},"requirements":{"minecraft:polished_diorite":7,"minecraft:stone_bricks":10},"sha256":"e91d21b2049d361648cb385d90634e431635abb4c93adce0432396677f25411a","size":{"x":32,"y":1,"z":32}},{"blockCount":17,"bytes":962,"file":"chunks/y144-z064-x224.json","offset":{"x":224,"y":144,"z":64},"requirements":{"minecraft:polished_diorite":7,"minecraft:stone_bricks":10},"sha256":"20ab09163112d2f90ecf2dd11345fe2b37da35eab03a30780137264948be40ae","size":{"x":32,"y":1,"z":32}},{"blockCount":41,"bytes":1594,"file":"chunks/y144-z096-x032.json","offset":{"x":32,"y":144,"z":96},"requirements":{"minecraft:polished_diorite":15,"minecraft:stone_bricks":26},"sha256":"9ed5a16a55858a2faff36b2e65faa00d276a6eed51282a8eddb8133e0557bc1d","size":{"x":32,"y":1,"z":32}},{"blockCount":41,"bytes":1702,"file":"chunks/y144-z096-x064.json","offset":{"x":64,"y":144,"z":96},"requirements":{"minecraft:polished_diorite":13,"minecraft:stone_bricks":28},"sha256":"101811927c744722ac4d0dc328e8b2aaeab310bb1512629cdda82c67e19f2a66","size":{"x":32,"y":1,"z":32}},{"blockCount":225,"bytes":6762,"file":"chunks/y144-z096-x096.json","offset":{"x":96,"y":144,"z":96},"requirements":{"minecraft:bricks":83,"minecraft:cobbled_deepslate":31,"minecraft:glass":2,"minecraft:oak_planks":10,"minecraft:polished_diorite":10,"minecraft:spruce_planks":12,"minecraft:stone_bricks":77},"sha256":"4663d51787e6fac08fb0e746dab7c13fb7c074ea97a3c2577e544175838a710e","size":{"x":32,"y":1,"z":32}},{"blockCount":86,"bytes":3142,"file":"chunks/y144-z096-x128.json","offset":{"x":128,"y":144,"z":96},"requirements":{"minecraft:cobbled_deepslate":31,"minecraft:glass":2,"minecraft:polished_diorite":16,"minecraft:spruce_planks":2,"minecraft:stone_bricks":35},"sha256":"fcf1ab2585511b0fc4e990d9cd6ff536b77e0386749826eac43c802ba61715df","size":{"x":32,"y":1,"z":32}},{"blockCount":43,"bytes":1665,"file":"chunks/y144-z096-x160.json","offset":{"x":160,"y":144,"z":96},"requirements":{"minecraft:polished_diorite":13,"minecraft:stone_bricks":30},"sha256":"8462d379c99d6cc714b3bf43129b3f255d1f049ccb114bd5053b9a3c732e3aa4","size":{"x":32,"y":1,"z":32}},{"blockCount":153,"bytes":3795,"file":"chunks/y144-z096-x192.json","offset":{"x":192,"y":144,"z":96},"requirements":{"minecraft:bricks":36,"minecraft:cobbled_deepslate":7,"minecraft:glass":9,"minecraft:polished_diorite":58,"minecraft:stone_bricks":43},"sha256":"caf19310c04ae0272ca0900ae436c27ff5d3689a0645472caa87c073883532de","size":{"x":32,"y":1,"z":32}},{"blockCount":126,"bytes":3158,"file":"chunks/y144-z096-x224.json","offset":{"x":224,"y":144,"z":96},"requirements":{"minecraft:bricks":36,"minecraft:glass":17,"minecraft:polished_diorite":49,"minecraft:stone_bricks":24},"sha256":"a33a647c8718be2d9d373fe85446b3597c3a85bd441ad5452b30254bdf6f4338","size":{"x":32,"y":1,"z":32}},{"blockCount":322,"bytes":4019,"file":"chunks/y144-z128-x032.json","offset":{"x":32,"y":144,"z":128},"requirements":{"minecraft:bricks":23,"minecraft:cobbled_deepslate":196,"minecraft:glass":2,"minecraft:oak_planks":4,"minecraft:polished_diorite":8,"minecraft:sandstone":1,"minecraft:spruce_planks":4,"minecraft:stone_bricks":84},"sha256":"9ee9b0be6a3aab515e41fafa97ba50acef991887a6f809abf4e170a065234788","size":{"x":32,"y":1,"z":32}},{"blockCount":235,"bytes":4362,"file":"chunks/y144-z128-x064.json","offset":{"x":64,"y":144,"z":128},"requirements":{"minecraft:bricks":78,"minecraft:cobbled_deepslate":61,"minecraft:glass":2,"minecraft:oak_planks":10,"minecraft:polished_diorite":2,"minecraft:spruce_planks":12,"minecraft:stone_bricks":70},"sha256":"df78dbc1410f328c88c3549e92d8a68fcda71be4f6ad24d4cf793ee17b69b8bd","size":{"x":32,"y":1,"z":32}},{"blockCount":293,"bytes":6686,"file":"chunks/y144-z128-x096.json","offset":{"x":96,"y":144,"z":128},"requirements":{"minecraft:bricks":141,"minecraft:cobbled_deepslate":42,"minecraft:glass":3,"minecraft:oak_planks":10,"minecraft:spruce_planks":11,"minecraft:stone_bricks":86},"sha256":"5dc17e3230e44309ece4f175649a66ff9bbf717a08399f096588e99a4056bc1d","size":{"x":32,"y":1,"z":32}},{"blockCount":256,"bytes":4652,"file":"chunks/y144-z128-x128.json","offset":{"x":128,"y":144,"z":128},"requirements":{"minecraft:bricks":82,"minecraft:cobbled_deepslate":69,"minecraft:glass":5,"minecraft:oak_planks":8,"minecraft:polished_diorite":1,"minecraft:spruce_planks":15,"minecraft:stone_bricks":76},"sha256":"e05583ca90ac0639320ee5fcfacdd0db75fb4345b2eabc812e934de9f107c8a6","size":{"x":32,"y":1,"z":32}},{"blockCount":234,"bytes":4476,"file":"chunks/y144-z128-x160.json","offset":{"x":160,"y":144,"z":128},"requirements":{"minecraft:bricks":76,"minecraft:cobbled_deepslate":56,"minecraft:glass":2,"minecraft:oak_planks":10,"minecraft:polished_diorite":2,"minecraft:spruce_planks":12,"minecraft:stone_bricks":76},"sha256":"9b68eb7976cbc1dc2c864dfe0d9a4f1c9302f596e11f0c86e75d36f9a8d1c4d9","size":{"x":32,"y":1,"z":32}},{"blockCount":267,"bytes":5545,"file":"chunks/y144-z128-x192.json","offset":{"x":192,"y":144,"z":128},"requirements":{"minecraft:bricks":77,"minecraft:cobbled_deepslate":69,"minecraft:glass":4,"minecraft:oak_planks":18,"minecraft:polished_diorite":8,"minecraft:spruce_planks":18,"minecraft:stone_bricks":73},"sha256":"cd1a6a8b20d82307c47b501aaac0da3e259d21a95e18401a2baf5184af254880","size":{"x":32,"y":1,"z":32}},{"blockCount":80,"bytes":2324,"file":"chunks/y144-z128-x224.json","offset":{"x":224,"y":144,"z":128},"requirements":{"minecraft:bricks":7,"minecraft:cobbled_deepslate":8,"minecraft:oak_planks":2,"minecraft:polished_diorite":36,"minecraft:sandstone":4,"minecraft:stone_bricks":23},"sha256":"72eb633f81a10e439ab8364191e0abc618054a11740060db09f39ae6e749e3e2","size":{"x":32,"y":1,"z":32}},{"blockCount":22,"bytes":1210,"file":"chunks/y144-z160-x032.json","offset":{"x":32,"y":144,"z":160},"requirements":{"minecraft:polished_diorite":9,"minecraft:stone_bricks":13},"sha256":"44f356ea9744e0a811177c85260f3626274ab79aef3f946bd535def73197c6e1","size":{"x":32,"y":1,"z":32}},{"blockCount":30,"bytes":1492,"file":"chunks/y144-z160-x064.json","offset":{"x":64,"y":144,"z":160},"requirements":{"minecraft:polished_diorite":11,"minecraft:stone_bricks":19},"sha256":"398b84cf0dbd92a28567c7c43448757eae422d0616c5d89397859635b506b17a","size":{"x":32,"y":1,"z":32}},{"blockCount":226,"bytes":6821,"file":"chunks/y144-z160-x096.json","offset":{"x":96,"y":144,"z":160},"requirements":{"minecraft:bricks":80,"minecraft:cobbled_deepslate":31,"minecraft:glass":1,"minecraft:oak_planks":10,"minecraft:polished_diorite":11,"minecraft:spruce_planks":11,"minecraft:stone_bricks":82},"sha256":"53c057430ba3cf77ce36c5987aafafcea261f44046cbf87fbd91c930b4564ca4","size":{"x":32,"y":1,"z":32}},{"blockCount":84,"bytes":3200,"file":"chunks/y144-z160-x128.json","offset":{"x":128,"y":144,"z":160},"requirements":{"minecraft:cobbled_deepslate":29,"minecraft:glass":1,"minecraft:polished_diorite":16,"minecraft:spruce_planks":1,"minecraft:stone_bricks":37},"sha256":"f0f6810d80583738a171985da0b67754b15af5fb6bcd0150c593f64e8b072a6e","size":{"x":32,"y":1,"z":32}},{"blockCount":31,"bytes":1474,"file":"chunks/y144-z160-x160.json","offset":{"x":160,"y":144,"z":160},"requirements":{"minecraft:polished_diorite":11,"minecraft:stone_bricks":20},"sha256":"d6b393f6436951f19a2dbb4f9b5534bc1219f7cacd253a2ed291c50e47238cf7","size":{"x":32,"y":1,"z":32}},{"blockCount":136,"bytes":3421,"file":"chunks/y144-z160-x192.json","offset":{"x":192,"y":144,"z":160},"requirements":{"minecraft:bricks":36,"minecraft:glass":7,"minecraft:polished_diorite":57,"minecraft:stone_bricks":36},"sha256":"c6a96bb5a7b04c1356aa09a8b15cd0393c834183589ef3b94a60247d3c8edfcf","size":{"x":32,"y":1,"z":32}},{"blockCount":126,"bytes":3159,"file":"chunks/y144-z160-x224.json","offset":{"x":224,"y":144,"z":160},"requirements":{"minecraft:bricks":36,"minecraft:glass":17,"minecraft:polished_diorite":49,"minecraft:stone_bricks":24},"sha256":"1d81802fc380f3583c70a14ba643780947f740fc6a4c42669d12aa968a91b51b","size":{"x":32,"y":1,"z":32}},{"blockCount":172,"bytes":4763,"file":"chunks/y144-z192-x096.json","offset":{"x":96,"y":144,"z":192},"requirements":{"minecraft:bricks":40,"minecraft:cobbled_deepslate":19,"minecraft:glass":1,"minecraft:oak_planks":5,"minecraft:polished_diorite":37,"minecraft:sandstone":4,"minecraft:spruce_planks":5,"minecraft:stone_bricks":61},"sha256":"924f3b054f49b6466a82ce3a4969fbd6e969556dd90724d1f1140b66cc88aae4","size":{"x":32,"y":1,"z":32}},{"blockCount":65,"bytes":2438,"file":"chunks/y144-z192-x128.json","offset":{"x":128,"y":144,"z":192},"requirements":{"minecraft:cobbled_deepslate":16,"minecraft:glass":1,"minecraft:oak_planks":1,"minecraft:polished_diorite":14,"minecraft:spruce_planks":1,"minecraft:stone_bricks":32},"sha256":"ba4faca3605134d66a6d38011c75d771fd79ffb200fd4b753c3b12e92261381e","size":{"x":32,"y":1,"z":32}},{"blockCount":205,"bytes":6114,"file":"chunks/y145-z064-x096.json","offset":{"x":96,"y":145,"z":64},"requirements":{"minecraft:bricks":51,"minecraft:cobbled_deepslate":25,"minecraft:glass":2,"minecraft:oak_planks":7,"minecraft:polished_diorite":50,"minecraft:sandstone":5,"minecraft:spruce_planks":8,"minecraft:stone_bricks":57},"sha256":"e581d20576bc47994a1b0f636b711238be0dae41506536a7b038ac7de74d89e2","size":{"x":32,"y":1,"z":32}},{"blockCount":69,"bytes":2894,"file":"chunks/y145-z064-x128.json","offset":{"x":128,"y":145,"z":64},"requirements":{"minecraft:cobbled_deepslate":22,"minecraft:glass":1,"minecraft:oak_planks":1,"minecraft:polished_diorite":27,"minecraft:stone_bricks":18},"sha256":"fbdbd4db5372cf080dd358d28d75e1932b5ede329d339e181d3b8cedc720fd21","size":{"x":32,"y":1,"z":32}},{"blockCount":13,"bytes":922,"file":"chunks/y145-z064-x192.json","offset":{"x":192,"y":145,"z":64},"requirements":{"minecraft:polished_diorite":7,"minecraft:stone_bricks":6},"sha256":"39510a43b6818beb03095cedab5b250795eda200fafd06b76663d92559bcc283","size":{"x":32,"y":1,"z":32}},{"blockCount":13,"bytes":923,"file":"chunks/y145-z064-x224.json","offset":{"x":224,"y":145,"z":64},"requirements":{"minecraft:polished_diorite":7,"minecraft:stone_bricks":6},"sha256":"0d2b5347d8eb790f35757455d5ab2a3ddd1321933e69556817beea9d7601e9a6","size":{"x":32,"y":1,"z":32}},{"blockCount":33,"bytes":1653,"file":"chunks/y145-z096-x032.json","offset":{"x":32,"y":145,"z":96},"requirements":{"minecraft:polished_diorite":23,"minecraft:stone_bricks":10},"sha256":"12b3e67710d3d81231b7c9882806e8427bda358fd6732fb9c2fb82e14df84cc9","size":{"x":32,"y":1,"z":32}},{"blockCount":31,"bytes":1647,"file":"chunks/y145-z096-x064.json","offset":{"x":64,"y":145,"z":96},"requirements":{"minecraft:polished_diorite":22,"minecraft:stone_bricks":9},"sha256":"0b5e07d46a9d621ea4cc1838f293c71a4bfb77a72a00901c8da7cb85b21c92e6","size":{"x":32,"y":1,"z":32}},{"blockCount":219,"bytes":6971,"file":"chunks/y145-z096-x096.json","offset":{"x":96,"y":145,"z":96},"requirements":{"minecraft:bricks":76,"minecraft:cobbled_deepslate":27,"minecraft:glass":8,"minecraft:oak_planks":10,"minecraft:polished_diorite":15,"minecraft:sandstone":3,"minecraft:spruce_planks":10,"minecraft:stone_bricks":70},"sha256":"313dac81c751378ad2136a6e199ec36c6215049b3362347763340e39c3bd91c1","size":{"x":32,"y":1,"z":32}},{"blockCount":74,"bytes":3155,"file":"chunks/y145-z096-x128.json","offset":{"x":128,"y":145,"z":96},"requirements":{"minecraft:cobbled_deepslate":33,"minecraft:glass":2,"minecraft:polished_diorite":25,"minecraft:stone_bricks":14},"sha256":"72835e505674de110d71435808f5b9aa2f194bb1a61fb38046c2bd0202d16688","size":{"x":32,"y":1,"z":32}},{"blockCount":33,"bytes":1706,"file":"chunks/y145-z096-x160.json","offset":{"x":160,"y":145,"z":96},"requirements":{"minecraft:polished_diorite":24,"minecraft:stone_bricks":9},"sha256":"126f6cd02cc34a0c8965aec777a177d9e7707bdd93033bad71293d147b42bb01","size":{"x":32,"y":1,"z":32}},{"blockCount":140,"bytes":3645,"file":"chunks/y145-z096-x192.json","offset":{"x":192,"y":145,"z":96},"requirements":{"minecraft:bricks":38,"minecraft:cobbled_deepslate":4,"minecraft:glass":7,"minecraft:polished_diorite":67,"minecraft:stone_bricks":24},"sha256":"f9ade46400f7154c2dd497232fe1d57c737e74ff06f87b97ab04210d1bcc4cbc","size":{"x":32,"y":1,"z":32}},{"blockCount":126,"bytes":3196,"file":"chunks/y145-z096-x224.json","offset":{"x":224,"y":145,"z":96},"requirements":{"minecraft:bricks":42,"minecraft:glass":11,"minecraft:polished_diorite":55,"minecraft:stone_bricks":18},"sha256":"3b59a3ac7ceb2914f10ef000c1fcc8ecd48d5b077d980141cf36d5455543cb4c","size":{"x":32,"y":1,"z":32}},{"blockCount":165,"bytes":4091,"file":"chunks/y145-z128-x032.json","offset":{"x":32,"y":145,"z":128},"requirements":{"minecraft:bricks":13,"minecraft:cobbled_deepslate":41,"minecraft:glass":6,"minecraft:oak_planks":7,"minecraft:polished_diorite":17,"minecraft:sandstone":1,"minecraft:spruce_planks":4,"minecraft:stone_bricks":76},"sha256":"f28864365840849bc03dfdeda6b7c247dc8bca2d74a89f828bcd6372221304a7","size":{"x":32,"y":1,"z":32}},{"blockCount":224,"bytes":4194,"file":"chunks/y145-z128-x064.json","offset":{"x":64,"y":145,"z":128},"requirements":{"minecraft:bricks":72,"minecraft:cobbled_deepslate":61,"minecraft:glass":2,"minecraft:oak_planks":10,"minecraft:polished_diorite":4,"minecraft:sandstone":2,"minecraft:spruce_planks":10,"minecraft:stone_bricks":63},"sha256":"74c476e08cec6cfd66c35d52f33fefbd2ea3e83a8e25e3f9f5fd2faa79806834","size":{"x":32,"y":1,"z":32}},{"blockCount":292,"bytes":7031,"file":"chunks/y145-z128-x096.json","offset":{"x":96,"y":145,"z":128},"requirements":{"minecraft:bricks":131,"minecraft:cobbled_deepslate":41,"minecraft:glass":5,"minecraft:oak_planks":10,"minecraft:sandstone":2,"minecraft:spruce_planks":10,"minecraft:stone_bricks":93},"sha256":"e7b56c962b6f6efbcf7f0e9db156be7ed30c34d80fecd8eeb7994b99a0132759","size":{"x":32,"y":1,"z":32}},{"blockCount":243,"bytes":4461,"file":"chunks/y145-z128-x128.json","offset":{"x":128,"y":145,"z":128},"requirements":{"minecraft:bricks":76,"minecraft:cobbled_deepslate":70,"minecraft:glass":5,"minecraft:oak_planks":8,"minecraft:polished_diorite":2,"minecraft:sandstone":2,"minecraft:spruce_planks":8,"minecraft:stone_bricks":72},"sha256":"92638463321c6a75b96858d70718d735f9f1dc39959ecec15bb685032b9e1be1","size":{"x":32,"y":1,"z":32}},{"blockCount":223,"bytes":4421,"file":"chunks/y145-z128-x160.json","offset":{"x":160,"y":145,"z":128},"requirements":{"minecraft:bricks":70,"minecraft:cobbled_deepslate":54,"minecraft:glass":2,"minecraft:oak_planks":10,"minecraft:polished_diorite":5,"minecraft:sandstone":2,"minecraft:spruce_planks":10,"minecraft:stone_bricks":70},"sha256":"b5454800afdb343424eea9f7c44abe5d3d311178a4374314a45637d4634be591","size":{"x":32,"y":1,"z":32}},{"blockCount":260,"bytes":5320,"file":"chunks/y145-z128-x192.json","offset":{"x":192,"y":145,"z":128},"requirements":{"minecraft:bricks":68,"minecraft:cobbled_deepslate":70,"minecraft:glass":4,"minecraft:oak_planks":18,"minecraft:polished_diorite":11,"minecraft:sandstone":3,"minecraft:spruce_planks":20,"minecraft:stone_bricks":66},"sha256":"9fd61541699dd9611dad5d1fd782b03e4de50e7f7fdb730b1c775f5e416d0834","size":{"x":32,"y":1,"z":32}},{"blockCount":77,"bytes":2410,"file":"chunks/y145-z128-x224.json","offset":{"x":224,"y":145,"z":128},"requirements":{"minecraft:bricks":5,"minecraft:cobbled_deepslate":6,"minecraft:oak_planks":2,"minecraft:polished_diorite":38,"minecraft:sandstone":4,"minecraft:spruce_planks":2,"minecraft:stone_bricks":20},"sha256":"bdf7fb591533e8c9fa17e8f22cc421aaa6d9be7afb4984cec5bb9c1c48b37cf8","size":{"x":32,"y":1,"z":32}},{"blockCount":19,"bytes":1249,"file":"chunks/y145-z160-x032.json","offset":{"x":32,"y":145,"z":160},"requirements":{"minecraft:polished_diorite":14,"minecraft:stone_bricks":5},"sha256":"47ba2faf943b227eea9c614d4c0f9f79b8cd9fcf7853ad517de1b3409e47b11c","size":{"x":32,"y":1,"z":32}}],"schema":1}
