{"entries":[{"blockCount":25,"bytes":1474,"file":"chunks/y145-z160-x064.json","offset":{"x":64,"y":145,"z":160},"requirements":{"minecraft:polished_diorite":18,"minecraft:stone_bricks":7},"sha256":"69e8e99a7497debeabd63604f2efe675a1ff71b801bf2dfc97a78b79a38fb929","size":{"x":32,"y":1,"z":32}},{"blockCount":218,"bytes":6971,"file":"chunks/y145-z160-x096.json","offset":{"x":96,"y":145,"z":160},"requirements":{"minecraft:bricks":76,"minecraft:cobbled_deepslate":30,"minecraft:glass":5,"minecraft:oak_planks":10,"minecraft:polished_diorite":19,"minecraft:sandstone":2,"minecraft:spruce_planks":10,"minecraft:stone_bricks":66},"sha256":"8b6dcf6dd1830449be49c286b2a7e113e073cc50a8fdd4888a46f231c028f1f3","size":{"x":32,"y":1,"z":32}},{"blockCount":73,"bytes":3195,"file":"chunks/y145-z160-x128.json","offset":{"x":128,"y":145,"z":160},"requirements":{"minecraft:cobbled_deepslate":32,"minecraft:glass":1,"minecraft:polished_diorite":27,"minecraft:stone_bricks":13},"sha256":"3e151eb01a56a54a91e0580667384f2030d0afc02e72b7d20d9dd5b3adc14972","size":{"x":32,"y":1,"z":32}},{"blockCount":26,"bytes":1513,"file":"chunks/y145-z160-x160.json","offset":{"x":160,"y":145,"z":160},"requirements":{"minecraft:polished_diorite":19,"minecraft:stone_bricks":7},"sha256":"1c90f3560c1ed489d2dd3754ebd6bca12f4dbd73f6cb182d3c6394c2ac3283bf","size":{"x":32,"y":1,"z":32}},{"blockCount":129,"bytes":3308,"file":"chunks/y145-z160-x192.json","offset":{"x":192,"y":145,"z":160},"requirements":{"minecraft:bricks":38,"minecraft:glass":5,"minecraft:polished_diorite":63,"minecraft:stone_bricks":23},"sha256":"d8366fe805a8b81a92c3a5b175bded16544710af39fccbb61d9b5b85a5e9afdf","size":{"x":32,"y":1,"z":32}},{"blockCount":126,"bytes":3197,"file":"chunks/y145-z160-x224.json","offset":{"x":224,"y":145,"z":160},"requirements":{"minecraft:bricks":42,"minecraft:glass":11,"minecraft:polished_diorite":55,"minecraft:stone_bricks":18},"sha256":"c228d9e0e8169a913c0b8ec4f8d2f75b1986edd3d2ddf90e70b438f996189bdf","size":{"x":32,"y":1,"z":32}},{"blockCount":161,"bytes":4799,"file":"chunks/y145-z192-x096.json","offset":{"x":96,"y":145,"z":192},"requirements":{"minecraft:bricks":35,"minecraft:cobbled_deepslate":17,"minecraft:glass":2,"minecraft:oak_planks":5,"minecraft:polished_diorite":46,"minecraft:sandstone":5,"minecraft:spruce_planks":6,"minecraft:stone_bricks":45},"sha256":"86c8b16e78e7466e24ac92317a9ed8da13aaf92bee00804e4c0872c58eed6d1d","size":{"x":32,"y":1,"z":32}},{"blockCount":57,"bytes":2450,"file":"chunks/y145-z192-x128.json","offset":{"x":128,"y":145,"z":192},"requirements":{"minecraft:cobbled_deepslate":17,"minecraft:glass":1,"minecraft:oak_planks":1,"minecraft:polished_diorite":23,"minecraft:stone_bricks":15},"sha256":"779787869443e0db5e8e2c85d150b5d8a3c7cae4a6b2ddfecae501f3ec51576e","size":{"x":32,"y":1,"z":32}},{"blockCount":202,"bytes":5460,"file":"chunks/y146-z064-x096.json","offset":{"x":96,"y":146,"z":64},"requirements":{"minecraft:bricks":46,"minecraft:cobbled_deepslate":27,"minecraft:oak_planks":14,"minecraft:polished_diorite":60,"minecraft:sandstone":4,"minecraft:stone_bricks":51},"sha256":"06b3cc7adf9e6f7ff1e3801dbd8025d3c0195d3f1befd65cac3a54e5e5ae7684","size":{"x":32,"y":1,"z":32}},{"blockCount":69,"bytes":2545,"file":"chunks/y146-z064-x128.json","offset":{"x":128,"y":146,"z":64},"requirements":{"minecraft:cobbled_deepslate":28,"minecraft:polished_diorite":33,"minecraft:stone_bricks":8},"sha256":"f765c7bd4c3ff818fef1945739386fd6e8ee0c1a80d4f4d343c3347dd629d6ad","size":{"x":32,"y":1,"z":32}},{"blockCount":13,"bytes":883,"file":"chunks/y146-z064-x192.json","offset":{"x":192,"y":146,"z":64},"requirements":{"minecraft:polished_diorite":8,"minecraft:stone_bricks":5},"sha256":"470f2a7c82a61a587ac1fa760e4e73d4ee7b8093c0d0c28d1ac10c99415a7f02","size":{"x":32,"y":1,"z":32}},{"blockCount":13,"bytes":903,"file":"chunks/y146-z064-x224.json","offset":{"x":224,"y":146,"z":64},"requirements":{"minecraft:polished_diorite":8,"minecraft:stone_bricks":5},"sha256":"bfd9dcee5854c9a03b7b7fde79031aefb44e3e07699dad3a41aeb2310b9d26c5","size":{"x":32,"y":1,"z":32}},{"blockCount":33,"bytes":1378,"file":"chunks/y146-z096-x032.json","offset":{"x":32,"y":146,"z":96},"requirements":{"minecraft:polished_diorite":33},"sha256":"717842dcd08251153dfb1995f605268e72092eeffa431cad2c8dc155d810f8f9","size":{"x":32,"y":1,"z":32}},{"blockCount":31,"bytes":1449,"file":"chunks/y146-z096-x064.json","offset":{"x":64,"y":146,"z":96},"requirements":{"minecraft:polished_diorite":31},"sha256":"bae4b637eb03b36a41e374ef26bd604f029af25a0290cdc1f0be24c0a442b93d","size":{"x":32,"y":1,"z":32}},{"blockCount":209,"bytes":6029,"file":"chunks/y146-z096-x096.json","offset":{"x":96,"y":146,"z":96},"requirements":{"minecraft:bricks":69,"minecraft:cobbled_deepslate":41,"minecraft:oak_planks":20,"minecraft:polished_diorite":22,"minecraft:stone_bricks":57},"sha256":"b6c1258ebbe5065d4d57801797bb641d9e14fffcbe646cf22da6542a4fef8d5c","size":{"x":32,"y":1,"z":32}},{"blockCount":80,"bytes":2816,"file":"chunks/y146-z096-x128.json","offset":{"x":128,"y":146,"z":96},"requirements":{"minecraft:cobbled_deepslate":43,"minecraft:polished_diorite":36,"minecraft:stone_bricks":1},"sha256":"9c0933a4173d63ab5e7c60f2d04d2dc80bebd61255fdf6e84975eba43da64789","size":{"x":32,"y":1,"z":32}},{"blockCount":33,"bytes":1489,"file":"chunks/y146-z096-x160.json","offset":{"x":160,"y":146,"z":96},"requirements":{"minecraft:polished_diorite":33},"sha256":"297ccf1ace3549a188a36776f63429f7d0dd6ae25a83c50365c9b2d6ba79727a","size":{"x":32,"y":1,"z":32}},{"blockCount":135,"bytes":3377,"file":"chunks/y146-z096-x192.json","offset":{"x":192,"y":146,"z":96},"requirements":{"minecraft:bricks":37,"minecraft:cobbled_deepslate":1,"minecraft:glass":8,"minecraft:polished_diorite":74,"minecraft:stone_bricks":15},"sha256":"b7017a52903cc733115a231694822353001f3e5363432e6fa6e11eb9e4914f3e","size":{"x":32,"y":1,"z":32}},{"blockCount":121,"bytes":3005,"file":"chunks/y146-z096-x224.json","offset":{"x":224,"y":146,"z":96},"requirements":{"minecraft:bricks":39,"minecraft:glass":14,"minecraft:polished_diorite":53,"minecraft:stone_bricks":15},"sha256":"39cf576db3f579a559495d7270e598960df0dfc1b5ddf03799435d6b61b73ec5","size":{"x":32,"y":1,"z":32}},{"blockCount":156,"bytes":3246,"file":"chunks/y146-z128-x032.json","offset":{"x":32,"y":146,"z":128},"requirements":{"minecraft:bricks":5,"minecraft:cobbled_deepslate":56,"minecraft:glass":4,"minecraft:oak_planks":8,"minecraft:polished_diorite":24,"minecraft:spruce_planks":2,"minecraft:stone_bricks":57},"sha256":"3cfa346c5d0aa07bfdd939f3233d4a2d3a76b7a390c598d2f6c7225b88420d82","size":{"x":32,"y":1,"z":32}},{"blockCount":224,"bytes":3868,"file":"chunks/y146-z128-x064.json","offset":{"x":64,"y":146,"z":128},"requirements":{"minecraft:bricks":68,"minecraft:cobbled_deepslate":65,"minecraft:oak_planks":20,"minecraft:polished_diorite":6,"minecraft:stone_bricks":65},"sha256":"5f6f8c6c2893771b137da583f67126eac7873a8af12d40c8dab56f9416e94764","size":{"x":32,"y":1,"z":32}},{"blockCount":314,"bytes":6520,"file":"chunks/y146-z128-x096.json","offset":{"x":96,"y":146,"z":128},"requirements":{"minecraft:bricks":129,"minecraft:cobbled_deepslate":61,"minecraft:oak_planks":16,"minecraft:sandstone":4,"minecraft:spruce_planks":4,"minecraft:stone_bricks":100},"sha256":"ef437877685fab29a65f48fa1a9d2d5ad10a8f3690c28d82ae517f49212d9eb1","size":{"x":32,"y":1,"z":32}},{"blockCount":255,"bytes":3596,"file":"chunks/y146-z128-x128.json","offset":{"x":128,"y":146,"z":128},"requirements":{"minecraft:bricks":70,"minecraft:cobbled_deepslate":101,"minecraft:oak_planks":16,"minecraft:polished_diorite":3,"minecraft:stone_bricks":65},"sha256":"780e3b2e110233f46a6e5907389d36e1fe5dd16865cdd621c916c1bcbf836e0c","size":{"x":32,"y":1,"z":32}},{"blockCount":222,"bytes":3775,"file":"chunks/y146-z128-x160.json","offset":{"x":160,"y":146,"z":128},"requirements":{"minecraft:bricks":65,"minecraft:cobbled_deepslate":67,"minecraft:oak_planks":20,"minecraft:polished_diorite":7,"minecraft:stone_bricks":63},"sha256":"85e755a79928920ad2c59bd19a190e6019d79bbf29ee5881086d53e454f90c8b","size":{"x":32,"y":1,"z":32}},{"blockCount":259,"bytes":4760,"file":"chunks/y146-z128-x192.json","offset":{"x":192,"y":146,"z":128},"requirements":{"minecraft:bricks":63,"minecraft:cobbled_deepslate":85,"minecraft:glass":2,"minecraft:oak_planks":26,"minecraft:polished_diorite":14,"minecraft:spruce_planks":10,"minecraft:stone_bricks":59},"sha256":"926dd6db149e6d58aa84e1bedfa50fffcd928114ce6d8ff009ce1782636c4d44","size":{"x":32,"y":1,"z":32}},{"blockCount":73,"bytes":2151,"file":"chunks/y146-z128-x224.json","offset":{"x":224,"y":146,"z":128},"requirements":{"minecraft:bricks":3,"minecraft:cobbled_deepslate":8,"minecraft:oak_planks":2,"minecraft:polished_diorite":37,"minecraft:sandstone":4,"minecraft:stone_bricks":19},"sha256":"5d49d5d1c06d73dc922b2c97a746076027dfd90a9b81a5a9443c88b30d86ecaa","size":{"x":32,"y":1,"z":32}},{"blockCount":19,"bytes":1108,"file":"chunks/y146-z160-x032.json","offset":{"x":32,"y":146,"z":160},"requirements":{"minecraft:polished_diorite":19},"sha256":"7c1b57e0c6314fd8dcd1896babcaacc61e5a5ced1f4e64b48b42703215e1e511","size":{"x":32,"y":1,"z":32}},{"blockCount":25,"bytes":1352,"file":"chunks/y146-z160-x064.json","offset":{"x":64,"y":146,"z":160},"requirements":{"minecraft:polished_diorite":25},"sha256":"ee425ee324478cdf0763aced03b7613edbd1140d5f03767847d6dd49e11af50e","size":{"x":32,"y":1,"z":32}},{"blockCount":209,"bytes":6201,"file":"chunks/y146-z160-x096.json","offset":{"x":96,"y":146,"z":160},"requirements":{"minecraft:bricks":70,"minecraft:cobbled_deepslate":37,"minecraft:oak_planks":20,"minecraft:polished_diorite":27,"minecraft:stone_bricks":55},"sha256":"005dc4371f65dae5678142982fd24cabac19cf4326e4738e3cb361dfef12ed06","size":{"x":32,"y":1,"z":32}},{"blockCount":76,"bytes":2895,"file":"chunks/y146-z160-x128.json","offset":{"x":128,"y":146,"z":160},"requirements":{"minecraft:cobbled_deepslate":35,"minecraft:polished_diorite":38,"minecraft:stone_bricks":3},"sha256":"3c67cb7eab9ea3f9e6d3ca5e03301092dec97a0fac7c210edf0c919520650d4a","size":{"x":32,"y":1,"z":32}},{"blockCount":26,"bytes":1372,"file":"chunks/y146-z160-x160.json","offset":{"x":160,"y":146,"z":160},"requirements":{"minecraft:polished_diorite":26},"sha256":"00fc97420decd6fd652c5801812d2ed2a11e3b65de90e122a8ef09ae447b31a1","size":{"x":32,"y":1,"z":32}},{"blockCount":126,"bytes":3136,"file":"chunks/y146-z160-x192.json","offset":{"x":192,"y":146,"z":160},"requirements":{"minecraft:bricks":37,"minecraft:glass":6,"minecraft:polished_diorite":68,"minecraft:stone_bricks":15},"sha256":"27e88e2c40fa73896d41b9a17ea7543862fe466df7bfd00b440645590009b1b9","size":{"x":32,"y":1,"z":32}},{"blockCount":121,"bytes":3006,"file":"chunks/y146-z160-x224.json","offset":{"x":224,"y":146,"z":160},"requirements":{"minecraft:bricks":39,"minecraft:glass":14,"minecraft:polished_diorite":53,"minecraft:stone_bricks":15},"sha256":"bdd983345dd6a7ee523e6bd9ac3ab89116d62e8fbd7cfd11fca7d0aedbc7fc98","size":{"x":32,"y":1,"z":32}},{"blockCount":159,"bytes":4258,"file":"chunks/y146-z192-x096.json","offset":{"x":96,"y":146,"z":192},"requirements":{"minecraft:bricks":31,"minecraft:cobbled_deepslate":24,"minecraft:oak_planks":10,"minecraft:polished_diorite":55,"minecraft:sandstone":4,"minecraft:stone_bricks":35},"sha256":"4f05e256b409918655f6ee26bf6046c6310a712610a2b06b226fa8b315b3027f","size":{"x":32,"y":1,"z":32}},{"blockCount":57,"bytes":2157,"file":"chunks/y146-z192-x128.json","offset":{"x":128,"y":146,"z":192},"requirements":{"minecraft:cobbled_deepslate":23,"minecraft:polished_diorite":28,"minecraft:stone_bricks":6},"sha256":"ffecb2826d2ffa109b9a86897685babd3b1fc6b58de7863c5d72bba848f9fdf7","size":{"x":32,"y":1,"z":32}},{"blockCount":247,"bytes":7222,"file":"chunks/y147-z064-x096.json","offset":{"x":96,"y":147,"z":64},"requirements":{"minecraft:bricks":39,"minecraft:cobbled_deepslate":24,"minecraft:glass":44,"minecraft:oak_planks":14,"minecraft:polished_diorite":58,"minecraft:sandstone":3,"minecraft:spruce_planks":8,"minecraft:stone_bricks":57},"sha256":"42a4ba681a79e12886dfecc6e2cbfd4bb6d7bc12a05679ae8ad5444119f4a88f","size":{"x":32,"y":1,"z":32}},{"blockCount":72,"bytes":2700,"file":"chunks/y147-z064-x128.json","offset":{"x":128,"y":147,"z":64},"requirements":{"minecraft:cobbled_deepslate":24,"minecraft:polished_diorite":33,"minecraft:stone_bricks":15},"sha256":"c81783b9a92478dbbf45a923ca0923e5d3eb5114fb7ac665cbb41ff6208fbcfe","size":{"x":32,"y":1,"z":32}},{"blockCount":17,"bytes":904,"file":"chunks/y147-z064-x192.json","offset":{"x":192,"y":147,"z":64},"requirements":{"minecraft:polished_diorite":12,"minecraft:stone_bricks":5},"sha256":"c548c155ae39ae32c1cfc97af73924d38a64b6597f191d40c303cefc8052e7a6","size":{"x":32,"y":1,"z":32}},{"blockCount":19,"bytes":981,"file":"chunks/y147-z064-x224.json","offset":{"x":224,"y":147,"z":64},"requirements":{"minecraft:polished_diorite":12,"minecraft:stone_bricks":7},"sha256":"3e9d537b8c38a0f4466e8c40b1a18068a402129964a5c4135f2ba5aca8130623","size":{"x":32,"y":1,"z":32}},{"blockCount":41,"bytes":1555,"file":"chunks/y147-z096-x032.json","offset":{"x":32,"y":147,"z":96},"requirements":{"minecraft:polished_diorite":33,"minecraft:stone_bricks":8},"sha256":"75b84f762cee2c386141daae94636d94401cc57f66e3df3e3b180d9f085ffb29","size":{"x":32,"y":1,"z":32}},{"blockCount":41,"bytes":1702,"file":"chunks/y147-z096-x064.json","offset":{"x":64,"y":147,"z":96},"requirements":{"minecraft:polished_diorite":31,"minecraft:stone_bricks":10},"sha256":"a24cfd1d24a2323f639b9dde78a775a4d5471932ffb75664b193a533667c9d42","size":{"x":32,"y":1,"z":32}},{"blockCount":274,"bytes":8359,"file":"chunks/y147-z096-x096.json","offset":{"x":96,"y":147,"z":96},"requirements":{"minecraft:bricks":61,"minecraft:cobbled_deepslate":35,"minecraft:glass":64,"minecraft:oak_planks":20,"minecraft:polished_diorite":22,"minecraft:spruce_planks":10,"minecraft:stone_bricks":62},"sha256":"40512734fcb19732e3ad3d2a4a11633b772cf090242a7b52e3215d0dce184f2b","size":{"x":32,"y":1,"z":32}},{"blockCount":82,"bytes":3026,"file":"chunks/y147-z096-x128.json","offset":{"x":128,"y":147,"z":96},"requirements":{"minecraft:cobbled_deepslate":32,"minecraft:polished_diorite":36,"minecraft:stone_bricks":14},"sha256":"a7bf3d06b128fd4fe624f43a2cbb8afac71a6491f9266bd9561a0e8af002b228","size":{"x":32,"y":1,"z":32}},{"blockCount":43,"bytes":1703,"file":"chunks/y147-z096-x160.json","offset":{"x":160,"y":147,"z":96},"requirements":{"minecraft:polished_diorite":33,"minecraft:stone_bricks":10},"sha256":"ccbe8955768380f4578ac6aef1fde08bb6aa813cd9777641c10e3813eb3452dd","size":{"x":32,"y":1,"z":32}},{"blockCount":154,"bytes":3440,"file":"chunks/y147-z096-x192.json","offset":{"x":192,"y":147,"z":96},"requirements":{"minecraft:bricks":41,"minecraft:glass":4,"minecraft:polished_diorite":86,"minecraft:stone_bricks":23},"sha256":"e352f7f7d681c942d6bb29c9cdb807d484e964c615f4973889cd892ff3f76083","size":{"x":32,"y":1,"z":32}},{"blockCount":137,"bytes":3120,"file":"chunks/y147-z096-x224.json","offset":{"x":224,"y":147,"z":96},"requirements":{"minecraft:bricks":43,"minecraft:glass":10,"minecraft:polished_diorite":65,"minecraft:stone_bricks":19},"sha256":"f0dc92a74b311becb4eab0e3716bff0ecc76030da48e934f128218f327c2e98f","size":{"x":32,"y":1,"z":32}},{"blockCount":164,"bytes":3494,"file":"chunks/y147-z128-x032.json","offset":{"x":32,"y":147,"z":128},"requirements":{"minecraft:bricks":1,"minecraft:cobbled_deepslate":55,"minecraft:glass":18,"minecraft:oak_planks":32,"minecraft:polished_diorite":24,"minecraft:spruce_planks":3,"minecraft:stone_bricks":31},"sha256":"2cf92cc12762197622c6702e7a826c6c57cb40299d436e398fc1b3bb36fe8be8","size":{"x":32,"y":1,"z":32}},{"blockCount":287,"bytes":3953,"file":"chunks/y147-z128-x064.json","offset":{"x":64,"y":147,"z":128},"requirements":{"minecraft:bricks":60,"minecraft:cobbled_deepslate":63,"minecraft:glass":64,"minecraft:oak_planks":20,"minecraft:polished_diorite":6,"minecraft:spruce_planks":10,"minecraft:stone_bricks":64},"sha256":"08a9001ab897c7d0b09c0aeede6efb8154faa77cd8ff2f5948066c28032b0771","size":{"x":32,"y":1,"z":32}},{"blockCount":382,"bytes":7355,"file":"chunks/y147-z128-x096.json","offset":{"x":96,"y":147,"z":128},"requirements":{"minecraft:bricks":123,"minecraft:cobbled_deepslate":55,"minecraft:glass":72,"minecraft:oak_planks":16,"minecraft:spruce_planks":10,"minecraft:stone_bricks":106},"sha256":"22111f2df1eac82ef1b8c64fb7bbb5644aed4ccb42683d271ec1e575fdb87975","size":{"x":32,"y":1,"z":32}},{"blockCount":303,"bytes":4003,"file":"chunks/y147-z128-x128.json","offset":{"x":128,"y":147,"z":128},"requirements":{"minecraft:bricks":64,"minecraft:cobbled_deepslate":78,"minecraft:glass":64,"minecraft:oak_planks":16,"minecraft:polished_diorite":3,"minecraft:spruce_planks":8,"minecraft:stone_bricks":70},"sha256":"b8daeb8a8329adca5c5aff01d965dd65613a20f38f7fce52728010c1333c05d2","size":{"x":32,"y":1,"z":32}},{"blockCount":284,"bytes":4049,"file":"chunks/y147-z128-x160.json","offset":{"x":160,"y":147,"z":128},"requirements":{"minecraft:bricks":55,"minecraft:cobbled_deepslate":57,"minecraft:glass":64,"minecraft:oak_planks":20,"minecraft:polished_diorite":7,"minecraft:spruce_planks":10,"minecraft:stone_bricks":71},"sha256":"9b81aaf25a23be74c74e63a8a96eb06417deba57b023fe96e5c9f0ae2bb6df3b","size":{"x":32,"y":1,"z":32}},{"blockCount":288,"bytes":4856,"file":"chunks/y147-z128-x192.json","offset":{"x":192,"y":147,"z":128},"requirements":{"minecraft:bricks":52,"minecraft:cobbled_deepslate":77,"minecraft:glass":36,"minecraft:oak_planks":24,"minecraft:polished_diorite":18,"minecraft:spruce_planks":18,"minecraft:stone_bricks":63},"sha256":"a7fe5392990c7d20525e99b3286f545c1f05e057e9ed14130e5ce3f935ddf22e","size":{"x":32,"y":1,"z":32}},{"blockCount":71,"bytes":2121,"file":"chunks/y147-z128-x224.json","offset":{"x":224,"y":147,"z":128},"requirements":{"minecraft:bricks":2,"minecraft:cobbled_deepslate":7,"minecraft:oak_planks":2,"minecraft:polished_diorite":39,"minecraft:sandstone":3,"minecraft:spruce_planks":2,"minecraft:stone_bricks":16},"sha256":"1074e842bb05ff06931fc8e89e094f716059fe54fab4e563d375a0bc4285eb2f","size":{"x":32,"y":1,"z":32}},{"blockCount":22,"bytes":1191,"file":"chunks/y147-z160-x032.json","offset":{"x":32,"y":147,"z":160},"requirements":{"minecraft:polished_diorite":19,"minecraft:stone_bricks":3},"sha256":"fe55a803a96fa49df72156c7d212bedadd03285d84a87e14d4f76e19931969e0","size":{"x":32,"y":1,"z":32}},{"blockCount":30,"bytes":1491,"file":"chunks/y147-z160-x064.json","offset":{"x":64,"y":147,"z":160},"requirements":{"minecraft:polished_diorite":25,"minecraft:stone_bricks":5},"sha256":"507c2107246e6bf38e7cc0eb2da9796194af3fb97a28ea376f9d58f85f85dfce","size":{"x":32,"y":1,"z":32}},{"blockCount":281,"bytes":8569,"file":"chunks/y147-z160-x096.json","offset":{"x":96,"y":147,"z":160},"requirements":{"minecraft:bricks":64,"minecraft:cobbled_deepslate":31,"minecraft:glass":64,"minecraft:oak_planks":20,"minecraft:polished_diorite":27,"minecraft:spruce_planks":10,"minecraft:stone_bricks":65},"sha256":"a39200d415dcabf3fe737b762d7ea6e38fd1a141c13d00d056d2bcb9d2910277","size":{"x":32,"y":1,"z":32}},{"blockCount":82,"bytes":3086,"file":"chunks/y147-z160-x128.json","offset":{"x":128,"y":147,"z":160},"requirements":{"minecraft:cobbled_deepslate":30,"minecraft:polished_diorite":38,"minecraft:stone_bricks":14},"sha256":"05bdbb90a0b6273f5b8623e5b7cafd7dae97cca745868321696d651485cef050","size":{"x":32,"y":1,"z":32}},{"blockCount":31,"bytes":1492,"file":"chunks/y147-z160-x160.json","offset":{"x":160,"y":147,"z":160},"requirements":{"minecraft:polished_diorite":26,"minecraft:stone_bricks":5},"sha256":"cf15163032fbf64c22c52fc364f8740e6dd3afecc263003808772cdcfee0a58a","size":{"x":32,"y":1,"z":32}},{"blockCount":143,"bytes":3212,"file":"chunks/y147-z160-x192.json","offset":{"x":192,"y":147,"z":160},"requirements":{"minecraft:bricks":41,"minecraft:glass":2,"minecraft:polished_diorite":80,"minecraft:stone_bricks":20},"sha256":"9a793884c7f9468ae848d5b8fc9a83bccde101178ab2bb1c0546a6244a4a218e","size":{"x":32,"y":1,"z":32}},{"blockCount":137,"bytes":3121,"file":"chunks/y147-z160-x224.json","offset":{"x":224,"y":147,"z":160},"requirements":{"minecraft:bricks":43,"minecraft:glass":10,"minecraft:polished_diorite":65,"minecraft:stone_bricks":19},"sha256":"cef896b6b6f25a1174390d21e757f2a4b6a3639fee950a2fabe61b2c7234859a","size":{"x":32,"y":1,"z":32}},{"blockCount":188,"bytes":5544,"file":"chunks/y147-z192-x096.json","offset":{"x":96,"y":147,"z":192},"requirements":{"minecraft:bricks":26,"minecraft:cobbled_deepslate":19,"minecraft:glass":30,"minecraft:oak_planks":10,"minecraft:polished_diorite":53,"minecraft:sandstone":3,"minecraft:spruce_planks":6,"minecraft:stone_bricks":41},"sha256":"11a0df5a16d65af79879b0b1d477d226b1b9eb10dd02779a968c6b48c7d0c72e","size":{"x":32,"y":1,"z":32}},{"blockCount":58,"bytes":2255,"file":"chunks/y147-z192-x128.json","offset":{"x":128,"y":147,"z":192},"requirements":{"minecraft:cobbled_deepslate":19,"minecraft:polished_diorite":28,"minecraft:stone_bricks":11},"sha256":"e50a6983cfa08d577f4a8cb154545399eeb236bfd3072ea389b73de80ce61d3d","size":{"x":32,"y":1,"z":32}},{"blockCount":227,"bytes":6938,"file":"chunks/y148-z064-x096.json","offset":{"x":96,"y":148,"z":64},"requirements":{"minecraft:bricks":33,"minecraft:cobbled_deepslate":47,"minecraft:oak_planks":14,"minecraft:polished_diorite":57,"minecraft:sandstone":1,"minecraft:spruce_planks":6,"minecraft:stone_bricks":69},"sha256":"af016f84f90dff5383df50758d62252e4c33a20866cd96f6dfbdfd1987891daf","size":{"x":32,"y":1,"z":32}},{"blockCount":56,"bytes":2062,"file":"chunks/y148-z064-x128.json","offset":{"x":128,"y":148,"z":64},"requirements":{"minecraft:polished_diorite":32,"minecraft:stone_bricks":24},"sha256":"8dfd6b988fddff2257b893ec307d3990491dedd4a8dc30f8904fc80ebfe592bb","size":{"x":32,"y":1,"z":32}},{"blockCount":22,"bytes":1037,"file":"chunks/y148-z064-x192.json","offset":{"x":192,"y":148,"z":64},"requirements":{"minecraft:polished_diorite":8,"minecraft:stone_bricks":14},"sha256":"6dd6e7994d2ff4d6e9306ebbe5c05139b4fd2beff984b3a2fc4586af16cf5407","size":{"x":32,"y":1,"z":32}},{"blockCount":25,"bytes":1115,"file":"chunks/y148-z064-x224.json","offset":{"x":224,"y":148,"z":64},"requirements":{"minecraft:polished_diorite":10,"minecraft:stone_bricks":15},"sha256":"63f887f62136c2945c51bdd85110b016586e47e8d2cfd7b0971770a5700d3acc","size":{"x":32,"y":1,"z":32}},{"blockCount":1,"bytes":641,"file":"chunks/y148-z096-x000.json","offset":{"x":0,"y":148,"z":96},"requirements":{"minecraft:stone_bricks":1},"sha256":"c189cbb81cc209f993b371a9eeff50a93497723d48edd47e39de9aff7e011d10","size":{"x":32,"y":1,"z":32}},{"blockCount":50,"bytes":1924,"file":"chunks/y148-z096-x032.json","offset":{"x":32,"y":148,"z":96},"requirements":{"minecraft:polished_diorite":33,"minecraft:stone_bricks":17},"sha256":"e4fff4d96b44441400aa0a16cdad1b56507ac87db1facf231db957da93ee0a5f","size":{"x":32,"y":1,"z":32}},{"blockCount":49,"bytes":1975,"file":"chunks/y148-z096-x064.json","offset":{"x":64,"y":148,"z":96},"requirements":{"minecraft:polished_diorite":31,"minecraft:stone_bricks":18},"sha256":"a394a4714f2d712f2409411ad04481cc65b96d3da9cd693898bf2d36318303c6","size":{"x":32,"y":1,"z":32}},{"blockCount":232,"bytes":7730,"file":"chunks/y148-z096-x096.json","offset":{"x":96,"y":148,"z":96},"requirements":{"minecraft:bricks":50,"minecraft:cobbled_deepslate":60,"minecraft:oak_planks":20,"minecraft:polished_diorite":22,"minecraft:spruce_planks":10,"minecraft:stone_bricks":70},"sha256":"c192f0a6529d4f108a59bbe62022e008516996e351ba862ade7c71e7412e8943","size":{"x":32,"y":1,"z":32}},{"blockCount":56,"bytes":2139,"file":"chunks/y148-z096-x128.json","offset":{"x":128,"y":148,"z":96},"requirements":{"minecraft:polished_diorite":36,"minecraft:stone_bricks":20},"sha256":"2aad41a424b5d5fc9b929a4781746a0927f6f353612c33a4367fecdcec2c5cf8","size":{"x":32,"y":1,"z":32}},{"blockCount":53,"bytes":2091,"file":"chunks/y148-z096-x160.json","offset":{"x":160,"y":148,"z":96},"requirements":{"minecraft:polished_diorite":33,"minecraft:stone_bricks":20},"sha256":"45ca4e3f935acbb493b2b4428d1c51875a34c636b1f204a2c3fb9719be302d1d","size":{"x":32,"y":1,"z":32}},{"blockCount":171,"bytes":3917,"file":"chunks/y148-z096-x192.json","offset":{"x":192,"y":148,"z":96},"requirements":{"minecraft:bricks":42,"minecraft:glass":2,"minecraft:polished_diorite":82,"minecraft:stone_bricks":45},"sha256":"2e532c2f72f3f3597bf8a80c6b8759aaf3ebea30eee6f8853c99e998a99c886c","size":{"x":32,"y":1,"z":32}},{"blockCount":153,"bytes":3408,"file":"chunks/y148-z096-x224.json","offset":{"x":224,"y":148,"z":96},"requirements":{"minecraft:bricks":46,"minecraft:glass":7,"minecraft:polished_diorite":64,"minecraft:stone_bricks":36},"sha256":"b116850c42788bcd60bf4d0d21eba5a7a7a22d047ab68e0c43a22fa6a7f88be1","size":{"x":32,"y":1,"z":32}},{"blockCount":3,"bytes":721,"file":"chunks/y148-z128-x000.json","offset":{"x":0,"y":148,"z":128},"requirements":{"minecraft:stone_bricks":3},"sha256":"48d76948cacde3b9e9d3edd1bf2c866027f62bcdbeda2c3f088b79a02132b69d","size":{"x":32,"y":1,"z":32}},{"blockCount":132,"bytes":3283,"file":"chunks/y148-z128-x032.json","offset":{"x":32,"y":148,"z":128},"requirements":{"minecraft:cobbled_deepslate":36,"minecraft:glass":4,"minecraft:oak_planks":30,"minecraft:polished_diorite":24,"minecraft:spruce_planks":2,"minecraft:stone_bricks":36},"sha256":"d2ac41c0deafa1ef1f255d961174a39b824a2d0ff404df28f5450fccd6f0dc55","size":{"x":32,"y":1,"z":32}},{"blockCount":209,"bytes":3400,"file":"chunks/y148-z128-x064.json","offset":{"x":64,"y":148,"z":128},"requirements":{"minecraft:bricks":51,"minecraft:cobbled_deepslate":59,"minecraft:oak_planks":20,"minecraft:polished_diorite":6,"minecraft:spruce_planks":10,"minecraft:stone_bricks":63},"sha256":"16f0181a72194ac429302909877f6ef082986e6df4e2a62924f69140b76e8210","size":{"x":32,"y":1,"z":32}},{"blockCount":338,"bytes":6633,"file":"chunks/y148-z128-x096.json","offset":{"x":96,"y":148,"z":128},"requirements":{"minecraft:bricks":99,"minecraft:cobbled_deepslate":62,"minecraft:oak_planks":20,"minecraft:spruce_planks":10,"minecraft:stone_bricks":147},"sha256":"264cde0f0f9bef3259d8ba369f941f584a7b49efd3ec2f5b40f38fb8eec1cbf6","size":{"x":32,"y":1,"z":32}},{"blockCount":204,"bytes":2641,"file":"chunks/y148-z128-x128.json","offset":{"x":128,"y":148,"z":128},"requirements":{"minecraft:bricks":55,"minecraft:cobbled_deepslate":60,"minecraft:oak_planks":16,"minecraft:polished_diorite":3,"minecraft:spruce_planks":8,"minecraft:stone_bricks":62},"sha256":"0c47ebbd13c5a2bc43c38a5ce0b350b12b2edf75b035d5905f803c8fb1456df5","size":{"x":32,"y":1,"z":32}},{"blockCount":205,"bytes":3438,"file":"chunks/y148-z128-x160.json","offset":{"x":160,"y":148,"z":128},"requirements":{"minecraft:bricks":45,"minecraft:cobbled_deepslate":55,"minecraft:oak_planks":20,"minecraft:polished_diorite":7,"minecraft:spruce_planks":10,"minecraft:stone_bricks":68},"sha256":"160b8e433f19858b9db933aae77f1b91071849e3dc800364f4f52e084f615a41","size":{"x":32,"y":1,"z":32}},{"blockCount":238,"bytes":4473,"file":"chunks/y148-z128-x192.json","offset":{"x":192,"y":148,"z":128},"requirements":{"minecraft:bricks":43,"minecraft:cobbled_deepslate":72,"minecraft:glass":3,"minecraft:oak_planks":20,"minecraft:polished_diorite":14,"minecraft:spruce_planks":14,"minecraft:stone_bricks":72},"sha256":"5a77be6ab0ae89e538792947ab37ff7f2e15b3a909b39070fefda041df6399dc","size":{"x":32,"y":1,"z":32}},{"blockCount":75,"bytes":2150,"file":"chunks/y148-z128-x224.json","offset":{"x":224,"y":148,"z":128},"requirements":{"minecraft:bricks":2,"minecraft:cobbled_deepslate":7,"minecraft:oak_planks":2,"minecraft:polished_diorite":35,"minecraft:sandstone":1,"minecraft:stone_bricks":28},"sha256":"134f18e8ac8816eff97b2b3714e7d06ca425bb1641e046ec225a5d61a6d98a36","size":{"x":32,"y":1,"z":32}},{"blockCount":29,"bytes":1404,"file":"chunks/y148-z160-x032.json","offset":{"x":32,"y":148,"z":160},"requirements":{"minecraft:polished_diorite":19,"minecraft:stone_bricks":10},"sha256":"48dbafe29706c9b153ec5c9a8ff86a48d6e12f0afb4a31f33210d47e7fe4bbbd","size":{"x":32,"y":1,"z":32}},{"blockCount":39,"bytes":1724,"file":"chunks/y148-z160-x064.json","offset":{"x":64,"y":148,"z":160},"requirements":{"minecraft:polished_diorite":25,"minecraft:stone_bricks":14},"sha256":"154fa29f3a89d3fe72e2ba70326e38b55f1dba10d9b6aecb502d5cffa5d17eb2","size":{"x":32,"y":1,"z":32}},{"blockCount":245,"bytes":8054,"file":"chunks/y148-z160-x096.json","offset":{"x":96,"y":148,"z":160},"requirements":{"minecraft:bricks":54,"minecraft:cobbled_deepslate":58,"minecraft:oak_planks":20,"minecraft:polished_diorite":27,"minecraft:spruce_planks":10,"minecraft:stone_bricks":76},"sha256":"d0b79f996c9474ce4b2b7ee0e0037d187604c25b18991345e2f6b32b3c71841f","size":{"x":32,"y":1,"z":32}},{"blockCount":60,"bytes":2254,"file":"chunks/y148-z160-x128.json","offset":{"x":128,"y":148,"z":160},"requirements":{"minecraft:polished_diorite":38,"minecraft:stone_bricks":22},"sha256":"6fb0cc5a582d624e1e3dd2c96e127756ad1280c89f2cad331e00335d09e4f978","size":{"x":32,"y":1,"z":32}},{"blockCount":41,"bytes":1782,"file":"chunks/y148-z160-x160.json","offset":{"x":160,"y":148,"z":160},"requirements":{"minecraft:polished_diorite":26,"minecraft:stone_bricks":15},"sha256":"4ccc1a781b3ca3d57af9f3fba86cf9744728d86873b3cc7ac5be2870f2710333","size":{"x":32,"y":1,"z":32}},{"blockCount":162,"bytes":3670,"file":"chunks/y148-z160-x192.json","offset":{"x":192,"y":148,"z":160},"requirements":{"minecraft:bricks":42,"minecraft:glass":1,"minecraft:polished_diorite":76,"minecraft:stone_bricks":43},"sha256":"c7b06a14978abe5c4e01d06d12903b44f9f428cb4cdfc232f6b71e631b811085","size":{"x":32,"y":1,"z":32}},{"blockCount":153,"bytes":3409,"file":"chunks/y148-z160-x224.json","offset":{"x":224,"y":148,"z":160},"requirements":{"minecraft:bricks":46,"minecraft:glass":7,"minecraft:polished_diorite":64,"minecraft:stone_bricks":36},"sha256":"64bb92aa9ceae56691b26ce9c5a47cd76142bb042f4de0b7a3c8b8c517cd0f53","size":{"x":32,"y":1,"z":32}},{"blockCount":175,"bytes":5355,"file":"chunks/y148-z192-x096.json","offset":{"x":96,"y":148,"z":192},"requirements":{"minecraft:bricks":22,"minecraft:cobbled_deepslate":33,"minecraft:oak_planks":10,"minecraft:polished_diorite":52,"minecraft:sandstone":1,"minecraft:spruce_planks":4,"minecraft:stone_bricks":53},"sha256":"e3e6b0339e73c208a3071942252d1733bad3e8b018097bb30e673dd51d4d8513","size":{"x":32,"y":1,"z":32}},{"blockCount":47,"bytes":1833,"file":"chunks/y148-z192-x128.json","offset":{"x":128,"y":148,"z":192},"requirements":{"minecraft:polished_diorite":27,"minecraft:stone_bricks":20},"sha256":"e870af84c410c4d7b447c856840ba83b81fc13bdd2a4c7bd069d3da5ffcc1b24","size":{"x":32,"y":1,"z":32}},{"blockCount":247,"bytes":6192,"file":"chunks/y149-z064-x096.json","offset":{"x":96,"y":149,"z":64},"requirements":{"minecraft:bricks":23,"minecraft:cobbled_deepslate":44,"minecraft:glass":1,"minecraft:oak_planks":14,"minecraft:polished_diorite":73,"minecraft:spruce_planks":7,"minecraft:stone_bricks":85},"sha256":"bfb9ca5f9a981a1e93bf8bf9bb6fe1a2c9ce8f96f1e92f77abeccb0ff88bf74f","size":{"x":32,"y":1,"z":32}},{"blockCount":94,"bytes":1892,"file":"chunks/y149-z064-x128.json","offset":{"x":128,"y":149,"z":64},"requirements":{"minecraft:glass":1,"minecraft:polished_diorite":50,"minecraft:stone_bricks":43},"sha256":"2f3916b052f4e6668af42f16138178aa3a86d4324da4e82a05a5055d22adfb43","size":{"x":32,"y":1,"z":32}},{"blockCount":22,"bytes":1018,"file":"chunks/y149-z064-x192.json","offset":{"x":192,"y":149,"z":64},"requirements":{"minecraft:polished_diorite":13,"minecraft:stone_bricks":9},"sha256":"e6d2a652942e12712a6e71bc31c3df675f9b8d35caa61864d503e7541a488a48","size":{"x":32,"y":1,"z":32}},{"blockCount":25,"bytes":1096,"file":"chunks/y149-z064-x224.json","offset":{"x":224,"y":149,"z":64},"requirements":{"minecraft:polished_diorite":14,"minecraft:stone_bricks":11},"sha256":"acb23ed87d60b12112fbf770ab46af813dbed64717829ad02f132dde9d44c649","size":{"x":32,"y":1,"z":32}},{"blockCount":2,"bytes":660,"file":"chunks/y149-z096-x000.json","offset":{"x":0,"y":149,"z":96},"requirements":{"minecraft:stone_bricks":2},"sha256":"e2cea8221db182be447c3fa985180747340a6bbf76acd1c89ea9ce2485fc436e","size":{"x":32,"y":1,"z":32}},{"blockCount":86,"bytes":1694,"file":"chunks/y149-z096-x032.json","offset":{"x":32,"y":149,"z":96},"requirements":{"minecraft:polished_diorite":52,"minecraft:stone_bricks":34},"sha256":"c84ebae36edb951db6b790f9c0cc2ee7ddae039b06678ad4adf39e56f6f5bade","size":{"x":32,"y":1,"z":32}},{"blockCount":82,"bytes":1800,"file":"chunks/y149-z096-x064.json","offset":{"x":64,"y":149,"z":96},"requirements":{"minecraft:polished_diorite":45,"minecraft:stone_bricks":37},"sha256":"5ac04cfdb945b119799da455b422d2dc9c72e361adce5ed7b4bb3d1c2073bacc","size":{"x":32,"y":1,"z":32}},{"blockCount":231,"bytes":6762,"file":"chunks/y149-z096-x096.json","offset":{"x":96,"y":149,"z":96},"requirements":{"minecraft:bricks":33,"minecraft:cobbled_deepslate":55,"minecraft:glass":2,"minecraft:oak_planks":20,"minecraft:polished_diorite":34,"minecraft:spruce_planks":10,"minecraft:stone_bricks":77},"sha256":"4aa7d36c7418227347658f877da4e9ef48bbbcc48befedfcd509cb659998030b","size":{"x":32,"y":1,"z":32}},{"blockCount":98,"bytes":1932,"file":"chunks/y149-z096-x128.json","offset":{"x":128,"y":149,"z":96},"requirements":{"minecraft:glass":2,"minecraft:polished_diorite":55,"minecraft:stone_bricks":41},"sha256":"103cea5431730708774355c865d2f9970336b25fea0357b3f6d1700622323c46","size":{"x":32,"y":1,"z":32}},{"blockCount":89,"bytes":1916,"file":"chunks/y149-z096-x160.json","offset":{"x":160,"y":149,"z":96},"requirements":{"minecraft:polished_diorite":50,"minecraft:stone_bricks":39},"sha256":"9ee134312a777d2bf41454251906ad752ad4bd3b004c996856ea32778c582250","size":{"x":32,"y":1,"z":32}},{"blockCount":194,"bytes":3496,"file":"chunks/y149-z096-x192.json","offset":{"x":192,"y":149,"z":96},"requirements":{"minecraft:bricks":41,"minecraft:polished_diorite":103,"minecraft:stone_bricks":50},"sha256":"5a02f74ab01ff21a9b3bafaa924eb29ecb554a84244c83ee9191d216e70acd1d","size":{"x":32,"y":1,"z":32}},{"blockCount":157,"bytes":3180,"file":"chunks/y149-z096-x224.json","offset":{"x":224,"y":149,"z":96},"requirements":{"minecraft:bricks":51,"minecraft:glass":4,"minecraft:polished_diorite":76,"minecraft:stone_bricks":26},"sha256":"00af544639491f3d576b51a7fc6d2716878e54fcc7ba7896bb40c7d18807322d","size":{"x":32,"y":1,"z":32}},{"blockCount":4,"bytes":760,"file":"chunks/y149-z128-x000.json","offset":{"x":0,"y":149,"z":128},"requirements":{"minecraft:stone_bricks":4},"sha256":"c0a068523b2f4aa8e7e226dc6c45513d85a41bed32e3ff4a773e4d8e3ab0dcb8","size":{"x":32,"y":1,"z":32}},{"blockCount":159,"bytes":3376,"file":"chunks/y149-z128-x032.json","offset":{"x":32,"y":149,"z":128},"requirements":{"minecraft:cobbled_deepslate":37,"minecraft:glass":8,"minecraft:oak_planks":30,"minecraft:polished_diorite":35,"minecraft:spruce_planks":2,"minecraft:stone_bricks":47},"sha256":"111b92ad27e8893d5f87e8dbb481817df213624c2857fe5d3103a270ccf8ab0a","size":{"x":32,"y":1,"z":32}},{"blockCount":192,"bytes":3134,"file":"chunks/y149-z128-x064.json","offset":{"x":64,"y":149,"z":128},"requirements":{"minecraft:bricks":35,"minecraft:cobbled_deepslate":60,"minecraft:glass":2,"minecraft:oak_planks":20,"minecraft:polished_diorite":6,"minecraft:spruce_planks":10,"minecraft:stone_bricks":59},"sha256":"f4dce4422c536619a384736dbe32abaa51b8c5a2ed3e44b00c0c7cbe96cc45d1","size":{"x":32,"y":1,"z":32}},{"blockCount":301,"bytes":6122,"file":"chunks/y149-z128-x096.json","offset":{"x":96,"y":149,"z":128},"requirements":{"minecraft:bricks":49,"minecraft:cobbled_deepslate":65,"minecraft:glass":19,"minecraft:oak_planks":20,"minecraft:spruce_planks":10,"minecraft:stone_bricks":138},"sha256":"02a740977b581e5297b7902922fca7b0cb000915bf23badb646b09b8d736bfd7","size":{"x":32,"y":1,"z":32}},{"blockCount":185,"bytes":2662,"file":"chunks/y149-z128-x128.json","offset":{"x":128,"y":149,"z":128},"requirements":{"minecraft:bricks":36,"minecraft:cobbled_deepslate":59,"minecraft:glass":5,"minecraft:oak_planks":16,"minecraft:polished_diorite":3,"minecraft:spruce_planks":8,"minecraft:stone_bricks":58},"sha256":"1d0c7afc07dcf4ebd4d321275108b1b205b4c1e4e391ab7ba6a0f15404a21762","size":{"x":32,"y":1,"z":32}},{"blockCount":187,"bytes":3116,"file":"chunks/y149-z128-x160.json","offset":{"x":160,"y":149,"z":128},"requirements":{"minecraft:bricks":30,"minecraft:cobbled_deepslate":58,"minecraft:glass":2,"minecraft:oak_planks":20,"minecraft:polished_diorite":7,"minecraft:spruce_planks":10,"minecraft:stone_bricks":60},"sha256":"a2aad87307f9c749575e29f7f1aa018c948fff90ea6f9f7732170432f51a160b","size":{"x":32,"y":1,"z":32}},{"blockCount":220,"bytes":3844,"file":"chunks/y149-z128-x192.json","offset":{"x":192,"y":149,"z":128},"requirements":{"minecraft:bricks":28,"minecraft:cobbled_deepslate":71,"minecraft:glass":6,"minecraft:oak_planks":20,"minecraft:polished_diorite":18,"minecraft:spruce_planks":17,"minecraft:stone_bricks":60},"sha256":"6253d18203cd9419f32ba79ea255bd43e8a34ae65e9b5eaa866b36274dddcfde","size":{"x":32,"y":1,"z":32}},{"blockCount":73,"bytes":2269,"file":"chunks/y149-z128-x224.json","offset":{"x":224,"y":149,"z":128},"requirements":{"minecraft:bricks":1,"minecraft:cobbled_deepslate":5,"minecraft:oak_planks":2,"minecraft:polished_diorite":38,"minecraft:spruce_planks":2,"minecraft:stone_bricks":25},"sha256":"e478f5848c94eb6eab7071340f63d28b627169f598c4a35cc86a2f09cdfe9f69","size":{"x":32,"y":1,"z":32}},{"blockCount":51,"bytes":1251,"file":"chunks/y149-z160-x032.json","offset":{"x":32,"y":149,"z":160},"requirements":{"minecraft:polished_diorite":33,"minecraft:stone_bricks":18},"sha256":"7dc37e402affbfde4e0c4cb80ae3b31dd58f753004b4261217a18cf4ed82df8f","size":{"x":32,"y":1,"z":32}},{"blockCount":65,"bytes":1513,"file":"chunks/y149-z160-x064.json","offset":{"x":64,"y":149,"z":160},"requirements":{"minecraft:polished_diorite":39,"minecraft:stone_bricks":26},"sha256":"d5d7f5ea6ec3b6225d2029c25ad51617b4a8eae79e9216e78cd9b5c038a957ec","size":{"x":32,"y":1,"z":32}},{"blockCount":252,"bytes":7086,"file":"chunks/y149-z160-x096.json","offset":{"x":96,"y":149,"z":160},"requirements":{"minecraft:bricks":38,"minecraft:cobbled_deepslate":59,"minecraft:glass":1,"minecraft:oak_planks":20,"minecraft:polished_diorite":42,"minecraft:spruce_planks":10,"minecraft:stone_bricks":82},"sha256":"1f0f0f24e0f9bf428bf80c70c49a28c5bd691e277392ac0d1d1499bd58272059","size":{"x":32,"y":1,"z":32}},{"blockCount":104,"bytes":1972,"file":"chunks/y149-z160-x128.json","offset":{"x":128,"y":149,"z":160},"requirements":{"minecraft:glass":1,"minecraft:polished_diorite":60,"minecraft:stone_bricks":43},"sha256":"f7597a697014836385de8d96a1c1ba3239565c375adb3282f6212de80313c6b6","size":{"x":32,"y":1,"z":32}},{"blockCount":70,"bytes":1590,"file":"chunks/y149-z160-x160.json","offset":{"x":160,"y":149,"z":160},"requirements":{"minecraft:polished_diorite":43,"minecraft:stone_bricks":27},"sha256":"0fcbab2968f7f44daac92bbb851e669ea76711c902a3b73032881e3253e2c228","size":{"x":32,"y":1,"z":32}},{"blockCount":181,"bytes":3288,"file":"chunks/y149-z160-x192.json","offset":{"x":192,"y":149,"z":160},"requirements":{"minecraft:bricks":41,"minecraft:polished_diorite":98,"minecraft:stone_bricks":42},"sha256":"8d7906f090dd541a4b410d235d85bb51b27d94645a0d4f25dd74a7d022558949","size":{"x":32,"y":1,"z":32}},{"blockCount":158,"bytes":3181,"file":"chunks/y149-z160-x224.json","offset":{"x":224,"y":149,"z":160},"requirements":{"minecraft:bricks":51,"minecraft:glass":4,"minecraft:polished_diorite":76,"minecraft:stone_bricks":27},"sha256":"e554be786b4e6a839551bf671ad2001996755168b5630a4039f8ac6f13e59bbc","size":{"x":32,"y":1,"z":32}},{"blockCount":194,"bytes":4761,"file":"chunks/y149-z192-x096.json","offset":{"x":96,"y":149,"z":192},"requirements":{"minecraft:bricks":15,"minecraft:cobbled_deepslate":34,"minecraft:glass":1,"minecraft:oak_planks":10,"minecraft:polished_diorite":65,"minecraft:spruce_planks":5,"minecraft:stone_bricks":64},"sha256":"e98298f6e1e084bb2dee50fbd9dcd42a70d7c2cb75c4431a96fcddffbdb9ac6b","size":{"x":32,"y":1,"z":32}},{"blockCount":79,"bytes":1701,"file":"chunks/y149-z192-x128.json","offset":{"x":128,"y":149,"z":192},"requirements":{"minecraft:glass":1,"minecraft:polished_diorite":42,"minecraft:stone_bricks":36},"sha256":"7f92025f64d3cab23c65f56288f80de1fbfa28d7100b2710e7734e3ffe3a83b5","size":{"x":32,"y":1,"z":32}},{"blockCount":244,"bytes":6591,"file":"chunks/y150-z064-x096.json","offset":{"x":96,"y":150,"z":64},"requirements":{"minecraft:bricks":8,"minecraft:cobbled_deepslate":45,"minecraft:glass":18,"minecraft:oak_planks":49,"minecraft:polished_diorite":67,"minecraft:spruce_planks":8,"minecraft:stone_bricks":49},"sha256":"45bc129e078b1c4c43f118ad767f4175799a8f3eaf32596d48a5cbfbcaf86b44","size":{"x":32,"y":1,"z":32}},{"blockCount":61,"bytes":2462,"file":"chunks/y150-z064-x128.json","offset":{"x":128,"y":150,"z":64},"requirements":{"minecraft:glass":1,"minecraft:polished_diorite":48,"minecraft:stone_bricks":12},"sha256":"2c93fbbf2d832cac42383d16a4071bf5bdb29bfc477502f5130a44ef47701cc5","size":{"x":32,"y":1,"z":32}},{"blockCount":22,"bytes":961,"file":"chunks/y150-z064-x192.json","offset":{"x":192,"y":150,"z":64},"requirements":{"minecraft:polished_diorite":6,"minecraft:stone_bricks":16},"sha256":"57c759da9e9852f22a9dc1fe0eafae9a253946f93b31f2a870067583ff1e115f","size":{"x":32,"y":1,"z":32}},{"blockCount":25,"bytes":1038,"file":"chunks/y150-z064-x224.json","offset":{"x":224,"y":150,"z":64},"requirements":{"minecraft:polished_diorite":8,"minecraft:stone_bricks":17},"sha256":"69ae6bd274a5c923693304d973ae42934ff4a4c4bb02b1da75b08288aa20e228","size":{"x":32,"y":1,"z":32}},{"blockCount":2,"bytes":664,"file":"chunks/y150-z096-x000.json","offset":{"x":0,"y":150,"z":96},"requirements":{"minecraft:polished_diorite":2},"sha256":"bc3f047c624b18eee01184f456ac268714115a92dea60a0d852001287e661e7d","size":{"x":32,"y":1,"z":32}},{"blockCount":55,"bytes":2188,"file":"chunks/y150-z096-x032.json","offset":{"x":32,"y":150,"z":96},"requirements":{"minecraft:polished_diorite":45,"minecraft:stone_bricks":10},"sha256":"72df1f1e2e5b92f4f9d19bc440d8c6ab8a0a2ab8083e780f6648498e9598cb63","size":{"x":32,"y":1,"z":32}},{"blockCount":54,"bytes":2217,"file":"chunks/y150-z096-x064.json","offset":{"x":64,"y":150,"z":96},"requirements":{"minecraft:polished_diorite":45,"minecraft:stone_bricks":9},"sha256":"4dd7c0ed5c6820fdd2afab08213d2707aa45c93b6274919fda3dcb3395bb789e","size":{"x":32,"y":1,"z":32}},{"blockCount":259,"bytes":7067,"file":"chunks/y150-z096-x096.json","offset":{"x":96,"y":150,"z":96},"requirements":{"minecraft:bricks":10,"minecraft:cobbled_deepslate":63,"minecraft:glass":29,"minecraft:oak_planks":69,"minecraft:polished_diorite":32,"minecraft:spruce_planks":14,"minecraft:stone_bricks":42},"sha256":"dfccf2a52f8bb41f9f09d32d3dee34ec6cfb4016f20f7c81d36d4682289bea71","size":{"x":32,"y":1,"z":32}}],"schema":1}
