{"entries":[{"blockCount":65,"bytes":2540,"file":"chunks/y150-z096-x128.json","offset":{"x":128,"y":150,"z":96},"requirements":{"minecraft:glass":2,"minecraft:polished_diorite":52,"minecraft:stone_bricks":11},"sha256":"bb2d9a680667adc388573afc3f1e8aa9ae91e232963b73c25c5d88d69bd6961d","size":{"x":32,"y":1,"z":32}},{"blockCount":57,"bytes":2314,"file":"chunks/y150-z096-x160.json","offset":{"x":160,"y":150,"z":96},"requirements":{"minecraft:polished_diorite":48,"minecraft:stone_bricks":9},"sha256":"17db43185d879be6102ecfb7f267e4d94d964579160ddd7575c907a8d278f79a","size":{"x":32,"y":1,"z":32}},{"blockCount":172,"bytes":4027,"file":"chunks/y150-z096-x192.json","offset":{"x":192,"y":150,"z":96},"requirements":{"minecraft:bricks":40,"minecraft:polished_diorite":84,"minecraft:stone_bricks":48},"sha256":"c4b8b4c24720686f46ab722470f60342eea5f5e3df565c8265edcd28703c993a","size":{"x":32,"y":1,"z":32}},{"blockCount":154,"bytes":3313,"file":"chunks/y150-z096-x224.json","offset":{"x":224,"y":150,"z":96},"requirements":{"minecraft:bricks":48,"minecraft:glass":4,"minecraft:polished_diorite":59,"minecraft:stone_bricks":43},"sha256":"3e22762f3738b4ea47a8135e43ff9bf8552558b74c5d41dbf24834ddc184532e","size":{"x":32,"y":1,"z":32}},{"blockCount":4,"bytes":764,"file":"chunks/y150-z128-x000.json","offset":{"x":0,"y":150,"z":128},"requirements":{"minecraft:polished_diorite":4},"sha256":"0518223ce13fea747c464931a190ea7a1dcf8827c562f32393ff45c0bbb015f5","size":{"x":32,"y":1,"z":32}},{"blockCount":154,"bytes":3831,"file":"chunks/y150-z128-x032.json","offset":{"x":32,"y":150,"z":128},"requirements":{"minecraft:cobbled_deepslate":39,"minecraft:glass":17,"minecraft:oak_planks":40,"minecraft:polished_diorite":33,"minecraft:spruce_planks":4,"minecraft:stone_bricks":21},"sha256":"af68cfb7e58ae026ae2e0c140e4a1ff6d7f9db56012a95e06ce4c695c628cb52","size":{"x":32,"y":1,"z":32}},{"blockCount":223,"bytes":3224,"file":"chunks/y150-z128-x064.json","offset":{"x":64,"y":150,"z":128},"requirements":{"minecraft:bricks":12,"minecraft:cobbled_deepslate":64,"minecraft:glass":20,"minecraft:oak_planks":69,"minecraft:polished_diorite":11,"minecraft:spruce_planks":12,"minecraft:stone_bricks":35},"sha256":"29016f16fcd584e3b60f96d257e41b9a1a8bd20c95122a34f2acda52dfc1a759","size":{"x":32,"y":1,"z":32}},{"blockCount":315,"bytes":6730,"file":"chunks/y150-z128-x096.json","offset":{"x":96,"y":150,"z":128},"requirements":{"minecraft:bricks":3,"minecraft:cobbled_deepslate":76,"minecraft:glass":21,"minecraft:oak_planks":115,"minecraft:spruce_planks":18,"minecraft:stone_bricks":82},"sha256":"055b538e459d1c4f08ba580d54f929a33fef8448d9a80f1dd096c5f0c33d18a1","size":{"x":32,"y":1,"z":32}},{"blockCount":221,"bytes":3225,"file":"chunks/y150-z128-x128.json","offset":{"x":128,"y":150,"z":128},"requirements":{"minecraft:bricks":10,"minecraft:cobbled_deepslate":61,"minecraft:glass":23,"minecraft:oak_planks":68,"minecraft:polished_diorite":5,"minecraft:spruce_planks":12,"minecraft:stone_bricks":42},"sha256":"5de67de66a3c5bf77cbe0f8baeb25859fde5ec3381b6ea733439b3a2f2638169","size":{"x":32,"y":1,"z":32}},{"blockCount":218,"bytes":3434,"file":"chunks/y150-z128-x160.json","offset":{"x":160,"y":150,"z":128},"requirements":{"minecraft:bricks":10,"minecraft:cobbled_deepslate":56,"minecraft:glass":20,"minecraft:oak_planks":69,"minecraft:polished_diorite":12,"minecraft:spruce_planks":12,"minecraft:stone_bricks":39},"sha256":"9d75db760bee7adca1b27fdbe48d7701774cb00349c476338507b9e64ee94294","size":{"x":32,"y":1,"z":32}},{"blockCount":258,"bytes":4096,"file":"chunks/y150-z128-x192.json","offset":{"x":192,"y":150,"z":128},"requirements":{"minecraft:bricks":10,"minecraft:cobbled_deepslate":70,"minecraft:glass":30,"minecraft:oak_planks":68,"minecraft:polished_diorite":15,"minecraft:spruce_planks":15,"minecraft:stone_bricks":50},"sha256":"33faa24a7f3ae7041b9f0609fbd0d0cad859549276d2fdb1bec07a80eb9538e5","size":{"x":32,"y":1,"z":32}},{"blockCount":75,"bytes":2086,"file":"chunks/y150-z128-x224.json","offset":{"x":224,"y":150,"z":128},"requirements":{"minecraft:cobbled_deepslate":8,"minecraft:glass":8,"minecraft:oak_planks":4,"minecraft:polished_diorite":27,"minecraft:stone_bricks":28},"sha256":"e2c09d2d43d7fbc933d5ec775726945c945f6a5fef2c17bed3b419b692a29001","size":{"x":32,"y":1,"z":32}},{"blockCount":31,"bytes":1554,"file":"chunks/y150-z160-x032.json","offset":{"x":32,"y":150,"z":160},"requirements":{"minecraft:polished_diorite":26,"minecraft:stone_bricks":5},"sha256":"c0facedbd76451c65c5d9715a710e45bcc577d9ee165a88e6609e79984806719","size":{"x":32,"y":1,"z":32}},{"blockCount":41,"bytes":1873,"file":"chunks/y150-z160-x064.json","offset":{"x":64,"y":150,"z":160},"requirements":{"minecraft:polished_diorite":34,"minecraft:stone_bricks":7},"sha256":"aab297e3c7d313b51aa440459d3178c65cc27caa1ff0e6dea00c19faae193127","size":{"x":32,"y":1,"z":32}},{"blockCount":260,"bytes":7448,"file":"chunks/y150-z160-x096.json","offset":{"x":96,"y":150,"z":160},"requirements":{"minecraft:bricks":13,"minecraft:cobbled_deepslate":60,"minecraft:glass":19,"minecraft:oak_planks":69,"minecraft:polished_diorite":40,"minecraft:spruce_planks":12,"minecraft:stone_bricks":47},"sha256":"aa1a2a9d3dbd82f33d4a4e5b7747db34858663b1a97df497adf9790e193b27f6","size":{"x":32,"y":1,"z":32}},{"blockCount":67,"bytes":2618,"file":"chunks/y150-z160-x128.json","offset":{"x":128,"y":150,"z":160},"requirements":{"minecraft:glass":1,"minecraft:polished_diorite":55,"minecraft:stone_bricks":11},"sha256":"63c5d6d4e850605f7de1b00b65b738cea2df47c12fa1b94c1360986880d51f07","size":{"x":32,"y":1,"z":32}},{"blockCount":43,"bytes":1931,"file":"chunks/y150-z160-x160.json","offset":{"x":160,"y":150,"z":160},"requirements":{"minecraft:polished_diorite":36,"minecraft:stone_bricks":7},"sha256":"eb1978ced8c7ef9e2b6bb69556a9b033623ec5f22e14dc2e30df1402a607d502","size":{"x":32,"y":1,"z":32}},{"blockCount":163,"bytes":3762,"file":"chunks/y150-z160-x192.json","offset":{"x":192,"y":150,"z":160},"requirements":{"minecraft:bricks":40,"minecraft:polished_diorite":75,"minecraft:stone_bricks":48},"sha256":"991c5c165a1da129222284855316edf401c097d0947f0110a6512063d31336c8","size":{"x":32,"y":1,"z":32}},{"blockCount":155,"bytes":3333,"file":"chunks/y150-z160-x224.json","offset":{"x":224,"y":150,"z":160},"requirements":{"minecraft:bricks":48,"minecraft:glass":4,"minecraft:polished_diorite":59,"minecraft:stone_bricks":44},"sha256":"990072f6338fce5c4cbc044d6a589085ef1d0e16d04630044b70d818b6e244b2","size":{"x":32,"y":1,"z":32}},{"blockCount":207,"bytes":5218,"file":"chunks/y150-z192-x096.json","offset":{"x":96,"y":150,"z":192},"requirements":{"minecraft:bricks":5,"minecraft:cobbled_deepslate":35,"minecraft:glass":18,"minecraft:oak_planks":34,"minecraft:polished_diorite":59,"minecraft:spruce_planks":20,"minecraft:stone_bricks":36},"sha256":"d578d4775ccbea92a52f67df2cf56573383545824d2dd5fe5bf4b2f2bc30c6f2","size":{"x":32,"y":1,"z":32}},{"blockCount":52,"bytes":2195,"file":"chunks/y150-z192-x128.json","offset":{"x":128,"y":150,"z":192},"requirements":{"minecraft:glass":1,"minecraft:polished_diorite":40,"minecraft:stone_bricks":11},"sha256":"2b929be164d3a41fd3b3e6e541628f8c132aeb6c15175fc78fa4522615666eb6","size":{"x":32,"y":1,"z":32}},{"blockCount":161,"bytes":5099,"file":"chunks/y151-z064-x096.json","offset":{"x":96,"y":151,"z":64},"requirements":{"minecraft:cobbled_deepslate":47,"minecraft:glass":1,"minecraft:oak_planks":43,"minecraft:polished_diorite":39,"minecraft:stone_bricks":31},"sha256":"0bd3c1831d629ef6071823b2b16fe35f5d9752e55862781715de216188038814","size":{"x":32,"y":1,"z":32}},{"blockCount":38,"bytes":1967,"file":"chunks/y151-z064-x128.json","offset":{"x":128,"y":151,"z":64},"requirements":{"minecraft:glass":1,"minecraft:polished_diorite":18,"minecraft:stone_bricks":19},"sha256":"10f5b5b3124db886bd01fa3a39bbdabfc1fd2ebbaa52cd16071883f966c1778a","size":{"x":32,"y":1,"z":32}},{"blockCount":16,"bytes":979,"file":"chunks/y151-z064-x192.json","offset":{"x":192,"y":151,"z":64},"requirements":{"minecraft:polished_diorite":7,"minecraft:stone_bricks":9},"sha256":"b0590b16247976392211e07e1afe144b9eece75cece2e8b4b5be2f6b0f381e44","size":{"x":32,"y":1,"z":32}},{"blockCount":17,"bytes":1037,"file":"chunks/y151-z064-x224.json","offset":{"x":224,"y":151,"z":64},"requirements":{"minecraft:polished_diorite":8,"minecraft:stone_bricks":9},"sha256":"ae69dcd87d2ddc43ad878e90341eb69fd70a39d466b7ccdcd6e95b3ddb5d1c30","size":{"x":32,"y":1,"z":32}},{"blockCount":1,"bytes":626,"file":"chunks/y151-z096-x000.json","offset":{"x":0,"y":151,"z":96},"requirements":{"minecraft:polished_diorite":1},"sha256":"c2be9dccbde91bc2cbd2330dbde8358a090ca43a3fff542f6cc0474a081be671","size":{"x":32,"y":1,"z":32}},{"blockCount":38,"bytes":1924,"file":"chunks/y151-z096-x032.json","offset":{"x":32,"y":151,"z":96},"requirements":{"minecraft:polished_diorite":20,"minecraft:stone_bricks":18},"sha256":"1eeac06d386d3319ea6c4c688901268107be2554085c74756e00bb023f8bd3bb","size":{"x":32,"y":1,"z":32}},{"blockCount":36,"bytes":1842,"file":"chunks/y151-z096-x064.json","offset":{"x":64,"y":151,"z":96},"requirements":{"minecraft:polished_diorite":17,"minecraft:stone_bricks":19},"sha256":"1e4179a4a5fd4c27ee2e1d3df97790af42c248bfbbbac4bf777dd7ba4e0f4f82","size":{"x":32,"y":1,"z":32}},{"blockCount":163,"bytes":5232,"file":"chunks/y151-z096-x096.json","offset":{"x":96,"y":151,"z":96},"requirements":{"minecraft:cobbled_deepslate":60,"minecraft:glass":2,"minecraft:oak_planks":62,"minecraft:polished_diorite":14,"minecraft:stone_bricks":25},"sha256":"c9bdededfa82002b7789dbd56a9612f8412fee0ec2aac6bc19de1607526c5a4a","size":{"x":32,"y":1,"z":32}},{"blockCount":45,"bytes":2160,"file":"chunks/y151-z096-x128.json","offset":{"x":128,"y":151,"z":96},"requirements":{"minecraft:glass":2,"minecraft:polished_diorite":22,"minecraft:stone_bricks":21},"sha256":"001fa12af1afb7ee1d47d019bc1827f0de109eff1dabb67352572860e127d363","size":{"x":32,"y":1,"z":32}},{"blockCount":37,"bytes":1862,"file":"chunks/y151-z096-x160.json","offset":{"x":160,"y":151,"z":96},"requirements":{"minecraft:polished_diorite":18,"minecraft:stone_bricks":19},"sha256":"0a0623e332882f65b3b311e186e189762945be06d9a1d83819a2e29fda1fac53","size":{"x":32,"y":1,"z":32}},{"blockCount":144,"bytes":3497,"file":"chunks/y151-z096-x192.json","offset":{"x":192,"y":151,"z":96},"requirements":{"minecraft:bricks":39,"minecraft:polished_diorite":68,"minecraft:stone_bricks":37},"sha256":"52f9bc96acc9047e80eaafbc1f6881a11fcb48ba63e89821496c2ec45980d3e0","size":{"x":32,"y":1,"z":32}},{"blockCount":134,"bytes":3007,"file":"chunks/y151-z096-x224.json","offset":{"x":224,"y":151,"z":96},"requirements":{"minecraft:bricks":45,"minecraft:glass":4,"minecraft:polished_diorite":58,"minecraft:stone_bricks":27},"sha256":"606eb9a60f5f6953eafa98d0f184534e75201e1a8f5c34ee959d2c76330e03d4","size":{"x":32,"y":1,"z":32}},{"blockCount":1,"bytes":647,"file":"chunks/y151-z128-x000.json","offset":{"x":0,"y":151,"z":128},"requirements":{"minecraft:polished_diorite":1},"sha256":"c2a0a36bbe3673e11ed8207cb156a9b21d02d86fcae849d2bff3591e76f38df3","size":{"x":32,"y":1,"z":32}},{"blockCount":133,"bytes":3792,"file":"chunks/y151-z128-x032.json","offset":{"x":32,"y":151,"z":128},"requirements":{"minecraft:cobbled_deepslate":39,"minecraft:glass":8,"minecraft:oak_planks":39,"minecraft:polished_diorite":11,"minecraft:spruce_planks":3,"minecraft:stone_bricks":33},"sha256":"24de0944e36728d9c36013539a146288fa3714bf534d47e7e1c31fa5ba28cff5","size":{"x":32,"y":1,"z":32}},{"blockCount":131,"bytes":2473,"file":"chunks/y151-z128-x064.json","offset":{"x":64,"y":151,"z":128},"requirements":{"minecraft:cobbled_deepslate":57,"minecraft:glass":2,"minecraft:oak_planks":52,"minecraft:polished_diorite":2,"minecraft:stone_bricks":18},"sha256":"6b7746f4e59064628a050a37cb6ae3573255d35b42c3f9dd65652e576edce948","size":{"x":32,"y":1,"z":32}},{"blockCount":216,"bytes":5534,"file":"chunks/y151-z128-x096.json","offset":{"x":96,"y":151,"z":128},"requirements":{"minecraft:cobbled_deepslate":75,"minecraft:glass":15,"minecraft:oak_planks":81,"minecraft:spruce_planks":16,"minecraft:stone_bricks":29},"sha256":"095eddd7100c8752f6fe9255bdba8a2ca5fada9ac5b716bec8960c13e2539b26","size":{"x":32,"y":1,"z":32}},{"blockCount":193,"bytes":2749,"file":"chunks/y151-z128-x128.json","offset":{"x":128,"y":151,"z":128},"requirements":{"minecraft:cobbled_deepslate":58,"minecraft:glass":5,"minecraft:oak_planks":52,"minecraft:polished_diorite":1,"minecraft:spruce_planks":60,"minecraft:stone_bricks":17},"sha256":"5425cd9a56af343c1d0b1cf761232a5614e71bc6911804ac0d6606fefae42b95","size":{"x":32,"y":1,"z":32}},{"blockCount":191,"bytes":2524,"file":"chunks/y151-z128-x160.json","offset":{"x":160,"y":151,"z":128},"requirements":{"minecraft:cobbled_deepslate":59,"minecraft:glass":2,"minecraft:oak_planks":52,"minecraft:polished_diorite":2,"minecraft:spruce_planks":60,"minecraft:stone_bricks":16},"sha256":"d583431e3c560c1537dff0be985cf6ae27b5ecd089db23dfbf8a0f31e16185fc","size":{"x":32,"y":1,"z":32}},{"blockCount":207,"bytes":3675,"file":"chunks/y151-z128-x192.json","offset":{"x":192,"y":151,"z":128},"requirements":{"minecraft:cobbled_deepslate":61,"minecraft:glass":6,"minecraft:oak_planks":55,"minecraft:polished_diorite":8,"minecraft:spruce_planks":49,"minecraft:stone_bricks":28},"sha256":"04e4e4c4f6bd38c911ddbbb688bbf1b781cbf688d25535b3a3bd7cbe49d47808","size":{"x":32,"y":1,"z":32}},{"blockCount":60,"bytes":1950,"file":"chunks/y151-z128-x224.json","offset":{"x":224,"y":151,"z":128},"requirements":{"minecraft:cobbled_deepslate":6,"minecraft:oak_planks":12,"minecraft:polished_diorite":29,"minecraft:stone_bricks":13},"sha256":"0666ae2dc208151819ee5af9022b7d9f1dc3b4069c98f03a75dbefedec03544e","size":{"x":32,"y":1,"z":32}},{"blockCount":21,"bytes":1328,"file":"chunks/y151-z160-x032.json","offset":{"x":32,"y":151,"z":160},"requirements":{"minecraft:polished_diorite":13,"minecraft:stone_bricks":8},"sha256":"a1e4a0d797d9f2ea639627f44db42bdb349264d12ed4fd11507aafd8d7742059","size":{"x":32,"y":1,"z":32}},{"blockCount":27,"bytes":1498,"file":"chunks/y151-z160-x064.json","offset":{"x":64,"y":151,"z":160},"requirements":{"minecraft:polished_diorite":15,"minecraft:stone_bricks":12},"sha256":"38f700137bcca832f7c3cb38e97d9c465b75c931ff264b06d3534c19a79a1521","size":{"x":32,"y":1,"z":32}},{"blockCount":153,"bytes":5422,"file":"chunks/y151-z160-x096.json","offset":{"x":96,"y":151,"z":160},"requirements":{"minecraft:cobbled_deepslate":62,"minecraft:glass":1,"minecraft:oak_planks":52,"minecraft:polished_diorite":16,"minecraft:stone_bricks":22},"sha256":"4797a0175a4bdfa50b38deb487005fa2a3b6bc99830d075737e7991e861a542d","size":{"x":32,"y":1,"z":32}},{"blockCount":45,"bytes":2162,"file":"chunks/y151-z160-x128.json","offset":{"x":128,"y":151,"z":160},"requirements":{"minecraft:glass":1,"minecraft:polished_diorite":23,"minecraft:stone_bricks":21},"sha256":"fa43efefdd94aeb2cddbc1d35d8c4ab54bf6889351987577c38f2894f9dbbad4","size":{"x":32,"y":1,"z":32}},{"blockCount":28,"bytes":1517,"file":"chunks/y151-z160-x160.json","offset":{"x":160,"y":151,"z":160},"requirements":{"minecraft:polished_diorite":16,"minecraft:stone_bricks":12},"sha256":"a8ba7bdcd06666e428f3816b11b72594554302099ae5ba4d04a24a48830ad932","size":{"x":32,"y":1,"z":32}},{"blockCount":139,"bytes":3327,"file":"chunks/y151-z160-x192.json","offset":{"x":192,"y":151,"z":160},"requirements":{"minecraft:bricks":39,"minecraft:polished_diorite":67,"minecraft:stone_bricks":33},"sha256":"065c312fbeb78fc3b886660250ff052fe5aca211ce166d899e73b0cf77b52e31","size":{"x":32,"y":1,"z":32}},{"blockCount":136,"bytes":3046,"file":"chunks/y151-z160-x224.json","offset":{"x":224,"y":151,"z":160},"requirements":{"minecraft:bricks":45,"minecraft:glass":4,"minecraft:polished_diorite":58,"minecraft:stone_bricks":29},"sha256":"e2dfe8cc0c825925735fb907f6e398f7d1185bbec9a0513e0b4beb6eaa9fe1fd","size":{"x":32,"y":1,"z":32}},{"blockCount":134,"bytes":4029,"file":"chunks/y151-z192-x096.json","offset":{"x":96,"y":151,"z":192},"requirements":{"minecraft:cobbled_deepslate":32,"minecraft:glass":1,"minecraft:oak_planks":36,"minecraft:polished_diorite":37,"minecraft:stone_bricks":28},"sha256":"f8dc10b60661fe60f6b53d775ff2008a7376bbc3b782b20f46bc3d1874663aab","size":{"x":32,"y":1,"z":32}},{"blockCount":33,"bytes":1776,"file":"chunks/y151-z192-x128.json","offset":{"x":128,"y":151,"z":192},"requirements":{"minecraft:glass":1,"minecraft:polished_diorite":16,"minecraft:stone_bricks":16},"sha256":"4346f19f775158adb966a24a0ffa549a083c174f8228a29fbe3b818a6f880d81","size":{"x":32,"y":1,"z":32}},{"blockCount":130,"bytes":4164,"file":"chunks/y152-z064-x096.json","offset":{"x":96,"y":152,"z":64},"requirements":{"minecraft:cobbled_deepslate":57,"minecraft:oak_planks":4,"minecraft:polished_diorite":37,"minecraft:stone_bricks":32},"sha256":"19848c7448a6ad0d12b2e9d87fb283c7e7f5712740620c49ed392ca201f92337","size":{"x":32,"y":1,"z":32}},{"blockCount":37,"bytes":1909,"file":"chunks/y152-z064-x128.json","offset":{"x":128,"y":152,"z":64},"requirements":{"minecraft:polished_diorite":18,"minecraft:stone_bricks":19},"sha256":"08b0ca14d507a1fe8097659fd94449c8cc95c7bb9c2a1ec8be6c70debe400d83","size":{"x":32,"y":1,"z":32}},{"blockCount":16,"bytes":923,"file":"chunks/y152-z064-x192.json","offset":{"x":192,"y":152,"z":64},"requirements":{"minecraft:polished_diorite":6,"minecraft:stone_bricks":10},"sha256":"176bcf45c6083bd57cc66653e2e06f721c8d2b7186c6219799e295678bd930c2","size":{"x":32,"y":1,"z":32}},{"blockCount":16,"bytes":943,"file":"chunks/y152-z064-x224.json","offset":{"x":224,"y":152,"z":64},"requirements":{"minecraft:polished_diorite":6,"minecraft:stone_bricks":10},"sha256":"ed1bb80f185033ed6f894287bdbe241264e918f8fd1e0dc52024462482bc174b","size":{"x":32,"y":1,"z":32}},{"blockCount":1,"bytes":626,"file":"chunks/y152-z096-x000.json","offset":{"x":0,"y":152,"z":96},"requirements":{"minecraft:polished_diorite":1},"sha256":"fc4cadc99a74fceec9a2af9a2475ccd3050495361be9aef8529fda76929983de","size":{"x":32,"y":1,"z":32}},{"blockCount":38,"bytes":1924,"file":"chunks/y152-z096-x032.json","offset":{"x":32,"y":152,"z":96},"requirements":{"minecraft:polished_diorite":20,"minecraft:stone_bricks":18},"sha256":"53994d7f0096096de6ac24ee976e4f4fcc29d0d65d88533023cfa0e55e99862d","size":{"x":32,"y":1,"z":32}},{"blockCount":36,"bytes":1842,"file":"chunks/y152-z096-x064.json","offset":{"x":64,"y":152,"z":96},"requirements":{"minecraft:polished_diorite":17,"minecraft:stone_bricks":19},"sha256":"e042d6d360bacd48bba825ffb35837cf30cb95a37325b2bf6d11608f38ca5d11","size":{"x":32,"y":1,"z":32}},{"blockCount":121,"bytes":4258,"file":"chunks/y152-z096-x096.json","offset":{"x":96,"y":152,"z":96},"requirements":{"minecraft:cobbled_deepslate":80,"minecraft:oak_planks":6,"minecraft:polished_diorite":14,"minecraft:stone_bricks":21},"sha256":"56d069116afcad2b8d8824c3a67105ddb72c0d6bfcd7380aeb02254b4e46759a","size":{"x":32,"y":1,"z":32}},{"blockCount":43,"bytes":2063,"file":"chunks/y152-z096-x128.json","offset":{"x":128,"y":152,"z":96},"requirements":{"minecraft:polished_diorite":22,"minecraft:stone_bricks":21},"sha256":"d92a5104a95311aaa2768ca8e1efc4129f9c7f5a50ed046beea79e0edf6ccee3","size":{"x":32,"y":1,"z":32}},{"blockCount":37,"bytes":1862,"file":"chunks/y152-z096-x160.json","offset":{"x":160,"y":152,"z":96},"requirements":{"minecraft:polished_diorite":18,"minecraft:stone_bricks":19},"sha256":"dd80e26483f6fdcc7ccb4269841e2b3feb6778b3c3e5181250a58568f6516370","size":{"x":32,"y":1,"z":32}},{"blockCount":143,"bytes":3573,"file":"chunks/y152-z096-x192.json","offset":{"x":192,"y":152,"z":96},"requirements":{"minecraft:bricks":39,"minecraft:polished_diorite":63,"minecraft:stone_bricks":41},"sha256":"725fe75fe3661780d03caf0fec415807439c8d9c4f4b12f94d5bc7bd4082d1d2","size":{"x":32,"y":1,"z":32}},{"blockCount":132,"bytes":2931,"file":"chunks/y152-z096-x224.json","offset":{"x":224,"y":152,"z":96},"requirements":{"minecraft:bricks":45,"minecraft:glass":4,"minecraft:polished_diorite":49,"minecraft:stone_bricks":34},"sha256":"f148fcd8585c840c4f9c160503a41e8325312c5e525b93894dc03e4edd075db4","size":{"x":32,"y":1,"z":32}},{"blockCount":1,"bytes":647,"file":"chunks/y152-z128-x000.json","offset":{"x":0,"y":152,"z":128},"requirements":{"minecraft:polished_diorite":1},"sha256":"2cbb4583c39314012d7ee2e30cffdd09698ac966bcfa404f3f2f13966d148f8c","size":{"x":32,"y":1,"z":32}},{"blockCount":115,"bytes":3117,"file":"chunks/y152-z128-x032.json","offset":{"x":32,"y":152,"z":128},"requirements":{"minecraft:cobbled_deepslate":41,"minecraft:glass":8,"minecraft:oak_planks":25,"minecraft:polished_diorite":11,"minecraft:stone_bricks":30},"sha256":"29a7c1e249febf5bac59e2d16d7b31ed055079166dd14b5cebcd3fdfb59c9ca5","size":{"x":32,"y":1,"z":32}},{"blockCount":89,"bytes":1583,"file":"chunks/y152-z128-x064.json","offset":{"x":64,"y":152,"z":128},"requirements":{"minecraft:cobbled_deepslate":71,"minecraft:oak_planks":4,"minecraft:polished_diorite":2,"minecraft:stone_bricks":12},"sha256":"d38a9a766bd7bac628789f8e2b135593c2fef808b6382c523705a3678388be1a","size":{"x":32,"y":1,"z":32}},{"blockCount":157,"bytes":4134,"file":"chunks/y152-z128-x096.json","offset":{"x":96,"y":152,"z":128},"requirements":{"minecraft:cobbled_deepslate":97,"minecraft:glass":24,"minecraft:oak_planks":5,"minecraft:stone_bricks":31},"sha256":"8a960139e72fd23750a6639ec4936049d2b703dd7795f9e4a9e427a456de1184","size":{"x":32,"y":1,"z":32}},{"blockCount":148,"bytes":1872,"file":"chunks/y152-z128-x128.json","offset":{"x":128,"y":152,"z":128},"requirements":{"minecraft:cobbled_deepslate":80,"minecraft:glass":52,"minecraft:oak_planks":4,"minecraft:polished_diorite":1,"minecraft:stone_bricks":11},"sha256":"1e3c1ccb68fb13c279ff980b5dafd42cd4158f572ccba2306196149cdb6661d0","size":{"x":32,"y":1,"z":32}},{"blockCount":139,"bytes":1952,"file":"chunks/y152-z128-x160.json","offset":{"x":160,"y":152,"z":128},"requirements":{"minecraft:cobbled_deepslate":69,"minecraft:glass":50,"minecraft:oak_planks":4,"minecraft:polished_diorite":2,"minecraft:stone_bricks":14},"sha256":"43a1236003853f5ee3a6d9105df7dbfc32304992e1b67857660745342b3d88c7","size":{"x":32,"y":1,"z":32}},{"blockCount":151,"bytes":2387,"file":"chunks/y152-z128-x192.json","offset":{"x":192,"y":152,"z":128},"requirements":{"minecraft:cobbled_deepslate":77,"minecraft:glass":40,"minecraft:oak_planks":6,"minecraft:polished_diorite":7,"minecraft:stone_bricks":21},"sha256":"87a60570978219970435b9d8634167ed9e829a22c329642deed19283a6c5e0b9","size":{"x":32,"y":1,"z":32}},{"blockCount":51,"bytes":1665,"file":"chunks/y152-z128-x224.json","offset":{"x":224,"y":152,"z":128},"requirements":{"minecraft:cobbled_deepslate":7,"minecraft:glass":1,"minecraft:oak_planks":2,"minecraft:polished_diorite":23,"minecraft:stone_bricks":18},"sha256":"776f09bba759ae4df7df486282b43001660fb0f5f46f3a172ed53d8763a24367","size":{"x":32,"y":1,"z":32}},{"blockCount":21,"bytes":1328,"file":"chunks/y152-z160-x032.json","offset":{"x":32,"y":152,"z":160},"requirements":{"minecraft:polished_diorite":13,"minecraft:stone_bricks":8},"sha256":"c3ddbcd152842db7fb6d34957e0eb3a7fb9d023dacdc66f587b40f0dbf5217cb","size":{"x":32,"y":1,"z":32}},{"blockCount":27,"bytes":1498,"file":"chunks/y152-z160-x064.json","offset":{"x":64,"y":152,"z":160},"requirements":{"minecraft:polished_diorite":15,"minecraft:stone_bricks":12},"sha256":"36522ead24434c3ab96d2bde107e7936642015e54c60c642962599e762bcfeec","size":{"x":32,"y":1,"z":32}},{"blockCount":112,"bytes":4316,"file":"chunks/y152-z160-x096.json","offset":{"x":96,"y":152,"z":160},"requirements":{"minecraft:cobbled_deepslate":73,"minecraft:oak_planks":4,"minecraft:polished_diorite":16,"minecraft:stone_bricks":19},"sha256":"d86c0913512b128e3206574018935f7112b548087c9f8de67b49860ca349fde5","size":{"x":32,"y":1,"z":32}},{"blockCount":44,"bytes":2102,"file":"chunks/y152-z160-x128.json","offset":{"x":128,"y":152,"z":160},"requirements":{"minecraft:polished_diorite":23,"minecraft:stone_bricks":21},"sha256":"9468a853b07a0da7f1f0b6a5cc817a357df28d4d67161b46434b18cd1aa6df3e","size":{"x":32,"y":1,"z":32}},{"blockCount":28,"bytes":1517,"file":"chunks/y152-z160-x160.json","offset":{"x":160,"y":152,"z":160},"requirements":{"minecraft:polished_diorite":16,"minecraft:stone_bricks":12},"sha256":"76bfd8e6a8eec6216229f9e4a6e7d0e1bcd486275035d75ab963e0cf47993db0","size":{"x":32,"y":1,"z":32}},{"blockCount":138,"bytes":3384,"file":"chunks/y152-z160-x192.json","offset":{"x":192,"y":152,"z":160},"requirements":{"minecraft:bricks":39,"minecraft:polished_diorite":62,"minecraft:stone_bricks":37},"sha256":"459b64821d62e4359d2f22120cbb688a5788c247d61011a87377e5c2140281a9","size":{"x":32,"y":1,"z":32}},{"blockCount":134,"bytes":2989,"file":"chunks/y152-z160-x224.json","offset":{"x":224,"y":152,"z":160},"requirements":{"minecraft:bricks":45,"minecraft:glass":4,"minecraft:polished_diorite":50,"minecraft:stone_bricks":35},"sha256":"b7926f142d671fbf3dc771302d88adfa2e30bcb03f24f16bee0a737ba2eb0af9","size":{"x":32,"y":1,"z":32}},{"blockCount":113,"bytes":3455,"file":"chunks/y152-z192-x096.json","offset":{"x":96,"y":152,"z":192},"requirements":{"minecraft:cobbled_deepslate":48,"minecraft:oak_planks":4,"minecraft:polished_diorite":37,"minecraft:stone_bricks":24},"sha256":"e82b6c8ae640a280dc2658a9d09e83800fa118bb744785d77a5a53594da18a5b","size":{"x":32,"y":1,"z":32}},{"blockCount":32,"bytes":1718,"file":"chunks/y152-z192-x128.json","offset":{"x":128,"y":152,"z":192},"requirements":{"minecraft:polished_diorite":16,"minecraft:stone_bricks":16},"sha256":"244e809f9dbbf581151148f4a561d9e740389cc4c27e4cf9a25d9990a0fa34c1","size":{"x":32,"y":1,"z":32}},{"blockCount":155,"bytes":4782,"file":"chunks/y153-z064-x096.json","offset":{"x":96,"y":153,"z":64},"requirements":{"minecraft:cobbled_deepslate":50,"minecraft:oak_planks":4,"minecraft:polished_diorite":35,"minecraft:spruce_planks":46,"minecraft:stone_bricks":20},"sha256":"ab1982859a28108fc794c7a18c682e2fddf7cc02ba7678540b4b658db21a9d13","size":{"x":32,"y":1,"z":32}},{"blockCount":28,"bytes":1568,"file":"chunks/y153-z064-x128.json","offset":{"x":128,"y":153,"z":64},"requirements":{"minecraft:polished_diorite":18,"minecraft:stone_bricks":10},"sha256":"0f03b7cdedac7bd69bc2b73ac0dba090b3894687e5f4c508ffa4d574f1b9a403","size":{"x":32,"y":1,"z":32}},{"blockCount":12,"bytes":941,"file":"chunks/y153-z064-x192.json","offset":{"x":192,"y":153,"z":64},"requirements":{"minecraft:polished_diorite":5,"minecraft:stone_bricks":7},"sha256":"9b6e7a0432b7de91a846f47b60557fbda4adc611709601e6b85fcd0a8c471cdb","size":{"x":32,"y":1,"z":32}},{"blockCount":17,"bytes":1000,"file":"chunks/y153-z064-x224.json","offset":{"x":224,"y":153,"z":64},"requirements":{"minecraft:polished_diorite":5,"minecraft:stone_bricks":12},"sha256":"109c456471ea03c0d47dca15afdafc5b3f3cd1bdc373051bfedcefe4254d88ed","size":{"x":32,"y":1,"z":32}},{"blockCount":1,"bytes":626,"file":"chunks/y153-z096-x000.json","offset":{"x":0,"y":153,"z":96},"requirements":{"minecraft:polished_diorite":1},"sha256":"6ef6c80c2d726c5d6b7a22bee99529df1f510c08775ab92e513f2f27d5e60712","size":{"x":32,"y":1,"z":32}},{"blockCount":30,"bytes":1622,"file":"chunks/y153-z096-x032.json","offset":{"x":32,"y":153,"z":96},"requirements":{"minecraft:polished_diorite":20,"minecraft:stone_bricks":10},"sha256":"09e4e1b6d4ba3767af92b3e64d7a5d5fedbeecbe894b110ec32112161cc8ddb6","size":{"x":32,"y":1,"z":32}},{"blockCount":26,"bytes":1465,"file":"chunks/y153-z096-x064.json","offset":{"x":64,"y":153,"z":96},"requirements":{"minecraft:polished_diorite":17,"minecraft:stone_bricks":9},"sha256":"49cb0f026fbd2ab6840300c9343dc32897932181f310a6e3e96e210389992bfe","size":{"x":32,"y":1,"z":32}},{"blockCount":163,"bytes":5142,"file":"chunks/y153-z096-x096.json","offset":{"x":96,"y":153,"z":96},"requirements":{"minecraft:cobbled_deepslate":63,"minecraft:oak_planks":6,"minecraft:polished_diorite":14,"minecraft:spruce_planks":64,"minecraft:stone_bricks":16},"sha256":"4ba9eabc19bc7c35a21d01486ebb4e2e87899635c7b3304c831258531d735f5b","size":{"x":32,"y":1,"z":32}},{"blockCount":33,"bytes":1683,"file":"chunks/y153-z096-x128.json","offset":{"x":128,"y":153,"z":96},"requirements":{"minecraft:polished_diorite":22,"minecraft:stone_bricks":11},"sha256":"510a212800a7a7fd0163b5820601f113e99552e7a71847605101f1b9a3ffb9ec","size":{"x":32,"y":1,"z":32}},{"blockCount":27,"bytes":1485,"file":"chunks/y153-z096-x160.json","offset":{"x":160,"y":153,"z":96},"requirements":{"minecraft:polished_diorite":18,"minecraft:stone_bricks":9},"sha256":"bd33238019d6d385b91065483124e52bacb3670d7a6c3d8a9257877c017d90d5","size":{"x":32,"y":1,"z":32}},{"blockCount":135,"bytes":3346,"file":"chunks/y153-z096-x192.json","offset":{"x":192,"y":153,"z":96},"requirements":{"minecraft:bricks":41,"minecraft:polished_diorite":63,"minecraft:stone_bricks":31},"sha256":"2980eb6cd65ce2896ad956f7f75a76f7badab2bfc58fb98a1552e075a3832749","size":{"x":32,"y":1,"z":32}},{"blockCount":135,"bytes":2914,"file":"chunks/y153-z096-x224.json","offset":{"x":224,"y":153,"z":96},"requirements":{"minecraft:bricks":47,"minecraft:glass":4,"minecraft:polished_diorite":56,"minecraft:stone_bricks":28},"sha256":"c87f13f4bd447b5986ae01c55028317dadd821847b9acce9bd04cb1ad6df3f43","size":{"x":32,"y":1,"z":32}},{"blockCount":1,"bytes":647,"file":"chunks/y153-z128-x000.json","offset":{"x":0,"y":153,"z":128},"requirements":{"minecraft:polished_diorite":1},"sha256":"b42f657e852627a4fa38522e4a18192bb498ca88dfe25fa0c32f1d7c99f03b5f","size":{"x":32,"y":1,"z":32}},{"blockCount":104,"bytes":2729,"file":"chunks/y153-z128-x032.json","offset":{"x":32,"y":153,"z":128},"requirements":{"minecraft:cobbled_deepslate":39,"minecraft:oak_planks":23,"minecraft:polished_diorite":11,"minecraft:spruce_planks":10,"minecraft:stone_bricks":21},"sha256":"03e08ed5de49a00ae24fe180cda3e1642be2a6f62381632c5ee2f623751bb5bf","size":{"x":32,"y":1,"z":32}},{"blockCount":140,"bytes":1730,"file":"chunks/y153-z128-x064.json","offset":{"x":64,"y":153,"z":128},"requirements":{"minecraft:cobbled_deepslate":59,"minecraft:oak_planks":4,"minecraft:polished_diorite":2,"minecraft:spruce_planks":64,"minecraft:stone_bricks":11},"sha256":"159001abeb3ec9dedbebd79873308ba951c29dbbfb9c272f3323210c052aeefb","size":{"x":32,"y":1,"z":32}},{"blockCount":213,"bytes":4769,"file":"chunks/y153-z128-x096.json","offset":{"x":96,"y":153,"z":128},"requirements":{"minecraft:cobbled_deepslate":80,"minecraft:glass":4,"minecraft:oak_planks":5,"minecraft:spruce_planks":92,"minecraft:stone_bricks":32},"sha256":"9a5dfaed966f071b371793db72541ab72bdcafc1acac08040b27b44bbb1b256d","size":{"x":32,"y":1,"z":32}},{"blockCount":142,"bytes":1692,"file":"chunks/y153-z128-x128.json","offset":{"x":128,"y":153,"z":128},"requirements":{"minecraft:cobbled_deepslate":68,"minecraft:oak_planks":4,"minecraft:polished_diorite":1,"minecraft:spruce_planks":64,"minecraft:stone_bricks":5},"sha256":"60a867b6cf34760ece6913db4151e74dad12c4a58f634d2f48b6cb54cf37e631","size":{"x":32,"y":1,"z":32}},{"blockCount":140,"bytes":1734,"file":"chunks/y153-z128-x160.json","offset":{"x":160,"y":153,"z":128},"requirements":{"minecraft:cobbled_deepslate":59,"minecraft:oak_planks":4,"minecraft:polished_diorite":2,"minecraft:spruce_planks":64,"minecraft:stone_bricks":11},"sha256":"9656122fc598ee5a389d701a220728d30f0e0ae3ec2cc63fcc82cc51362d292e","size":{"x":32,"y":1,"z":32}},{"blockCount":159,"bytes":2225,"file":"chunks/y153-z128-x192.json","offset":{"x":192,"y":153,"z":128},"requirements":{"minecraft:cobbled_deepslate":65,"minecraft:glass":4,"minecraft:oak_planks":6,"minecraft:polished_diorite":7,"minecraft:spruce_planks":64,"minecraft:stone_bricks":13},"sha256":"2bc689389ba7b49216acb3bcd5d58538b925d3433919204a3df4eb35f0a3906d","size":{"x":32,"y":1,"z":32}},{"blockCount":52,"bytes":1807,"file":"chunks/y153-z128-x224.json","offset":{"x":224,"y":153,"z":128},"requirements":{"minecraft:cobbled_deepslate":7,"minecraft:oak_planks":2,"minecraft:polished_diorite":21,"minecraft:spruce_planks":4,"minecraft:stone_bricks":18},"sha256":"fff4716d05adac4bbf54826d6b9f3133d737327555aabee0497cde1b77866b91","size":{"x":32,"y":1,"z":32}},{"blockCount":18,"bytes":1215,"file":"chunks/y153-z160-x032.json","offset":{"x":32,"y":153,"z":160},"requirements":{"minecraft:polished_diorite":13,"minecraft:stone_bricks":5},"sha256":"07a38c0c8f72f7597252a0ef851213c1db3d1d8b86d38bfb047bbf1a7c93ca2e","size":{"x":32,"y":1,"z":32}},{"blockCount":22,"bytes":1309,"file":"chunks/y153-z160-x064.json","offset":{"x":64,"y":153,"z":160},"requirements":{"minecraft:polished_diorite":15,"minecraft:stone_bricks":7},"sha256":"d3b325838012e5e42a697448af119c4a3082813e9e41522d5644e331e1adaf38","size":{"x":32,"y":1,"z":32}},{"blockCount":160,"bytes":5238,"file":"chunks/y153-z160-x096.json","offset":{"x":96,"y":153,"z":160},"requirements":{"minecraft:cobbled_deepslate":60,"minecraft:oak_planks":4,"minecraft:polished_diorite":16,"minecraft:spruce_planks":64,"minecraft:stone_bricks":16},"sha256":"5178a21ef1b0a29398e96c33097f599ee7ffbed557699ddf00bed6cef1d5c5ac","size":{"x":32,"y":1,"z":32}},{"blockCount":34,"bytes":1722,"file":"chunks/y153-z160-x128.json","offset":{"x":128,"y":153,"z":160},"requirements":{"minecraft:polished_diorite":23,"minecraft:stone_bricks":11},"sha256":"75f8cb2c2095b2f6183e549cde85b0095b21c4a21453d99a3a4206940f600667","size":{"x":32,"y":1,"z":32}},{"blockCount":23,"bytes":1328,"file":"chunks/y153-z160-x160.json","offset":{"x":160,"y":153,"z":160},"requirements":{"minecraft:polished_diorite":16,"minecraft:stone_bricks":7},"sha256":"da83371d20a0bedf84ad01c6ed59b26141deb973dee51b1c48587769de13b7a6","size":{"x":32,"y":1,"z":32}},{"blockCount":132,"bytes":3252,"file":"chunks/y153-z160-x192.json","offset":{"x":192,"y":153,"z":160},"requirements":{"minecraft:bricks":41,"minecraft:polished_diorite":61,"minecraft:stone_bricks":30},"sha256":"8781b439767ac89f5ee2d1376180dae41af17018cee2249825d2ea73b9ec2260","size":{"x":32,"y":1,"z":32}},{"blockCount":138,"bytes":2991,"file":"chunks/y153-z160-x224.json","offset":{"x":224,"y":153,"z":160},"requirements":{"minecraft:bricks":47,"minecraft:glass":4,"minecraft:polished_diorite":56,"minecraft:stone_bricks":31},"sha256":"54195a2e613cb42ea712fda67e9f8640e23e892601b7bb8ca30b085d9d656559","size":{"x":32,"y":1,"z":32}},{"blockCount":124,"bytes":3845,"file":"chunks/y153-z192-x096.json","offset":{"x":96,"y":153,"z":192},"requirements":{"minecraft:cobbled_deepslate":36,"minecraft:oak_planks":4,"minecraft:polished_diorite":35,"minecraft:spruce_planks":30,"minecraft:stone_bricks":19},"sha256":"8f7502cd72535b79c9c9f0b38b9bfeb96928faae95d2e57599533bd3ad702017","size":{"x":32,"y":1,"z":32}},{"blockCount":25,"bytes":1452,"file":"chunks/y153-z192-x128.json","offset":{"x":128,"y":153,"z":192},"requirements":{"minecraft:polished_diorite":16,"minecraft:stone_bricks":9},"sha256":"f2f21da382398e8aa0583db62f67b183844d12e58ef571710a8c22c3eed1c67b","size":{"x":32,"y":1,"z":32}},{"blockCount":107,"bytes":3688,"file":"chunks/y154-z064-x096.json","offset":{"x":96,"y":154,"z":64},"requirements":{"minecraft:cobbled_deepslate":45,"minecraft:oak_planks":4,"minecraft:polished_diorite":42,"minecraft:stone_bricks":16},"sha256":"ed86663cd3ef6879d0acbd1f0f9e326bb36e350c50e11e37e5a3753f202fc028","size":{"x":32,"y":1,"z":32}},{"blockCount":30,"bytes":1415,"file":"chunks/y154-z064-x128.json","offset":{"x":128,"y":154,"z":64},"requirements":{"minecraft:polished_diorite":27,"minecraft:stone_bricks":3},"sha256":"3cad9f8d006ad98400a0cbca48c632d8f45bab71a99ff9b2411ae312a48c5cbc","size":{"x":32,"y":1,"z":32}},{"blockCount":16,"bytes":1018,"file":"chunks/y154-z064-x192.json","offset":{"x":192,"y":154,"z":64},"requirements":{"minecraft:polished_diorite":6,"minecraft:stone_bricks":10},"sha256":"36fccb19d59954ed390dd1936a2062fce0cb6895d5d74a4285edf90ae9aeecc8","size":{"x":32,"y":1,"z":32}},{"blockCount":21,"bytes":1114,"file":"chunks/y154-z064-x224.json","offset":{"x":224,"y":154,"z":64},"requirements":{"minecraft:polished_diorite":6,"minecraft:stone_bricks":15},"sha256":"189237f515b9e5fe7ab39b08a2132007d9c4508406066889af904808dd6db2e1","size":{"x":32,"y":1,"z":32}},{"blockCount":1,"bytes":626,"file":"chunks/y154-z096-x000.json","offset":{"x":0,"y":154,"z":96},"requirements":{"minecraft:polished_diorite":1},"sha256":"a7bc4d322fbdf848eef556dcfed1fa42888b5cf5eb408aa8e472e0af85548d14","size":{"x":32,"y":1,"z":32}},{"blockCount":33,"bytes":1450,"file":"chunks/y154-z096-x032.json","offset":{"x":32,"y":154,"z":96},"requirements":{"minecraft:polished_diorite":30,"minecraft:stone_bricks":3},"sha256":"f63de9f024c99ce7df52d518635bf4054d5a1cd276582c7dafab1fe044ed6c4d","size":{"x":32,"y":1,"z":32}},{"blockCount":28,"bytes":1294,"file":"chunks/y154-z096-x064.json","offset":{"x":64,"y":154,"z":96},"requirements":{"minecraft:polished_diorite":26,"minecraft:stone_bricks":2},"sha256":"5e1c1996630010f84092a967b599b4d32b4a06720d21feb3bb4c7a7148592bea","size":{"x":32,"y":1,"z":32}},{"blockCount":93,"bytes":3744,"file":"chunks/y154-z096-x096.json","offset":{"x":96,"y":154,"z":96},"requirements":{"minecraft:cobbled_deepslate":57,"minecraft:oak_planks":6,"minecraft:polished_diorite":21,"minecraft:stone_bricks":9},"sha256":"43cfca07830be16d8483888e4a57372bb1d844c3a57f5336fa2eb06fe8cd45e2","size":{"x":32,"y":1,"z":32}},{"blockCount":36,"bytes":1454,"file":"chunks/y154-z096-x128.json","offset":{"x":128,"y":154,"z":96},"requirements":{"minecraft:polished_diorite":33,"minecraft:stone_bricks":3},"sha256":"10303d1a2d6d33e6202dd4e4f1f9383685754913664d5f21f5cb57df04893988","size":{"x":32,"y":1,"z":32}},{"blockCount":29,"bytes":1295,"file":"chunks/y154-z096-x160.json","offset":{"x":160,"y":154,"z":96},"requirements":{"minecraft:polished_diorite":27,"minecraft:stone_bricks":2},"sha256":"7120f95b926f1665e5b5816b726b0f5dceed9a717474120194a59f2c5c98a572","size":{"x":32,"y":1,"z":32}},{"blockCount":149,"bytes":3461,"file":"chunks/y154-z096-x192.json","offset":{"x":192,"y":154,"z":96},"requirements":{"minecraft:bricks":47,"minecraft:polished_diorite":71,"minecraft:stone_bricks":31},"sha256":"81e2312d2f9f7ccf94d46f0ba605ebcaac4c324da249ea36e84fd10f60e0c77f","size":{"x":32,"y":1,"z":32}},{"blockCount":150,"bytes":3104,"file":"chunks/y154-z096-x224.json","offset":{"x":224,"y":154,"z":96},"requirements":{"minecraft:bricks":54,"minecraft:glass":4,"minecraft:polished_diorite":60,"minecraft:stone_bricks":32},"sha256":"5502313fcc442dda36c0ffa17e141d23785609c482dbd4b053f9ce745f484b53","size":{"x":32,"y":1,"z":32}},{"blockCount":1,"bytes":647,"file":"chunks/y154-z128-x000.json","offset":{"x":0,"y":154,"z":128},"requirements":{"minecraft:polished_diorite":1},"sha256":"2acb87c44094893e69c567519c3b3b4d2619952e3338e56f0858ece7f1b6940a","size":{"x":32,"y":1,"z":32}},{"blockCount":78,"bytes":2105,"file":"chunks/y154-z128-x032.json","offset":{"x":32,"y":154,"z":128},"requirements":{"minecraft:cobbled_deepslate":30,"minecraft:oak_planks":21,"minecraft:polished_diorite":18,"minecraft:stone_bricks":9},"sha256":"78a94663da5e4238ce37d9677f9a8ae0b6f525a172a37e9a790bed8f066933f8","size":{"x":32,"y":1,"z":32}},{"blockCount":72,"bytes":1276,"file":"chunks/y154-z128-x064.json","offset":{"x":64,"y":154,"z":128},"requirements":{"minecraft:cobbled_deepslate":58,"minecraft:oak_planks":4,"minecraft:polished_diorite":4,"minecraft:stone_bricks":6},"sha256":"da85128fd9478fad4a30bbdfd77b491b907822df7dc33d8cdb030cd2c42f9bc3","size":{"x":32,"y":1,"z":32}},{"blockCount":121,"bytes":3411,"file":"chunks/y154-z128-x096.json","offset":{"x":96,"y":154,"z":128},"requirements":{"minecraft:cobbled_deepslate":85,"minecraft:glass":4,"minecraft:oak_planks":5,"minecraft:stone_bricks":27},"sha256":"c2b80ddc69357812949fb1b8cb7b031a9ee277a9aa8b41a9b6817ee4ade56703","size":{"x":32,"y":1,"z":32}},{"blockCount":70,"bytes":1234,"file":"chunks/y154-z128-x128.json","offset":{"x":128,"y":154,"z":128},"requirements":{"minecraft:cobbled_deepslate":58,"minecraft:oak_planks":4,"minecraft:polished_diorite":2,"minecraft:stone_bricks":6},"sha256":"8f2e094598abdbf97de7db805eb4f3b2e4b551665b6c095f97c5c5a71b09180f","size":{"x":32,"y":1,"z":32}},{"blockCount":72,"bytes":1315,"file":"chunks/y154-z128-x160.json","offset":{"x":160,"y":154,"z":128},"requirements":{"minecraft:cobbled_deepslate":57,"minecraft:oak_planks":4,"minecraft:polished_diorite":4,"minecraft:stone_bricks":7},"sha256":"13d14558f7a096b311b9b9c27947bccd9f9a5a221437c45a23a268abdf2bd075","size":{"x":32,"y":1,"z":32}},{"blockCount":95,"bytes":1927,"file":"chunks/y154-z128-x192.json","offset":{"x":192,"y":154,"z":128},"requirements":{"minecraft:cobbled_deepslate":61,"minecraft:glass":4,"minecraft:oak_planks":6,"minecraft:polished_diorite":9,"minecraft:stone_bricks":15},"sha256":"0ea924ffb284a78ca210ecbbc5fdcb858ba19bc0fce06833f8f3ae65579a887a","size":{"x":32,"y":1,"z":32}},{"blockCount":52,"bytes":1701,"file":"chunks/y154-z128-x224.json","offset":{"x":224,"y":154,"z":128},"requirements":{"minecraft:cobbled_deepslate":8,"minecraft:oak_planks":2,"minecraft:polished_diorite":19,"minecraft:stone_bricks":23},"sha256":"caaf9e75827839cb750ef982f73d7416460ec776da99bf6249c74912c9a248d7","size":{"x":32,"y":1,"z":32}}],"schema":1}
