{"entries":[{"blockCount":20,"bytes":1101,"file":"chunks/y154-z160-x032.json","offset":{"x":32,"y":154,"z":160},"requirements":{"minecraft:polished_diorite":18,"minecraft:stone_bricks":2},"sha256":"b44858eb2780ddb2c400b70929f66d8c736b41475927e979f6e2bd07a7e22e36","size":{"x":32,"y":1,"z":32}},{"blockCount":24,"bytes":1138,"file":"chunks/y154-z160-x064.json","offset":{"x":64,"y":154,"z":160},"requirements":{"minecraft:polished_diorite":22,"minecraft:stone_bricks":2},"sha256":"247a2807f02073282719d41d8a54608ef579ea5935d3132a4a2f7bb47d13eb22","size":{"x":32,"y":1,"z":32}},{"blockCount":94,"bytes":3840,"file":"chunks/y154-z160-x096.json","offset":{"x":96,"y":154,"z":160},"requirements":{"minecraft:cobbled_deepslate":59,"minecraft:oak_planks":4,"minecraft:polished_diorite":24,"minecraft:stone_bricks":7},"sha256":"49ef6213b741e40fc6a44aca3d899ea3c2aa059f095497399640e51e2100bd13","size":{"x":32,"y":1,"z":32}},{"blockCount":37,"bytes":1493,"file":"chunks/y154-z160-x128.json","offset":{"x":128,"y":154,"z":160},"requirements":{"minecraft:polished_diorite":34,"minecraft:stone_bricks":3},"sha256":"ace792364f69daca4c61ea1ae539ffb3ce8e28d2133b5af25ec51cdc2f17fcf1","size":{"x":32,"y":1,"z":32}},{"blockCount":25,"bytes":1138,"file":"chunks/y154-z160-x160.json","offset":{"x":160,"y":154,"z":160},"requirements":{"minecraft:polished_diorite":23,"minecraft:stone_bricks":2},"sha256":"b753e7efee5b6a5efdd96631a91b19d0f34667c03707b7fb8b3ddfc462764da6","size":{"x":32,"y":1,"z":32}},{"blockCount":146,"bytes":3347,"file":"chunks/y154-z160-x192.json","offset":{"x":192,"y":154,"z":160},"requirements":{"minecraft:bricks":47,"minecraft:polished_diorite":68,"minecraft:stone_bricks":31},"sha256":"11c666a245732e35a26fcba1b5cffd44831b88d7f81ac6f3d26fc2eceb57f0eb","size":{"x":32,"y":1,"z":32}},{"blockCount":153,"bytes":3200,"file":"chunks/y154-z160-x224.json","offset":{"x":224,"y":154,"z":160},"requirements":{"minecraft:bricks":54,"minecraft:glass":4,"minecraft:polished_diorite":61,"minecraft:stone_bricks":34},"sha256":"840b7c4f9f4822c77618aead2ce38c6e0781a27062cb1dd1209b6f7a03de6b3e","size":{"x":32,"y":1,"z":32}},{"blockCount":90,"bytes":3036,"file":"chunks/y154-z192-x096.json","offset":{"x":96,"y":154,"z":192},"requirements":{"minecraft:cobbled_deepslate":33,"minecraft:oak_planks":4,"minecraft:polished_diorite":39,"minecraft:stone_bricks":14},"sha256":"8396a12c9dbf8eee5316a80a136cf4468e07080891fd08440db89b7a7c612713","size":{"x":32,"y":1,"z":32}},{"blockCount":27,"bytes":1300,"file":"chunks/y154-z192-x128.json","offset":{"x":128,"y":154,"z":192},"requirements":{"minecraft:polished_diorite":24,"minecraft:stone_bricks":3},"sha256":"255cbc1d3f748c8f7cde22f095cb2667a2f954b11c69bb24ef1dcc67095677a1","size":{"x":32,"y":1,"z":32}},{"blockCount":141,"bytes":4496,"file":"chunks/y155-z064-x096.json","offset":{"x":96,"y":155,"z":64},"requirements":{"minecraft:cobbled_deepslate":46,"minecraft:glass":2,"minecraft:oak_planks":4,"minecraft:polished_diorite":33,"minecraft:spruce_planks":46,"minecraft:stone_bricks":10},"sha256":"e8850037c0b73324054e123bf4e62b1ce9ea560e858e19f1c33656bd95173a7c","size":{"x":32,"y":1,"z":32}},{"blockCount":20,"bytes":1181,"file":"chunks/y155-z064-x128.json","offset":{"x":128,"y":155,"z":64},"requirements":{"minecraft:polished_diorite":18,"minecraft:stone_bricks":2},"sha256":"f96d5352e60f4c8bfd0e3ddc2299502a83947134df699c6f170d3b6355e0f3c1","size":{"x":32,"y":1,"z":32}},{"blockCount":24,"bytes":886,"file":"chunks/y155-z064-x192.json","offset":{"x":192,"y":155,"z":64},"requirements":{"minecraft:polished_diorite":6,"minecraft:stone_bricks":18},"sha256":"55088e4a82bc7960bcdff28e495111876a44ba3411814805b35a8b974c98be2a","size":{"x":32,"y":1,"z":32}},{"blockCount":30,"bytes":945,"file":"chunks/y155-z064-x224.json","offset":{"x":224,"y":155,"z":64},"requirements":{"minecraft:polished_diorite":6,"minecraft:stone_bricks":24},"sha256":"adeb4b592aa0108e5e85384021fde1975386eb358c3ba8600db26ca92ac99d6d","size":{"x":32,"y":1,"z":32}},{"blockCount":24,"bytes":1255,"file":"chunks/y155-z096-x032.json","offset":{"x":32,"y":155,"z":96},"requirements":{"minecraft:polished_diorite":21,"minecraft:stone_bricks":3},"sha256":"b62728693cd75b2be7bc4f21d15c825adf0e60016d0f8cff39881eabce90158f","size":{"x":32,"y":1,"z":32}},{"blockCount":19,"bytes":1138,"file":"chunks/y155-z096-x064.json","offset":{"x":64,"y":155,"z":96},"requirements":{"minecraft:polished_diorite":17,"minecraft:stone_bricks":2},"sha256":"9c01c43e499eee971d7f37770ac0e70076c00946377bca81ef4bf36dbdf670b0","size":{"x":32,"y":1,"z":32}},{"blockCount":154,"bytes":4991,"file":"chunks/y155-z096-x096.json","offset":{"x":96,"y":155,"z":96},"requirements":{"minecraft:cobbled_deepslate":56,"minecraft:glass":4,"minecraft:oak_planks":6,"minecraft:polished_diorite":14,"minecraft:spruce_planks":64,"minecraft:stone_bricks":10},"sha256":"eb63ea6bb02c3641057229c4f03ad91ad48d86fbeea616cc4517242ed6a75058","size":{"x":32,"y":1,"z":32}},{"blockCount":25,"bytes":1259,"file":"chunks/y155-z096-x128.json","offset":{"x":128,"y":155,"z":96},"requirements":{"minecraft:polished_diorite":22,"minecraft:stone_bricks":3},"sha256":"cec2c3b5ea02270136e88d0d148777bc40f8bc664bf5558d1f86f715c2943e91","size":{"x":32,"y":1,"z":32}},{"blockCount":20,"bytes":1139,"file":"chunks/y155-z096-x160.json","offset":{"x":160,"y":155,"z":96},"requirements":{"minecraft:polished_diorite":18,"minecraft:stone_bricks":2},"sha256":"11cf63d9359f99ddade98efeb3fb84986c051f75539152ce8f42a77db001509d","size":{"x":32,"y":1,"z":32}},{"blockCount":177,"bytes":3386,"file":"chunks/y155-z096-x192.json","offset":{"x":192,"y":155,"z":96},"requirements":{"minecraft:bricks":35,"minecraft:polished_diorite":90,"minecraft:stone_bricks":52},"sha256":"5c059be434f4d69649b453b96ce77891aac8da3b04443b25aa8a8dc2c9dd1838","size":{"x":32,"y":1,"z":32}},{"blockCount":182,"bytes":3161,"file":"chunks/y155-z096-x224.json","offset":{"x":224,"y":155,"z":96},"requirements":{"minecraft:bricks":41,"minecraft:glass":4,"minecraft:polished_diorite":84,"minecraft:stone_bricks":53},"sha256":"2a8de8c8d5f894a1413b3dab7ec623fff8dcc53e331ebead08a07ffa8b1e567c","size":{"x":32,"y":1,"z":32}},{"blockCount":84,"bytes":2189,"file":"chunks/y155-z128-x032.json","offset":{"x":32,"y":155,"z":128},"requirements":{"minecraft:cobbled_deepslate":29,"minecraft:glass":2,"minecraft:oak_planks":21,"minecraft:polished_diorite":12,"minecraft:spruce_planks":8,"minecraft:stone_bricks":12},"sha256":"a0c3619a078d2ad9bf1d002af1f81bcee5d966a9f5946d2911e630b2955f9ebb","size":{"x":32,"y":1,"z":32}},{"blockCount":136,"bytes":1499,"file":"chunks/y155-z128-x064.json","offset":{"x":64,"y":155,"z":128},"requirements":{"minecraft:cobbled_deepslate":59,"minecraft:glass":2,"minecraft:oak_planks":4,"minecraft:polished_diorite":2,"minecraft:spruce_planks":64,"minecraft:stone_bricks":5},"sha256":"684861b446b27a443ae32146976f4b6a67037097a9dab50c983606e7ae3c125a","size":{"x":32,"y":1,"z":32}},{"blockCount":217,"bytes":4581,"file":"chunks/y155-z128-x096.json","offset":{"x":96,"y":155,"z":128},"requirements":{"minecraft:cobbled_deepslate":84,"minecraft:glass":8,"minecraft:oak_planks":5,"minecraft:spruce_planks":92,"minecraft:stone_bricks":28},"sha256":"e292b05398f0127ec7847c49154068fe08f13317a447671b573a4879df1cda16","size":{"x":32,"y":1,"z":32}},{"blockCount":137,"bytes":1593,"file":"chunks/y155-z128-x128.json","offset":{"x":128,"y":155,"z":128},"requirements":{"minecraft:cobbled_deepslate":58,"minecraft:glass":4,"minecraft:oak_planks":4,"minecraft:polished_diorite":1,"minecraft:spruce_planks":64,"minecraft:stone_bricks":6},"sha256":"36607afe6a50f7831f3935c007a76ea1413724c72be903e7fac949ae6248a6b1","size":{"x":32,"y":1,"z":32}},{"blockCount":136,"bytes":1540,"file":"chunks/y155-z128-x160.json","offset":{"x":160,"y":155,"z":128},"requirements":{"minecraft:cobbled_deepslate":57,"minecraft:glass":2,"minecraft:oak_planks":4,"minecraft:polished_diorite":2,"minecraft:spruce_planks":64,"minecraft:stone_bricks":7},"sha256":"4c4b13da3890f202cbf8b024764ebfcd366f7dd9373b73cb5891a9c83f98ef74","size":{"x":32,"y":1,"z":32}},{"blockCount":166,"bytes":2090,"file":"chunks/y155-z128-x192.json","offset":{"x":192,"y":155,"z":128},"requirements":{"minecraft:cobbled_deepslate":56,"minecraft:glass":6,"minecraft:oak_planks":6,"minecraft:polished_diorite":8,"minecraft:spruce_planks":64,"minecraft:stone_bricks":26},"sha256":"12893d8b835ced6f723958e10e21b2db50e6aaefea38a0892e3b531827e70cd3","size":{"x":32,"y":1,"z":32}},{"blockCount":60,"bytes":1652,"file":"chunks/y155-z128-x224.json","offset":{"x":224,"y":155,"z":128},"requirements":{"minecraft:cobbled_deepslate":6,"minecraft:oak_planks":2,"minecraft:polished_diorite":21,"minecraft:spruce_planks":4,"minecraft:stone_bricks":27},"sha256":"7c14328319118b7d5522d1ec3c0c592ce4aeb3e4b5ad72f6e10f1634361079db","size":{"x":32,"y":1,"z":32}},{"blockCount":15,"bytes":1023,"file":"chunks/y155-z160-x032.json","offset":{"x":32,"y":155,"z":160},"requirements":{"minecraft:polished_diorite":13,"minecraft:stone_bricks":2},"sha256":"11c2271b73ff22d7a1839d97928fac67f432dc23c26d7e2708a5912d4ab87a1a","size":{"x":32,"y":1,"z":32}},{"blockCount":17,"bytes":1060,"file":"chunks/y155-z160-x064.json","offset":{"x":64,"y":155,"z":160},"requirements":{"minecraft:polished_diorite":15,"minecraft:stone_bricks":2},"sha256":"0c8ab2b0741179d60867c723b01eab153456feacca42922bd8e45428cf099c81","size":{"x":32,"y":1,"z":32}},{"blockCount":152,"bytes":4991,"file":"chunks/y155-z160-x096.json","offset":{"x":96,"y":155,"z":160},"requirements":{"minecraft:cobbled_deepslate":58,"minecraft:glass":2,"minecraft:oak_planks":4,"minecraft:polished_diorite":16,"minecraft:spruce_planks":64,"minecraft:stone_bricks":8},"sha256":"b7c4a9bed8b606e00668d93ff02874c9d0928e245f2b0b423cbee5854ddfa3ac","size":{"x":32,"y":1,"z":32}},{"blockCount":26,"bytes":1299,"file":"chunks/y155-z160-x128.json","offset":{"x":128,"y":155,"z":160},"requirements":{"minecraft:polished_diorite":23,"minecraft:stone_bricks":3},"sha256":"897a79523a23046d46e560583795fbb8dd564d4772517c70130579c1a8b981cc","size":{"x":32,"y":1,"z":32}},{"blockCount":18,"bytes":1060,"file":"chunks/y155-z160-x160.json","offset":{"x":160,"y":155,"z":160},"requirements":{"minecraft:polished_diorite":16,"minecraft:stone_bricks":2},"sha256":"d64f867ff500b76f95730d67112260e97de98af726231b4da898867eee7cc33c","size":{"x":32,"y":1,"z":32}},{"blockCount":175,"bytes":3310,"file":"chunks/y155-z160-x192.json","offset":{"x":192,"y":155,"z":160},"requirements":{"minecraft:bricks":35,"minecraft:polished_diorite":88,"minecraft:stone_bricks":52},"sha256":"b055b936adced3ee8d2d00f9ec451afc7e66652631713fbc7775cf58ea1a779b","size":{"x":32,"y":1,"z":32}},{"blockCount":185,"bytes":3200,"file":"chunks/y155-z160-x224.json","offset":{"x":224,"y":155,"z":160},"requirements":{"minecraft:bricks":41,"minecraft:glass":4,"minecraft:polished_diorite":84,"minecraft:stone_bricks":56},"sha256":"7e38c733126f92c696868e7ff3020caa459e736941434b809fa1d01ac11d5476","size":{"x":32,"y":1,"z":32}},{"blockCount":111,"bytes":3616,"file":"chunks/y155-z192-x096.json","offset":{"x":96,"y":155,"z":192},"requirements":{"minecraft:cobbled_deepslate":32,"minecraft:glass":2,"minecraft:oak_planks":4,"minecraft:polished_diorite":31,"minecraft:spruce_planks":32,"minecraft:stone_bricks":10},"sha256":"3a6fe9f294c25c3140604690a5299f010873858aff94c62d027607c769eb82da","size":{"x":32,"y":1,"z":32}},{"blockCount":18,"bytes":1105,"file":"chunks/y155-z192-x128.json","offset":{"x":128,"y":155,"z":192},"requirements":{"minecraft:polished_diorite":16,"minecraft:stone_bricks":2},"sha256":"af78184a8b6faab1483fb1366ca5ead23ee3ae96774a350a2f51ba8391913a05","size":{"x":32,"y":1,"z":32}},{"blockCount":101,"bytes":3602,"file":"chunks/y156-z064-x096.json","offset":{"x":96,"y":156,"z":64},"requirements":{"minecraft:cobbled_deepslate":48,"minecraft:glass":2,"minecraft:oak_planks":4,"minecraft:polished_diorite":20,"minecraft:spruce_planks":2,"minecraft:stone_bricks":25},"sha256":"3099cd2d8a0be1efb63809f9d85d7bd79e3652bbd5b3f671dfec1aeed76193b6","size":{"x":32,"y":1,"z":32}},{"blockCount":20,"bytes":1181,"file":"chunks/y156-z064-x128.json","offset":{"x":128,"y":156,"z":64},"requirements":{"minecraft:polished_diorite":9,"minecraft:stone_bricks":11},"sha256":"b78c5ca874de331b1b3b6b77878a4fbfabed40b270affa70e3ded72664074b68","size":{"x":32,"y":1,"z":32}},{"blockCount":10,"bytes":944,"file":"chunks/y156-z064-x192.json","offset":{"x":192,"y":156,"z":64},"requirements":{"minecraft:polished_diorite":5,"minecraft:stone_bricks":5},"sha256":"64170e8458287cc4db226eccd8d395d9a2bf3b446e3f762f5ce811882c1db66d","size":{"x":32,"y":1,"z":32}},{"blockCount":14,"bytes":1059,"file":"chunks/y156-z064-x224.json","offset":{"x":224,"y":156,"z":64},"requirements":{"minecraft:polished_diorite":7,"minecraft:stone_bricks":7},"sha256":"de1d2c65b69e1df031c61d6f7798ae3cb08b4863543bee1d2cd56017af3a0522","size":{"x":32,"y":1,"z":32}},{"blockCount":24,"bytes":1237,"file":"chunks/y156-z096-x032.json","offset":{"x":32,"y":156,"z":96},"requirements":{"minecraft:polished_diorite":10,"minecraft:stone_bricks":14},"sha256":"231bb069bb3169361ca2cfcb76c99296e17e7f05d841a89c636c4d8f5be9ab18","size":{"x":32,"y":1,"z":32}},{"blockCount":19,"bytes":1138,"file":"chunks/y156-z096-x064.json","offset":{"x":64,"y":156,"z":96},"requirements":{"minecraft:polished_diorite":9,"minecraft:stone_bricks":10},"sha256":"a08e23a52d1154aa5d74487bb7ed4c8a3fa7235a4b46d937cc25c43ad446acc8","size":{"x":32,"y":1,"z":32}},{"blockCount":102,"bytes":3849,"file":"chunks/y156-z096-x096.json","offset":{"x":96,"y":156,"z":96},"requirements":{"minecraft:cobbled_deepslate":64,"minecraft:glass":4,"minecraft:oak_planks":6,"minecraft:polished_diorite":7,"minecraft:spruce_planks":4,"minecraft:stone_bricks":17},"sha256":"c8ab5aae634eca3654bdeb873fcdc2a626c17fdb8b7f6dc09a25d32214a14f51","size":{"x":32,"y":1,"z":32}},{"blockCount":25,"bytes":1260,"file":"chunks/y156-z096-x128.json","offset":{"x":128,"y":156,"z":96},"requirements":{"minecraft:polished_diorite":11,"minecraft:stone_bricks":14},"sha256":"7185bf26f8f57b1dd963320a4ee6b55f871f2468e7533f811682f878d256ff2e","size":{"x":32,"y":1,"z":32}},{"blockCount":20,"bytes":1158,"file":"chunks/y156-z096-x160.json","offset":{"x":160,"y":156,"z":96},"requirements":{"minecraft:polished_diorite":9,"minecraft:stone_bricks":11},"sha256":"077ed0eae039578f09c11c71ec282fd1465b53dc25cd780defade57b7ad6493b","size":{"x":32,"y":1,"z":32}},{"blockCount":122,"bytes":3766,"file":"chunks/y156-z096-x192.json","offset":{"x":192,"y":156,"z":96},"requirements":{"minecraft:bricks":29,"minecraft:polished_diorite":58,"minecraft:stone_bricks":35},"sha256":"5cbba1d35964b69d902cf4be2220df155b2fde59594d8c99d87651752bca894f","size":{"x":32,"y":1,"z":32}},{"blockCount":129,"bytes":4033,"file":"chunks/y156-z096-x224.json","offset":{"x":224,"y":156,"z":96},"requirements":{"minecraft:bricks":35,"minecraft:glass":4,"minecraft:polished_diorite":53,"minecraft:stone_bricks":37},"sha256":"f6cde786a2f345faa5b527581b9fb135f6534117e49590fa28849578ceb93fa9","size":{"x":32,"y":1,"z":32}},{"blockCount":76,"bytes":2074,"file":"chunks/y156-z128-x032.json","offset":{"x":32,"y":156,"z":128},"requirements":{"minecraft:cobbled_deepslate":30,"minecraft:glass":2,"minecraft:oak_planks":21,"minecraft:polished_diorite":7,"minecraft:spruce_planks":2,"minecraft:stone_bricks":14},"sha256":"487ea59301498c9777a64b1d938e268f9c39ed7c6b2b796c353806dd78943156","size":{"x":32,"y":1,"z":32}},{"blockCount":78,"bytes":1554,"file":"chunks/y156-z128-x064.json","offset":{"x":64,"y":156,"z":128},"requirements":{"minecraft:cobbled_deepslate":60,"minecraft:glass":2,"minecraft:oak_planks":4,"minecraft:polished_diorite":2,"minecraft:spruce_planks":2,"minecraft:stone_bricks":8},"sha256":"a15fcc20156ca2e2137b9b5df8caad06a3b11bbaa5ae0350e4d0d333aa549409","size":{"x":32,"y":1,"z":32}},{"blockCount":141,"bytes":3972,"file":"chunks/y156-z128-x096.json","offset":{"x":96,"y":156,"z":128},"requirements":{"minecraft:cobbled_deepslate":91,"minecraft:glass":8,"minecraft:oak_planks":5,"minecraft:spruce_planks":4,"minecraft:stone_bricks":33},"sha256":"6fa06c756c26b7fbcd809de6104ab173199e1e16b6086818bc6068e0c9169405","size":{"x":32,"y":1,"z":32}},{"blockCount":85,"bytes":1801,"file":"chunks/y156-z128-x128.json","offset":{"x":128,"y":156,"z":128},"requirements":{"minecraft:cobbled_deepslate":59,"minecraft:glass":4,"minecraft:oak_planks":4,"minecraft:polished_diorite":1,"minecraft:spruce_planks":4,"minecraft:stone_bricks":13},"sha256":"f89d81a5e94cef034a41178d74c100bd2ae6a1f65f888be259c3c900e6afd46a","size":{"x":32,"y":1,"z":32}},{"blockCount":78,"bytes":1537,"file":"chunks/y156-z128-x160.json","offset":{"x":160,"y":156,"z":128},"requirements":{"minecraft:cobbled_deepslate":59,"minecraft:glass":2,"minecraft:oak_planks":4,"minecraft:polished_diorite":2,"minecraft:spruce_planks":2,"minecraft:stone_bricks":9},"sha256":"a847274ffd5da4c35e9029805c336960c8178029f822720541357bb12a839310","size":{"x":32,"y":1,"z":32}},{"blockCount":92,"bytes":1993,"file":"chunks/y156-z128-x192.json","offset":{"x":192,"y":156,"z":128},"requirements":{"minecraft:cobbled_deepslate":59,"minecraft:glass":6,"minecraft:oak_planks":6,"minecraft:polished_diorite":9,"minecraft:spruce_planks":2,"minecraft:stone_bricks":10},"sha256":"e4f6c5e7f553af801ebb1ccc2ecf6165900959aa78a8fb02b73d077ddb7a939d","size":{"x":32,"y":1,"z":32}},{"blockCount":40,"bytes":1568,"file":"chunks/y156-z128-x224.json","offset":{"x":224,"y":156,"z":128},"requirements":{"minecraft:cobbled_deepslate":7,"minecraft:oak_planks":2,"minecraft:polished_diorite":16,"minecraft:stone_bricks":15},"sha256":"3293ebff14be11690796f2d06c32404b1b9649a99698aa7e8a3c1aabbfd16ebc","size":{"x":32,"y":1,"z":32}},{"blockCount":15,"bytes":1004,"file":"chunks/y156-z160-x032.json","offset":{"x":32,"y":156,"z":160},"requirements":{"minecraft:polished_diorite":5,"minecraft:stone_bricks":10},"sha256":"d3ebd43bbe85b5e56f201e7cb8cd51d43a4d094802be7698d20324b8438bcbed","size":{"x":32,"y":1,"z":32}},{"blockCount":17,"bytes":1060,"file":"chunks/y156-z160-x064.json","offset":{"x":64,"y":156,"z":160},"requirements":{"minecraft:polished_diorite":7,"minecraft:stone_bricks":10},"sha256":"dbfa6489e89125abdc9fc791aa70437af519499646437f035613a8a9ac73866a","size":{"x":32,"y":1,"z":32}},{"blockCount":94,"bytes":3812,"file":"chunks/y156-z160-x096.json","offset":{"x":96,"y":156,"z":160},"requirements":{"minecraft:cobbled_deepslate":59,"minecraft:glass":2,"minecraft:oak_planks":4,"minecraft:polished_diorite":8,"minecraft:spruce_planks":2,"minecraft:stone_bricks":19},"sha256":"308da9b189f8bd07742ed73138dceb3d0caff7b08f616f855523ee12e7c20195","size":{"x":32,"y":1,"z":32}},{"blockCount":26,"bytes":1300,"file":"chunks/y156-z160-x128.json","offset":{"x":128,"y":156,"z":160},"requirements":{"minecraft:polished_diorite":11,"minecraft:stone_bricks":15},"sha256":"ab41e80b7027e65d3e781e6df170b4361dbbd261c442e2386cc25b6fab5ae63a","size":{"x":32,"y":1,"z":32}},{"blockCount":18,"bytes":1079,"file":"chunks/y156-z160-x160.json","offset":{"x":160,"y":156,"z":160},"requirements":{"minecraft:polished_diorite":7,"minecraft:stone_bricks":11},"sha256":"bd1b39f4afee62699d9d3f5e246bfdb4571cad816c46e0ad7273abe7aaa6f5ee","size":{"x":32,"y":1,"z":32}},{"blockCount":122,"bytes":3730,"file":"chunks/y156-z160-x192.json","offset":{"x":192,"y":156,"z":160},"requirements":{"minecraft:bricks":29,"minecraft:polished_diorite":54,"minecraft:stone_bricks":39},"sha256":"f266749b3e83d018236d4c14d43490f2c49ce4c8e4f0edbde9442155bd09ae8a","size":{"x":32,"y":1,"z":32}},{"blockCount":132,"bytes":4129,"file":"chunks/y156-z160-x224.json","offset":{"x":224,"y":156,"z":160},"requirements":{"minecraft:bricks":35,"minecraft:glass":4,"minecraft:polished_diorite":55,"minecraft:stone_bricks":38},"sha256":"af4c9bf98a8044015ced6f03adcdde65dac13410d31ed0a76eca746f694707de","size":{"x":32,"y":1,"z":32}},{"blockCount":85,"bytes":2969,"file":"chunks/y156-z192-x096.json","offset":{"x":96,"y":156,"z":192},"requirements":{"minecraft:cobbled_deepslate":36,"minecraft:glass":2,"minecraft:oak_planks":4,"minecraft:polished_diorite":19,"minecraft:spruce_planks":2,"minecraft:stone_bricks":22},"sha256":"d2918ba3456d1a82f38080e8c14f735f25ded12c7b5e6736e27f3b8e89f3d24a","size":{"x":32,"y":1,"z":32}},{"blockCount":18,"bytes":1105,"file":"chunks/y156-z192-x128.json","offset":{"x":128,"y":156,"z":192},"requirements":{"minecraft:polished_diorite":8,"minecraft:stone_bricks":10},"sha256":"9db95a52f82e77a1c714f424b9dd5e2de1b1c652125b9ad795f5d977ff4b5a8f","size":{"x":32,"y":1,"z":32}},{"blockCount":147,"bytes":4477,"file":"chunks/y157-z064-x096.json","offset":{"x":96,"y":157,"z":64},"requirements":{"minecraft:cobbled_deepslate":46,"minecraft:glass":2,"minecraft:oak_planks":4,"minecraft:polished_diorite":22,"minecraft:spruce_planks":46,"minecraft:stone_bricks":27},"sha256":"ebd9fd1dd13f7f22e5e3295cb638512ca4664c4a82997b4c30de1dbc3f259d7b","size":{"x":32,"y":1,"z":32}},{"blockCount":20,"bytes":1181,"file":"chunks/y157-z064-x128.json","offset":{"x":128,"y":157,"z":64},"requirements":{"minecraft:polished_diorite":9,"minecraft:stone_bricks":11},"sha256":"963f3aacde720de7941ac2a64b7d009ce69cb8cb59eee724a49ad1da93fc89a7","size":{"x":32,"y":1,"z":32}},{"blockCount":10,"bytes":944,"file":"chunks/y157-z064-x192.json","offset":{"x":192,"y":157,"z":64},"requirements":{"minecraft:polished_diorite":5,"minecraft:stone_bricks":5},"sha256":"f3776d90050bca0ebaea9e139154b29bae8d4daaf71a879d34226a03576d70ce","size":{"x":32,"y":1,"z":32}},{"blockCount":12,"bytes":1022,"file":"chunks/y157-z064-x224.json","offset":{"x":224,"y":157,"z":64},"requirements":{"minecraft:polished_diorite":5,"minecraft:stone_bricks":7},"sha256":"e51747a2fc9c18b94967cfbddcdb86e836e327aed707c9ed1cc5c404ed6d7784","size":{"x":32,"y":1,"z":32}},{"blockCount":24,"bytes":1237,"file":"chunks/y157-z096-x032.json","offset":{"x":32,"y":157,"z":96},"requirements":{"minecraft:polished_diorite":10,"minecraft:stone_bricks":14},"sha256":"397db3b42b0f5065985c62d2c67e63dfeda45e64b4fe399514d20458722f2b70","size":{"x":32,"y":1,"z":32}},{"blockCount":19,"bytes":1138,"file":"chunks/y157-z096-x064.json","offset":{"x":64,"y":157,"z":96},"requirements":{"minecraft:polished_diorite":9,"minecraft:stone_bricks":10},"sha256":"3b73c1f14cc42ca0bc3fed02f6f3b40fba27b9021f24128f2a328a97d3e89c5e","size":{"x":32,"y":1,"z":32}},{"blockCount":162,"bytes":5085,"file":"chunks/y157-z096-x096.json","offset":{"x":96,"y":157,"z":96},"requirements":{"minecraft:cobbled_deepslate":58,"minecraft:glass":4,"minecraft:oak_planks":6,"minecraft:polished_diorite":7,"minecraft:spruce_planks":64,"minecraft:stone_bricks":23},"sha256":"0f087b929f27bc7a012c8c3226f644112f6857f28db5144a8e63a9594808a659","size":{"x":32,"y":1,"z":32}},{"blockCount":25,"bytes":1260,"file":"chunks/y157-z096-x128.json","offset":{"x":128,"y":157,"z":96},"requirements":{"minecraft:polished_diorite":11,"minecraft:stone_bricks":14},"sha256":"d6b264f0aec4ea99cc472a1cbabe4596ab5e3563fb583ec1959b5b0a6f318afc","size":{"x":32,"y":1,"z":32}},{"blockCount":20,"bytes":1158,"file":"chunks/y157-z096-x160.json","offset":{"x":160,"y":157,"z":96},"requirements":{"minecraft:polished_diorite":9,"minecraft:stone_bricks":11},"sha256":"50ccc20fe3f2525d5d1078aa950ce09fb5b7bf02c87478fb1bb0ab9fa8f2e410","size":{"x":32,"y":1,"z":32}},{"blockCount":129,"bytes":3802,"file":"chunks/y157-z096-x192.json","offset":{"x":192,"y":157,"z":96},"requirements":{"minecraft:bricks":29,"minecraft:polished_diorite":53,"minecraft:stone_bricks":47},"sha256":"e3bd1bc5622c79f334a02d5f25628ef662ebedf2c5e401fde0723a816322d707","size":{"x":32,"y":1,"z":32}},{"blockCount":141,"bytes":3976,"file":"chunks/y157-z096-x224.json","offset":{"x":224,"y":157,"z":96},"requirements":{"minecraft:bricks":35,"minecraft:glass":4,"minecraft:polished_diorite":49,"minecraft:stone_bricks":53},"sha256":"28bbf44504c575d4d2fb57efd66bc9a17b8963e50ee9343e1784c8726b829870","size":{"x":32,"y":1,"z":32}},{"blockCount":82,"bytes":2245,"file":"chunks/y157-z128-x032.json","offset":{"x":32,"y":157,"z":128},"requirements":{"minecraft:cobbled_deepslate":32,"minecraft:glass":2,"minecraft:oak_planks":19,"minecraft:polished_diorite":7,"minecraft:spruce_planks":6,"minecraft:stone_bricks":16},"sha256":"7092a5ecd0210f846516c7a3aab83ef60b7ac644d6699adaee0b4ae07a01f839","size":{"x":32,"y":1,"z":32}},{"blockCount":140,"bytes":1749,"file":"chunks/y157-z128-x064.json","offset":{"x":64,"y":157,"z":128},"requirements":{"minecraft:cobbled_deepslate":58,"minecraft:glass":2,"minecraft:oak_planks":4,"minecraft:polished_diorite":2,"minecraft:spruce_planks":64,"minecraft:stone_bricks":10},"sha256":"27fd62a00a16432a7a0fc3f798dfed937c7195d8edc98686e2a256d385159fd2","size":{"x":32,"y":1,"z":32}},{"blockCount":225,"bytes":4905,"file":"chunks/y157-z128-x096.json","offset":{"x":96,"y":157,"z":128},"requirements":{"minecraft:cobbled_deepslate":86,"minecraft:glass":8,"minecraft:oak_planks":5,"minecraft:spruce_planks":84,"minecraft:stone_bricks":42},"sha256":"a5e948929a8e2f4716f85d8c6c3875ccee984216f48048eff0a3ad7378af2982","size":{"x":32,"y":1,"z":32}},{"blockCount":145,"bytes":1993,"file":"chunks/y157-z128-x128.json","offset":{"x":128,"y":157,"z":128},"requirements":{"minecraft:cobbled_deepslate":60,"minecraft:glass":4,"minecraft:oak_planks":4,"minecraft:polished_diorite":1,"minecraft:spruce_planks":64,"minecraft:stone_bricks":12},"sha256":"b1bf899d91e22663cd9115a2c3a65d67302d2b2333746b290996e4e40cc0c3e3","size":{"x":32,"y":1,"z":32}},{"blockCount":140,"bytes":1674,"file":"chunks/y157-z128-x160.json","offset":{"x":160,"y":157,"z":128},"requirements":{"minecraft:cobbled_deepslate":60,"minecraft:glass":2,"minecraft:oak_planks":4,"minecraft:polished_diorite":2,"minecraft:spruce_planks":64,"minecraft:stone_bricks":8},"sha256":"5ec4a604c627a9127807e7581131ac2c960a6faa4676814100b5afcb1aa4ca69","size":{"x":32,"y":1,"z":32}},{"blockCount":151,"bytes":2124,"file":"chunks/y157-z128-x192.json","offset":{"x":192,"y":157,"z":128},"requirements":{"minecraft:cobbled_deepslate":58,"minecraft:glass":4,"minecraft:oak_planks":6,"minecraft:polished_diorite":8,"minecraft:spruce_planks":64,"minecraft:stone_bricks":11},"sha256":"ffb6253db334d8d354d43af1ad3b039d2c065e97ff3bd570c338403cae7adeb4","size":{"x":32,"y":1,"z":32}},{"blockCount":47,"bytes":1750,"file":"chunks/y157-z128-x224.json","offset":{"x":224,"y":157,"z":128},"requirements":{"minecraft:cobbled_deepslate":7,"minecraft:oak_planks":2,"minecraft:polished_diorite":19,"minecraft:spruce_planks":4,"minecraft:stone_bricks":15},"sha256":"70d9b1ce814b689ae04bbdee2d65c7d150d1e829fd44cc09a9feea8c30dcceff","size":{"x":32,"y":1,"z":32}},{"blockCount":15,"bytes":1004,"file":"chunks/y157-z160-x032.json","offset":{"x":32,"y":157,"z":160},"requirements":{"minecraft:polished_diorite":5,"minecraft:stone_bricks":10},"sha256":"b6bd30408b99bc36b5e4cc4cad4338f2bb88ea10b7bb1fd743b2886b4972ec13","size":{"x":32,"y":1,"z":32}},{"blockCount":17,"bytes":1060,"file":"chunks/y157-z160-x064.json","offset":{"x":64,"y":157,"z":160},"requirements":{"minecraft:polished_diorite":7,"minecraft:stone_bricks":10},"sha256":"463deac78cdaaccaa7a3ecf4f0952291292ab43d4dc67cce0db10c05a9f700a1","size":{"x":32,"y":1,"z":32}},{"blockCount":156,"bytes":5029,"file":"chunks/y157-z160-x096.json","offset":{"x":96,"y":157,"z":160},"requirements":{"minecraft:cobbled_deepslate":55,"minecraft:glass":2,"minecraft:oak_planks":4,"minecraft:polished_diorite":8,"minecraft:spruce_planks":64,"minecraft:stone_bricks":23},"sha256":"b5e84fd0b08519f345b5f934235a9067be91e583ad11e0fd89679160826178ec","size":{"x":32,"y":1,"z":32}},{"blockCount":26,"bytes":1300,"file":"chunks/y157-z160-x128.json","offset":{"x":128,"y":157,"z":160},"requirements":{"minecraft:polished_diorite":11,"minecraft:stone_bricks":15},"sha256":"068c1c35e9adb268118fb8c90599e22fccc41420106560fc3f66e98d5d4d9945","size":{"x":32,"y":1,"z":32}},{"blockCount":18,"bytes":1079,"file":"chunks/y157-z160-x160.json","offset":{"x":160,"y":157,"z":160},"requirements":{"minecraft:polished_diorite":7,"minecraft:stone_bricks":11},"sha256":"1df7693627cdfcbfc2962ec4dfa107f4e660fdd6af6ddb425d04937c4dfea790","size":{"x":32,"y":1,"z":32}},{"blockCount":130,"bytes":3805,"file":"chunks/y157-z160-x192.json","offset":{"x":192,"y":157,"z":160},"requirements":{"minecraft:bricks":29,"minecraft:polished_diorite":50,"minecraft:stone_bricks":51},"sha256":"fb8fbeac8a178c05ff951617030846041a81889d5f11444c88db73979a921fc2","size":{"x":32,"y":1,"z":32}},{"blockCount":142,"bytes":4016,"file":"chunks/y157-z160-x224.json","offset":{"x":224,"y":157,"z":160},"requirements":{"minecraft:bricks":35,"minecraft:glass":4,"minecraft:polished_diorite":49,"minecraft:stone_bricks":54},"sha256":"4e82d8466c617981a571b9d8058d3c61cb80a670695f8b97c40071553cc49bd2","size":{"x":32,"y":1,"z":32}},{"blockCount":117,"bytes":3578,"file":"chunks/y157-z192-x096.json","offset":{"x":96,"y":157,"z":192},"requirements":{"minecraft:cobbled_deepslate":34,"minecraft:glass":2,"minecraft:oak_planks":4,"minecraft:polished_diorite":21,"minecraft:spruce_planks":32,"minecraft:stone_bricks":24},"sha256":"70936b792c2227db976a2120034ba307fcc20f4b88579f740971e59c6614c612","size":{"x":32,"y":1,"z":32}},{"blockCount":18,"bytes":1105,"file":"chunks/y157-z192-x128.json","offset":{"x":128,"y":157,"z":192},"requirements":{"minecraft:polished_diorite":8,"minecraft:stone_bricks":10},"sha256":"0b3707cba296f3b45335223cc3c2145559cfb0c6cb20ec6cb140c004042d7120","size":{"x":32,"y":1,"z":32}},{"blockCount":103,"bytes":3459,"file":"chunks/y158-z064-x096.json","offset":{"x":96,"y":158,"z":64},"requirements":{"minecraft:cobbled_deepslate":59,"minecraft:oak_planks":4,"minecraft:polished_diorite":25,"minecraft:stone_bricks":15},"sha256":"3a599ef91adb6c72b4e31328a2ab9443e255776e90c0225f3dbb967d055a700b","size":{"x":32,"y":1,"z":32}},{"blockCount":20,"bytes":1181,"file":"chunks/y158-z064-x128.json","offset":{"x":128,"y":158,"z":64},"requirements":{"minecraft:polished_diorite":18,"minecraft:stone_bricks":2},"sha256":"22a7d6d39492d8316053c908175e94dc1f1a52d8e1adc78ef2374c253c9811ae","size":{"x":32,"y":1,"z":32}},{"blockCount":10,"bytes":944,"file":"chunks/y158-z064-x192.json","offset":{"x":192,"y":158,"z":64},"requirements":{"minecraft:polished_diorite":5,"minecraft:stone_bricks":5},"sha256":"e04194aa97b674350f47e5f071272379e53cbe246d4ed9a5d1f938a012cfb8a7","size":{"x":32,"y":1,"z":32}},{"blockCount":11,"bytes":984,"file":"chunks/y158-z064-x224.json","offset":{"x":224,"y":158,"z":64},"requirements":{"minecraft:polished_diorite":5,"minecraft:stone_bricks":6},"sha256":"de4e5b9a84ca8fa98f4181b7b55ff69abbd594aa2785e98324b731e83848f47b","size":{"x":32,"y":1,"z":32}},{"blockCount":24,"bytes":1255,"file":"chunks/y158-z096-x032.json","offset":{"x":32,"y":158,"z":96},"requirements":{"minecraft:polished_diorite":21,"minecraft:stone_bricks":3},"sha256":"683748e951b7371689f9c8e31b3ceca5c2d7498792d43a8fbbf61df069a0c0cb","size":{"x":32,"y":1,"z":32}},{"blockCount":19,"bytes":1138,"file":"chunks/y158-z096-x064.json","offset":{"x":64,"y":158,"z":96},"requirements":{"minecraft:polished_diorite":17,"minecraft:stone_bricks":2},"sha256":"1ed50cebca1125045314153bdaaf452db91e1f3fca3d9393bc8000d4efebbc08","size":{"x":32,"y":1,"z":32}},{"blockCount":110,"bytes":3707,"file":"chunks/y158-z096-x096.json","offset":{"x":96,"y":158,"z":96},"requirements":{"minecraft:cobbled_deepslate":75,"minecraft:oak_planks":6,"minecraft:polished_diorite":14,"minecraft:stone_bricks":15},"sha256":"debb591ad945fb10b21c5fc5c4a5c506448b8c963f7af3172e8707d30b43c7e5","size":{"x":32,"y":1,"z":32}},{"blockCount":25,"bytes":1259,"file":"chunks/y158-z096-x128.json","offset":{"x":128,"y":158,"z":96},"requirements":{"minecraft:polished_diorite":22,"minecraft:stone_bricks":3},"sha256":"706bd32f865111fdb4c5188a0748b85383e6991099381efdea87ad68a25563f3","size":{"x":32,"y":1,"z":32}},{"blockCount":20,"bytes":1139,"file":"chunks/y158-z096-x160.json","offset":{"x":160,"y":158,"z":96},"requirements":{"minecraft:polished_diorite":18,"minecraft:stone_bricks":2},"sha256":"6c0158cf69f1df6da2ccc92e6bec131c350f83f29dd25cadbca140a6de9cbffe","size":{"x":32,"y":1,"z":32}},{"blockCount":120,"bytes":3822,"file":"chunks/y158-z096-x192.json","offset":{"x":192,"y":158,"z":96},"requirements":{"minecraft:bricks":29,"minecraft:polished_diorite":60,"minecraft:stone_bricks":31},"sha256":"2fd77703956a6e7e8dc3c2a12c459f8c6d0cb9ba12ce43b75cd3134be01bcd13","size":{"x":32,"y":1,"z":32}},{"blockCount":127,"bytes":4033,"file":"chunks/y158-z096-x224.json","offset":{"x":224,"y":158,"z":96},"requirements":{"minecraft:bricks":35,"minecraft:glass":4,"minecraft:polished_diorite":49,"minecraft:stone_bricks":39},"sha256":"945d5c808ed8b54a3a23ce74f752a4cd00bdf0ea3eb3c5d3e09984316233b0d3","size":{"x":32,"y":1,"z":32}},{"blockCount":70,"bytes":1759,"file":"chunks/y158-z128-x032.json","offset":{"x":32,"y":158,"z":128},"requirements":{"minecraft:cobbled_deepslate":34,"minecraft:oak_planks":17,"minecraft:polished_diorite":12,"minecraft:stone_bricks":7},"sha256":"a22b68f083a244e79a1a13a31fbabd29d7c7c1be713091021b0b9ca750d89c07","size":{"x":32,"y":1,"z":32}},{"blockCount":82,"bytes":1428,"file":"chunks/y158-z128-x064.json","offset":{"x":64,"y":158,"z":128},"requirements":{"minecraft:cobbled_deepslate":69,"minecraft:oak_planks":4,"minecraft:polished_diorite":2,"minecraft:stone_bricks":7},"sha256":"7d8be9398bf9505474f734c482e8a64b9657a48f31d7dbb434efd2a7a3567a5c","size":{"x":32,"y":1,"z":32}},{"blockCount":153,"bytes":3714,"file":"chunks/y158-z128-x096.json","offset":{"x":96,"y":158,"z":128},"requirements":{"minecraft:cobbled_deepslate":99,"minecraft:glass":4,"minecraft:oak_planks":5,"minecraft:stone_bricks":45},"sha256":"48a4dbd5fa57ef6c8fb500f6f6fddfc4568d7b6073e7a9d9660936d2c86a176a","size":{"x":32,"y":1,"z":32}},{"blockCount":93,"bytes":1351,"file":"chunks/y158-z128-x128.json","offset":{"x":128,"y":158,"z":128},"requirements":{"minecraft:cobbled_deepslate":84,"minecraft:oak_planks":4,"minecraft:polished_diorite":1,"minecraft:stone_bricks":4},"sha256":"43f0891255a9fc28516749e7c233519e49cfb38517d739276a21573b1e913077","size":{"x":32,"y":1,"z":32}},{"blockCount":82,"bytes":1431,"file":"chunks/y158-z128-x160.json","offset":{"x":160,"y":158,"z":128},"requirements":{"minecraft:cobbled_deepslate":68,"minecraft:oak_planks":4,"minecraft:polished_diorite":2,"minecraft:stone_bricks":8},"sha256":"0b076e8a6f3d9ab7a0b596531510e472cdc25db785d4a99f942e280dec5152d9","size":{"x":32,"y":1,"z":32}},{"blockCount":93,"bytes":1904,"file":"chunks/y158-z128-x192.json","offset":{"x":192,"y":158,"z":128},"requirements":{"minecraft:cobbled_deepslate":65,"minecraft:glass":2,"minecraft:oak_planks":6,"minecraft:polished_diorite":8,"minecraft:stone_bricks":12},"sha256":"e9cc64c0019bd0e311c09d496137bb0524c704bf2c15f1f387972bd9ffe3cd67","size":{"x":32,"y":1,"z":32}},{"blockCount":38,"bytes":1549,"file":"chunks/y158-z128-x224.json","offset":{"x":224,"y":158,"z":128},"requirements":{"minecraft:cobbled_deepslate":7,"minecraft:oak_planks":2,"minecraft:polished_diorite":13,"minecraft:stone_bricks":16},"sha256":"8ab23222cae224f2ff42d6e4eeb45436be758847ee7f2d3db141301f5d15a826","size":{"x":32,"y":1,"z":32}},{"blockCount":15,"bytes":1023,"file":"chunks/y158-z160-x032.json","offset":{"x":32,"y":158,"z":160},"requirements":{"minecraft:polished_diorite":13,"minecraft:stone_bricks":2},"sha256":"ed7441818c8feeb50b0a4a25435778c55acbd3a09d1f71350213d826b929d51c","size":{"x":32,"y":1,"z":32}},{"blockCount":17,"bytes":1060,"file":"chunks/y158-z160-x064.json","offset":{"x":64,"y":158,"z":160},"requirements":{"minecraft:polished_diorite":15,"minecraft:stone_bricks":2},"sha256":"b677d4c8b758883239c76945340f3e59e60292285e5a4b038a69d90ea3ed9cc3","size":{"x":32,"y":1,"z":32}},{"blockCount":98,"bytes":3765,"file":"chunks/y158-z160-x096.json","offset":{"x":96,"y":158,"z":160},"requirements":{"minecraft:cobbled_deepslate":66,"minecraft:oak_planks":4,"minecraft:polished_diorite":16,"minecraft:stone_bricks":12},"sha256":"e1daa9f7a5372fb6165a06e312581ff8b292d60f35bdcc30f092c760ff528016","size":{"x":32,"y":1,"z":32}},{"blockCount":26,"bytes":1299,"file":"chunks/y158-z160-x128.json","offset":{"x":128,"y":158,"z":160},"requirements":{"minecraft:polished_diorite":23,"minecraft:stone_bricks":3},"sha256":"17d2d8eaf41995a1f710a4ce6c47d0336b7c3248725028a6f2be49596b007371","size":{"x":32,"y":1,"z":32}},{"blockCount":18,"bytes":1060,"file":"chunks/y158-z160-x160.json","offset":{"x":160,"y":158,"z":160},"requirements":{"minecraft:polished_diorite":16,"minecraft:stone_bricks":2},"sha256":"87425cf412468647308d2a44711bb9642f32fc64792c025a56f0422b8bac0721","size":{"x":32,"y":1,"z":32}},{"blockCount":121,"bytes":3825,"file":"chunks/y158-z160-x192.json","offset":{"x":192,"y":158,"z":160},"requirements":{"minecraft:bricks":29,"minecraft:polished_diorite":57,"minecraft:stone_bricks":35},"sha256":"d77577362c5956385fa020b20dbe5c261e82d9affd7a099aa142ac6a42451bb0","size":{"x":32,"y":1,"z":32}},{"blockCount":128,"bytes":4073,"file":"chunks/y158-z160-x224.json","offset":{"x":224,"y":158,"z":160},"requirements":{"minecraft:bricks":35,"minecraft:glass":4,"minecraft:polished_diorite":49,"minecraft:stone_bricks":40},"sha256":"3be4da79a7f611a57724dc833bbdf853c61c5905948fe0abe0f585e518d1cbfe","size":{"x":32,"y":1,"z":32}},{"blockCount":88,"bytes":2902,"file":"chunks/y158-z192-x096.json","offset":{"x":96,"y":158,"z":192},"requirements":{"minecraft:cobbled_deepslate":44,"minecraft:oak_planks":4,"minecraft:polished_diorite":24,"minecraft:stone_bricks":16},"sha256":"38449d5ba47314d24cc73299a57dcc1046711c5f0caefb3b7fb7c7b5eeb06c9a","size":{"x":32,"y":1,"z":32}},{"blockCount":18,"bytes":1105,"file":"chunks/y158-z192-x128.json","offset":{"x":128,"y":158,"z":192},"requirements":{"minecraft:polished_diorite":16,"minecraft:stone_bricks":2},"sha256":"0d4ac7e360e9ba815c1147640b8b8ddf97d388ed0a08b789ef925b8eb52746ca","size":{"x":32,"y":1,"z":32}},{"blockCount":85,"bytes":3258,"file":"chunks/y159-z064-x096.json","offset":{"x":96,"y":159,"z":64},"requirements":{"minecraft:cobbled_deepslate":47,"minecraft:oak_planks":4,"minecraft:polished_diorite":19,"minecraft:spruce_planks":2,"minecraft:stone_bricks":13},"sha256":"183826db2e3740c3cc05cf383e46dcc4526ecca550ee6daf797eb318a1f54e10","size":{"x":32,"y":1,"z":32}},{"blockCount":11,"bytes":986,"file":"chunks/y159-z064-x128.json","offset":{"x":128,"y":159,"z":64},"requirements":{"minecraft:polished_diorite":9,"minecraft:stone_bricks":2},"sha256":"29480f80a4a7d7c650ab0ce7548cd18e5a2e4ce4b0db1c48bd06e8bc94dbf7ab","size":{"x":32,"y":1,"z":32}},{"blockCount":7,"bytes":827,"file":"chunks/y159-z064-x192.json","offset":{"x":192,"y":159,"z":64},"requirements":{"minecraft:polished_diorite":5,"minecraft:stone_bricks":2},"sha256":"a65883f425f2916e480ff3fa5ead8af9fb133ac5462baa7b2da12cb19b2d7550","size":{"x":32,"y":1,"z":32}},{"blockCount":8,"bytes":867,"file":"chunks/y159-z064-x224.json","offset":{"x":224,"y":159,"z":64},"requirements":{"minecraft:polished_diorite":5,"minecraft:stone_bricks":3},"sha256":"f6a1d4b8c3801ac344de73e8c0095c2738dd87eb3240b0bb5a3e8348fc4bcfbd","size":{"x":32,"y":1,"z":32}},{"blockCount":14,"bytes":1062,"file":"chunks/y159-z096-x032.json","offset":{"x":32,"y":159,"z":96},"requirements":{"minecraft:polished_diorite":11,"minecraft:stone_bricks":3},"sha256":"cdadeb6ee229fb32eafea91511eb99c2ef433d3c9c21b5be964fce24f563b520","size":{"x":32,"y":1,"z":32}},{"blockCount":10,"bytes":945,"file":"chunks/y159-z096-x064.json","offset":{"x":64,"y":159,"z":96},"requirements":{"minecraft:polished_diorite":8,"minecraft:stone_bricks":2},"sha256":"320317516eeb29e10b30ce0cfbf3a08b300b152a57639b6f855e1f027f82ce02","size":{"x":32,"y":1,"z":32}},{"blockCount":90,"bytes":3581,"file":"chunks/y159-z096-x096.json","offset":{"x":96,"y":159,"z":96},"requirements":{"minecraft:cobbled_deepslate":68,"minecraft:oak_planks":6,"minecraft:polished_diorite":7,"minecraft:spruce_planks":3,"minecraft:stone_bricks":6},"sha256":"99c4ff73442abed19524be1eacae9b724e72afee120d634baab9399c71b7f5a1","size":{"x":32,"y":1,"z":32}},{"blockCount":14,"bytes":1064,"file":"chunks/y159-z096-x128.json","offset":{"x":128,"y":159,"z":96},"requirements":{"minecraft:polished_diorite":11,"minecraft:stone_bricks":3},"sha256":"e92b79bb8b596eaeab62d399b59e529ca5c4f384d8715a6b0717dab53eea5d39","size":{"x":32,"y":1,"z":32}},{"blockCount":11,"bytes":984,"file":"chunks/y159-z096-x160.json","offset":{"x":160,"y":159,"z":96},"requirements":{"minecraft:polished_diorite":9,"minecraft:stone_bricks":2},"sha256":"ced5e43c7f6c0f2cbb196227d271811fd0c880b150f3af5e8ee340d6f2cc0ba1","size":{"x":32,"y":1,"z":32}},{"blockCount":115,"bytes":3670,"file":"chunks/y159-z096-x192.json","offset":{"x":192,"y":159,"z":96},"requirements":{"minecraft:bricks":29,"minecraft:polished_diorite":48,"minecraft:stone_bricks":38},"sha256":"603f3a59c633deda010e558e429a09d672ec82dd0f3403808eae8660461e3b64","size":{"x":32,"y":1,"z":32}},{"blockCount":126,"bytes":3822,"file":"chunks/y159-z096-x224.json","offset":{"x":224,"y":159,"z":96},"requirements":{"minecraft:bricks":35,"minecraft:glass":4,"minecraft:polished_diorite":45,"minecraft:stone_bricks":42},"sha256":"184c6a2014cf93f38599281be7481f03f6681c355de957bf97755a5a2d79f1cb","size":{"x":32,"y":1,"z":32}}],"schema":1}
