{"entries":[{"blockCount":56,"bytes":1554,"file":"chunks/y159-z128-x032.json","offset":{"x":32,"y":159,"z":128},"requirements":{"minecraft:cobbled_deepslate":28,"minecraft:oak_planks":17,"minecraft:polished_diorite":5,"minecraft:spruce_planks":1,"minecraft:stone_bricks":5},"sha256":"45fcefb543c2d3d8ac11e91f77e9e69f68550371b04f3c45628baf2e2a0ddd28","size":{"x":32,"y":1,"z":32}},{"blockCount":74,"bytes":1313,"file":"chunks/y159-z128-x064.json","offset":{"x":64,"y":159,"z":128},"requirements":{"minecraft:cobbled_deepslate":64,"minecraft:oak_planks":4,"minecraft:spruce_planks":2,"minecraft:stone_bricks":4},"sha256":"1b81494295df11107c366c11e0718d5ba5bba2bf2fc91087c241e20c9b4d464c","size":{"x":32,"y":1,"z":32}},{"blockCount":155,"bytes":3705,"file":"chunks/y159-z128-x096.json","offset":{"x":96,"y":159,"z":128},"requirements":{"minecraft:cobbled_deepslate":85,"minecraft:glass":4,"minecraft:oak_planks":5,"minecraft:spruce_planks":2,"minecraft:stone_bricks":59},"sha256":"aba065c37518fbf7b901e6237bd9ee85bbd6b709c1d8934b1e7572ede7296154","size":{"x":32,"y":1,"z":32}},{"blockCount":78,"bytes":1505,"file":"chunks/y159-z128-x128.json","offset":{"x":128,"y":159,"z":128},"requirements":{"minecraft:cobbled_deepslate":66,"minecraft:oak_planks":4,"minecraft:spruce_planks":2,"minecraft:stone_bricks":6},"sha256":"33f4ee9ff53c4aad9e8a6a96938c783232bb8f0ff353c1ad3e030e3947b371be","size":{"x":32,"y":1,"z":32}},{"blockCount":74,"bytes":1391,"file":"chunks/y159-z128-x160.json","offset":{"x":160,"y":159,"z":128},"requirements":{"minecraft:cobbled_deepslate":61,"minecraft:oak_planks":4,"minecraft:spruce_planks":2,"minecraft:stone_bricks":7},"sha256":"3ec1017c19d3fb90af4211feba9d1396badc5685092169220c09dbd7d2f14641","size":{"x":32,"y":1,"z":32}},{"blockCount":84,"bytes":1665,"file":"chunks/y159-z128-x192.json","offset":{"x":192,"y":159,"z":128},"requirements":{"minecraft:cobbled_deepslate":62,"minecraft:oak_planks":6,"minecraft:polished_diorite":5,"minecraft:spruce_planks":3,"minecraft:stone_bricks":8},"sha256":"fe0bf129adcb50255cb6f42e1c816b4f02e8f3d475e4ed7ca5553917680b9fe3","size":{"x":32,"y":1,"z":32}},{"blockCount":32,"bytes":1303,"file":"chunks/y159-z128-x224.json","offset":{"x":224,"y":159,"z":128},"requirements":{"minecraft:cobbled_deepslate":7,"minecraft:oak_planks":2,"minecraft:polished_diorite":15,"minecraft:spruce_planks":1,"minecraft:stone_bricks":7},"sha256":"6980487cc204b3f453e75f2436a8797531d432e71c3b5648059b7628577210db","size":{"x":32,"y":1,"z":32}},{"blockCount":10,"bytes":945,"file":"chunks/y159-z160-x032.json","offset":{"x":32,"y":159,"z":160},"requirements":{"minecraft:polished_diorite":8,"minecraft:stone_bricks":2},"sha256":"2c21bf792083ea3aab8c9efa1f10a4bb0f476b5c15e1cc2a579354aa49e1a4de","size":{"x":32,"y":1,"z":32}},{"blockCount":10,"bytes":945,"file":"chunks/y159-z160-x064.json","offset":{"x":64,"y":159,"z":160},"requirements":{"minecraft:polished_diorite":8,"minecraft:stone_bricks":2},"sha256":"6dddf369369700591824b75c91b1eb72cb67e9bf7bc1877d70a4931b96ab4dc3","size":{"x":32,"y":1,"z":32}},{"blockCount":84,"bytes":3563,"file":"chunks/y159-z160-x096.json","offset":{"x":96,"y":159,"z":160},"requirements":{"minecraft:cobbled_deepslate":63,"minecraft:oak_planks":4,"minecraft:polished_diorite":8,"minecraft:spruce_planks":2,"minecraft:stone_bricks":7},"sha256":"20a10a7e7b177526426c32d6c630053a165baacfb7079f9efcbdc3e13cad1ceb","size":{"x":32,"y":1,"z":32}},{"blockCount":15,"bytes":1104,"file":"chunks/y159-z160-x128.json","offset":{"x":128,"y":159,"z":160},"requirements":{"minecraft:polished_diorite":12,"minecraft:stone_bricks":3},"sha256":"0015a5b71ece06b48e63aee71ce6899015e04434532eb8a053fb770e91593358","size":{"x":32,"y":1,"z":32}},{"blockCount":11,"bytes":983,"file":"chunks/y159-z160-x160.json","offset":{"x":160,"y":159,"z":160},"requirements":{"minecraft:polished_diorite":9,"minecraft:stone_bricks":2},"sha256":"4580bb7f3cb04e8cca883ea41776d800bd2705cdd988629836e7f8770697ca4e","size":{"x":32,"y":1,"z":32}},{"blockCount":115,"bytes":3614,"file":"chunks/y159-z160-x192.json","offset":{"x":192,"y":159,"z":160},"requirements":{"minecraft:bricks":29,"minecraft:polished_diorite":48,"minecraft:stone_bricks":38},"sha256":"08485b2ecd841909c9b7f0be76d6f2f2a612aeab5c6958821fc74af1e557f7c3","size":{"x":32,"y":1,"z":32}},{"blockCount":127,"bytes":3862,"file":"chunks/y159-z160-x224.json","offset":{"x":224,"y":159,"z":160},"requirements":{"minecraft:bricks":35,"minecraft:glass":4,"minecraft:polished_diorite":45,"minecraft:stone_bricks":43},"sha256":"1a149a1a51f772bd2fc0c9228f5786cc20da93073ed73850f60569bbc3411aa9","size":{"x":32,"y":1,"z":32}},{"blockCount":70,"bytes":2681,"file":"chunks/y159-z192-x096.json","offset":{"x":96,"y":159,"z":192},"requirements":{"minecraft:cobbled_deepslate":37,"minecraft:oak_planks":4,"minecraft:polished_diorite":18,"minecraft:spruce_planks":2,"minecraft:stone_bricks":9},"sha256":"14388e9f6d5ae16f0779465c85e77cc835bcf5b14efd0bb64f92d158f158651c","size":{"x":32,"y":1,"z":32}},{"blockCount":10,"bytes":948,"file":"chunks/y159-z192-x128.json","offset":{"x":128,"y":159,"z":192},"requirements":{"minecraft:polished_diorite":8,"minecraft:stone_bricks":2},"sha256":"07af722e23ebc1512daeb704b2d14c497696da8be462d4d41c02a7a59f21cf64","size":{"x":32,"y":1,"z":32}},{"blockCount":75,"bytes":3154,"file":"chunks/y160-z064-x096.json","offset":{"x":96,"y":160,"z":64},"requirements":{"minecraft:cobbled_deepslate":50,"minecraft:oak_planks":2,"minecraft:polished_diorite":13,"minecraft:stone_bricks":10},"sha256":"92ac411da4341961a29665bbee80bf43b00b0ed77f37f6db1ac885e858504837","size":{"x":32,"y":1,"z":32}},{"blockCount":11,"bytes":986,"file":"chunks/y160-z064-x128.json","offset":{"x":128,"y":160,"z":64},"requirements":{"minecraft:polished_diorite":9,"minecraft:stone_bricks":2},"sha256":"ec8af61e3fe84f8f0982179e8e2cc04fbaee0f38b1b1c292ca704ed4bdc67b2d","size":{"x":32,"y":1,"z":32}},{"blockCount":6,"bytes":788,"file":"chunks/y160-z064-x192.json","offset":{"x":192,"y":160,"z":64},"requirements":{"minecraft:polished_diorite":5,"minecraft:stone_bricks":1},"sha256":"26bd4a8619c40b655b53a6f96e223356baa54ac5edf2e4a7cbc76e7bb5bc0ad8","size":{"x":32,"y":1,"z":32}},{"blockCount":7,"bytes":828,"file":"chunks/y160-z064-x224.json","offset":{"x":224,"y":160,"z":64},"requirements":{"minecraft:polished_diorite":5,"minecraft:stone_bricks":2},"sha256":"6923b83066efe14d017c0c4ceb2c02523c1ea42b0505c725a65d40f27db72cb1","size":{"x":32,"y":1,"z":32}},{"blockCount":14,"bytes":1062,"file":"chunks/y160-z096-x032.json","offset":{"x":32,"y":160,"z":96},"requirements":{"minecraft:polished_diorite":11,"minecraft:stone_bricks":3},"sha256":"fcbb3103c3ced53352a5f872f5aa7fcce0006dca81e3aba211b00243ce034f09","size":{"x":32,"y":1,"z":32}},{"blockCount":10,"bytes":945,"file":"chunks/y160-z096-x064.json","offset":{"x":64,"y":160,"z":96},"requirements":{"minecraft:polished_diorite":8,"minecraft:stone_bricks":2},"sha256":"201672e106737e93127867d7a3b0aad73707de0424796b6cb386a93d8edff0d1","size":{"x":32,"y":1,"z":32}},{"blockCount":76,"bytes":3420,"file":"chunks/y160-z096-x096.json","offset":{"x":96,"y":160,"z":96},"requirements":{"minecraft:cobbled_deepslate":61,"minecraft:oak_planks":3,"minecraft:polished_diorite":7,"minecraft:stone_bricks":5},"sha256":"1197bfc643c420b31c7dbe40b927bec3b31d925913957b75b30511759c79cf3e","size":{"x":32,"y":1,"z":32}},{"blockCount":14,"bytes":1064,"file":"chunks/y160-z096-x128.json","offset":{"x":128,"y":160,"z":96},"requirements":{"minecraft:polished_diorite":11,"minecraft:stone_bricks":3},"sha256":"114bca0bd97d4fb9266e2ed1e8067a7947632d771a7d5f3fd26818dee2401231","size":{"x":32,"y":1,"z":32}},{"blockCount":11,"bytes":984,"file":"chunks/y160-z096-x160.json","offset":{"x":160,"y":160,"z":96},"requirements":{"minecraft:polished_diorite":9,"minecraft:stone_bricks":2},"sha256":"88dc9165094ac61925260a61598e0a3cb222475ae768405a0262e85e95540640","size":{"x":32,"y":1,"z":32}},{"blockCount":116,"bytes":3670,"file":"chunks/y160-z096-x192.json","offset":{"x":192,"y":160,"z":96},"requirements":{"minecraft:bricks":29,"minecraft:polished_diorite":48,"minecraft:stone_bricks":39},"sha256":"8fdcca359a06cc515402d6283c2817a8a5235daea349b489507f620497d24d31","size":{"x":32,"y":1,"z":32}},{"blockCount":125,"bytes":3745,"file":"chunks/y160-z096-x224.json","offset":{"x":224,"y":160,"z":96},"requirements":{"minecraft:bricks":35,"minecraft:glass":4,"minecraft:polished_diorite":45,"minecraft:stone_bricks":41},"sha256":"bbf3591a364093524ee38fefe81be1e3761defbb4db3985a7ec6dff18a861639","size":{"x":32,"y":1,"z":32}},{"blockCount":38,"bytes":1083,"file":"chunks/y160-z128-x032.json","offset":{"x":32,"y":160,"z":128},"requirements":{"minecraft:cobbled_deepslate":23,"minecraft:oak_planks":8,"minecraft:polished_diorite":5,"minecraft:stone_bricks":2},"sha256":"c9f7541f89ac0ece32e4c3614c5981e26b49538a77ae824e527f5d5c95e189d1","size":{"x":32,"y":1,"z":32}},{"blockCount":66,"bytes":897,"file":"chunks/y160-z128-x064.json","offset":{"x":64,"y":160,"z":128},"requirements":{"minecraft:cobbled_deepslate":62,"minecraft:oak_planks":2,"minecraft:stone_bricks":2},"sha256":"4eb13afacaff56d97319f8048e1a572de54ff610c6105414f522c1ec15204d7c","size":{"x":32,"y":1,"z":32}},{"blockCount":155,"bytes":3602,"file":"chunks/y160-z128-x096.json","offset":{"x":96,"y":160,"z":128},"requirements":{"minecraft:cobbled_deepslate":82,"minecraft:glass":24,"minecraft:oak_planks":3,"minecraft:stone_bricks":46},"sha256":"c4b38fd53337375104262771849234e6ff36c2051c79aa96316303ec90848dcb","size":{"x":32,"y":1,"z":32}},{"blockCount":66,"bytes":858,"file":"chunks/y160-z128-x128.json","offset":{"x":128,"y":160,"z":128},"requirements":{"minecraft:cobbled_deepslate":63,"minecraft:oak_planks":2,"minecraft:stone_bricks":1},"sha256":"d83fcbc9975e619355abc06d9679bcb248d89da07e59a259e52a0db5652bee14","size":{"x":32,"y":1,"z":32}},{"blockCount":66,"bytes":917,"file":"chunks/y160-z128-x160.json","offset":{"x":160,"y":160,"z":128},"requirements":{"minecraft:cobbled_deepslate":61,"minecraft:oak_planks":2,"minecraft:stone_bricks":3},"sha256":"595c98a6ffe10a9f8886dc7e71608d4daa0f3f88aa8df47eba8d2a40390307e4","size":{"x":32,"y":1,"z":32}},{"blockCount":74,"bytes":1271,"file":"chunks/y160-z128-x192.json","offset":{"x":192,"y":160,"z":128},"requirements":{"minecraft:cobbled_deepslate":58,"minecraft:oak_planks":3,"minecraft:polished_diorite":5,"minecraft:stone_bricks":8},"sha256":"15de13562d3cb441ed6d40321621d99fefe1e8b69125eeed3613bd3b270ddd5e","size":{"x":32,"y":1,"z":32}},{"blockCount":28,"bytes":1179,"file":"chunks/y160-z128-x224.json","offset":{"x":224,"y":160,"z":128},"requirements":{"minecraft:cobbled_deepslate":8,"minecraft:oak_planks":1,"minecraft:polished_diorite":10,"minecraft:stone_bricks":9},"sha256":"135ffc26a46b6cc524c85e82be4284068c4f9aa8c93e87b303aee916f02f3c4e","size":{"x":32,"y":1,"z":32}},{"blockCount":10,"bytes":945,"file":"chunks/y160-z160-x032.json","offset":{"x":32,"y":160,"z":160},"requirements":{"minecraft:polished_diorite":8,"minecraft:stone_bricks":2},"sha256":"b572119f60f0cd389243708b77657a5ca813f538f38cfba34e1b734c5edd5c1f","size":{"x":32,"y":1,"z":32}},{"blockCount":10,"bytes":945,"file":"chunks/y160-z160-x064.json","offset":{"x":64,"y":160,"z":160},"requirements":{"minecraft:polished_diorite":8,"minecraft:stone_bricks":2},"sha256":"094ab408fc6b79e0056a5ceac8071a32f6153608cee194135258190e6a33fe15","size":{"x":32,"y":1,"z":32}},{"blockCount":76,"bytes":3459,"file":"chunks/y160-z160-x096.json","offset":{"x":96,"y":160,"z":160},"requirements":{"minecraft:cobbled_deepslate":61,"minecraft:oak_planks":2,"minecraft:polished_diorite":8,"minecraft:stone_bricks":5},"sha256":"d85055b21e444186cbf4faa3535440ce50c2de5a301a55a197199a2694496dc9","size":{"x":32,"y":1,"z":32}},{"blockCount":15,"bytes":1104,"file":"chunks/y160-z160-x128.json","offset":{"x":128,"y":160,"z":160},"requirements":{"minecraft:polished_diorite":12,"minecraft:stone_bricks":3},"sha256":"2dd6ce539e7a54e8efc4661378935db1fb7d177124602d0d68072d70a05ff0dc","size":{"x":32,"y":1,"z":32}},{"blockCount":11,"bytes":983,"file":"chunks/y160-z160-x160.json","offset":{"x":160,"y":160,"z":160},"requirements":{"minecraft:polished_diorite":9,"minecraft:stone_bricks":2},"sha256":"0a767c7fe441a3c4943378081a4dd7776aea75efd48a858455a649a9957d8f5f","size":{"x":32,"y":1,"z":32}},{"blockCount":115,"bytes":3575,"file":"chunks/y160-z160-x192.json","offset":{"x":192,"y":160,"z":160},"requirements":{"minecraft:bricks":29,"minecraft:polished_diorite":48,"minecraft:stone_bricks":38},"sha256":"f5889ba9511753a9c3524031aab25dcf13782e76cb0d9aa8ecf9c3ddb05cf95b","size":{"x":32,"y":1,"z":32}},{"blockCount":126,"bytes":3785,"file":"chunks/y160-z160-x224.json","offset":{"x":224,"y":160,"z":160},"requirements":{"minecraft:bricks":35,"minecraft:glass":4,"minecraft:polished_diorite":45,"minecraft:stone_bricks":42},"sha256":"4da3f0bb90e6edcfe76609c0eedb85430bbe6b3360da26452026464000c95b55","size":{"x":32,"y":1,"z":32}},{"blockCount":60,"bytes":2578,"file":"chunks/y160-z192-x096.json","offset":{"x":96,"y":160,"z":192},"requirements":{"minecraft:cobbled_deepslate":35,"minecraft:oak_planks":2,"minecraft:polished_diorite":12,"minecraft:stone_bricks":11},"sha256":"85e5fdf863273cdf29e8dcd504438b78c321c9c33fb09e33e69395342e942c0e","size":{"x":32,"y":1,"z":32}},{"blockCount":10,"bytes":948,"file":"chunks/y160-z192-x128.json","offset":{"x":128,"y":160,"z":192},"requirements":{"minecraft:polished_diorite":8,"minecraft:stone_bricks":2},"sha256":"ce782cc9d22a4768f3b8a46cf61a8a875aafe9d687a13ba78bd9035573960950","size":{"x":32,"y":1,"z":32}},{"blockCount":97,"bytes":3117,"file":"chunks/y161-z064-x096.json","offset":{"x":96,"y":161,"z":64},"requirements":{"minecraft:cobbled_deepslate":50,"minecraft:oak_planks":23,"minecraft:polished_diorite":14,"minecraft:stone_bricks":10},"sha256":"2fb6e572ce2c57f7cd1396425f79f6d0f7cc980ee8a63135db0699cff9785eeb","size":{"x":32,"y":1,"z":32}},{"blockCount":11,"bytes":986,"file":"chunks/y161-z064-x128.json","offset":{"x":128,"y":161,"z":64},"requirements":{"minecraft:polished_diorite":9,"minecraft:stone_bricks":2},"sha256":"1fc7795775287827e3abb1d8c17a321e72e404d67b0327331985f3b8a452b395","size":{"x":32,"y":1,"z":32}},{"blockCount":8,"bytes":826,"file":"chunks/y161-z064-x192.json","offset":{"x":192,"y":161,"z":64},"requirements":{"minecraft:polished_diorite":5,"minecraft:stone_bricks":3},"sha256":"d3cb6afb7d8bb71802d3245956780fc0c72c0138b0d4cd26464acd78df1a0225","size":{"x":32,"y":1,"z":32}},{"blockCount":13,"bytes":942,"file":"chunks/y161-z064-x224.json","offset":{"x":224,"y":161,"z":64},"requirements":{"minecraft:polished_diorite":5,"minecraft:stone_bricks":8},"sha256":"8d77e8a55b592e7d6bebc7412718319489ec66f29753f86e7b315eb2e6550a92","size":{"x":32,"y":1,"z":32}},{"blockCount":14,"bytes":1062,"file":"chunks/y161-z096-x032.json","offset":{"x":32,"y":161,"z":96},"requirements":{"minecraft:polished_diorite":11,"minecraft:stone_bricks":3},"sha256":"1fa544f49e71bea7417f07f7f77e05e51db6f71c55ad69682889ce84fc3c0108","size":{"x":32,"y":1,"z":32}},{"blockCount":10,"bytes":945,"file":"chunks/y161-z096-x064.json","offset":{"x":64,"y":161,"z":96},"requirements":{"minecraft:polished_diorite":8,"minecraft:stone_bricks":2},"sha256":"f60c11a9df9261964922315a0e77ecb43ba0addeb84e4035c7c01c42adcb0eae","size":{"x":32,"y":1,"z":32}},{"blockCount":105,"bytes":3421,"file":"chunks/y161-z096-x096.json","offset":{"x":96,"y":161,"z":96},"requirements":{"minecraft:cobbled_deepslate":64,"minecraft:oak_planks":32,"minecraft:polished_diorite":7,"minecraft:stone_bricks":2},"sha256":"4d1a51b25c766e59fc0f60b1332d89a940d360daa772e06ee008788972623f7b","size":{"x":32,"y":1,"z":32}},{"blockCount":14,"bytes":1064,"file":"chunks/y161-z096-x128.json","offset":{"x":128,"y":161,"z":96},"requirements":{"minecraft:polished_diorite":11,"minecraft:stone_bricks":3},"sha256":"f0f5db0ec424db2660a6395d359676f9c63cb2158d25e5430e2167c9f44ecca6","size":{"x":32,"y":1,"z":32}},{"blockCount":11,"bytes":984,"file":"chunks/y161-z096-x160.json","offset":{"x":160,"y":161,"z":96},"requirements":{"minecraft:polished_diorite":9,"minecraft:stone_bricks":2},"sha256":"c49a1ce53b9e9f8af6c93e0092629977c5c432823ca0135f14260093d23ca399","size":{"x":32,"y":1,"z":32}},{"blockCount":139,"bytes":4078,"file":"chunks/y161-z096-x192.json","offset":{"x":192,"y":161,"z":96},"requirements":{"minecraft:bricks":29,"minecraft:polished_diorite":42,"minecraft:spruce_planks":23,"minecraft:stone_bricks":45},"sha256":"19d85e6f5cf35a9817a816e84a68edb5837dc376cb70e1a045413ef32586f94e","size":{"x":32,"y":1,"z":32}},{"blockCount":150,"bytes":3964,"file":"chunks/y161-z096-x224.json","offset":{"x":224,"y":161,"z":96},"requirements":{"minecraft:bricks":35,"minecraft:glass":2,"minecraft:polished_diorite":35,"minecraft:spruce_planks":28,"minecraft:stone_bricks":50},"sha256":"c0e82c570b1bce2f399eada4b6556cf51bddeeadc5b430947234085334a5e0fe","size":{"x":32,"y":1,"z":32}},{"blockCount":33,"bytes":1064,"file":"chunks/y161-z128-x032.json","offset":{"x":32,"y":161,"z":128},"requirements":{"minecraft:cobbled_deepslate":23,"minecraft:oak_planks":3,"minecraft:polished_diorite":5,"minecraft:stone_bricks":2},"sha256":"93945d9b29ae61726b6294bdc18d5d1b3aae377ded9276333b77e3c5e563091e","size":{"x":32,"y":1,"z":32}},{"blockCount":96,"bytes":717,"file":"chunks/y161-z128-x064.json","offset":{"x":64,"y":161,"z":128},"requirements":{"minecraft:cobbled_deepslate":64,"minecraft:oak_planks":32},"sha256":"c060bd739ef7582b6e67d995269ed270d679d79c84e8127a61900bd28e68e5fb","size":{"x":32,"y":1,"z":32}},{"blockCount":195,"bytes":3565,"file":"chunks/y161-z128-x096.json","offset":{"x":96,"y":161,"z":128},"requirements":{"minecraft:cobbled_deepslate":84,"minecraft:glass":24,"minecraft:oak_planks":43,"minecraft:stone_bricks":44},"sha256":"48eb18a005a30dc51cd113d6c45b74283b67085238437d4ab667ccf429029d29","size":{"x":32,"y":1,"z":32}},{"blockCount":96,"bytes":718,"file":"chunks/y161-z128-x128.json","offset":{"x":128,"y":161,"z":128},"requirements":{"minecraft:cobbled_deepslate":64,"minecraft:oak_planks":32},"sha256":"a49139fcd19d029f86e4ffd7ce5fed1b7d4dada37cb90e9457e73e6b52967380","size":{"x":32,"y":1,"z":32}},{"blockCount":96,"bytes":718,"file":"chunks/y161-z128-x160.json","offset":{"x":160,"y":161,"z":128},"requirements":{"minecraft:cobbled_deepslate":64,"minecraft:oak_planks":32},"sha256":"9900e11cc0b69b9741785611c0a62769bd8235e3caddddd56cb2cf8cb519c13f","size":{"x":32,"y":1,"z":32}},{"blockCount":104,"bytes":967,"file":"chunks/y161-z128-x192.json","offset":{"x":192,"y":161,"z":128},"requirements":{"minecraft:cobbled_deepslate":64,"minecraft:oak_planks":32,"minecraft:polished_diorite":5,"minecraft:stone_bricks":3},"sha256":"aa1fa655b2c5b786e9b7eb86f5a8038c5cd99553d88e88b67b415b25a4d843c6","size":{"x":32,"y":1,"z":32}},{"blockCount":32,"bytes":1334,"file":"chunks/y161-z128-x224.json","offset":{"x":224,"y":161,"z":128},"requirements":{"minecraft:cobbled_deepslate":8,"minecraft:oak_planks":2,"minecraft:polished_diorite":10,"minecraft:stone_bricks":12},"sha256":"2a9b26856b23c71427479dd6e17619ec3aad500a24f2e31edaec7f2a95233e33","size":{"x":32,"y":1,"z":32}},{"blockCount":10,"bytes":945,"file":"chunks/y161-z160-x032.json","offset":{"x":32,"y":161,"z":160},"requirements":{"minecraft:polished_diorite":8,"minecraft:stone_bricks":2},"sha256":"6356d4623f2cb8634a013be3c7c5dd93e5d4457d1568d7cdfad7164a2c8496dc","size":{"x":32,"y":1,"z":32}},{"blockCount":10,"bytes":945,"file":"chunks/y161-z160-x064.json","offset":{"x":64,"y":161,"z":160},"requirements":{"minecraft:polished_diorite":8,"minecraft:stone_bricks":2},"sha256":"b0fd77a601c9c5f5081fdba503cd80d6dab4687d49bf00db3fec3507cbe0bb13","size":{"x":32,"y":1,"z":32}},{"blockCount":106,"bytes":3460,"file":"chunks/y161-z160-x096.json","offset":{"x":96,"y":161,"z":160},"requirements":{"minecraft:cobbled_deepslate":64,"minecraft:oak_planks":32,"minecraft:polished_diorite":8,"minecraft:stone_bricks":2},"sha256":"7299cb97e2c43ed51cdcc075d3e5d50c2b41d590829a0fbaba2564fe0547bdb3","size":{"x":32,"y":1,"z":32}},{"blockCount":15,"bytes":1104,"file":"chunks/y161-z160-x128.json","offset":{"x":128,"y":161,"z":160},"requirements":{"minecraft:polished_diorite":12,"minecraft:stone_bricks":3},"sha256":"70c24a4afeb33f823bb426c559563156267e3ed87b3d1b69cf6f40afc924f4cf","size":{"x":32,"y":1,"z":32}},{"blockCount":11,"bytes":983,"file":"chunks/y161-z160-x160.json","offset":{"x":160,"y":161,"z":160},"requirements":{"minecraft:polished_diorite":9,"minecraft:stone_bricks":2},"sha256":"7a042402baeca00b25fdc99a8cb5bed2625d7c72c7fe2c677e08917e346bd82d","size":{"x":32,"y":1,"z":32}},{"blockCount":139,"bytes":4022,"file":"chunks/y161-z160-x192.json","offset":{"x":192,"y":161,"z":160},"requirements":{"minecraft:bricks":29,"minecraft:polished_diorite":42,"minecraft:spruce_planks":23,"minecraft:stone_bricks":45},"sha256":"61bbed0229b615d69e2fe31f356b24254c45cda6d6ca0ecd2274b5fb4bf576c4","size":{"x":32,"y":1,"z":32}},{"blockCount":154,"bytes":4042,"file":"chunks/y161-z160-x224.json","offset":{"x":224,"y":161,"z":160},"requirements":{"minecraft:bricks":35,"minecraft:glass":2,"minecraft:polished_diorite":35,"minecraft:spruce_planks":28,"minecraft:stone_bricks":54},"sha256":"8f8da70f27fbf6afc2a40c50226f14765d40f4e58ede68a4c44304c7a54a7f8f","size":{"x":32,"y":1,"z":32}},{"blockCount":75,"bytes":2541,"file":"chunks/y161-z192-x096.json","offset":{"x":96,"y":161,"z":192},"requirements":{"minecraft:cobbled_deepslate":36,"minecraft:oak_planks":16,"minecraft:polished_diorite":13,"minecraft:stone_bricks":10},"sha256":"a8263f3d49b0f1911d637da441c4fde912f2f9b46a97a1e72146ef6fcde2a32a","size":{"x":32,"y":1,"z":32}},{"blockCount":10,"bytes":948,"file":"chunks/y161-z192-x128.json","offset":{"x":128,"y":161,"z":192},"requirements":{"minecraft:polished_diorite":8,"minecraft:stone_bricks":2},"sha256":"6c2c51b53216436e6e67c3df28e28b6a0dd5a8807bb1bfc74915b2e4665ed600","size":{"x":32,"y":1,"z":32}},{"blockCount":63,"bytes":2220,"file":"chunks/y162-z064-x096.json","offset":{"x":96,"y":162,"z":64},"requirements":{"minecraft:cobbled_deepslate":41,"minecraft:polished_diorite":10,"minecraft:stone_bricks":12},"sha256":"b2ba76d1cb4ad1fb6c870cf4d20c9f1e7beae07fa1b4a5680adadbfc88cc87f2","size":{"x":32,"y":1,"z":32}},{"blockCount":11,"bytes":986,"file":"chunks/y162-z064-x128.json","offset":{"x":128,"y":162,"z":64},"requirements":{"minecraft:polished_diorite":9,"minecraft:stone_bricks":2},"sha256":"2021e192bdb60f24ec8a04c24539c10489df0c2c1e8df10fb6f45f39cf486bfa","size":{"x":32,"y":1,"z":32}},{"blockCount":16,"bytes":960,"file":"chunks/y162-z064-x192.json","offset":{"x":192,"y":162,"z":64},"requirements":{"minecraft:polished_diorite":8,"minecraft:stone_bricks":8},"sha256":"6e9ded257da799f50819769310270c0fa660465d25991db2792f29e90754ec2b","size":{"x":32,"y":1,"z":32}},{"blockCount":18,"bytes":1056,"file":"chunks/y162-z064-x224.json","offset":{"x":224,"y":162,"z":64},"requirements":{"minecraft:polished_diorite":9,"minecraft:stone_bricks":9},"sha256":"c34b5fdc789fa9978218afdd58d79b47e0ea2317db1f8637bf461220b9bd4a7b","size":{"x":32,"y":1,"z":32}},{"blockCount":14,"bytes":1062,"file":"chunks/y162-z096-x032.json","offset":{"x":32,"y":162,"z":96},"requirements":{"minecraft:polished_diorite":11,"minecraft:stone_bricks":3},"sha256":"115d2dfe99b693d3637a1f595dd82a0aa6ac198ff9f44bb57ba2a1172788d3d1","size":{"x":32,"y":1,"z":32}},{"blockCount":10,"bytes":945,"file":"chunks/y162-z096-x064.json","offset":{"x":64,"y":162,"z":96},"requirements":{"minecraft:polished_diorite":8,"minecraft:stone_bricks":2},"sha256":"43374d7efef13e35ee7e01f3963be04a2f7fb7a7fe3bfa9108c529418267a6bf","size":{"x":32,"y":1,"z":32}},{"blockCount":63,"bytes":2180,"file":"chunks/y162-z096-x096.json","offset":{"x":96,"y":162,"z":96},"requirements":{"minecraft:cobbled_deepslate":54,"minecraft:polished_diorite":7,"minecraft:stone_bricks":2},"sha256":"63d043f1895f0f7adc7b3012b7cc9dc86ecff13208ba74904326cc3c33d8cd2d","size":{"x":32,"y":1,"z":32}},{"blockCount":14,"bytes":1064,"file":"chunks/y162-z096-x128.json","offset":{"x":128,"y":162,"z":96},"requirements":{"minecraft:polished_diorite":11,"minecraft:stone_bricks":3},"sha256":"ede4126d47e7ed337864a2a00b4ee39c9b68843826798c6fc3a9256dd63913a8","size":{"x":32,"y":1,"z":32}},{"blockCount":11,"bytes":984,"file":"chunks/y162-z096-x160.json","offset":{"x":160,"y":162,"z":96},"requirements":{"minecraft:polished_diorite":9,"minecraft:stone_bricks":2},"sha256":"fb3e504f6bf675a505151c8e42f98a59e7c2f98cb86070b8df05a14e32c3a4bf","size":{"x":32,"y":1,"z":32}},{"blockCount":225,"bytes":4904,"file":"chunks/y162-z096-x192.json","offset":{"x":192,"y":162,"z":96},"requirements":{"minecraft:bricks":33,"minecraft:glass":10,"minecraft:oak_planks":37,"minecraft:polished_diorite":91,"minecraft:spruce_planks":4,"minecraft:stone_bricks":50},"sha256":"707ee8dded52edbd47a6c48f064eed2a559585d7026b3769f25e519e8a710989","size":{"x":32,"y":1,"z":32}},{"blockCount":250,"bytes":5152,"file":"chunks/y162-z096-x224.json","offset":{"x":224,"y":162,"z":96},"requirements":{"minecraft:bricks":39,"minecraft:glass":18,"minecraft:oak_planks":43,"minecraft:polished_diorite":95,"minecraft:spruce_planks":4,"minecraft:stone_bricks":51},"sha256":"7fe36be18efca99c2914fcf04d5437ed86fbc786c881863e319795192b8144d7","size":{"x":32,"y":1,"z":32}},{"blockCount":26,"bytes":1209,"file":"chunks/y162-z128-x032.json","offset":{"x":32,"y":162,"z":128},"requirements":{"minecraft:cobbled_deepslate":20,"minecraft:polished_diorite":5,"minecraft:stone_bricks":1},"sha256":"268bbc8e0fa6ca75f28ee2236fdf40280d27f1cc918d95f5caadabe51775a69a","size":{"x":32,"y":1,"z":32}},{"blockCount":54,"bytes":1449,"file":"chunks/y162-z128-x064.json","offset":{"x":64,"y":162,"z":128},"requirements":{"minecraft:cobbled_deepslate":54},"sha256":"838142380c6825620853a2e25b4718f581a04ca5bb0f1dd19dbb10020889ee7f","size":{"x":32,"y":1,"z":32}},{"blockCount":135,"bytes":3258,"file":"chunks/y162-z128-x096.json","offset":{"x":96,"y":162,"z":128},"requirements":{"minecraft:cobbled_deepslate":66,"minecraft:glass":24,"minecraft:oak_planks":1,"minecraft:stone_bricks":44},"sha256":"e6eb0089ea51240e065eb26b87bcfde8c59a1e85eb257842c186ef7445a161c7","size":{"x":32,"y":1,"z":32}},{"blockCount":54,"bytes":1450,"file":"chunks/y162-z128-x128.json","offset":{"x":128,"y":162,"z":128},"requirements":{"minecraft:cobbled_deepslate":54},"sha256":"cdd3a56980e2f38fb88bd2e47bce4de8608dadcd7e1ba0d6796e3496aad61946","size":{"x":32,"y":1,"z":32}},{"blockCount":54,"bytes":1450,"file":"chunks/y162-z128-x160.json","offset":{"x":160,"y":162,"z":128},"requirements":{"minecraft:cobbled_deepslate":54},"sha256":"33231040e53237ae5fa87118f7c4095eafba5fcebf599a98ed2b2b6214621a9d","size":{"x":32,"y":1,"z":32}},{"blockCount":68,"bytes":1795,"file":"chunks/y162-z128-x192.json","offset":{"x":192,"y":162,"z":128},"requirements":{"minecraft:cobbled_deepslate":52,"minecraft:polished_diorite":8,"minecraft:stone_bricks":8},"sha256":"45156dc9edff37915ea1711964979dbab0ee4b01d198ef4380b6cbd58d8f2e14","size":{"x":32,"y":1,"z":32}},{"blockCount":37,"bytes":1498,"file":"chunks/y162-z128-x224.json","offset":{"x":224,"y":162,"z":128},"requirements":{"minecraft:cobbled_deepslate":8,"minecraft:polished_diorite":10,"minecraft:stone_bricks":19},"sha256":"f61fd005679123dcdf0915eb678e5c1541ed52bd2f6bfeceb146db69551369b1","size":{"x":32,"y":1,"z":32}},{"blockCount":10,"bytes":945,"file":"chunks/y162-z160-x032.json","offset":{"x":32,"y":162,"z":160},"requirements":{"minecraft:polished_diorite":8,"minecraft:stone_bricks":2},"sha256":"09bd51929254e5479ccec38569ad52265ab710e518c7a9c96fe3e2a608982232","size":{"x":32,"y":1,"z":32}},{"blockCount":10,"bytes":945,"file":"chunks/y162-z160-x064.json","offset":{"x":64,"y":162,"z":160},"requirements":{"minecraft:polished_diorite":8,"minecraft:stone_bricks":2},"sha256":"83727d674ffd5f5fe1f7fcc58b8336a98f43b1c48f0c06415721c064fcb7346f","size":{"x":32,"y":1,"z":32}},{"blockCount":64,"bytes":2221,"file":"chunks/y162-z160-x096.json","offset":{"x":96,"y":162,"z":160},"requirements":{"minecraft:cobbled_deepslate":54,"minecraft:polished_diorite":8,"minecraft:stone_bricks":2},"sha256":"e309c2a526fb7f04f24b3f77196f895443a6825abc24bbdd1c8009eb2ad18ef4","size":{"x":32,"y":1,"z":32}},{"blockCount":15,"bytes":1104,"file":"chunks/y162-z160-x128.json","offset":{"x":128,"y":162,"z":160},"requirements":{"minecraft:polished_diorite":12,"minecraft:stone_bricks":3},"sha256":"332b10b3dd51564ce711241b4ee0a3cf4e9d848ec282db366f6e01103ecfefa4","size":{"x":32,"y":1,"z":32}},{"blockCount":11,"bytes":983,"file":"chunks/y162-z160-x160.json","offset":{"x":160,"y":162,"z":160},"requirements":{"minecraft:polished_diorite":9,"minecraft:stone_bricks":2},"sha256":"dd7a650346d9c2053ec5bd3e06c835c7b434794cdda1a7aec7491213255157f6","size":{"x":32,"y":1,"z":32}},{"blockCount":225,"bytes":4867,"file":"chunks/y162-z160-x192.json","offset":{"x":192,"y":162,"z":160},"requirements":{"minecraft:bricks":33,"minecraft:glass":10,"minecraft:oak_planks":37,"minecraft:polished_diorite":91,"minecraft:spruce_planks":4,"minecraft:stone_bricks":50},"sha256":"1bb6d7076b42cd48191f7990974d654710a20680423f7b4da9182e53fddf1408","size":{"x":32,"y":1,"z":32}},{"blockCount":250,"bytes":5153,"file":"chunks/y162-z160-x224.json","offset":{"x":224,"y":162,"z":160},"requirements":{"minecraft:bricks":39,"minecraft:glass":18,"minecraft:oak_planks":43,"minecraft:polished_diorite":95,"minecraft:spruce_planks":4,"minecraft:stone_bricks":51},"sha256":"f46871cc3f7602edd719e1b22dd93d55293fb288b2b69223e2c33a28b4640800","size":{"x":32,"y":1,"z":32}},{"blockCount":51,"bytes":1907,"file":"chunks/y162-z192-x096.json","offset":{"x":96,"y":162,"z":192},"requirements":{"minecraft:cobbled_deepslate":30,"minecraft:polished_diorite":9,"minecraft:stone_bricks":12},"sha256":"40e808e61a640355cf4a01c5414106a982d92d89bcc7e54c7717fea616c43302","size":{"x":32,"y":1,"z":32}},{"blockCount":10,"bytes":948,"file":"chunks/y162-z192-x128.json","offset":{"x":128,"y":162,"z":192},"requirements":{"minecraft:polished_diorite":8,"minecraft:stone_bricks":2},"sha256":"a4d74e407a90912b1a155d19dc87d75277eb996a4e5b2065f2863f315faa1461","size":{"x":32,"y":1,"z":32}},{"blockCount":41,"bytes":2093,"file":"chunks/y163-z064-x096.json","offset":{"x":96,"y":163,"z":64},"requirements":{"minecraft:glass":17,"minecraft:polished_diorite":2,"minecraft:stone_bricks":22},"sha256":"1bd4b54291f237cdb8b2e35d5acad51cb69e3535f09d072de70633b7c3a7c8fa","size":{"x":32,"y":1,"z":32}},{"blockCount":11,"bytes":986,"file":"chunks/y163-z064-x128.json","offset":{"x":128,"y":163,"z":64},"requirements":{"minecraft:polished_diorite":2,"minecraft:stone_bricks":9},"sha256":"823eb99ae8082e408b1b1fd79d2fa839c45e2614622672ede22221b9f6af4b2a","size":{"x":32,"y":1,"z":32}},{"blockCount":12,"bytes":845,"file":"chunks/y163-z064-x192.json","offset":{"x":192,"y":163,"z":64},"requirements":{"minecraft:polished_diorite":6,"minecraft:stone_bricks":6},"sha256":"618fb8e09729816f5eb3e4ca4b0932a2606a81019602a1cf04d2012e3e8c8dad","size":{"x":32,"y":1,"z":32}},{"blockCount":15,"bytes":922,"file":"chunks/y163-z064-x224.json","offset":{"x":224,"y":163,"z":64},"requirements":{"minecraft:polished_diorite":8,"minecraft:stone_bricks":7},"sha256":"654ab489825b11cdb28ec16e662568b2ef91acecb44bbb8c7ee41064055f5940","size":{"x":32,"y":1,"z":32}},{"blockCount":14,"bytes":1062,"file":"chunks/y163-z096-x032.json","offset":{"x":32,"y":163,"z":96},"requirements":{"minecraft:polished_diorite":3,"minecraft:stone_bricks":11},"sha256":"30ad7401c4e481317d7ed0fc2ae2eae438bd5bab5eb93e832083baa5b8df5514","size":{"x":32,"y":1,"z":32}},{"blockCount":10,"bytes":945,"file":"chunks/y163-z096-x064.json","offset":{"x":64,"y":163,"z":96},"requirements":{"minecraft:polished_diorite":2,"minecraft:stone_bricks":8},"sha256":"51873e9b0a333e35361da603f1c688c775103573032af9b9280cee80e7147a38","size":{"x":32,"y":1,"z":32}},{"blockCount":41,"bytes":2171,"file":"chunks/y163-z096-x096.json","offset":{"x":96,"y":163,"z":96},"requirements":{"minecraft:glass":21,"minecraft:polished_diorite":2,"minecraft:stone_bricks":18},"sha256":"bc23fc8b4f19ae8d76700521b19f858d785c34860d73392c22af506610b29c96","size":{"x":32,"y":1,"z":32}},{"blockCount":14,"bytes":1064,"file":"chunks/y163-z096-x128.json","offset":{"x":128,"y":163,"z":96},"requirements":{"minecraft:polished_diorite":3,"minecraft:stone_bricks":11},"sha256":"241ed58d853029b195806776ec65dd559177f3aef120507a45f69b3c4e1f5480","size":{"x":32,"y":1,"z":32}},{"blockCount":11,"bytes":984,"file":"chunks/y163-z096-x160.json","offset":{"x":160,"y":163,"z":96},"requirements":{"minecraft:polished_diorite":2,"minecraft:stone_bricks":9},"sha256":"dfa01e0b8de257a7d469d0a04da61e51e8972524a9c3baad5263683a9d25fdac","size":{"x":32,"y":1,"z":32}},{"blockCount":230,"bytes":4295,"file":"chunks/y163-z096-x192.json","offset":{"x":192,"y":163,"z":96},"requirements":{"minecraft:bricks":21,"minecraft:glass":8,"minecraft:oak_planks":57,"minecraft:polished_diorite":108,"minecraft:spruce_planks":6,"minecraft:stone_bricks":30},"sha256":"b3cd8eeb9df138bec37ae3fbade56bc00fc4fea738683cbc0373f16bd36dfc77","size":{"x":32,"y":1,"z":32}},{"blockCount":272,"bytes":4371,"file":"chunks/y163-z096-x224.json","offset":{"x":224,"y":163,"z":96},"requirements":{"minecraft:bricks":25,"minecraft:glass":12,"minecraft:oak_planks":83,"minecraft:polished_diorite":120,"minecraft:spruce_planks":8,"minecraft:stone_bricks":24},"sha256":"0609d070d43324dcddca3e8405eebb783f60614a39bdbb87671ed4fb21d42973","size":{"x":32,"y":1,"z":32}},{"blockCount":17,"bytes":1022,"file":"chunks/y163-z128-x032.json","offset":{"x":32,"y":163,"z":128},"requirements":{"minecraft:glass":7,"minecraft:polished_diorite":1,"minecraft:stone_bricks":9},"sha256":"4ce481ed0fae9892b66594cf953aefa87c5c66e8f39f108421271177d0488921","size":{"x":32,"y":1,"z":32}},{"blockCount":32,"bytes":1065,"file":"chunks/y163-z128-x064.json","offset":{"x":64,"y":163,"z":128},"requirements":{"minecraft:glass":21,"minecraft:stone_bricks":11},"sha256":"6a85196cc5c29c53b162fc7b7f327533bb387ea6db745515f587620b021ada98","size":{"x":32,"y":1,"z":32}},{"blockCount":111,"bytes":2998,"file":"chunks/y163-z128-x096.json","offset":{"x":96,"y":163,"z":128},"requirements":{"minecraft:glass":54,"minecraft:oak_planks":1,"minecraft:stone_bricks":56},"sha256":"e4d3e2c6569833acc870d2e7a867a85d4f45b815ab684fe521033203a4eec8d1","size":{"x":32,"y":1,"z":32}},{"blockCount":32,"bytes":1066,"file":"chunks/y163-z128-x128.json","offset":{"x":128,"y":163,"z":128},"requirements":{"minecraft:glass":21,"minecraft:stone_bricks":11},"sha256":"6dedaa4fa0aac72dedeb848ce2efaccb579dc1c61e8d8a42c4464b08d08b282c","size":{"x":32,"y":1,"z":32}},{"blockCount":32,"bytes":1066,"file":"chunks/y163-z128-x160.json","offset":{"x":160,"y":163,"z":128},"requirements":{"minecraft:glass":21,"minecraft:stone_bricks":11},"sha256":"2748cebdc1b6607e8a050b0a143423f6a9afc129b2ced90aece18e79ccda7981","size":{"x":32,"y":1,"z":32}},{"blockCount":44,"bytes":1288,"file":"chunks/y163-z128-x192.json","offset":{"x":192,"y":163,"z":128},"requirements":{"minecraft:glass":22,"minecraft:polished_diorite":6,"minecraft:stone_bricks":16},"sha256":"450d613197a4a5e346fb8d6e12305516c973292f69fe7620a75520de9ff8b51c","size":{"x":32,"y":1,"z":32}},{"blockCount":24,"bytes":1100,"file":"chunks/y163-z128-x224.json","offset":{"x":224,"y":163,"z":128},"requirements":{"minecraft:glass":2,"minecraft:polished_diorite":8,"minecraft:stone_bricks":14},"sha256":"cc43981460eefa7d5b390b7ba3e544ee53d2cb3c1ec2549d4463035e7dbfbed4","size":{"x":32,"y":1,"z":32}},{"blockCount":10,"bytes":945,"file":"chunks/y163-z160-x032.json","offset":{"x":32,"y":163,"z":160},"requirements":{"minecraft:polished_diorite":2,"minecraft:stone_bricks":8},"sha256":"604b7e915d51d8b4473e952d700728176d058a2a0c437a74daf97a68cff7aade","size":{"x":32,"y":1,"z":32}},{"blockCount":10,"bytes":945,"file":"chunks/y163-z160-x064.json","offset":{"x":64,"y":163,"z":160},"requirements":{"minecraft:polished_diorite":2,"minecraft:stone_bricks":8},"sha256":"dea6d11e57917f6c020a470f6e9261c990e83433b39bad722f1cf3776d0eb3cd","size":{"x":32,"y":1,"z":32}},{"blockCount":42,"bytes":2211,"file":"chunks/y163-z160-x096.json","offset":{"x":96,"y":163,"z":160},"requirements":{"minecraft:glass":21,"minecraft:polished_diorite":2,"minecraft:stone_bricks":19},"sha256":"a3e610a0fb18bc8996fe05eb11b633a792116be06a1c321c90c332329c707c02","size":{"x":32,"y":1,"z":32}},{"blockCount":15,"bytes":1104,"file":"chunks/y163-z160-x128.json","offset":{"x":128,"y":163,"z":160},"requirements":{"minecraft:polished_diorite":3,"minecraft:stone_bricks":12},"sha256":"fd7ee20f55c412c04376ce32d7e65c98c4d2e72ae7c45758a053cc4fab1730d6","size":{"x":32,"y":1,"z":32}},{"blockCount":11,"bytes":983,"file":"chunks/y163-z160-x160.json","offset":{"x":160,"y":163,"z":160},"requirements":{"minecraft:polished_diorite":2,"minecraft:stone_bricks":9},"sha256":"f970223ce52ffe02c577e945340da759a1e82ecc1cab6da09d447a7ad47c61c4","size":{"x":32,"y":1,"z":32}},{"blockCount":230,"bytes":4258,"file":"chunks/y163-z160-x192.json","offset":{"x":192,"y":163,"z":160},"requirements":{"minecraft:bricks":21,"minecraft:glass":8,"minecraft:oak_planks":57,"minecraft:polished_diorite":108,"minecraft:spruce_planks":6,"minecraft:stone_bricks":30},"sha256":"26c5f8d9a0164f0ac3c40cd9eac5dd4815769514e10c6be35ef5a873fc113cb6","size":{"x":32,"y":1,"z":32}},{"blockCount":272,"bytes":4372,"file":"chunks/y163-z160-x224.json","offset":{"x":224,"y":163,"z":160},"requirements":{"minecraft:bricks":25,"minecraft:glass":12,"minecraft:oak_planks":83,"minecraft:polished_diorite":120,"minecraft:spruce_planks":8,"minecraft:stone_bricks":24},"sha256":"1ef6a291b108c8b500630fbd18898c9e0192389ee60a403af2be736e0ce286dc","size":{"x":32,"y":1,"z":32}},{"blockCount":33,"bytes":1782,"file":"chunks/y163-z192-x096.json","offset":{"x":96,"y":163,"z":192},"requirements":{"minecraft:glass":12,"minecraft:polished_diorite":2,"minecraft:stone_bricks":19},"sha256":"129b9b958fb5944acee206c47a75aff3cbd0ce5e135b371bdcb147e67a6b8bd2","size":{"x":32,"y":1,"z":32}},{"blockCount":10,"bytes":948,"file":"chunks/y163-z192-x128.json","offset":{"x":128,"y":163,"z":192},"requirements":{"minecraft:polished_diorite":2,"minecraft:stone_bricks":8},"sha256":"a7aefb8e177ed25eaddb3d2c963cca39f6db28639f2fbe3f89786c0bfaa99eea","size":{"x":32,"y":1,"z":32}},{"blockCount":42,"bytes":2034,"file":"chunks/y164-z064-x096.json","offset":{"x":96,"y":164,"z":64},"requirements":{"minecraft:polished_diorite":9,"minecraft:stone_bricks":33},"sha256":"95d2f6af4477847468fb953c7b8fc1867ad98282efeb24614cb2907f1c474b95","size":{"x":32,"y":1,"z":32}},{"blockCount":11,"bytes":986,"file":"chunks/y164-z064-x128.json","offset":{"x":128,"y":164,"z":64},"requirements":{"minecraft:polished_diorite":9,"minecraft:stone_bricks":2},"sha256":"c4c6e03c4a0242807743e9b3839bdce824db221b743aa0cdd995e8c848a4e625","size":{"x":32,"y":1,"z":32}},{"blockCount":11,"bytes":846,"file":"chunks/y164-z064-x192.json","offset":{"x":192,"y":164,"z":64},"requirements":{"minecraft:glass":3,"minecraft:polished_diorite":5,"minecraft:stone_bricks":3},"sha256":"edba1bbfa86daa2fb1ac0c90a7dcfe1d098ab350b2e87fa2efe34b8dca653190","size":{"x":32,"y":1,"z":32}},{"blockCount":14,"bytes":866,"file":"chunks/y164-z064-x224.json","offset":{"x":224,"y":164,"z":64},"requirements":{"minecraft:glass":6,"minecraft:polished_diorite":5,"minecraft:stone_bricks":3},"sha256":"87baf5aa2dab034f3f57f231c9dbbdab325e05a2c8c63294ef2cedbe70d260df","size":{"x":32,"y":1,"z":32}}],"schema":1}
