{"entries":[{"blockCount":14,"bytes":1062,"file":"chunks/y164-z096-x032.json","offset":{"x":32,"y":164,"z":96},"requirements":{"minecraft:polished_diorite":11,"minecraft:stone_bricks":3},"sha256":"ed2e7de1d2d916d27f391c38e2b2e13d31eb9c698ad06abceb2fb4882451b330","size":{"x":32,"y":1,"z":32}},{"blockCount":10,"bytes":945,"file":"chunks/y164-z096-x064.json","offset":{"x":64,"y":164,"z":96},"requirements":{"minecraft:polished_diorite":8,"minecraft:stone_bricks":2},"sha256":"58e67a596b4005010daea529d6755f2f21f73448b5724f9024be72424b994591","size":{"x":32,"y":1,"z":32}},{"blockCount":41,"bytes":2150,"file":"chunks/y164-z096-x096.json","offset":{"x":96,"y":164,"z":96},"requirements":{"minecraft:polished_diorite":7,"minecraft:stone_bricks":34},"sha256":"9a43bb893f4c60d3d61761ff8dd7760580814e5c3e721c31d64d671bfdb09759","size":{"x":32,"y":1,"z":32}},{"blockCount":14,"bytes":1064,"file":"chunks/y164-z096-x128.json","offset":{"x":128,"y":164,"z":96},"requirements":{"minecraft:polished_diorite":11,"minecraft:stone_bricks":3},"sha256":"c9c5248e2771870b38c674dc079013e4587716ee88c269c60ef569cc72199015","size":{"x":32,"y":1,"z":32}},{"blockCount":11,"bytes":984,"file":"chunks/y164-z096-x160.json","offset":{"x":160,"y":164,"z":96},"requirements":{"minecraft:polished_diorite":9,"minecraft:stone_bricks":2},"sha256":"1405087169dd75f46ac3665e0f2efe3b138602277460023e2584a50172ad25f8","size":{"x":32,"y":1,"z":32}},{"blockCount":146,"bytes":4274,"file":"chunks/y164-z096-x192.json","offset":{"x":192,"y":164,"z":96},"requirements":{"minecraft:bricks":7,"minecraft:glass":66,"minecraft:oak_planks":8,"minecraft:polished_diorite":51,"minecraft:spruce_planks":3,"minecraft:stone_bricks":11},"sha256":"ae0e1618473b7e9ed39f1b4165bf0c98ac1b25ff197fa844e25c0d720cb9d368","size":{"x":32,"y":1,"z":32}},{"blockCount":150,"bytes":4122,"file":"chunks/y164-z096-x224.json","offset":{"x":224,"y":164,"z":96},"requirements":{"minecraft:bricks":9,"minecraft:glass":72,"minecraft:oak_planks":8,"minecraft:polished_diorite":46,"minecraft:spruce_planks":6,"minecraft:stone_bricks":9},"sha256":"70a55a45ec5b843b061d6ca7293ff13b94948b8dc72ed6dc7bbbaa856be6911d","size":{"x":32,"y":1,"z":32}},{"blockCount":17,"bytes":871,"file":"chunks/y164-z128-x032.json","offset":{"x":32,"y":164,"z":128},"requirements":{"minecraft:polished_diorite":5,"minecraft:stone_bricks":12},"sha256":"dd3f3057c50ac5f2acf09684906082ddcd3e7cf4c43fb8c1fdd511c534830c4b","size":{"x":32,"y":1,"z":32}},{"blockCount":32,"bytes":646,"file":"chunks/y164-z128-x064.json","offset":{"x":64,"y":164,"z":128},"requirements":{"minecraft:stone_bricks":32},"sha256":"21f4210a65e1df10f73129738138dca4250a141c481811f0e0bfaecd9c835cec","size":{"x":32,"y":1,"z":32}},{"blockCount":111,"bytes":2733,"file":"chunks/y164-z128-x096.json","offset":{"x":96,"y":164,"z":128},"requirements":{"minecraft:glass":24,"minecraft:oak_planks":1,"minecraft:stone_bricks":86},"sha256":"8dbc299e5a5f7c0f9989618289fa6f65b3591736f81bc7eb5e38efff4b8fe511","size":{"x":32,"y":1,"z":32}},{"blockCount":32,"bytes":647,"file":"chunks/y164-z128-x128.json","offset":{"x":128,"y":164,"z":128},"requirements":{"minecraft:stone_bricks":32},"sha256":"013f9144e3387dcf503e6c52e2e2864cc48f218180f4a3eacbf478d283c74426","size":{"x":32,"y":1,"z":32}},{"blockCount":32,"bytes":647,"file":"chunks/y164-z128-x160.json","offset":{"x":160,"y":164,"z":128},"requirements":{"minecraft:stone_bricks":32},"sha256":"5f69c2210617e6fe8f120dada671ca74ca3dae79700d34c5f3a33472d76b2fa4","size":{"x":32,"y":1,"z":32}},{"blockCount":43,"bytes":889,"file":"chunks/y164-z128-x192.json","offset":{"x":192,"y":164,"z":128},"requirements":{"minecraft:glass":3,"minecraft:polished_diorite":5,"minecraft:stone_bricks":35},"sha256":"65a5733a897e8270ec5777141265b11a8bfc79a4154f1a80e425245ceaa0ae17","size":{"x":32,"y":1,"z":32}},{"blockCount":24,"bytes":986,"file":"chunks/y164-z128-x224.json","offset":{"x":224,"y":164,"z":128},"requirements":{"minecraft:glass":6,"minecraft:polished_diorite":5,"minecraft:stone_bricks":13},"sha256":"876eb4aad8c848008930ae15e4f842a7b978bff460aa0c26762518f34004d8cd","size":{"x":32,"y":1,"z":32}},{"blockCount":10,"bytes":945,"file":"chunks/y164-z160-x032.json","offset":{"x":32,"y":164,"z":160},"requirements":{"minecraft:polished_diorite":8,"minecraft:stone_bricks":2},"sha256":"dc6f63d1ea9d4df7105ae3735511285aa7afdd21218ee9601b0b2256960fdce0","size":{"x":32,"y":1,"z":32}},{"blockCount":10,"bytes":945,"file":"chunks/y164-z160-x064.json","offset":{"x":64,"y":164,"z":160},"requirements":{"minecraft:polished_diorite":8,"minecraft:stone_bricks":2},"sha256":"37fc196befb1a7f773b4e8fc771556a6cab1fe9bbfe8c5d9d83c5cf87d454a3b","size":{"x":32,"y":1,"z":32}},{"blockCount":42,"bytes":2190,"file":"chunks/y164-z160-x096.json","offset":{"x":96,"y":164,"z":160},"requirements":{"minecraft:polished_diorite":8,"minecraft:stone_bricks":34},"sha256":"ee295d2296000d91d1ea36f35cf4479ec15b2e9e0670697f938a4b5e99b9fcb8","size":{"x":32,"y":1,"z":32}},{"blockCount":15,"bytes":1104,"file":"chunks/y164-z160-x128.json","offset":{"x":128,"y":164,"z":160},"requirements":{"minecraft:polished_diorite":12,"minecraft:stone_bricks":3},"sha256":"3d2fa8bc731b175842e689925311b5554def4dab6d52b23cc1a785f0bf7087ad","size":{"x":32,"y":1,"z":32}},{"blockCount":11,"bytes":983,"file":"chunks/y164-z160-x160.json","offset":{"x":160,"y":164,"z":160},"requirements":{"minecraft:polished_diorite":9,"minecraft:stone_bricks":2},"sha256":"0dcd8f913cde5767a943de37a8591d81fffb3c60e4282d4304bb35a2b27d64b8","size":{"x":32,"y":1,"z":32}},{"blockCount":146,"bytes":4256,"file":"chunks/y164-z160-x192.json","offset":{"x":192,"y":164,"z":160},"requirements":{"minecraft:bricks":7,"minecraft:glass":66,"minecraft:oak_planks":8,"minecraft:polished_diorite":51,"minecraft:spruce_planks":3,"minecraft:stone_bricks":11},"sha256":"163d73196b728f3d36c9a166e03e0a48bfb185062023d4cbf7dd64ad229d28ff","size":{"x":32,"y":1,"z":32}},{"blockCount":150,"bytes":4123,"file":"chunks/y164-z160-x224.json","offset":{"x":224,"y":164,"z":160},"requirements":{"minecraft:bricks":9,"minecraft:glass":72,"minecraft:oak_planks":8,"minecraft:polished_diorite":46,"minecraft:spruce_planks":6,"minecraft:stone_bricks":9},"sha256":"587fdb36d0c053aad85eaa1fdcefbc04bed28de5b8eade4c04d7292ae9bece24","size":{"x":32,"y":1,"z":32}},{"blockCount":34,"bytes":1723,"file":"chunks/y164-z192-x096.json","offset":{"x":96,"y":164,"z":192},"requirements":{"minecraft:polished_diorite":8,"minecraft:stone_bricks":26},"sha256":"ac466f5e94ac885986974e08134b86256d77adead197172c63d62565a8130480","size":{"x":32,"y":1,"z":32}},{"blockCount":10,"bytes":948,"file":"chunks/y164-z192-x128.json","offset":{"x":128,"y":164,"z":192},"requirements":{"minecraft:polished_diorite":8,"minecraft:stone_bricks":2},"sha256":"31759515df151d8ec00593c389a3c7cf65ff17bd5412d740809e4ae22d2b881f","size":{"x":32,"y":1,"z":32}},{"blockCount":11,"bytes":1033,"file":"chunks/y165-z064-x096.json","offset":{"x":96,"y":165,"z":64},"requirements":{"minecraft:stone_bricks":11},"sha256":"23e990c3e82c11604cc390f2a42681f57d28fdac7b77be5a8da25218fa1cc6f4","size":{"x":32,"y":1,"z":32}},{"blockCount":2,"bytes":684,"file":"chunks/y165-z064-x128.json","offset":{"x":128,"y":165,"z":64},"requirements":{"minecraft:stone_bricks":2},"sha256":"2e883566913bbcbcb757c35cfb8ffd4fde9826078b1ae44f3dc0bb68ffea2798","size":{"x":32,"y":1,"z":32}},{"blockCount":6,"bytes":788,"file":"chunks/y165-z064-x192.json","offset":{"x":192,"y":165,"z":64},"requirements":{"minecraft:polished_diorite":5,"minecraft:stone_bricks":1},"sha256":"7c97291dedd77e04cb5e1e5dae8157eace50ec1189ac7fd04c75545d537248e7","size":{"x":32,"y":1,"z":32}},{"blockCount":6,"bytes":789,"file":"chunks/y165-z064-x224.json","offset":{"x":224,"y":165,"z":64},"requirements":{"minecraft:polished_diorite":5,"minecraft:stone_bricks":1},"sha256":"f53f6c5743a91828dc77ee3e208bc46c2c7d58e771499abd66c4c8d3311826b6","size":{"x":32,"y":1,"z":32}},{"blockCount":3,"bytes":721,"file":"chunks/y165-z096-x032.json","offset":{"x":32,"y":165,"z":96},"requirements":{"minecraft:stone_bricks":3},"sha256":"5bf32ae0033fcd93f84e672b906c9e98f9d645578f726308f2999ed7381de255","size":{"x":32,"y":1,"z":32}},{"blockCount":2,"bytes":682,"file":"chunks/y165-z096-x064.json","offset":{"x":64,"y":165,"z":96},"requirements":{"minecraft:stone_bricks":2},"sha256":"84d2f5da11c15f4677c109386749927de617a61fcea146f83da99af5ea3b7b9d","size":{"x":32,"y":1,"z":32}},{"blockCount":13,"bytes":1109,"file":"chunks/y165-z096-x096.json","offset":{"x":96,"y":165,"z":96},"requirements":{"minecraft:stone_bricks":13},"sha256":"615965af041b43a5cee72075caf3e448ac6ebaec5935e22a57193ab64869acb7","size":{"x":32,"y":1,"z":32}},{"blockCount":3,"bytes":723,"file":"chunks/y165-z096-x128.json","offset":{"x":128,"y":165,"z":96},"requirements":{"minecraft:stone_bricks":3},"sha256":"02596e1e2662d0cdb9c26b2ddd6cc9ac72fd602e2eacba307f7bc918c60eb20d","size":{"x":32,"y":1,"z":32}},{"blockCount":2,"bytes":683,"file":"chunks/y165-z096-x160.json","offset":{"x":160,"y":165,"z":96},"requirements":{"minecraft:stone_bricks":2},"sha256":"dd66626ce8d10836f817d939a29e438d5d4f9d609ffe41f8bff0a8b7860fe3d2","size":{"x":32,"y":1,"z":32}},{"blockCount":90,"bytes":3075,"file":"chunks/y165-z096-x192.json","offset":{"x":192,"y":165,"z":96},"requirements":{"minecraft:bricks":7,"minecraft:oak_planks":8,"minecraft:polished_diorite":44,"minecraft:spruce_planks":8,"minecraft:stone_bricks":23},"sha256":"c9a9aa7185a57b31fda205183cd0b2588a2c20b9be6285b84a0c321afa38f7c6","size":{"x":32,"y":1,"z":32}},{"blockCount":100,"bytes":3341,"file":"chunks/y165-z096-x224.json","offset":{"x":224,"y":165,"z":96},"requirements":{"minecraft:bricks":9,"minecraft:glass":4,"minecraft:oak_planks":8,"minecraft:polished_diorite":46,"minecraft:spruce_planks":8,"minecraft:stone_bricks":25},"sha256":"fcc7e08811ccc38da093e03019ee88215f1187b24a8588ddaedbb95c53058f0e","size":{"x":32,"y":1,"z":32}},{"blockCount":5,"bytes":798,"file":"chunks/y165-z128-x032.json","offset":{"x":32,"y":165,"z":128},"requirements":{"minecraft:stone_bricks":5},"sha256":"7d4313e90addcf59553588e2f91d9c9d50aacc299178f8f7f0c5a6495ce64e3a","size":{"x":32,"y":1,"z":32}},{"blockCount":11,"bytes":1025,"file":"chunks/y165-z128-x064.json","offset":{"x":64,"y":165,"z":128},"requirements":{"minecraft:stone_bricks":11},"sha256":"8cc2492d1aefa2c7479eb21bf9cb0e4e73adbccd660a22f0bb83472a12ba1609","size":{"x":32,"y":1,"z":32}},{"blockCount":73,"bytes":2149,"file":"chunks/y165-z128-x096.json","offset":{"x":96,"y":165,"z":128},"requirements":{"minecraft:glass":4,"minecraft:oak_planks":1,"minecraft:stone_bricks":68},"sha256":"33fec24b71b98b9b0b7f7eed087cb0a8ded9ccf10ce2caa2aaf747c3cffa0fd0","size":{"x":32,"y":1,"z":32}},{"blockCount":11,"bytes":1026,"file":"chunks/y165-z128-x128.json","offset":{"x":128,"y":165,"z":128},"requirements":{"minecraft:stone_bricks":11},"sha256":"7e37111eef2ad42b0bc89d96759962f43d7faf7d003975ef4e8641507a04b186","size":{"x":32,"y":1,"z":32}},{"blockCount":11,"bytes":1026,"file":"chunks/y165-z128-x160.json","offset":{"x":160,"y":165,"z":128},"requirements":{"minecraft:stone_bricks":11},"sha256":"2633f178018c173f1a98291e3f27137c9c2446d618c00ad8b1f1b6d76cd0a71c","size":{"x":32,"y":1,"z":32}},{"blockCount":16,"bytes":1172,"file":"chunks/y165-z128-x192.json","offset":{"x":192,"y":165,"z":128},"requirements":{"minecraft:polished_diorite":5,"minecraft:stone_bricks":11},"sha256":"110fda6b2f5fa6949f9eb2af6f4b693d8926c803cf77427bff47a08f6ae6a288","size":{"x":32,"y":1,"z":32}},{"blockCount":9,"bytes":906,"file":"chunks/y165-z128-x224.json","offset":{"x":224,"y":165,"z":128},"requirements":{"minecraft:polished_diorite":5,"minecraft:stone_bricks":4},"sha256":"209746ccb8261f67878b2ea4e7b26a8143561cc05c3c76b36a63e493493bbcd7","size":{"x":32,"y":1,"z":32}},{"blockCount":2,"bytes":682,"file":"chunks/y165-z160-x032.json","offset":{"x":32,"y":165,"z":160},"requirements":{"minecraft:stone_bricks":2},"sha256":"d76c614615814c1443bbe667c46ce804ffaca2e34c913dba45fc11a275da06d7","size":{"x":32,"y":1,"z":32}},{"blockCount":2,"bytes":682,"file":"chunks/y165-z160-x064.json","offset":{"x":64,"y":165,"z":160},"requirements":{"minecraft:stone_bricks":2},"sha256":"cf28b346b7db02c1f35ad67a785a37e666a7c36bf51ad9a838514962d4bc8dc8","size":{"x":32,"y":1,"z":32}},{"blockCount":13,"bytes":1111,"file":"chunks/y165-z160-x096.json","offset":{"x":96,"y":165,"z":160},"requirements":{"minecraft:stone_bricks":13},"sha256":"6514c6d21d5d236add078df4f69ec4a6526d4b7f47b95a86edc6961ada537979","size":{"x":32,"y":1,"z":32}},{"blockCount":3,"bytes":724,"file":"chunks/y165-z160-x128.json","offset":{"x":128,"y":165,"z":160},"requirements":{"minecraft:stone_bricks":3},"sha256":"3eb33e1c33bb0d5f15ace5d1009dad6e9c7925cfc9eff298b00fcfa5ae8dc27e","size":{"x":32,"y":1,"z":32}},{"blockCount":2,"bytes":683,"file":"chunks/y165-z160-x160.json","offset":{"x":160,"y":165,"z":160},"requirements":{"minecraft:stone_bricks":2},"sha256":"b522597592d6470716acc8d71cf11d165d948f5eff7967da6e74c20f02d996e5","size":{"x":32,"y":1,"z":32}},{"blockCount":90,"bytes":3114,"file":"chunks/y165-z160-x192.json","offset":{"x":192,"y":165,"z":160},"requirements":{"minecraft:bricks":7,"minecraft:oak_planks":8,"minecraft:polished_diorite":44,"minecraft:spruce_planks":8,"minecraft:stone_bricks":23},"sha256":"d8191dda8b3d94f648ae8f4b6d91535c2186faf983e21a44cebf2d052ae3922a","size":{"x":32,"y":1,"z":32}},{"blockCount":100,"bytes":3342,"file":"chunks/y165-z160-x224.json","offset":{"x":224,"y":165,"z":160},"requirements":{"minecraft:bricks":9,"minecraft:glass":4,"minecraft:oak_planks":8,"minecraft:polished_diorite":46,"minecraft:spruce_planks":8,"minecraft:stone_bricks":25},"sha256":"62d267028e1f7fcc4a8f158dd2efc55b5d07898ca9104bc8be55cab5385bf0ab","size":{"x":32,"y":1,"z":32}},{"blockCount":9,"bytes":955,"file":"chunks/y165-z192-x096.json","offset":{"x":96,"y":165,"z":192},"requirements":{"minecraft:stone_bricks":9},"sha256":"ea2ef7ca8a21283d66c4114df0d78c2ba3fd77ac8ca616890c61614e42c76aec","size":{"x":32,"y":1,"z":32}},{"blockCount":2,"bytes":685,"file":"chunks/y165-z192-x128.json","offset":{"x":128,"y":165,"z":192},"requirements":{"minecraft:stone_bricks":2},"sha256":"5751920e30305086bc9a5ae402fff7dd08a586e2ec291569e7be520fe8bc68cb","size":{"x":32,"y":1,"z":32}},{"blockCount":11,"bytes":1052,"file":"chunks/y166-z064-x096.json","offset":{"x":96,"y":166,"z":64},"requirements":{"minecraft:glass":8,"minecraft:stone_bricks":3},"sha256":"4959fe30d47fadf49eedadd2d608db6519a8dd941d893f7b08d8ccd44a884447","size":{"x":32,"y":1,"z":32}},{"blockCount":2,"bytes":684,"file":"chunks/y166-z064-x128.json","offset":{"x":128,"y":166,"z":64},"requirements":{"minecraft:stone_bricks":2},"sha256":"6362b760a20ec9489e0ac3672a3c35b7fcceac6c9df8105a2764e0b9ad0ec93a","size":{"x":32,"y":1,"z":32}},{"blockCount":6,"bytes":788,"file":"chunks/y166-z064-x192.json","offset":{"x":192,"y":166,"z":64},"requirements":{"minecraft:polished_diorite":5,"minecraft:stone_bricks":1},"sha256":"c4d34aad5a9437c028c0c6ddf287d9cd8f02283b6d79d9a165352746bfed7168","size":{"x":32,"y":1,"z":32}},{"blockCount":6,"bytes":789,"file":"chunks/y166-z064-x224.json","offset":{"x":224,"y":166,"z":64},"requirements":{"minecraft:polished_diorite":5,"minecraft:stone_bricks":1},"sha256":"7ef2f3265b8a8232fc2eb9bcd6ff6cf228dcdc4f8922c3ce2bb6f2a12f8305ea","size":{"x":32,"y":1,"z":32}},{"blockCount":3,"bytes":721,"file":"chunks/y166-z096-x032.json","offset":{"x":32,"y":166,"z":96},"requirements":{"minecraft:stone_bricks":3},"sha256":"f0c1a6da1b365b18be80946caeb5449462f647953c06db460af3fb77ef2cce27","size":{"x":32,"y":1,"z":32}},{"blockCount":2,"bytes":682,"file":"chunks/y166-z096-x064.json","offset":{"x":64,"y":166,"z":96},"requirements":{"minecraft:stone_bricks":2},"sha256":"22c9cb0eca75c7f0d2ab4f38fe047f03e9525d088961c72f70ac02fe5bd7d3be","size":{"x":32,"y":1,"z":32}},{"blockCount":13,"bytes":1129,"file":"chunks/y166-z096-x096.json","offset":{"x":96,"y":166,"z":96},"requirements":{"minecraft:glass":11,"minecraft:stone_bricks":2},"sha256":"d590d5efa3d0aefa449f3ab6e7bdd1c3d25a9dfe521cb359a3106ebe7a86c37b","size":{"x":32,"y":1,"z":32}},{"blockCount":3,"bytes":723,"file":"chunks/y166-z096-x128.json","offset":{"x":128,"y":166,"z":96},"requirements":{"minecraft:stone_bricks":3},"sha256":"db27ae0011ba20155b52312e941a1e048e192837d10f26b4f770c47c12955707","size":{"x":32,"y":1,"z":32}},{"blockCount":2,"bytes":683,"file":"chunks/y166-z096-x160.json","offset":{"x":160,"y":166,"z":96},"requirements":{"minecraft:stone_bricks":2},"sha256":"e5709422fdce0bed888d455f526aa93ade5be8819133580778132ecdf461a91d","size":{"x":32,"y":1,"z":32}},{"blockCount":89,"bytes":3228,"file":"chunks/y166-z096-x192.json","offset":{"x":192,"y":166,"z":96},"requirements":{"minecraft:bricks":7,"minecraft:glass":8,"minecraft:oak_planks":8,"minecraft:polished_diorite":44,"minecraft:spruce_planks":17,"minecraft:stone_bricks":5},"sha256":"e03cc3bed6729298072a23565279d2294d681ec6c379a1d3bfc6966462e3195c","size":{"x":32,"y":1,"z":32}},{"blockCount":96,"bytes":3475,"file":"chunks/y166-z096-x224.json","offset":{"x":224,"y":166,"z":96},"requirements":{"minecraft:bricks":9,"minecraft:glass":13,"minecraft:oak_planks":8,"minecraft:polished_diorite":46,"minecraft:spruce_planks":17,"minecraft:stone_bricks":3},"sha256":"2332e45953f6a6c1a82a4714ed44998532a3f0fbeb6fd4224dc9b1ecf998aa89","size":{"x":32,"y":1,"z":32}},{"blockCount":5,"bytes":818,"file":"chunks/y166-z128-x032.json","offset":{"x":32,"y":166,"z":128},"requirements":{"minecraft:glass":3,"minecraft:stone_bricks":2},"sha256":"56ce99bd3656ab7cff0e92bbf93189f7fd7ecea740d0e832fbf608949d6382e2","size":{"x":32,"y":1,"z":32}},{"blockCount":11,"bytes":1018,"file":"chunks/y166-z128-x064.json","offset":{"x":64,"y":166,"z":128},"requirements":{"minecraft:glass":11},"sha256":"f286943d54e74384ffc9f44d8f7aa39f53dd4f3f54294fe47b927810d264143f","size":{"x":32,"y":1,"z":32}},{"blockCount":61,"bytes":2150,"file":"chunks/y166-z128-x096.json","offset":{"x":96,"y":166,"z":128},"requirements":{"minecraft:glass":16,"minecraft:oak_planks":1,"minecraft:stone_bricks":44},"sha256":"b06d4e16294ae006224972f599344eb5545b1ea4bb92f0d0572ab35eaf25a413","size":{"x":32,"y":1,"z":32}},{"blockCount":11,"bytes":1019,"file":"chunks/y166-z128-x128.json","offset":{"x":128,"y":166,"z":128},"requirements":{"minecraft:glass":11},"sha256":"4c140e2bdcaa390597edf5668c081536ac3b5e253461272b7086174f28018604","size":{"x":32,"y":1,"z":32}},{"blockCount":11,"bytes":1019,"file":"chunks/y166-z128-x160.json","offset":{"x":160,"y":166,"z":128},"requirements":{"minecraft:glass":11},"sha256":"e9d9ddcd5358f7d8e54a082bddab652e580ceecd75468f301d96d36d303a6faa","size":{"x":32,"y":1,"z":32}},{"blockCount":16,"bytes":1192,"file":"chunks/y166-z128-x192.json","offset":{"x":192,"y":166,"z":128},"requirements":{"minecraft:glass":10,"minecraft:polished_diorite":5,"minecraft:stone_bricks":1},"sha256":"d923e29d330a69a921f9fee251b51993432ad1a57cbaa84c6b483c503956401a","size":{"x":32,"y":1,"z":32}},{"blockCount":9,"bytes":926,"file":"chunks/y166-z128-x224.json","offset":{"x":224,"y":166,"z":128},"requirements":{"minecraft:glass":2,"minecraft:polished_diorite":5,"minecraft:stone_bricks":2},"sha256":"764c33c3e91f766c95ebaf79d3d7c443072ae43e71237a870b445788af8979fc","size":{"x":32,"y":1,"z":32}},{"blockCount":2,"bytes":682,"file":"chunks/y166-z160-x032.json","offset":{"x":32,"y":166,"z":160},"requirements":{"minecraft:stone_bricks":2},"sha256":"ef415db382a0935309f0300f6e8eed90e9bf0619178397c33d5c7543890b819e","size":{"x":32,"y":1,"z":32}},{"blockCount":2,"bytes":682,"file":"chunks/y166-z160-x064.json","offset":{"x":64,"y":166,"z":160},"requirements":{"minecraft:stone_bricks":2},"sha256":"9826fdb8779c3d37d8b54274c4baf2d8e8dcf6d82e1ac2097e419add2e9ff369","size":{"x":32,"y":1,"z":32}},{"blockCount":13,"bytes":1131,"file":"chunks/y166-z160-x096.json","offset":{"x":96,"y":166,"z":160},"requirements":{"minecraft:glass":11,"minecraft:stone_bricks":2},"sha256":"5ffcadbaf7d922c6e381dfb7cf02309aff68a8e5ed27bd04db4052bb1d297844","size":{"x":32,"y":1,"z":32}},{"blockCount":3,"bytes":724,"file":"chunks/y166-z160-x128.json","offset":{"x":128,"y":166,"z":160},"requirements":{"minecraft:stone_bricks":3},"sha256":"525b20dcbab05d36dada444b10d36ae27b0809df916b97f0a8b5e56965233236","size":{"x":32,"y":1,"z":32}},{"blockCount":2,"bytes":683,"file":"chunks/y166-z160-x160.json","offset":{"x":160,"y":166,"z":160},"requirements":{"minecraft:stone_bricks":2},"sha256":"95be06ec87d9291d0abbcd3930e530d117cc19b71c179738eccaa82301e746c4","size":{"x":32,"y":1,"z":32}},{"blockCount":89,"bytes":3229,"file":"chunks/y166-z160-x192.json","offset":{"x":192,"y":166,"z":160},"requirements":{"minecraft:bricks":7,"minecraft:glass":8,"minecraft:oak_planks":8,"minecraft:polished_diorite":44,"minecraft:spruce_planks":17,"minecraft:stone_bricks":5},"sha256":"ee581310d062baa9a0a126af7a779bdb6fffffd74abc1f401cece54a07edf221","size":{"x":32,"y":1,"z":32}},{"blockCount":96,"bytes":3476,"file":"chunks/y166-z160-x224.json","offset":{"x":224,"y":166,"z":160},"requirements":{"minecraft:bricks":9,"minecraft:glass":13,"minecraft:oak_planks":8,"minecraft:polished_diorite":46,"minecraft:spruce_planks":17,"minecraft:stone_bricks":3},"sha256":"022778291be5ab29d4b3ab6665f794ace5c668925041469be118e318d94212cd","size":{"x":32,"y":1,"z":32}},{"blockCount":9,"bytes":975,"file":"chunks/y166-z192-x096.json","offset":{"x":96,"y":166,"z":192},"requirements":{"minecraft:glass":6,"minecraft:stone_bricks":3},"sha256":"c0ccdda737d34446f14bfc22febaf35dbfc4c3d769dc4e0a8ab7438f4e46d693","size":{"x":32,"y":1,"z":32}},{"blockCount":2,"bytes":685,"file":"chunks/y166-z192-x128.json","offset":{"x":128,"y":166,"z":192},"requirements":{"minecraft:stone_bricks":2},"sha256":"058a0269280822cf16e90355c8e31dac69d50b4d9518841930d7156704b336fd","size":{"x":32,"y":1,"z":32}},{"blockCount":7,"bytes":824,"file":"chunks/y167-z064-x096.json","offset":{"x":96,"y":167,"z":64},"requirements":{"minecraft:sandstone":2,"minecraft:stone_bricks":5},"sha256":"053bfe17949541aa5f84897a72be41356f4f97347f5a74c1dd3a553c50dcce9e","size":{"x":32,"y":1,"z":32}},{"blockCount":2,"bytes":681,"file":"chunks/y167-z064-x128.json","offset":{"x":128,"y":167,"z":64},"requirements":{"minecraft:sandstone":2},"sha256":"361fc4fd7f79a3f4a8655a7da25a405ae9df3b56a238c02c4f16d61c70da37de","size":{"x":32,"y":1,"z":32}},{"blockCount":6,"bytes":788,"file":"chunks/y167-z064-x192.json","offset":{"x":192,"y":167,"z":64},"requirements":{"minecraft:polished_diorite":5,"minecraft:stone_bricks":1},"sha256":"2c1a39c2218601cdb24a08cb3fb9aef386784ccdd96e5af6c2cb60c1e5de3dba","size":{"x":32,"y":1,"z":32}},{"blockCount":6,"bytes":789,"file":"chunks/y167-z064-x224.json","offset":{"x":224,"y":167,"z":64},"requirements":{"minecraft:polished_diorite":5,"minecraft:stone_bricks":1},"sha256":"884bd968f7c07857f56904eb230d591bcef9538426f86c8dd81f4c62dd9a97f0","size":{"x":32,"y":1,"z":32}},{"blockCount":3,"bytes":718,"file":"chunks/y167-z096-x032.json","offset":{"x":32,"y":167,"z":96},"requirements":{"minecraft:sandstone":3},"sha256":"2f32cb1ca7113563366ae63fc7e68d57fb95cc2b18ad8ffc3a1e6884c1048c78","size":{"x":32,"y":1,"z":32}},{"blockCount":2,"bytes":679,"file":"chunks/y167-z096-x064.json","offset":{"x":64,"y":167,"z":96},"requirements":{"minecraft:sandstone":2},"sha256":"2745f26bed4b408a2769d0516be5010a0bb86c18640f1c271047420bdd7061bf","size":{"x":32,"y":1,"z":32}},{"blockCount":2,"bytes":678,"file":"chunks/y167-z096-x096.json","offset":{"x":96,"y":167,"z":96},"requirements":{"minecraft:sandstone":2},"sha256":"f78cbfc638e5c10a22d5055728fc7883607da95d812ae6226d043204027e4651","size":{"x":32,"y":1,"z":32}},{"blockCount":3,"bytes":720,"file":"chunks/y167-z096-x128.json","offset":{"x":128,"y":167,"z":96},"requirements":{"minecraft:sandstone":3},"sha256":"2364c2862c5697762df35a2b329d551ddb0fe474c6576a79c1deed2ba74474c8","size":{"x":32,"y":1,"z":32}},{"blockCount":2,"bytes":680,"file":"chunks/y167-z096-x160.json","offset":{"x":160,"y":167,"z":96},"requirements":{"minecraft:sandstone":2},"sha256":"83d56bca6f2fb87d7278d80047df8de9998e46fbe493bc724bcf28289f46fb84","size":{"x":32,"y":1,"z":32}},{"blockCount":82,"bytes":2900,"file":"chunks/y167-z096-x192.json","offset":{"x":192,"y":167,"z":96},"requirements":{"minecraft:bricks":7,"minecraft:oak_planks":8,"minecraft:polished_diorite":44,"minecraft:sandstone":2,"minecraft:stone_bricks":21},"sha256":"2569ef86d035ca24b9abfc8b09bc13f34490961d6139c63ccf3de3dfac97b7fa","size":{"x":32,"y":1,"z":32}},{"blockCount":93,"bytes":3204,"file":"chunks/y167-z096-x224.json","offset":{"x":224,"y":167,"z":96},"requirements":{"minecraft:bricks":9,"minecraft:glass":4,"minecraft:oak_planks":8,"minecraft:polished_diorite":46,"minecraft:sandstone":1,"minecraft:stone_bricks":25},"sha256":"fb5a4830d368d07879c4ff2101c33b05b764c6347d3da453ab8dbd9a838e2b84","size":{"x":32,"y":1,"z":32}},{"blockCount":6,"bytes":786,"file":"chunks/y167-z128-x032.json","offset":{"x":32,"y":167,"z":128},"requirements":{"minecraft:sandstone":1,"minecraft:stone_bricks":5},"sha256":"3e09d8d26f22676ef2eaa11659031777828078481dac194014266a04b3e69778","size":{"x":32,"y":1,"z":32}},{"blockCount":50,"bytes":1709,"file":"chunks/y167-z128-x096.json","offset":{"x":96,"y":167,"z":128},"requirements":{"minecraft:glass":5,"minecraft:oak_planks":1,"minecraft:stone_bricks":44},"sha256":"bab9df2ab48134aec0b2a23da74c75f11131b23415e58cceaa91abf7fc3418e9","size":{"x":32,"y":1,"z":32}},{"blockCount":6,"bytes":789,"file":"chunks/y167-z128-x192.json","offset":{"x":192,"y":167,"z":128},"requirements":{"minecraft:polished_diorite":5,"minecraft:stone_bricks":1},"sha256":"008a02f25de9ba2a9f27dd6c81921eaf04a4858c1c792b924aec0b121c75a027","size":{"x":32,"y":1,"z":32}},{"blockCount":11,"bytes":908,"file":"chunks/y167-z128-x224.json","offset":{"x":224,"y":167,"z":128},"requirements":{"minecraft:polished_diorite":5,"minecraft:stone_bricks":6},"sha256":"bccdfe46463225f64cda76fb84774fd2fb96f69c4f6458d9fd0e2f1cbff48416","size":{"x":32,"y":1,"z":32}},{"blockCount":2,"bytes":679,"file":"chunks/y167-z160-x032.json","offset":{"x":32,"y":167,"z":160},"requirements":{"minecraft:sandstone":2},"sha256":"f18bc7b5260146a4cb9733fb46ee31158166bd125e3169f7ebe83780024eceeb","size":{"x":32,"y":1,"z":32}},{"blockCount":2,"bytes":679,"file":"chunks/y167-z160-x064.json","offset":{"x":64,"y":167,"z":160},"requirements":{"minecraft:sandstone":2},"sha256":"2a6fb68ade72bcc473aaa83e541d37a0d205b550e9b72ed9a8917b586248f48c","size":{"x":32,"y":1,"z":32}},{"blockCount":2,"bytes":681,"file":"chunks/y167-z160-x096.json","offset":{"x":96,"y":167,"z":160},"requirements":{"minecraft:sandstone":2},"sha256":"28fea99d9797acc8619c998eaf2465a67a9efaf66f47773cd328da86e1b59e1f","size":{"x":32,"y":1,"z":32}},{"blockCount":3,"bytes":721,"file":"chunks/y167-z160-x128.json","offset":{"x":128,"y":167,"z":160},"requirements":{"minecraft:sandstone":3},"sha256":"8c5067b9b40488b407f8399003f92a3f642c0af2b465aaa6a0fa22ae0bc44170","size":{"x":32,"y":1,"z":32}},{"blockCount":2,"bytes":680,"file":"chunks/y167-z160-x160.json","offset":{"x":160,"y":167,"z":160},"requirements":{"minecraft:sandstone":2},"sha256":"1a6be47f1f96d9dd730d0078a242eccd6458987788517176ba79a81ebcfab85f","size":{"x":32,"y":1,"z":32}},{"blockCount":82,"bytes":2920,"file":"chunks/y167-z160-x192.json","offset":{"x":192,"y":167,"z":160},"requirements":{"minecraft:bricks":7,"minecraft:oak_planks":8,"minecraft:polished_diorite":44,"minecraft:sandstone":2,"minecraft:stone_bricks":21},"sha256":"97737c9e74fabe958ddf8c4179f01c182817aa74b264cf43cfabb260cd76f65f","size":{"x":32,"y":1,"z":32}},{"blockCount":93,"bytes":3205,"file":"chunks/y167-z160-x224.json","offset":{"x":224,"y":167,"z":160},"requirements":{"minecraft:bricks":9,"minecraft:glass":4,"minecraft:oak_planks":8,"minecraft:polished_diorite":46,"minecraft:sandstone":1,"minecraft:stone_bricks":25},"sha256":"07be8ebd66393479cce5659575b1f86858b991976b25e5642760815ac25268a8","size":{"x":32,"y":1,"z":32}},{"blockCount":7,"bytes":824,"file":"chunks/y167-z192-x096.json","offset":{"x":96,"y":167,"z":192},"requirements":{"minecraft:sandstone":2,"minecraft:stone_bricks":5},"sha256":"8dd2cf2cda64292fd3372390ca6c2fda52973b14f63d21a34aedc83b77eece04","size":{"x":32,"y":1,"z":32}},{"blockCount":2,"bytes":682,"file":"chunks/y167-z192-x128.json","offset":{"x":128,"y":167,"z":192},"requirements":{"minecraft:sandstone":2},"sha256":"c6a4d69578764986b80716b731d862674648c310f449b4d091fafb0e2810553d","size":{"x":32,"y":1,"z":32}},{"blockCount":7,"bytes":800,"file":"chunks/y168-z064-x096.json","offset":{"x":96,"y":168,"z":64},"requirements":{"minecraft:stone_bricks":7},"sha256":"dddb94dbea16b614784e4af3bc9a3407a5d711bfe90d18a2b2aecb0c7a4ae76d","size":{"x":32,"y":1,"z":32}},{"blockCount":2,"bytes":684,"file":"chunks/y168-z064-x128.json","offset":{"x":128,"y":168,"z":64},"requirements":{"minecraft:stone_bricks":2},"sha256":"a9624c992a6f4853d2137953b05359c2b37cb06d8158578cfd7b93fc54c38e08","size":{"x":32,"y":1,"z":32}},{"blockCount":6,"bytes":788,"file":"chunks/y168-z064-x192.json","offset":{"x":192,"y":168,"z":64},"requirements":{"minecraft:polished_diorite":5,"minecraft:stone_bricks":1},"sha256":"b2bbc3dfceaea18f1764e9b101a41e6fd79f32681fe9e5dd9ec3f5a30e020e22","size":{"x":32,"y":1,"z":32}},{"blockCount":6,"bytes":789,"file":"chunks/y168-z064-x224.json","offset":{"x":224,"y":168,"z":64},"requirements":{"minecraft:polished_diorite":5,"minecraft:stone_bricks":1},"sha256":"9eb01c86d4abf41c49cfaf26a30f81bb2ebc56bdfb4cdb5e9b65122ce1ed1321","size":{"x":32,"y":1,"z":32}},{"blockCount":3,"bytes":721,"file":"chunks/y168-z096-x032.json","offset":{"x":32,"y":168,"z":96},"requirements":{"minecraft:stone_bricks":3},"sha256":"a4ee4d82c66eb348fbfbc8c691a3b4308d7dd83d24846440361e1916f9f3263b","size":{"x":32,"y":1,"z":32}},{"blockCount":2,"bytes":682,"file":"chunks/y168-z096-x064.json","offset":{"x":64,"y":168,"z":96},"requirements":{"minecraft:stone_bricks":2},"sha256":"a84aad1c8c8f9e581d085cc6b8ee7bef45651063011956f859c0628440e71457","size":{"x":32,"y":1,"z":32}},{"blockCount":2,"bytes":681,"file":"chunks/y168-z096-x096.json","offset":{"x":96,"y":168,"z":96},"requirements":{"minecraft:stone_bricks":2},"sha256":"f74f8f19bfdbdd43a7b7411c68182db92a50d98f20df36f934eb0587fca13c8d","size":{"x":32,"y":1,"z":32}},{"blockCount":3,"bytes":723,"file":"chunks/y168-z096-x128.json","offset":{"x":128,"y":168,"z":96},"requirements":{"minecraft:stone_bricks":3},"sha256":"c49ae02a3db009b112a922b496d853c48f7c4ce0a51cbdd688a876841bb535f8","size":{"x":32,"y":1,"z":32}},{"blockCount":2,"bytes":683,"file":"chunks/y168-z096-x160.json","offset":{"x":160,"y":168,"z":96},"requirements":{"minecraft:stone_bricks":2},"sha256":"b80e1c67b0943cdc6b4bd19885d18c5f22248978add2be1cf3e07e899cc79b40","size":{"x":32,"y":1,"z":32}},{"blockCount":72,"bytes":2682,"file":"chunks/y168-z096-x192.json","offset":{"x":192,"y":168,"z":96},"requirements":{"minecraft:bricks":7,"minecraft:glass":8,"minecraft:oak_planks":8,"minecraft:polished_diorite":44,"minecraft:stone_bricks":5},"sha256":"e4148eddea3b2bbe82f3d3f1ce66221d87e3d2c06ba8e328bc5f4697f4c2ae92","size":{"x":32,"y":1,"z":32}},{"blockCount":79,"bytes":2948,"file":"chunks/y168-z096-x224.json","offset":{"x":224,"y":168,"z":96},"requirements":{"minecraft:bricks":9,"minecraft:glass":13,"minecraft:oak_planks":8,"minecraft:polished_diorite":46,"minecraft:stone_bricks":3},"sha256":"3f99ca1f627d18d138345548368d9be6fb58ae2ebbfddc8c0b4632c2477525dc","size":{"x":32,"y":1,"z":32}},{"blockCount":2,"bytes":684,"file":"chunks/y168-z128-x032.json","offset":{"x":32,"y":168,"z":128},"requirements":{"minecraft:stone_bricks":2},"sha256":"39730e57948ea99dbd0da32a09a47df7b7aaf2e875746beb5d24645a4fb290a5","size":{"x":32,"y":1,"z":32}},{"blockCount":125,"bytes":1290,"file":"chunks/y168-z128-x096.json","offset":{"x":96,"y":168,"z":128},"requirements":{"minecraft:glass":2,"minecraft:stone_bricks":123},"sha256":"914797843d64b7d4e3b29f3ee74f7d8ed6c2d21bd83f5511a26f9a7f82142fc9","size":{"x":32,"y":1,"z":32}},{"blockCount":6,"bytes":789,"file":"chunks/y168-z128-x192.json","offset":{"x":192,"y":168,"z":128},"requirements":{"minecraft:polished_diorite":5,"minecraft:stone_bricks":1},"sha256":"83d6ce0b1466f97d29056a2e4753c7d6f47d939ddab3f05d85a389ed5abef826","size":{"x":32,"y":1,"z":32}},{"blockCount":11,"bytes":908,"file":"chunks/y168-z128-x224.json","offset":{"x":224,"y":168,"z":128},"requirements":{"minecraft:polished_diorite":5,"minecraft:stone_bricks":6},"sha256":"25b0cbcb2a109cc30cb19b03deb0db1bb90bdc47df59a7537a43b0678e8afcff","size":{"x":32,"y":1,"z":32}},{"blockCount":2,"bytes":682,"file":"chunks/y168-z160-x032.json","offset":{"x":32,"y":168,"z":160},"requirements":{"minecraft:stone_bricks":2},"sha256":"206a3e7ec41e03c279609596d7f38aefa0937d2b88ccb456c7bf0954529e8b8c","size":{"x":32,"y":1,"z":32}},{"blockCount":2,"bytes":682,"file":"chunks/y168-z160-x064.json","offset":{"x":64,"y":168,"z":160},"requirements":{"minecraft:stone_bricks":2},"sha256":"cb2ba6848d1a3bac06410c098996e98fc08a6d5868b3a5a7a3198505d5db88f8","size":{"x":32,"y":1,"z":32}},{"blockCount":2,"bytes":684,"file":"chunks/y168-z160-x096.json","offset":{"x":96,"y":168,"z":160},"requirements":{"minecraft:stone_bricks":2},"sha256":"7788a30819edde7824832c6878bc8922c12942bb42d957f5064ed039bdc0d378","size":{"x":32,"y":1,"z":32}},{"blockCount":3,"bytes":724,"file":"chunks/y168-z160-x128.json","offset":{"x":128,"y":168,"z":160},"requirements":{"minecraft:stone_bricks":3},"sha256":"19f85d2c7f723c6c756edbc04d583f08e86eae570117abc62955fb35f8f8c1a7","size":{"x":32,"y":1,"z":32}},{"blockCount":2,"bytes":683,"file":"chunks/y168-z160-x160.json","offset":{"x":160,"y":168,"z":160},"requirements":{"minecraft:stone_bricks":2},"sha256":"2636bd902a676e5c0fd05a70c0f127a116403580b36847bbb329dad573b9385d","size":{"x":32,"y":1,"z":32}},{"blockCount":72,"bytes":2683,"file":"chunks/y168-z160-x192.json","offset":{"x":192,"y":168,"z":160},"requirements":{"minecraft:bricks":7,"minecraft:glass":8,"minecraft:oak_planks":8,"minecraft:polished_diorite":44,"minecraft:stone_bricks":5},"sha256":"69a64603efd677d81b829cafc3f70af6506861d0656b8eaf46a65bdab14091ce","size":{"x":32,"y":1,"z":32}},{"blockCount":79,"bytes":2949,"file":"chunks/y168-z160-x224.json","offset":{"x":224,"y":168,"z":160},"requirements":{"minecraft:bricks":9,"minecraft:glass":13,"minecraft:oak_planks":8,"minecraft:polished_diorite":46,"minecraft:stone_bricks":3},"sha256":"dc427d50b284617b5b9151dccc311606124f9577e3f8bf7cdec160fca1654685","size":{"x":32,"y":1,"z":32}},{"blockCount":7,"bytes":800,"file":"chunks/y168-z192-x096.json","offset":{"x":96,"y":168,"z":192},"requirements":{"minecraft:stone_bricks":7},"sha256":"e314c3bb78c49b786fe5d8d01d3f7e0dee95cd4c844a1e10f6c4ad67c6d5a4b0","size":{"x":32,"y":1,"z":32}},{"blockCount":2,"bytes":685,"file":"chunks/y168-z192-x128.json","offset":{"x":128,"y":168,"z":192},"requirements":{"minecraft:stone_bricks":2},"sha256":"70412e10c6122229013f9a20c940af1322fe7dfcdacca6c6dc7e5323d31cdd73","size":{"x":32,"y":1,"z":32}},{"blockCount":3,"bytes":722,"file":"chunks/y169-z064-x096.json","offset":{"x":96,"y":169,"z":64},"requirements":{"minecraft:stone_bricks":3},"sha256":"9ffcc8df53866afc2a911c0442079ca02b464a1fb18a8734a415962d20cda785","size":{"x":32,"y":1,"z":32}},{"blockCount":2,"bytes":684,"file":"chunks/y169-z064-x128.json","offset":{"x":128,"y":169,"z":64},"requirements":{"minecraft:stone_bricks":2},"sha256":"f592fd074de008ae4423a60c0ebf61cd3192cdd8d09762379647c7071e4d04c2","size":{"x":32,"y":1,"z":32}},{"blockCount":6,"bytes":788,"file":"chunks/y169-z064-x192.json","offset":{"x":192,"y":169,"z":64},"requirements":{"minecraft:polished_diorite":5,"minecraft:stone_bricks":1},"sha256":"195dd4129bbe3f114e115e3ca13ab0dad9809e4651495df9099d605eccddcb12","size":{"x":32,"y":1,"z":32}}],"schema":1}
