{"entries":[{"blockCount":6,"bytes":789,"file":"chunks/y169-z064-x224.json","offset":{"x":224,"y":169,"z":64},"requirements":{"minecraft:polished_diorite":5,"minecraft:stone_bricks":1},"sha256":"426edd3b7dc581f17019ddb09984b30e7962d534124a4cbfba19c5e9ef87f83a","size":{"x":32,"y":1,"z":32}},{"blockCount":3,"bytes":721,"file":"chunks/y169-z096-x032.json","offset":{"x":32,"y":169,"z":96},"requirements":{"minecraft:stone_bricks":3},"sha256":"b01c983989c8914b748b30b5c3df4da1fd767226b4d13adb7d48693b3c10aa09","size":{"x":32,"y":1,"z":32}},{"blockCount":2,"bytes":682,"file":"chunks/y169-z096-x064.json","offset":{"x":64,"y":169,"z":96},"requirements":{"minecraft:stone_bricks":2},"sha256":"94606318bed404e4dc49a06feb002b36f757d843965a72e6f03204f72d9f6d60","size":{"x":32,"y":1,"z":32}},{"blockCount":2,"bytes":681,"file":"chunks/y169-z096-x096.json","offset":{"x":96,"y":169,"z":96},"requirements":{"minecraft:stone_bricks":2},"sha256":"f13d8f9b995486694c048be602d879d50ffd8994282ce6d597ab3712c5a41348","size":{"x":32,"y":1,"z":32}},{"blockCount":3,"bytes":723,"file":"chunks/y169-z096-x128.json","offset":{"x":128,"y":169,"z":96},"requirements":{"minecraft:stone_bricks":3},"sha256":"6ab5bdfb6130991d924a121cedf07e11c8af0a5cf64e9d1f4ca18958f62bba13","size":{"x":32,"y":1,"z":32}},{"blockCount":2,"bytes":683,"file":"chunks/y169-z096-x160.json","offset":{"x":160,"y":169,"z":96},"requirements":{"minecraft:stone_bricks":2},"sha256":"0dc864d056e7c5765b4498a9e8c7a42628f633608127e420a62a0562f03a10ee","size":{"x":32,"y":1,"z":32}},{"blockCount":82,"bytes":2857,"file":"chunks/y169-z096-x192.json","offset":{"x":192,"y":169,"z":96},"requirements":{"minecraft:bricks":7,"minecraft:oak_planks":8,"minecraft:polished_diorite":44,"minecraft:stone_bricks":23},"sha256":"03e8babda87e72af37b4b2e1c3af9c57a40796a80be6a3f28f7cb92eac59bdbc","size":{"x":32,"y":1,"z":32}},{"blockCount":93,"bytes":3180,"file":"chunks/y169-z096-x224.json","offset":{"x":224,"y":169,"z":96},"requirements":{"minecraft:bricks":9,"minecraft:glass":5,"minecraft:oak_planks":8,"minecraft:polished_diorite":46,"minecraft:stone_bricks":25},"sha256":"7d3b38ae04005231fdcc5e5977c48d0581911b8170bfd28406698f88b82ae1ea","size":{"x":32,"y":1,"z":32}},{"blockCount":2,"bytes":684,"file":"chunks/y169-z128-x032.json","offset":{"x":32,"y":169,"z":128},"requirements":{"minecraft:stone_bricks":2},"sha256":"bb22bc1b71761ca890684c32d5547953393e31e779702999ae70f27e17ff2082","size":{"x":32,"y":1,"z":32}},{"blockCount":55,"bytes":1849,"file":"chunks/y169-z128-x096.json","offset":{"x":96,"y":169,"z":128},"requirements":{"minecraft:glass":4,"minecraft:polished_diorite":40,"minecraft:stone_bricks":11},"sha256":"31eeb16985b2d172af2af148ba7d753d77baf68a2dd1031b182ba8a2e28939d6","size":{"x":32,"y":1,"z":32}},{"blockCount":6,"bytes":789,"file":"chunks/y169-z128-x192.json","offset":{"x":192,"y":169,"z":128},"requirements":{"minecraft:polished_diorite":5,"minecraft:stone_bricks":1},"sha256":"740b39ceea9d425d126eefc2f1a801d938f8b220e20aa2027c0c5fa3ad00d957","size":{"x":32,"y":1,"z":32}},{"blockCount":7,"bytes":830,"file":"chunks/y169-z128-x224.json","offset":{"x":224,"y":169,"z":128},"requirements":{"minecraft:polished_diorite":5,"minecraft:stone_bricks":2},"sha256":"4708f40341be20b491207e3ee3b02eab82edabd4f5e1a3f472fd3e1311c057b6","size":{"x":32,"y":1,"z":32}},{"blockCount":2,"bytes":682,"file":"chunks/y169-z160-x032.json","offset":{"x":32,"y":169,"z":160},"requirements":{"minecraft:stone_bricks":2},"sha256":"7acd22f573b0a92348362e4cfdcbe135a45b5adf765f98acc3d728879927b28a","size":{"x":32,"y":1,"z":32}},{"blockCount":2,"bytes":682,"file":"chunks/y169-z160-x064.json","offset":{"x":64,"y":169,"z":160},"requirements":{"minecraft:stone_bricks":2},"sha256":"de3776646d8c5f95a96e3a3a9aca78150de6b34281880b2f49c68167308ed85d","size":{"x":32,"y":1,"z":32}},{"blockCount":2,"bytes":684,"file":"chunks/y169-z160-x096.json","offset":{"x":96,"y":169,"z":160},"requirements":{"minecraft:stone_bricks":2},"sha256":"0f1f9f4b831de369a9b42c4009ff5ff11ee7ea44525cd0622e527cb9550a6ca7","size":{"x":32,"y":1,"z":32}},{"blockCount":3,"bytes":724,"file":"chunks/y169-z160-x128.json","offset":{"x":128,"y":169,"z":160},"requirements":{"minecraft:stone_bricks":3},"sha256":"e29eefb728dcb8c9fefc771ccdaf853c5b839eae09859c5751899ecb754552e5","size":{"x":32,"y":1,"z":32}},{"blockCount":2,"bytes":683,"file":"chunks/y169-z160-x160.json","offset":{"x":160,"y":169,"z":160},"requirements":{"minecraft:stone_bricks":2},"sha256":"57eb57e843de685b9f403784a4b81e3ab0d53093260e9b47d260443d68f2c335","size":{"x":32,"y":1,"z":32}},{"blockCount":82,"bytes":2896,"file":"chunks/y169-z160-x192.json","offset":{"x":192,"y":169,"z":160},"requirements":{"minecraft:bricks":7,"minecraft:oak_planks":8,"minecraft:polished_diorite":44,"minecraft:stone_bricks":23},"sha256":"db61dc197a13118011a19d3d1985e55fa88977eb3abba92756781a90bb88bdea","size":{"x":32,"y":1,"z":32}},{"blockCount":93,"bytes":3181,"file":"chunks/y169-z160-x224.json","offset":{"x":224,"y":169,"z":160},"requirements":{"minecraft:bricks":9,"minecraft:glass":5,"minecraft:oak_planks":8,"minecraft:polished_diorite":46,"minecraft:stone_bricks":25},"sha256":"e67fd0bd29af50e9c3d67538783a8e906ca67f828f5ed14cccdd1d3668964697","size":{"x":32,"y":1,"z":32}},{"blockCount":3,"bytes":723,"file":"chunks/y169-z192-x096.json","offset":{"x":96,"y":169,"z":192},"requirements":{"minecraft:stone_bricks":3},"sha256":"c53418ebf4e1585a3b48026178b77e01df37a56b7ff82b3d25bee270d4a2d1a6","size":{"x":32,"y":1,"z":32}},{"blockCount":2,"bytes":685,"file":"chunks/y169-z192-x128.json","offset":{"x":128,"y":169,"z":192},"requirements":{"minecraft:stone_bricks":2},"sha256":"ff8c72a8f9d297998a2504638ff271d6921838d007c4ae2f58a35e64ad0e5551","size":{"x":32,"y":1,"z":32}},{"blockCount":16,"bytes":1095,"file":"chunks/y170-z064-x096.json","offset":{"x":96,"y":170,"z":64},"requirements":{"minecraft:sandstone":2,"minecraft:stone_bricks":14},"sha256":"3199efe1213de35bbe2d7493432c1263c2629244e8759c78cbea3d4c5ef0ebd6","size":{"x":32,"y":1,"z":32}},{"blockCount":11,"bytes":979,"file":"chunks/y170-z064-x128.json","offset":{"x":128,"y":170,"z":64},"requirements":{"minecraft:sandstone":2,"minecraft:stone_bricks":9},"sha256":"df87c0bb8b09f94fc52db0be38aa4c6bba03f6075ea802f3a818817bd5c5d2f2","size":{"x":32,"y":1,"z":32}},{"blockCount":6,"bytes":826,"file":"chunks/y170-z064-x192.json","offset":{"x":192,"y":170,"z":64},"requirements":{"minecraft:polished_diorite":4,"minecraft:stone_bricks":2},"sha256":"7ea93ea40be0ac3ea4a4f97a1214769b9b168a5e1006359179020c288c3b0e4d","size":{"x":32,"y":1,"z":32}},{"blockCount":6,"bytes":827,"file":"chunks/y170-z064-x224.json","offset":{"x":224,"y":170,"z":64},"requirements":{"minecraft:polished_diorite":4,"minecraft:stone_bricks":2},"sha256":"4a41f0ccb78057278d8ca28c3307ded0ae48e0efbd3cd26543155749bfbf266a","size":{"x":32,"y":1,"z":32}},{"blockCount":14,"bytes":1055,"file":"chunks/y170-z096-x032.json","offset":{"x":32,"y":170,"z":96},"requirements":{"minecraft:sandstone":3,"minecraft:stone_bricks":11},"sha256":"d976f0842b9bb45789e7dcc6c61b099a5a0933dca74ef9a0059bfd23e32ba1ff","size":{"x":32,"y":1,"z":32}},{"blockCount":10,"bytes":938,"file":"chunks/y170-z096-x064.json","offset":{"x":64,"y":170,"z":96},"requirements":{"minecraft:sandstone":2,"minecraft:stone_bricks":8},"sha256":"1683f0068bdda599a1bcccde5f1edd6f61e2e1aba9cfba971c7d28ac7c256321","size":{"x":32,"y":1,"z":32}},{"blockCount":9,"bytes":898,"file":"chunks/y170-z096-x096.json","offset":{"x":96,"y":170,"z":96},"requirements":{"minecraft:sandstone":2,"minecraft:stone_bricks":7},"sha256":"e50864476d5b4c32deb481bb9e542decfa7005379c02c3ffd2d0e1e5ee854d7e","size":{"x":32,"y":1,"z":32}},{"blockCount":14,"bytes":1057,"file":"chunks/y170-z096-x128.json","offset":{"x":128,"y":170,"z":96},"requirements":{"minecraft:sandstone":3,"minecraft:stone_bricks":11},"sha256":"6ae3788cee91266767fc63b6ace4a7f9b3823df4ea788bfeb9bbaef8919307c4","size":{"x":32,"y":1,"z":32}},{"blockCount":11,"bytes":977,"file":"chunks/y170-z096-x160.json","offset":{"x":160,"y":170,"z":96},"requirements":{"minecraft:sandstone":2,"minecraft:stone_bricks":9},"sha256":"ac6a5a2def419e477d06972c150e8f48d1f22bcf37a3b3651e5ce68d97e4eed9","size":{"x":32,"y":1,"z":32}},{"blockCount":79,"bytes":3144,"file":"chunks/y170-z096-x192.json","offset":{"x":192,"y":170,"z":96},"requirements":{"minecraft:bricks":7,"minecraft:glass":8,"minecraft:oak_planks":8,"minecraft:polished_diorite":29,"minecraft:sandstone":2,"minecraft:stone_bricks":25},"sha256":"bd2ff2fb27f051dd0a872ea7b6e33fa448f7bce37e0f62e2ed86a8abe9e6380d","size":{"x":32,"y":1,"z":32}},{"blockCount":80,"bytes":3215,"file":"chunks/y170-z096-x224.json","offset":{"x":224,"y":170,"z":96},"requirements":{"minecraft:bricks":9,"minecraft:glass":14,"minecraft:oak_planks":8,"minecraft:polished_diorite":31,"minecraft:stone_bricks":18},"sha256":"c5e62305a154e8710f7bcc1586f2e33de0eae9365f5dfd1a8cf14076e019bdc5","size":{"x":32,"y":1,"z":32}},{"blockCount":7,"bytes":862,"file":"chunks/y170-z128-x032.json","offset":{"x":32,"y":170,"z":128},"requirements":{"minecraft:sandstone":1,"minecraft:stone_bricks":6},"sha256":"064fa9c4ea4a86d10634f8ff2ce5fca079cc378bd33ebd11a06b4becbae1727e","size":{"x":32,"y":1,"z":32}},{"blockCount":57,"bytes":1924,"file":"chunks/y170-z128-x096.json","offset":{"x":96,"y":170,"z":128},"requirements":{"minecraft:glass":40,"minecraft:polished_diorite":8,"minecraft:stone_bricks":9},"sha256":"bb950eb98794b6fe803b81a9048e1c1ee3573fe38a1f6d15e97bfc9c24917961","size":{"x":32,"y":1,"z":32}},{"blockCount":6,"bytes":827,"file":"chunks/y170-z128-x192.json","offset":{"x":192,"y":170,"z":128},"requirements":{"minecraft:polished_diorite":4,"minecraft:stone_bricks":2},"sha256":"6b05cebb3b19dab4d7ad10e0fe59ae1e19b1d323a33da1edef847f29721fec10","size":{"x":32,"y":1,"z":32}},{"blockCount":7,"bytes":868,"file":"chunks/y170-z128-x224.json","offset":{"x":224,"y":170,"z":128},"requirements":{"minecraft:polished_diorite":4,"minecraft:stone_bricks":3},"sha256":"c8e6a3b0922abca55fabcd1222d973fe645f687b041abbb1b694a3d6bd3ffe05","size":{"x":32,"y":1,"z":32}},{"blockCount":10,"bytes":938,"file":"chunks/y170-z160-x032.json","offset":{"x":32,"y":170,"z":160},"requirements":{"minecraft:sandstone":2,"minecraft:stone_bricks":8},"sha256":"c3fd32152a978bbe6acb997bc40a108aea58cf5ae6156d6c7bfc1991534f127f","size":{"x":32,"y":1,"z":32}},{"blockCount":10,"bytes":938,"file":"chunks/y170-z160-x064.json","offset":{"x":64,"y":170,"z":160},"requirements":{"minecraft:sandstone":2,"minecraft:stone_bricks":8},"sha256":"e84e5ece7373b048671fd66a49538f57aef96397e75e17dd23172a0af7209cdd","size":{"x":32,"y":1,"z":32}},{"blockCount":10,"bytes":940,"file":"chunks/y170-z160-x096.json","offset":{"x":96,"y":170,"z":160},"requirements":{"minecraft:sandstone":2,"minecraft:stone_bricks":8},"sha256":"ed26b8d2488ceaafe061efa9a4664fe52d20ee1f1c5f7ac37b335424edca66f4","size":{"x":32,"y":1,"z":32}},{"blockCount":15,"bytes":1097,"file":"chunks/y170-z160-x128.json","offset":{"x":128,"y":170,"z":160},"requirements":{"minecraft:sandstone":3,"minecraft:stone_bricks":12},"sha256":"3c2b6416ecc7e5825da9dc1d008df3cf0bbf58ba505595cd7c083283f186a882","size":{"x":32,"y":1,"z":32}},{"blockCount":11,"bytes":976,"file":"chunks/y170-z160-x160.json","offset":{"x":160,"y":170,"z":160},"requirements":{"minecraft:sandstone":2,"minecraft:stone_bricks":9},"sha256":"d27bec2445d1dc337a0648f462204d97b028211b00dc74b8ce21400b41c68e4b","size":{"x":32,"y":1,"z":32}},{"blockCount":79,"bytes":3126,"file":"chunks/y170-z160-x192.json","offset":{"x":192,"y":170,"z":160},"requirements":{"minecraft:bricks":7,"minecraft:glass":8,"minecraft:oak_planks":8,"minecraft:polished_diorite":29,"minecraft:sandstone":2,"minecraft:stone_bricks":25},"sha256":"5a55f5ff148452f8d7ba38754b0fb4d88345b8bf361cdd82213415cefa61456b","size":{"x":32,"y":1,"z":32}},{"blockCount":80,"bytes":3216,"file":"chunks/y170-z160-x224.json","offset":{"x":224,"y":170,"z":160},"requirements":{"minecraft:bricks":9,"minecraft:glass":14,"minecraft:oak_planks":8,"minecraft:polished_diorite":31,"minecraft:stone_bricks":18},"sha256":"7c09155a57ee72683ae2809c65d59a2e3ee173c84b0a3392cc4fcfa322aafd41","size":{"x":32,"y":1,"z":32}},{"blockCount":15,"bytes":1057,"file":"chunks/y170-z192-x096.json","offset":{"x":96,"y":170,"z":192},"requirements":{"minecraft:sandstone":2,"minecraft:stone_bricks":13},"sha256":"43f46af6ff06af2163c7288378fead79a96178611a402a01b75209118fa4e475","size":{"x":32,"y":1,"z":32}},{"blockCount":10,"bytes":941,"file":"chunks/y170-z192-x128.json","offset":{"x":128,"y":170,"z":192},"requirements":{"minecraft:sandstone":2,"minecraft:stone_bricks":8},"sha256":"45d9f99d2c7af7117d418511e3b16beaa4566fbf8b26113c8c9bee31adc63230","size":{"x":32,"y":1,"z":32}},{"blockCount":3,"bytes":722,"file":"chunks/y171-z064-x096.json","offset":{"x":96,"y":171,"z":64},"requirements":{"minecraft:stone_bricks":3},"sha256":"1c11a59f5e1ee73a796d6857ca734692198e74ea54d992b1fad5803dc4e72d9c","size":{"x":32,"y":1,"z":32}},{"blockCount":2,"bytes":684,"file":"chunks/y171-z064-x128.json","offset":{"x":128,"y":171,"z":64},"requirements":{"minecraft:stone_bricks":2},"sha256":"494c93098a396cbb265ab606bc4fccad51100ac3f08524ae83c24db2ca81bdcf","size":{"x":32,"y":1,"z":32}},{"blockCount":6,"bytes":757,"file":"chunks/y171-z064-x192.json","offset":{"x":192,"y":171,"z":64},"requirements":{"minecraft:stone_bricks":6},"sha256":"d8b39eda299ef2190e26178ed339f56f8799648b87363e9a7dffc77f8b133987","size":{"x":32,"y":1,"z":32}},{"blockCount":6,"bytes":758,"file":"chunks/y171-z064-x224.json","offset":{"x":224,"y":171,"z":64},"requirements":{"minecraft:stone_bricks":6},"sha256":"247cf0d98323f63bfd40074439c1b41db6bece0db13e13b520e8a049e061448f","size":{"x":32,"y":1,"z":32}},{"blockCount":3,"bytes":721,"file":"chunks/y171-z096-x032.json","offset":{"x":32,"y":171,"z":96},"requirements":{"minecraft:stone_bricks":3},"sha256":"643b98a6a0b6377d47db77a075151c17f2f198a12ce2c25cdd4b6f9c9150630f","size":{"x":32,"y":1,"z":32}},{"blockCount":2,"bytes":682,"file":"chunks/y171-z096-x064.json","offset":{"x":64,"y":171,"z":96},"requirements":{"minecraft:stone_bricks":2},"sha256":"5345e5a454cddfcec1fb95c10ea2de4020a2cf964512cee1cb718dad5910c26c","size":{"x":32,"y":1,"z":32}},{"blockCount":2,"bytes":681,"file":"chunks/y171-z096-x096.json","offset":{"x":96,"y":171,"z":96},"requirements":{"minecraft:stone_bricks":2},"sha256":"3e1d8805d9f7ea003a669f6f0ad398f735b8cf820cd7a4aa2b3db9b10e359039","size":{"x":32,"y":1,"z":32}},{"blockCount":3,"bytes":723,"file":"chunks/y171-z096-x128.json","offset":{"x":128,"y":171,"z":96},"requirements":{"minecraft:stone_bricks":3},"sha256":"6ada67218e820e7bec7a96354673554616849ed1db36ebe0225cfa6746f46323","size":{"x":32,"y":1,"z":32}},{"blockCount":2,"bytes":683,"file":"chunks/y171-z096-x160.json","offset":{"x":160,"y":171,"z":96},"requirements":{"minecraft:stone_bricks":2},"sha256":"aa6f8ec3bd804bad44508be3e3fd259fe13da0ce1e3879d759b3ed03c39eff05","size":{"x":32,"y":1,"z":32}},{"blockCount":82,"bytes":2971,"file":"chunks/y171-z096-x192.json","offset":{"x":192,"y":171,"z":96},"requirements":{"minecraft:bricks":7,"minecraft:oak_planks":8,"minecraft:polished_diorite":17,"minecraft:stone_bricks":50},"sha256":"3ab89c3fbed07acee9b0302a769ce7f540b327017914a5e00f069ec779b26d21","size":{"x":32,"y":1,"z":32}},{"blockCount":94,"bytes":3356,"file":"chunks/y171-z096-x224.json","offset":{"x":224,"y":171,"z":96},"requirements":{"minecraft:bricks":9,"minecraft:glass":5,"minecraft:oak_planks":8,"minecraft:polished_diorite":19,"minecraft:sandstone":1,"minecraft:stone_bricks":52},"sha256":"ad80ad05c53e1fe4967d1f708f4f02316080437e68d1cade458d18c82ead75eb","size":{"x":32,"y":1,"z":32}},{"blockCount":1,"bytes":644,"file":"chunks/y171-z128-x032.json","offset":{"x":32,"y":171,"z":128},"requirements":{"minecraft:stone_bricks":1},"sha256":"20f6ce907ffd4927a30d6ae090a6fb7b13273147fb506d07359b763b561e63b1","size":{"x":32,"y":1,"z":32}},{"blockCount":40,"bytes":1717,"file":"chunks/y171-z128-x096.json","offset":{"x":96,"y":171,"z":128},"requirements":{"minecraft:polished_diorite":8,"minecraft:stone_bricks":32},"sha256":"ff8e6194cb6533755271e678c4b5bacbe666988da326decd3bc2bf233de3cb25","size":{"x":32,"y":1,"z":32}},{"blockCount":6,"bytes":758,"file":"chunks/y171-z128-x192.json","offset":{"x":192,"y":171,"z":128},"requirements":{"minecraft:stone_bricks":6},"sha256":"a1c7d551a02b2731545d8decb9f3d427267792690396eebf926632a8159cb2de","size":{"x":32,"y":1,"z":32}},{"blockCount":11,"bytes":878,"file":"chunks/y171-z128-x224.json","offset":{"x":224,"y":171,"z":128},"requirements":{"minecraft:stone_bricks":11},"sha256":"f9b8b520e21764979a73e25a43388bfb8623f734cef548b7ec14e2c331188097","size":{"x":32,"y":1,"z":32}},{"blockCount":2,"bytes":682,"file":"chunks/y171-z160-x032.json","offset":{"x":32,"y":171,"z":160},"requirements":{"minecraft:stone_bricks":2},"sha256":"7bc00e91683643b85a3a18df9947940adf7499bf35876f7413c6c501e67eb568","size":{"x":32,"y":1,"z":32}},{"blockCount":2,"bytes":682,"file":"chunks/y171-z160-x064.json","offset":{"x":64,"y":171,"z":160},"requirements":{"minecraft:stone_bricks":2},"sha256":"4aec7c330ac1a8aa85686ac8f676bf1df1033fdef0ebebe009df46daa2b1f3be","size":{"x":32,"y":1,"z":32}},{"blockCount":2,"bytes":684,"file":"chunks/y171-z160-x096.json","offset":{"x":96,"y":171,"z":160},"requirements":{"minecraft:stone_bricks":2},"sha256":"731d0a8c027353026ac70f454e1b4b09f1b82db9243df59c69edcdf50dfe1911","size":{"x":32,"y":1,"z":32}},{"blockCount":3,"bytes":724,"file":"chunks/y171-z160-x128.json","offset":{"x":128,"y":171,"z":160},"requirements":{"minecraft:stone_bricks":3},"sha256":"ae868884c3e1d9e68b1b2c9c66c033bc2e73574ce8cee3e0c1256091c6115e17","size":{"x":32,"y":1,"z":32}},{"blockCount":2,"bytes":683,"file":"chunks/y171-z160-x160.json","offset":{"x":160,"y":171,"z":160},"requirements":{"minecraft:stone_bricks":2},"sha256":"4b5e903def80a49d6dd2f3e18439ce1f3b447bb34cd75660335d02ebce914721","size":{"x":32,"y":1,"z":32}},{"blockCount":82,"bytes":3010,"file":"chunks/y171-z160-x192.json","offset":{"x":192,"y":171,"z":160},"requirements":{"minecraft:bricks":7,"minecraft:oak_planks":8,"minecraft:polished_diorite":17,"minecraft:stone_bricks":50},"sha256":"d15cc4c92aa4fb7bcf2bb92c21325ee9ff4b68a3b5762fa22c51a44503aeeeca","size":{"x":32,"y":1,"z":32}},{"blockCount":94,"bytes":3357,"file":"chunks/y171-z160-x224.json","offset":{"x":224,"y":171,"z":160},"requirements":{"minecraft:bricks":9,"minecraft:glass":5,"minecraft:oak_planks":8,"minecraft:polished_diorite":19,"minecraft:sandstone":1,"minecraft:stone_bricks":52},"sha256":"da1e062cafbf7af524936658a597ad77b3f5d753c2c8c3bdeb4f8dfbb3a5dc70","size":{"x":32,"y":1,"z":32}},{"blockCount":3,"bytes":723,"file":"chunks/y171-z192-x096.json","offset":{"x":96,"y":171,"z":192},"requirements":{"minecraft:stone_bricks":3},"sha256":"08fb3324e12ae885535fc93a23506405b2b3261c475bcd3dc6650c8e5de869e3","size":{"x":32,"y":1,"z":32}},{"blockCount":2,"bytes":685,"file":"chunks/y171-z192-x128.json","offset":{"x":128,"y":171,"z":192},"requirements":{"minecraft:stone_bricks":2},"sha256":"815c2edca155eb64eab3e647d2c699834fa2d2a6f9dcb722253d2e5113127841","size":{"x":32,"y":1,"z":32}},{"blockCount":3,"bytes":746,"file":"chunks/y172-z064-x096.json","offset":{"x":96,"y":172,"z":64},"requirements":{"minecraft:sandstone":1,"minecraft:stone_bricks":2},"sha256":"4c1d357848b7df2d6fb485c48a7d593f7d41380c63a8b59d045408fe4a883124","size":{"x":32,"y":1,"z":32}},{"blockCount":2,"bytes":684,"file":"chunks/y172-z064-x128.json","offset":{"x":128,"y":172,"z":64},"requirements":{"minecraft:stone_bricks":2},"sha256":"a1d0653563b16c710a0539d4e419e41b2478ba5893cf843eaf18e3c60d837c57","size":{"x":32,"y":1,"z":32}},{"blockCount":6,"bytes":826,"file":"chunks/y172-z064-x192.json","offset":{"x":192,"y":172,"z":64},"requirements":{"minecraft:polished_diorite":1,"minecraft:stone_bricks":5},"sha256":"eaa0bd1317e4b5e1d4c9e3089ab8d7289dbbbfd30743a24335d19d8585f11be3","size":{"x":32,"y":1,"z":32}},{"blockCount":6,"bytes":827,"file":"chunks/y172-z064-x224.json","offset":{"x":224,"y":172,"z":64},"requirements":{"minecraft:polished_diorite":1,"minecraft:stone_bricks":5},"sha256":"b4382dc4328b94d2a144bf868ea68918a765c5b4aeb75dceccc143168fa74a99","size":{"x":32,"y":1,"z":32}},{"blockCount":3,"bytes":721,"file":"chunks/y172-z096-x032.json","offset":{"x":32,"y":172,"z":96},"requirements":{"minecraft:stone_bricks":3},"sha256":"9bfe87c888a6f882d920ce42ca2d2d974fc1c4ca0b043c28ed9267749d313c6a","size":{"x":32,"y":1,"z":32}},{"blockCount":2,"bytes":682,"file":"chunks/y172-z096-x064.json","offset":{"x":64,"y":172,"z":96},"requirements":{"minecraft:stone_bricks":2},"sha256":"6b3a8ddceda521ee08a09a06fe5b6007440e51358473496f6577f157c2e620cf","size":{"x":32,"y":1,"z":32}},{"blockCount":2,"bytes":681,"file":"chunks/y172-z096-x096.json","offset":{"x":96,"y":172,"z":96},"requirements":{"minecraft:stone_bricks":2},"sha256":"eaa489d86382395bdbfd45049592fcb69509445e5fb39989c5656cff68c1cf31","size":{"x":32,"y":1,"z":32}},{"blockCount":3,"bytes":723,"file":"chunks/y172-z096-x128.json","offset":{"x":128,"y":172,"z":96},"requirements":{"minecraft:stone_bricks":3},"sha256":"771c10adaea7b843c88c745273008a919b34f9cbea3784c7c6146c8e99bd91b7","size":{"x":32,"y":1,"z":32}},{"blockCount":2,"bytes":683,"file":"chunks/y172-z096-x160.json","offset":{"x":160,"y":172,"z":96},"requirements":{"minecraft:stone_bricks":2},"sha256":"027a671a781273ba59dde5c1d82d9124c1871e71d134b5240b81ac7657928890","size":{"x":32,"y":1,"z":32}},{"blockCount":77,"bytes":3137,"file":"chunks/y172-z096-x192.json","offset":{"x":192,"y":172,"z":96},"requirements":{"minecraft:bricks":7,"minecraft:cobbled_deepslate":5,"minecraft:glass":8,"minecraft:oak_planks":8,"minecraft:polished_diorite":24,"minecraft:stone_bricks":25},"sha256":"017e7415518da9b95dba583ff96e35b932e03a376ba38342e78ccf32a31a6505","size":{"x":32,"y":1,"z":32}},{"blockCount":91,"bytes":3542,"file":"chunks/y172-z096-x224.json","offset":{"x":224,"y":172,"z":96},"requirements":{"minecraft:bricks":9,"minecraft:cobbled_deepslate":11,"minecraft:glass":13,"minecraft:oak_planks":8,"minecraft:polished_diorite":26,"minecraft:sandstone":1,"minecraft:stone_bricks":23},"sha256":"e3064561cc3fa3617bc047abc1e60df0c798de9500594d2fc1df59a9dbb7a56d","size":{"x":32,"y":1,"z":32}},{"blockCount":1,"bytes":644,"file":"chunks/y172-z128-x032.json","offset":{"x":32,"y":172,"z":128},"requirements":{"minecraft:stone_bricks":1},"sha256":"90b808d8f1e8f9e622658a5591ff8b91de93bba49634d1bf80cb219dbcc946d9","size":{"x":32,"y":1,"z":32}},{"blockCount":8,"bytes":918,"file":"chunks/y172-z128-x096.json","offset":{"x":96,"y":172,"z":128},"requirements":{"minecraft:polished_diorite":8},"sha256":"a95d4c838bb55c33ead36e24a1ccdb0373a42fcb17871c4312273999c4ec002f","size":{"x":32,"y":1,"z":32}},{"blockCount":6,"bytes":827,"file":"chunks/y172-z128-x192.json","offset":{"x":192,"y":172,"z":128},"requirements":{"minecraft:polished_diorite":1,"minecraft:stone_bricks":5},"sha256":"d3f9cac20cd212205bd8093dc5f56b059299aab17be6398df105d01b199fc932","size":{"x":32,"y":1,"z":32}},{"blockCount":7,"bytes":868,"file":"chunks/y172-z128-x224.json","offset":{"x":224,"y":172,"z":128},"requirements":{"minecraft:polished_diorite":1,"minecraft:stone_bricks":6},"sha256":"cc4bb91c1a51c2029146a336166640716e03fd5468f3b191fa4d43cbd97b67ec","size":{"x":32,"y":1,"z":32}},{"blockCount":2,"bytes":682,"file":"chunks/y172-z160-x032.json","offset":{"x":32,"y":172,"z":160},"requirements":{"minecraft:stone_bricks":2},"sha256":"1dfde0a1c55e1a0c7e1ea8f51ad9f00e33434b46909750a5e6868e3e30e8ad7e","size":{"x":32,"y":1,"z":32}},{"blockCount":2,"bytes":682,"file":"chunks/y172-z160-x064.json","offset":{"x":64,"y":172,"z":160},"requirements":{"minecraft:stone_bricks":2},"sha256":"2cb7446771b37c76a1a1b7ca8e4137f2617763b5bb69c658a997e21b7f8efb49","size":{"x":32,"y":1,"z":32}},{"blockCount":2,"bytes":684,"file":"chunks/y172-z160-x096.json","offset":{"x":96,"y":172,"z":160},"requirements":{"minecraft:stone_bricks":2},"sha256":"ea148bb5f07ee43bf51e34684f45df83c15580cd95914902fc2aeb10c8e7d3cc","size":{"x":32,"y":1,"z":32}},{"blockCount":3,"bytes":724,"file":"chunks/y172-z160-x128.json","offset":{"x":128,"y":172,"z":160},"requirements":{"minecraft:stone_bricks":3},"sha256":"8432e60e0631240164ef75cb61a3f0e07ea31180df8424c78b1df82ed66d8921","size":{"x":32,"y":1,"z":32}},{"blockCount":2,"bytes":683,"file":"chunks/y172-z160-x160.json","offset":{"x":160,"y":172,"z":160},"requirements":{"minecraft:stone_bricks":2},"sha256":"6b86ac169ab606a4a3825af4b956f2285f98bb54e1d56d174991da9cddd33595","size":{"x":32,"y":1,"z":32}},{"blockCount":77,"bytes":3138,"file":"chunks/y172-z160-x192.json","offset":{"x":192,"y":172,"z":160},"requirements":{"minecraft:bricks":7,"minecraft:cobbled_deepslate":5,"minecraft:glass":8,"minecraft:oak_planks":8,"minecraft:polished_diorite":24,"minecraft:stone_bricks":25},"sha256":"d0ebca9a3871d5c26c3fea4edae18ced002aee9d3608bb31d8b4e4a77204dca4","size":{"x":32,"y":1,"z":32}},{"blockCount":91,"bytes":3543,"file":"chunks/y172-z160-x224.json","offset":{"x":224,"y":172,"z":160},"requirements":{"minecraft:bricks":9,"minecraft:cobbled_deepslate":11,"minecraft:glass":13,"minecraft:oak_planks":8,"minecraft:polished_diorite":26,"minecraft:sandstone":1,"minecraft:stone_bricks":23},"sha256":"dca7c48d77933e507a65a595b5a3637c5c9fd449f8b18c41bcfbdeedc167e6e2","size":{"x":32,"y":1,"z":32}},{"blockCount":3,"bytes":747,"file":"chunks/y172-z192-x096.json","offset":{"x":96,"y":172,"z":192},"requirements":{"minecraft:sandstone":1,"minecraft:stone_bricks":2},"sha256":"e55e29170a10d294e9a2a709e3190b09c8ef62d7d458ad54bc89dd07cd72ec73","size":{"x":32,"y":1,"z":32}},{"blockCount":2,"bytes":685,"file":"chunks/y172-z192-x128.json","offset":{"x":128,"y":172,"z":192},"requirements":{"minecraft:stone_bricks":2},"sha256":"f24c75a88f180d3abdc0297030e8f0850d85859d2e8893d5ae330b174fcb17a5","size":{"x":32,"y":1,"z":32}},{"blockCount":1,"bytes":643,"file":"chunks/y173-z064-x096.json","offset":{"x":96,"y":173,"z":64},"requirements":{"minecraft:stone_bricks":1},"sha256":"97b21ada875268546c481cc45b484995d7ab3205c1ba0eb0dc111fe6b11d93b2","size":{"x":32,"y":1,"z":32}},{"blockCount":6,"bytes":826,"file":"chunks/y173-z064-x192.json","offset":{"x":192,"y":173,"z":64},"requirements":{"minecraft:polished_diorite":4,"minecraft:stone_bricks":2},"sha256":"f14afc68f5bfb1ba42adda4a206b1c76aa519b44992adcf29b5f5dcfe6ded545","size":{"x":32,"y":1,"z":32}},{"blockCount":6,"bytes":827,"file":"chunks/y173-z064-x224.json","offset":{"x":224,"y":173,"z":64},"requirements":{"minecraft:polished_diorite":4,"minecraft:stone_bricks":2},"sha256":"9f7a4f4b94e74f02878d0fe48f9cf6028d1a970ca46fbe51167969790d21fcf2","size":{"x":32,"y":1,"z":32}},{"blockCount":85,"bytes":3147,"file":"chunks/y173-z096-x192.json","offset":{"x":192,"y":173,"z":96},"requirements":{"minecraft:bricks":7,"minecraft:oak_planks":8,"minecraft:polished_diorite":37,"minecraft:sandstone":5,"minecraft:stone_bricks":28},"sha256":"258633166d52ea914c9b2daf09552c921c3d2ff51e63783fdcbfc49af98dffe3","size":{"x":32,"y":1,"z":32}},{"blockCount":104,"bytes":3585,"file":"chunks/y173-z096-x224.json","offset":{"x":224,"y":173,"z":96},"requirements":{"minecraft:bricks":9,"minecraft:glass":5,"minecraft:oak_planks":8,"minecraft:polished_diorite":39,"minecraft:sandstone":11,"minecraft:stone_bricks":32},"sha256":"c202855cb69fe2bc94fa3f6507b9022731a1fc4e49823bd2dd7507f597664753","size":{"x":32,"y":1,"z":32}},{"blockCount":8,"bytes":918,"file":"chunks/y173-z128-x096.json","offset":{"x":96,"y":173,"z":128},"requirements":{"minecraft:polished_diorite":8},"sha256":"354735eadd81d32754315f78986bf371808c35a4fc9ffe0fa4fc0a3b5c14153b","size":{"x":32,"y":1,"z":32}},{"blockCount":6,"bytes":827,"file":"chunks/y173-z128-x192.json","offset":{"x":192,"y":173,"z":128},"requirements":{"minecraft:polished_diorite":4,"minecraft:stone_bricks":2},"sha256":"87ea4b3ef138efa407b8ef4009d334af40359055ace29a81981a6c07edee2594","size":{"x":32,"y":1,"z":32}},{"blockCount":7,"bytes":868,"file":"chunks/y173-z128-x224.json","offset":{"x":224,"y":173,"z":128},"requirements":{"minecraft:polished_diorite":4,"minecraft:stone_bricks":3},"sha256":"3802a99783cf3be8ba3248c108434a31a31deec5f1abea66ec4a56e46b7bab2c","size":{"x":32,"y":1,"z":32}},{"blockCount":85,"bytes":3148,"file":"chunks/y173-z160-x192.json","offset":{"x":192,"y":173,"z":160},"requirements":{"minecraft:bricks":7,"minecraft:oak_planks":8,"minecraft:polished_diorite":37,"minecraft:sandstone":5,"minecraft:stone_bricks":28},"sha256":"4501305be7903710ca2aaa137975301dc7aea26754a53b0317cd28adef775338","size":{"x":32,"y":1,"z":32}},{"blockCount":104,"bytes":3586,"file":"chunks/y173-z160-x224.json","offset":{"x":224,"y":173,"z":160},"requirements":{"minecraft:bricks":9,"minecraft:glass":5,"minecraft:oak_planks":8,"minecraft:polished_diorite":39,"minecraft:sandstone":11,"minecraft:stone_bricks":32},"sha256":"a7ae08cf5f9b75b1201d4334f6c558e896bdfeb590814dc2ce804067008f7721","size":{"x":32,"y":1,"z":32}},{"blockCount":1,"bytes":644,"file":"chunks/y173-z192-x096.json","offset":{"x":96,"y":173,"z":192},"requirements":{"minecraft:stone_bricks":1},"sha256":"86372ad51040850372e939ee40677e7c8349bfbac21433fdd5e485cb3d0c53cd","size":{"x":32,"y":1,"z":32}},{"blockCount":1,"bytes":643,"file":"chunks/y174-z064-x096.json","offset":{"x":96,"y":174,"z":64},"requirements":{"minecraft:stone_bricks":1},"sha256":"cdeb0ae5690770810570096df513006f7cfe2c64030b833002a90f1650ef7c7c","size":{"x":32,"y":1,"z":32}},{"blockCount":6,"bytes":788,"file":"chunks/y174-z064-x192.json","offset":{"x":192,"y":174,"z":64},"requirements":{"minecraft:polished_diorite":5,"minecraft:stone_bricks":1},"sha256":"abb345fbb54a00ee5f84257061456761c32e31867a1dd6d675b1a984fd9ea5d2","size":{"x":32,"y":1,"z":32}},{"blockCount":6,"bytes":789,"file":"chunks/y174-z064-x224.json","offset":{"x":224,"y":174,"z":64},"requirements":{"minecraft:polished_diorite":5,"minecraft:stone_bricks":1},"sha256":"f03771ff9323031819f98e312755434ccdc13d3a64b7b0f347f46c81c0b9ec4e","size":{"x":32,"y":1,"z":32}},{"blockCount":78,"bytes":2913,"file":"chunks/y174-z096-x192.json","offset":{"x":192,"y":174,"z":96},"requirements":{"minecraft:bricks":7,"minecraft:cobbled_deepslate":5,"minecraft:glass":8,"minecraft:oak_planks":8,"minecraft:polished_diorite":44,"minecraft:sandstone":3,"minecraft:stone_bricks":3},"sha256":"c978bb78018ca305ddba9d4eaee6c5241bf7e3934eb30257730990e603a83410","size":{"x":32,"y":1,"z":32}},{"blockCount":100,"bytes":3408,"file":"chunks/y174-z096-x224.json","offset":{"x":224,"y":174,"z":96},"requirements":{"minecraft:bricks":9,"minecraft:cobbled_deepslate":11,"minecraft:glass":14,"minecraft:oak_planks":8,"minecraft:polished_diorite":46,"minecraft:sandstone":9,"minecraft:stone_bricks":3},"sha256":"a7d363d51f6a789365b3a39edffca19a8b9c03235bf1eae7590ed4414e9d8e16","size":{"x":32,"y":1,"z":32}},{"blockCount":8,"bytes":918,"file":"chunks/y174-z128-x096.json","offset":{"x":96,"y":174,"z":128},"requirements":{"minecraft:polished_diorite":8},"sha256":"20058cccfa765fa3c17ca7a0db41d470922365285ea2ea69ebd65e1306ad6822","size":{"x":32,"y":1,"z":32}},{"blockCount":6,"bytes":789,"file":"chunks/y174-z128-x192.json","offset":{"x":192,"y":174,"z":128},"requirements":{"minecraft:polished_diorite":5,"minecraft:stone_bricks":1},"sha256":"8028d688fb2a2a102e1a487c3687d1f79c1dde529b0d247f0eaf0eab5654312d","size":{"x":32,"y":1,"z":32}},{"blockCount":7,"bytes":830,"file":"chunks/y174-z128-x224.json","offset":{"x":224,"y":174,"z":128},"requirements":{"minecraft:polished_diorite":5,"minecraft:stone_bricks":2},"sha256":"ce168f5261bcd5191db2bde5fcf4a3283de6835937f7553233c61e03f7b6b8bf","size":{"x":32,"y":1,"z":32}},{"blockCount":78,"bytes":2914,"file":"chunks/y174-z160-x192.json","offset":{"x":192,"y":174,"z":160},"requirements":{"minecraft:bricks":7,"minecraft:cobbled_deepslate":5,"minecraft:glass":8,"minecraft:oak_planks":8,"minecraft:polished_diorite":44,"minecraft:sandstone":3,"minecraft:stone_bricks":3},"sha256":"a4a19db0a8dcee1fa24d36fdb54a4601e988d4b6947b189e50edbbce3a040e37","size":{"x":32,"y":1,"z":32}},{"blockCount":100,"bytes":3409,"file":"chunks/y174-z160-x224.json","offset":{"x":224,"y":174,"z":160},"requirements":{"minecraft:bricks":9,"minecraft:cobbled_deepslate":11,"minecraft:glass":14,"minecraft:oak_planks":8,"minecraft:polished_diorite":46,"minecraft:sandstone":9,"minecraft:stone_bricks":3},"sha256":"edc8c693b12c2fda8dac47ee618167a98db259e808f87350ca3ebf6a5e96c768","size":{"x":32,"y":1,"z":32}},{"blockCount":1,"bytes":644,"file":"chunks/y174-z192-x096.json","offset":{"x":96,"y":174,"z":192},"requirements":{"minecraft:stone_bricks":1},"sha256":"a0a4994fc81ac6d6a86122dab01d098811b91ad776a220e1005182b28e554213","size":{"x":32,"y":1,"z":32}},{"blockCount":6,"bytes":788,"file":"chunks/y175-z064-x192.json","offset":{"x":192,"y":175,"z":64},"requirements":{"minecraft:polished_diorite":5,"minecraft:stone_bricks":1},"sha256":"d11fb7b040361a29e5effedb8acbe1e7ae8b1ca973fe8ff4c54c299f24396fc3","size":{"x":32,"y":1,"z":32}},{"blockCount":6,"bytes":789,"file":"chunks/y175-z064-x224.json","offset":{"x":224,"y":175,"z":64},"requirements":{"minecraft:polished_diorite":5,"minecraft:stone_bricks":1},"sha256":"7dc5db62257f7fe3327f318c60d81d41c7302fc9ac22c474eafebd540e537e0b","size":{"x":32,"y":1,"z":32}},{"blockCount":83,"bytes":2957,"file":"chunks/y175-z096-x192.json","offset":{"x":192,"y":175,"z":96},"requirements":{"minecraft:bricks":7,"minecraft:oak_planks":8,"minecraft:polished_diorite":44,"minecraft:sandstone":3,"minecraft:stone_bricks":21},"sha256":"8ff23b8a0f3334a34dabe4a4ca9d8cdc80e9f94720813b6a9442e838fa6092e7","size":{"x":32,"y":1,"z":32}},{"blockCount":103,"bytes":3432,"file":"chunks/y175-z096-x224.json","offset":{"x":224,"y":175,"z":96},"requirements":{"minecraft:bricks":9,"minecraft:glass":6,"minecraft:oak_planks":8,"minecraft:polished_diorite":46,"minecraft:sandstone":9,"minecraft:stone_bricks":25},"sha256":"5aad027a63355ecaf5cd1c1fc3c54314c7d7c80eb8eb91409709877bb873fb13","size":{"x":32,"y":1,"z":32}},{"blockCount":8,"bytes":918,"file":"chunks/y175-z128-x096.json","offset":{"x":96,"y":175,"z":128},"requirements":{"minecraft:polished_diorite":8},"sha256":"fab1a7f71b2ea76441050cd1b191264f19ac97cdaf4253d5fcdf1c8758944925","size":{"x":32,"y":1,"z":32}},{"blockCount":6,"bytes":789,"file":"chunks/y175-z128-x192.json","offset":{"x":192,"y":175,"z":128},"requirements":{"minecraft:polished_diorite":5,"minecraft:stone_bricks":1},"sha256":"013b0efb6eacd6ea045e05959e0b9be8c8a3ce1e39398f102b38712f2c691907","size":{"x":32,"y":1,"z":32}},{"blockCount":7,"bytes":830,"file":"chunks/y175-z128-x224.json","offset":{"x":224,"y":175,"z":128},"requirements":{"minecraft:polished_diorite":5,"minecraft:stone_bricks":2},"sha256":"d142757cd06990900ab452b64e1460ff985cbc0bc562190746deb05212b6fd45","size":{"x":32,"y":1,"z":32}},{"blockCount":83,"bytes":2958,"file":"chunks/y175-z160-x192.json","offset":{"x":192,"y":175,"z":160},"requirements":{"minecraft:bricks":7,"minecraft:oak_planks":8,"minecraft:polished_diorite":44,"minecraft:sandstone":3,"minecraft:stone_bricks":21},"sha256":"024055bd072352476ad6cf8a33c27dc42d2800f7121e79808d98839f51633079","size":{"x":32,"y":1,"z":32}},{"blockCount":103,"bytes":3433,"file":"chunks/y175-z160-x224.json","offset":{"x":224,"y":175,"z":160},"requirements":{"minecraft:bricks":9,"minecraft:glass":6,"minecraft:oak_planks":8,"minecraft:polished_diorite":46,"minecraft:sandstone":9,"minecraft:stone_bricks":25},"sha256":"093600da9caa35091ae826554184943e92ee4041f047f23022658f40ea744f34","size":{"x":32,"y":1,"z":32}},{"blockCount":8,"bytes":757,"file":"chunks/y176-z064-x192.json","offset":{"x":192,"y":176,"z":64},"requirements":{"minecraft:stone_bricks":8},"sha256":"828468e2fc47bfc7bd14d562b3079908536e66617b86a106c981e402f8e3b13b","size":{"x":32,"y":1,"z":32}},{"blockCount":8,"bytes":758,"file":"chunks/y176-z064-x224.json","offset":{"x":224,"y":176,"z":64},"requirements":{"minecraft:stone_bricks":8},"sha256":"080bb3425c65c9b1bc5f2e00a65310221422fbf87ebe68de79722c293d118f03","size":{"x":32,"y":1,"z":32}},{"blockCount":79,"bytes":2747,"file":"chunks/y176-z096-x192.json","offset":{"x":192,"y":176,"z":96},"requirements":{"minecraft:bricks":7,"minecraft:glass":8,"minecraft:oak_planks":8,"minecraft:polished_diorite":25,"minecraft:sandstone":3,"minecraft:stone_bricks":28},"sha256":"3d9aa3924138f52323ec413b47375b532cddfd569f8ecf2ad047f8e4e87bc8db","size":{"x":32,"y":1,"z":32}},{"blockCount":95,"bytes":3205,"file":"chunks/y176-z096-x224.json","offset":{"x":224,"y":176,"z":96},"requirements":{"minecraft:bricks":9,"minecraft:glass":14,"minecraft:oak_planks":8,"minecraft:polished_diorite":27,"minecraft:sandstone":9,"minecraft:stone_bricks":28},"sha256":"0c207b2e8f0e944355f6a15119955d99bb79a070584d67f55b703ed744719726","size":{"x":32,"y":1,"z":32}}],"schema":1}
