{"entries":[{"blockCount":8,"bytes":918,"file":"chunks/y176-z128-x096.json","offset":{"x":96,"y":176,"z":128},"requirements":{"minecraft:polished_diorite":8},"sha256":"bee3d81556b536cf636c188bdc6d0f2dd4ac71363ffbcb88582944a6495abc95","size":{"x":32,"y":1,"z":32}},{"blockCount":8,"bytes":758,"file":"chunks/y176-z128-x192.json","offset":{"x":192,"y":176,"z":128},"requirements":{"minecraft:stone_bricks":8},"sha256":"10b2e10d4052213acda48dafc4537ed6c5dbea07ca2469a36682ce131a10bec1","size":{"x":32,"y":1,"z":32}},{"blockCount":8,"bytes":759,"file":"chunks/y176-z128-x224.json","offset":{"x":224,"y":176,"z":128},"requirements":{"minecraft:stone_bricks":8},"sha256":"be70c6045f4d68045fabf9177128a6634f29c7a96a7711c913ebc2fd4833c4ea","size":{"x":32,"y":1,"z":32}},{"blockCount":79,"bytes":2748,"file":"chunks/y176-z160-x192.json","offset":{"x":192,"y":176,"z":160},"requirements":{"minecraft:bricks":7,"minecraft:glass":8,"minecraft:oak_planks":8,"minecraft:polished_diorite":25,"minecraft:sandstone":3,"minecraft:stone_bricks":28},"sha256":"c931cb64815337c21f637b7a0c09e4bf12bb6554066cd3639250c8aef6ed6839","size":{"x":32,"y":1,"z":32}},{"blockCount":95,"bytes":3206,"file":"chunks/y176-z160-x224.json","offset":{"x":224,"y":176,"z":160},"requirements":{"minecraft:bricks":9,"minecraft:glass":14,"minecraft:oak_planks":8,"minecraft:polished_diorite":27,"minecraft:sandstone":9,"minecraft:stone_bricks":28},"sha256":"191304b9c6d909e99ef2a1ff5743a2a12dd6e405677c1698669bf851c7e7633d","size":{"x":32,"y":1,"z":32}},{"blockCount":6,"bytes":788,"file":"chunks/y177-z064-x192.json","offset":{"x":192,"y":177,"z":64},"requirements":{"minecraft:polished_diorite":5,"minecraft:stone_bricks":1},"sha256":"f37ba89971958830bff8b14c7598f10a0fda879308ac3d67d37c739797122d36","size":{"x":32,"y":1,"z":32}},{"blockCount":6,"bytes":789,"file":"chunks/y177-z064-x224.json","offset":{"x":224,"y":177,"z":64},"requirements":{"minecraft:polished_diorite":5,"minecraft:stone_bricks":1},"sha256":"1951273dcdd93fdc36192ab09ff82ba1659abde095cb1ba94297b59c921be6b3","size":{"x":32,"y":1,"z":32}},{"blockCount":83,"bytes":2985,"file":"chunks/y177-z096-x192.json","offset":{"x":192,"y":177,"z":96},"requirements":{"minecraft:bricks":7,"minecraft:oak_planks":8,"minecraft:polished_diorite":44,"minecraft:sandstone":1,"minecraft:spruce_planks":2,"minecraft:stone_bricks":21},"sha256":"b9e3039c416dc27c5ad18224abee05c861e1c3997fb56f88469fda4d49dcd6a1","size":{"x":32,"y":1,"z":32}},{"blockCount":103,"bytes":3612,"file":"chunks/y177-z096-x224.json","offset":{"x":224,"y":177,"z":96},"requirements":{"minecraft:bricks":9,"minecraft:glass":5,"minecraft:oak_planks":8,"minecraft:polished_diorite":46,"minecraft:sandstone":7,"minecraft:spruce_planks":2,"minecraft:stone_bricks":26},"sha256":"e9a6ea6b3421594213bb0ea0682da2202c0085971d21257e8aa56ee59f6fa8ea","size":{"x":32,"y":1,"z":32}},{"blockCount":8,"bytes":918,"file":"chunks/y177-z128-x096.json","offset":{"x":96,"y":177,"z":128},"requirements":{"minecraft:polished_diorite":8},"sha256":"3a98e2d7ea9f9ca03f2fc858a77ad317f5b98be4be6309dd7e5e1b309bf0671e","size":{"x":32,"y":1,"z":32}},{"blockCount":6,"bytes":789,"file":"chunks/y177-z128-x192.json","offset":{"x":192,"y":177,"z":128},"requirements":{"minecraft:polished_diorite":5,"minecraft:stone_bricks":1},"sha256":"fd4935dba9f427f59aed5515627e8c123fba7db519e2b323a9a4682517583e0c","size":{"x":32,"y":1,"z":32}},{"blockCount":6,"bytes":790,"file":"chunks/y177-z128-x224.json","offset":{"x":224,"y":177,"z":128},"requirements":{"minecraft:polished_diorite":5,"minecraft:stone_bricks":1},"sha256":"29760a8af9903be90620b20e31d6f52ff9b2ce9e916db45c2571f05ad008a324","size":{"x":32,"y":1,"z":32}},{"blockCount":83,"bytes":2986,"file":"chunks/y177-z160-x192.json","offset":{"x":192,"y":177,"z":160},"requirements":{"minecraft:bricks":7,"minecraft:oak_planks":8,"minecraft:polished_diorite":44,"minecraft:sandstone":1,"minecraft:spruce_planks":2,"minecraft:stone_bricks":21},"sha256":"1c4e6fdd8ba3c1c23b13d9fb540cf3626ac56e7508d5bcbfe0bcdcf37a34546f","size":{"x":32,"y":1,"z":32}},{"blockCount":103,"bytes":3613,"file":"chunks/y177-z160-x224.json","offset":{"x":224,"y":177,"z":160},"requirements":{"minecraft:bricks":9,"minecraft:glass":5,"minecraft:oak_planks":8,"minecraft:polished_diorite":46,"minecraft:sandstone":7,"minecraft:spruce_planks":2,"minecraft:stone_bricks":26},"sha256":"e447bcbea4cd520a853adb960244df14c104302b5921edec7520aec50fea4d32","size":{"x":32,"y":1,"z":32}},{"blockCount":6,"bytes":788,"file":"chunks/y178-z064-x192.json","offset":{"x":192,"y":178,"z":64},"requirements":{"minecraft:polished_diorite":5,"minecraft:stone_bricks":1},"sha256":"aec2d81390ad18dda187a886c800fd2b4a36a1337ec814357872270018adca1f","size":{"x":32,"y":1,"z":32}},{"blockCount":6,"bytes":789,"file":"chunks/y178-z064-x224.json","offset":{"x":224,"y":178,"z":64},"requirements":{"minecraft:polished_diorite":5,"minecraft:stone_bricks":1},"sha256":"159db7de23c9f14998fc1066840842d55f7883d0de6b7ad84d5a1009f97c0901","size":{"x":32,"y":1,"z":32}},{"blockCount":75,"bytes":2850,"file":"chunks/y178-z096-x192.json","offset":{"x":192,"y":178,"z":96},"requirements":{"minecraft:bricks":7,"minecraft:glass":8,"minecraft:oak_planks":8,"minecraft:polished_diorite":44,"minecraft:sandstone":1,"minecraft:spruce_planks":4,"minecraft:stone_bricks":3},"sha256":"ae17fd5807b4215c787a38bc0c58f9e5e2efdd7c9589a9e934392a88ca13048f","size":{"x":32,"y":1,"z":32}},{"blockCount":94,"bytes":3347,"file":"chunks/y178-z096-x224.json","offset":{"x":224,"y":178,"z":96},"requirements":{"minecraft:bricks":9,"minecraft:glass":13,"minecraft:oak_planks":8,"minecraft:polished_diorite":45,"minecraft:sandstone":11,"minecraft:spruce_planks":4,"minecraft:stone_bricks":4},"sha256":"0d9e112f337345fed4a779ec761ac496d5e3c9c47f63ca88f5a3b28c17b90af1","size":{"x":32,"y":1,"z":32}},{"blockCount":8,"bytes":918,"file":"chunks/y178-z128-x096.json","offset":{"x":96,"y":178,"z":128},"requirements":{"minecraft:polished_diorite":8},"sha256":"9e2824c931d9d12ccff4c9b61da50a8515d03dc2a75f905ffd0b5bf6dd28dc22","size":{"x":32,"y":1,"z":32}},{"blockCount":6,"bytes":789,"file":"chunks/y178-z128-x192.json","offset":{"x":192,"y":178,"z":128},"requirements":{"minecraft:polished_diorite":5,"minecraft:stone_bricks":1},"sha256":"1144b51b6bb83f089f31d174a2ca6865e3e94b23424fbaa819403feda9e8d660","size":{"x":32,"y":1,"z":32}},{"blockCount":6,"bytes":790,"file":"chunks/y178-z128-x224.json","offset":{"x":224,"y":178,"z":128},"requirements":{"minecraft:polished_diorite":5,"minecraft:stone_bricks":1},"sha256":"301f0d4a45a425eb21505e8f01f7458c59d520258900a150ebe7b801270295c2","size":{"x":32,"y":1,"z":32}},{"blockCount":75,"bytes":2851,"file":"chunks/y178-z160-x192.json","offset":{"x":192,"y":178,"z":160},"requirements":{"minecraft:bricks":7,"minecraft:glass":8,"minecraft:oak_planks":8,"minecraft:polished_diorite":44,"minecraft:sandstone":1,"minecraft:spruce_planks":4,"minecraft:stone_bricks":3},"sha256":"8df3cb23f81a0ba7d21ecd9512829251684a0246dd19a43b01a64dd4c8bfb032","size":{"x":32,"y":1,"z":32}},{"blockCount":94,"bytes":3348,"file":"chunks/y178-z160-x224.json","offset":{"x":224,"y":178,"z":160},"requirements":{"minecraft:bricks":9,"minecraft:glass":13,"minecraft:oak_planks":8,"minecraft:polished_diorite":45,"minecraft:sandstone":11,"minecraft:spruce_planks":4,"minecraft:stone_bricks":4},"sha256":"6ea9474d2ce27600316178bb8025d2a5ea7464938172888576b9f81865deb1ee","size":{"x":32,"y":1,"z":32}},{"blockCount":14,"bytes":979,"file":"chunks/y179-z064-x192.json","offset":{"x":192,"y":179,"z":64},"requirements":{"minecraft:polished_diorite":7,"minecraft:stone_bricks":7},"sha256":"5a57f8b91c6cdcdbd3ef91326af7e8987c8cab44b6a1ced1b2b6b6fa52495a4a","size":{"x":32,"y":1,"z":32}},{"blockCount":14,"bytes":980,"file":"chunks/y179-z064-x224.json","offset":{"x":224,"y":179,"z":64},"requirements":{"minecraft:polished_diorite":7,"minecraft:stone_bricks":7},"sha256":"a354a55bea07bb7bf67ab60345866fa98a204e20d1481e42b20a05a4c175f119","size":{"x":32,"y":1,"z":32}},{"blockCount":103,"bytes":3381,"file":"chunks/y179-z096-x192.json","offset":{"x":192,"y":179,"z":96},"requirements":{"minecraft:bricks":7,"minecraft:glass":8,"minecraft:oak_planks":8,"minecraft:polished_diorite":55,"minecraft:spruce_planks":4,"minecraft:stone_bricks":21},"sha256":"a8f18d06aa0e011e28db8aaf88ea01dc5a62a96b330e4938adf3e18082cb5f0f","size":{"x":32,"y":1,"z":32}},{"blockCount":122,"bytes":3975,"file":"chunks/y179-z096-x224.json","offset":{"x":224,"y":179,"z":96},"requirements":{"minecraft:bricks":9,"minecraft:glass":13,"minecraft:oak_planks":8,"minecraft:polished_diorite":59,"minecraft:sandstone":8,"minecraft:spruce_planks":4,"minecraft:stone_bricks":21},"sha256":"fb2965510ed50ff2bf4506283b1900d332fce84360a208fef35cbadbc15eb7c4","size":{"x":32,"y":1,"z":32}},{"blockCount":8,"bytes":918,"file":"chunks/y179-z128-x096.json","offset":{"x":96,"y":179,"z":128},"requirements":{"minecraft:polished_diorite":8},"sha256":"89c1fe823e41b63a1c967ea75bee962fa81a2b1c4e4c4d7b7e11e544ab843081","size":{"x":32,"y":1,"z":32}},{"blockCount":14,"bytes":980,"file":"chunks/y179-z128-x192.json","offset":{"x":192,"y":179,"z":128},"requirements":{"minecraft:polished_diorite":7,"minecraft:stone_bricks":7},"sha256":"658741a00ac8a61e8301e16c63d608bff2ada0ba482510922d6316907e47157d","size":{"x":32,"y":1,"z":32}},{"blockCount":14,"bytes":981,"file":"chunks/y179-z128-x224.json","offset":{"x":224,"y":179,"z":128},"requirements":{"minecraft:polished_diorite":7,"minecraft:stone_bricks":7},"sha256":"c26a4a17e5e37a90766ee090e0fe1323e90f70b2cabb3162753466680f245acb","size":{"x":32,"y":1,"z":32}},{"blockCount":103,"bytes":3382,"file":"chunks/y179-z160-x192.json","offset":{"x":192,"y":179,"z":160},"requirements":{"minecraft:bricks":7,"minecraft:glass":8,"minecraft:oak_planks":8,"minecraft:polished_diorite":55,"minecraft:spruce_planks":4,"minecraft:stone_bricks":21},"sha256":"8a5ecc502a398c692b7be7000b5754d2cfde04bc642a93cada252640ae492ceb","size":{"x":32,"y":1,"z":32}},{"blockCount":122,"bytes":3976,"file":"chunks/y179-z160-x224.json","offset":{"x":224,"y":179,"z":160},"requirements":{"minecraft:bricks":9,"minecraft:glass":13,"minecraft:oak_planks":8,"minecraft:polished_diorite":59,"minecraft:sandstone":8,"minecraft:spruce_planks":4,"minecraft:stone_bricks":21},"sha256":"6ce6230e4034915fb4b64fabd32a37b21ec7e89c4865db4242b3bba872127d97","size":{"x":32,"y":1,"z":32}},{"blockCount":13,"bytes":865,"file":"chunks/y180-z064-x192.json","offset":{"x":192,"y":180,"z":64},"requirements":{"minecraft:polished_diorite":5,"minecraft:stone_bricks":8},"sha256":"412fc6408c87e3fb983fecc490d798c17f92b1bd92e6e210bee274506767df4a","size":{"x":32,"y":1,"z":32}},{"blockCount":13,"bytes":866,"file":"chunks/y180-z064-x224.json","offset":{"x":224,"y":180,"z":64},"requirements":{"minecraft:polished_diorite":5,"minecraft:stone_bricks":8},"sha256":"661cfff0f27a5076d2f4ac67220c5dbe52d2a591bbc404a494a44aa033899be0","size":{"x":32,"y":1,"z":32}},{"blockCount":113,"bytes":3153,"file":"chunks/y180-z096-x192.json","offset":{"x":192,"y":180,"z":96},"requirements":{"minecraft:bricks":7,"minecraft:glass":8,"minecraft:oak_planks":8,"minecraft:polished_diorite":59,"minecraft:spruce_planks":3,"minecraft:stone_bricks":28},"sha256":"b26bc69c51ad33630f490c84b907a9061be4438d43b7dc63ca44818e18da9e5a","size":{"x":32,"y":1,"z":32}},{"blockCount":126,"bytes":3539,"file":"chunks/y180-z096-x224.json","offset":{"x":224,"y":180,"z":96},"requirements":{"minecraft:bricks":10,"minecraft:glass":13,"minecraft:oak_planks":8,"minecraft:polished_diorite":59,"minecraft:sandstone":5,"minecraft:spruce_planks":3,"minecraft:stone_bricks":28},"sha256":"2a900a664dfd9f68c4aa4c30f8bfbdea6605c5787aa0f9a83d7b817179820d0c","size":{"x":32,"y":1,"z":32}},{"blockCount":8,"bytes":918,"file":"chunks/y180-z128-x096.json","offset":{"x":96,"y":180,"z":128},"requirements":{"minecraft:polished_diorite":8},"sha256":"3fa3381f4183d18890021c4eb40b31eb74844465c102b1cfad8a69b781798eb4","size":{"x":32,"y":1,"z":32}},{"blockCount":13,"bytes":866,"file":"chunks/y180-z128-x192.json","offset":{"x":192,"y":180,"z":128},"requirements":{"minecraft:polished_diorite":5,"minecraft:stone_bricks":8},"sha256":"f73d681d7ad727994b17db0067f326200cb824c511b401dd7c058c3c25abad0d","size":{"x":32,"y":1,"z":32}},{"blockCount":13,"bytes":867,"file":"chunks/y180-z128-x224.json","offset":{"x":224,"y":180,"z":128},"requirements":{"minecraft:polished_diorite":5,"minecraft:stone_bricks":8},"sha256":"bcf4b2ac263e73723b2046df65e22ea9446e02124989f90f4f6050a3054c664b","size":{"x":32,"y":1,"z":32}},{"blockCount":113,"bytes":3154,"file":"chunks/y180-z160-x192.json","offset":{"x":192,"y":180,"z":160},"requirements":{"minecraft:bricks":7,"minecraft:glass":8,"minecraft:oak_planks":8,"minecraft:polished_diorite":59,"minecraft:spruce_planks":3,"minecraft:stone_bricks":28},"sha256":"b51a97ec11c0f8c2d7da34caf08beadf1d83953b48855363690b976354fc7074","size":{"x":32,"y":1,"z":32}},{"blockCount":126,"bytes":3610,"file":"chunks/y180-z160-x224.json","offset":{"x":224,"y":180,"z":160},"requirements":{"minecraft:bricks":10,"minecraft:cobbled_deepslate":1,"minecraft:glass":13,"minecraft:oak_planks":8,"minecraft:polished_diorite":59,"minecraft:sandstone":4,"minecraft:spruce_planks":3,"minecraft:stone_bricks":28},"sha256":"2ffcd7abb608c5890c4605cffc87936204f6c9b972a635665e7d25e9fd67a8a5","size":{"x":32,"y":1,"z":32}},{"blockCount":10,"bytes":846,"file":"chunks/y181-z064-x192.json","offset":{"x":192,"y":181,"z":64},"requirements":{"minecraft:polished_diorite":6,"minecraft:stone_bricks":4},"sha256":"3cd1308763cb63a21c68fd55ff42a27560a335b982c6a075c54f2a3f2afeb3e0","size":{"x":32,"y":1,"z":32}},{"blockCount":10,"bytes":847,"file":"chunks/y181-z064-x224.json","offset":{"x":224,"y":181,"z":64},"requirements":{"minecraft:polished_diorite":6,"minecraft:stone_bricks":4},"sha256":"4f6050c94fc0243060f9946d73e854b4e6914164050e2cb147a23ddf05887b77","size":{"x":32,"y":1,"z":32}},{"blockCount":105,"bytes":3018,"file":"chunks/y181-z096-x192.json","offset":{"x":192,"y":181,"z":96},"requirements":{"minecraft:bricks":7,"minecraft:glass":8,"minecraft:oak_planks":8,"minecraft:polished_diorite":65,"minecraft:spruce_planks":3,"minecraft:stone_bricks":14},"sha256":"10236b92bd7a6aff3fd81dd9cb03199a73e3672aefaae479b79b1cf91f63a964","size":{"x":32,"y":1,"z":32}},{"blockCount":115,"bytes":3323,"file":"chunks/y181-z096-x224.json","offset":{"x":224,"y":181,"z":96},"requirements":{"minecraft:bricks":10,"minecraft:glass":13,"minecraft:oak_planks":8,"minecraft:polished_diorite":67,"minecraft:spruce_planks":3,"minecraft:stone_bricks":14},"sha256":"763d7e7a67fad8033310760ebf3587b3bc1c0a3591c2515464c1bcad66564240","size":{"x":32,"y":1,"z":32}},{"blockCount":8,"bytes":914,"file":"chunks/y181-z128-x096.json","offset":{"x":96,"y":181,"z":128},"requirements":{"minecraft:stone_bricks":8},"sha256":"2c6500723e23a1feeb66aa7aef89f5700b5210a35e2431700549556956661d30","size":{"x":32,"y":1,"z":32}},{"blockCount":10,"bytes":847,"file":"chunks/y181-z128-x192.json","offset":{"x":192,"y":181,"z":128},"requirements":{"minecraft:polished_diorite":6,"minecraft:stone_bricks":4},"sha256":"4ffbc32c705564385ef11baf1c94acb0d0b0af8d82499eebb89b3f1740779307","size":{"x":32,"y":1,"z":32}},{"blockCount":10,"bytes":848,"file":"chunks/y181-z128-x224.json","offset":{"x":224,"y":181,"z":128},"requirements":{"minecraft:polished_diorite":6,"minecraft:stone_bricks":4},"sha256":"02880b96125eef38cd29b256301357cd8497e7ec82f3660e99643e092f263134","size":{"x":32,"y":1,"z":32}},{"blockCount":105,"bytes":3019,"file":"chunks/y181-z160-x192.json","offset":{"x":192,"y":181,"z":160},"requirements":{"minecraft:bricks":7,"minecraft:glass":8,"minecraft:oak_planks":8,"minecraft:polished_diorite":65,"minecraft:spruce_planks":3,"minecraft:stone_bricks":14},"sha256":"d9e28d4e225ff23052adb20190a3e1f9657772a8cd2cf27f9bf5e410032f13c2","size":{"x":32,"y":1,"z":32}},{"blockCount":115,"bytes":3324,"file":"chunks/y181-z160-x224.json","offset":{"x":224,"y":181,"z":160},"requirements":{"minecraft:bricks":10,"minecraft:glass":13,"minecraft:oak_planks":8,"minecraft:polished_diorite":67,"minecraft:spruce_planks":3,"minecraft:stone_bricks":14},"sha256":"e3fabb6c4eae195926dfe6fae2bd3b4afe1ebd2c51d289a7dcbf89d20f84d65b","size":{"x":32,"y":1,"z":32}},{"blockCount":9,"bytes":788,"file":"chunks/y182-z064-x192.json","offset":{"x":192,"y":182,"z":64},"requirements":{"minecraft:polished_diorite":5,"minecraft:stone_bricks":4},"sha256":"75e7d7738528270ca7ee88eae6b2c76e86eea42e45d6939b206c482933d8ef73","size":{"x":32,"y":1,"z":32}},{"blockCount":9,"bytes":789,"file":"chunks/y182-z064-x224.json","offset":{"x":224,"y":182,"z":64},"requirements":{"minecraft:polished_diorite":5,"minecraft:stone_bricks":4},"sha256":"c1cb2bdc48d464ac3a9defe9b91bd103de651e907b2b090ec6c9af321d978dc3","size":{"x":32,"y":1,"z":32}},{"blockCount":125,"bytes":3058,"file":"chunks/y182-z096-x192.json","offset":{"x":192,"y":182,"z":96},"requirements":{"minecraft:bricks":10,"minecraft:oak_planks":21,"minecraft:polished_diorite":67,"minecraft:spruce_planks":3,"minecraft:stone_bricks":24},"sha256":"d97da233de6bb8623da568c77ab493dd7c578a94d8c215a5ba9039ade93c6e4b","size":{"x":32,"y":1,"z":32}},{"blockCount":140,"bytes":3381,"file":"chunks/y182-z096-x224.json","offset":{"x":224,"y":182,"z":96},"requirements":{"minecraft:bricks":13,"minecraft:glass":4,"minecraft:oak_planks":26,"minecraft:polished_diorite":67,"minecraft:spruce_planks":6,"minecraft:stone_bricks":24},"sha256":"e44a324af45cd98581bc567965478a88d5f8c94ef344223dc3f2a2330723206d","size":{"x":32,"y":1,"z":32}},{"blockCount":24,"bytes":1226,"file":"chunks/y182-z128-x096.json","offset":{"x":96,"y":182,"z":128},"requirements":{"minecraft:polished_diorite":24},"sha256":"22ca758c82067102a38a02e0adca5cc2ea958c68923ce0888738f21a549eba09","size":{"x":32,"y":1,"z":32}},{"blockCount":9,"bytes":789,"file":"chunks/y182-z128-x192.json","offset":{"x":192,"y":182,"z":128},"requirements":{"minecraft:polished_diorite":5,"minecraft:stone_bricks":4},"sha256":"fa0c565e02c3fbf20b6352fa5240a7d4b340e1315279f4b49e067c0ae9b7b291","size":{"x":32,"y":1,"z":32}},{"blockCount":9,"bytes":790,"file":"chunks/y182-z128-x224.json","offset":{"x":224,"y":182,"z":128},"requirements":{"minecraft:polished_diorite":5,"minecraft:stone_bricks":4},"sha256":"02730ff99556da91abc17111c833884c971d3dad774383d5f99fa6521c307d4f","size":{"x":32,"y":1,"z":32}},{"blockCount":125,"bytes":3059,"file":"chunks/y182-z160-x192.json","offset":{"x":192,"y":182,"z":160},"requirements":{"minecraft:bricks":10,"minecraft:oak_planks":21,"minecraft:polished_diorite":67,"minecraft:spruce_planks":3,"minecraft:stone_bricks":24},"sha256":"666aa758bf5afb5d5e3cd7711bbac4bb2201b1b38633c23b4bb816bb1f1ea2ec","size":{"x":32,"y":1,"z":32}},{"blockCount":140,"bytes":3382,"file":"chunks/y182-z160-x224.json","offset":{"x":224,"y":182,"z":160},"requirements":{"minecraft:bricks":13,"minecraft:glass":4,"minecraft:oak_planks":26,"minecraft:polished_diorite":67,"minecraft:spruce_planks":6,"minecraft:stone_bricks":24},"sha256":"f330c6f68b055e0499020f982695c56fa32c4900189a6fd6739a154bba2d1d32","size":{"x":32,"y":1,"z":32}},{"blockCount":8,"bytes":826,"file":"chunks/y183-z064-x192.json","offset":{"x":192,"y":183,"z":64},"requirements":{"minecraft:polished_diorite":6,"minecraft:stone_bricks":2},"sha256":"293cf321e3ee7de78324d1681f615ce06cdeec8ab554605fde32d9585ccc74e3","size":{"x":32,"y":1,"z":32}},{"blockCount":8,"bytes":846,"file":"chunks/y183-z064-x224.json","offset":{"x":224,"y":183,"z":64},"requirements":{"minecraft:polished_diorite":6,"minecraft:stone_bricks":2},"sha256":"08a0370deccb7608e1096e7f5c38a21f65e6a77a1c31a4d1ae63b2a6f6af6ef3","size":{"x":32,"y":1,"z":32}},{"blockCount":127,"bytes":3076,"file":"chunks/y183-z096-x192.json","offset":{"x":192,"y":183,"z":96},"requirements":{"minecraft:bricks":13,"minecraft:oak_planks":9,"minecraft:polished_diorite":90,"minecraft:spruce_planks":5,"minecraft:stone_bricks":10},"sha256":"70ab8e9105dacf5b1c8d81e5c3b1623680ef5b2709cf82fb5dd094121b129542","size":{"x":32,"y":1,"z":32}},{"blockCount":147,"bytes":3514,"file":"chunks/y183-z096-x224.json","offset":{"x":224,"y":183,"z":96},"requirements":{"minecraft:bricks":16,"minecraft:glass":6,"minecraft:oak_planks":12,"minecraft:polished_diorite":98,"minecraft:spruce_planks":5,"minecraft:stone_bricks":10},"sha256":"d09da63b75f362f86db189d37fbb0f470905ab9d21404b72e6189fa8c642d97b","size":{"x":32,"y":1,"z":32}},{"blockCount":57,"bytes":2103,"file":"chunks/y183-z128-x096.json","offset":{"x":96,"y":183,"z":128},"requirements":{"minecraft:polished_diorite":57},"sha256":"54736fe4f6a78f62f08cf373abf71b4bc412eb1ae14423b853a63355d1a5fe12","size":{"x":32,"y":1,"z":32}},{"blockCount":8,"bytes":827,"file":"chunks/y183-z128-x192.json","offset":{"x":192,"y":183,"z":128},"requirements":{"minecraft:polished_diorite":6,"minecraft:stone_bricks":2},"sha256":"feb643e46cd52bdc9cfe39d19e502173c6a71cc5b3d54c93f1c41bdcc86e66db","size":{"x":32,"y":1,"z":32}},{"blockCount":8,"bytes":847,"file":"chunks/y183-z128-x224.json","offset":{"x":224,"y":183,"z":128},"requirements":{"minecraft:polished_diorite":6,"minecraft:stone_bricks":2},"sha256":"1afd542cc4f60a58c6af74a0612eb00647145e15670da3d4dd5ba534cd380b65","size":{"x":32,"y":1,"z":32}},{"blockCount":127,"bytes":3077,"file":"chunks/y183-z160-x192.json","offset":{"x":192,"y":183,"z":160},"requirements":{"minecraft:bricks":13,"minecraft:oak_planks":9,"minecraft:polished_diorite":90,"minecraft:spruce_planks":5,"minecraft:stone_bricks":10},"sha256":"36eb73659e53d9be03e864d018d756180aee447985b6167cac94b0a71c8e9518","size":{"x":32,"y":1,"z":32}},{"blockCount":147,"bytes":3515,"file":"chunks/y183-z160-x224.json","offset":{"x":224,"y":183,"z":160},"requirements":{"minecraft:bricks":16,"minecraft:glass":6,"minecraft:oak_planks":12,"minecraft:polished_diorite":98,"minecraft:spruce_planks":5,"minecraft:stone_bricks":10},"sha256":"28a8c573938dc9c8c02ceab410f548769cca713d409b737053712b56e638e9d1","size":{"x":32,"y":1,"z":32}},{"blockCount":9,"bytes":845,"file":"chunks/y184-z064-x192.json","offset":{"x":192,"y":184,"z":64},"requirements":{"minecraft:polished_diorite":2,"minecraft:stone_bricks":7},"sha256":"6a7436d395a20023ed65219e40e0dc1c42bce2c2c1b95c4ea49b67686051fce3","size":{"x":32,"y":1,"z":32}},{"blockCount":11,"bytes":922,"file":"chunks/y184-z064-x224.json","offset":{"x":224,"y":184,"z":64},"requirements":{"minecraft:polished_diorite":4,"minecraft:stone_bricks":7},"sha256":"878737f67bfb2c298279551a67e2b79dd420e53ca5ddc86ae025b5e2cf5a9fda","size":{"x":32,"y":1,"z":32}},{"blockCount":162,"bytes":3589,"file":"chunks/y184-z096-x192.json","offset":{"x":192,"y":184,"z":96},"requirements":{"minecraft:bricks":26,"minecraft:oak_planks":8,"minecraft:polished_diorite":86,"minecraft:spruce_planks":9,"minecraft:stone_bricks":33},"sha256":"573e41c6790c6c8d0b55cfb37dafbe36d03540ca7c323ac90e6adcc73ee83a7c","size":{"x":32,"y":1,"z":32}},{"blockCount":185,"bytes":4009,"file":"chunks/y184-z096-x224.json","offset":{"x":224,"y":184,"z":96},"requirements":{"minecraft:bricks":26,"minecraft:glass":6,"minecraft:oak_planks":9,"minecraft:polished_diorite":100,"minecraft:spruce_planks":11,"minecraft:stone_bricks":33},"sha256":"44a8cc21073bf2d5e3c8271068635532cd62a0d19eed68b552109615569fce63","size":{"x":32,"y":1,"z":32}},{"blockCount":72,"bytes":2133,"file":"chunks/y184-z128-x096.json","offset":{"x":96,"y":184,"z":128},"requirements":{"minecraft:cobbled_deepslate":26,"minecraft:oak_planks":4,"minecraft:polished_diorite":36,"minecraft:stone_bricks":6},"sha256":"450204e590f0d3d02e66b92f5ef50d4d2babd1dcbe68b1d3ce1676e0087a30d7","size":{"x":32,"y":1,"z":32}},{"blockCount":9,"bytes":846,"file":"chunks/y184-z128-x192.json","offset":{"x":192,"y":184,"z":128},"requirements":{"minecraft:polished_diorite":2,"minecraft:stone_bricks":7},"sha256":"12bf6c8560bea66446abbbc932397c26e5ddb37d0ca2998e3a350fba852cb513","size":{"x":32,"y":1,"z":32}},{"blockCount":11,"bytes":923,"file":"chunks/y184-z128-x224.json","offset":{"x":224,"y":184,"z":128},"requirements":{"minecraft:polished_diorite":4,"minecraft:stone_bricks":7},"sha256":"91a5bcb154dfb57ae9a1fc70e5d362a536d723770fcc7f0c669e35a2dcc26efb","size":{"x":32,"y":1,"z":32}},{"blockCount":162,"bytes":3590,"file":"chunks/y184-z160-x192.json","offset":{"x":192,"y":184,"z":160},"requirements":{"minecraft:bricks":26,"minecraft:oak_planks":8,"minecraft:polished_diorite":86,"minecraft:spruce_planks":9,"minecraft:stone_bricks":33},"sha256":"0cb56755a76eee8943451c099e4f2bb00c6189877980fbf4c721bc4dfeb27a55","size":{"x":32,"y":1,"z":32}},{"blockCount":185,"bytes":4010,"file":"chunks/y184-z160-x224.json","offset":{"x":224,"y":184,"z":160},"requirements":{"minecraft:bricks":26,"minecraft:glass":6,"minecraft:oak_planks":9,"minecraft:polished_diorite":100,"minecraft:spruce_planks":11,"minecraft:stone_bricks":33},"sha256":"fb8319ca551459127910734895bdcd348ed5c3607dae0d0cded52abb72de5191","size":{"x":32,"y":1,"z":32}},{"blockCount":10,"bytes":883,"file":"chunks/y185-z064-x192.json","offset":{"x":192,"y":185,"z":64},"requirements":{"minecraft:polished_diorite":4,"minecraft:stone_bricks":6},"sha256":"f5516d8859b749b0c0ff2a79a8463705bac4c5c83741560d1fa3184b76a8fb85","size":{"x":32,"y":1,"z":32}},{"blockCount":13,"bytes":941,"file":"chunks/y185-z064-x224.json","offset":{"x":224,"y":185,"z":64},"requirements":{"minecraft:polished_diorite":5,"minecraft:stone_bricks":8},"sha256":"3c5afbfff9266a2ab7ed00d25df978f8eb660a1458581454eb817ce0c46388c0","size":{"x":32,"y":1,"z":32}},{"blockCount":169,"bytes":3600,"file":"chunks/y185-z096-x192.json","offset":{"x":192,"y":185,"z":96},"requirements":{"minecraft:bricks":34,"minecraft:oak_planks":16,"minecraft:polished_diorite":75,"minecraft:stone_bricks":44},"sha256":"2695b8f022c907e85bfae2e0ec978f1075167cccc7c2e7319b4443fe9a6808ed","size":{"x":32,"y":1,"z":32}},{"blockCount":204,"bytes":4000,"file":"chunks/y185-z096-x224.json","offset":{"x":224,"y":185,"z":96},"requirements":{"minecraft:bricks":40,"minecraft:glass":9,"minecraft:oak_planks":21,"minecraft:polished_diorite":88,"minecraft:stone_bricks":46},"sha256":"1832018443e21804fc9e50a372dc07a6ead70cb5d270feb34a6b33bc33bd971e","size":{"x":32,"y":1,"z":32}},{"blockCount":68,"bytes":2456,"file":"chunks/y185-z128-x096.json","offset":{"x":96,"y":185,"z":128},"requirements":{"minecraft:cobbled_deepslate":18,"minecraft:oak_planks":4,"minecraft:polished_diorite":44,"minecraft:stone_bricks":2},"sha256":"cc73636c6a2a45652c64be59b99bf0e1a33a910068246e4a2061df3546669cb8","size":{"x":32,"y":1,"z":32}},{"blockCount":10,"bytes":884,"file":"chunks/y185-z128-x192.json","offset":{"x":192,"y":185,"z":128},"requirements":{"minecraft:polished_diorite":4,"minecraft:stone_bricks":6},"sha256":"3eb7c966a7dbadd43db1882f5336703f9f05bf255fadb87a21d36f3b64bea58f","size":{"x":32,"y":1,"z":32}},{"blockCount":13,"bytes":942,"file":"chunks/y185-z128-x224.json","offset":{"x":224,"y":185,"z":128},"requirements":{"minecraft:polished_diorite":5,"minecraft:stone_bricks":8},"sha256":"a397559a6bc87dc23a5b2b2f910d35c6c84db9645cff6e7e23d07b9fc51af4ba","size":{"x":32,"y":1,"z":32}},{"blockCount":169,"bytes":3601,"file":"chunks/y185-z160-x192.json","offset":{"x":192,"y":185,"z":160},"requirements":{"minecraft:bricks":34,"minecraft:oak_planks":16,"minecraft:polished_diorite":75,"minecraft:stone_bricks":44},"sha256":"730cb4085db4806fc7a57230ead4c07e706c4cf892836d7626aafeab5b3643d0","size":{"x":32,"y":1,"z":32}},{"blockCount":204,"bytes":4001,"file":"chunks/y185-z160-x224.json","offset":{"x":224,"y":185,"z":160},"requirements":{"minecraft:bricks":40,"minecraft:glass":9,"minecraft:oak_planks":21,"minecraft:polished_diorite":88,"minecraft:stone_bricks":46},"sha256":"fed137c9060468cfc9b823d9640b83cc9ba48c035ec0209d5099b91a057a7108","size":{"x":32,"y":1,"z":32}},{"blockCount":10,"bytes":883,"file":"chunks/y186-z064-x192.json","offset":{"x":192,"y":186,"z":64},"requirements":{"minecraft:polished_diorite":2,"minecraft:stone_bricks":8},"sha256":"34e7f0a1cc1547d81963a34164bea54d2e44b8ad3ccab8cdd0990dd7c7e7a32e","size":{"x":32,"y":1,"z":32}},{"blockCount":13,"bytes":923,"file":"chunks/y186-z064-x224.json","offset":{"x":224,"y":186,"z":64},"requirements":{"minecraft:polished_diorite":2,"minecraft:stone_bricks":11},"sha256":"530e0d50c031df043bdeaa5ad4953a74ae9e748264baa979798162839cf64ba1","size":{"x":32,"y":1,"z":32}},{"blockCount":155,"bytes":3475,"file":"chunks/y186-z096-x192.json","offset":{"x":192,"y":186,"z":96},"requirements":{"minecraft:bricks":31,"minecraft:oak_planks":8,"minecraft:polished_diorite":72,"minecraft:spruce_planks":1,"minecraft:stone_bricks":43},"sha256":"c4628c6001a89e64ea7392315b26fd24ba7b693076aa7bcd3c7639424ccc2492","size":{"x":32,"y":1,"z":32}},{"blockCount":181,"bytes":3798,"file":"chunks/y186-z096-x224.json","offset":{"x":224,"y":186,"z":96},"requirements":{"minecraft:bricks":40,"minecraft:glass":2,"minecraft:oak_planks":8,"minecraft:polished_diorite":84,"minecraft:spruce_planks":1,"minecraft:stone_bricks":46},"sha256":"89abf29353698b67377e2df2682f222b0cbab39820b218dd7efb4a2387b05be7","size":{"x":32,"y":1,"z":32}},{"blockCount":68,"bytes":2124,"file":"chunks/y186-z128-x096.json","offset":{"x":96,"y":186,"z":128},"requirements":{"minecraft:cobbled_deepslate":20,"minecraft:oak_planks":20,"minecraft:polished_diorite":20,"minecraft:spruce_planks":4,"minecraft:stone_bricks":4},"sha256":"6a48b9db2a0a7c411574188f539b2bb19d284b8c4cfb36a777d597e161bdada5","size":{"x":32,"y":1,"z":32}},{"blockCount":10,"bytes":884,"file":"chunks/y186-z128-x192.json","offset":{"x":192,"y":186,"z":128},"requirements":{"minecraft:polished_diorite":2,"minecraft:stone_bricks":8},"sha256":"988f59c5072ba218342c33d66607c6ebfe67135abe7fedb2b91f11c02aba0ab5","size":{"x":32,"y":1,"z":32}},{"blockCount":13,"bytes":924,"file":"chunks/y186-z128-x224.json","offset":{"x":224,"y":186,"z":128},"requirements":{"minecraft:polished_diorite":2,"minecraft:stone_bricks":11},"sha256":"53e23310b9b1aada408202d0adb479445a82bfb9e38fb13a8044bf8b64a8aa9a","size":{"x":32,"y":1,"z":32}},{"blockCount":155,"bytes":3476,"file":"chunks/y186-z160-x192.json","offset":{"x":192,"y":186,"z":160},"requirements":{"minecraft:bricks":31,"minecraft:oak_planks":8,"minecraft:polished_diorite":72,"minecraft:spruce_planks":1,"minecraft:stone_bricks":43},"sha256":"7e8179e174c1b25130319117639bc319d133aff52adafa751a08dda9046414a5","size":{"x":32,"y":1,"z":32}},{"blockCount":181,"bytes":3799,"file":"chunks/y186-z160-x224.json","offset":{"x":224,"y":186,"z":160},"requirements":{"minecraft:bricks":40,"minecraft:glass":2,"minecraft:oak_planks":8,"minecraft:polished_diorite":84,"minecraft:spruce_planks":1,"minecraft:stone_bricks":46},"sha256":"53b022fd4c71ab63d4c3d97b3bf1df83f9b0445a9f9c7e06001721a2428d31dc","size":{"x":32,"y":1,"z":32}},{"blockCount":16,"bytes":980,"file":"chunks/y187-z064-x192.json","offset":{"x":192,"y":187,"z":64},"requirements":{"minecraft:polished_diorite":4,"minecraft:stone_bricks":12},"sha256":"55327d85ea7362448f221f528f233543c5a3e48c1ad065a9330c089585d96e8f","size":{"x":32,"y":1,"z":32}},{"blockCount":17,"bytes":1019,"file":"chunks/y187-z064-x224.json","offset":{"x":224,"y":187,"z":64},"requirements":{"minecraft:polished_diorite":4,"minecraft:stone_bricks":13},"sha256":"963ee1931dfbef07b8dae68a6bff53721eae765fef6078c81e8b2c5ec9af1d9a","size":{"x":32,"y":1,"z":32}},{"blockCount":167,"bytes":3790,"file":"chunks/y187-z096-x192.json","offset":{"x":192,"y":187,"z":96},"requirements":{"minecraft:bricks":28,"minecraft:oak_planks":8,"minecraft:polished_diorite":74,"minecraft:stone_bricks":57},"sha256":"01c2f70cdb86d59e43149924c8ce3247dad51e37bd53202f2a219f01865674c4","size":{"x":32,"y":1,"z":32}},{"blockCount":191,"bytes":4094,"file":"chunks/y187-z096-x224.json","offset":{"x":224,"y":187,"z":96},"requirements":{"minecraft:bricks":35,"minecraft:glass":4,"minecraft:oak_planks":8,"minecraft:polished_diorite":82,"minecraft:stone_bricks":62},"sha256":"5110915a1828c30d6fd12b1222e05c78291c03877807003e6fadec23903b7f11","size":{"x":32,"y":1,"z":32}},{"blockCount":36,"bytes":1682,"file":"chunks/y187-z128-x096.json","offset":{"x":96,"y":187,"z":128},"requirements":{"minecraft:cobbled_deepslate":21,"minecraft:oak_planks":4,"minecraft:stone_bricks":11},"sha256":"cf686cdb2bba9d3182c37755641c186add6d92375c6aae7e4d45eff847aab37c","size":{"x":32,"y":1,"z":32}},{"blockCount":16,"bytes":981,"file":"chunks/y187-z128-x192.json","offset":{"x":192,"y":187,"z":128},"requirements":{"minecraft:polished_diorite":4,"minecraft:stone_bricks":12},"sha256":"9b0e536bf1d5a2b5ea7b60ee7e7d3cdf6b90af816e1980ddb419e41161704dc2","size":{"x":32,"y":1,"z":32}},{"blockCount":17,"bytes":1020,"file":"chunks/y187-z128-x224.json","offset":{"x":224,"y":187,"z":128},"requirements":{"minecraft:polished_diorite":4,"minecraft:stone_bricks":13},"sha256":"b0d4c5abe52afe464c88cd53efd55510e6fcea3ee936beb8c85883b1590e1a9d","size":{"x":32,"y":1,"z":32}},{"blockCount":167,"bytes":3791,"file":"chunks/y187-z160-x192.json","offset":{"x":192,"y":187,"z":160},"requirements":{"minecraft:bricks":28,"minecraft:oak_planks":8,"minecraft:polished_diorite":74,"minecraft:stone_bricks":57},"sha256":"3fd490d2abd81fd9dbc3df276a80f48ac78d7e46f61f10586919be384604154a","size":{"x":32,"y":1,"z":32}},{"blockCount":191,"bytes":4095,"file":"chunks/y187-z160-x224.json","offset":{"x":224,"y":187,"z":160},"requirements":{"minecraft:bricks":35,"minecraft:glass":4,"minecraft:oak_planks":8,"minecraft:polished_diorite":82,"minecraft:stone_bricks":62},"sha256":"32ce2bf6e9bcb6b844964394e6fd0c21eb5362151b85dc6af725a29fd5edc23a","size":{"x":32,"y":1,"z":32}},{"blockCount":13,"bytes":903,"file":"chunks/y188-z064-x192.json","offset":{"x":192,"y":188,"z":64},"requirements":{"minecraft:polished_diorite":6,"minecraft:stone_bricks":7},"sha256":"9bef36d51ca7e7913f081e283dd4d57a8c13bbd7cebbe6b4d99124a0f1e7b33d","size":{"x":32,"y":1,"z":32}},{"blockCount":13,"bytes":923,"file":"chunks/y188-z064-x224.json","offset":{"x":224,"y":188,"z":64},"requirements":{"minecraft:polished_diorite":6,"minecraft:stone_bricks":7},"sha256":"cf03025c242cadef90103c2f6b788b7e753ffb7e0ad2d8a12e1bf67a4b5b8493","size":{"x":32,"y":1,"z":32}},{"blockCount":162,"bytes":3543,"file":"chunks/y188-z096-x192.json","offset":{"x":192,"y":188,"z":96},"requirements":{"minecraft:bricks":25,"minecraft:oak_planks":8,"minecraft:polished_diorite":91,"minecraft:stone_bricks":38},"sha256":"9e1972563c3e0e18dde4dcad08e1f9b4bf95cef994d3334ec11e49fe6f18171b","size":{"x":32,"y":1,"z":32}},{"blockCount":183,"bytes":3733,"file":"chunks/y188-z096-x224.json","offset":{"x":224,"y":188,"z":96},"requirements":{"minecraft:bricks":30,"minecraft:glass":4,"minecraft:oak_planks":8,"minecraft:polished_diorite":97,"minecraft:stone_bricks":44},"sha256":"cfda642ead8353a28e17fb2dc7d542aef5705359c4adeb37dc8908934068f962","size":{"x":32,"y":1,"z":32}},{"blockCount":36,"bytes":1643,"file":"chunks/y188-z128-x096.json","offset":{"x":96,"y":188,"z":128},"requirements":{"minecraft:cobbled_deepslate":23,"minecraft:oak_planks":4,"minecraft:stone_bricks":9},"sha256":"6e2e9f24adf1795a36ee51dfe5f7decded5b59aaa6b7bbca7fbc2db525084e47","size":{"x":32,"y":1,"z":32}},{"blockCount":13,"bytes":904,"file":"chunks/y188-z128-x192.json","offset":{"x":192,"y":188,"z":128},"requirements":{"minecraft:polished_diorite":6,"minecraft:stone_bricks":7},"sha256":"58298ac186aeeba52b91df6ef3e7b09a9232b8af83e5df794228ac7cca594a89","size":{"x":32,"y":1,"z":32}},{"blockCount":13,"bytes":924,"file":"chunks/y188-z128-x224.json","offset":{"x":224,"y":188,"z":128},"requirements":{"minecraft:polished_diorite":6,"minecraft:stone_bricks":7},"sha256":"7b41c2a4051990cf1af09191f1ee658b00ee58fdda57a2162db14c33bf57d325","size":{"x":32,"y":1,"z":32}},{"blockCount":162,"bytes":3544,"file":"chunks/y188-z160-x192.json","offset":{"x":192,"y":188,"z":160},"requirements":{"minecraft:bricks":25,"minecraft:oak_planks":8,"minecraft:polished_diorite":91,"minecraft:stone_bricks":38},"sha256":"c6997390db9915ff4a60b9bef502742c275b782a0f28dcc6dab6adc25fe7b6ab","size":{"x":32,"y":1,"z":32}},{"blockCount":183,"bytes":3734,"file":"chunks/y188-z160-x224.json","offset":{"x":224,"y":188,"z":160},"requirements":{"minecraft:bricks":30,"minecraft:glass":4,"minecraft:oak_planks":8,"minecraft:polished_diorite":97,"minecraft:stone_bricks":44},"sha256":"2b52c00a6284a89beee25b09243266f2e06c6ffa30e9a5ae09a75001dba20fa4","size":{"x":32,"y":1,"z":32}},{"blockCount":17,"bytes":1037,"file":"chunks/y189-z064-x192.json","offset":{"x":192,"y":189,"z":64},"requirements":{"minecraft:polished_diorite":5,"minecraft:stone_bricks":12},"sha256":"9c505098928ee1464cc7a97116f03cf29c8486f42553f88fda91272d942e893f","size":{"x":32,"y":1,"z":32}},{"blockCount":17,"bytes":1057,"file":"chunks/y189-z064-x224.json","offset":{"x":224,"y":189,"z":64},"requirements":{"minecraft:polished_diorite":5,"minecraft:stone_bricks":12},"sha256":"f24ee970f58298e39d9baeea0d17652663bcbe477e43273706245b3c15f9b498","size":{"x":32,"y":1,"z":32}},{"blockCount":179,"bytes":3524,"file":"chunks/y189-z096-x192.json","offset":{"x":192,"y":189,"z":96},"requirements":{"minecraft:bricks":25,"minecraft:oak_planks":8,"minecraft:polished_diorite":93,"minecraft:stone_bricks":53},"sha256":"3aae93d9c4c9d3d1d7faa153ddf9f5089c6ad0b1dfb26fd7ffdb732ca1dce4e2","size":{"x":32,"y":1,"z":32}},{"blockCount":199,"bytes":3753,"file":"chunks/y189-z096-x224.json","offset":{"x":224,"y":189,"z":96},"requirements":{"minecraft:bricks":30,"minecraft:glass":4,"minecraft:oak_planks":8,"minecraft:polished_diorite":102,"minecraft:stone_bricks":55},"sha256":"9841448380d6b0f59395497eda8fa1ed0172e4572b310a80cd530a4aa75b3b7f","size":{"x":32,"y":1,"z":32}},{"blockCount":52,"bytes":1759,"file":"chunks/y189-z128-x096.json","offset":{"x":96,"y":189,"z":128},"requirements":{"minecraft:cobbled_deepslate":21,"minecraft:oak_planks":20,"minecraft:stone_bricks":11},"sha256":"ffada7786213de3aee9579398b02a7cd2c7ed4dc173b9593f84bab4b19488e24","size":{"x":32,"y":1,"z":32}},{"blockCount":17,"bytes":1038,"file":"chunks/y189-z128-x192.json","offset":{"x":192,"y":189,"z":128},"requirements":{"minecraft:polished_diorite":5,"minecraft:stone_bricks":12},"sha256":"ecf5251722cbcbc69554e6ec0cfa53e06503711295c1f1db72859004c6c27f7e","size":{"x":32,"y":1,"z":32}},{"blockCount":17,"bytes":1058,"file":"chunks/y189-z128-x224.json","offset":{"x":224,"y":189,"z":128},"requirements":{"minecraft:polished_diorite":5,"minecraft:stone_bricks":12},"sha256":"8a979d12bbb4a735591e7a6e77b469a417bdc2d1605df6eb79131685b7e86037","size":{"x":32,"y":1,"z":32}},{"blockCount":179,"bytes":3525,"file":"chunks/y189-z160-x192.json","offset":{"x":192,"y":189,"z":160},"requirements":{"minecraft:bricks":25,"minecraft:oak_planks":8,"minecraft:polished_diorite":93,"minecraft:stone_bricks":53},"sha256":"ce0950ca0cffbc7deb495c1e829f1041f5c71f896199114b5a739f3fb817f7d7","size":{"x":32,"y":1,"z":32}},{"blockCount":199,"bytes":3754,"file":"chunks/y189-z160-x224.json","offset":{"x":224,"y":189,"z":160},"requirements":{"minecraft:bricks":30,"minecraft:glass":4,"minecraft:oak_planks":8,"minecraft:polished_diorite":102,"minecraft:stone_bricks":55},"sha256":"52ddaad85283393e03f4cf555dc02524d0136b8e075e49292d48137019741816","size":{"x":32,"y":1,"z":32}},{"blockCount":14,"bytes":1036,"file":"chunks/y190-z064-x192.json","offset":{"x":192,"y":190,"z":64},"requirements":{"minecraft:polished_diorite":8,"minecraft:stone_bricks":6},"sha256":"d7dd0c89edffd6f6e2ffa9ddc72e6ca9eff46446a0ac7c9859a8afdf3a2ca216","size":{"x":32,"y":1,"z":32}},{"blockCount":17,"bytes":1114,"file":"chunks/y190-z064-x224.json","offset":{"x":224,"y":190,"z":64},"requirements":{"minecraft:polished_diorite":10,"minecraft:stone_bricks":7},"sha256":"7f5b5741fcdd10cedcb721a88451d673abb6e2a68d3d63808c6dd4bb3e341f8f","size":{"x":32,"y":1,"z":32}},{"blockCount":177,"bytes":3867,"file":"chunks/y190-z096-x192.json","offset":{"x":192,"y":190,"z":96},"requirements":{"minecraft:bricks":25,"minecraft:oak_planks":8,"minecraft:polished_diorite":109,"minecraft:stone_bricks":35},"sha256":"5942fc01d737806f298e7d8c9cac5c0dd3f193d3758a70c8c9a7a9ddd8ac857a","size":{"x":32,"y":1,"z":32}},{"blockCount":200,"bytes":4076,"file":"chunks/y190-z096-x224.json","offset":{"x":224,"y":190,"z":96},"requirements":{"minecraft:bricks":30,"minecraft:glass":4,"minecraft:oak_planks":8,"minecraft:polished_diorite":122,"minecraft:stone_bricks":36},"sha256":"ef9e81bef8e3140485276614482565267c4878a28764d31729b533414b3e92c5","size":{"x":32,"y":1,"z":32}},{"blockCount":48,"bytes":1967,"file":"chunks/y190-z128-x096.json","offset":{"x":96,"y":190,"z":128},"requirements":{"minecraft:cobbled_deepslate":31,"minecraft:oak_planks":4,"minecraft:stone_bricks":13},"sha256":"395721252f201b76c90c4211a1c6c4a6d14ca445677baebb6be6ae7e9523919a","size":{"x":32,"y":1,"z":32}},{"blockCount":14,"bytes":1037,"file":"chunks/y190-z128-x192.json","offset":{"x":192,"y":190,"z":128},"requirements":{"minecraft:polished_diorite":8,"minecraft:stone_bricks":6},"sha256":"41057787c8ac46b7ae487ff8d41d9b33ecfe221bc0901d573e1488667a5833c6","size":{"x":32,"y":1,"z":32}}],"schema":1}
