{"entries":[{"blockCount":17,"bytes":1115,"file":"chunks/y190-z128-x224.json","offset":{"x":224,"y":190,"z":128},"requirements":{"minecraft:polished_diorite":10,"minecraft:stone_bricks":7},"sha256":"aa87fbfd03d884a104e29c88fc54c834549aa708a342678abb76ac9bc2d5d59a","size":{"x":32,"y":1,"z":32}},{"blockCount":177,"bytes":3868,"file":"chunks/y190-z160-x192.json","offset":{"x":192,"y":190,"z":160},"requirements":{"minecraft:bricks":25,"minecraft:oak_planks":8,"minecraft:polished_diorite":109,"minecraft:stone_bricks":35},"sha256":"c0db68db511fb4424443d0bc3208d3a9e477cb6530d3af18f27ac6416a360b64","size":{"x":32,"y":1,"z":32}},{"blockCount":200,"bytes":4077,"file":"chunks/y190-z160-x224.json","offset":{"x":224,"y":190,"z":160},"requirements":{"minecraft:bricks":30,"minecraft:glass":4,"minecraft:oak_planks":8,"minecraft:polished_diorite":122,"minecraft:stone_bricks":36},"sha256":"9056c8eb113185e295c7f6f34d77ea372b0a57bb9ac02d6b43e349aa3f07969f","size":{"x":32,"y":1,"z":32}},{"blockCount":9,"bytes":922,"file":"chunks/y191-z064-x192.json","offset":{"x":192,"y":191,"z":64},"requirements":{"minecraft:polished_diorite":2,"minecraft:stone_bricks":7},"sha256":"1a30e5e68f9879a6961e097761b5ea897123a97c8d52672190239d7c293ad31b","size":{"x":32,"y":1,"z":32}},{"blockCount":14,"bytes":1019,"file":"chunks/y191-z064-x224.json","offset":{"x":224,"y":191,"z":64},"requirements":{"minecraft:polished_diorite":2,"minecraft:stone_bricks":12},"sha256":"75130ee70b079d7f93fca9f0416bfe8a2c485d3e553e19be4da5a2416455769f","size":{"x":32,"y":1,"z":32}},{"blockCount":184,"bytes":4133,"file":"chunks/y191-z096-x192.json","offset":{"x":192,"y":191,"z":96},"requirements":{"minecraft:bricks":24,"minecraft:oak_planks":25,"minecraft:polished_diorite":88,"minecraft:stone_bricks":47},"sha256":"f84625b95414e6f7499b9b7a03826294aaf36f59d4efc652ef72add03e125d54","size":{"x":32,"y":1,"z":32}},{"blockCount":208,"bytes":4343,"file":"chunks/y191-z096-x224.json","offset":{"x":224,"y":191,"z":96},"requirements":{"minecraft:bricks":30,"minecraft:glass":4,"minecraft:oak_planks":25,"minecraft:polished_diorite":100,"minecraft:stone_bricks":49},"sha256":"f394f15db9a27c2013ecacc271c4e6949f27925c57b9c1a53a7db52b3404c63a","size":{"x":32,"y":1,"z":32}},{"blockCount":56,"bytes":1758,"file":"chunks/y191-z128-x096.json","offset":{"x":96,"y":191,"z":128},"requirements":{"minecraft:cobbled_deepslate":38,"minecraft:oak_planks":4,"minecraft:stone_bricks":14},"sha256":"3ffcf00957a9ec8dc6f5cd15555aa793180e6e627ed76a04e4edf9bcfaef91ca","size":{"x":32,"y":1,"z":32}},{"blockCount":10,"bytes":923,"file":"chunks/y191-z128-x192.json","offset":{"x":192,"y":191,"z":128},"requirements":{"minecraft:polished_diorite":2,"minecraft:stone_bricks":8},"sha256":"b74b0ebed223c315c0b78ab0a5009e9b8a678fd193b12e97693680f199821727","size":{"x":32,"y":1,"z":32}},{"blockCount":13,"bytes":1020,"file":"chunks/y191-z128-x224.json","offset":{"x":224,"y":191,"z":128},"requirements":{"minecraft:polished_diorite":2,"minecraft:stone_bricks":11},"sha256":"c81fc5fb27857b73d057df233fc7d530e15c4dcd22440f9b89f308dd69d67a31","size":{"x":32,"y":1,"z":32}},{"blockCount":183,"bytes":4134,"file":"chunks/y191-z160-x192.json","offset":{"x":192,"y":191,"z":160},"requirements":{"minecraft:bricks":24,"minecraft:oak_planks":25,"minecraft:polished_diorite":88,"minecraft:stone_bricks":46},"sha256":"bb09dc158d17d763bc8cacabd28559587722310fb83b5b8f026a9e5b76a529c6","size":{"x":32,"y":1,"z":32}},{"blockCount":209,"bytes":4344,"file":"chunks/y191-z160-x224.json","offset":{"x":224,"y":191,"z":160},"requirements":{"minecraft:bricks":30,"minecraft:glass":4,"minecraft:oak_planks":25,"minecraft:polished_diorite":100,"minecraft:stone_bricks":50},"sha256":"df10b345f7dcf8327a094499ca5d676bc12ae1a3d0aca7830987895c90eaf404","size":{"x":32,"y":1,"z":32}},{"blockCount":11,"bytes":884,"file":"chunks/y192-z064-x192.json","offset":{"x":192,"y":192,"z":64},"requirements":{"minecraft:polished_diorite":2,"minecraft:stone_bricks":9},"sha256":"952b73cd12f375a8bbeec594c94e83d691becfd38d24b52edecd39d6ba2e65f0","size":{"x":32,"y":1,"z":32}},{"blockCount":16,"bytes":981,"file":"chunks/y192-z064-x224.json","offset":{"x":224,"y":192,"z":64},"requirements":{"minecraft:polished_diorite":3,"minecraft:stone_bricks":13},"sha256":"3cac15d988edba269da4cf937644dcfe97983fc1c1a823e82fa06a621e609c2d","size":{"x":32,"y":1,"z":32}},{"blockCount":187,"bytes":3316,"file":"chunks/y192-z096-x192.json","offset":{"x":192,"y":192,"z":96},"requirements":{"minecraft:bricks":25,"minecraft:oak_planks":18,"minecraft:polished_diorite":89,"minecraft:stone_bricks":55},"sha256":"99081666c47b020995968f7824eaa62bfa156c30868f2784ae6524c444c396e4","size":{"x":32,"y":1,"z":32}},{"blockCount":220,"bytes":3547,"file":"chunks/y192-z096-x224.json","offset":{"x":224,"y":192,"z":96},"requirements":{"minecraft:bricks":31,"minecraft:glass":4,"minecraft:oak_planks":24,"minecraft:polished_diorite":102,"minecraft:stone_bricks":59},"sha256":"0e04c34cb5163725c6fe52590b8ce5a0d732e206eb1af661592a11afc86799b0","size":{"x":32,"y":1,"z":32}},{"blockCount":28,"bytes":1492,"file":"chunks/y192-z128-x096.json","offset":{"x":96,"y":192,"z":128},"requirements":{"minecraft:cobbled_deepslate":15,"minecraft:spruce_planks":4,"minecraft:stone_bricks":9},"sha256":"0513b14d23d5168d66e37bfc0d19efefa2729f0db9d0d1f3ffe3fc63127beefe","size":{"x":32,"y":1,"z":32}},{"blockCount":11,"bytes":885,"file":"chunks/y192-z128-x192.json","offset":{"x":192,"y":192,"z":128},"requirements":{"minecraft:polished_diorite":2,"minecraft:stone_bricks":9},"sha256":"c058de9f0a3eae0c7a0a5b5d0110d0097bc98b78d76ae0491d85e862b3f105e4","size":{"x":32,"y":1,"z":32}},{"blockCount":16,"bytes":982,"file":"chunks/y192-z128-x224.json","offset":{"x":224,"y":192,"z":128},"requirements":{"minecraft:polished_diorite":3,"minecraft:stone_bricks":13},"sha256":"595e4e6b437a55574e2ef07106a38d150985e823e798c3c5f5514d9f74cf17c5","size":{"x":32,"y":1,"z":32}},{"blockCount":187,"bytes":3317,"file":"chunks/y192-z160-x192.json","offset":{"x":192,"y":192,"z":160},"requirements":{"minecraft:bricks":25,"minecraft:oak_planks":18,"minecraft:polished_diorite":89,"minecraft:stone_bricks":55},"sha256":"902f3e36f99603e19c7960722a80c1393a9420d709ff2111bed2820a07337df0","size":{"x":32,"y":1,"z":32}},{"blockCount":220,"bytes":3548,"file":"chunks/y192-z160-x224.json","offset":{"x":224,"y":192,"z":160},"requirements":{"minecraft:bricks":31,"minecraft:glass":4,"minecraft:oak_planks":24,"minecraft:polished_diorite":102,"minecraft:stone_bricks":59},"sha256":"5dcc231ab075b0353a82744623293abe48be294c8ef1526f097a4da1e4c10165","size":{"x":32,"y":1,"z":32}},{"blockCount":4,"bytes":789,"file":"chunks/y193-z064-x192.json","offset":{"x":192,"y":193,"z":64},"requirements":{"minecraft:polished_diorite":2,"minecraft:stone_bricks":2},"sha256":"7ae3941a8760339aeeab9e9205836ffe39bcd63e282c70e981e9f6f45674485c","size":{"x":32,"y":1,"z":32}},{"blockCount":9,"bytes":905,"file":"chunks/y193-z064-x224.json","offset":{"x":224,"y":193,"z":64},"requirements":{"minecraft:polished_diorite":2,"minecraft:stone_bricks":7},"sha256":"6a5431f406387b9b40cc2425888b56acfdd85b5fded22d67a054951c1c4c4d7a","size":{"x":32,"y":1,"z":32}},{"blockCount":206,"bytes":3521,"file":"chunks/y193-z096-x192.json","offset":{"x":192,"y":193,"z":96},"requirements":{"minecraft:cobbled_deepslate":16,"minecraft:polished_diorite":28,"minecraft:spruce_planks":115,"minecraft:stone_bricks":47},"sha256":"beb9b07a71390a60e98075a87d9d970dc7c2a05a5704af650de2e397f4be22c5","size":{"x":32,"y":1,"z":32}},{"blockCount":312,"bytes":3743,"file":"chunks/y193-z096-x224.json","offset":{"x":224,"y":193,"z":96},"requirements":{"minecraft:cobbled_deepslate":19,"minecraft:glass":2,"minecraft:polished_diorite":32,"minecraft:spruce_planks":202,"minecraft:stone_bricks":57},"sha256":"a57f26de512f96008c0fa77c6ec09e849e26a8c28213b1ae5252266bee037c0b","size":{"x":32,"y":1,"z":32}},{"blockCount":28,"bytes":1508,"file":"chunks/y193-z128-x096.json","offset":{"x":96,"y":193,"z":128},"requirements":{"minecraft:cobbled_deepslate":16,"minecraft:oak_planks":4,"minecraft:stone_bricks":8},"sha256":"8ab4a5d075a8b503559997c1b16590f5fdf0802aadb18a3031f61ca95f5d3083","size":{"x":32,"y":1,"z":32}},{"blockCount":4,"bytes":790,"file":"chunks/y193-z128-x192.json","offset":{"x":192,"y":193,"z":128},"requirements":{"minecraft:polished_diorite":2,"minecraft:stone_bricks":2},"sha256":"300a1d4b994a4932b398b1004f1ae698aaf17f26798e48ebeaf8b1c007387552","size":{"x":32,"y":1,"z":32}},{"blockCount":9,"bytes":906,"file":"chunks/y193-z128-x224.json","offset":{"x":224,"y":193,"z":128},"requirements":{"minecraft:polished_diorite":2,"minecraft:stone_bricks":7},"sha256":"cd89682b0597dab271b038cb0cef0ad70a54d133d449d3b990c458efe568b9b1","size":{"x":32,"y":1,"z":32}},{"blockCount":206,"bytes":3522,"file":"chunks/y193-z160-x192.json","offset":{"x":192,"y":193,"z":160},"requirements":{"minecraft:cobbled_deepslate":16,"minecraft:polished_diorite":28,"minecraft:spruce_planks":115,"minecraft:stone_bricks":47},"sha256":"d8f3c6e950d6998d4d788012e071931224958e3390c4c9b87868a8ce9842d66d","size":{"x":32,"y":1,"z":32}},{"blockCount":312,"bytes":3782,"file":"chunks/y193-z160-x224.json","offset":{"x":224,"y":193,"z":160},"requirements":{"minecraft:cobbled_deepslate":18,"minecraft:glass":2,"minecraft:polished_diorite":32,"minecraft:spruce_planks":202,"minecraft:stone_bricks":58},"sha256":"c1d88b229ef1cca04e2639d55e7fca1cbd26350d38e443c36356a784c2312aa4","size":{"x":32,"y":1,"z":32}},{"blockCount":3,"bytes":725,"file":"chunks/y194-z064-x192.json","offset":{"x":192,"y":194,"z":64},"requirements":{"minecraft:polished_diorite":3},"sha256":"7765b3c64b0bd5d5bec4e5ca02f86bd5569bd904117fc9e09f41b96856952db2","size":{"x":32,"y":1,"z":32}},{"blockCount":7,"bytes":830,"file":"chunks/y194-z064-x224.json","offset":{"x":224,"y":194,"z":64},"requirements":{"minecraft:polished_diorite":3,"minecraft:stone_bricks":4},"sha256":"fdd2cac8519e7a586193ecd1c75c4196b623c561860bab14ef533d954d536bfc","size":{"x":32,"y":1,"z":32}},{"blockCount":117,"bytes":3254,"file":"chunks/y194-z096-x192.json","offset":{"x":192,"y":194,"z":96},"requirements":{"minecraft:cobbled_deepslate":14,"minecraft:polished_diorite":35,"minecraft:spruce_planks":34,"minecraft:stone_bricks":34},"sha256":"2ed84489041398035cd0d7cd7041f370016ea0ac7563a5fd1eec03176a85d3f0","size":{"x":32,"y":1,"z":32}},{"blockCount":136,"bytes":3521,"file":"chunks/y194-z096-x224.json","offset":{"x":224,"y":194,"z":96},"requirements":{"minecraft:cobbled_deepslate":14,"minecraft:polished_diorite":39,"minecraft:spruce_planks":41,"minecraft:stone_bricks":42},"sha256":"16a19cfc74cb7c2cc532a4e193290683e0280b712a51c9ee6a2281850713c784","size":{"x":32,"y":1,"z":32}},{"blockCount":36,"bytes":1567,"file":"chunks/y194-z128-x096.json","offset":{"x":96,"y":194,"z":128},"requirements":{"minecraft:cobbled_deepslate":13,"minecraft:oak_planks":12,"minecraft:stone_bricks":11},"sha256":"eb24b4341961b5f22c64f63442665f7b28dc00c3fd747cf3b940c63a24e8634a","size":{"x":32,"y":1,"z":32}},{"blockCount":3,"bytes":726,"file":"chunks/y194-z128-x192.json","offset":{"x":192,"y":194,"z":128},"requirements":{"minecraft:polished_diorite":3},"sha256":"3176a240b4319317f9dc6ae240faab59a9bf0ef1aead9bdb59354e6792218873","size":{"x":32,"y":1,"z":32}},{"blockCount":7,"bytes":831,"file":"chunks/y194-z128-x224.json","offset":{"x":224,"y":194,"z":128},"requirements":{"minecraft:polished_diorite":3,"minecraft:stone_bricks":4},"sha256":"9ad13dcc3692c1c4541c87ed206e9388ee03728611f0b861087fa4f3f65d8193","size":{"x":32,"y":1,"z":32}},{"blockCount":117,"bytes":3255,"file":"chunks/y194-z160-x192.json","offset":{"x":192,"y":194,"z":160},"requirements":{"minecraft:cobbled_deepslate":13,"minecraft:polished_diorite":35,"minecraft:spruce_planks":34,"minecraft:stone_bricks":35},"sha256":"159736c06680edb3890546ee2d90655fe9908dff9aae0b63e358912e4b80d45f","size":{"x":32,"y":1,"z":32}},{"blockCount":136,"bytes":3560,"file":"chunks/y194-z160-x224.json","offset":{"x":224,"y":194,"z":160},"requirements":{"minecraft:cobbled_deepslate":16,"minecraft:polished_diorite":39,"minecraft:spruce_planks":41,"minecraft:stone_bricks":40},"sha256":"6d982c9c935aa832b2776c1f19d25e449c900f0e01dbfed381f86b35a8e5216e","size":{"x":32,"y":1,"z":32}},{"blockCount":2,"bytes":686,"file":"chunks/y195-z064-x192.json","offset":{"x":192,"y":195,"z":64},"requirements":{"minecraft:polished_diorite":2},"sha256":"1e9a665604469f839175a2ab447d947230beaaecb23539efbf1746b9588dc2ff","size":{"x":32,"y":1,"z":32}},{"blockCount":4,"bytes":791,"file":"chunks/y195-z064-x224.json","offset":{"x":224,"y":195,"z":64},"requirements":{"minecraft:polished_diorite":2,"minecraft:stone_bricks":2},"sha256":"c110f464e612c65ee2e1ece7d33370233d13b05468995d6a5245844deb9f71f8","size":{"x":32,"y":1,"z":32}},{"blockCount":114,"bytes":3069,"file":"chunks/y195-z096-x192.json","offset":{"x":192,"y":195,"z":96},"requirements":{"minecraft:cobbled_deepslate":21,"minecraft:oak_planks":1,"minecraft:polished_diorite":28,"minecraft:spruce_planks":33,"minecraft:stone_bricks":31},"sha256":"1e2af2f9510456f6aba2f20c47b70ce38f39b2fe11b8f303ad0c123e0994b836","size":{"x":32,"y":1,"z":32}},{"blockCount":135,"bytes":3393,"file":"chunks/y195-z096-x224.json","offset":{"x":224,"y":195,"z":96},"requirements":{"minecraft:cobbled_deepslate":28,"minecraft:oak_planks":3,"minecraft:polished_diorite":32,"minecraft:spruce_planks":38,"minecraft:stone_bricks":34},"sha256":"c192ae5a71dab72155a964fd7ed2c973460d99d116ebba38cffbdcf3fd8ff88e","size":{"x":32,"y":1,"z":32}},{"blockCount":36,"bytes":1432,"file":"chunks/y195-z128-x096.json","offset":{"x":96,"y":195,"z":128},"requirements":{"minecraft:cobbled_deepslate":24,"minecraft:oak_planks":4,"minecraft:stone_bricks":8},"sha256":"5d757eb43bd96a5e85c57879e7175e5750d6fdc517ef7ac487fd7a53b8607b7f","size":{"x":32,"y":1,"z":32}},{"blockCount":2,"bytes":687,"file":"chunks/y195-z128-x192.json","offset":{"x":192,"y":195,"z":128},"requirements":{"minecraft:polished_diorite":2},"sha256":"f3502770aa77b7390e3470c71d94a18303eb43254e31b7f9a9ddb00f02dde9bb","size":{"x":32,"y":1,"z":32}},{"blockCount":4,"bytes":792,"file":"chunks/y195-z128-x224.json","offset":{"x":224,"y":195,"z":128},"requirements":{"minecraft:polished_diorite":2,"minecraft:stone_bricks":2},"sha256":"dff385e7a9f808dc86d4907b161718654eb7a2acb3aaa20e3b4a0e79d5b0f7dd","size":{"x":32,"y":1,"z":32}},{"blockCount":114,"bytes":3070,"file":"chunks/y195-z160-x192.json","offset":{"x":192,"y":195,"z":160},"requirements":{"minecraft:cobbled_deepslate":23,"minecraft:oak_planks":1,"minecraft:polished_diorite":28,"minecraft:spruce_planks":33,"minecraft:stone_bricks":29},"sha256":"11ab037427981e46bb4cffb1191c756be6d8f729dff29d9ebb0532cf16a01d44","size":{"x":32,"y":1,"z":32}},{"blockCount":135,"bytes":3337,"file":"chunks/y195-z160-x224.json","offset":{"x":224,"y":195,"z":160},"requirements":{"minecraft:cobbled_deepslate":31,"minecraft:oak_planks":3,"minecraft:polished_diorite":32,"minecraft:spruce_planks":38,"minecraft:stone_bricks":31},"sha256":"8e0b81af9649def9cb30521e977bd69f3a0e22ec8a42ddb81718e3bb7d246365","size":{"x":32,"y":1,"z":32}},{"blockCount":2,"bytes":713,"file":"chunks/y196-z064-x192.json","offset":{"x":192,"y":196,"z":64},"requirements":{"minecraft:polished_diorite":1,"minecraft:stone_bricks":1},"sha256":"0c85213d46ed14f3c26c71f65ba346a08d6286b34934dc938089227786032667","size":{"x":32,"y":1,"z":32}},{"blockCount":3,"bytes":752,"file":"chunks/y196-z064-x224.json","offset":{"x":224,"y":196,"z":64},"requirements":{"minecraft:polished_diorite":1,"minecraft:stone_bricks":2},"sha256":"814c30b725969c7aa67dd9852d545e612b73ec9e2ffeb17609a12a6b1bd0be20","size":{"x":32,"y":1,"z":32}},{"blockCount":131,"bytes":3221,"file":"chunks/y196-z096-x192.json","offset":{"x":192,"y":196,"z":96},"requirements":{"minecraft:cobbled_deepslate":25,"minecraft:oak_planks":19,"minecraft:polished_diorite":7,"minecraft:spruce_planks":33,"minecraft:stone_bricks":47},"sha256":"9f50e492a096edc4781fcf955ef2c48fc2bd0d235dab09248bdfd3143467b220","size":{"x":32,"y":1,"z":32}},{"blockCount":156,"bytes":3240,"file":"chunks/y196-z096-x224.json","offset":{"x":224,"y":196,"z":96},"requirements":{"minecraft:cobbled_deepslate":31,"minecraft:oak_planks":25,"minecraft:polished_diorite":7,"minecraft:spruce_planks":39,"minecraft:stone_bricks":54},"sha256":"6dbfdbc33a38afa0700d659c745f0e221c9cd0f0c7263db8db2529dbd5136b7c","size":{"x":32,"y":1,"z":32}},{"blockCount":36,"bytes":1528,"file":"chunks/y196-z128-x096.json","offset":{"x":96,"y":196,"z":128},"requirements":{"minecraft:cobbled_deepslate":19,"minecraft:oak_planks":4,"minecraft:stone_bricks":13},"sha256":"f9d282c37653d574729c123234455a06bae3f436f68473e19fa61ff4e222ac5b","size":{"x":32,"y":1,"z":32}},{"blockCount":2,"bytes":714,"file":"chunks/y196-z128-x192.json","offset":{"x":192,"y":196,"z":128},"requirements":{"minecraft:polished_diorite":1,"minecraft:stone_bricks":1},"sha256":"98bd2cb8654e74070fbcf93206e796ee886ab28d6b290c3ee6460c2aac4677e3","size":{"x":32,"y":1,"z":32}},{"blockCount":3,"bytes":753,"file":"chunks/y196-z128-x224.json","offset":{"x":224,"y":196,"z":128},"requirements":{"minecraft:polished_diorite":1,"minecraft:stone_bricks":2},"sha256":"18f48f6bea44f636bd062a9b0ac20d17168447b5f377a5e3bb4d4866ff31944c","size":{"x":32,"y":1,"z":32}},{"blockCount":131,"bytes":3165,"file":"chunks/y196-z160-x192.json","offset":{"x":192,"y":196,"z":160},"requirements":{"minecraft:cobbled_deepslate":25,"minecraft:oak_planks":19,"minecraft:polished_diorite":7,"minecraft:spruce_planks":33,"minecraft:stone_bricks":47},"sha256":"9f5ad6159c2cebd64fb67548345efc2451662578bfaa8b967379f8b518293b2d","size":{"x":32,"y":1,"z":32}},{"blockCount":156,"bytes":3184,"file":"chunks/y196-z160-x224.json","offset":{"x":224,"y":196,"z":160},"requirements":{"minecraft:cobbled_deepslate":31,"minecraft:oak_planks":25,"minecraft:polished_diorite":7,"minecraft:spruce_planks":39,"minecraft:stone_bricks":54},"sha256":"417cc4f45f9841b642b75af0ff7fb34a2c2cd1e37afefa58bd0723ebb722990b","size":{"x":32,"y":1,"z":32}},{"blockCount":2,"bytes":713,"file":"chunks/y197-z064-x192.json","offset":{"x":192,"y":197,"z":64},"requirements":{"minecraft:polished_diorite":1,"minecraft:stone_bricks":1},"sha256":"4f1175f08ff8f72559fbac5cfb580c6768fdc3998e05ef4557118f17345fb7cc","size":{"x":32,"y":1,"z":32}},{"blockCount":2,"bytes":713,"file":"chunks/y197-z064-x224.json","offset":{"x":224,"y":197,"z":64},"requirements":{"minecraft:polished_diorite":1,"minecraft:stone_bricks":1},"sha256":"185db3799cdf68f335a0c85e9f9a9484e3735ddc750fc1e25b7e1bab493cf27d","size":{"x":32,"y":1,"z":32}},{"blockCount":96,"bytes":2573,"file":"chunks/y197-z096-x192.json","offset":{"x":192,"y":197,"z":96},"requirements":{"minecraft:cobbled_deepslate":24,"minecraft:oak_planks":1,"minecraft:polished_diorite":7,"minecraft:spruce_planks":2,"minecraft:stone_bricks":62},"sha256":"1a208f7e59503148ffbeb5cd7ab6bc4e44ffe5254b1953751159dba91cfbc8bd","size":{"x":32,"y":1,"z":32}},{"blockCount":112,"bytes":2743,"file":"chunks/y197-z096-x224.json","offset":{"x":224,"y":197,"z":96},"requirements":{"minecraft:cobbled_deepslate":32,"minecraft:oak_planks":2,"minecraft:polished_diorite":7,"minecraft:spruce_planks":3,"minecraft:stone_bricks":68},"sha256":"d9fe7cd6fcf5f8a5c67f35958ed38cadb7216dd8a67ed3c2110421ee053186ee","size":{"x":32,"y":1,"z":32}},{"blockCount":24,"bytes":1263,"file":"chunks/y197-z128-x096.json","offset":{"x":96,"y":197,"z":128},"requirements":{"minecraft:cobbled_deepslate":10,"minecraft:spruce_planks":4,"minecraft:stone_bricks":10},"sha256":"f31a9fc23511b4ff55de38b2237d7d85d3212bb6ab0c895ad8953b77df260d53","size":{"x":32,"y":1,"z":32}},{"blockCount":2,"bytes":714,"file":"chunks/y197-z128-x192.json","offset":{"x":192,"y":197,"z":128},"requirements":{"minecraft:polished_diorite":1,"minecraft:stone_bricks":1},"sha256":"219d4bd44576ee67d86e46dcf1b0ad9803c884d3dc3f95a17446b6bd33a27345","size":{"x":32,"y":1,"z":32}},{"blockCount":2,"bytes":714,"file":"chunks/y197-z128-x224.json","offset":{"x":224,"y":197,"z":128},"requirements":{"minecraft:polished_diorite":1,"minecraft:stone_bricks":1},"sha256":"0da900650a81436523ae3420892f4c1c04c8937ba19c83519a781aa60aa2847f","size":{"x":32,"y":1,"z":32}},{"blockCount":96,"bytes":2593,"file":"chunks/y197-z160-x192.json","offset":{"x":192,"y":197,"z":160},"requirements":{"minecraft:cobbled_deepslate":23,"minecraft:oak_planks":1,"minecraft:polished_diorite":7,"minecraft:spruce_planks":2,"minecraft:stone_bricks":63},"sha256":"b9274ce15925e525aea616f77df3720a812490c8a711db173b195e271d647a21","size":{"x":32,"y":1,"z":32}},{"blockCount":112,"bytes":2744,"file":"chunks/y197-z160-x224.json","offset":{"x":224,"y":197,"z":160},"requirements":{"minecraft:cobbled_deepslate":29,"minecraft:oak_planks":2,"minecraft:polished_diorite":7,"minecraft:spruce_planks":3,"minecraft:stone_bricks":71},"sha256":"f481d9c3632941840e5a899b48413984010f19b7d5201427124d3439af9edaba","size":{"x":32,"y":1,"z":32}},{"blockCount":2,"bytes":686,"file":"chunks/y198-z064-x192.json","offset":{"x":192,"y":198,"z":64},"requirements":{"minecraft:polished_diorite":2},"sha256":"5cda228d1515375b6b7b2289bd30d931cfeb637e429d6fe8a6cefc9ab0965225","size":{"x":32,"y":1,"z":32}},{"blockCount":2,"bytes":686,"file":"chunks/y198-z064-x224.json","offset":{"x":224,"y":198,"z":64},"requirements":{"minecraft:polished_diorite":2},"sha256":"e96a1d7e98ba0f2b51bc5008c22b554c97488434d8afdfb871101db322407585","size":{"x":32,"y":1,"z":32}},{"blockCount":55,"bytes":2232,"file":"chunks/y198-z096-x192.json","offset":{"x":192,"y":198,"z":96},"requirements":{"minecraft:cobbled_deepslate":24,"minecraft:oak_planks":1,"minecraft:polished_diorite":14,"minecraft:spruce_planks":3,"minecraft:stone_bricks":13},"sha256":"8f5fbe39e7ba069bd737c59a0a9ae8220a22b8e94406fe808ec7928a97b1ca4f","size":{"x":32,"y":1,"z":32}},{"blockCount":69,"bytes":2516,"file":"chunks/y198-z096-x224.json","offset":{"x":224,"y":198,"z":96},"requirements":{"minecraft:cobbled_deepslate":30,"minecraft:oak_planks":3,"minecraft:polished_diorite":14,"minecraft:spruce_planks":5,"minecraft:stone_bricks":17},"sha256":"f28ff601cfd3fb14567fc884c8336394fd633c30175414385c4511c88b5bde32","size":{"x":32,"y":1,"z":32}},{"blockCount":25,"bytes":1240,"file":"chunks/y198-z128-x096.json","offset":{"x":96,"y":198,"z":128},"requirements":{"minecraft:cobbled_deepslate":12,"minecraft:oak_planks":5,"minecraft:stone_bricks":8},"sha256":"b3cec8a09c134b426b344371b0ad3f900ec7fdcf8a735e5c12e6ef5aba122549","size":{"x":32,"y":1,"z":32}},{"blockCount":2,"bytes":687,"file":"chunks/y198-z128-x192.json","offset":{"x":192,"y":198,"z":128},"requirements":{"minecraft:polished_diorite":2},"sha256":"bbfb01adc747e1e7194a4028c5e8dc2d513dcd28e58649333475c5790d60db93","size":{"x":32,"y":1,"z":32}},{"blockCount":2,"bytes":687,"file":"chunks/y198-z128-x224.json","offset":{"x":224,"y":198,"z":128},"requirements":{"minecraft:polished_diorite":2},"sha256":"50250949976d8eab546051a60904311ec04a822dc4fe26c54ca970d5eef6d589","size":{"x":32,"y":1,"z":32}},{"blockCount":55,"bytes":2157,"file":"chunks/y198-z160-x192.json","offset":{"x":192,"y":198,"z":160},"requirements":{"minecraft:cobbled_deepslate":26,"minecraft:oak_planks":1,"minecraft:polished_diorite":14,"minecraft:spruce_planks":3,"minecraft:stone_bricks":11},"sha256":"84a3855f4344fd51dcef70aafd22525ec9b5099f3c8ada46da70948e46e5a432","size":{"x":32,"y":1,"z":32}},{"blockCount":69,"bytes":2536,"file":"chunks/y198-z160-x224.json","offset":{"x":224,"y":198,"z":160},"requirements":{"minecraft:cobbled_deepslate":26,"minecraft:oak_planks":3,"minecraft:polished_diorite":14,"minecraft:spruce_planks":5,"minecraft:stone_bricks":21},"sha256":"d3fe94ede0e0237f6abee9597be53661a6036592772e440f697b806499375228","size":{"x":32,"y":1,"z":32}},{"blockCount":1,"bytes":648,"file":"chunks/y199-z064-x192.json","offset":{"x":192,"y":199,"z":64},"requirements":{"minecraft:polished_diorite":1},"sha256":"3bc48d38dbf480f8c1099f5428e82c7dceba51dc281aa5e7ed1b775443026eeb","size":{"x":32,"y":1,"z":32}},{"blockCount":1,"bytes":648,"file":"chunks/y199-z064-x224.json","offset":{"x":224,"y":199,"z":64},"requirements":{"minecraft:polished_diorite":1},"sha256":"a4204a06f0e40d560fbf4effd7a3c5f4e887575c637f82237ffd544a1576eebc","size":{"x":32,"y":1,"z":32}},{"blockCount":60,"bytes":2211,"file":"chunks/y199-z096-x192.json","offset":{"x":192,"y":199,"z":96},"requirements":{"minecraft:cobbled_deepslate":21,"minecraft:oak_planks":1,"minecraft:polished_diorite":7,"minecraft:spruce_planks":4,"minecraft:stone_bricks":27},"sha256":"eff7cb81460de8bc28589400bb40933d50d0e50074234009131d615e545e6ac9","size":{"x":32,"y":1,"z":32}},{"blockCount":74,"bytes":2609,"file":"chunks/y199-z096-x224.json","offset":{"x":224,"y":199,"z":96},"requirements":{"minecraft:cobbled_deepslate":30,"minecraft:oak_planks":3,"minecraft:polished_diorite":7,"minecraft:spruce_planks":8,"minecraft:stone_bricks":26},"sha256":"7f681a9f5ae07f7c26dbaf4dcfa40f03b08d01bbe4cee41eb9bee40a61455e45","size":{"x":32,"y":1,"z":32}},{"blockCount":21,"bytes":1183,"file":"chunks/y199-z128-x096.json","offset":{"x":96,"y":199,"z":128},"requirements":{"minecraft:cobbled_deepslate":11,"minecraft:oak_planks":1,"minecraft:stone_bricks":9},"sha256":"0b66b099636aa299a78de77785e781422ba5feeebdbbe0ce48b4c22f9ccc53aa","size":{"x":32,"y":1,"z":32}},{"blockCount":1,"bytes":649,"file":"chunks/y199-z128-x192.json","offset":{"x":192,"y":199,"z":128},"requirements":{"minecraft:polished_diorite":1},"sha256":"f34be7ab75db01dd7d6e3f15b7e454da106ea27b602a90a9eec132f9605f93c8","size":{"x":32,"y":1,"z":32}},{"blockCount":1,"bytes":649,"file":"chunks/y199-z128-x224.json","offset":{"x":224,"y":199,"z":128},"requirements":{"minecraft:polished_diorite":1},"sha256":"41f8b0d51cd1f7ea648f98c8b80ff9a76677c1673bdc3e9ec0715ca8899f9918","size":{"x":32,"y":1,"z":32}},{"blockCount":60,"bytes":2307,"file":"chunks/y199-z160-x192.json","offset":{"x":192,"y":199,"z":160},"requirements":{"minecraft:cobbled_deepslate":21,"minecraft:oak_planks":1,"minecraft:polished_diorite":7,"minecraft:spruce_planks":4,"minecraft:stone_bricks":27},"sha256":"da266bdec8651b8c757493bcaa255e241dca4fd9ea39a3a363fb538fc498efe6","size":{"x":32,"y":1,"z":32}},{"blockCount":74,"bytes":2572,"file":"chunks/y199-z160-x224.json","offset":{"x":224,"y":199,"z":160},"requirements":{"minecraft:cobbled_deepslate":27,"minecraft:oak_planks":3,"minecraft:polished_diorite":7,"minecraft:spruce_planks":8,"minecraft:stone_bricks":29},"sha256":"399e55974d25ca7df3a03a7147b9f7e7e3127269fde9e77ba97b11653a4327ee","size":{"x":32,"y":1,"z":32}},{"blockCount":1,"bytes":648,"file":"chunks/y200-z064-x192.json","offset":{"x":192,"y":200,"z":64},"requirements":{"minecraft:polished_diorite":1},"sha256":"cb82da2eb535fce8e09f900bd1a3629db9922c043c77b1a1b67be3728e7d7d36","size":{"x":32,"y":1,"z":32}},{"blockCount":1,"bytes":648,"file":"chunks/y200-z064-x224.json","offset":{"x":224,"y":200,"z":64},"requirements":{"minecraft:polished_diorite":1},"sha256":"2cf8fc5f8765a1ca4a2eb72590e9f885656c4dc9dfcc3f1346d98ed0dde3f479","size":{"x":32,"y":1,"z":32}},{"blockCount":71,"bytes":2383,"file":"chunks/y200-z096-x192.json","offset":{"x":192,"y":200,"z":96},"requirements":{"minecraft:cobbled_deepslate":25,"minecraft:oak_planks":19,"minecraft:polished_diorite":7,"minecraft:spruce_planks":9,"minecraft:stone_bricks":11},"sha256":"8bf443a34c7eb3775ec82445e9012653319c97a9ceda4ae40bef10d04da608c5","size":{"x":32,"y":1,"z":32}},{"blockCount":91,"bytes":2726,"file":"chunks/y200-z096-x224.json","offset":{"x":224,"y":200,"z":96},"requirements":{"minecraft:cobbled_deepslate":27,"minecraft:oak_planks":25,"minecraft:polished_diorite":7,"minecraft:spruce_planks":15,"minecraft:stone_bricks":17},"sha256":"1ff6089dfecb84b5aae0bc68e2449d96b5e59d1c9d557a1a1f002164ca58d837","size":{"x":32,"y":1,"z":32}},{"blockCount":29,"bytes":1146,"file":"chunks/y200-z128-x096.json","offset":{"x":96,"y":200,"z":128},"requirements":{"minecraft:cobbled_deepslate":18,"minecraft:oak_planks":1,"minecraft:stone_bricks":10},"sha256":"eaf1a1a2a37e6260ab083b4033f71841c9d08af3e627b934111bb5ed2195e895","size":{"x":32,"y":1,"z":32}},{"blockCount":1,"bytes":649,"file":"chunks/y200-z128-x192.json","offset":{"x":192,"y":200,"z":128},"requirements":{"minecraft:polished_diorite":1},"sha256":"14f787a185ce7cb38c9d31856791e2d2035e5b697c031cba4cf294ae3d7b44d3","size":{"x":32,"y":1,"z":32}},{"blockCount":1,"bytes":649,"file":"chunks/y200-z128-x224.json","offset":{"x":224,"y":200,"z":128},"requirements":{"minecraft:polished_diorite":1},"sha256":"e46446037d41ae0d2c0ebebeb3e530764514bc5c824b8b3d8c4517a475afa09e","size":{"x":32,"y":1,"z":32}},{"blockCount":71,"bytes":2346,"file":"chunks/y200-z160-x192.json","offset":{"x":192,"y":200,"z":160},"requirements":{"minecraft:cobbled_deepslate":22,"minecraft:oak_planks":19,"minecraft:polished_diorite":7,"minecraft:spruce_planks":9,"minecraft:stone_bricks":14},"sha256":"dbaddcf7c600fc6432ce930994309f112dba1edb31d6eb69204be088e264dc5e","size":{"x":32,"y":1,"z":32}},{"blockCount":91,"bytes":2727,"file":"chunks/y200-z160-x224.json","offset":{"x":224,"y":200,"z":160},"requirements":{"minecraft:cobbled_deepslate":29,"minecraft:oak_planks":25,"minecraft:polished_diorite":7,"minecraft:spruce_planks":15,"minecraft:stone_bricks":15},"sha256":"cb8c12b36f23ebe39053e99b51b71c229adb716d3d658880646fc6c19b00dbce","size":{"x":32,"y":1,"z":32}},{"blockCount":1,"bytes":648,"file":"chunks/y201-z064-x192.json","offset":{"x":192,"y":201,"z":64},"requirements":{"minecraft:polished_diorite":1},"sha256":"9d0903c0afd096dbf392d0d7dc320158f4e7ffb479af06ab67629417be1f6e1c","size":{"x":32,"y":1,"z":32}},{"blockCount":1,"bytes":648,"file":"chunks/y201-z064-x224.json","offset":{"x":224,"y":201,"z":64},"requirements":{"minecraft:polished_diorite":1},"sha256":"68b4e8bbab712f8b570a0132eb241024ea752f75a9fd7ded883003d76d2c16c4","size":{"x":32,"y":1,"z":32}},{"blockCount":81,"bytes":2344,"file":"chunks/y201-z096-x192.json","offset":{"x":192,"y":201,"z":96},"requirements":{"minecraft:cobbled_deepslate":31,"minecraft:oak_planks":1,"minecraft:polished_diorite":7,"minecraft:spruce_planks":4,"minecraft:stone_bricks":38},"sha256":"bdded576f586586ba5ad2ba81725240d519f7d9046c8ffb3cd8e89002930dfaa","size":{"x":32,"y":1,"z":32}},{"blockCount":101,"bytes":2629,"file":"chunks/y201-z096-x224.json","offset":{"x":224,"y":201,"z":96},"requirements":{"minecraft:cobbled_deepslate":35,"minecraft:oak_planks":3,"minecraft:polished_diorite":7,"minecraft:spruce_planks":8,"minecraft:stone_bricks":48},"sha256":"73d3700c57daf511921d6b9ad4c4326b4555adfa447da0c4936df3bc5b87dd0b","size":{"x":32,"y":1,"z":32}},{"blockCount":20,"bytes":844,"file":"chunks/y201-z128-x096.json","offset":{"x":96,"y":201,"z":128},"requirements":{"minecraft:cobbled_deepslate":20},"sha256":"c98a1672b5175695f18c7491204f4e7aaeb2f50f864907cf8746c70212adc3cd","size":{"x":32,"y":1,"z":32}},{"blockCount":1,"bytes":649,"file":"chunks/y201-z128-x192.json","offset":{"x":192,"y":201,"z":128},"requirements":{"minecraft:polished_diorite":1},"sha256":"b7a8cc77f13d27b590bb2a2b656b2fc55646dac1081144c668d27d5ad2caac63","size":{"x":32,"y":1,"z":32}},{"blockCount":1,"bytes":649,"file":"chunks/y201-z128-x224.json","offset":{"x":224,"y":201,"z":128},"requirements":{"minecraft:polished_diorite":1},"sha256":"c3b324e7507a9e1f545edeba8774a1611e853f2e0f9998326d0b4533f53e9660","size":{"x":32,"y":1,"z":32}},{"blockCount":81,"bytes":2402,"file":"chunks/y201-z160-x192.json","offset":{"x":192,"y":201,"z":160},"requirements":{"minecraft:cobbled_deepslate":27,"minecraft:oak_planks":1,"minecraft:polished_diorite":7,"minecraft:spruce_planks":4,"minecraft:stone_bricks":42},"sha256":"063b886f08f179d06c5d4c590daebf3b4da402ca936599ba711591c1de9df338","size":{"x":32,"y":1,"z":32}},{"blockCount":101,"bytes":2668,"file":"chunks/y201-z160-x224.json","offset":{"x":224,"y":201,"z":160},"requirements":{"minecraft:cobbled_deepslate":37,"minecraft:oak_planks":3,"minecraft:polished_diorite":7,"minecraft:spruce_planks":8,"minecraft:stone_bricks":46},"sha256":"dd01af1a9941738d933ad033c914751f83ef2d66d0ee55eb90a5d4772a701e11","size":{"x":32,"y":1,"z":32}},{"blockCount":1,"bytes":648,"file":"chunks/y202-z064-x192.json","offset":{"x":192,"y":202,"z":64},"requirements":{"minecraft:polished_diorite":1},"sha256":"fbce18abfbbb309e0f027622a69579b3361144626c941ee33249c352b4d05663","size":{"x":32,"y":1,"z":32}},{"blockCount":1,"bytes":648,"file":"chunks/y202-z064-x224.json","offset":{"x":224,"y":202,"z":64},"requirements":{"minecraft:polished_diorite":1},"sha256":"26db382313a2fa2bc2c7390462f7ce5bf7a6f6f8159851393a98368f93d5e173","size":{"x":32,"y":1,"z":32}},{"blockCount":44,"bytes":2021,"file":"chunks/y202-z096-x192.json","offset":{"x":192,"y":202,"z":96},"requirements":{"minecraft:cobbled_deepslate":22,"minecraft:oak_planks":1,"minecraft:polished_diorite":7,"minecraft:spruce_planks":4,"minecraft:stone_bricks":10},"sha256":"428fbf227f6e9a9a110b628e1aca17c613bef453364436b2685e5309311d059a","size":{"x":32,"y":1,"z":32}},{"blockCount":58,"bytes":2344,"file":"chunks/y202-z096-x224.json","offset":{"x":224,"y":202,"z":96},"requirements":{"minecraft:cobbled_deepslate":28,"minecraft:oak_planks":3,"minecraft:polished_diorite":7,"minecraft:spruce_planks":8,"minecraft:stone_bricks":12},"sha256":"58b11c65e43d2426949be96800267af58772562d153303d8e6272391646a76da","size":{"x":32,"y":1,"z":32}},{"blockCount":13,"bytes":970,"file":"chunks/y202-z128-x096.json","offset":{"x":96,"y":202,"z":128},"requirements":{"minecraft:cobbled_deepslate":5,"minecraft:sandstone":4,"minecraft:stone_bricks":4},"sha256":"853fcb1648bd489d965b8818bae6362ce80dd8171182f15df84a1b690456dfe8","size":{"x":32,"y":1,"z":32}},{"blockCount":1,"bytes":649,"file":"chunks/y202-z128-x192.json","offset":{"x":192,"y":202,"z":128},"requirements":{"minecraft:polished_diorite":1},"sha256":"0fe315efbc647360919d234f6099afe4f52ccd041888c8aad6f51b8bd7514267","size":{"x":32,"y":1,"z":32}},{"blockCount":1,"bytes":649,"file":"chunks/y202-z128-x224.json","offset":{"x":224,"y":202,"z":128},"requirements":{"minecraft:polished_diorite":1},"sha256":"b5ecd3fb6ab5bf2413e2a9471eafbf46b27ee953faf8958de2b20a008235ee98","size":{"x":32,"y":1,"z":32}},{"blockCount":44,"bytes":2022,"file":"chunks/y202-z160-x192.json","offset":{"x":192,"y":202,"z":160},"requirements":{"minecraft:cobbled_deepslate":19,"minecraft:oak_planks":1,"minecraft:polished_diorite":7,"minecraft:spruce_planks":4,"minecraft:stone_bricks":13},"sha256":"c94e45d6639ceb9f249667eeee0c4dad2c61b885dc9bbceed3b0ecff60ee0317","size":{"x":32,"y":1,"z":32}},{"blockCount":58,"bytes":2345,"file":"chunks/y202-z160-x224.json","offset":{"x":224,"y":202,"z":160},"requirements":{"minecraft:cobbled_deepslate":25,"minecraft:oak_planks":3,"minecraft:polished_diorite":7,"minecraft:spruce_planks":8,"minecraft:stone_bricks":15},"sha256":"d817f1b120ae1e21081da421b6b826b6234361bb6713ef7ea871558663ce3b4c","size":{"x":32,"y":1,"z":32}},{"blockCount":1,"bytes":644,"file":"chunks/y203-z064-x192.json","offset":{"x":192,"y":203,"z":64},"requirements":{"minecraft:stone_bricks":1},"sha256":"2c8032787948387fced743395f9bb4330f82cd2577c70430d9f71d052aae2e10","size":{"x":32,"y":1,"z":32}},{"blockCount":1,"bytes":644,"file":"chunks/y203-z064-x224.json","offset":{"x":224,"y":203,"z":64},"requirements":{"minecraft:stone_bricks":1},"sha256":"c9ec4eeeca36ba6e3b711bc5887ed571cd6b5b8d346a632cfb9a610dcca360ed","size":{"x":32,"y":1,"z":32}},{"blockCount":56,"bytes":2192,"file":"chunks/y203-z096-x192.json","offset":{"x":192,"y":203,"z":96},"requirements":{"minecraft:cobbled_deepslate":21,"minecraft:oak_planks":1,"minecraft:polished_diorite":2,"minecraft:spruce_planks":4,"minecraft:stone_bricks":28},"sha256":"35842735fa808f90895d5bb79a2af370d1350cdf6cd8c74dfda54445f712928f","size":{"x":32,"y":1,"z":32}},{"blockCount":71,"bytes":2534,"file":"chunks/y203-z096-x224.json","offset":{"x":224,"y":203,"z":96},"requirements":{"minecraft:cobbled_deepslate":28,"minecraft:oak_planks":3,"minecraft:polished_diorite":2,"minecraft:spruce_planks":9,"minecraft:stone_bricks":29},"sha256":"a9a60569dff00863b7030b003f976068a582fe9b4f6ee033b09dcaa041588ec5","size":{"x":32,"y":1,"z":32}},{"blockCount":13,"bytes":970,"file":"chunks/y203-z128-x096.json","offset":{"x":96,"y":203,"z":128},"requirements":{"minecraft:cobbled_deepslate":5,"minecraft:sandstone":4,"minecraft:stone_bricks":4},"sha256":"d0ee4eef74d7b35a5aebebf4ebca19072b3ed55c825949903a7d977f07ec9eee","size":{"x":32,"y":1,"z":32}},{"blockCount":1,"bytes":645,"file":"chunks/y203-z128-x192.json","offset":{"x":192,"y":203,"z":128},"requirements":{"minecraft:stone_bricks":1},"sha256":"ed37d18ec77cf1087af3f0430797858fa90f9d0485500873fa1d27f5ed43b925","size":{"x":32,"y":1,"z":32}},{"blockCount":1,"bytes":645,"file":"chunks/y203-z128-x224.json","offset":{"x":224,"y":203,"z":128},"requirements":{"minecraft:stone_bricks":1},"sha256":"86fc7f41d9f8be6dffaea68d19441725a648c979520278d5006d1ec1c0d95731","size":{"x":32,"y":1,"z":32}},{"blockCount":56,"bytes":2193,"file":"chunks/y203-z160-x192.json","offset":{"x":192,"y":203,"z":160},"requirements":{"minecraft:cobbled_deepslate":21,"minecraft:oak_planks":1,"minecraft:polished_diorite":2,"minecraft:spruce_planks":4,"minecraft:stone_bricks":28},"sha256":"cc2447ec25b9f7f558c8a8dd0cc4166e55a72ad9075d7fce8a90a21377a61fee","size":{"x":32,"y":1,"z":32}},{"blockCount":71,"bytes":2497,"file":"chunks/y203-z160-x224.json","offset":{"x":224,"y":203,"z":160},"requirements":{"minecraft:cobbled_deepslate":27,"minecraft:oak_planks":3,"minecraft:polished_diorite":2,"minecraft:spruce_planks":9,"minecraft:stone_bricks":30},"sha256":"d422efacc2a5a2c34c5e5ad6bd329d9140c9e7f477433c67aa89d79240212f9d","size":{"x":32,"y":1,"z":32}},{"blockCount":1,"bytes":648,"file":"chunks/y204-z064-x192.json","offset":{"x":192,"y":204,"z":64},"requirements":{"minecraft:polished_diorite":1},"sha256":"225c1395e0af3fc7d96fe56a844d45c99c909fc17170d9f5302d8b2859380b5e","size":{"x":32,"y":1,"z":32}},{"blockCount":1,"bytes":648,"file":"chunks/y204-z064-x224.json","offset":{"x":224,"y":204,"z":64},"requirements":{"minecraft:polished_diorite":1},"sha256":"d63e419c445c43c4bf262cb60771d40d56ea418ca876d9d454100045aebff23b","size":{"x":32,"y":1,"z":32}},{"blockCount":63,"bytes":2346,"file":"chunks/y204-z096-x192.json","offset":{"x":192,"y":204,"z":96},"requirements":{"minecraft:cobbled_deepslate":19,"minecraft:oak_planks":13,"minecraft:polished_diorite":7,"minecraft:spruce_planks":11,"minecraft:stone_bricks":13},"sha256":"1c526261dd397bedf2f21e01096220ea2995d493eb5f0bde07c77e900741a225","size":{"x":32,"y":1,"z":32}},{"blockCount":83,"bytes":2669,"file":"chunks/y204-z096-x224.json","offset":{"x":224,"y":204,"z":96},"requirements":{"minecraft:cobbled_deepslate":25,"minecraft:oak_planks":20,"minecraft:polished_diorite":7,"minecraft:spruce_planks":16,"minecraft:stone_bricks":15},"sha256":"87a12b0391f3e2f15d9b1b00ba902367d8038f15c01261781fc2b021827bec1d","size":{"x":32,"y":1,"z":32}},{"blockCount":13,"bytes":970,"file":"chunks/y204-z128-x096.json","offset":{"x":96,"y":204,"z":128},"requirements":{"minecraft:cobbled_deepslate":5,"minecraft:sandstone":4,"minecraft:stone_bricks":4},"sha256":"7175c0addafb36ff317696fa495042fd4a03e2b7f35550f3258fe2eafa6a4856","size":{"x":32,"y":1,"z":32}},{"blockCount":1,"bytes":649,"file":"chunks/y204-z128-x192.json","offset":{"x":192,"y":204,"z":128},"requirements":{"minecraft:polished_diorite":1},"sha256":"cdd560d2db73a437415e8fe5a03ccfcc0d5a14f3aed3da93d7b355a561607b39","size":{"x":32,"y":1,"z":32}},{"blockCount":1,"bytes":649,"file":"chunks/y204-z128-x224.json","offset":{"x":224,"y":204,"z":128},"requirements":{"minecraft:polished_diorite":1},"sha256":"3a6dd2df9a029fd39e14d8a4c6c70e427afcf1dbbdb149cd64227ffe80c1ba95","size":{"x":32,"y":1,"z":32}},{"blockCount":63,"bytes":2347,"file":"chunks/y204-z160-x192.json","offset":{"x":192,"y":204,"z":160},"requirements":{"minecraft:cobbled_deepslate":19,"minecraft:oak_planks":13,"minecraft:polished_diorite":7,"minecraft:spruce_planks":11,"minecraft:stone_bricks":13},"sha256":"0e7e18373f8e26f414803e34c6fd67b6397fdddcfaf69c172bb09ed16db2b055","size":{"x":32,"y":1,"z":32}}],"schema":1}
