{"entries":[{"blockCount":83,"bytes":2594,"file":"chunks/y204-z160-x224.json","offset":{"x":224,"y":204,"z":160},"requirements":{"minecraft:cobbled_deepslate":28,"minecraft:oak_planks":20,"minecraft:polished_diorite":7,"minecraft:spruce_planks":16,"minecraft:stone_bricks":12},"sha256":"79353c7c0b941fa5935d43f8407ac80bc94bf15340b27fa34a58dadaea049934","size":{"x":32,"y":1,"z":32}},{"blockCount":61,"bytes":2044,"file":"chunks/y205-z096-x192.json","offset":{"x":192,"y":205,"z":96},"requirements":{"minecraft:cobbled_deepslate":16,"minecraft:oak_planks":1,"minecraft:spruce_planks":3,"minecraft:stone_bricks":41},"sha256":"d2d1cadfb24a8b30bab7fa2e081e5b8b311d2756bc9c3a2b8a0823ac2e8948ea","size":{"x":32,"y":1,"z":32}},{"blockCount":83,"bytes":2443,"file":"chunks/y205-z096-x224.json","offset":{"x":224,"y":205,"z":96},"requirements":{"minecraft:cobbled_deepslate":24,"minecraft:oak_planks":3,"minecraft:spruce_planks":9,"minecraft:stone_bricks":47},"sha256":"a1b70529411c9e735ebb60b9823f1ad295cbf07cb7699a9a7028cd86a6d772f4","size":{"x":32,"y":1,"z":32}},{"blockCount":13,"bytes":970,"file":"chunks/y205-z128-x096.json","offset":{"x":96,"y":205,"z":128},"requirements":{"minecraft:cobbled_deepslate":5,"minecraft:sandstone":4,"minecraft:stone_bricks":4},"sha256":"e59b8c4217011ffb535707b567cf4a7cd493b3a963744360c3c37a471e55a4e3","size":{"x":32,"y":1,"z":32}},{"blockCount":61,"bytes":2026,"file":"chunks/y205-z160-x192.json","offset":{"x":192,"y":205,"z":160},"requirements":{"minecraft:cobbled_deepslate":16,"minecraft:oak_planks":1,"minecraft:spruce_planks":3,"minecraft:stone_bricks":41},"sha256":"f7547ecbd4c3b6ed9deee1433680a75f22467113e915989e5c9950cd109ac9b6","size":{"x":32,"y":1,"z":32}},{"blockCount":83,"bytes":2406,"file":"chunks/y205-z160-x224.json","offset":{"x":224,"y":205,"z":160},"requirements":{"minecraft:cobbled_deepslate":22,"minecraft:oak_planks":3,"minecraft:spruce_planks":9,"minecraft:stone_bricks":49},"sha256":"56fd6df940de665d78a3379ebb9442cabc5ab304eb0efe86af8227e75eac37ef","size":{"x":32,"y":1,"z":32}},{"blockCount":33,"bytes":1739,"file":"chunks/y206-z096-x192.json","offset":{"x":192,"y":206,"z":96},"requirements":{"minecraft:cobbled_deepslate":19,"minecraft:oak_planks":1,"minecraft:spruce_planks":2,"minecraft:stone_bricks":11},"sha256":"dc19f2c1ea77553f2be9f5e6ab4be42bf4bcae37fccc4bcb77098d4253d0280e","size":{"x":32,"y":1,"z":32}},{"blockCount":48,"bytes":1986,"file":"chunks/y206-z096-x224.json","offset":{"x":224,"y":206,"z":96},"requirements":{"minecraft:cobbled_deepslate":25,"minecraft:oak_planks":3,"minecraft:spruce_planks":7,"minecraft:stone_bricks":13},"sha256":"61b8ca890ddb7b1ff8d309e177058e364ace80561a9472279621653b45ee3e0a","size":{"x":32,"y":1,"z":32}},{"blockCount":13,"bytes":970,"file":"chunks/y206-z128-x096.json","offset":{"x":96,"y":206,"z":128},"requirements":{"minecraft:cobbled_deepslate":5,"minecraft:sandstone":4,"minecraft:stone_bricks":4},"sha256":"2a1ca4fbd27e066bcc71856c07bf0f81ba1ace725fa2f49b6b869e09e0fb329a","size":{"x":32,"y":1,"z":32}},{"blockCount":33,"bytes":1778,"file":"chunks/y206-z160-x192.json","offset":{"x":192,"y":206,"z":160},"requirements":{"minecraft:cobbled_deepslate":17,"minecraft:oak_planks":1,"minecraft:spruce_planks":2,"minecraft:stone_bricks":13},"sha256":"19bf48888a3dee7c12cfc549b4e334f5355c07dcc0137cf7037398bfbd9faa22","size":{"x":32,"y":1,"z":32}},{"blockCount":48,"bytes":2063,"file":"chunks/y206-z160-x224.json","offset":{"x":224,"y":206,"z":160},"requirements":{"minecraft:cobbled_deepslate":23,"minecraft:oak_planks":3,"minecraft:spruce_planks":7,"minecraft:stone_bricks":15},"sha256":"c4edc25e59b6550341754c3b415a98f7de2ffd8ba122c35678bce465080aa535","size":{"x":32,"y":1,"z":32}},{"blockCount":50,"bytes":1935,"file":"chunks/y207-z096-x192.json","offset":{"x":192,"y":207,"z":96},"requirements":{"minecraft:cobbled_deepslate":19,"minecraft:oak_planks":6,"minecraft:sandstone":2,"minecraft:spruce_planks":2,"minecraft:stone_bricks":21},"sha256":"818a0a55afd271cec0dd19aef71eeb83cff7636fd48d0be7a4b47f6321f024e1","size":{"x":32,"y":1,"z":32}},{"blockCount":75,"bytes":2601,"file":"chunks/y207-z096-x224.json","offset":{"x":224,"y":207,"z":96},"requirements":{"minecraft:cobbled_deepslate":26,"minecraft:oak_planks":22,"minecraft:sandstone":2,"minecraft:spruce_planks":3,"minecraft:stone_bricks":22},"sha256":"982d96beb7340919a7e94b1cb78cfbef2f21e06b2ccddeba8635f56fea0a2e9f","size":{"x":32,"y":1,"z":32}},{"blockCount":9,"bytes":892,"file":"chunks/y207-z128-x096.json","offset":{"x":96,"y":207,"z":128},"requirements":{"minecraft:cobbled_deepslate":1,"minecraft:sandstone":4,"minecraft:stone_bricks":4},"sha256":"7b2366f6c4ff9e0267dd008eb39ec8f4cfbe20bdc38e30811e522f5e069d9253","size":{"x":32,"y":1,"z":32}},{"blockCount":50,"bytes":1974,"file":"chunks/y207-z160-x192.json","offset":{"x":192,"y":207,"z":160},"requirements":{"minecraft:cobbled_deepslate":19,"minecraft:oak_planks":6,"minecraft:sandstone":2,"minecraft:spruce_planks":2,"minecraft:stone_bricks":21},"sha256":"4b2e0ea38ce27cbb216b6b7b4d10bbe68aa18c0f13d03ec621e3b0649f79844c","size":{"x":32,"y":1,"z":32}},{"blockCount":75,"bytes":2621,"file":"chunks/y207-z160-x224.json","offset":{"x":224,"y":207,"z":160},"requirements":{"minecraft:cobbled_deepslate":25,"minecraft:oak_planks":22,"minecraft:sandstone":2,"minecraft:spruce_planks":3,"minecraft:stone_bricks":23},"sha256":"5d0c6b2d837180733a3068c2ad4a1eae9752fa7b04b521b53a473a5a0b09dc6f","size":{"x":32,"y":1,"z":32}},{"blockCount":58,"bytes":2178,"file":"chunks/y208-z096-x192.json","offset":{"x":192,"y":208,"z":96},"requirements":{"minecraft:cobbled_deepslate":20,"minecraft:oak_planks":15,"minecraft:spruce_planks":13,"minecraft:stone_bricks":10},"sha256":"6a9a4f210b09afa262dfd8e7ffcd08fb8684aea989178044fb5a002733dcf8c2","size":{"x":32,"y":1,"z":32}},{"blockCount":79,"bytes":2520,"file":"chunks/y208-z096-x224.json","offset":{"x":224,"y":208,"z":96},"requirements":{"minecraft:cobbled_deepslate":26,"minecraft:oak_planks":23,"minecraft:spruce_planks":18,"minecraft:stone_bricks":12},"sha256":"8d154bee7e6774fb67e5141049fde5562fb17203835cf4a35bc07cfb42788b1f","size":{"x":32,"y":1,"z":32}},{"blockCount":9,"bytes":892,"file":"chunks/y208-z128-x096.json","offset":{"x":96,"y":208,"z":128},"requirements":{"minecraft:cobbled_deepslate":1,"minecraft:sandstone":4,"minecraft:stone_bricks":4},"sha256":"41b190959991b370931a047dc727179db1eedb06a6e7a482bab5355b404c13ce","size":{"x":32,"y":1,"z":32}},{"blockCount":58,"bytes":2179,"file":"chunks/y208-z160-x192.json","offset":{"x":192,"y":208,"z":160},"requirements":{"minecraft:cobbled_deepslate":20,"minecraft:oak_planks":15,"minecraft:spruce_planks":13,"minecraft:stone_bricks":10},"sha256":"c175f93b00b28f4deda2d20dc5e56c2a14c71ae00a87185a8012b5e707b40beb","size":{"x":32,"y":1,"z":32}},{"blockCount":79,"bytes":2597,"file":"chunks/y208-z160-x224.json","offset":{"x":224,"y":208,"z":160},"requirements":{"minecraft:cobbled_deepslate":21,"minecraft:oak_planks":23,"minecraft:spruce_planks":18,"minecraft:stone_bricks":17},"sha256":"dc97b67f7b2c92b497421620c36216746097dcd85d1d6521d972f21c990541e8","size":{"x":32,"y":1,"z":32}},{"blockCount":56,"bytes":1882,"file":"chunks/y209-z096-x192.json","offset":{"x":192,"y":209,"z":96},"requirements":{"minecraft:cobbled_deepslate":24,"minecraft:oak_planks":1,"minecraft:stone_bricks":31},"sha256":"26a8d7fecc868438df4c4a8a75d34de7e65303c9c41c196488295ab955fc245d","size":{"x":32,"y":1,"z":32}},{"blockCount":73,"bytes":2129,"file":"chunks/y209-z096-x224.json","offset":{"x":224,"y":209,"z":96},"requirements":{"minecraft:cobbled_deepslate":29,"minecraft:oak_planks":4,"minecraft:stone_bricks":40},"sha256":"3809a1bc683db943bc2902d9ca2d34f42f70a24b7d984d141aa7ccb5e523df5d","size":{"x":32,"y":1,"z":32}},{"blockCount":5,"bytes":784,"file":"chunks/y209-z128-x096.json","offset":{"x":96,"y":209,"z":128},"requirements":{"minecraft:sandstone":1,"minecraft:stone_bricks":4},"sha256":"a606a4cd15ad4632f09cae173d137b98d399a4efc97649907d812668a20bb2f0","size":{"x":32,"y":1,"z":32}},{"blockCount":56,"bytes":1864,"file":"chunks/y209-z160-x192.json","offset":{"x":192,"y":209,"z":160},"requirements":{"minecraft:cobbled_deepslate":25,"minecraft:oak_planks":1,"minecraft:stone_bricks":30},"sha256":"85dd1e314030fb7bfef1d1aa074508532f0ea86bc400b37448bd2f4526cbbad2","size":{"x":32,"y":1,"z":32}},{"blockCount":73,"bytes":2111,"file":"chunks/y209-z160-x224.json","offset":{"x":224,"y":209,"z":160},"requirements":{"minecraft:cobbled_deepslate":26,"minecraft:oak_planks":4,"minecraft:stone_bricks":43},"sha256":"37824b72b0fbe64ab654a5c5b7cf9850a60051a0ba8fd8e76761c1f69ba74fbd","size":{"x":32,"y":1,"z":32}},{"blockCount":1,"bytes":644,"file":"chunks/y210-z064-x192.json","offset":{"x":192,"y":210,"z":64},"requirements":{"minecraft:stone_bricks":1},"sha256":"cb4865c9f21cce2aee590c23eae645b13b2177b082fe70ac581700019b21c461","size":{"x":32,"y":1,"z":32}},{"blockCount":1,"bytes":644,"file":"chunks/y210-z064-x224.json","offset":{"x":224,"y":210,"z":64},"requirements":{"minecraft:stone_bricks":1},"sha256":"3a8a56903b0733f3d1e98ed26df0da4bb64a019fce3dc241a56b1bef5e68b8b1","size":{"x":32,"y":1,"z":32}},{"blockCount":34,"bytes":1774,"file":"chunks/y210-z096-x192.json","offset":{"x":192,"y":210,"z":96},"requirements":{"minecraft:cobbled_deepslate":17,"minecraft:oak_planks":1,"minecraft:sandstone":2,"minecraft:stone_bricks":14},"sha256":"f3a6d65e23ffdb3add13f8a98ae1d1a9ea6cf7fc03533c03f07d3d4684fd62a4","size":{"x":32,"y":1,"z":32}},{"blockCount":45,"bytes":1964,"file":"chunks/y210-z096-x224.json","offset":{"x":224,"y":210,"z":96},"requirements":{"minecraft:cobbled_deepslate":22,"minecraft:oak_planks":4,"minecraft:sandstone":2,"minecraft:stone_bricks":17},"sha256":"c36c644157401ae18b95933e6f1fd3b3dbd84a523fc67ac51ead3a89306af1a1","size":{"x":32,"y":1,"z":32}},{"blockCount":5,"bytes":784,"file":"chunks/y210-z128-x096.json","offset":{"x":96,"y":210,"z":128},"requirements":{"minecraft:sandstone":4,"minecraft:stone_bricks":1},"sha256":"8b9443585bc01ea7e1ac2319f19e28706446ad3721745d6c94cb1816bab66f3b","size":{"x":32,"y":1,"z":32}},{"blockCount":1,"bytes":645,"file":"chunks/y210-z128-x192.json","offset":{"x":192,"y":210,"z":128},"requirements":{"minecraft:stone_bricks":1},"sha256":"7a877b3c18b90952c763601c11102f5d1c4c0d15df315f47c5f58ca91ec5c5c8","size":{"x":32,"y":1,"z":32}},{"blockCount":1,"bytes":645,"file":"chunks/y210-z128-x224.json","offset":{"x":224,"y":210,"z":128},"requirements":{"minecraft:stone_bricks":1},"sha256":"84ba0e1e56d87661f856215ebf675b57a4d242d99068978db4d1cb126fc9e5f9","size":{"x":32,"y":1,"z":32}},{"blockCount":34,"bytes":1756,"file":"chunks/y210-z160-x192.json","offset":{"x":192,"y":210,"z":160},"requirements":{"minecraft:cobbled_deepslate":15,"minecraft:oak_planks":1,"minecraft:sandstone":2,"minecraft:stone_bricks":16},"sha256":"69296958f7ee3f164de1bcb394b36d8bbeebb277571cb37841194990c936c4df","size":{"x":32,"y":1,"z":32}},{"blockCount":45,"bytes":1984,"file":"chunks/y210-z160-x224.json","offset":{"x":224,"y":210,"z":160},"requirements":{"minecraft:cobbled_deepslate":21,"minecraft:oak_planks":4,"minecraft:sandstone":2,"minecraft:stone_bricks":18},"sha256":"937776d5a22ad5820b21188c8376ea5b251f08362ebb627ad2719726b35acf7c","size":{"x":32,"y":1,"z":32}},{"blockCount":39,"bytes":1749,"file":"chunks/y211-z096-x192.json","offset":{"x":192,"y":211,"z":96},"requirements":{"minecraft:cobbled_deepslate":17,"minecraft:oak_planks":1,"minecraft:stone_bricks":21},"sha256":"d0ac71067ec140d74c9a90dd89ce6ae3879c5a0bf6554cb2fe93b582a18a4878","size":{"x":32,"y":1,"z":32}},{"blockCount":50,"bytes":1939,"file":"chunks/y211-z096-x224.json","offset":{"x":224,"y":211,"z":96},"requirements":{"minecraft:cobbled_deepslate":23,"minecraft:oak_planks":4,"minecraft:stone_bricks":23},"sha256":"e2d1275e0d5ef6d83d3e9006b35261af101b54822779059b5a50bb18b760945b","size":{"x":32,"y":1,"z":32}},{"blockCount":1,"bytes":649,"file":"chunks/y211-z128-x096.json","offset":{"x":96,"y":211,"z":128},"requirements":{"minecraft:cobbled_deepslate":1},"sha256":"1991ab3dc0ae0c27c7067348cebb846ac74bd041577522d9dd2c49c8b9963a97","size":{"x":32,"y":1,"z":32}},{"blockCount":39,"bytes":1712,"file":"chunks/y211-z160-x192.json","offset":{"x":192,"y":211,"z":160},"requirements":{"minecraft:cobbled_deepslate":15,"minecraft:oak_planks":1,"minecraft:stone_bricks":23},"sha256":"15cae1f86f17834891d855be9b6e9ddab4ef52ea777aa8c6adb4bf4f1f5c702b","size":{"x":32,"y":1,"z":32}},{"blockCount":50,"bytes":1959,"file":"chunks/y211-z160-x224.json","offset":{"x":224,"y":211,"z":160},"requirements":{"minecraft:cobbled_deepslate":21,"minecraft:oak_planks":4,"minecraft:stone_bricks":25},"sha256":"2efaefa5b52a26dad6f0cda9b7d756d89b2575aae7a909521ce5d6be26246219","size":{"x":32,"y":1,"z":32}},{"blockCount":42,"bytes":1833,"file":"chunks/y212-z096-x192.json","offset":{"x":192,"y":212,"z":96},"requirements":{"minecraft:cobbled_deepslate":17,"minecraft:oak_planks":11,"minecraft:spruce_planks":5,"minecraft:stone_bricks":9},"sha256":"16dc4af86382709234f1d68d0a78430765eb0418a63bd1a4111dc751c89913eb","size":{"x":32,"y":1,"z":32}},{"blockCount":59,"bytes":2043,"file":"chunks/y212-z096-x224.json","offset":{"x":224,"y":212,"z":96},"requirements":{"minecraft:cobbled_deepslate":20,"minecraft:oak_planks":18,"minecraft:spruce_planks":7,"minecraft:stone_bricks":14},"sha256":"1c9ead7d60bedf88a72cf592709ab8b6d8fce062c355d2b5636c2fbce99a5aba","size":{"x":32,"y":1,"z":32}},{"blockCount":1,"bytes":644,"file":"chunks/y212-z128-x096.json","offset":{"x":96,"y":212,"z":128},"requirements":{"minecraft:stone_bricks":1},"sha256":"e3e0a8b5f18e4444f47dab0861c15b701fc2511b19698488d7ac020a1f8c3cd3","size":{"x":32,"y":1,"z":32}},{"blockCount":42,"bytes":1834,"file":"chunks/y212-z160-x192.json","offset":{"x":192,"y":212,"z":160},"requirements":{"minecraft:cobbled_deepslate":17,"minecraft:oak_planks":11,"minecraft:spruce_planks":5,"minecraft:stone_bricks":9},"sha256":"f4200346c2d11fa3cde4b2d1f7504aee26a39ae081ab9b51cc536f53454e812d","size":{"x":32,"y":1,"z":32}},{"blockCount":59,"bytes":2063,"file":"chunks/y212-z160-x224.json","offset":{"x":224,"y":212,"z":160},"requirements":{"minecraft:cobbled_deepslate":22,"minecraft:oak_planks":18,"minecraft:spruce_planks":7,"minecraft:stone_bricks":12},"sha256":"2df681cbad72054d1207a4c9297634c126c8fad59f10f09ee6ee6fd4a8a40063","size":{"x":32,"y":1,"z":32}},{"blockCount":46,"bytes":1730,"file":"chunks/y213-z096-x192.json","offset":{"x":192,"y":213,"z":96},"requirements":{"minecraft:cobbled_deepslate":13,"minecraft:glass":2,"minecraft:oak_planks":1,"minecraft:stone_bricks":30},"sha256":"c2b9523747f2414cd8739e5ea9d12410961dceb7cbc724474553f51c5ce8ab32","size":{"x":32,"y":1,"z":32}},{"blockCount":63,"bytes":1958,"file":"chunks/y213-z096-x224.json","offset":{"x":224,"y":213,"z":96},"requirements":{"minecraft:cobbled_deepslate":21,"minecraft:glass":2,"minecraft:oak_planks":4,"minecraft:stone_bricks":36},"sha256":"7e5d5f90549aab19a4dbe788b555223f91f6f1327a4bb5cbeed47f81d0cce05d","size":{"x":32,"y":1,"z":32}},{"blockCount":5,"bytes":722,"file":"chunks/y213-z128-x096.json","offset":{"x":96,"y":213,"z":128},"requirements":{"minecraft:stone_bricks":5},"sha256":"b42cb14b3cf42f3a5604b1882d5f359a55c6213cbd6c648344f0c9c79e953f1c","size":{"x":32,"y":1,"z":32}},{"blockCount":46,"bytes":1712,"file":"chunks/y213-z160-x192.json","offset":{"x":192,"y":213,"z":160},"requirements":{"minecraft:cobbled_deepslate":12,"minecraft:glass":2,"minecraft:oak_planks":1,"minecraft:stone_bricks":31},"sha256":"3c9565d78b964978c042a4678d01a954b91f05feb374e19771cd8eb33c2d992f","size":{"x":32,"y":1,"z":32}},{"blockCount":63,"bytes":1940,"file":"chunks/y213-z160-x224.json","offset":{"x":224,"y":213,"z":160},"requirements":{"minecraft:cobbled_deepslate":20,"minecraft:glass":2,"minecraft:oak_planks":4,"minecraft:stone_bricks":37},"sha256":"cf2c1659e03fa43fc9fe0885ebbbcd12ee0d1a270d2df1e740895dd29246cc3f","size":{"x":32,"y":1,"z":32}},{"blockCount":23,"bytes":1363,"file":"chunks/y214-z096-x192.json","offset":{"x":192,"y":214,"z":96},"requirements":{"minecraft:cobbled_deepslate":12,"minecraft:oak_planks":1,"minecraft:stone_bricks":10},"sha256":"9f3d99674bbd06b95d0ca3570edbc50a7e3aa9ffc12b2f7e975ac56f87bb7141","size":{"x":32,"y":1,"z":32}},{"blockCount":34,"bytes":1591,"file":"chunks/y214-z096-x224.json","offset":{"x":224,"y":214,"z":96},"requirements":{"minecraft:cobbled_deepslate":17,"minecraft:oak_planks":4,"minecraft:stone_bricks":13},"sha256":"41f291e7ea31a2dc0d38be8465a5c615d867da41fc5c1e99bba9607d91b226d5","size":{"x":32,"y":1,"z":32}},{"blockCount":1,"bytes":644,"file":"chunks/y214-z128-x096.json","offset":{"x":96,"y":214,"z":128},"requirements":{"minecraft:stone_bricks":1},"sha256":"af8140e2016e5bb17f063b3a3ba9eeccde3bd6fc4f89fd822664623cdbedf8ed","size":{"x":32,"y":1,"z":32}},{"blockCount":23,"bytes":1382,"file":"chunks/y214-z160-x192.json","offset":{"x":192,"y":214,"z":160},"requirements":{"minecraft:cobbled_deepslate":14,"minecraft:oak_planks":1,"minecraft:stone_bricks":8},"sha256":"796ab83d1dce7afbdf8ddf54bad4262dbf418e3fe23ff8be690a5fc51f670914","size":{"x":32,"y":1,"z":32}},{"blockCount":34,"bytes":1592,"file":"chunks/y214-z160-x224.json","offset":{"x":224,"y":214,"z":160},"requirements":{"minecraft:cobbled_deepslate":19,"minecraft:oak_planks":4,"minecraft:stone_bricks":11},"sha256":"8b79146bba089d21fe5e654355ccd1d768b6c1519f430e09f7b3d1f5f01aaa6b","size":{"x":32,"y":1,"z":32}},{"blockCount":35,"bytes":1555,"file":"chunks/y215-z096-x192.json","offset":{"x":192,"y":215,"z":96},"requirements":{"minecraft:cobbled_deepslate":15,"minecraft:oak_planks":1,"minecraft:stone_bricks":19},"sha256":"7fb2b1f316ba468806609eaa5295653cd134cc19468dc2fbe233dda3bd2d937d","size":{"x":32,"y":1,"z":32}},{"blockCount":46,"bytes":1802,"file":"chunks/y215-z096-x224.json","offset":{"x":224,"y":215,"z":96},"requirements":{"minecraft:cobbled_deepslate":18,"minecraft:oak_planks":4,"minecraft:stone_bricks":24},"sha256":"c34c9d6e35033f6e2ce7f75b575e9debc642557e1aef81536280fc0c0914411a","size":{"x":32,"y":1,"z":32}},{"blockCount":1,"bytes":641,"file":"chunks/y215-z128-x096.json","offset":{"x":96,"y":215,"z":128},"requirements":{"minecraft:sandstone":1},"sha256":"e8294dcd0ef385db138b96a7ef4af77a83020b4f809ae7b11c550a7f33522bfe","size":{"x":32,"y":1,"z":32}},{"blockCount":35,"bytes":1556,"file":"chunks/y215-z160-x192.json","offset":{"x":192,"y":215,"z":160},"requirements":{"minecraft:cobbled_deepslate":12,"minecraft:oak_planks":1,"minecraft:stone_bricks":22},"sha256":"c271994cf468e2b0a50e023d9477c17d46516ba0bcc19db8e5bfa0f9093d3174","size":{"x":32,"y":1,"z":32}},{"blockCount":46,"bytes":1746,"file":"chunks/y215-z160-x224.json","offset":{"x":224,"y":215,"z":160},"requirements":{"minecraft:cobbled_deepslate":20,"minecraft:oak_planks":4,"minecraft:stone_bricks":22},"sha256":"1d5051b892bd3f34c25c31b5c84d9df14dc2e17724499ddb278d6f575a884443","size":{"x":32,"y":1,"z":32}},{"blockCount":37,"bytes":1600,"file":"chunks/y216-z096-x192.json","offset":{"x":192,"y":216,"z":96},"requirements":{"minecraft:cobbled_deepslate":14,"minecraft:oak_planks":11,"minecraft:spruce_planks":4,"minecraft:stone_bricks":8},"sha256":"1150bc97f54595b24fd619762c767f9b03f95af2cc41eb89a0f861334c196746","size":{"x":32,"y":1,"z":32}},{"blockCount":63,"bytes":2058,"file":"chunks/y216-z096-x224.json","offset":{"x":224,"y":216,"z":96},"requirements":{"minecraft:cobbled_deepslate":17,"minecraft:oak_planks":18,"minecraft:spruce_planks":15,"minecraft:stone_bricks":13},"sha256":"cc10d4c0619e4ed0a4cebc3f263cf6c697e45298b4a56f1361793e79d57464ad","size":{"x":32,"y":1,"z":32}},{"blockCount":1,"bytes":644,"file":"chunks/y216-z128-x096.json","offset":{"x":96,"y":216,"z":128},"requirements":{"minecraft:stone_bricks":1},"sha256":"6f24371ee41e08592779d7f4f90849915e328f2360c8d2ae76cd8c1968c78282","size":{"x":32,"y":1,"z":32}},{"blockCount":37,"bytes":1582,"file":"chunks/y216-z160-x192.json","offset":{"x":192,"y":216,"z":160},"requirements":{"minecraft:cobbled_deepslate":14,"minecraft:oak_planks":11,"minecraft:spruce_planks":4,"minecraft:stone_bricks":8},"sha256":"4553737f96ae9cadc8be15b52d88db2b75ea76e151a99fed595c72ca132a0073","size":{"x":32,"y":1,"z":32}},{"blockCount":63,"bytes":2040,"file":"chunks/y216-z160-x224.json","offset":{"x":224,"y":216,"z":160},"requirements":{"minecraft:cobbled_deepslate":17,"minecraft:oak_planks":18,"minecraft:spruce_planks":15,"minecraft:stone_bricks":13},"sha256":"23e4852520a74ef54d85949c31bbf628e35c86e9948672ae5bb6d9220f0e83ca","size":{"x":32,"y":1,"z":32}},{"blockCount":40,"bytes":1477,"file":"chunks/y217-z096-x192.json","offset":{"x":192,"y":217,"z":96},"requirements":{"minecraft:cobbled_deepslate":17,"minecraft:oak_planks":1,"minecraft:stone_bricks":22},"sha256":"7883348595897d34ac64584a2dab46a67b05786fe83f7d0a7e8bbebe66bd9306","size":{"x":32,"y":1,"z":32}},{"blockCount":57,"bytes":1686,"file":"chunks/y217-z096-x224.json","offset":{"x":224,"y":217,"z":96},"requirements":{"minecraft:cobbled_deepslate":20,"minecraft:oak_planks":4,"minecraft:stone_bricks":33},"sha256":"61fe5e87a17b3a79ed4fe518bcf6719b2d09f52db383e270deea355b885e1e43","size":{"x":32,"y":1,"z":32}},{"blockCount":1,"bytes":644,"file":"chunks/y217-z128-x096.json","offset":{"x":96,"y":217,"z":128},"requirements":{"minecraft:stone_bricks":1},"sha256":"9770118823e14da916145b2d5dbeb16a160735fe75e380a1bf042cff98d9b9fd","size":{"x":32,"y":1,"z":32}},{"blockCount":40,"bytes":1478,"file":"chunks/y217-z160-x192.json","offset":{"x":192,"y":217,"z":160},"requirements":{"minecraft:cobbled_deepslate":17,"minecraft:oak_planks":1,"minecraft:stone_bricks":22},"sha256":"100d2de3c7d02f0369abbb0ca020463b6596ff6ca6b2f3a0ce5d3fbe87278064","size":{"x":32,"y":1,"z":32}},{"blockCount":57,"bytes":1668,"file":"chunks/y217-z160-x224.json","offset":{"x":224,"y":217,"z":160},"requirements":{"minecraft:cobbled_deepslate":19,"minecraft:oak_planks":4,"minecraft:stone_bricks":34},"sha256":"de3f5eb65c69f83673cb6631d4ee54f679eba200f4254f340ca2cb68f821e3ff","size":{"x":32,"y":1,"z":32}},{"blockCount":19,"bytes":1284,"file":"chunks/y218-z096-x192.json","offset":{"x":192,"y":218,"z":96},"requirements":{"minecraft:cobbled_deepslate":11,"minecraft:oak_planks":1,"minecraft:stone_bricks":7},"sha256":"0ae379972f4eade040f032b828d10693cd37be7ad8474a7ac3a241b4b7002168","size":{"x":32,"y":1,"z":32}},{"blockCount":30,"bytes":1494,"file":"chunks/y218-z096-x224.json","offset":{"x":224,"y":218,"z":96},"requirements":{"minecraft:cobbled_deepslate":15,"minecraft:oak_planks":4,"minecraft:stone_bricks":11},"sha256":"8258006f87e73e948b1d2b9649b11cbd682089667cc2d2cc5ca32e4ecd18a555","size":{"x":32,"y":1,"z":32}},{"blockCount":1,"bytes":644,"file":"chunks/y218-z128-x096.json","offset":{"x":96,"y":218,"z":128},"requirements":{"minecraft:stone_bricks":1},"sha256":"98f6e695eb5e4084986e448fbcbd7ab992c82172e78f7c6f9fe964c094e5d059","size":{"x":32,"y":1,"z":32}},{"blockCount":19,"bytes":1284,"file":"chunks/y218-z160-x192.json","offset":{"x":192,"y":218,"z":160},"requirements":{"minecraft:cobbled_deepslate":9,"minecraft:oak_planks":1,"minecraft:stone_bricks":9},"sha256":"56e790a5f4fa402ebc9dd6966bf07321b7a7935902f6135415c83b0eca3820cb","size":{"x":32,"y":1,"z":32}},{"blockCount":30,"bytes":1552,"file":"chunks/y218-z160-x224.json","offset":{"x":224,"y":218,"z":160},"requirements":{"minecraft:cobbled_deepslate":15,"minecraft:oak_planks":4,"minecraft:stone_bricks":11},"sha256":"9d1d322fa48d59d35a464b0403161c5c57b7b7d4f374cb6a6e2883585b030194","size":{"x":32,"y":1,"z":32}},{"blockCount":27,"bytes":1420,"file":"chunks/y219-z096-x192.json","offset":{"x":192,"y":219,"z":96},"requirements":{"minecraft:cobbled_deepslate":10,"minecraft:oak_planks":1,"minecraft:stone_bricks":16},"sha256":"a4d4fa2cfe4bc7fe3ed02a2b7a0e39670992a50a991d2842f1f7fe0e89b5ccbe","size":{"x":32,"y":1,"z":32}},{"blockCount":38,"bytes":1610,"file":"chunks/y219-z096-x224.json","offset":{"x":224,"y":219,"z":96},"requirements":{"minecraft:cobbled_deepslate":15,"minecraft:oak_planks":4,"minecraft:stone_bricks":19},"sha256":"51ecf2c09a99834e73f6c0d9baebfcbc9349402ab5684e00bd2f217f299c95c0","size":{"x":32,"y":1,"z":32}},{"blockCount":1,"bytes":644,"file":"chunks/y219-z128-x096.json","offset":{"x":96,"y":219,"z":128},"requirements":{"minecraft:stone_bricks":1},"sha256":"5a26773cbf1efee5a3707d6b72bc89862456267b306f1efba0bcee9a69895219","size":{"x":32,"y":1,"z":32}},{"blockCount":27,"bytes":1439,"file":"chunks/y219-z160-x192.json","offset":{"x":192,"y":219,"z":160},"requirements":{"minecraft:cobbled_deepslate":9,"minecraft:oak_planks":1,"minecraft:stone_bricks":17},"sha256":"63bcb5e257325fde96a8c6adccc2561cb41670853a8ba8ce55f7a357a59a560f","size":{"x":32,"y":1,"z":32}},{"blockCount":38,"bytes":1649,"file":"chunks/y219-z160-x224.json","offset":{"x":224,"y":219,"z":160},"requirements":{"minecraft:cobbled_deepslate":15,"minecraft:oak_planks":4,"minecraft:stone_bricks":19},"sha256":"3e5d3a32cd96755223517290633e2355cd1faf56ff7fae1f5754c271895c8506","size":{"x":32,"y":1,"z":32}},{"blockCount":28,"bytes":1483,"file":"chunks/y220-z096-x192.json","offset":{"x":192,"y":220,"z":96},"requirements":{"minecraft:cobbled_deepslate":11,"minecraft:oak_planks":7,"minecraft:spruce_planks":3,"minecraft:stone_bricks":7},"sha256":"5d8456c1a57e4a00f3b7571b9ef809635de6f354e07a720f5c7d0c06cc260a72","size":{"x":32,"y":1,"z":32}},{"blockCount":45,"bytes":1713,"file":"chunks/y220-z096-x224.json","offset":{"x":224,"y":220,"z":96},"requirements":{"minecraft:cobbled_deepslate":16,"minecraft:oak_planks":14,"minecraft:spruce_planks":5,"minecraft:stone_bricks":10},"sha256":"b0db905f42ff864eeb72e090452883917303ddc62529ffff895748cab3172b9e","size":{"x":32,"y":1,"z":32}},{"blockCount":3,"bytes":753,"file":"chunks/y220-z128-x096.json","offset":{"x":96,"y":220,"z":128},"requirements":{"minecraft:polished_diorite":2,"minecraft:stone_bricks":1},"sha256":"7a56ef8dbcb67c76225b5b9064c9f42f895f61b6114bb350489e67060b9838e2","size":{"x":32,"y":1,"z":32}},{"blockCount":28,"bytes":1465,"file":"chunks/y220-z160-x192.json","offset":{"x":192,"y":220,"z":160},"requirements":{"minecraft:cobbled_deepslate":10,"minecraft:oak_planks":7,"minecraft:spruce_planks":3,"minecraft:stone_bricks":8},"sha256":"797e92636757c8df5d2d838a5266fca868ae790e8dfa1a6ad802c0623e613888","size":{"x":32,"y":1,"z":32}},{"blockCount":45,"bytes":1675,"file":"chunks/y220-z160-x224.json","offset":{"x":224,"y":220,"z":160},"requirements":{"minecraft:cobbled_deepslate":17,"minecraft:oak_planks":14,"minecraft:spruce_planks":5,"minecraft:stone_bricks":9},"sha256":"dbb7d039c907e4f54dd94becd280b8d5a41cbea209aaa603fdf0e42057551858","size":{"x":32,"y":1,"z":32}},{"blockCount":32,"bytes":1341,"file":"chunks/y221-z096-x192.json","offset":{"x":192,"y":221,"z":96},"requirements":{"minecraft:cobbled_deepslate":8,"minecraft:oak_planks":1,"minecraft:stone_bricks":23},"sha256":"1934a840c14528106fd48d82473a8fbef1e6e67053f5a0082da9a25e4dc90ae6","size":{"x":32,"y":1,"z":32}},{"blockCount":49,"bytes":1589,"file":"chunks/y221-z096-x224.json","offset":{"x":224,"y":221,"z":96},"requirements":{"minecraft:cobbled_deepslate":14,"minecraft:oak_planks":4,"minecraft:stone_bricks":31},"sha256":"2128939f71778ba24fd2a7e109d0e3b97bb1bd2a7fcd8dbe310ddcbc60e7892a","size":{"x":32,"y":1,"z":32}},{"blockCount":7,"bytes":902,"file":"chunks/y221-z128-x096.json","offset":{"x":96,"y":221,"z":128},"requirements":{"minecraft:sandstone":3,"minecraft:stone_bricks":4},"sha256":"cfbcdac9f478ee4f0f5d7153a3f9f3d61a67e2cb55ce874ba1e32aaa896da364","size":{"x":32,"y":1,"z":32}},{"blockCount":32,"bytes":1342,"file":"chunks/y221-z160-x192.json","offset":{"x":192,"y":221,"z":160},"requirements":{"minecraft:cobbled_deepslate":8,"minecraft:oak_planks":1,"minecraft:stone_bricks":23},"sha256":"8187d3cd1e57f507fe5cc35f36e03890b642244978c1354074cf7444c5325aff","size":{"x":32,"y":1,"z":32}},{"blockCount":49,"bytes":1552,"file":"chunks/y221-z160-x224.json","offset":{"x":224,"y":221,"z":160},"requirements":{"minecraft:cobbled_deepslate":14,"minecraft:oak_planks":4,"minecraft:stone_bricks":31},"sha256":"d8014ae46093419e50702544b348dd33d87133e4fc57d2c7cd2199bd56bbe2a2","size":{"x":32,"y":1,"z":32}},{"blockCount":17,"bytes":1243,"file":"chunks/y222-z096-x192.json","offset":{"x":192,"y":222,"z":96},"requirements":{"minecraft:cobbled_deepslate":9,"minecraft:oak_planks":1,"minecraft:stone_bricks":7},"sha256":"821e8a5f7d8643703cf691eacc71317d796e1529e16e55fbd3d8fcc44b628244","size":{"x":32,"y":1,"z":32}},{"blockCount":28,"bytes":1434,"file":"chunks/y222-z096-x224.json","offset":{"x":224,"y":222,"z":96},"requirements":{"minecraft:cobbled_deepslate":15,"minecraft:oak_planks":4,"minecraft:stone_bricks":9},"sha256":"c4a61f736b33370f465819d8d013123c1ecf1d97ac117bb5d666f0dc49f2137b","size":{"x":32,"y":1,"z":32}},{"blockCount":3,"bytes":753,"file":"chunks/y222-z128-x096.json","offset":{"x":96,"y":222,"z":128},"requirements":{"minecraft:polished_diorite":2,"minecraft:stone_bricks":1},"sha256":"1a5036e50a01fb911e09620c4e3470d0dc926bed58a56cfdb0d452187e5949ef","size":{"x":32,"y":1,"z":32}},{"blockCount":17,"bytes":1244,"file":"chunks/y222-z160-x192.json","offset":{"x":192,"y":222,"z":160},"requirements":{"minecraft:cobbled_deepslate":9,"minecraft:oak_planks":1,"minecraft:stone_bricks":7},"sha256":"f10c7195f5ed5e79970d8d43049ff1091029d0b588c1b7fedb12ee22db45842f","size":{"x":32,"y":1,"z":32}},{"blockCount":28,"bytes":1435,"file":"chunks/y222-z160-x224.json","offset":{"x":224,"y":222,"z":160},"requirements":{"minecraft:cobbled_deepslate":15,"minecraft:oak_planks":4,"minecraft:stone_bricks":9},"sha256":"3f35a510dad00b5ad7e7257614ecdd67e0b61a860649cc3f5ede89fd62309dfe","size":{"x":32,"y":1,"z":32}},{"blockCount":25,"bytes":1398,"file":"chunks/y223-z096-x192.json","offset":{"x":192,"y":223,"z":96},"requirements":{"minecraft:cobbled_deepslate":9,"minecraft:oak_planks":1,"minecraft:stone_bricks":15},"sha256":"4f6a96ac1638158ccca80c9cc8932efb4bce9a353f62e7c68df3e8a58e053898","size":{"x":32,"y":1,"z":32}},{"blockCount":36,"bytes":1627,"file":"chunks/y223-z096-x224.json","offset":{"x":224,"y":223,"z":96},"requirements":{"minecraft:cobbled_deepslate":13,"minecraft:oak_planks":4,"minecraft:stone_bricks":19},"sha256":"191a91b939171b2d4d1cdafb1a0a68237e547cffd254bca3da12508f2910b38e","size":{"x":32,"y":1,"z":32}},{"blockCount":1,"bytes":644,"file":"chunks/y223-z128-x096.json","offset":{"x":96,"y":223,"z":128},"requirements":{"minecraft:stone_bricks":1},"sha256":"022336603dccedbb78d2da34527c9d6808ed2a438b15c915523b7109cf9af8a6","size":{"x":32,"y":1,"z":32}},{"blockCount":25,"bytes":1380,"file":"chunks/y223-z160-x192.json","offset":{"x":192,"y":223,"z":160},"requirements":{"minecraft:cobbled_deepslate":8,"minecraft:oak_planks":1,"minecraft:stone_bricks":16},"sha256":"b4845e3fdec4a35d609ec0fb0fc3708f687b54504b664769ff7b9288cf770d30","size":{"x":32,"y":1,"z":32}},{"blockCount":36,"bytes":1609,"file":"chunks/y223-z160-x224.json","offset":{"x":224,"y":223,"z":160},"requirements":{"minecraft:cobbled_deepslate":14,"minecraft:oak_planks":4,"minecraft:stone_bricks":18},"sha256":"64473696f47f7c750ff811cd782609f4b7308a6e7de8b247006a6888cf4ab5fb","size":{"x":32,"y":1,"z":32}},{"blockCount":26,"bytes":1442,"file":"chunks/y224-z096-x192.json","offset":{"x":192,"y":224,"z":96},"requirements":{"minecraft:cobbled_deepslate":9,"minecraft:oak_planks":7,"minecraft:spruce_planks":3,"minecraft:stone_bricks":7},"sha256":"cd41eafd72180a4c6c63e3b1de1dfccb3f2fe448984a2c224c03f5175e27403b","size":{"x":32,"y":1,"z":32}},{"blockCount":47,"bytes":1693,"file":"chunks/y224-z096-x224.json","offset":{"x":224,"y":224,"z":96},"requirements":{"minecraft:cobbled_deepslate":13,"minecraft:oak_planks":13,"minecraft:spruce_planks":10,"minecraft:stone_bricks":11},"sha256":"65d3c70776c95ddeb03c066331c03cf3d01e6536895250cc2099a2d9f9d25183","size":{"x":32,"y":1,"z":32}},{"blockCount":1,"bytes":641,"file":"chunks/y224-z128-x096.json","offset":{"x":96,"y":224,"z":128},"requirements":{"minecraft:sandstone":1},"sha256":"8a626b9a5b53fff1397dab25507c56f33553d3a369d20335c48fc7e1eb77fadf","size":{"x":32,"y":1,"z":32}},{"blockCount":26,"bytes":1443,"file":"chunks/y224-z160-x192.json","offset":{"x":192,"y":224,"z":160},"requirements":{"minecraft:cobbled_deepslate":9,"minecraft:oak_planks":7,"minecraft:spruce_planks":3,"minecraft:stone_bricks":7},"sha256":"77ae1768e9bfd3b64f39b23edb8d52288d44a17e876db75344953b974498cbbc","size":{"x":32,"y":1,"z":32}},{"blockCount":47,"bytes":1656,"file":"chunks/y224-z160-x224.json","offset":{"x":224,"y":224,"z":160},"requirements":{"minecraft:cobbled_deepslate":14,"minecraft:oak_planks":13,"minecraft:spruce_planks":10,"minecraft:stone_bricks":10},"sha256":"42329d18552326f011d6f7a388f7a4a16933b3609adc368efb9380ff866146f5","size":{"x":32,"y":1,"z":32}},{"blockCount":21,"bytes":1147,"file":"chunks/y225-z096-x192.json","offset":{"x":192,"y":225,"z":96},"requirements":{"minecraft:cobbled_deepslate":7,"minecraft:oak_planks":1,"minecraft:stone_bricks":13},"sha256":"efddc492da0128c6768254a982071dd9b1bce2f5c63aac83e99ac0322cfc93da","size":{"x":32,"y":1,"z":32}},{"blockCount":40,"bytes":1454,"file":"chunks/y225-z096-x224.json","offset":{"x":224,"y":225,"z":96},"requirements":{"minecraft:cobbled_deepslate":14,"minecraft:oak_planks":3,"minecraft:stone_bricks":23},"sha256":"9f9965c8c28b87e82d383510297be2b08472eb6fd458b719a1867daf2f34a624","size":{"x":32,"y":1,"z":32}},{"blockCount":21,"bytes":1167,"file":"chunks/y225-z160-x192.json","offset":{"x":192,"y":225,"z":160},"requirements":{"minecraft:cobbled_deepslate":9,"minecraft:oak_planks":1,"minecraft:stone_bricks":11},"sha256":"cd359c3148309f25211dc1afca09a53692f0515918ff368810792b4f2dbb0332","size":{"x":32,"y":1,"z":32}},{"blockCount":40,"bytes":1455,"file":"chunks/y225-z160-x224.json","offset":{"x":224,"y":225,"z":160},"requirements":{"minecraft:cobbled_deepslate":13,"minecraft:oak_planks":3,"minecraft:stone_bricks":24},"sha256":"b8a6c532a5582f777bb6fd47134295f35abe60e175e80258b7750be44576d79a","size":{"x":32,"y":1,"z":32}},{"blockCount":11,"bytes":1030,"file":"chunks/y226-z096-x192.json","offset":{"x":192,"y":226,"z":96},"requirements":{"minecraft:cobbled_deepslate":3,"minecraft:oak_planks":1,"minecraft:stone_bricks":7},"sha256":"f2eb3a2f84270a051346f9e839a4348a863ae1f3d0e2b485e4e9e1535c7d01ca","size":{"x":32,"y":1,"z":32}},{"blockCount":22,"bytes":1299,"file":"chunks/y226-z096-x224.json","offset":{"x":224,"y":226,"z":96},"requirements":{"minecraft:cobbled_deepslate":9,"minecraft:oak_planks":3,"minecraft:stone_bricks":10},"sha256":"3eb42765b11a791628b7f98ede9f71ade6bb7ac5139e28cc424fc8c8ae135c5b","size":{"x":32,"y":1,"z":32}},{"blockCount":11,"bytes":1031,"file":"chunks/y226-z160-x192.json","offset":{"x":192,"y":226,"z":160},"requirements":{"minecraft:cobbled_deepslate":5,"minecraft:oak_planks":1,"minecraft:stone_bricks":5},"sha256":"8999c7668480298784772cd725a31177e2677a06851df8fb63ae42e59f0642f0","size":{"x":32,"y":1,"z":32}},{"blockCount":22,"bytes":1281,"file":"chunks/y226-z160-x224.json","offset":{"x":224,"y":226,"z":160},"requirements":{"minecraft:cobbled_deepslate":10,"minecraft:oak_planks":3,"minecraft:stone_bricks":9},"sha256":"24e7241894f04ce073cf64094c91f59e844ee5682ff2a6780b31d7b1ff1c962a","size":{"x":32,"y":1,"z":32}},{"blockCount":16,"bytes":1147,"file":"chunks/y227-z096-x192.json","offset":{"x":192,"y":227,"z":96},"requirements":{"minecraft:cobbled_deepslate":3,"minecraft:oak_planks":1,"minecraft:stone_bricks":12},"sha256":"73b43418c270bfab62cefa97cec05b908ce26bb46a4c3742625714a666da69f0","size":{"x":32,"y":1,"z":32}},{"blockCount":32,"bytes":1549,"file":"chunks/y227-z096-x224.json","offset":{"x":224,"y":227,"z":96},"requirements":{"minecraft:cobbled_deepslate":10,"minecraft:oak_planks":3,"minecraft:stone_bricks":19},"sha256":"0dd9cd3683cb74caed22c5ee59b08ccf9427963ba6e55ed25ddf816ce6cce1b0","size":{"x":32,"y":1,"z":32}},{"blockCount":16,"bytes":1148,"file":"chunks/y227-z160-x192.json","offset":{"x":192,"y":227,"z":160},"requirements":{"minecraft:cobbled_deepslate":5,"minecraft:oak_planks":1,"minecraft:stone_bricks":10},"sha256":"53d201ed1a0173546d085f102c8fa523ba2976e52dc60942d02ff14f3040d17f","size":{"x":32,"y":1,"z":32}},{"blockCount":32,"bytes":1530,"file":"chunks/y227-z160-x224.json","offset":{"x":224,"y":227,"z":160},"requirements":{"minecraft:cobbled_deepslate":9,"minecraft:oak_planks":3,"minecraft:stone_bricks":20},"sha256":"b7b80e1335fc23d72c5183f98043bdb46b3fba477a27e1792fd23eaa92376c57","size":{"x":32,"y":1,"z":32}},{"blockCount":12,"bytes":1030,"file":"chunks/y228-z096-x192.json","offset":{"x":192,"y":228,"z":96},"requirements":{"minecraft:cobbled_deepslate":4,"minecraft:oak_planks":3,"minecraft:stone_bricks":5},"sha256":"8416e9fa3cfbed75709356d4b7390d65cf00ddef65f608716a6a2867905b322c","size":{"x":32,"y":1,"z":32}},{"blockCount":32,"bytes":1460,"file":"chunks/y228-z096-x224.json","offset":{"x":224,"y":228,"z":96},"requirements":{"minecraft:cobbled_deepslate":8,"minecraft:oak_planks":9,"minecraft:spruce_planks":4,"minecraft:stone_bricks":11},"sha256":"2c6ceac9e76c6f171b0f875bc75c6dea306f1867543184f6d6fee57e35b5d592","size":{"x":32,"y":1,"z":32}},{"blockCount":12,"bytes":1031,"file":"chunks/y228-z160-x192.json","offset":{"x":192,"y":228,"z":160},"requirements":{"minecraft:cobbled_deepslate":5,"minecraft:oak_planks":3,"minecraft:stone_bricks":4},"sha256":"dbc5206b7f174d1530770eb5d6984bb144bfe0d7d4e4aeb25178a07d8bf13a56","size":{"x":32,"y":1,"z":32}},{"blockCount":32,"bytes":1480,"file":"chunks/y228-z160-x224.json","offset":{"x":224,"y":228,"z":160},"requirements":{"minecraft:cobbled_deepslate":9,"minecraft:oak_planks":9,"minecraft:spruce_planks":4,"minecraft:stone_bricks":10},"sha256":"6bc8097ba600739d8251533eaa55d7064ff3d646d4fb4a3c2fbf32140d5939ac","size":{"x":32,"y":1,"z":32}},{"blockCount":14,"bytes":949,"file":"chunks/y229-z096-x192.json","offset":{"x":192,"y":229,"z":96},"requirements":{"minecraft:cobbled_deepslate":2,"minecraft:stone_bricks":12},"sha256":"b6522f1192fb0fe84364189dde04b759d70060c43d284d7dca93695b708c61c3","size":{"x":32,"y":1,"z":32}},{"blockCount":34,"bytes":1318,"file":"chunks/y229-z096-x224.json","offset":{"x":224,"y":229,"z":96},"requirements":{"minecraft:cobbled_deepslate":8,"minecraft:oak_planks":4,"minecraft:stone_bricks":22},"sha256":"4b3e6d02e7651fdf9a911738226ab883146340260c0601e9be818be3311ed7c4","size":{"x":32,"y":1,"z":32}},{"blockCount":14,"bytes":969,"file":"chunks/y229-z160-x192.json","offset":{"x":192,"y":229,"z":160},"requirements":{"minecraft:cobbled_deepslate":3,"minecraft:stone_bricks":11},"sha256":"80eb0c1d1c65a83b6a335a76094780b2b84dbebe72a476175bc53bb355bec209","size":{"x":32,"y":1,"z":32}},{"blockCount":34,"bytes":1319,"file":"chunks/y229-z160-x224.json","offset":{"x":224,"y":229,"z":160},"requirements":{"minecraft:cobbled_deepslate":9,"minecraft:oak_planks":4,"minecraft:stone_bricks":21},"sha256":"77afff18bbbb822ffbcc746ab54754412074dc451d43ddfe92d75cae7b1d73be","size":{"x":32,"y":1,"z":32}},{"blockCount":7,"bytes":870,"file":"chunks/y230-z096-x192.json","offset":{"x":192,"y":230,"z":96},"requirements":{"minecraft:cobbled_deepslate":3,"minecraft:stone_bricks":4},"sha256":"df6d515fa31130f4ec0b808f3e1d4d23ca8b357709104d4942b00153577a478a","size":{"x":32,"y":1,"z":32}},{"blockCount":21,"bytes":1220,"file":"chunks/y230-z096-x224.json","offset":{"x":224,"y":230,"z":96},"requirements":{"minecraft:cobbled_deepslate":9,"minecraft:oak_planks":4,"minecraft:stone_bricks":8},"sha256":"d478826e2c2af174a8397857cf35490a4e93e6f39c1a4497641cad4cca87be97","size":{"x":32,"y":1,"z":32}},{"blockCount":7,"bytes":871,"file":"chunks/y230-z160-x192.json","offset":{"x":192,"y":230,"z":160},"requirements":{"minecraft:cobbled_deepslate":3,"minecraft:stone_bricks":4},"sha256":"e9b9c1d23e3b8d54c053154fce40bff916983c21050f5d90e1e8119d001fc18a","size":{"x":32,"y":1,"z":32}}],"schema":1}
