{"entries":[{"blockCount":21,"bytes":1240,"file":"chunks/y230-z160-x224.json","offset":{"x":224,"y":230,"z":160},"requirements":{"minecraft:cobbled_deepslate":8,"minecraft:oak_planks":4,"minecraft:stone_bricks":9},"sha256":"ca4b331f2d2598ccc0df83eaa9253081206b462a2d4a114fc5a964a77f192ccf","size":{"x":32,"y":1,"z":32}},{"blockCount":9,"bytes":851,"file":"chunks/y231-z096-x192.json","offset":{"x":192,"y":231,"z":96},"requirements":{"minecraft:cobbled_deepslate":2,"minecraft:stone_bricks":7},"sha256":"ae7f0cf9eae749b9647d2c8895c01bcf4681a37783beb3168ef12d6b74e4686c","size":{"x":32,"y":1,"z":32}},{"blockCount":27,"bytes":1394,"file":"chunks/y231-z096-x224.json","offset":{"x":224,"y":231,"z":96},"requirements":{"minecraft:cobbled_deepslate":7,"minecraft:oak_planks":4,"minecraft:stone_bricks":16},"sha256":"86fb9d9b6e816080f5d45d6bbfc595e7090c2fa732aaa3ea48602d2d8db2eeb1","size":{"x":32,"y":1,"z":32}},{"blockCount":9,"bytes":871,"file":"chunks/y231-z160-x192.json","offset":{"x":192,"y":231,"z":160},"requirements":{"minecraft:cobbled_deepslate":2,"minecraft:stone_bricks":7},"sha256":"1b7363c58ebf9f97cd8143d9dd0752e11305b9c1a8a394099bdefcc8748ceff6","size":{"x":32,"y":1,"z":32}},{"blockCount":27,"bytes":1376,"file":"chunks/y231-z160-x224.json","offset":{"x":224,"y":231,"z":160},"requirements":{"minecraft:cobbled_deepslate":9,"minecraft:oak_planks":4,"minecraft:stone_bricks":14},"sha256":"5e828d2132344bf0fb7908fa5df44d24ec4265ee4ffb6fcf405c246650e7b95c","size":{"x":32,"y":1,"z":32}},{"blockCount":7,"bytes":870,"file":"chunks/y232-z096-x192.json","offset":{"x":192,"y":232,"z":96},"requirements":{"minecraft:cobbled_deepslate":3,"minecraft:stone_bricks":4},"sha256":"3d0341f2ee38614858de076f52525a04ea4686997f29816c36dbc8fece1cd3ef","size":{"x":32,"y":1,"z":32}},{"blockCount":25,"bytes":1220,"file":"chunks/y232-z096-x224.json","offset":{"x":224,"y":232,"z":96},"requirements":{"minecraft:cobbled_deepslate":8,"minecraft:oak_planks":8,"minecraft:stone_bricks":9},"sha256":"50e759f7f9f190fd9972af7a535f768a53b50dd5b332e6180f0edd1b0010f3f5","size":{"x":32,"y":1,"z":32}},{"blockCount":7,"bytes":871,"file":"chunks/y232-z160-x192.json","offset":{"x":192,"y":232,"z":160},"requirements":{"minecraft:cobbled_deepslate":3,"minecraft:stone_bricks":4},"sha256":"c0b8af892f1fba991f103dd57ada139bcddac34b7b8baca4cae3da22497243ea","size":{"x":32,"y":1,"z":32}},{"blockCount":25,"bytes":1183,"file":"chunks/y232-z160-x224.json","offset":{"x":224,"y":232,"z":160},"requirements":{"minecraft:cobbled_deepslate":9,"minecraft:oak_planks":8,"minecraft:stone_bricks":8},"sha256":"65b396bdda91ee78dbe6170429c67b70775a30d146c19c8c8cf4837c4472a1eb","size":{"x":32,"y":1,"z":32}},{"blockCount":7,"bytes":800,"file":"chunks/y233-z096-x192.json","offset":{"x":192,"y":233,"z":96},"requirements":{"minecraft:stone_bricks":7},"sha256":"e2ed9934ef42c34b88b9ae85882904588e4ff738a076833ed9ed539403902fd8","size":{"x":32,"y":1,"z":32}},{"blockCount":21,"bytes":1120,"file":"chunks/y233-z096-x224.json","offset":{"x":224,"y":233,"z":96},"requirements":{"minecraft:cobbled_deepslate":4,"minecraft:stone_bricks":17},"sha256":"4a9ccd86a5b9d35799db41b3fed4a8a5280ae917014e99c07b1ff7d5603a7429","size":{"x":32,"y":1,"z":32}},{"blockCount":7,"bytes":801,"file":"chunks/y233-z160-x192.json","offset":{"x":192,"y":233,"z":160},"requirements":{"minecraft:stone_bricks":7},"sha256":"3730fb712befecf3378d33de9c6c6049af2985e5edd72b721045eaad588cd2b4","size":{"x":32,"y":1,"z":32}},{"blockCount":21,"bytes":1121,"file":"chunks/y233-z160-x224.json","offset":{"x":224,"y":233,"z":160},"requirements":{"minecraft:cobbled_deepslate":4,"minecraft:stone_bricks":17},"sha256":"53ccf8a3b9eaece9816a39d554ae564f3dd781eba69f8d58cb5b1735a9d24dbb","size":{"x":32,"y":1,"z":32}},{"blockCount":2,"bytes":683,"file":"chunks/y234-z096-x192.json","offset":{"x":192,"y":234,"z":96},"requirements":{"minecraft:stone_bricks":2},"sha256":"f45ce50bf5c9509620d93b509a678f9c6632f3707423ef190c305daaa6832872","size":{"x":32,"y":1,"z":32}},{"blockCount":10,"bytes":1022,"file":"chunks/y234-z096-x224.json","offset":{"x":224,"y":234,"z":96},"requirements":{"minecraft:cobbled_deepslate":4,"minecraft:stone_bricks":6},"sha256":"70307f6f1d57ac6771cae4d21c0734f6c969cd20c16ea41ee8b646454a05d98b","size":{"x":32,"y":1,"z":32}},{"blockCount":2,"bytes":684,"file":"chunks/y234-z160-x192.json","offset":{"x":192,"y":234,"z":160},"requirements":{"minecraft:stone_bricks":2},"sha256":"0d109350b8a67517ae8a7f5a0307434ed1e1fe6e85f168dca5df57164bcbdbfd","size":{"x":32,"y":1,"z":32}},{"blockCount":10,"bytes":992,"file":"chunks/y234-z160-x224.json","offset":{"x":224,"y":234,"z":160},"requirements":{"minecraft:stone_bricks":10},"sha256":"bfa7a075118403e937d4af8a6f81e3ab3b8381dba22b583e358f387bdbd19a6f","size":{"x":32,"y":1,"z":32}},{"blockCount":6,"bytes":761,"file":"chunks/y235-z096-x192.json","offset":{"x":192,"y":235,"z":96},"requirements":{"minecraft:stone_bricks":6},"sha256":"55bdac90da7af58fa1ab6906c0a05fbe7ec7d7d0600679714c8db46224cf95f6","size":{"x":32,"y":1,"z":32}},{"blockCount":18,"bytes":1177,"file":"chunks/y235-z096-x224.json","offset":{"x":224,"y":235,"z":96},"requirements":{"minecraft:cobbled_deepslate":3,"minecraft:stone_bricks":15},"sha256":"507e5de73b5b4800b436d49ead3de425c9f70ecbfa7c2a607fcc90f22db734cb","size":{"x":32,"y":1,"z":32}},{"blockCount":6,"bytes":762,"file":"chunks/y235-z160-x192.json","offset":{"x":192,"y":235,"z":160},"requirements":{"minecraft:stone_bricks":6},"sha256":"707cea664718e7695b9a9007c31e9e0891efbd6217ba00f21fc1be82684b8ff6","size":{"x":32,"y":1,"z":32}},{"blockCount":18,"bytes":1178,"file":"chunks/y235-z160-x224.json","offset":{"x":224,"y":235,"z":160},"requirements":{"minecraft:cobbled_deepslate":3,"minecraft:stone_bricks":15},"sha256":"ba7d1dfd6ec50b8663c2178359738db1bdccfde0c916e7eb81d1b780ebcff37d","size":{"x":32,"y":1,"z":32}},{"blockCount":2,"bytes":683,"file":"chunks/y236-z096-x192.json","offset":{"x":192,"y":236,"z":96},"requirements":{"minecraft:stone_bricks":2},"sha256":"fc36d6f0524e84e14583208395b1f24fa855d8a80cc8e4b05415228d6fee597a","size":{"x":32,"y":1,"z":32}},{"blockCount":11,"bytes":1022,"file":"chunks/y236-z096-x224.json","offset":{"x":224,"y":236,"z":96},"requirements":{"minecraft:cobbled_deepslate":4,"minecraft:stone_bricks":7},"sha256":"cd96c40f2e57de92459c29ae25ca001bc214981194e62c8b50906803c0403335","size":{"x":32,"y":1,"z":32}},{"blockCount":2,"bytes":684,"file":"chunks/y236-z160-x192.json","offset":{"x":192,"y":236,"z":160},"requirements":{"minecraft:stone_bricks":2},"sha256":"3d8d18990eee548330abf0c505e872fb2676a278e72fc944beeec153618880cf","size":{"x":32,"y":1,"z":32}},{"blockCount":11,"bytes":1023,"file":"chunks/y236-z160-x224.json","offset":{"x":224,"y":236,"z":160},"requirements":{"minecraft:cobbled_deepslate":4,"minecraft:stone_bricks":7},"sha256":"7ceb2b738aece24b8b9053215fb2a8932bb46907b3346d24c6cb9460846cfc9e","size":{"x":32,"y":1,"z":32}},{"blockCount":2,"bytes":683,"file":"chunks/y237-z096-x192.json","offset":{"x":192,"y":237,"z":96},"requirements":{"minecraft:stone_bricks":2},"sha256":"80528309b64715b30852072d2ee3aecd4899012501c4c00495037476ce95a303","size":{"x":32,"y":1,"z":32}},{"blockCount":15,"bytes":947,"file":"chunks/y237-z096-x224.json","offset":{"x":224,"y":237,"z":96},"requirements":{"minecraft:cobbled_deepslate":1,"minecraft:stone_bricks":14},"sha256":"7c39c486a76e78ef45b68cf5f23d6754a7d0aa15ff885e981d25e01cb419396f","size":{"x":32,"y":1,"z":32}},{"blockCount":2,"bytes":684,"file":"chunks/y237-z160-x192.json","offset":{"x":192,"y":237,"z":160},"requirements":{"minecraft:stone_bricks":2},"sha256":"f085fd2386979453abd551a1eea75f1586a21b2d0c9beecf7fd8b7200ffcef16","size":{"x":32,"y":1,"z":32}},{"blockCount":15,"bytes":948,"file":"chunks/y237-z160-x224.json","offset":{"x":224,"y":237,"z":160},"requirements":{"minecraft:cobbled_deepslate":1,"minecraft:stone_bricks":14},"sha256":"fbf895a988537f3b5f492089b0f6c80a054ac44dcb0f67b9c2053c5df4d3936c","size":{"x":32,"y":1,"z":32}},{"blockCount":5,"bytes":830,"file":"chunks/y238-z096-x224.json","offset":{"x":224,"y":238,"z":96},"requirements":{"minecraft:cobbled_deepslate":1,"minecraft:stone_bricks":4},"sha256":"9058c33ca2232b28f51dfb930003784655945593ada3858ae5f98c366f0433ea","size":{"x":32,"y":1,"z":32}},{"blockCount":5,"bytes":799,"file":"chunks/y238-z160-x224.json","offset":{"x":224,"y":238,"z":160},"requirements":{"minecraft:stone_bricks":5},"sha256":"4e0fd1bd698d14dfef567200abac9a7db926a6f0295ce87a51a805b0dd89d9f5","size":{"x":32,"y":1,"z":32}},{"blockCount":2,"bytes":683,"file":"chunks/y239-z096-x192.json","offset":{"x":192,"y":239,"z":96},"requirements":{"minecraft:stone_bricks":2},"sha256":"627f4d896c6b83f8d39c596edefee88469f2abe494c81366817fc1044a1492b2","size":{"x":32,"y":1,"z":32}},{"blockCount":11,"bytes":985,"file":"chunks/y239-z096-x224.json","offset":{"x":224,"y":239,"z":96},"requirements":{"minecraft:cobbled_deepslate":1,"minecraft:stone_bricks":10},"sha256":"b520d312080aa2c2f4b22e598dcdaa9b2211d328985988d1bd65f513b94fcfb5","size":{"x":32,"y":1,"z":32}},{"blockCount":2,"bytes":684,"file":"chunks/y239-z160-x192.json","offset":{"x":192,"y":239,"z":160},"requirements":{"minecraft:stone_bricks":2},"sha256":"0472a371766a8f0d11858dcf7e36fbe436e49b3bf0e4d9e73d49c56ce7ce800f","size":{"x":32,"y":1,"z":32}},{"blockCount":11,"bytes":986,"file":"chunks/y239-z160-x224.json","offset":{"x":224,"y":239,"z":160},"requirements":{"minecraft:cobbled_deepslate":1,"minecraft:stone_bricks":10},"sha256":"86209477d9ee279893af62127d5646965ffe899bc9356a7bd78972c24ed5c282","size":{"x":32,"y":1,"z":32}},{"blockCount":9,"bytes":792,"file":"chunks/y240-z096-x224.json","offset":{"x":224,"y":240,"z":96},"requirements":{"minecraft:cobbled_deepslate":1,"minecraft:stone_bricks":8},"sha256":"01f379ed78fc2a69430406f726bc165cd732665232bce2c24b150d89400ab291","size":{"x":32,"y":1,"z":32}},{"blockCount":9,"bytes":793,"file":"chunks/y240-z160-x224.json","offset":{"x":224,"y":240,"z":160},"requirements":{"minecraft:cobbled_deepslate":1,"minecraft:stone_bricks":8},"sha256":"582205d8005b4fdb3773e3edded7054964bb5d1f7800e9c21a9de4fd761bacb2","size":{"x":32,"y":1,"z":32}},{"blockCount":3,"bytes":722,"file":"chunks/y241-z096-x192.json","offset":{"x":192,"y":241,"z":96},"requirements":{"minecraft:stone_bricks":3},"sha256":"34ba32e98e77b9d323180b9448d1864eb02a83cba6c2d32d03a0bca767979832","size":{"x":32,"y":1,"z":32}},{"blockCount":18,"bytes":947,"file":"chunks/y241-z096-x224.json","offset":{"x":224,"y":241,"z":96},"requirements":{"minecraft:cobbled_deepslate":4,"minecraft:stone_bricks":14},"sha256":"674909a1d689855baa34283adbcd56fc8b5c1b6c15da415addff122318f9df62","size":{"x":32,"y":1,"z":32}},{"blockCount":3,"bytes":723,"file":"chunks/y241-z160-x192.json","offset":{"x":192,"y":241,"z":160},"requirements":{"minecraft:stone_bricks":3},"sha256":"26ae1624dedbc92aac78f9e767945c0535f7c1c0b68d318896175b1f25466071","size":{"x":32,"y":1,"z":32}},{"blockCount":17,"bytes":948,"file":"chunks/y241-z160-x224.json","offset":{"x":224,"y":241,"z":160},"requirements":{"minecraft:cobbled_deepslate":4,"minecraft:stone_bricks":13},"sha256":"341da885f29b693e56a71396bbb3f64365cfdcdf546596605dfc2167926ce557","size":{"x":32,"y":1,"z":32}},{"blockCount":5,"bytes":792,"file":"chunks/y242-z096-x224.json","offset":{"x":224,"y":242,"z":96},"requirements":{"minecraft:cobbled_deepslate":4,"minecraft:stone_bricks":1},"sha256":"28563a8c05c60aeae9b6e17b5110f3ae8bcccf45cac846209b94ae55be8b3bef","size":{"x":32,"y":1,"z":32}},{"blockCount":5,"bytes":793,"file":"chunks/y242-z160-x224.json","offset":{"x":224,"y":242,"z":160},"requirements":{"minecraft:cobbled_deepslate":4,"minecraft:stone_bricks":1},"sha256":"6457fa47a996cdc4bb55569f80b089acb6f2d6b43e99fe19d991c95e922f3a70","size":{"x":32,"y":1,"z":32}},{"blockCount":1,"bytes":644,"file":"chunks/y243-z096-x224.json","offset":{"x":224,"y":243,"z":96},"requirements":{"minecraft:stone_bricks":1},"sha256":"835290653ebca80fd41af64827a4ef648df7b92fe2a345a59a17b52ae36e1dd7","size":{"x":32,"y":1,"z":32}},{"blockCount":1,"bytes":645,"file":"chunks/y243-z160-x224.json","offset":{"x":224,"y":243,"z":160},"requirements":{"minecraft:stone_bricks":1},"sha256":"96a0bb51520c233e4f99751ee9960a1e16bd6f222e3db9e968f8c9abcadf20a3","size":{"x":32,"y":1,"z":32}},{"blockCount":1,"bytes":644,"file":"chunks/y244-z096-x224.json","offset":{"x":224,"y":244,"z":96},"requirements":{"minecraft:stone_bricks":1},"sha256":"3ace6d1a7d2c8c7f8d8d50bcf56e4575e0d9d41a603ac6ae59ae0d7c2f6e1b08","size":{"x":32,"y":1,"z":32}},{"blockCount":1,"bytes":645,"file":"chunks/y244-z160-x224.json","offset":{"x":224,"y":244,"z":160},"requirements":{"minecraft:stone_bricks":1},"sha256":"400e27ddf9a5d006cff5eb4fa2a090c048171e32453f441b9c3583db2a646c6a","size":{"x":32,"y":1,"z":32}},{"blockCount":5,"bytes":722,"file":"chunks/y245-z096-x224.json","offset":{"x":224,"y":245,"z":96},"requirements":{"minecraft:stone_bricks":5},"sha256":"088749c1e36fb6ff43b0435e31cb6a559c1a1f45c1322f4d6450d1941ca20b48","size":{"x":32,"y":1,"z":32}},{"blockCount":5,"bytes":723,"file":"chunks/y245-z160-x224.json","offset":{"x":224,"y":245,"z":160},"requirements":{"minecraft:stone_bricks":5},"sha256":"d4b5b0265464508935b0bb0d2d7f29f818d1e667208a3e558a5901149edc4ccc","size":{"x":32,"y":1,"z":32}},{"blockCount":1,"bytes":644,"file":"chunks/y246-z096-x192.json","offset":{"x":192,"y":246,"z":96},"requirements":{"minecraft:stone_bricks":1},"sha256":"619da618fcf4a560ad87cc2a3230ae2b21951f7af0685feda6a2920c74386766","size":{"x":32,"y":1,"z":32}},{"blockCount":8,"bytes":800,"file":"chunks/y246-z096-x224.json","offset":{"x":224,"y":246,"z":96},"requirements":{"minecraft:stone_bricks":8},"sha256":"b6bcf1f9aa5c96f8742afbf1a7daab435f54c97118ff766374984db6b1cf4882","size":{"x":32,"y":1,"z":32}},{"blockCount":1,"bytes":645,"file":"chunks/y246-z160-x192.json","offset":{"x":192,"y":246,"z":160},"requirements":{"minecraft:stone_bricks":1},"sha256":"7435926eab751b136ae84f1a592ed0e74e303d9b3a82e958377df2467a97d42c","size":{"x":32,"y":1,"z":32}},{"blockCount":8,"bytes":801,"file":"chunks/y246-z160-x224.json","offset":{"x":224,"y":246,"z":160},"requirements":{"minecraft:stone_bricks":8},"sha256":"2837f27854ff839fb7357bece3fe31fc05b87ca836a527d8e18afce1c3332517","size":{"x":32,"y":1,"z":32}},{"blockCount":1,"bytes":644,"file":"chunks/y247-z096-x224.json","offset":{"x":224,"y":247,"z":96},"requirements":{"minecraft:stone_bricks":1},"sha256":"5f8b32ee230f0166bb9f057638124eb71bc204b32f0bfef52caa4ba5efb10dc5","size":{"x":32,"y":1,"z":32}},{"blockCount":1,"bytes":645,"file":"chunks/y247-z160-x224.json","offset":{"x":224,"y":247,"z":160},"requirements":{"minecraft:stone_bricks":1},"sha256":"9c77e097f55587335eb73976efbed7a5fa6ebea4c744709422fbaeb36aad7977","size":{"x":32,"y":1,"z":32}},{"blockCount":5,"bytes":722,"file":"chunks/y248-z096-x224.json","offset":{"x":224,"y":248,"z":96},"requirements":{"minecraft:stone_bricks":5},"sha256":"09c81b65ff20790f43e513ff2f26b367d110eca585c8a45b61a942132c66a5ca","size":{"x":32,"y":1,"z":32}},{"blockCount":5,"bytes":723,"file":"chunks/y248-z160-x224.json","offset":{"x":224,"y":248,"z":160},"requirements":{"minecraft:stone_bricks":5},"sha256":"fef1b3c757a009ec9f16fd1a573d67eda39088f4ec26b7b4b73a876c475e71b9","size":{"x":32,"y":1,"z":32}},{"blockCount":1,"bytes":626,"file":"chunks/y249-z000-x000.json","offset":{"x":0,"y":249,"z":0},"requirements":{"minecraft:cobbled_deepslate":1},"sha256":"80eb5700730fc9a4eb86b04a9d3947949ff6208e003cffbf2fc1643e6f8b7630","size":{"x":32,"y":1,"z":32}},{"blockCount":1,"bytes":644,"file":"chunks/y249-z096-x224.json","offset":{"x":224,"y":249,"z":96},"requirements":{"minecraft:stone_bricks":1},"sha256":"c04064d1be3450a5d7d14c1fa43eba482e3b905fe2ba342e261dee1b14c90d99","size":{"x":32,"y":1,"z":32}},{"blockCount":1,"bytes":645,"file":"chunks/y249-z160-x224.json","offset":{"x":224,"y":249,"z":160},"requirements":{"minecraft:stone_bricks":1},"sha256":"6a45fc27ac3b9be2e0d8e323ba89acc7c97a215283864d4d7b7ed05700944395","size":{"x":32,"y":1,"z":32}},{"blockCount":1,"bytes":618,"file":"chunks/y250-z000-x000.json","offset":{"x":0,"y":250,"z":0},"requirements":{"minecraft:sandstone":1},"sha256":"5e65e3a9a10ca46682343e50b2f5d0e2a7716acfb7deb9717e460d8aa5d832eb","size":{"x":32,"y":1,"z":32}},{"blockCount":1,"bytes":644,"file":"chunks/y250-z096-x224.json","offset":{"x":224,"y":250,"z":96},"requirements":{"minecraft:stone_bricks":1},"sha256":"003ee974fd8b5da1429136efc72c5969ae1b73a7dfb120c1e43a1a14b46746a5","size":{"x":32,"y":1,"z":32}},{"blockCount":1,"bytes":645,"file":"chunks/y250-z160-x224.json","offset":{"x":224,"y":250,"z":160},"requirements":{"minecraft:stone_bricks":1},"sha256":"7b6b4b15f0a30b08f562670147ae4fbee88f3335460eb89b745c4167cd2c4018","size":{"x":32,"y":1,"z":32}},{"blockCount":1,"bytes":626,"file":"chunks/y251-z000-x000.json","offset":{"x":0,"y":251,"z":0},"requirements":{"minecraft:cobbled_deepslate":1},"sha256":"34da33d37ffaeabec00cc649ccf58668617e0e65823bfbab4240221a093e670c","size":{"x":32,"y":1,"z":32}},{"blockCount":1,"bytes":644,"file":"chunks/y251-z096-x224.json","offset":{"x":224,"y":251,"z":96},"requirements":{"minecraft:stone_bricks":1},"sha256":"6d2b879e162740ade0405d1bd053e510348d4ebdb8ff7418d2790ef89f6aabc6","size":{"x":32,"y":1,"z":32}},{"blockCount":1,"bytes":645,"file":"chunks/y251-z160-x224.json","offset":{"x":224,"y":251,"z":160},"requirements":{"minecraft:stone_bricks":1},"sha256":"312708b8d7681bd76ecbb75edfabe3c18458f95808b26c5f78609dbc05885374","size":{"x":32,"y":1,"z":32}},{"blockCount":1,"bytes":618,"file":"chunks/y252-z000-x000.json","offset":{"x":0,"y":252,"z":0},"requirements":{"minecraft:sandstone":1},"sha256":"f21f5a09e7c24178c7393aa697f8c4ce8ef8299cf7e6eb16d521e76402459c26","size":{"x":32,"y":1,"z":32}},{"blockCount":5,"bytes":784,"file":"chunks/y252-z096-x224.json","offset":{"x":224,"y":252,"z":96},"requirements":{"minecraft:sandstone":1,"minecraft:stone_bricks":4},"sha256":"9cf95dfe415a8e2e804deb731096a4ab28cca3a0fffaa6d7b61af833f56d1f22","size":{"x":32,"y":1,"z":32}},{"blockCount":5,"bytes":785,"file":"chunks/y252-z160-x224.json","offset":{"x":224,"y":252,"z":160},"requirements":{"minecraft:sandstone":1,"minecraft:stone_bricks":4},"sha256":"b9597f7bdeb542f81f9e4124fa75b63ec69542f874017383aaa37de6ac6273cd","size":{"x":32,"y":1,"z":32}},{"blockCount":1,"bytes":626,"file":"chunks/y253-z000-x000.json","offset":{"x":0,"y":253,"z":0},"requirements":{"minecraft:cobbled_deepslate":1},"sha256":"14c893f6eda7381cff9d4e3c4d20413f7ba79c7400c495b22c69cd30fd2838d3","size":{"x":32,"y":1,"z":32}},{"blockCount":1,"bytes":644,"file":"chunks/y253-z096-x224.json","offset":{"x":224,"y":253,"z":96},"requirements":{"minecraft:stone_bricks":1},"sha256":"96b08c58777c2803e00e188efde075867b589599fc9dec220c9378ea93ef10b1","size":{"x":32,"y":1,"z":32}},{"blockCount":1,"bytes":645,"file":"chunks/y253-z160-x224.json","offset":{"x":224,"y":253,"z":160},"requirements":{"minecraft:stone_bricks":1},"sha256":"bceb0763cb2ed27c3e8178c1719a81710ab39d9de2aa553d2cf47112ebf31630","size":{"x":32,"y":1,"z":32}},{"blockCount":1,"bytes":618,"file":"chunks/y254-z000-x000.json","offset":{"x":0,"y":254,"z":0},"requirements":{"minecraft:sandstone":1},"sha256":"2bf4ad3c17a74e082d313cb3ac5829fd43a263b4d4910b959492f01a613418e8","size":{"x":32,"y":1,"z":32}},{"blockCount":1,"bytes":644,"file":"chunks/y254-z096-x224.json","offset":{"x":224,"y":254,"z":96},"requirements":{"minecraft:stone_bricks":1},"sha256":"8f01a748c07415c1be0a1eed220a0e73b984c373f50814117381b8752bcd888b","size":{"x":32,"y":1,"z":32}},{"blockCount":1,"bytes":645,"file":"chunks/y254-z160-x224.json","offset":{"x":224,"y":254,"z":160},"requirements":{"minecraft:stone_bricks":1},"sha256":"cea065d74955974b1cc1807c91d9603e40b4380418c626d997a46cc947be2b2f","size":{"x":32,"y":1,"z":32}},{"blockCount":1,"bytes":621,"file":"chunks/y255-z000-x000.json","offset":{"x":0,"y":255,"z":0},"requirements":{"minecraft:stone_bricks":1},"sha256":"f77f84b62f204729c42fdb13239de0ddd19927a4cd20ad741e59950e937e2e8a","size":{"x":32,"y":1,"z":32}}],"schema":1}
